Qubicle Exchange Format
Version 0.2
www.minddesk.com
276 122 359
46
0.137255 0.639216 0.160784
0.141176 0.329412 0.650980
0.180392 0.176471 0.176471
0.196078 0.384314 0.701961
0.227451 0.415686 0.737255
0.266667 0.156863 0.000000
0.290196 0.298039 0.301961
0.298039 0.486275 0.811765
0.356863 0.545098 0.874510
0.360784 0.545098 0.654902
0.431373 0.603922 0.709804
0.435294 0.458824 0.470588
0.443137 0.509804 0.619608
0.462745 0.105882 0.156863
0.486275 0.309804 0.054902
0.486275 0.682353 0.129412
0.490196 0.517647 0.529412
0.529412 0.345098 0.082353
0.549020 0.796078 0.839216
0.552941 0.564706 0.572549
0.615686 0.635294 0.643137
0.682353 0.466667 0.019608
0.788235 0.243137 0.133333
0.788235 0.611765 0.254902
0.796078 0.803922 0.807843
0.811765 0.964706 0.988235
0.823529 0.258824 0.145098
0.839216 0.611765 0.152941
0.862745 0.815686 0.498039
0.874510 0.274510 0.152941
0.890196 0.831373 0.427451
0.894118 0.200000 0.203922
0.909804 0.286275 0.160784
0.909804 0.913725 0.913725
0.921569 0.282353 0.156863
0.929412 0.925490 0.925490
0.933333 0.882353 0.529412
0.937255 0.890196 0.600000
0.941176 0.701961 0.215686
0.945098 0.294118 0.164706
0.956863 0.890196 0.435294
0.960784 0.533333 0.086275
0.980392 0.305882 0.172549
0.988235 0.360784 0.235294
1.000000 0.905882 0.003922
1.000000 1.000000 1.000000
172 21 78 0 52
172 21 77 0 20
172 21 76 0 84
172 22 80 0 52
172 22 79 0 20
172 22 78 0 4
172 22 77 0 4
172 22 76 0 4
172 22 75 0 20
172 22 74 0 84
172 23 81 0 60
172 23 80 0 4
172 23 79 0 4
172 23 78 0 4
172 23 77 0 4
172 23 76 0 4
172 23 75 0 4
172 23 74 0 4
172 23 73 0 92
172 24 80 0 44
172 24 79 0 12
172 24 78 0 4
172 24 77 0 4
172 24 76 0 4
172 24 75 0 12
172 24 74 0 76
172 25 78 0 44
172 25 77 0 12
172 25 76 0 76
173 20 77 0 116
173 21 81 0 52
173 21 80 0 20
173 21 79 0 20
173 21 78 0 16
173 21 77 0 0
173 21 76 0 16
173 21 75 0 20
173 21 74 0 20
173 21 73 0 84
173 22 82 0 52
173 22 81 0 4
173 22 80 0 0
173 22 79 0 0
173 22 78 0 0
173 22 77 0 0
173 22 76 0 0
173 22 75 0 0
173 22 74 0 0
173 22 73 0 4
173 22 72 0 84
173 23 83 0 60
173 23 82 0 4
173 23 81 0 0
173 23 80 0 0
173 23 79 0 0
173 23 78 0 0
173 23 77 0 0
173 23 76 0 0
173 23 75 0 0
173 23 74 0 0
173 23 73 0 0
173 23 72 0 4
173 23 71 0 92
173 24 82 0 44
173 24 81 0 4
173 24 80 0 0
173 24 79 0 0
173 24 78 0 0
173 24 77 0 0
173 24 76 0 0
173 24 75 0 0
173 24 74 0 0
173 24 73 0 4
173 24 72 0 76
173 25 81 0 44
173 25 80 0 12
173 25 79 0 12
173 25 78 0 8
173 25 77 0 0
173 25 76 0 8
173 25 75 0 12
173 25 74 0 12
173 25 73 0 76
173 26 77 0 108
174 20 80 0 52
174 20 79 0 20
174 20 78 0 20
174 20 77 0 16
174 20 76 0 20
174 20 75 0 20
174 20 74 0 84
174 21 89 0 52
174 21 88 0 20
174 21 87 0 20
174 21 86 0 20
174 21 85 0 84
174 21 82 0 52
174 21 81 0 16
174 21 80 0 0
174 21 79 0 0
174 21 78 0 0
174 21 77 0 0
174 21 76 0 0
174 21 75 0 0
174 21 74 0 0
174 21 73 0 16
174 21 72 0 84
174 22 91 0 52
174 22 90 0 20
174 22 89 0 4
174 22 88 0 4
174 22 87 0 4
174 22 86 0 4
174 22 85 0 4
174 22 84 0 20
174 22 83 0 20
174 22 82 0 0
174 22 81 0 0
174 22 80 0 0
174 22 79 0 0
174 22 78 0 0
174 22 77 0 0
174 22 76 0 0
174 22 75 0 0
174 22 74 0 0
174 22 73 0 0
174 22 72 0 0
174 22 71 0 84
174 23 91 0 44
174 23 90 0 12
174 23 89 0 4
174 23 88 0 4
174 23 87 0 4
174 23 86 0 4
174 23 85 0 4
174 23 84 0 12
174 23 83 0 0
174 23 82 0 0
174 23 81 0 0
174 23 80 0 0
174 23 79 0 0
174 23 78 0 0
174 23 77 0 0
174 23 76 0 0
174 23 75 0 0
174 23 74 0 0
174 23 73 0 0
174 23 72 0 0
174 23 71 0 0
174 23 70 0 92
174 24 89 0 44
174 24 88 0 12
174 24 87 0 12
174 24 86 0 12
174 24 85 0 76
174 24 83 0 44
174 24 82 0 0
174 24 81 0 0
174 24 80 0 0
174 24 79 0 0
174 24 78 0 0
174 24 77 0 0
174 24 76 0 0
174 24 75 0 0
174 24 74 0 0
174 24 73 0 0
174 24 72 0 0
174 24 71 0 76
174 25 82 0 44
174 25 81 0 8
174 25 80 0 0
174 25 79 0 0
174 25 78 0 0
174 25 77 0 0
174 25 76 0 0
174 25 75 0 0
174 25 74 0 0
174 25 73 0 8
174 25 72 0 76
174 26 80 0 44
174 26 79 0 12
174 26 78 0 12
174 26 77 0 8
174 26 76 0 12
174 26 75 0 12
174 26 74 0 76
175 19 77 0 116
175 20 89 0 52
175 20 88 0 20
175 20 87 0 20
175 20 86 0 20
175 20 85 0 84
175 20 82 0 52
175 20 81 0 20
175 20 80 0 16
175 20 79 0 16
175 20 78 0 16
175 20 77 0 0
175 20 76 0 16
175 20 75 0 16
175 20 74 0 16
175 20 73 0 20
175 20 72 0 84
175 21 91 0 52
175 21 90 0 20
175 21 89 0 0
175 21 88 0 0
175 21 87 0 0
175 21 86 0 0
175 21 85 0 0
175 21 84 0 20
175 21 83 0 20
175 21 82 0 0
175 21 81 0 0
175 21 80 0 0
175 21 79 0 0
175 21 78 0 0
175 21 77 0 0
175 21 76 0 0
175 21 75 0 0
175 21 74 0 0
175 21 73 0 0
175 21 72 0 0
175 21 71 0 84
175 22 92 0 52
175 22 91 0 0
175 22 90 0 0
175 22 89 0 0
175 22 88 0 0
175 22 87 0 0
175 22 86 0 0
175 22 85 0 0
175 22 84 0 0
175 22 83 0 0
175 22 82 0 0
175 22 81 0 0
175 22 80 0 0
175 22 79 0 0
175 22 78 0 0
175 22 77 0 0
175 22 76 0 0
175 22 75 0 0
175 22 74 0 0
175 22 73 0 0
175 22 72 0 0
175 22 71 0 0
175 22 70 0 84
175 23 92 0 44
175 23 91 0 0
175 23 90 0 0
175 23 89 0 0
175 23 88 0 0
175 23 87 0 0
175 23 86 0 0
175 23 85 0 0
175 23 84 0 0
175 23 83 0 0
175 23 82 0 0
175 23 81 0 0
175 23 80 0 0
175 23 79 0 0
175 23 78 0 0
175 23 77 0 0
175 23 76 0 0
175 23 75 0 0
175 23 74 0 0
175 23 73 0 0
175 23 72 0 0
175 23 71 0 0
175 23 70 0 0
175 23 69 0 92
175 24 91 0 44
175 24 90 0 12
175 24 89 0 0
175 24 88 0 0
175 24 87 0 0
175 24 86 0 0
175 24 85 0 0
175 24 84 0 12
175 24 83 0 0
175 24 82 0 0
175 24 81 0 0
175 24 80 0 0
175 24 79 0 0
175 24 78 0 0
175 24 77 0 0
175 24 76 0 0
175 24 75 0 0
175 24 74 0 0
175 24 73 0 0
175 24 72 0 0
175 24 71 0 0
175 24 70 0 76
175 25 89 0 44
175 25 88 0 12
175 25 87 0 12
175 25 86 0 12
175 25 85 0 76
175 25 83 0 44
175 25 82 0 0
175 25 81 0 0
175 25 80 0 0
175 25 79 0 0
175 25 78 0 0
175 25 77 0 0
175 25 76 0 0
175 25 75 0 0
175 25 74 0 0
175 25 73 0 0
175 25 72 0 0
175 25 71 0 76
175 26 82 0 44
175 26 81 0 12
175 26 80 0 8
175 26 79 0 8
175 26 78 0 8
175 26 77 0 0
175 26 76 0 8
175 26 75 0 8
175 26 74 0 8
175 26 73 0 12
175 26 72 0 76
175 27 77 0 108
176 19 80 0 52
176 19 79 0 20
176 19 78 0 20
176 19 77 0 16
176 19 76 0 20
176 19 75 0 20
176 19 74 0 84
176 20 91 0 52
176 20 90 0 20
176 20 89 0 16
176 20 88 0 16
176 20 87 0 16
176 20 86 0 16
176 20 85 0 16
176 20 84 0 20
176 20 83 0 20
176 20 82 0 16
176 20 81 0 16
176 20 80 0 0
176 20 79 0 0
176 20 78 0 0
176 20 77 0 0
176 20 76 0 0
176 20 75 0 0
176 20 74 0 0
176 20 73 0 16
176 20 72 0 16
176 20 71 0 84
176 21 93 0 52
176 21 92 0 20
176 21 91 0 0
176 21 90 0 0
176 21 89 0 0
176 21 88 0 0
176 21 87 0 0
176 21 86 0 0
176 21 85 0 0
176 21 84 0 0
176 21 83 0 0
176 21 82 0 0
176 21 81 0 0
176 21 80 0 0
176 21 79 0 0
176 21 78 0 0
176 21 77 0 0
176 21 76 0 0
176 21 75 0 0
176 21 74 0 0
176 21 73 0 0
176 21 72 0 0
176 21 71 0 0
176 21 70 0 84
176 22 94 0 52
176 22 93 0 4
176 22 92 0 0
176 22 91 0 0
176 22 90 0 0
176 22 89 0 0
176 22 88 0 0
176 22 87 0 0
176 22 86 0 0
176 22 85 0 0
176 22 84 0 0
176 22 83 0 0
176 22 82 0 0
176 22 81 0 0
176 22 80 0 0
176 22 79 0 0
176 22 78 0 0
176 22 77 0 0
176 22 76 0 0
176 22 75 0 0
176 22 74 0 0
176 22 73 0 0
176 22 72 0 0
176 22 71 0 0
176 22 70 0 0
176 22 69 0 84
176 23 94 0 44
176 23 93 0 4
176 23 92 0 0
176 23 91 0 0
176 23 90 0 0
176 23 89 0 0
176 23 88 0 0
176 23 87 0 0
176 23 86 0 0
176 23 85 0 0
176 23 84 0 0
176 23 83 0 0
176 23 82 0 0
176 23 81 0 0
176 23 80 0 0
176 23 79 0 0
176 23 78 0 0
176 23 77 0 0
176 23 76 0 0
176 23 75 0 0
176 23 74 0 0
176 23 73 0 0
176 23 72 0 0
176 23 71 0 0
176 23 70 0 0
176 23 69 0 64
176 24 93 0 44
176 24 92 0 12
176 24 91 0 0
176 24 90 0 0
176 24 89 0 0
176 24 88 0 0
176 24 87 0 0
176 24 86 0 0
176 24 85 0 0
176 24 84 0 0
176 24 83 0 0
176 24 82 0 0
176 24 81 0 0
176 24 80 0 0
176 24 79 0 0
176 24 78 0 0
176 24 77 0 0
176 24 76 0 0
176 24 75 0 0
176 24 74 0 0
176 24 73 0 0
176 24 72 0 0
176 24 71 0 0
176 24 70 0 0
176 24 69 0 76
176 25 91 0 44
176 25 90 0 12
176 25 89 0 8
176 25 88 0 8
176 25 87 0 8
176 25 86 0 8
176 25 85 0 8
176 25 84 0 12
176 25 83 0 0
176 25 82 0 0
176 25 81 0 0
176 25 80 0 0
176 25 79 0 0
176 25 78 0 0
176 25 77 0 0
176 25 76 0 0
176 25 75 0 0
176 25 74 0 0
176 25 73 0 0
176 25 72 0 0
176 25 71 0 0
176 25 70 0 76
176 26 83 0 44
176 26 82 0 8
176 26 81 0 8
176 26 80 0 0
176 26 79 0 0
176 26 78 0 0
176 26 77 0 0
176 26 76 0 0
176 26 75 0 0
176 26 74 0 0
176 26 73 0 8
176 26 72 0 8
176 26 71 0 76
176 27 80 0 44
176 27 79 0 12
176 27 78 0 12
176 27 77 0 8
176 27 76 0 12
176 27 75 0 12
176 27 74 0 76
177 18 85 0 52
177 18 84 0 20
177 18 83 0 20
177 18 82 0 20
177 18 81 0 84
177 19 88 0 52
177 19 87 0 20
177 19 86 0 20
177 19 85 0 4
177 19 84 0 4
177 19 83 0 4
177 19 82 0 4
177 19 81 0 4
177 19 80 0 16
177 19 79 0 16
177 19 78 0 16
177 19 77 0 16
177 19 76 0 16
177 19 75 0 16
177 19 74 0 16
177 19 73 0 84
177 20 92 0 52
177 20 91 0 16
177 20 90 0 16
177 20 89 0 16
177 20 88 0 0
177 20 87 0 0
177 20 86 0 0
177 20 85 0 0
177 20 84 0 0
177 20 83 0 0
177 20 82 0 0
177 20 81 0 0
177 20 80 0 0
177 20 79 0 0
177 20 78 0 0
177 20 77 0 0
177 20 76 0 0
177 20 75 0 0
177 20 74 0 0
177 20 73 0 0
177 20 72 0 16
177 20 71 0 80
177 21 94 0 52
177 21 93 0 16
177 21 92 0 0
177 21 91 0 0
177 21 90 0 0
177 21 89 0 0
177 21 88 0 0
177 21 87 0 0
177 21 86 0 0
177 21 85 0 0
177 21 84 0 0
177 21 83 0 0
177 21 82 0 0
177 21 81 0 0
177 21 80 0 0
177 21 79 0 0
177 21 78 0 0
177 21 77 0 0
177 21 76 0 0
177 21 75 0 0
177 21 74 0 0
177 21 73 0 0
177 21 72 0 0
177 21 71 0 0
177 21 70 0 16
177 21 69 0 84
177 22 94 0 32
177 22 93 0 0
177 22 92 0 0
177 22 91 0 0
177 22 90 0 0
177 22 89 0 0
177 22 88 0 0
177 22 87 0 0
177 22 86 0 0
177 22 85 0 0
177 22 84 0 0
177 22 83 0 0
177 22 82 0 0
177 22 81 0 0
177 22 80 0 0
177 22 79 0 0
177 22 78 0 0
177 22 77 0 0
177 22 76 0 0
177 22 75 0 0
177 22 74 0 0
177 22 73 0 0
177 22 72 0 0
177 22 71 0 0
177 22 70 0 0
177 22 69 0 64
177 23 94 0 32
177 23 93 0 0
177 23 92 0 0
177 23 91 0 0
177 23 90 0 0
177 23 89 0 0
177 23 88 0 0
177 23 87 0 0
177 23 86 0 0
177 23 85 0 0
177 23 84 0 0
177 23 83 0 0
177 23 82 0 0
177 23 81 0 0
177 23 80 0 0
177 23 79 0 0
177 23 78 0 0
177 23 77 0 0
177 23 76 0 0
177 23 75 0 0
177 23 74 0 0
177 23 73 0 0
177 23 72 0 0
177 23 71 0 0
177 23 70 0 0
177 23 69 0 0
177 23 68 0 92
177 24 94 0 44
177 24 93 0 8
177 24 92 0 0
177 24 91 0 0
177 24 90 0 0
177 24 89 0 0
177 24 88 0 0
177 24 87 0 0
177 24 86 0 0
177 24 85 0 0
177 24 84 0 0
177 24 83 0 0
177 24 82 0 0
177 24 81 0 0
177 24 80 0 0
177 24 79 0 0
177 24 78 0 0
177 24 77 0 0
177 24 76 0 0
177 24 75 0 0
177 24 74 0 0
177 24 73 0 0
177 24 72 0 0
177 24 71 0 0
177 24 70 0 0
177 24 69 0 64
177 25 92 0 44
177 25 91 0 8
177 25 90 0 8
177 25 89 0 8
177 25 88 0 0
177 25 87 0 0
177 25 86 0 0
177 25 85 0 8
177 25 84 0 8
177 25 83 0 0
177 25 82 0 0
177 25 81 0 0
177 25 80 0 0
177 25 79 0 0
177 25 78 0 0
177 25 77 0 0
177 25 76 0 0
177 25 75 0 0
177 25 74 0 0
177 25 73 0 0
177 25 72 0 0
177 25 71 0 0
177 25 70 0 0
177 25 69 0 68
177 26 88 0 44
177 26 87 0 12
177 26 86 0 76
177 26 83 0 40
177 26 82 0 8
177 26 81 0 0
177 26 80 0 0
177 26 79 0 0
177 26 78 0 0
177 26 77 0 0
177 26 76 0 0
177 26 75 0 0
177 26 74 0 0
177 26 73 0 0
177 26 72 0 0
177 26 71 0 0
177 26 70 0 4
177 26 69 0 68
177 27 81 0 44
177 27 80 0 8
177 27 79 0 8
177 27 78 0 8
177 27 77 0 8
177 27 76 0 8
177 27 75 0 8
177 27 74 0 8
177 27 73 0 4
177 27 72 0 4
177 27 71 0 4
177 27 70 0 4
177 27 69 0 76
177 28 73 0 44
177 28 72 0 12
177 28 71 0 12
177 28 70 0 76
178 17 81 21 116
178 18 87 0 52
178 18 86 0 20
178 18 85 0 16
178 18 84 0 16
178 18 83 0 16
178 18 82 0 16
178 18 81 0 64
178 19 90 0 52
178 19 89 0 20
178 19 88 0 16
178 19 87 0 0
178 19 86 0 0
178 19 85 0 0
178 19 84 0 0
178 19 83 0 0
178 19 82 0 0
178 19 81 0 0
178 19 80 0 16
178 19 79 0 16
178 19 78 0 16
178 19 77 0 16
178 19 76 0 16
178 19 75 0 16
178 19 74 0 16
178 19 73 0 16
178 19 72 0 84
178 20 93 0 52
178 20 92 0 16
178 20 91 0 16
178 20 90 0 0
178 20 89 0 0
178 20 88 0 0
178 20 87 0 0
178 20 86 0 0
178 20 85 0 0
178 20 84 0 0
178 20 83 0 0
178 20 82 0 0
178 20 81 0 0
178 20 80 0 0
178 20 79 0 0
178 20 78 0 0
178 20 77 0 0
178 20 76 0 0
178 20 75 0 0
178 20 74 0 0
178 20 73 0 0
178 20 72 0 0
178 20 71 0 16
178 20 70 0 84
178 21 94 0 48
178 21 93 0 0
178 21 92 0 0
178 21 91 0 0
178 21 90 0 0
178 21 89 0 0
178 21 88 0 0
178 21 87 0 0
178 21 86 0 0
178 21 85 0 0
178 21 84 0 0
178 21 83 0 0
178 21 82 0 0
178 21 81 0 0
178 21 80 0 0
178 21 79 0 0
178 21 78 0 0
178 21 77 0 0
178 21 76 0 0
178 21 75 0 0
178 21 74 0 0
178 21 73 0 0
178 21 72 0 0
178 21 71 0 0
178 21 70 0 0
178 21 69 0 80
178 22 95 0 52
178 22 94 0 0
178 22 93 0 0
178 22 92 0 0
178 22 91 0 0
178 22 90 0 0
178 22 89 0 0
178 22 88 0 0
178 22 87 0 0
178 22 86 0 0
178 22 85 0 0
178 22 84 0 0
178 22 83 0 0
178 22 82 0 0
178 22 81 0 0
178 22 80 0 0
178 22 79 0 0
178 22 78 0 0
178 22 77 0 0
178 22 76 0 0
178 22 75 0 0
178 22 74 0 0
178 22 73 0 0
178 22 72 0 0
178 22 71 0 0
178 22 70 0 0
178 22 69 0 0
178 22 68 0 84
178 23 95 0 44
178 23 94 0 0
178 23 93 0 0
178 23 92 0 0
178 23 91 0 0
178 23 90 0 0
178 23 89 0 0
178 23 88 0 0
178 23 87 0 0
178 23 86 0 0
178 23 85 0 0
178 23 84 0 0
178 23 83 0 0
178 23 82 0 0
178 23 81 0 0
178 23 80 0 0
178 23 79 0 0
178 23 78 0 0
178 23 77 0 0
178 23 76 0 0
178 23 75 0 0
178 23 74 0 0
178 23 73 0 0
178 23 72 0 0
178 23 71 0 0
178 23 70 0 0
178 23 69 0 0
178 23 68 0 64
178 24 94 0 40
178 24 93 0 0
178 24 92 0 0
178 24 91 0 0
178 24 90 0 0
178 24 89 0 0
178 24 88 0 0
178 24 87 0 0
178 24 86 0 0
178 24 85 0 0
178 24 84 0 0
178 24 83 0 0
178 24 82 0 0
178 24 81 0 0
178 24 80 0 0
178 24 79 0 0
178 24 78 0 0
178 24 77 0 0
178 24 76 0 0
178 24 75 0 0
178 24 74 0 0
178 24 73 0 0
178 24 72 0 0
178 24 71 0 0
178 24 70 0 0
178 24 69 0 0
178 24 68 0 68
178 25 93 0 44
178 25 92 0 8
178 25 91 0 8
178 25 90 0 0
178 25 89 0 0
178 25 88 0 0
178 25 87 0 0
178 25 86 0 0
178 25 85 0 0
178 25 84 0 0
178 25 83 0 0
178 25 82 0 0
178 25 81 0 0
178 25 80 0 0
178 25 79 0 0
178 25 78 0 0
178 25 77 0 0
178 25 76 0 0
178 25 75 0 0
178 25 74 0 0
178 25 73 0 0
178 25 72 0 0
178 25 71 0 0
178 25 70 0 0
178 25 69 0 0
178 25 68 0 4
178 25 67 0 84
178 26 90 0 44
178 26 89 0 12
178 26 88 0 8
178 26 87 0 8
178 26 86 0 8
178 26 85 0 12
178 26 84 0 12
178 26 83 0 8
178 26 82 0 0
178 26 81 0 0
178 26 80 0 0
178 26 79 0 0
178 26 78 0 0
178 26 77 0 0
178 26 76 0 0
178 26 75 0 0
178 26 74 0 0
178 26 73 0 0
178 26 72 0 0
178 26 71 0 0
178 26 70 0 0
178 26 69 0 0
178 26 68 0 4
178 26 67 0 76
178 27 82 0 44
178 27 81 0 8
178 27 80 0 8
178 27 79 0 8
178 27 78 0 8
178 27 77 0 8
178 27 76 0 8
178 27 75 0 0
178 27 74 0 0
178 27 73 0 0
178 27 72 0 0
178 27 71 0 0
178 27 70 0 0
178 27 69 0 0
178 27 68 0 68
178 28 75 0 44
178 28 74 0 12
178 28 73 0 0
178 28 72 0 0
178 28 71 0 0
178 28 70 0 0
178 28 69 0 12
178 28 68 0 76
178 29 73 0 44
178 29 72 0 12
178 29 71 0 12
178 29 70 0 76
179 14 80 21 116
179 15 81 21 54
179 15 80 21 76
179 16 81 21 102
179 17 81 21 98
179 18 88 0 52
179 18 87 0 16
179 18 86 0 16
179 18 85 0 16
179 18 84 0 16
179 18 83 0 16
179 18 82 0 16
179 18 81 0 0
179 18 80 0 20
179 18 79 0 84
179 19 91 0 52
179 19 90 0 16
179 19 89 0 16
179 19 88 0 0
179 19 87 0 0
179 19 86 0 0
179 19 85 0 0
179 19 84 0 0
179 19 83 0 0
179 19 82 0 0
179 19 81 0 0
179 19 80 0 0
179 19 79 0 0
179 19 78 0 16
179 19 77 0 16
179 19 76 0 16
179 19 75 0 16
179 19 74 0 16
179 19 73 0 16
179 19 72 0 80
179 20 94 0 52
179 20 93 0 16
179 20 92 0 16
179 20 91 0 0
179 20 90 0 0
179 20 89 0 0
179 20 88 0 0
179 20 87 0 0
179 20 86 0 0
179 20 85 0 0
179 20 84 0 0
179 20 83 0 0
179 20 82 0 0
179 20 81 0 0
179 20 80 0 0
179 20 79 0 0
179 20 78 0 0
179 20 77 0 0
179 20 76 0 0
179 20 75 0 0
179 20 74 0 0
179 20 73 0 0
179 20 72 0 0
179 20 71 0 16
179 20 70 0 80
179 21 95 0 52
179 21 94 0 0
179 21 93 0 0
179 21 92 0 0
179 21 91 0 0
179 21 90 0 0
179 21 89 0 0
179 21 88 0 0
179 21 87 0 0
179 21 86 0 0
179 21 85 0 0
179 21 84 0 0
179 21 83 0 0
179 21 82 0 0
179 21 81 0 0
179 21 80 0 0
179 21 79 0 0
179 21 78 0 0
179 21 77 0 0
179 21 76 0 0
179 21 75 0 0
179 21 74 0 0
179 21 73 0 0
179 21 72 0 0
179 21 71 0 0
179 21 70 0 0
179 21 69 0 80
179 22 96 0 52
179 22 95 0 0
179 22 94 0 0
179 22 93 0 0
179 22 92 0 0
179 22 91 0 0
179 22 90 0 0
179 22 89 0 0
179 22 88 0 0
179 22 87 0 0
179 22 86 0 0
179 22 85 0 0
179 22 84 0 0
179 22 83 0 0
179 22 82 0 0
179 22 81 0 0
179 22 80 0 0
179 22 79 0 0
179 22 78 0 0
179 22 77 0 0
179 22 76 0 0
179 22 75 0 0
179 22 74 0 0
179 22 73 0 0
179 22 72 0 0
179 22 71 0 0
179 22 70 0 0
179 22 69 0 0
179 22 68 0 80
179 23 96 0 44
179 23 95 0 0
179 23 94 0 0
179 23 93 0 0
179 23 92 0 0
179 23 91 0 0
179 23 90 0 0
179 23 89 0 0
179 23 88 0 0
179 23 87 0 0
179 23 86 0 0
179 23 85 0 0
179 23 84 0 0
179 23 83 0 0
179 23 82 0 0
179 23 81 0 0
179 23 80 0 0
179 23 79 0 0
179 23 78 0 0
179 23 77 0 0
179 23 76 0 0
179 23 75 0 0
179 23 74 0 0
179 23 73 0 0
179 23 72 0 0
179 23 71 0 0
179 23 70 0 0
179 23 69 0 0
179 23 68 0 0
179 23 67 0 84
179 24 95 0 44
179 24 94 0 0
179 24 93 0 0
179 24 92 0 0
179 24 91 0 0
179 24 90 0 0
179 24 89 0 0
179 24 88 0 0
179 24 87 0 0
179 24 86 0 0
179 24 85 0 0
179 24 84 0 0
179 24 83 0 0
179 24 82 0 0
179 24 81 0 0
179 24 80 0 0
179 24 79 0 0
179 24 78 0 0
179 24 77 0 0
179 24 76 0 0
179 24 75 0 0
179 24 74 0 0
179 24 73 0 0
179 24 72 0 0
179 24 71 0 0
179 24 70 0 0
179 24 69 0 0
179 24 68 0 0
179 24 67 0 68
179 25 94 0 44
179 25 93 0 8
179 25 92 0 8
179 25 91 0 0
179 25 90 0 0
179 25 89 0 0
179 25 88 0 0
179 25 87 0 0
179 25 86 0 0
179 25 85 0 0
179 25 84 0 0
179 25 83 0 0
179 25 82 0 0
179 25 81 0 0
179 25 80 0 0
179 25 79 0 0
179 25 78 0 0
179 25 77 0 0
179 25 76 0 0
179 25 75 0 0
179 25 74 0 0
179 25 73 0 0
179 25 72 0 0
179 25 71 0 0
179 25 70 0 0
179 25 69 0 0
179 25 68 0 0
179 25 67 0 64
179 26 91 0 44
179 26 90 0 8
179 26 89 0 8
179 26 88 0 8
179 26 87 0 8
179 26 86 0 8
179 26 85 0 8
179 26 84 0 8
179 26 83 0 8
179 26 82 0 0
179 26 81 0 0
179 26 80 0 0
179 26 79 0 0
179 26 78 0 0
179 26 77 0 0
179 26 76 0 0
179 26 75 0 0
179 26 74 0 0
179 26 73 0 0
179 26 72 0 0
179 26 71 0 0
179 26 70 0 0
179 26 69 0 0
179 26 68 0 0
179 26 67 0 64
179 27 82 0 40
179 27 81 0 8
179 27 80 0 8
179 27 79 0 8
179 27 78 0 8
179 27 77 0 8
179 27 76 0 0
179 27 75 0 0
179 27 74 0 0
179 27 73 0 0
179 27 72 0 0
179 27 71 0 0
179 27 70 0 0
179 27 69 0 0
179 27 68 0 0
179 27 67 0 68
179 28 76 0 44
179 28 75 0 0
179 28 74 0 0
179 28 73 0 0
179 28 72 0 0
179 28 71 0 0
179 28 70 0 0
179 28 69 0 0
179 28 68 0 0
179 28 67 0 76
179 29 75 0 44
179 29 74 0 12
179 29 73 0 8
179 29 72 0 0
179 29 71 0 0
179 29 70 0 8
179 29 69 0 12
179 29 68 0 76
179 30 72 0 44
179 30 71 0 76
180 3 80 21 124
180 13 80 21 116
180 14 80 21 96
180 15 80 21 106
180 18 89 0 52
180 18 88 0 16
180 18 87 0 16
180 18 86 0 16
180 18 85 0 16
180 18 84 0 16
180 18 83 0 16
180 18 82 0 16
180 18 81 0 16
180 18 80 0 16
180 18 79 0 16
180 18 78 0 20
180 18 77 0 84
180 19 92 0 52
180 19 91 0 16
180 19 90 0 16
180 19 89 0 0
180 19 88 0 0
180 19 87 0 0
180 19 86 0 0
180 19 85 0 0
180 19 84 0 0
180 19 83 0 0
180 19 82 0 0
180 19 81 0 0
180 19 80 0 0
180 19 79 0 0
180 19 78 0 0
180 19 77 0 0
180 19 76 0 16
180 19 75 0 16
180 19 74 0 16
180 19 73 0 16
180 19 72 0 80
180 20 94 0 48
180 20 93 0 16
180 20 92 0 0
180 20 91 0 0
180 20 90 0 0
180 20 89 0 0
180 20 88 0 0
180 20 87 0 0
180 20 86 0 0
180 20 85 0 0
180 20 84 0 0
180 20 83 0 0
180 20 82 0 0
180 20 81 0 0
180 20 80 0 0
180 20 79 0 0
180 20 78 0 0
180 20 77 0 0
180 20 76 0 0
180 20 75 0 0
180 20 74 0 0
180 20 73 0 0
180 20 72 0 0
180 20 71 0 16
180 20 70 0 80
180 21 95 0 48
180 21 94 0 0
180 21 93 0 0
180 21 92 0 0
180 21 91 0 0
180 21 90 0 0
180 21 89 0 0
180 21 88 0 0
180 21 87 0 0
180 21 86 0 0
180 21 85 0 0
180 21 84 0 0
180 21 83 0 0
180 21 82 0 0
180 21 81 0 0
180 21 80 0 0
180 21 79 0 0
180 21 78 0 0
180 21 77 0 0
180 21 76 0 0
180 21 75 0 0
180 21 74 0 0
180 21 73 0 0
180 21 72 0 0
180 21 71 0 0
180 21 70 0 0
180 21 69 0 16
180 21 68 0 84
180 22 96 0 48
180 22 95 0 0
180 22 94 0 0
180 22 93 0 0
180 22 92 0 0
180 22 91 0 0
180 22 90 0 0
180 22 89 0 0
180 22 88 0 0
180 22 87 0 0
180 22 86 0 0
180 22 85 0 0
180 22 84 0 0
180 22 83 0 0
180 22 82 0 0
180 22 81 0 0
180 22 80 0 0
180 22 79 0 0
180 22 78 0 0
180 22 77 0 0
180 22 76 0 0
180 22 75 0 0
180 22 74 0 0
180 22 73 0 0
180 22 72 0 0
180 22 71 0 0
180 22 70 0 0
180 22 69 0 0
180 22 68 0 64
180 23 96 0 40
180 23 95 0 0
180 23 94 0 0
180 23 93 0 0
180 23 92 0 0
180 23 91 0 0
180 23 90 0 0
180 23 89 0 0
180 23 88 0 0
180 23 87 0 0
180 23 86 0 0
180 23 85 0 0
180 23 84 0 0
180 23 83 0 0
180 23 82 0 0
180 23 81 0 0
180 23 80 0 0
180 23 79 0 0
180 23 78 0 0
180 23 77 0 0
180 23 76 0 0
180 23 75 0 0
180 23 74 0 0
180 23 73 0 0
180 23 72 0 0
180 23 71 0 0
180 23 70 0 0
180 23 69 0 0
180 23 68 0 0
180 23 67 0 80
180 24 95 0 40
180 24 94 0 0
180 24 93 0 0
180 24 92 0 0
180 24 91 0 0
180 24 90 0 0
180 24 89 0 0
180 24 88 0 0
180 24 87 0 0
180 24 86 0 0
180 24 85 0 0
180 24 84 0 0
180 24 83 0 0
180 24 82 0 0
180 24 81 0 0
180 24 80 0 0
180 24 79 0 0
180 24 78 0 0
180 24 77 0 0
180 24 76 0 0
180 24 75 0 0
180 24 74 0 0
180 24 73 0 0
180 24 72 0 0
180 24 71 0 0
180 24 70 0 0
180 24 69 0 0
180 24 68 0 0
180 24 67 0 0
180 24 66 0 84
180 25 94 0 40
180 25 93 0 8
180 25 92 0 0
180 25 91 0 0
180 25 90 0 0
180 25 89 0 0
180 25 88 0 0
180 25 87 0 0
180 25 86 0 0
180 25 85 0 0
180 25 84 0 0
180 25 83 0 0
180 25 82 0 0
180 25 81 0 0
180 25 80 0 0
180 25 79 0 0
180 25 78 0 0
180 25 77 0 0
180 25 76 0 0
180 25 75 0 0
180 25 74 0 0
180 25 73 0 0
180 25 72 0 0
180 25 71 0 0
180 25 70 0 0
180 25 69 0 0
180 25 68 0 0
180 25 67 0 0
180 25 66 0 68
180 26 92 0 44
180 26 91 0 8
180 26 90 0 8
180 26 89 0 8
180 26 88 0 8
180 26 87 0 8
180 26 86 0 8
180 26 85 0 8
180 26 84 0 8
180 26 83 0 8
180 26 82 0 0
180 26 81 0 0
180 26 80 0 0
180 26 79 0 0
180 26 78 0 0
180 26 77 0 0
180 26 76 0 0
180 26 75 0 0
180 26 74 0 0
180 26 73 0 0
180 26 72 0 0
180 26 71 0 0
180 26 70 0 0
180 26 69 0 0
180 26 68 0 0
180 26 67 0 0
180 26 66 0 68
180 27 82 0 40
180 27 81 0 8
180 27 80 0 8
180 27 79 0 8
180 27 78 0 8
180 27 77 0 8
180 27 76 0 0
180 27 75 0 0
180 27 74 0 0
180 27 73 0 0
180 27 72 0 0
180 27 71 0 0
180 27 70 0 0
180 27 69 0 0
180 27 68 0 0
180 27 67 0 0
180 27 66 0 76
180 28 76 0 40
180 28 75 0 0
180 28 74 0 0
180 28 73 0 0
180 28 72 0 0
180 28 71 0 0
180 28 70 0 0
180 28 69 0 0
180 28 68 0 0
180 28 67 0 72
180 29 75 0 40
180 29 74 0 0
180 29 73 0 0
180 29 72 0 0
180 29 71 0 0
180 29 70 0 0
180 29 69 0 0
180 29 68 0 72
180 30 74 0 44
180 30 73 0 12
180 30 72 0 8
180 30 71 0 8
180 30 70 0 12
180 30 69 0 76
181 3 80 21 56
181 3 79 21 92
181 12 80 21 116
181 13 80 21 98
181 14 80 21 106
181 17 81 0 52
181 17 80 0 20
181 17 79 0 20
181 17 78 0 20
181 17 77 0 20
181 17 76 0 20
181 17 75 0 20
181 17 74 0 84
181 18 89 0 48
181 18 88 0 16
181 18 87 0 16
181 18 86 0 16
181 18 85 0 16
181 18 84 0 16
181 18 83 0 16
181 18 82 0 16
181 18 81 0 0
181 18 80 0 0
181 18 79 0 0
181 18 78 0 0
181 18 77 0 0
181 18 76 0 4
181 18 75 0 4
181 18 74 0 4
181 18 73 0 20
181 18 72 0 84
181 19 92 0 48
181 19 91 0 16
181 19 90 0 16
181 19 89 0 0
181 19 88 0 0
181 19 87 0 0
181 19 86 0 0
181 19 85 0 0
181 19 84 0 0
181 19 83 0 0
181 19 82 0 0
181 19 81 0 0
181 19 80 0 0
181 19 79 0 0
181 19 78 0 0
181 19 77 0 0
181 19 76 0 0
181 19 75 0 0
181 19 74 0 0
181 19 73 0 0
181 19 72 0 0
181 19 71 0 20
181 19 70 0 84
181 20 95 0 52
181 20 94 0 16
181 20 93 0 16
181 20 92 0 0
181 20 91 0 0
181 20 90 0 0
181 20 89 0 0
181 20 88 0 0
181 20 87 0 0
181 20 86 0 0
181 20 85 0 0
181 20 84 0 0
181 20 83 0 0
181 20 82 0 0
181 20 81 0 0
181 20 80 0 0
181 20 79 0 0
181 20 78 0 0
181 20 77 0 0
181 20 76 0 0
181 20 75 0 0
181 20 74 0 0
181 20 73 0 0
181 20 72 0 0
181 20 71 0 0
181 20 70 0 0
181 20 69 0 84
181 21 96 0 52
181 21 95 0 0
181 21 94 0 0
181 21 93 0 0
181 21 92 0 0
181 21 91 0 0
181 21 90 0 0
181 21 89 0 0
181 21 88 0 0
181 21 87 0 0
181 21 86 0 0
181 21 85 0 0
181 21 84 0 0
181 21 83 0 0
181 21 82 0 0
181 21 81 0 0
181 21 80 0 0
181 21 79 0 0
181 21 78 0 0
181 21 77 0 0
181 21 76 0 0
181 21 75 0 0
181 21 74 0 0
181 21 73 0 0
181 21 72 0 0
181 21 71 0 0
181 21 70 0 0
181 21 69 0 0
181 21 68 0 80
181 22 96 0 32
181 22 95 0 0
181 22 94 0 0
181 22 93 0 0
181 22 92 0 0
181 22 91 0 0
181 22 90 0 0
181 22 89 0 0
181 22 88 0 0
181 22 87 0 0
181 22 86 0 0
181 22 85 0 0
181 22 84 0 0
181 22 83 0 0
181 22 82 0 0
181 22 81 0 0
181 22 80 0 0
181 22 79 0 0
181 22 78 0 0
181 22 77 0 0
181 22 76 0 0
181 22 75 0 0
181 22 74 0 0
181 22 73 0 0
181 22 72 0 0
181 22 71 0 0
181 22 70 0 0
181 22 69 0 0
181 22 68 0 0
181 22 67 0 84
181 23 96 0 32
181 23 95 0 0
181 23 94 0 0
181 23 93 0 0
181 23 92 0 0
181 23 91 0 0
181 23 90 0 0
181 23 89 0 0
181 23 88 0 0
181 23 87 0 0
181 23 86 0 0
181 23 85 0 0
181 23 84 0 0
181 23 83 0 0
181 23 82 0 0
181 23 81 0 0
181 23 80 0 0
181 23 79 0 0
181 23 78 0 0
181 23 77 0 0
181 23 76 0 0
181 23 75 0 0
181 23 74 0 0
181 23 73 0 0
181 23 72 0 0
181 23 71 0 0
181 23 70 0 0
181 23 69 0 0
181 23 68 0 0
181 23 67 0 0
181 23 66 0 84
181 24 96 0 44
181 24 95 0 0
181 24 94 0 0
181 24 93 0 0
181 24 92 0 0
181 24 91 0 0
181 24 90 0 0
181 24 89 0 0
181 24 88 0 0
181 24 87 0 0
181 24 86 0 0
181 24 85 0 0
181 24 84 0 0
181 24 83 0 0
181 24 82 0 0
181 24 81 0 0
181 24 80 0 0
181 24 79 0 0
181 24 78 0 0
181 24 77 0 0
181 24 76 0 0
181 24 75 0 0
181 24 74 0 0
181 24 73 0 0
181 24 72 0 0
181 24 71 0 0
181 24 70 0 0
181 24 69 0 0
181 24 68 0 0
181 24 67 0 0
181 24 66 0 64
181 25 95 0 44
181 25 94 0 8
181 25 93 0 8
181 25 92 0 0
181 25 91 0 0
181 25 90 0 0
181 25 89 0 0
181 25 88 0 0
181 25 87 0 0
181 25 86 0 0
181 25 85 0 0
181 25 84 0 0
181 25 83 0 0
181 25 82 0 0
181 25 81 0 0
181 25 80 0 0
181 25 79 0 0
181 25 78 0 0
181 25 77 0 0
181 25 76 0 0
181 25 75 0 0
181 25 74 0 0
181 25 73 0 0
181 25 72 0 0
181 25 71 0 0
181 25 70 0 0
181 25 69 0 0
181 25 68 0 0
181 25 67 0 0
181 25 66 0 64
181 26 92 0 40
181 26 91 0 8
181 26 90 0 8
181 26 89 0 8
181 26 88 0 8
181 26 87 0 8
181 26 86 0 8
181 26 85 0 8
181 26 84 0 0
181 26 83 0 0
181 26 82 0 0
181 26 81 0 0
181 26 80 0 0
181 26 79 0 0
181 26 78 0 0
181 26 77 0 0
181 26 76 0 0
181 26 75 0 0
181 26 74 0 0
181 26 73 0 0
181 26 72 0 0
181 26 71 0 0
181 26 70 0 0
181 26 69 0 0
181 26 68 0 0
181 26 67 0 0
181 26 66 0 64
181 27 84 0 44
181 27 83 0 12
181 27 82 0 8
181 27 81 0 8
181 27 80 0 8
181 27 79 0 8
181 27 78 0 8
181 27 77 0 0
181 27 76 0 0
181 27 75 0 0
181 27 74 0 0
181 27 73 0 0
181 27 72 0 0
181 27 71 0 0
181 27 70 0 0
181 27 69 0 0
181 27 68 0 0
181 27 67 0 0
181 27 66 0 64
181 28 77 0 44
181 28 76 0 0
181 28 75 0 0
181 28 74 0 0
181 28 73 0 0
181 28 72 0 0
181 28 71 0 0
181 28 70 0 0
181 28 69 0 0
181 28 68 0 0
181 28 67 0 0
181 28 66 0 76
181 29 76 0 44
181 29 75 0 8
181 29 74 0 0
181 29 73 0 0
181 29 72 0 0
181 29 71 0 0
181 29 70 0 0
181 29 69 0 0
181 29 68 0 8
181 29 67 0 76
181 30 74 0 40
181 30 73 0 8
181 30 72 0 8
181 30 71 0 8
181 30 70 0 8
181 30 69 0 72
182 3 81 21 60
182 3 80 21 16
182 3 79 21 88
182 4 80 21 108
182 11 80 21 116
182 12 80 21 104
182 16 82 0 52
182 16 81 0 20
182 16 80 0 20
182 16 79 0 20
182 16 78 0 20
182 16 77 0 20
182 16 76 0 20
182 16 75 0 20
182 16 74 0 20
182 16 73 0 84
182 17 83 0 52
182 17 82 0 4
182 17 81 0 0
182 17 80 0 0
182 17 79 0 0
182 17 78 0 0
182 17 77 0 0
182 17 76 0 0
182 17 75 0 0
182 17 74 0 0
182 17 73 0 4
182 17 72 0 84
182 18 90 0 52
182 18 89 0 16
182 18 88 0 16
182 18 87 0 16
182 18 86 0 16
182 18 85 0 16
182 18 84 0 16
182 18 83 0 0
182 18 82 0 0
182 18 81 0 0
182 18 80 0 0
182 18 79 0 0
182 18 78 0 0
182 18 77 0 0
182 18 76 0 0
182 18 75 0 0
182 18 74 0 0
182 18 73 0 0
182 18 72 0 0
182 18 71 0 20
182 18 70 0 84
182 19 93 0 52
182 19 92 0 16
182 19 91 0 16
182 19 90 0 0
182 19 89 0 0
182 19 88 0 0
182 19 87 0 0
182 19 86 0 0
182 19 85 0 0
182 19 84 0 0
182 19 83 0 0
182 19 82 0 0
182 19 81 0 0
182 19 80 0 0
182 19 79 0 0
182 19 78 0 0
182 19 77 0 0
182 19 76 0 0
182 19 75 0 0
182 19 74 0 0
182 19 73 0 0
182 19 72 0 0
182 19 71 0 0
182 19 70 0 0
182 19 69 0 20
182 19 68 0 92
182 20 95 0 48
182 20 94 0 16
182 20 93 0 0
182 20 92 0 0
182 20 91 0 0
182 20 90 0 0
182 20 89 0 0
182 20 88 0 0
182 20 87 0 0
182 20 86 0 0
182 20 85 0 0
182 20 84 0 0
182 20 83 0 0
182 20 82 0 0
182 20 81 0 0
182 20 80 0 0
182 20 79 0 0
182 20 78 0 0
182 20 77 0 0
182 20 76 0 0
182 20 75 0 0
182 20 74 0 0
182 20 73 0 0
182 20 72 0 0
182 20 71 0 0
182 20 70 0 0
182 20 69 0 64
182 21 96 0 48
182 21 95 0 0
182 21 94 0 0
182 21 93 0 0
182 21 92 0 0
182 21 91 0 0
182 21 90 0 0
182 21 89 0 0
182 21 88 0 0
182 21 87 0 0
182 21 86 0 0
182 21 85 0 0
182 21 84 0 0
182 21 83 0 0
182 21 82 0 0
182 21 81 0 0
182 21 80 0 0
182 21 79 0 0
182 21 78 0 0
182 21 77 0 0
182 21 76 0 0
182 21 75 0 0
182 21 74 0 0
182 21 73 0 0
182 21 72 0 0
182 21 71 0 0
182 21 70 0 0
182 21 69 0 0
182 21 68 0 80
182 22 96 0 32
182 22 95 0 0
182 22 94 0 0
182 22 93 0 0
182 22 92 0 0
182 22 91 0 0
182 22 90 0 0
182 22 89 0 0
182 22 88 0 0
182 22 87 0 0
182 22 86 0 0
182 22 85 0 0
182 22 84 0 0
182 22 83 0 0
182 22 82 0 0
182 22 81 0 0
182 22 80 0 0
182 22 79 0 0
182 22 78 0 0
182 22 77 0 0
182 22 76 0 0
182 22 75 0 0
182 22 74 0 0
182 22 73 0 0
182 22 72 0 0
182 22 71 0 0
182 22 70 0 0
182 22 69 0 0
182 22 68 0 0
182 22 67 0 80
182 23 96 0 32
182 23 95 0 0
182 23 94 0 0
182 23 93 0 0
182 23 92 0 0
182 23 91 0 0
182 23 90 0 0
182 23 89 0 0
182 23 88 0 0
182 23 87 0 0
182 23 86 0 0
182 23 85 0 0
182 23 84 0 0
182 23 83 0 0
182 23 82 0 0
182 23 81 0 0
182 23 80 0 0
182 23 79 0 0
182 23 78 0 0
182 23 77 0 0
182 23 76 0 0
182 23 75 0 0
182 23 74 0 0
182 23 73 0 0
182 23 72 0 0
182 23 71 0 0
182 23 70 0 0
182 23 69 0 0
182 23 68 0 0
182 23 67 0 0
182 23 66 0 80
182 24 96 0 40
182 24 95 0 0
182 24 94 0 0
182 24 93 0 0
182 24 92 0 0
182 24 91 0 0
182 24 90 0 0
182 24 89 0 0
182 24 88 0 0
182 24 87 0 0
182 24 86 0 0
182 24 85 0 0
182 24 84 0 0
182 24 83 0 0
182 24 82 0 0
182 24 81 0 0
182 24 80 0 0
182 24 79 0 0
182 24 78 0 0
182 24 77 0 0
182 24 76 0 0
182 24 75 0 0
182 24 74 0 0
182 24 73 0 0
182 24 72 0 0
182 24 71 0 0
182 24 70 0 0
182 24 69 0 0
182 24 68 0 0
182 24 67 0 0
182 24 66 0 64
182 25 95 0 40
182 25 94 0 8
182 25 93 0 0
182 25 92 0 0
182 25 91 0 0
182 25 90 0 0
182 25 89 0 0
182 25 88 0 0
182 25 87 0 0
182 25 86 0 0
182 25 85 0 0
182 25 84 0 0
182 25 83 0 0
182 25 82 0 0
182 25 81 0 0
182 25 80 0 0
182 25 79 0 0
182 25 78 0 0
182 25 77 0 0
182 25 76 0 0
182 25 75 0 0
182 25 74 0 0
182 25 73 0 0
182 25 72 0 0
182 25 71 0 0
182 25 70 0 0
182 25 69 0 0
182 25 68 0 0
182 25 67 0 0
182 25 66 0 64
182 26 93 0 44
182 26 92 0 8
182 26 91 0 8
182 26 90 0 8
182 26 89 0 8
182 26 88 0 8
182 26 87 0 8
182 26 86 0 0
182 26 85 0 0
182 26 84 0 0
182 26 83 0 0
182 26 82 0 0
182 26 81 0 0
182 26 80 0 0
182 26 79 0 0
182 26 78 0 0
182 26 77 0 0
182 26 76 0 0
182 26 75 0 0
182 26 74 0 0
182 26 73 0 0
182 26 72 0 0
182 26 71 0 0
182 26 70 0 0
182 26 69 0 0
182 26 68 0 0
182 26 67 0 0
182 26 66 0 64
182 27 86 0 44
182 27 85 0 12
182 27 84 0 8
182 27 83 0 0
182 27 82 0 0
182 27 81 0 8
182 27 80 0 8
182 27 79 0 8
182 27 78 0 8
182 27 77 0 0
182 27 76 0 0
182 27 75 0 0
182 27 74 0 0
182 27 73 0 0
182 27 72 0 0
182 27 71 0 0
182 27 70 0 0
182 27 69 0 0
182 27 68 0 0
182 27 67 0 0
182 27 66 0 64
182 28 83 0 44
182 28 82 0 76
182 28 77 0 40
182 28 76 0 0
182 28 75 0 0
182 28 74 0 0
182 28 73 0 0
182 28 72 0 0
182 28 71 0 0
182 28 70 0 0
182 28 69 0 0
182 28 68 0 0
182 28 67 0 0
182 28 66 0 72
182 29 76 0 40
182 29 75 0 0
182 29 74 0 0
182 29 73 0 0
182 29 72 0 0
182 29 71 0 0
182 29 70 0 0
182 29 69 0 0
182 29 68 0 0
182 29 67 0 72
182 30 75 0 44
182 30 74 0 8
182 30 73 0 8
182 30 72 0 8
182 30 71 0 8
182 30 70 0 8
182 30 69 0 8
182 30 68 0 76
183 3 82 21 60
183 3 81 21 16
183 3 80 21 16
183 3 79 21 80
183 4 81 21 36
183 4 80 21 0
183 4 79 21 68
183 5 81 21 36
183 5 80 21 4
183 5 79 21 68
183 6 81 21 36
183 6 80 21 4
183 6 79 21 76
183 7 81 21 36
183 7 80 21 68
183 8 81 21 36
183 8 80 21 68
183 9 81 21 44
183 9 80 21 68
183 10 80 21 100
183 11 81 21 60
183 11 80 21 64
183 12 80 21 96
183 13 81 21 54
183 13 80 21 68
183 14 81 21 38
183 14 80 21 68
183 15 81 21 38
183 15 80 21 68
183 15 78 0 52
183 15 77 0 20
183 15 76 0 20
183 15 75 0 20
183 15 74 0 84
183 16 83 0 52
183 16 82 0 16
183 16 81 0 0
183 16 80 0 0
183 16 79 0 16
183 16 78 0 0
183 16 77 0 0
183 16 76 0 0
183 16 75 0 0
183 16 74 0 0
183 16 73 0 16
183 16 72 0 84
183 17 85 0 52
183 17 84 0 20
183 17 83 0 0
183 17 82 0 0
183 17 81 0 0
183 17 80 0 0
183 17 79 0 0
183 17 78 0 0
183 17 77 0 0
183 17 76 0 0
183 17 75 0 0
183 17 74 0 0
183 17 73 0 0
183 17 72 0 0
183 17 71 0 20
183 17 70 0 84
183 18 90 0 48
183 18 89 0 16
183 18 88 0 16
183 18 87 0 16
183 18 86 0 16
183 18 85 0 0
183 18 84 0 0
183 18 83 0 0
183 18 82 0 0
183 18 81 0 0
183 18 80 0 0
183 18 79 0 0
183 18 78 0 0
183 18 77 0 0
183 18 76 0 0
183 18 75 0 0
183 18 74 0 0
183 18 73 0 0
183 18 72 0 0
183 18 71 0 0
183 18 70 0 0
183 18 69 0 84
183 19 93 0 48
183 19 92 0 16
183 19 91 0 16
183 19 90 0 0
183 19 89 0 0
183 19 88 0 0
183 19 87 0 0
183 19 86 0 0
183 19 85 0 0
183 19 84 0 0
183 19 83 0 0
183 19 82 0 0
183 19 81 0 0
183 19 80 0 0
183 19 79 0 0
183 19 78 0 0
183 19 77 0 0
183 19 76 0 0
183 19 75 0 0
183 19 74 0 0
183 19 73 0 0
183 19 72 0 0
183 19 71 0 0
183 19 70 0 0
183 19 69 0 0
183 19 68 0 16
183 19 67 0 92
183 20 95 0 48
183 20 94 0 16
183 20 93 0 0
183 20 92 0 0
183 20 91 0 0
183 20 90 0 0
183 20 89 0 0
183 20 88 0 0
183 20 87 0 0
183 20 86 0 0
183 20 85 0 0
183 20 84 0 0
183 20 83 0 0
183 20 82 0 0
183 20 81 0 0
183 20 80 0 0
183 20 79 0 0
183 20 78 0 0
183 20 77 0 0
183 20 76 0 0
183 20 75 0 0
183 20 74 0 0
183 20 73 0 0
183 20 72 0 0
183 20 71 0 0
183 20 70 0 0
183 20 69 0 0
183 20 68 0 68
183 21 96 0 48
183 21 95 0 0
183 21 94 0 0
183 21 93 0 0
183 21 92 0 0
183 21 91 0 0
183 21 90 0 0
183 21 89 0 0
183 21 88 0 0
183 21 87 0 0
183 21 86 0 0
183 21 85 0 0
183 21 84 0 0
183 21 83 0 0
183 21 82 0 0
183 21 81 0 0
183 21 80 0 0
183 21 79 0 0
183 21 78 0 0
183 21 77 0 0
183 21 76 0 0
183 21 75 0 0
183 21 74 0 0
183 21 73 0 0
183 21 72 0 0
183 21 71 0 0
183 21 70 0 0
183 21 69 0 0
183 21 68 0 0
183 21 67 0 84
183 22 96 0 32
183 22 95 0 0
183 22 94 0 0
183 22 93 0 0
183 22 92 0 0
183 22 91 0 0
183 22 90 0 0
183 22 89 0 0
183 22 88 0 0
183 22 87 0 0
183 22 86 0 0
183 22 85 0 0
183 22 84 0 0
183 22 83 0 0
183 22 82 0 0
183 22 81 0 0
183 22 80 0 0
183 22 79 0 0
183 22 78 0 0
183 22 77 0 0
183 22 76 0 0
183 22 75 0 0
183 22 74 0 0
183 22 73 0 0
183 22 72 0 0
183 22 71 0 0
183 22 70 0 0
183 22 69 0 0
183 22 68 0 0
183 22 67 0 64
183 23 96 0 32
183 23 95 0 0
183 23 94 0 0
183 23 93 0 0
183 23 92 0 0
183 23 91 0 0
183 23 90 0 0
183 23 89 0 0
183 23 88 0 0
183 23 87 0 0
183 23 86 0 0
183 23 85 0 0
183 23 84 0 0
183 23 83 0 0
183 23 82 0 0
183 23 81 0 0
183 23 80 0 0
183 23 79 0 0
183 23 78 0 0
183 23 77 0 0
183 23 76 0 0
183 23 75 0 0
183 23 74 0 0
183 23 73 0 0
183 23 72 0 0
183 23 71 0 0
183 23 70 0 0
183 23 69 0 0
183 23 68 0 0
183 23 67 0 0
183 23 66 0 80
183 24 96 0 40
183 24 95 0 0
183 24 94 0 0
183 24 93 0 0
183 24 92 0 0
183 24 91 0 0
183 24 90 0 0
183 24 89 0 0
183 24 88 0 0
183 24 87 0 0
183 24 86 0 0
183 24 85 0 0
183 24 84 0 0
183 24 83 0 0
183 24 82 0 0
183 24 81 0 0
183 24 80 0 0
183 24 79 0 0
183 24 78 0 0
183 24 77 0 0
183 24 76 0 0
183 24 75 0 0
183 24 74 0 0
183 24 73 0 0
183 24 72 0 0
183 24 71 0 0
183 24 70 0 0
183 24 69 0 0
183 24 68 0 0
183 24 67 0 0
183 24 66 0 64
183 25 95 0 40
183 25 94 0 8
183 25 93 0 0
183 25 92 0 0
183 25 91 0 0
183 25 90 0 0
183 25 89 0 0
183 25 88 0 0
183 25 87 0 0
183 25 86 0 0
183 25 85 0 0
183 25 84 0 0
183 25 83 0 0
183 25 82 0 0
183 25 81 0 0
183 25 80 0 0
183 25 79 0 0
183 25 78 0 0
183 25 77 0 0
183 25 76 0 0
183 25 75 0 0
183 25 74 0 0
183 25 73 0 0
183 25 72 0 0
183 25 71 0 0
183 25 70 0 0
183 25 69 0 0
183 25 68 0 0
183 25 67 0 0
183 25 66 0 64
183 26 93 0 40
183 26 92 0 8
183 26 91 0 8
183 26 90 0 8
183 26 89 0 8
183 26 88 0 8
183 26 87 0 0
183 26 86 0 0
183 26 85 0 0
183 26 84 0 0
183 26 83 0 0
183 26 82 0 0
183 26 81 0 0
183 26 80 0 0
183 26 79 0 0
183 26 78 0 0
183 26 77 0 0
183 26 76 0 0
183 26 75 0 0
183 26 74 0 0
183 26 73 0 0
183 26 72 0 0
183 26 71 0 0
183 26 70 0 0
183 26 69 0 0
183 26 68 0 0
183 26 67 0 0
183 26 66 0 64
183 27 87 0 44
183 27 86 0 8
183 27 85 0 0
183 27 84 0 0
183 27 83 0 0
183 27 82 0 0
183 27 81 0 0
183 27 80 0 0
183 27 79 0 8
183 27 78 0 8
183 27 77 0 0
183 27 76 0 0
183 27 75 0 0
183 27 74 0 0
183 27 73 0 0
183 27 72 0 0
183 27 71 0 0
183 27 70 0 0
183 27 69 0 0
183 27 68 0 0
183 27 67 0 0
183 27 66 0 64
183 28 85 0 44
183 28 84 0 12
183 28 83 0 8
183 28 82 0 8
183 28 81 0 12
183 28 80 0 76
183 28 77 0 40
183 28 76 0 0
183 28 75 0 0
183 28 74 0 0
183 28 73 0 0
183 28 72 0 0
183 28 71 0 0
183 28 70 0 0
183 28 69 0 0
183 28 68 0 0
183 28 67 0 0
183 28 66 0 72
183 29 76 0 40
183 29 75 0 0
183 29 74 0 0
183 29 73 0 0
183 29 72 0 0
183 29 71 0 0
183 29 70 0 0
183 29 69 0 0
183 29 68 0 0
183 29 67 0 72
183 30 75 0 42
183 30 74 0 8
183 30 73 0 8
183 30 72 0 8
183 30 71 0 8
183 30 70 0 8
183 30 69 0 8
183 30 68 0 74
184 3 84 21 62
184 3 83 21 22
184 3 82 21 16
184 3 81 21 16
184 3 80 21 16
184 3 79 21 16
184 3 78 21 20
184 3 77 21 94
184 4 83 21 46
184 4 82 21 6
184 4 81 21 2
184 4 80 21 0
184 4 79 21 2
184 4 78 21 78
184 5 82 21 38
184 5 81 21 2
184 5 80 21 0
184 5 79 21 66
184 6 82 21 46
184 6 81 21 2
184 6 80 21 0
184 6 79 21 66
184 7 81 21 34
184 7 80 21 0
184 7 79 21 78
184 8 81 21 34
184 8 80 21 66
184 9 81 21 34
184 9 80 21 66
184 10 81 21 38
184 10 80 21 64
184 11 81 21 34
184 11 80 21 64
184 12 81 21 46
184 12 80 21 0
184 12 79 21 86
184 13 83 21 54
184 13 82 21 94
184 13 80 21 34
184 13 79 21 14
184 13 78 21 22
184 13 77 21 30
184 13 76 21 86
184 14 84 21 54
184 14 83 21 78
184 14 80 21 98
184 14 78 21 102
184 14 76 21 102
184 15 85 21 54
184 15 84 21 70
184 15 80 21 98
184 15 78 0 34
184 15 77 0 16
184 15 76 0 0
184 15 75 0 16
184 15 74 0 16
184 15 73 0 84
184 16 85 21 38
184 16 84 0 4
184 16 83 0 16
184 16 82 0 16
184 16 81 0 16
184 16 80 0 0
184 16 79 0 16
184 16 78 0 0
184 16 77 0 0
184 16 76 0 0
184 16 75 0 0
184 16 74 0 0
184 16 73 0 0
184 16 72 0 16
184 16 71 0 84
184 17 85 0 32
184 17 84 0 0
184 17 83 0 0
184 17 82 0 0
184 17 81 0 0
184 17 80 0 0
184 17 79 0 0
184 17 78 0 0
184 17 77 0 0
184 17 76 0 0
184 17 75 0 0
184 17 74 0 0
184 17 73 0 0
184 17 72 0 0
184 17 71 0 0
184 17 70 0 80
184 18 90 0 48
184 18 89 0 16
184 18 88 0 16
184 18 87 0 16
184 18 86 0 16
184 18 85 0 0
184 18 84 0 0
184 18 83 0 0
184 18 82 0 0
184 18 81 0 0
184 18 80 0 0
184 18 79 0 0
184 18 78 0 0
184 18 77 0 0
184 18 76 0 0
184 18 75 0 0
184 18 74 0 0
184 18 73 0 0
184 18 72 0 0
184 18 71 0 0
184 18 70 0 0
184 18 69 0 80
184 19 93 0 50
184 19 92 0 16
184 19 91 0 16
184 19 90 0 0
184 19 89 0 0
184 19 88 0 0
184 19 87 0 0
184 19 86 0 0
184 19 85 0 0
184 19 84 0 0
184 19 83 0 0
184 19 82 0 0
184 19 81 0 0
184 19 80 0 0
184 19 79 0 0
184 19 78 0 0
184 19 77 0 0
184 19 76 0 0
184 19 75 0 0
184 19 74 0 0
184 19 73 0 0
184 19 72 0 0
184 19 71 0 0
184 19 70 0 0
184 19 69 0 0
184 19 68 0 16
184 19 67 0 88
184 20 95 0 48
184 20 94 0 16
184 20 93 0 0
184 20 92 0 0
184 20 91 0 0
184 20 90 0 0
184 20 89 0 0
184 20 88 0 0
184 20 87 0 0
184 20 86 0 0
184 20 85 0 0
184 20 84 0 0
184 20 83 0 0
184 20 82 0 0
184 20 81 0 0
184 20 80 0 0
184 20 79 0 0
184 20 78 0 0
184 20 77 0 0
184 20 76 0 0
184 20 75 0 0
184 20 74 0 0
184 20 73 0 0
184 20 72 0 0
184 20 71 0 0
184 20 70 0 0
184 20 69 0 0
184 20 68 0 64
184 21 96 0 48
184 21 95 0 0
184 21 94 0 0
184 21 93 0 0
184 21 92 0 0
184 21 91 0 0
184 21 90 0 0
184 21 89 0 0
184 21 88 0 0
184 21 87 0 0
184 21 86 0 0
184 21 85 0 0
184 21 84 0 0
184 21 83 0 0
184 21 82 0 0
184 21 81 0 0
184 21 80 0 0
184 21 79 0 0
184 21 78 0 0
184 21 77 0 0
184 21 76 0 0
184 21 75 0 0
184 21 74 0 0
184 21 73 0 0
184 21 72 0 0
184 21 71 0 0
184 21 70 0 0
184 21 69 0 0
184 21 68 0 0
184 21 67 0 80
184 22 96 0 32
184 22 95 0 0
184 22 94 0 0
184 22 93 0 0
184 22 92 0 0
184 22 91 0 0
184 22 90 0 0
184 22 89 0 0
184 22 88 0 0
184 22 87 0 0
184 22 86 0 0
184 22 85 0 0
184 22 84 0 0
184 22 83 0 0
184 22 82 0 0
184 22 81 0 0
184 22 80 0 0
184 22 79 0 0
184 22 78 0 0
184 22 77 0 0
184 22 76 0 0
184 22 75 0 0
184 22 74 0 0
184 22 73 0 0
184 22 72 0 0
184 22 71 0 0
184 22 70 0 0
184 22 69 0 0
184 22 68 0 0
184 22 67 0 64
184 23 96 0 32
184 23 95 0 0
184 23 94 0 0
184 23 93 0 0
184 23 92 0 0
184 23 91 0 0
184 23 90 0 0
184 23 89 0 0
184 23 88 0 0
184 23 87 0 0
184 23 86 0 0
184 23 85 0 0
184 23 84 0 0
184 23 83 0 0
184 23 82 0 0
184 23 81 0 0
184 23 80 0 0
184 23 79 0 0
184 23 78 0 0
184 23 77 0 0
184 23 76 0 0
184 23 75 0 0
184 23 74 0 0
184 23 73 0 0
184 23 72 0 0
184 23 71 0 0
184 23 70 0 0
184 23 69 0 0
184 23 68 0 0
184 23 67 0 0
184 23 66 0 82
184 24 96 0 40
184 24 95 0 0
184 24 94 0 0
184 24 93 0 0
184 24 92 0 0
184 24 91 0 0
184 24 90 0 0
184 24 89 0 0
184 24 88 0 0
184 24 87 0 0
184 24 86 0 0
184 24 85 0 0
184 24 84 0 0
184 24 83 0 0
184 24 82 0 0
184 24 81 0 0
184 24 80 0 0
184 24 79 0 0
184 24 78 0 0
184 24 77 0 0
184 24 76 0 0
184 24 75 0 0
184 24 74 0 0
184 24 73 0 0
184 24 72 0 0
184 24 71 0 0
184 24 70 0 0
184 24 69 0 0
184 24 68 0 0
184 24 67 0 0
184 24 66 0 64
184 25 95 0 40
184 25 94 0 8
184 25 93 0 0
184 25 92 0 0
184 25 91 0 0
184 25 90 0 0
184 25 89 0 0
184 25 88 0 0
184 25 87 0 0
184 25 86 0 0
184 25 85 0 0
184 25 84 0 0
184 25 83 0 0
184 25 82 0 0
184 25 81 0 0
184 25 80 0 0
184 25 79 0 0
184 25 78 0 0
184 25 77 0 0
184 25 76 0 0
184 25 75 0 0
184 25 74 0 0
184 25 73 0 0
184 25 72 0 0
184 25 71 0 0
184 25 70 0 0
184 25 69 0 0
184 25 68 0 0
184 25 67 0 0
184 25 66 0 64
184 26 93 0 42
184 26 92 0 8
184 26 91 0 8
184 26 90 0 8
184 26 89 0 8
184 26 88 0 8
184 26 87 0 0
184 26 86 0 0
184 26 85 0 0
184 26 84 0 0
184 26 83 0 0
184 26 82 0 0
184 26 81 0 0
184 26 80 0 0
184 26 79 0 0
184 26 78 0 0
184 26 77 0 0
184 26 76 0 0
184 26 75 0 0
184 26 74 0 0
184 26 73 0 0
184 26 72 0 0
184 26 71 0 0
184 26 70 0 0
184 26 69 0 0
184 26 68 0 0
184 26 67 0 0
184 26 66 0 64
184 27 87 0 40
184 27 86 0 8
184 27 85 0 0
184 27 84 0 0
184 27 83 0 0
184 27 82 0 0
184 27 81 0 0
184 27 80 0 0
184 27 79 0 8
184 27 78 0 8
184 27 77 0 0
184 27 76 0 0
184 27 75 0 0
184 27 74 0 0
184 27 73 0 0
184 27 72 0 0
184 27 71 0 0
184 27 70 0 0
184 27 69 0 0
184 27 68 0 0
184 27 67 0 0
184 27 66 0 64
184 28 85 0 40
184 28 84 0 8
184 28 83 0 8
184 28 82 0 8
184 28 81 0 8
184 28 80 0 72
184 28 77 0 42
184 28 76 0 0
184 28 75 0 0
184 28 74 0 0
184 28 73 0 0
184 28 72 0 0
184 28 71 0 0
184 28 70 0 0
184 28 69 0 0
184 28 68 0 0
184 28 67 0 0
184 28 66 0 74
184 29 76 0 42
184 29 75 0 8
184 29 74 0 0
184 29 73 0 0
184 29 72 0 0
184 29 71 0 0
184 29 70 0 0
184 29 69 0 0
184 29 68 0 8
184 29 67 0 74
184 30 74 0 40
184 30 73 0 8
184 30 72 0 8
184 30 71 0 8
184 30 70 0 8
184 30 69 0 72
185 3 82 21 58
185 3 81 21 24
185 3 80 21 16
185 3 79 21 24
185 3 78 21 88
185 4 80 21 98
185 5 80 21 98
185 6 80 21 98
185 7 80 21 106
185 10 80 21 114
185 11 80 21 98
185 12 80 21 104
185 15 77 0 50
185 15 76 0 16
185 15 75 0 16
185 15 74 0 16
185 15 73 0 82
185 16 84 0 50
185 16 83 0 16
185 16 82 0 16
185 16 81 0 16
185 16 80 0 16
185 16 79 0 16
185 16 78 0 16
185 16 77 0 0
185 16 76 0 0
185 16 75 0 0
185 16 74 0 0
185 16 73 0 0
185 16 72 0 16
185 16 71 0 82
185 17 85 0 48
185 17 84 0 0
185 17 83 0 0
185 17 82 0 0
185 17 81 0 0
185 17 80 0 0
185 17 79 0 0
185 17 78 0 0
185 17 77 0 0
185 17 76 0 0
185 17 75 0 0
185 17 74 0 0
185 17 73 0 0
185 17 72 0 0
185 17 71 0 0
185 17 70 0 80
185 18 90 0 48
185 18 89 0 16
185 18 88 0 16
185 18 87 0 16
185 18 86 0 16
185 18 85 0 0
185 18 84 0 0
185 18 83 0 0
185 18 82 0 0
185 18 81 0 0
185 18 80 0 0
185 18 79 0 0
185 18 78 0 0
185 18 77 0 0
185 18 76 0 0
185 18 75 0 0
185 18 74 0 0
185 18 73 0 0
185 18 72 0 0
185 18 71 0 0
185 18 70 0 0
185 18 69 0 80
185 19 92 0 48
185 19 91 0 16
185 19 90 0 0
185 19 89 0 0
185 19 88 0 0
185 19 87 0 0
185 19 86 0 0
185 19 85 0 0
185 19 84 0 0
185 19 83 0 0
185 19 82 0 0
185 19 81 0 0
185 19 80 0 0
185 19 79 0 0
185 19 78 0 0
185 19 77 0 0
185 19 76 0 0
185 19 75 0 0
185 19 74 0 0
185 19 73 0 0
185 19 72 0 0
185 19 71 0 0
185 19 70 0 0
185 19 69 0 0
185 19 68 0 16
185 19 67 0 88
185 20 95 0 50
185 20 94 0 16
185 20 93 0 16
185 20 92 0 0
185 20 91 0 0
185 20 90 0 0
185 20 89 0 0
185 20 88 0 0
185 20 87 0 0
185 20 86 0 0
185 20 85 0 0
185 20 84 0 0
185 20 83 0 0
185 20 82 0 0
185 20 81 0 0
185 20 80 0 0
185 20 79 0 0
185 20 78 0 0
185 20 77 0 0
185 20 76 0 0
185 20 75 0 0
185 20 74 0 0
185 20 73 0 0
185 20 72 0 0
185 20 71 0 0
185 20 70 0 0
185 20 69 0 0
185 20 68 0 64
185 21 96 0 50
185 21 95 0 0
185 21 94 0 0
185 21 93 0 0
185 21 92 0 0
185 21 91 0 0
185 21 90 0 0
185 21 89 0 0
185 21 88 0 0
185 21 87 0 0
185 21 86 0 0
185 21 85 0 0
185 21 84 0 0
185 21 83 0 0
185 21 82 0 0
185 21 81 0 0
185 21 80 0 0
185 21 79 0 0
185 21 78 0 0
185 21 77 0 0
185 21 76 0 0
185 21 75 0 0
185 21 74 0 0
185 21 73 0 0
185 21 72 0 0
185 21 71 0 0
185 21 70 0 0
185 21 69 0 0
185 21 68 0 0
185 21 67 0 80
185 22 96 0 32
185 22 95 0 0
185 22 94 0 0
185 22 93 0 0
185 22 92 0 0
185 22 91 0 0
185 22 90 0 0
185 22 89 0 0
185 22 88 0 0
185 22 87 0 0
185 22 86 0 0
185 22 85 0 0
185 22 84 0 0
185 22 83 0 0
185 22 82 0 0
185 22 81 0 0
185 22 80 0 0
185 22 79 0 0
185 22 78 0 0
185 22 77 0 0
185 22 76 0 0
185 22 75 0 0
185 22 74 0 0
185 22 73 0 0
185 22 72 0 0
185 22 71 0 0
185 22 70 0 0
185 22 69 0 0
185 22 68 0 0
185 22 67 0 64
185 23 96 0 32
185 23 95 0 0
185 23 94 0 0
185 23 93 0 0
185 23 92 0 0
185 23 91 0 0
185 23 90 0 0
185 23 89 0 0
185 23 88 0 0
185 23 87 0 0
185 23 86 0 0
185 23 85 0 0
185 23 84 0 0
185 23 83 0 0
185 23 82 0 0
185 23 81 0 0
185 23 80 0 0
185 23 79 0 0
185 23 78 0 0
185 23 77 0 0
185 23 76 0 0
185 23 75 0 0
185 23 74 0 0
185 23 73 0 0
185 23 72 0 0
185 23 71 0 0
185 23 70 0 0
185 23 69 0 0
185 23 68 0 0
185 23 67 0 64
185 24 96 0 42
185 24 95 0 0
185 24 94 0 0
185 24 93 0 0
185 24 92 0 0
185 24 91 0 0
185 24 90 0 0
185 24 89 0 0
185 24 88 0 0
185 24 87 0 0
185 24 86 0 0
185 24 85 0 0
185 24 84 0 0
185 24 83 0 0
185 24 82 0 0
185 24 81 0 0
185 24 80 0 0
185 24 79 0 0
185 24 78 0 0
185 24 77 0 0
185 24 76 0 0
185 24 75 0 0
185 24 74 0 0
185 24 73 0 0
185 24 72 0 0
185 24 71 0 0
185 24 70 0 0
185 24 69 0 0
185 24 68 0 0
185 24 67 0 0
185 24 66 0 82
185 25 95 0 42
185 25 94 0 8
185 25 93 0 8
185 25 92 0 0
185 25 91 0 0
185 25 90 0 0
185 25 89 0 0
185 25 88 0 0
185 25 87 0 0
185 25 86 0 0
185 25 85 0 0
185 25 84 0 0
185 25 83 0 0
185 25 82 0 0
185 25 81 0 0
185 25 80 0 0
185 25 79 0 0
185 25 78 0 0
185 25 77 0 0
185 25 76 0 0
185 25 75 0 0
185 25 74 0 0
185 25 73 0 0
185 25 72 0 0
185 25 71 0 0
185 25 70 0 0
185 25 69 0 0
185 25 68 0 0
185 25 67 0 0
185 25 66 0 66
185 26 92 0 40
185 26 91 0 8
185 26 90 0 8
185 26 89 0 8
185 26 88 0 8
185 26 87 0 0
185 26 86 0 0
185 26 85 0 0
185 26 84 0 0
185 26 83 0 0
185 26 82 0 0
185 26 81 0 0
185 26 80 0 0
185 26 79 0 0
185 26 78 0 0
185 26 77 0 0
185 26 76 0 0
185 26 75 0 0
185 26 74 0 0
185 26 73 0 0
185 26 72 0 0
185 26 71 0 0
185 26 70 0 0
185 26 69 0 0
185 26 68 0 0
185 26 67 0 0
185 26 66 0 66
185 27 87 0 40
185 27 86 0 0
185 27 85 0 0
185 27 84 0 0
185 27 83 0 0
185 27 82 0 0
185 27 81 0 0
185 27 80 0 0
185 27 79 0 0
185 27 78 0 8
185 27 77 0 8
185 27 76 0 0
185 27 75 0 0
185 27 74 0 0
185 27 73 0 0
185 27 72 0 0
185 27 71 0 0
185 27 70 0 0
185 27 69 0 0
185 27 68 0 0
185 27 67 0 0
185 27 66 0 74
185 28 86 0 44
185 28 85 0 8
185 28 84 0 8
185 28 83 0 8
185 28 82 0 8
185 28 81 0 8
185 28 80 0 8
185 28 79 0 76
185 28 76 0 40
185 28 75 0 0
185 28 74 0 0
185 28 73 0 0
185 28 72 0 0
185 28 71 0 0
185 28 70 0 0
185 28 69 0 0
185 28 68 0 0
185 28 67 0 72
185 29 75 0 40
185 29 74 0 0
185 29 73 0 0
185 29 72 0 0
185 29 71 0 0
185 29 70 0 0
185 29 69 0 0
185 29 68 0 72
185 30 74 0 42
185 30 73 0 10
185 30 72 0 8
185 30 71 0 8
185 30 70 0 10
185 30 69 0 74
186 3 81 21 58
186 3 80 21 24
186 3 79 21 24
186 3 78 21 90
186 12 80 21 114
186 13 80 21 108
186 15 76 0 50
186 15 75 0 18
186 15 74 0 82
186 16 83 0 50
186 16 82 0 16
186 16 81 0 16
186 16 80 0 16
186 16 79 0 16
186 16 78 0 16
186 16 77 0 16
186 16 76 0 0
186 16 75 0 0
186 16 74 0 0
186 16 73 0 16
186 16 72 0 82
186 17 85 0 50
186 17 84 0 18
186 17 83 0 0
186 17 82 0 0
186 17 81 0 0
186 17 80 0 0
186 17 79 0 0
186 17 78 0 0
186 17 77 0 0
186 17 76 0 0
186 17 75 0 0
186 17 74 0 0
186 17 73 0 0
186 17 72 0 0
186 17 71 0 18
186 17 70 0 82
186 18 90 0 50
186 18 89 0 16
186 18 88 0 16
186 18 87 0 16
186 18 86 0 16
186 18 85 0 0
186 18 84 0 0
186 18 83 0 0
186 18 82 0 0
186 18 81 0 0
186 18 80 0 0
186 18 79 0 0
186 18 78 0 0
186 18 77 0 0
186 18 76 0 0
186 18 75 0 0
186 18 74 0 0
186 18 73 0 0
186 18 72 0 0
186 18 71 0 0
186 18 70 0 0
186 18 69 0 82
186 19 92 0 50
186 19 91 0 16
186 19 90 0 0
186 19 89 0 0
186 19 88 0 0
186 19 87 0 0
186 19 86 0 0
186 19 85 0 0
186 19 84 0 0
186 19 83 0 0
186 19 82 0 0
186 19 81 0 0
186 19 80 0 0
186 19 79 0 0
186 19 78 0 0
186 19 77 0 0
186 19 76 0 0
186 19 75 0 0
186 19 74 0 0
186 19 73 0 0
186 19 72 0 0
186 19 71 0 0
186 19 70 0 0
186 19 69 0 0
186 19 68 0 16
186 19 67 0 90
186 20 94 0 48
186 20 93 0 16
186 20 92 0 0
186 20 91 0 0
186 20 90 0 0
186 20 89 0 0
186 20 88 0 0
186 20 87 0 0
186 20 86 0 0
186 20 85 0 0
186 20 84 0 0
186 20 83 0 0
186 20 82 0 0
186 20 81 0 0
186 20 80 0 0
186 20 79 0 0
186 20 78 0 0
186 20 77 0 0
186 20 76 0 0
186 20 75 0 0
186 20 74 0 0
186 20 73 0 0
186 20 72 0 0
186 20 71 0 0
186 20 70 0 0
186 20 69 0 0
186 20 68 0 66
186 21 95 0 48
186 21 94 0 0
186 21 93 0 0
186 21 92 0 0
186 21 91 0 0
186 21 90 0 0
186 21 89 0 0
186 21 88 0 0
186 21 87 0 0
186 21 86 0 0
186 21 85 0 0
186 21 84 0 0
186 21 83 0 0
186 21 82 0 0
186 21 81 0 0
186 21 80 0 0
186 21 79 0 0
186 21 78 0 0
186 21 77 0 0
186 21 76 0 0
186 21 75 0 0
186 21 74 0 0
186 21 73 0 0
186 21 72 0 0
186 21 71 0 0
186 21 70 0 0
186 21 69 0 0
186 21 68 0 0
186 21 67 0 82
186 22 96 0 48
186 22 95 0 0
186 22 94 0 0
186 22 93 0 0
186 22 92 0 0
186 22 91 0 0
186 22 90 0 0
186 22 89 0 0
186 22 88 0 0
186 22 87 0 0
186 22 86 0 0
186 22 85 0 0
186 22 84 0 0
186 22 83 0 0
186 22 82 0 0
186 22 81 0 0
186 22 80 0 0
186 22 79 0 0
186 22 78 0 0
186 22 77 0 0
186 22 76 0 0
186 22 75 0 0
186 22 74 0 0
186 22 73 0 0
186 22 72 0 0
186 22 71 0 0
186 22 70 0 0
186 22 69 0 0
186 22 68 0 0
186 22 67 0 66
186 23 96 0 40
186 23 95 0 0
186 23 94 0 0
186 23 93 0 0
186 23 92 0 0
186 23 91 0 0
186 23 90 0 0
186 23 89 0 0
186 23 88 0 0
186 23 87 0 0
186 23 86 0 0
186 23 85 0 0
186 23 84 0 0
186 23 83 0 0
186 23 82 0 0
186 23 81 0 0
186 23 80 0 0
186 23 79 0 0
186 23 78 0 0
186 23 77 0 0
186 23 76 0 0
186 23 75 0 0
186 23 74 0 0
186 23 73 0 0
186 23 72 0 0
186 23 71 0 0
186 23 70 0 0
186 23 69 0 0
186 23 68 0 0
186 23 67 0 66
186 24 95 0 40
186 24 94 0 0
186 24 93 0 0
186 24 92 0 0
186 24 91 0 0
186 24 90 0 0
186 24 89 0 0
186 24 88 0 0
186 24 87 0 0
186 24 86 0 0
186 24 85 0 0
186 24 84 0 0
186 24 83 0 0
186 24 82 0 0
186 24 81 0 0
186 24 80 0 0
186 24 79 0 0
186 24 78 0 0
186 24 77 0 0
186 24 76 0 0
186 24 75 0 0
186 24 74 0 0
186 24 73 0 0
186 24 72 0 0
186 24 71 0 0
186 24 70 0 0
186 24 69 0 0
186 24 68 0 0
186 24 67 0 66
186 25 94 0 40
186 25 93 0 8
186 25 92 0 0
186 25 91 0 0
186 25 90 0 0
186 25 89 0 0
186 25 88 0 0
186 25 87 0 0
186 25 86 0 0
186 25 85 0 0
186 25 84 0 0
186 25 83 0 0
186 25 82 0 0
186 25 81 0 0
186 25 80 0 0
186 25 79 0 0
186 25 78 0 0
186 25 77 0 0
186 25 76 0 0
186 25 75 0 0
186 25 74 0 0
186 25 73 0 0
186 25 72 0 0
186 25 71 0 0
186 25 70 0 0
186 25 69 0 0
186 25 68 0 0
186 25 67 0 64
186 26 92 0 42
186 26 91 0 8
186 26 90 0 8
186 26 89 0 8
186 26 88 0 8
186 26 87 0 0
186 26 86 0 0
186 26 85 0 0
186 26 84 0 0
186 26 83 0 0
186 26 82 0 0
186 26 81 0 0
186 26 80 0 0
186 26 79 0 0
186 26 78 0 0
186 26 77 0 0
186 26 76 0 0
186 26 75 0 0
186 26 74 0 0
186 26 73 0 0
186 26 72 0 0
186 26 71 0 0
186 26 70 0 0
186 26 69 0 0
186 26 68 0 0
186 26 67 0 64
186 27 87 0 40
186 27 86 0 0
186 27 85 0 0
186 27 84 0 0
186 27 83 0 0
186 27 82 0 0
186 27 81 0 0
186 27 80 0 0
186 27 79 0 0
186 27 78 0 8
186 27 77 0 0
186 27 76 0 0
186 27 75 0 0
186 27 74 0 0
186 27 73 0 0
186 27 72 0 0
186 27 71 0 0
186 27 70 0 0
186 27 69 0 0
186 27 68 0 0
186 27 67 0 66
186 28 86 0 42
186 28 85 0 8
186 28 84 0 8
186 28 83 0 8
186 28 82 0 8
186 28 81 0 8
186 28 80 0 8
186 28 79 0 74
186 28 77 0 46
186 28 76 0 10
186 28 75 0 0
186 28 74 0 0
186 28 73 0 0
186 28 72 0 0
186 28 71 0 0
186 28 70 0 0
186 28 69 0 0
186 28 68 0 0
186 28 67 0 74
186 29 75 0 42
186 29 74 0 10
186 29 73 0 8
186 29 72 0 0
186 29 71 0 0
186 29 70 0 8
186 29 69 0 10
186 29 68 0 74
186 30 72 0 42
186 30 71 0 74
187 3 80 21 56
187 3 79 21 90
187 13 80 21 114
187 14 80 21 102
187 15 80 21 100
187 16 82 0 50
187 16 81 0 18
187 16 80 0 0
187 16 79 0 18
187 16 78 0 18
187 16 77 0 18
187 16 76 0 18
187 16 75 0 18
187 16 74 0 18
187 16 73 0 82
187 17 83 0 50
187 17 82 0 2
187 17 81 0 0
187 17 80 0 0
187 17 79 0 0
187 17 78 0 0
187 17 77 0 0
187 17 76 0 0
187 17 75 0 0
187 17 74 0 0
187 17 73 0 2
187 17 72 0 82
187 18 89 0 48
187 18 88 0 16
187 18 87 0 16
187 18 86 0 16
187 18 85 0 16
187 18 84 0 16
187 18 83 0 0
187 18 82 0 0
187 18 81 0 0
187 18 80 0 0
187 18 79 0 0
187 18 78 0 0
187 18 77 0 0
187 18 76 0 0
187 18 75 0 0
187 18 74 0 0
187 18 73 0 0
187 18 72 0 0
187 18 71 0 18
187 18 70 0 82
187 19 91 0 50
187 19 90 0 16
187 19 89 0 0
187 19 88 0 0
187 19 87 0 0
187 19 86 0 0
187 19 85 0 0
187 19 84 0 0
187 19 83 0 0
187 19 82 0 0
187 19 81 0 0
187 19 80 0 0
187 19 79 0 0
187 19 78 0 0
187 19 77 0 0
187 19 76 0 0
187 19 75 0 0
187 19 74 0 0
187 19 73 0 0
187 19 72 0 0
187 19 71 0 0
187 19 70 0 0
187 19 69 0 18
187 19 68 0 90
187 20 94 0 50
187 20 93 0 16
187 20 92 0 16
187 20 91 0 0
187 20 90 0 0
187 20 89 0 0
187 20 88 0 0
187 20 87 0 0
187 20 86 0 0
187 20 85 0 0
187 20 84 0 0
187 20 83 0 0
187 20 82 0 0
187 20 81 0 0
187 20 80 0 0
187 20 79 0 0
187 20 78 0 0
187 20 77 0 0
187 20 76 0 0
187 20 75 0 0
187 20 74 0 0
187 20 73 0 0
187 20 72 0 0
187 20 71 0 0
187 20 70 0 0
187 20 69 0 66
187 21 95 0 50
187 21 94 0 0
187 21 93 0 0
187 21 92 0 0
187 21 91 0 0
187 21 90 0 0
187 21 89 0 0
187 21 88 0 0
187 21 87 0 0
187 21 86 0 0
187 21 85 0 0
187 21 84 0 0
187 21 83 0 0
187 21 82 0 0
187 21 81 0 0
187 21 80 0 0
187 21 79 0 0
187 21 78 0 0
187 21 77 0 0
187 21 76 0 0
187 21 75 0 0
187 21 74 0 0
187 21 73 0 0
187 21 72 0 0
187 21 71 0 0
187 21 70 0 0
187 21 69 0 0
187 21 68 0 82
187 22 96 0 50
187 22 95 0 0
187 22 94 0 0
187 22 93 0 0
187 22 92 0 0
187 22 91 0 0
187 22 90 0 0
187 22 89 0 0
187 22 88 0 0
187 22 87 0 0
187 22 86 0 0
187 22 85 0 0
187 22 84 0 0
187 22 83 0 0
187 22 82 0 0
187 22 81 0 0
187 22 80 0 0
187 22 79 0 0
187 22 78 0 0
187 22 77 0 0
187 22 76 0 0
187 22 75 0 0
187 22 74 0 0
187 22 73 0 0
187 22 72 0 0
187 22 71 0 0
187 22 70 0 0
187 22 69 0 0
187 22 68 0 64
187 23 96 0 42
187 23 95 0 0
187 23 94 0 0
187 23 93 0 0
187 23 92 0 0
187 23 91 0 0
187 23 90 0 0
187 23 89 0 0
187 23 88 0 0
187 23 87 0 0
187 23 86 0 0
187 23 85 0 0
187 23 84 0 0
187 23 83 0 0
187 23 82 0 0
187 23 81 0 0
187 23 80 0 0
187 23 79 0 0
187 23 78 0 0
187 23 77 0 0
187 23 76 0 0
187 23 75 0 0
187 23 74 0 0
187 23 73 0 0
187 23 72 0 0
187 23 71 0 0
187 23 70 0 0
187 23 69 0 0
187 23 68 0 64
187 24 95 0 42
187 24 94 0 0
187 24 93 0 0
187 24 92 0 0
187 24 91 0 0
187 24 90 0 0
187 24 89 0 0
187 24 88 0 0
187 24 87 0 0
187 24 86 0 0
187 24 85 0 0
187 24 84 0 0
187 24 83 0 0
187 24 82 0 0
187 24 81 0 0
187 24 80 0 0
187 24 79 0 0
187 24 78 0 0
187 24 77 0 0
187 24 76 0 0
187 24 75 0 0
187 24 74 0 0
187 24 73 0 0
187 24 72 0 0
187 24 71 0 0
187 24 70 0 0
187 24 69 0 0
187 24 68 0 64
187 25 94 0 42
187 25 93 0 8
187 25 92 0 8
187 25 91 0 0
187 25 90 0 0
187 25 89 0 0
187 25 88 0 0
187 25 87 0 0
187 25 86 0 0
187 25 85 0 0
187 25 84 0 0
187 25 83 0 0
187 25 82 0 0
187 25 81 0 0
187 25 80 0 0
187 25 79 0 0
187 25 78 0 0
187 25 77 0 0
187 25 76 0 0
187 25 75 0 0
187 25 74 0 0
187 25 73 0 0
187 25 72 0 0
187 25 71 0 0
187 25 70 0 0
187 25 69 0 0
187 25 68 0 2
187 25 67 0 82
187 26 91 0 42
187 26 90 0 8
187 26 89 0 8
187 26 88 0 8
187 26 87 0 0
187 26 86 0 0
187 26 85 0 0
187 26 84 0 0
187 26 83 0 0
187 26 82 0 0
187 26 81 0 0
187 26 80 0 0
187 26 79 0 0
187 26 78 0 0
187 26 77 0 0
187 26 76 0 0
187 26 75 0 0
187 26 74 0 0
187 26 73 0 0
187 26 72 0 0
187 26 71 0 0
187 26 70 0 0
187 26 69 0 0
187 26 68 0 2
187 26 67 0 74
187 27 87 0 42
187 27 86 0 8
187 27 85 0 0
187 27 84 0 0
187 27 83 0 0
187 27 82 0 0
187 27 81 0 0
187 27 80 0 0
187 27 79 0 8
187 27 78 0 8
187 27 77 0 8
187 27 76 0 8
187 27 75 0 0
187 27 74 0 0
187 27 73 0 0
187 27 72 0 0
187 27 71 0 0
187 27 70 0 0
187 27 69 0 0
187 27 68 0 66
187 28 85 0 40
187 28 84 0 8
187 28 83 0 8
187 28 82 0 8
187 28 81 0 8
187 28 80 0 72
187 28 75 0 42
187 28 74 0 10
187 28 73 0 0
187 28 72 0 0
187 28 71 0 0
187 28 70 0 0
187 28 69 0 10
187 28 68 0 74
187 29 73 0 42
187 29 72 0 10
187 29 71 0 10
187 29 70 0 74
188 3 80 21 122
188 15 80 21 114
188 16 80 21 96
188 17 81 0 50
188 17 80 0 0
188 17 79 0 18
188 17 78 0 18
188 17 77 0 18
188 17 76 0 18
188 17 75 0 18
188 17 74 0 82
188 18 89 0 50
188 18 88 0 16
188 18 87 0 16
188 18 86 0 16
188 18 85 0 16
188 18 84 0 16
188 18 83 0 16
188 18 82 0 16
188 18 81 0 0
188 18 80 0 0
188 18 79 0 0
188 18 78 0 2
188 18 77 0 2
188 18 76 0 2
188 18 75 0 2
188 18 74 0 2
188 18 73 0 18
188 18 72 0 82
188 19 90 0 50
188 19 89 0 2
188 19 88 0 0
188 19 87 0 0
188 19 86 0 0
188 19 85 0 0
188 19 84 0 0
188 19 83 0 0
188 19 82 0 0
188 19 81 0 0
188 19 80 0 0
188 19 79 0 0
188 19 78 0 0
188 19 77 0 0
188 19 76 0 0
188 19 75 0 0
188 19 74 0 0
188 19 73 0 0
188 19 72 0 0
188 19 71 0 18
188 19 70 0 82
188 20 93 0 50
188 20 92 0 16
188 20 91 0 16
188 20 90 0 0
188 20 89 0 0
188 20 88 0 0
188 20 87 0 0
188 20 86 0 0
188 20 85 0 0
188 20 84 0 0
188 20 83 0 0
188 20 82 0 0
188 20 81 0 0
188 20 80 0 0
188 20 79 0 0
188 20 78 0 0
188 20 77 0 0
188 20 76 0 0
188 20 75 0 0
188 20 74 0 0
188 20 73 0 0
188 20 72 0 0
188 20 71 0 0
188 20 70 0 64
188 21 94 0 48
188 21 93 0 0
188 21 92 0 0
188 21 91 0 0
188 21 90 0 0
188 21 89 0 0
188 21 88 0 0
188 21 87 0 0
188 21 86 0 0
188 21 85 0 0
188 21 84 0 0
188 21 83 0 0
188 21 82 0 0
188 21 81 0 0
188 21 80 0 0
188 21 79 0 0
188 21 78 0 0
188 21 77 0 0
188 21 76 0 0
188 21 75 0 0
188 21 74 0 0
188 21 73 0 0
188 21 72 0 0
188 21 71 0 0
188 21 70 0 0
188 21 69 0 80
188 22 95 0 50
188 22 94 0 0
188 22 93 0 0
188 22 92 0 0
188 22 91 0 0
188 22 90 0 0
188 22 89 0 0
188 22 88 0 0
188 22 87 0 0
188 22 86 0 0
188 22 85 0 0
188 22 84 0 0
188 22 83 0 0
188 22 82 0 0
188 22 81 0 0
188 22 80 0 0
188 22 79 0 0
188 22 78 0 0
188 22 77 0 0
188 22 76 0 0
188 22 75 0 0
188 22 74 0 0
188 22 73 0 0
188 22 72 0 0
188 22 71 0 0
188 22 70 0 0
188 22 69 0 0
188 22 68 0 80
188 23 95 0 42
188 23 94 0 0
188 23 93 0 0
188 23 92 0 0
188 23 91 0 0
188 23 90 0 0
188 23 89 0 0
188 23 88 0 0
188 23 87 0 0
188 23 86 0 0
188 23 85 0 0
188 23 84 0 0
188 23 83 0 0
188 23 82 0 0
188 23 81 0 0
188 23 80 0 0
188 23 79 0 0
188 23 78 0 0
188 23 77 0 0
188 23 76 0 0
188 23 75 0 0
188 23 74 0 0
188 23 73 0 0
188 23 72 0 0
188 23 71 0 0
188 23 70 0 0
188 23 69 0 0
188 23 68 0 64
188 24 94 0 40
188 24 93 0 0
188 24 92 0 0
188 24 91 0 0
188 24 90 0 0
188 24 89 0 0
188 24 88 0 0
188 24 87 0 0
188 24 86 0 0
188 24 85 0 0
188 24 84 0 0
188 24 83 0 0
188 24 82 0 0
188 24 81 0 0
188 24 80 0 0
188 24 79 0 0
188 24 78 0 0
188 24 77 0 0
188 24 76 0 0
188 24 75 0 0
188 24 74 0 0
188 24 73 0 0
188 24 72 0 0
188 24 71 0 0
188 24 70 0 0
188 24 69 0 0
188 24 68 0 72
188 25 93 0 42
188 25 92 0 8
188 25 91 0 8
188 25 90 0 0
188 25 89 0 0
188 25 88 0 0
188 25 87 0 0
188 25 86 0 0
188 25 85 0 0
188 25 84 0 0
188 25 83 0 0
188 25 82 0 0
188 25 81 0 0
188 25 80 0 0
188 25 79 0 0
188 25 78 0 0
188 25 77 0 0
188 25 76 0 0
188 25 75 0 0
188 25 74 0 0
188 25 73 0 0
188 25 72 0 0
188 25 71 0 0
188 25 70 0 0
188 25 69 0 64
188 26 90 0 42
188 26 89 0 10
188 26 88 0 8
188 26 87 0 8
188 26 86 0 0
188 26 85 0 0
188 26 84 0 0
188 26 83 0 0
188 26 82 0 0
188 26 81 0 0
188 26 80 0 0
188 26 79 0 0
188 26 78 0 0
188 26 77 0 0
188 26 76 0 0
188 26 75 0 0
188 26 74 0 0
188 26 73 0 0
188 26 72 0 0
188 26 71 0 0
188 26 70 0 0
188 26 69 0 66
188 27 86 0 40
188 27 85 0 0
188 27 84 0 0
188 27 83 0 0
188 27 82 0 0
188 27 81 0 0
188 27 80 0 0
188 27 79 0 8
188 27 78 0 8
188 27 77 0 8
188 27 76 0 8
188 27 75 0 8
188 27 74 0 8
188 27 73 0 0
188 27 72 0 0
188 27 71 0 2
188 27 70 0 2
188 27 69 0 74
188 28 85 0 42
188 28 84 0 10
188 28 83 0 8
188 28 82 0 8
188 28 81 0 10
188 28 80 0 74
188 28 73 0 42
188 28 72 0 10
188 28 71 0 10
188 28 70 0 74
189 16 80 21 114
189 17 80 21 98
189 18 88 0 50
189 18 87 0 16
189 18 86 0 16
189 18 85 0 16
189 18 84 0 16
189 18 83 0 16
189 18 82 0 16
189 18 81 0 16
189 18 80 0 2
189 18 79 0 82
189 19 88 0 34
189 19 87 0 0
189 19 86 0 0
189 19 85 0 0
189 19 84 0 0
189 19 83 0 0
189 19 82 0 0
189 19 81 0 0
189 19 80 0 0
189 19 79 0 0
189 19 78 0 16
189 19 77 0 16
189 19 76 0 16
189 19 75 0 16
189 19 74 0 16
189 19 73 0 16
189 19 72 0 82
189 20 92 0 50
189 20 91 0 16
189 20 90 0 16
189 20 89 0 16
189 20 88 0 0
189 20 87 0 0
189 20 86 0 0
189 20 85 0 0
189 20 84 0 0
189 20 83 0 0
189 20 82 0 0
189 20 81 0 0
189 20 80 0 0
189 20 79 0 0
189 20 78 0 0
189 20 77 0 0
189 20 76 0 0
189 20 75 0 0
189 20 74 0 0
189 20 73 0 0
189 20 72 0 0
189 20 71 0 16
189 20 70 0 82
189 21 94 0 50
189 21 93 0 16
189 21 92 0 0
189 21 91 0 0
189 21 90 0 0
189 21 89 0 0
189 21 88 0 0
189 21 87 0 0
189 21 86 0 0
189 21 85 0 0
189 21 84 0 0
189 21 83 0 0
189 21 82 0 0
189 21 81 0 0
189 21 80 0 0
189 21 79 0 0
189 21 78 0 0
189 21 77 0 0
189 21 76 0 0
189 21 75 0 0
189 21 74 0 0
189 21 73 0 0
189 21 72 0 0
189 21 71 0 0
189 21 70 0 0
189 21 69 0 80
189 22 94 0 32
189 22 93 0 0
189 22 92 0 0
189 22 91 0 0
189 22 90 0 0
189 22 89 0 0
189 22 88 0 0
189 22 87 0 0
189 22 86 0 0
189 22 85 0 0
189 22 84 0 0
189 22 83 0 0
189 22 82 0 0
189 22 81 0 0
189 22 80 0 0
189 22 79 0 0
189 22 78 0 0
189 22 77 0 0
189 22 76 0 0
189 22 75 0 0
189 22 74 0 0
189 22 73 0 0
189 22 72 0 0
189 22 71 0 0
189 22 70 0 0
189 22 69 0 0
189 22 68 0 82
189 23 94 0 32
189 23 93 0 0
189 23 92 0 0
189 23 91 0 0
189 23 90 0 0
189 23 89 0 0
189 23 88 0 0
189 23 87 0 0
189 23 86 0 0
189 23 85 0 0
189 23 84 0 0
189 23 83 0 0
189 23 82 0 0
189 23 81 0 0
189 23 80 0 0
189 23 79 0 0
189 23 78 0 0
189 23 77 0 0
189 23 76 0 0
189 23 75 0 0
189 23 74 0 0
189 23 73 0 0
189 23 72 0 0
189 23 71 0 0
189 23 70 0 0
189 23 69 0 0
189 23 68 0 64
189 24 94 0 42
189 24 93 0 8
189 24 92 0 0
189 24 91 0 0
189 24 90 0 0
189 24 89 0 0
189 24 88 0 0
189 24 87 0 0
189 24 86 0 0
189 24 85 0 0
189 24 84 0 0
189 24 83 0 0
189 24 82 0 0
189 24 81 0 0
189 24 80 0 0
189 24 79 0 0
189 24 78 0 0
189 24 77 0 0
189 24 76 0 0
189 24 75 0 0
189 24 74 0 0
189 24 73 0 0
189 24 72 0 0
189 24 71 0 0
189 24 70 0 0
189 24 69 0 0
189 24 68 0 74
189 25 92 0 42
189 25 91 0 8
189 25 90 0 8
189 25 89 0 8
189 25 88 0 0
189 25 87 0 0
189 25 86 0 0
189 25 85 0 0
189 25 84 0 0
189 25 83 0 0
189 25 82 0 0
189 25 81 0 0
189 25 80 0 0
189 25 79 0 0
189 25 78 0 0
189 25 77 0 0
189 25 76 0 0
189 25 75 0 0
189 25 74 0 0
189 25 73 0 0
189 25 72 0 0
189 25 71 0 0
189 25 70 0 0
189 25 69 0 72
189 26 88 0 42
189 26 87 0 10
189 26 86 0 0
189 26 85 0 0
189 26 84 0 0
189 26 83 0 0
189 26 82 0 0
189 26 81 0 0
189 26 80 0 0
189 26 79 0 0
189 26 78 0 0
189 26 77 0 0
189 26 76 0 0
189 26 75 0 0
189 26 74 0 0
189 26 73 0 0
189 26 72 0 0
189 26 71 0 8
189 26 70 0 74
189 27 86 0 42
189 27 85 0 10
189 27 84 0 8
189 27 83 0 0
189 27 82 0 0
189 27 81 0 8
189 27 80 0 8
189 27 79 0 8
189 27 78 0 8
189 27 77 0 8
189 27 76 0 8
189 27 75 0 8
189 27 74 0 8
189 27 73 0 8
189 27 72 0 74
189 28 83 0 42
189 28 82 0 74
190 18 87 0 50
190 18 86 0 18
190 18 85 0 16
190 18 84 0 16
190 18 83 0 16
190 18 82 0 16
190 18 81 0 80
190 19 87 0 34
190 19 86 0 2
190 19 85 0 0
190 19 84 0 0
190 19 83 0 0
190 19 82 0 0
190 19 81 0 0
190 19 80 0 16
190 19 79 0 16
190 19 78 0 16
190 19 77 0 16
190 19 76 0 16
190 19 75 0 16
190 19 74 0 16
190 19 73 0 82
190 20 91 0 50
190 20 90 0 18
190 20 89 0 16
190 20 88 0 16
190 20 87 0 0
190 20 86 0 0
190 20 85 0 0
190 20 84 0 0
190 20 83 0 0
190 20 82 0 0
190 20 81 0 0
190 20 80 0 0
190 20 79 0 0
190 20 78 0 0
190 20 77 0 0
190 20 76 0 0
190 20 75 0 0
190 20 74 0 0
190 20 73 0 0
190 20 72 0 16
190 20 71 0 80
190 21 93 0 50
190 21 92 0 18
190 21 91 0 0
190 21 90 0 0
190 21 89 0 0
190 21 88 0 0
190 21 87 0 0
190 21 86 0 0
190 21 85 0 0
190 21 84 0 0
190 21 83 0 0
190 21 82 0 0
190 21 81 0 0
190 21 80 0 0
190 21 79 0 0
190 21 78 0 0
190 21 77 0 0
190 21 76 0 0
190 21 75 0 0
190 21 74 0 0
190 21 73 0 0
190 21 72 0 0
190 21 71 0 0
190 21 70 0 16
190 21 69 0 82
190 22 94 0 50
190 22 93 0 2
190 22 92 0 0
190 22 91 0 0
190 22 90 0 0
190 22 89 0 0
190 22 88 0 0
190 22 87 0 0
190 22 86 0 0
190 22 85 0 0
190 22 84 0 0
190 22 83 0 0
190 22 82 0 0
190 22 81 0 0
190 22 80 0 0
190 22 79 0 0
190 22 78 0 0
190 22 77 0 0
190 22 76 0 0
190 22 75 0 0
190 22 74 0 0
190 22 73 0 0
190 22 72 0 0
190 22 71 0 0
190 22 70 0 0
190 22 69 0 64
190 23 94 0 42
190 23 93 0 2
190 23 92 0 0
190 23 91 0 0
190 23 90 0 0
190 23 89 0 0
190 23 88 0 0
190 23 87 0 0
190 23 86 0 0
190 23 85 0 0
190 23 84 0 0
190 23 83 0 0
190 23 82 0 0
190 23 81 0 0
190 23 80 0 0
190 23 79 0 0
190 23 78 0 0
190 23 77 0 0
190 23 76 0 0
190 23 75 0 0
190 23 74 0 0
190 23 73 0 0
190 23 72 0 0
190 23 71 0 0
190 23 70 0 0
190 23 69 0 0
190 23 68 0 90
190 24 93 0 42
190 24 92 0 10
190 24 91 0 0
190 24 90 0 0
190 24 89 0 0
190 24 88 0 0
190 24 87 0 0
190 24 86 0 0
190 24 85 0 0
190 24 84 0 0
190 24 83 0 0
190 24 82 0 0
190 24 81 0 0
190 24 80 0 0
190 24 79 0 0
190 24 78 0 0
190 24 77 0 0
190 24 76 0 0
190 24 75 0 0
190 24 74 0 0
190 24 73 0 0
190 24 72 0 0
190 24 71 0 0
190 24 70 0 0
190 24 69 0 64
190 25 91 0 42
190 25 90 0 10
190 25 89 0 8
190 25 88 0 8
190 25 87 0 8
190 25 86 0 0
190 25 85 0 0
190 25 84 0 0
190 25 83 0 0
190 25 82 0 0
190 25 81 0 0
190 25 80 0 0
190 25 79 0 0
190 25 78 0 0
190 25 77 0 0
190 25 76 0 0
190 25 75 0 0
190 25 74 0 0
190 25 73 0 0
190 25 72 0 0
190 25 71 0 0
190 25 70 0 8
190 25 69 0 74
190 26 86 0 42
190 26 85 0 10
190 26 84 0 0
190 26 83 0 0
190 26 82 0 0
190 26 81 0 0
190 26 80 0 0
190 26 79 0 0
190 26 78 0 0
190 26 77 0 0
190 26 76 0 0
190 26 75 0 0
190 26 74 0 0
190 26 73 0 0
190 26 72 0 8
190 26 71 0 72
190 27 84 0 42
190 27 83 0 10
190 27 82 0 10
190 27 81 0 10
190 27 80 0 8
190 27 79 0 8
190 27 78 0 8
190 27 77 0 8
190 27 76 0 8
190 27 75 0 8
190 27 74 0 8
190 27 73 0 74
191 18 85 0 50
191 18 84 0 18
191 18 83 0 18
191 18 82 0 18
191 18 81 0 82
191 19 85 0 34
191 19 84 0 2
191 19 83 0 2
191 19 82 0 2
191 19 81 0 2
191 19 80 0 18
191 19 79 0 18
191 19 78 0 18
191 19 77 0 16
191 19 76 0 18
191 19 75 0 18
191 19 74 0 82
191 20 89 0 50
191 20 88 0 18
191 20 87 0 18
191 20 86 0 16
191 20 85 0 0
191 20 84 0 0
191 20 83 0 0
191 20 82 0 0
191 20 81 0 0
191 20 80 0 0
191 20 79 0 0
191 20 78 0 0
191 20 77 0 0
191 20 76 0 0
191 20 75 0 0
191 20 74 0 0
191 20 73 0 16
191 20 72 0 16
191 20 71 0 82
191 21 91 0 50
191 21 90 0 18
191 21 89 0 0
191 21 88 0 0
191 21 87 0 0
191 21 86 0 0
191 21 85 0 0
191 21 84 0 0
191 21 83 0 0
191 21 82 0 0
191 21 81 0 0
191 21 80 0 0
191 21 79 0 0
191 21 78 0 0
191 21 77 0 0
191 21 76 0 0
191 21 75 0 0
191 21 74 0 0
191 21 73 0 0
191 21 72 0 0
191 21 71 0 0
191 21 70 0 82
191 22 92 0 50
191 22 91 0 0
191 22 90 0 0
191 22 89 0 0
191 22 88 0 0
191 22 87 0 0
191 22 86 0 0
191 22 85 0 0
191 22 84 0 0
191 22 83 0 0
191 22 82 0 0
191 22 81 0 0
191 22 80 0 0
191 22 79 0 0
191 22 78 0 0
191 22 77 0 0
191 22 76 0 0
191 22 75 0 0
191 22 74 0 0
191 22 73 0 0
191 22 72 0 0
191 22 71 0 0
191 22 70 0 0
191 22 69 0 82
191 23 92 0 42
191 23 91 0 0
191 23 90 0 0
191 23 89 0 0
191 23 88 0 0
191 23 87 0 0
191 23 86 0 0
191 23 85 0 0
191 23 84 0 0
191 23 83 0 0
191 23 82 0 0
191 23 81 0 0
191 23 80 0 0
191 23 79 0 0
191 23 78 0 0
191 23 77 0 0
191 23 76 0 0
191 23 75 0 0
191 23 74 0 0
191 23 73 0 0
191 23 72 0 0
191 23 71 0 0
191 23 70 0 0
191 23 69 0 64
191 24 91 0 42
191 24 90 0 10
191 24 89 0 0
191 24 88 0 0
191 24 87 0 0
191 24 86 0 0
191 24 85 0 0
191 24 84 0 0
191 24 83 0 0
191 24 82 0 0
191 24 81 0 0
191 24 80 0 0
191 24 79 0 0
191 24 78 0 0
191 24 77 0 0
191 24 76 0 0
191 24 75 0 0
191 24 74 0 0
191 24 73 0 0
191 24 72 0 0
191 24 71 0 0
191 24 70 0 0
191 24 69 0 74
191 25 89 0 42
191 25 88 0 10
191 25 87 0 10
191 25 86 0 8
191 25 85 0 8
191 25 84 0 0
191 25 83 0 0
191 25 82 0 0
191 25 81 0 0
191 25 80 0 0
191 25 79 0 0
191 25 78 0 0
191 25 77 0 0
191 25 76 0 0
191 25 75 0 0
191 25 74 0 0
191 25 73 0 0
191 25 72 0 0
191 25 71 0 0
191 25 70 0 74
191 26 84 0 42
191 26 83 0 10
191 26 82 0 8
191 26 81 0 8
191 26 80 0 0
191 26 79 0 0
191 26 78 0 0
191 26 77 0 0
191 26 76 0 0
191 26 75 0 0
191 26 74 0 0
191 26 73 0 8
191 26 72 0 8
191 26 71 0 74
191 27 80 0 42
191 27 79 0 10
191 27 78 0 10
191 27 77 0 8
191 27 76 0 10
191 27 75 0 10
191 27 74 0 74
192 19 77 0 114
192 20 86 0 50
192 20 85 0 18
192 20 84 0 18
192 20 83 0 18
192 20 82 0 18
192 20 81 0 18
192 20 80 0 16
192 20 79 0 16
192 20 78 0 16
192 20 77 0 0
192 20 76 0 16
192 20 75 0 16
192 20 74 0 16
192 20 73 0 18
192 20 72 0 82
192 21 89 0 50
192 21 88 0 18
192 21 87 0 18
192 21 86 0 2
192 21 85 0 0
192 21 84 0 0
192 21 83 0 0
192 21 82 0 0
192 21 81 0 0
192 21 80 0 0
192 21 79 0 0
192 21 78 0 0
192 21 77 0 0
192 21 76 0 0
192 21 75 0 0
192 21 74 0 0
192 21 73 0 0
192 21 72 0 0
192 21 71 0 82
192 22 91 0 50
192 22 90 0 18
192 22 89 0 2
192 22 88 0 2
192 22 87 0 2
192 22 86 0 0
192 22 85 0 0
192 22 84 0 0
192 22 83 0 0
192 22 82 0 0
192 22 81 0 0
192 22 80 0 0
192 22 79 0 0
192 22 78 0 0
192 22 77 0 0
192 22 76 0 0
192 22 75 0 0
192 22 74 0 0
192 22 73 0 0
192 22 72 0 0
192 22 71 0 0
192 22 70 0 82
192 23 91 0 42
192 23 90 0 10
192 23 89 0 2
192 23 88 0 2
192 23 87 0 2
192 23 86 0 0
192 23 85 0 0
192 23 84 0 0
192 23 83 0 0
192 23 82 0 0
192 23 81 0 0
192 23 80 0 0
192 23 79 0 0
192 23 78 0 0
192 23 77 0 0
192 23 76 0 0
192 23 75 0 0
192 23 74 0 0
192 23 73 0 0
192 23 72 0 0
192 23 71 0 0
192 23 70 0 0
192 23 69 0 90
192 24 89 0 42
192 24 88 0 10
192 24 87 0 10
192 24 86 0 2
192 24 85 0 0
192 24 84 0 0
192 24 83 0 0
192 24 82 0 0
192 24 81 0 0
192 24 80 0 0
192 24 79 0 0
192 24 78 0 0
192 24 77 0 0
192 24 76 0 0
192 24 75 0 0
192 24 74 0 0
192 24 73 0 0
192 24 72 0 0
192 24 71 0 0
192 24 70 0 74
192 25 86 0 42
192 25 85 0 10
192 25 84 0 10
192 25 83 0 10
192 25 82 0 0
192 25 81 0 0
192 25 80 0 0
192 25 79 0 0
192 25 78 0 0
192 25 77 0 0
192 25 76 0 0
192 25 75 0 0
192 25 74 0 0
192 25 73 0 0
192 25 72 0 0
192 25 71 0 74
192 26 82 0 42
192 26 81 0 10
192 26 80 0 8
192 26 79 0 8
192 26 78 0 8
192 26 77 0 0
192 26 76 0 8
192 26 75 0 8
192 26 74 0 8
192 26 73 0 10
192 26 72 0 74
192 27 77 0 106
193 20 80 0 50
193 20 79 0 18
193 20 78 0 18
193 20 77 0 16
193 20 76 0 18
193 20 75 0 18
193 20 74 0 82
193 21 85 0 50
193 21 84 0 18
193 21 83 0 18
193 21 82 0 18
193 21 81 0 16
193 21 80 0 0
193 21 79 0 0
193 21 78 0 0
193 21 77 0 0
193 21 76 0 0
193 21 75 0 0
193 21 74 0 0
193 21 73 0 16
193 21 72 0 82
193 22 86 0 50
193 22 85 0 2
193 22 84 0 2
193 22 83 0 2
193 22 82 0 0
193 22 81 0 0
193 22 80 0 0
193 22 79 0 0
193 22 78 0 0
193 22 77 0 0
193 22 76 0 0
193 22 75 0 0
193 22 74 0 0
193 22 73 0 0
193 22 72 0 0
193 22 71 0 82
193 23 86 0 42
193 23 85 0 2
193 23 84 0 2
193 23 83 0 0
193 23 82 0 0
193 23 81 0 0
193 23 80 0 0
193 23 79 0 0
193 23 78 0 0
193 23 77 0 0
193 23 76 0 0
193 23 75 0 0
193 23 74 0 0
193 23 73 0 0
193 23 72 0 0
193 23 71 0 0
193 23 70 0 90
193 24 85 0 42
193 24 84 0 10
193 24 83 0 10
193 24 82 0 0
193 24 81 0 0
193 24 80 0 0
193 24 79 0 0
193 24 78 0 0
193 24 77 0 0
193 24 76 0 0
193 24 75 0 0
193 24 74 0 0
193 24 73 0 0
193 24 72 0 0
193 24 71 0 74
193 25 82 0 42
193 25 81 0 8
193 25 80 0 0
193 25 79 0 0
193 25 78 0 0
193 25 77 0 0
193 25 76 0 0
193 25 75 0 0
193 25 74 0 0
193 25 73 0 8
193 25 72 0 74
193 26 80 0 42
193 26 79 0 10
193 26 78 0 10
193 26 77 0 8
193 26 76 0 10
193 26 75 0 10
193 26 74 0 74
194 20 77 0 114
194 21 81 0 50
194 21 80 0 18
194 21 79 0 18
194 21 78 0 16
194 21 77 0 0
194 21 76 0 16
194 21 75 0 18
194 21 74 0 18
194 21 73 0 82
194 22 82 0 50
194 22 81 0 2
194 22 80 0 0
194 22 79 0 0
194 22 78 0 0
194 22 77 0 0
194 22 76 0 0
194 22 75 0 0
194 22 74 0 0
194 22 73 0 2
194 22 72 0 82
194 23 83 0 58
194 23 82 0 2
194 23 81 0 0
194 23 80 0 0
194 23 79 0 0
194 23 78 0 0
194 23 77 0 0
194 23 76 0 0
194 23 75 0 0
194 23 74 0 0
194 23 73 0 0
194 23 72 0 2
194 23 71 0 90
194 24 82 0 42
194 24 81 0 2
194 24 80 0 0
194 24 79 0 0
194 24 78 0 0
194 24 77 0 0
194 24 76 0 0
194 24 75 0 0
194 24 74 0 0
194 24 73 0 2
194 24 72 0 74
194 25 81 0 42
194 25 80 0 10
194 25 79 0 10
194 25 78 0 8
194 25 77 0 0
194 25 76 0 8
194 25 75 0 10
194 25 74 0 10
194 25 73 0 74
194 26 77 0 106
195 21 78 0 50
195 21 77 0 18
195 21 76 0 82
195 22 80 0 50
195 22 79 0 18
195 22 78 0 2
195 22 77 0 2
195 22 76 0 2
195 22 75 0 18
195 22 74 0 82
195 23 81 0 58
195 23 80 0 2
195 23 79 0 2
195 23 78 0 2
195 23 77 0 0
195 23 76 0 2
195 23 75 0 2
195 23 74 0 2
195 23 73 0 90
195 24 80 0 42
195 24 79 0 10
195 24 78 0 2
195 24 77 0 2
195 24 76 0 2
195 24 75 0 10
195 24 74 0 74
195 25 78 0 42
195 25 77 0 10
195 25 76 0 74
196 23 77 0 122
77 15 58 0 60
77 15 57 0 20
77 15 56 0 84
77 16 57 0 44
77 16 56 0 76
78 15 62 0 60
78 15 61 0 20
78 15 60 0 20
78 15 59 0 20
78 15 58 0 16
78 15 57 0 16
78 15 56 0 16
78 15 55 0 20
78 15 54 0 84
78 16 61 0 44
78 16 60 0 4
78 16 59 0 4
78 16 58 0 4
78 16 57 0 0
78 16 56 0 0
78 16 55 0 4
78 16 54 0 76
78 17 60 0 44
78 17 59 0 12
78 17 58 0 12
78 17 57 0 12
78 17 56 0 12
78 17 55 0 76
79 14 58 0 52
79 14 57 0 20
79 14 56 0 20
79 14 55 0 84
79 15 64 0 52
79 15 63 0 20
79 15 62 0 16
79 15 61 0 16
79 15 60 0 16
79 15 59 0 16
79 15 58 0 0
79 15 57 0 0
79 15 56 0 0
79 15 55 0 0
79 15 54 0 16
79 15 53 0 20
79 15 52 0 84
79 16 64 0 44
79 16 63 0 12
79 16 62 0 12
79 16 61 0 0
79 16 60 0 0
79 16 59 0 0
79 16 58 0 0
79 16 57 0 0
79 16 56 0 0
79 16 55 0 0
79 16 54 0 8
79 16 53 0 12
79 16 52 0 76
79 17 61 0 44
79 17 60 0 8
79 17 59 0 0
79 17 58 0 0
79 17 57 0 0
79 17 56 0 0
79 17 55 0 64
79 18 59 0 44
79 18 58 0 12
79 18 57 0 12
79 18 56 0 12
79 18 55 0 76
80 13 56 0 116
80 14 65 0 52
80 14 64 0 20
80 14 63 0 84
80 14 61 0 52
80 14 60 0 20
80 14 59 0 20
80 14 58 0 16
80 14 57 0 16
80 14 56 0 0
80 14 55 0 16
80 14 54 0 84
80 15 66 0 52
80 15 65 0 4
80 15 64 0 0
80 15 63 0 0
80 15 62 0 16
80 15 61 0 0
80 15 60 0 0
80 15 59 0 0
80 15 58 0 0
80 15 57 0 0
80 15 56 0 0
80 15 55 0 0
80 15 54 0 0
80 15 53 0 16
80 15 52 0 80
80 16 66 0 44
80 16 65 0 4
80 16 64 0 0
80 16 63 0 0
80 16 62 0 0
80 16 61 0 0
80 16 60 0 0
80 16 59 0 0
80 16 58 0 0
80 16 57 0 0
80 16 56 0 0
80 16 55 0 0
80 16 54 0 0
80 16 53 0 8
80 16 52 0 8
80 16 51 0 84
80 17 65 0 44
80 17 64 0 12
80 17 63 0 12
80 17 62 0 12
80 17 61 0 0
80 17 60 0 0
80 17 59 0 0
80 17 58 0 0
80 17 57 0 0
80 17 56 0 0
80 17 55 0 0
80 17 54 0 76
80 17 51 0 108
80 18 61 0 44
80 18 60 0 12
80 18 59 0 8
80 18 58 0 8
80 18 57 0 8
80 18 56 0 8
80 18 55 0 72
81 13 58 0 52
81 13 57 0 20
81 13 56 0 16
81 13 55 0 84
81 14 65 0 48
81 14 64 0 16
81 14 63 0 16
81 14 62 0 20
81 14 61 0 16
81 14 60 0 16
81 14 59 0 16
81 14 58 0 0
81 14 57 0 0
81 14 56 0 0
81 14 55 0 0
81 14 54 0 16
81 14 53 0 20
81 14 52 0 84
81 15 69 0 52
81 15 68 0 20
81 15 67 0 20
81 15 66 0 16
81 15 65 0 0
81 15 64 0 0
81 15 63 0 0
81 15 62 0 0
81 15 61 0 0
81 15 60 0 0
81 15 59 0 0
81 15 58 0 0
81 15 57 0 0
81 15 56 0 0
81 15 55 0 0
81 15 54 0 0
81 15 53 0 0
81 15 52 0 0
81 15 51 0 20
81 15 50 0 84
81 16 69 0 44
81 16 68 0 12
81 16 67 0 4
81 16 66 0 0
81 16 65 0 0
81 16 64 0 0
81 16 63 0 0
81 16 62 0 0
81 16 61 0 0
81 16 60 0 0
81 16 59 0 0
81 16 58 0 0
81 16 57 0 0
81 16 56 0 0
81 16 55 0 0
81 16 54 0 0
81 16 53 0 0
81 16 52 0 0
81 16 51 0 0
81 16 50 0 4
81 16 49 0 84
81 17 67 0 44
81 17 66 0 12
81 17 65 0 8
81 17 64 0 8
81 17 63 0 8
81 17 62 0 0
81 17 61 0 0
81 17 60 0 0
81 17 59 0 0
81 17 58 0 0
81 17 57 0 0
81 17 56 0 0
81 17 55 0 0
81 17 54 0 8
81 17 53 0 12
81 17 52 0 12
81 17 51 0 0
81 17 50 0 4
81 17 49 0 76
81 18 62 0 44
81 18 61 0 8
81 18 60 0 8
81 18 59 0 0
81 18 58 0 0
81 18 57 0 8
81 18 56 0 8
81 18 55 0 72
81 18 51 0 44
81 18 50 0 76
81 19 59 0 44
81 19 58 0 76
82 12 63 0 52
82 12 62 0 20
82 12 61 0 84
82 13 65 0 52
82 13 64 0 20
82 13 63 0 4
82 13 62 0 4
82 13 61 0 4
82 13 60 0 20
82 13 59 0 20
82 13 58 0 16
82 13 57 0 16
82 13 56 0 16
82 13 55 0 80
82 14 68 0 52
82 14 67 0 20
82 14 66 0 20
82 14 65 0 0
82 14 64 0 0
82 14 63 0 0
82 14 62 0 0
82 14 61 0 0
82 14 60 0 0
82 14 59 0 0
82 14 58 0 0
82 14 57 0 0
82 14 56 0 0
82 14 55 0 0
82 14 54 0 16
82 14 53 0 16
82 14 52 0 16
82 14 51 0 84
82 15 69 0 48
82 15 68 0 0
82 15 67 0 0
82 15 66 0 0
82 15 65 0 0
82 15 64 0 0
82 15 63 0 0
82 15 62 0 0
82 15 61 0 0
82 15 60 0 0
82 15 59 0 0
82 15 58 0 0
82 15 57 0 0
82 15 56 0 0
82 15 55 0 0
82 15 54 0 0
82 15 53 0 0
82 15 52 0 0
82 15 51 0 0
82 15 50 0 16
82 15 49 0 84
82 16 69 0 40
82 16 68 0 0
82 16 67 0 0
82 16 66 0 0
82 16 65 0 0
82 16 64 0 0
82 16 63 0 0
82 16 62 0 0
82 16 61 0 0
82 16 60 0 0
82 16 59 0 0
82 16 58 0 0
82 16 57 0 0
82 16 56 0 0
82 16 55 0 0
82 16 54 0 0
82 16 53 0 0
82 16 52 0 0
82 16 51 0 0
82 16 50 0 0
82 16 49 0 64
82 17 68 0 44
82 17 67 0 8
82 17 66 0 8
82 17 65 0 0
82 17 64 0 0
82 17 63 0 0
82 17 62 0 0
82 17 61 0 0
82 17 60 0 0
82 17 59 0 0
82 17 58 0 0
82 17 57 0 0
82 17 56 0 0
82 17 55 0 0
82 17 54 0 8
82 17 53 0 8
82 17 52 0 8
82 17 51 0 0
82 17 50 0 0
82 17 49 0 64
82 18 65 0 44
82 18 64 0 12
82 18 63 0 12
82 18 62 0 8
82 18 61 0 8
82 18 60 0 0
82 18 59 0 0
82 18 58 0 0
82 18 57 0 0
82 18 56 0 8
82 18 55 0 72
82 18 51 0 40
82 18 50 0 8
82 18 49 0 76
82 19 60 0 44
82 19 59 0 8
82 19 58 0 8
82 19 57 0 76
83 12 65 0 52
83 12 64 0 20
83 12 63 0 16
83 12 62 0 16
83 12 61 0 16
83 12 60 0 84
83 13 66 0 52
83 13 65 0 0
83 13 64 0 0
83 13 63 0 0
83 13 62 0 0
83 13 61 0 0
83 13 60 0 0
83 13 59 0 16
83 13 58 0 16
83 13 57 0 16
83 13 56 0 16
83 13 55 0 16
83 13 54 0 20
83 13 53 0 84
83 14 68 0 48
83 14 67 0 16
83 14 66 0 0
83 14 65 0 0
83 14 64 0 0
83 14 63 0 0
83 14 62 0 0
83 14 61 0 0
83 14 60 0 0
83 14 59 0 0
83 14 58 0 0
83 14 57 0 0
83 14 56 0 0
83 14 55 0 0
83 14 54 0 0
83 14 53 0 0
83 14 52 0 16
83 14 51 0 16
83 14 50 0 84
83 15 70 0 52
83 15 69 0 16
83 15 68 0 0
83 15 67 0 0
83 15 66 0 0
83 15 65 0 0
83 15 64 0 0
83 15 63 0 0
83 15 62 0 0
83 15 61 0 0
83 15 60 0 0
83 15 59 0 0
83 15 58 0 0
83 15 57 0 0
83 15 56 0 0
83 15 55 0 0
83 15 54 0 0
83 15 53 0 0
83 15 52 0 0
83 15 51 0 0
83 15 50 0 0
83 15 49 0 80
83 16 70 0 44
83 16 69 0 0
83 16 68 0 0
83 16 67 0 0
83 16 66 0 0
83 16 65 0 0
83 16 64 0 0
83 16 63 0 0
83 16 62 0 0
83 16 61 0 0
83 16 60 0 0
83 16 59 0 0
83 16 58 0 0
83 16 57 0 0
83 16 56 0 0
83 16 55 0 0
83 16 54 0 0
83 16 53 0 0
83 16 52 0 0
83 16 51 0 0
83 16 50 0 0
83 16 49 0 0
83 16 48 0 84
83 17 69 0 44
83 17 68 0 8
83 17 67 0 8
83 17 66 0 0
83 17 65 0 0
83 17 64 0 0
83 17 63 0 0
83 17 62 0 0
83 17 61 0 0
83 17 60 0 0
83 17 59 0 0
83 17 58 0 0
83 17 57 0 0
83 17 56 0 0
83 17 55 0 0
83 17 54 0 0
83 17 53 0 0
83 17 52 0 8
83 17 51 0 0
83 17 50 0 0
83 17 49 0 0
83 17 48 0 76
83 18 66 0 44
83 18 65 0 8
83 18 64 0 8
83 18 63 0 8
83 18 62 0 8
83 18 61 0 0
83 18 60 0 0
83 18 59 0 0
83 18 58 0 0
83 18 57 0 0
83 18 56 0 0
83 18 55 0 8
83 18 54 0 12
83 18 53 0 76
83 18 51 0 40
83 18 50 0 8
83 18 49 0 72
83 19 61 0 44
83 19 60 0 8
83 19 59 0 8
83 19 58 0 8
83 19 57 0 8
83 19 56 0 76
84 12 65 0 48
84 12 64 0 16
84 12 63 0 16
84 12 62 0 16
84 12 61 0 16
84 12 60 0 16
84 12 59 0 20
84 12 58 0 84
84 13 67 0 52
84 13 66 0 16
84 13 65 0 0
84 13 64 0 0
84 13 63 0 0
84 13 62 0 0
84 13 61 0 0
84 13 60 0 0
84 13 59 0 0
84 13 58 0 0
84 13 57 0 16
84 13 56 0 16
84 13 55 0 16
84 13 54 0 16
84 13 53 0 16
84 13 52 0 84
84 14 69 0 52
84 14 68 0 16
84 14 67 0 0
84 14 66 0 0
84 14 65 0 0
84 14 64 0 0
84 14 63 0 0
84 14 62 0 0
84 14 61 0 0
84 14 60 0 0
84 14 59 0 0
84 14 58 0 0
84 14 57 0 0
84 14 56 0 0
84 14 55 0 0
84 14 54 0 0
84 14 53 0 0
84 14 52 0 0
84 14 51 0 16
84 14 50 0 16
84 14 49 0 84
84 15 71 0 52
84 15 70 0 16
84 15 69 0 0
84 15 68 0 0
84 15 67 0 0
84 15 66 0 0
84 15 65 0 0
84 15 64 0 0
84 15 63 0 0
84 15 62 0 0
84 15 61 0 0
84 15 60 0 0
84 15 59 0 0
84 15 58 0 0
84 15 57 0 0
84 15 56 0 0
84 15 55 0 0
84 15 54 0 0
84 15 53 0 0
84 15 52 0 0
84 15 51 0 0
84 15 50 0 0
84 15 49 0 0
84 15 48 0 84
84 16 71 0 44
84 16 70 0 0
84 16 69 0 0
84 16 68 0 0
84 16 67 0 0
84 16 66 0 0
84 16 65 0 0
84 16 64 0 0
84 16 63 0 0
84 16 62 0 0
84 16 61 0 0
84 16 60 0 0
84 16 59 0 0
84 16 58 0 0
84 16 57 0 0
84 16 56 0 0
84 16 55 0 0
84 16 54 0 0
84 16 53 0 0
84 16 52 0 0
84 16 51 0 0
84 16 50 0 0
84 16 49 0 0
84 16 48 0 0
84 16 47 0 84
84 17 70 0 44
84 17 69 0 8
84 17 68 0 8
84 17 67 0 0
84 17 66 0 0
84 17 65 0 0
84 17 64 0 0
84 17 63 0 0
84 17 62 0 0
84 17 61 0 0
84 17 60 0 0
84 17 59 0 0
84 17 58 0 0
84 17 57 0 0
84 17 56 0 0
84 17 55 0 0
84 17 54 0 0
84 17 53 0 0
84 17 52 0 0
84 17 51 0 0
84 17 50 0 0
84 17 49 0 0
84 17 48 0 0
84 17 47 0 76
84 18 67 0 44
84 18 66 0 8
84 18 65 0 8
84 18 64 0 8
84 18 63 0 8
84 18 62 0 8
84 18 61 0 0
84 18 60 0 0
84 18 59 0 0
84 18 58 0 0
84 18 57 0 0
84 18 56 0 0
84 18 55 0 0
84 18 54 0 8
84 18 53 0 8
84 18 52 0 12
84 18 51 0 8
84 18 50 0 8
84 18 49 0 8
84 18 48 0 76
84 19 61 0 40
84 19 60 0 8
84 19 59 0 8
84 19 58 0 8
84 19 57 0 8
84 19 56 0 8
84 19 55 0 76
85 9 59 21 116
85 10 59 21 102
85 11 61 0 52
85 11 60 0 20
85 11 59 21 68
85 12 65 0 48
85 12 64 0 16
85 12 63 0 16
85 12 62 0 16
85 12 61 0 0
85 12 60 0 0
85 12 59 0 0
85 12 58 0 16
85 12 57 0 20
85 12 56 0 84
85 13 68 0 52
85 13 67 0 16
85 13 66 0 16
85 13 65 0 0
85 13 64 0 0
85 13 63 0 0
85 13 62 0 0
85 13 61 0 0
85 13 60 0 0
85 13 59 0 0
85 13 58 0 0
85 13 57 0 0
85 13 56 0 0
85 13 55 0 16
85 13 54 0 16
85 13 53 0 16
85 13 52 0 16
85 13 51 0 84
85 14 70 0 52
85 14 69 0 16
85 14 68 0 0
85 14 67 0 0
85 14 66 0 0
85 14 65 0 0
85 14 64 0 0
85 14 63 0 0
85 14 62 0 0
85 14 61 0 0
85 14 60 0 0
85 14 59 0 0
85 14 58 0 0
85 14 57 0 0
85 14 56 0 0
85 14 55 0 0
85 14 54 0 0
85 14 53 0 0
85 14 52 0 0
85 14 51 0 0
85 14 50 0 16
85 14 49 0 80
85 15 72 0 52
85 15 71 0 16
85 15 70 0 0
85 15 69 0 0
85 15 68 0 0
85 15 67 0 0
85 15 66 0 0
85 15 65 0 0
85 15 64 0 0
85 15 63 0 0
85 15 62 0 0
85 15 61 0 0
85 15 60 0 0
85 15 59 0 0
85 15 58 0 0
85 15 57 0 0
85 15 56 0 0
85 15 55 0 0
85 15 54 0 0
85 15 53 0 0
85 15 52 0 0
85 15 51 0 0
85 15 50 0 0
85 15 49 0 0
85 15 48 0 80
85 16 72 0 44
85 16 71 0 8
85 16 70 0 0
85 16 69 0 0
85 16 68 0 0
85 16 67 0 0
85 16 66 0 0
85 16 65 0 0
85 16 64 0 0
85 16 63 0 0
85 16 62 0 0
85 16 61 0 0
85 16 60 0 0
85 16 59 0 0
85 16 58 0 0
85 16 57 0 0
85 16 56 0 0
85 16 55 0 0
85 16 54 0 0
85 16 53 0 0
85 16 52 0 0
85 16 51 0 0
85 16 50 0 0
85 16 49 0 0
85 16 48 0 0
85 16 47 0 80
85 17 70 0 40
85 17 69 0 8
85 17 68 0 0
85 17 67 0 0
85 17 66 0 0
85 17 65 0 0
85 17 64 0 0
85 17 63 0 0
85 17 62 0 0
85 17 61 0 0
85 17 60 0 0
85 17 59 0 0
85 17 58 0 0
85 17 57 0 0
85 17 56 0 0
85 17 55 0 0
85 17 54 0 0
85 17 53 0 0
85 17 52 0 0
85 17 51 0 0
85 17 50 0 0
85 17 49 0 0
85 17 48 0 0
85 17 47 0 72
85 18 68 0 44
85 18 67 0 8
85 18 66 0 8
85 18 65 0 8
85 18 64 0 8
85 18 63 0 8
85 18 62 0 8
85 18 61 0 0
85 18 60 0 0
85 18 59 0 0
85 18 58 0 0
85 18 57 0 0
85 18 56 0 0
85 18 55 0 0
85 18 54 0 0
85 18 53 0 8
85 18 52 0 8
85 18 51 0 8
85 18 50 0 0
85 18 49 0 8
85 18 48 0 72
85 19 61 0 40
85 19 60 0 8
85 19 59 0 8
85 19 58 0 8
85 19 57 0 8
85 19 56 0 8
85 19 55 0 8
85 19 54 0 76
85 19 50 0 108
86 8 59 21 116
86 9 59 21 106
86 11 63 0 52
86 11 62 0 20
86 11 61 0 16
86 11 60 0 16
86 11 59 0 16
86 11 58 0 20
86 11 57 0 20
86 11 56 0 20
86 11 55 0 20
86 11 54 0 20
86 11 53 0 84
86 12 65 0 48
86 12 64 0 16
86 12 63 0 0
86 12 62 0 0
86 12 61 0 0
86 12 60 0 0
86 12 59 0 0
86 12 58 0 0
86 12 57 0 0
86 12 56 0 0
86 12 55 0 4
86 12 54 0 4
86 12 53 0 4
86 12 52 0 20
86 12 51 0 84
86 13 68 0 48
86 13 67 0 16
86 13 66 0 16
86 13 65 0 0
86 13 64 0 0
86 13 63 0 0
86 13 62 0 0
86 13 61 0 0
86 13 60 0 0
86 13 59 0 0
86 13 58 0 0
86 13 57 0 0
86 13 56 0 0
86 13 55 0 0
86 13 54 0 0
86 13 53 0 0
86 13 52 0 0
86 13 51 0 64
86 14 71 0 52
86 14 70 0 16
86 14 69 0 16
86 14 68 0 0
86 14 67 0 0
86 14 66 0 0
86 14 65 0 0
86 14 64 0 0
86 14 63 0 0
86 14 62 0 0
86 14 61 0 0
86 14 60 0 0
86 14 59 0 0
86 14 58 0 0
86 14 57 0 0
86 14 56 0 0
86 14 55 0 0
86 14 54 0 0
86 14 53 0 0
86 14 52 0 0
86 14 51 0 0
86 14 50 0 16
86 14 49 0 16
86 14 48 0 84
86 15 72 0 48
86 15 71 0 0
86 15 70 0 0
86 15 69 0 0
86 15 68 0 0
86 15 67 0 0
86 15 66 0 0
86 15 65 0 0
86 15 64 0 0
86 15 63 0 0
86 15 62 0 0
86 15 61 0 0
86 15 60 0 0
86 15 59 0 0
86 15 58 0 0
86 15 57 0 0
86 15 56 0 0
86 15 55 0 0
86 15 54 0 0
86 15 53 0 0
86 15 52 0 0
86 15 51 0 0
86 15 50 0 0
86 15 49 0 0
86 15 48 0 0
86 15 47 0 84
86 16 72 0 40
86 16 71 0 0
86 16 70 0 0
86 16 69 0 0
86 16 68 0 0
86 16 67 0 0
86 16 66 0 0
86 16 65 0 0
86 16 64 0 0
86 16 63 0 0
86 16 62 0 0
86 16 61 0 0
86 16 60 0 0
86 16 59 0 0
86 16 58 0 0
86 16 57 0 0
86 16 56 0 0
86 16 55 0 0
86 16 54 0 0
86 16 53 0 0
86 16 52 0 0
86 16 51 0 0
86 16 50 0 0
86 16 49 0 0
86 16 48 0 0
86 16 47 0 64
86 17 71 0 44
86 17 70 0 8
86 17 69 0 8
86 17 68 0 0
86 17 67 0 0
86 17 66 0 0
86 17 65 0 0
86 17 64 0 0
86 17 63 0 0
86 17 62 0 0
86 17 61 0 0
86 17 60 0 0
86 17 59 0 0
86 17 58 0 0
86 17 57 0 0
86 17 56 0 0
86 17 55 0 0
86 17 54 0 0
86 17 53 0 0
86 17 52 0 0
86 17 51 0 0
86 17 50 0 0
86 17 49 0 0
86 17 48 0 0
86 17 47 0 64
86 18 68 0 40
86 18 67 0 8
86 18 66 0 8
86 18 65 0 8
86 18 64 0 8
86 18 63 0 0
86 18 62 0 0
86 18 61 0 0
86 18 60 0 0
86 18 59 0 0
86 18 58 0 0
86 18 57 0 0
86 18 56 0 0
86 18 55 0 0
86 18 54 0 0
86 18 53 0 8
86 18 52 0 8
86 18 51 0 8
86 18 50 0 0
86 18 49 0 0
86 18 48 0 8
86 18 47 0 76
86 19 63 0 44
86 19 62 0 12
86 19 61 0 8
86 19 60 0 8
86 19 59 0 8
86 19 58 0 8
86 19 57 0 8
86 19 56 0 8
86 19 55 0 8
86 19 54 0 72
86 19 50 0 40
86 19 49 0 76
87 3 60 21 60
87 3 59 21 20
87 3 58 21 92
87 4 59 21 108
87 8 59 21 120
87 10 61 0 52
87 10 60 0 20
87 10 59 0 20
87 10 58 0 20
87 10 57 0 20
87 10 56 0 20
87 10 55 0 20
87 10 54 0 20
87 10 53 0 20
87 10 52 0 84
87 11 64 0 52
87 11 63 0 16
87 11 62 0 16
87 11 61 0 0
87 11 60 0 0
87 11 59 0 0
87 11 58 0 0
87 11 57 0 0
87 11 56 0 0
87 11 55 0 0
87 11 54 0 0
87 11 53 0 0
87 11 52 0 4
87 11 51 0 84
87 12 66 0 52
87 12 65 0 16
87 12 64 0 0
87 12 63 0 0
87 12 62 0 0
87 12 61 0 0
87 12 60 0 0
87 12 59 0 0
87 12 58 0 0
87 12 57 0 0
87 12 56 0 0
87 12 55 0 0
87 12 54 0 0
87 12 53 0 0
87 12 52 0 0
87 12 51 0 0
87 12 50 0 20
87 12 49 0 84
87 13 69 0 52
87 13 68 0 16
87 13 67 0 16
87 13 66 0 0
87 13 65 0 0
87 13 64 0 0
87 13 63 0 0
87 13 62 0 0
87 13 61 0 0
87 13 60 0 0
87 13 59 0 0
87 13 58 0 0
87 13 57 0 0
87 13 56 0 0
87 13 55 0 0
87 13 54 0 0
87 13 53 0 0
87 13 52 0 0
87 13 51 0 0
87 13 50 0 4
87 13 49 0 68
87 14 71 0 48
87 14 70 0 16
87 14 69 0 0
87 14 68 0 0
87 14 67 0 0
87 14 66 0 0
87 14 65 0 0
87 14 64 0 0
87 14 63 0 0
87 14 62 0 0
87 14 61 0 0
87 14 60 0 0
87 14 59 0 0
87 14 58 0 0
87 14 57 0 0
87 14 56 0 0
87 14 55 0 0
87 14 54 0 0
87 14 53 0 0
87 14 52 0 0
87 14 51 0 0
87 14 50 0 0
87 14 49 0 0
87 14 48 0 80
87 15 72 0 48
87 15 71 0 0
87 15 70 0 0
87 15 69 0 0
87 15 68 0 0
87 15 67 0 0
87 15 66 0 0
87 15 65 0 0
87 15 64 0 0
87 15 63 0 0
87 15 62 0 0
87 15 61 0 0
87 15 60 0 0
87 15 59 0 0
87 15 58 0 0
87 15 57 0 0
87 15 56 0 0
87 15 55 0 0
87 15 54 0 0
87 15 53 0 0
87 15 52 0 0
87 15 51 0 0
87 15 50 0 0
87 15 49 0 0
87 15 48 0 0
87 15 47 0 80
87 16 72 0 40
87 16 71 0 0
87 16 70 0 0
87 16 69 0 0
87 16 68 0 0
87 16 67 0 0
87 16 66 0 0
87 16 65 0 0
87 16 64 0 0
87 16 63 0 0
87 16 62 0 0
87 16 61 0 0
87 16 60 0 0
87 16 59 0 0
87 16 58 0 0
87 16 57 0 0
87 16 56 0 0
87 16 55 0 0
87 16 54 0 0
87 16 53 0 0
87 16 52 0 0
87 16 51 0 0
87 16 50 0 0
87 16 49 0 0
87 16 48 0 0
87 16 47 0 0
87 16 46 0 84
87 17 71 0 40
87 17 70 0 8
87 17 69 0 0
87 17 68 0 0
87 17 67 0 0
87 17 66 0 0
87 17 65 0 0
87 17 64 0 0
87 17 63 0 0
87 17 62 0 0
87 17 61 0 0
87 17 60 0 0
87 17 59 0 0
87 17 58 0 0
87 17 57 0 0
87 17 56 0 0
87 17 55 0 0
87 17 54 0 0
87 17 53 0 0
87 17 52 0 0
87 17 51 0 0
87 17 50 0 0
87 17 49 0 0
87 17 48 0 0
87 17 47 0 0
87 17 46 0 76
87 18 69 0 44
87 18 68 0 8
87 18 67 0 8
87 18 66 0 8
87 18 65 0 0
87 18 64 0 0
87 18 63 0 0
87 18 62 0 0
87 18 61 0 0
87 18 60 0 0
87 18 59 0 0
87 18 58 0 0
87 18 57 0 0
87 18 56 0 0
87 18 55 0 0
87 18 54 0 0
87 18 53 0 0
87 18 52 0 8
87 18 51 0 8
87 18 50 0 0
87 18 49 0 0
87 18 48 0 0
87 18 47 0 72
87 19 65 0 44
87 19 64 0 12
87 19 63 0 8
87 19 62 0 0
87 19 61 0 0
87 19 60 0 8
87 19 59 0 8
87 19 58 0 8
87 19 57 0 8
87 19 56 0 8
87 19 55 0 8
87 19 54 0 8
87 19 53 0 76
87 19 50 0 40
87 19 49 0 8
87 19 48 0 76
87 20 62 0 44
87 20 61 0 76
88 3 61 21 60
88 3 60 21 16
88 3 59 21 16
88 3 58 21 80
88 4 60 21 36
88 4 59 21 0
88 4 58 21 76
88 5 60 21 36
88 5 59 21 68
88 6 60 21 36
88 6 59 21 68
88 7 60 21 36
88 7 59 21 68
88 8 60 21 36
88 8 59 21 64
88 9 60 21 38
88 9 59 21 68
88 9 57 0 52
88 9 56 0 20
88 9 55 0 20
88 9 54 0 20
88 9 53 0 84
88 10 62 0 52
88 10 61 0 16
88 10 60 0 0
88 10 59 0 0
88 10 58 0 16
88 10 57 0 0
88 10 56 0 0
88 10 55 0 0
88 10 54 0 0
88 10 53 0 0
88 10 52 0 16
88 10 51 0 84
88 11 65 0 52
88 11 64 0 16
88 11 63 0 16
88 11 62 0 0
88 11 61 0 0
88 11 60 0 0
88 11 59 0 0
88 11 58 0 0
88 11 57 0 0
88 11 56 0 0
88 11 55 0 0
88 11 54 0 0
88 11 53 0 0
88 11 52 0 0
88 11 51 0 0
88 11 50 0 84
88 12 66 0 48
88 12 65 0 0
88 12 64 0 0
88 12 63 0 0
88 12 62 0 0
88 12 61 0 0
88 12 60 0 0
88 12 59 0 0
88 12 58 0 0
88 12 57 0 0
88 12 56 0 0
88 12 55 0 0
88 12 54 0 0
88 12 53 0 0
88 12 52 0 0
88 12 51 0 0
88 12 50 0 0
88 12 49 0 80
88 13 69 0 48
88 13 68 0 16
88 13 67 0 16
88 13 66 0 0
88 13 65 0 0
88 13 64 0 0
88 13 63 0 0
88 13 62 0 0
88 13 61 0 0
88 13 60 0 0
88 13 59 0 0
88 13 58 0 0
88 13 57 0 0
88 13 56 0 0
88 13 55 0 0
88 13 54 0 0
88 13 53 0 0
88 13 52 0 0
88 13 51 0 0
88 13 50 0 0
88 13 49 0 0
88 13 48 0 84
88 14 71 0 48
88 14 70 0 16
88 14 69 0 0
88 14 68 0 0
88 14 67 0 0
88 14 66 0 0
88 14 65 0 0
88 14 64 0 0
88 14 63 0 0
88 14 62 0 0
88 14 61 0 0
88 14 60 0 0
88 14 59 0 0
88 14 58 0 0
88 14 57 0 0
88 14 56 0 0
88 14 55 0 0
88 14 54 0 0
88 14 53 0 0
88 14 52 0 0
88 14 51 0 0
88 14 50 0 0
88 14 49 0 0
88 14 48 0 0
88 14 47 0 84
88 15 72 0 48
88 15 71 0 0
88 15 70 0 0
88 15 69 0 0
88 15 68 0 0
88 15 67 0 0
88 15 66 0 0
88 15 65 0 0
88 15 64 0 0
88 15 63 0 0
88 15 62 0 0
88 15 61 0 0
88 15 60 0 0
88 15 59 0 0
88 15 58 0 0
88 15 57 0 0
88 15 56 0 0
88 15 55 0 0
88 15 54 0 0
88 15 53 0 0
88 15 52 0 0
88 15 51 0 0
88 15 50 0 0
88 15 49 0 0
88 15 48 0 0
88 15 47 0 64
88 16 72 0 40
88 16 71 0 0
88 16 70 0 0
88 16 69 0 0
88 16 68 0 0
88 16 67 0 0
88 16 66 0 0
88 16 65 0 0
88 16 64 0 0
88 16 63 0 0
88 16 62 0 0
88 16 61 0 0
88 16 60 0 0
88 16 59 0 0
88 16 58 0 0
88 16 57 0 0
88 16 56 0 0
88 16 55 0 0
88 16 54 0 0
88 16 53 0 0
88 16 52 0 0
88 16 51 0 0
88 16 50 0 0
88 16 49 0 0
88 16 48 0 0
88 16 47 0 0
88 16 46 0 80
88 17 71 0 40
88 17 70 0 8
88 17 69 0 0
88 17 68 0 0
88 17 67 0 0
88 17 66 0 0
88 17 65 0 0
88 17 64 0 0
88 17 63 0 0
88 17 62 0 0
88 17 61 0 0
88 17 60 0 0
88 17 59 0 0
88 17 58 0 0
88 17 57 0 0
88 17 56 0 0
88 17 55 0 0
88 17 54 0 0
88 17 53 0 0
88 17 52 0 0
88 17 51 0 0
88 17 50 0 0
88 17 49 0 0
88 17 48 0 0
88 17 47 0 0
88 17 46 0 72
88 18 69 0 40
88 18 68 0 8
88 18 67 0 8
88 18 66 0 8
88 18 65 0 0
88 18 64 0 0
88 18 63 0 0
88 18 62 0 0
88 18 61 0 0
88 18 60 0 0
88 18 59 0 0
88 18 58 0 0
88 18 57 0 0
88 18 56 0 0
88 18 55 0 0
88 18 54 0 0
88 18 53 0 0
88 18 52 0 8
88 18 51 0 0
88 18 50 0 0
88 18 49 0 0
88 18 48 0 0
88 18 47 0 72
88 19 65 0 40
88 19 64 0 0
88 19 63 0 0
88 19 62 0 0
88 19 61 0 0
88 19 60 0 0
88 19 59 0 0
88 19 58 0 8
88 19 57 0 8
88 19 56 0 8
88 19 55 0 8
88 19 54 0 8
88 19 53 0 72
88 19 51 0 44
88 19 50 0 8
88 19 49 0 8
88 19 48 0 72
88 20 64 0 44
88 20 63 0 12
88 20 62 0 8
88 20 61 0 8
88 20 60 0 12
88 20 59 0 76
89 3 61 21 56
89 3 60 21 16
89 3 59 21 16
89 3 58 21 16
89 3 57 21 92
89 4 60 21 34
89 4 59 21 0
89 4 58 21 74
89 5 60 21 34
89 5 59 21 64
89 6 60 21 34
89 6 59 21 0
89 6 58 21 86
89 7 62 21 54
89 7 61 21 30
89 7 60 21 2
89 7 59 21 0
89 7 58 21 14
89 7 57 21 22
89 7 56 21 30
89 7 55 21 86
89 8 63 21 54
89 8 62 21 78
89 8 60 21 42
89 8 59 21 64
89 8 57 21 102
89 8 55 21 102
89 9 64 21 54
89 9 63 21 70
89 9 59 21 98
89 9 57 0 34
89 9 56 0 16
89 9 55 0 0
89 9 54 0 16
89 9 53 0 80
89 10 64 21 38
89 10 63 0 4
89 10 62 0 16
89 10 61 0 16
89 10 60 0 16
89 10 59 0 0
89 10 58 0 16
89 10 57 0 0
89 10 56 0 0
89 10 55 0 0
89 10 54 0 0
89 10 53 0 0
89 10 52 0 16
89 10 51 0 80
89 11 65 0 48
89 11 64 0 0
89 11 63 0 0
89 11 62 0 0
89 11 61 0 0
89 11 60 0 0
89 11 59 0 0
89 11 58 0 0
89 11 57 0 0
89 11 56 0 0
89 11 55 0 0
89 11 54 0 0
89 11 53 0 0
89 11 52 0 0
89 11 51 0 0
89 11 50 0 82
89 12 66 0 48
89 12 65 0 0
89 12 64 0 0
89 12 63 0 0
89 12 62 0 0
89 12 61 0 0
89 12 60 0 0
89 12 59 0 0
89 12 58 0 0
89 12 57 0 0
89 12 56 0 0
89 12 55 0 0
89 12 54 0 0
89 12 53 0 0
89 12 52 0 0
89 12 51 0 0
89 12 50 0 0
89 12 49 0 80
89 13 69 0 50
89 13 68 0 16
89 13 67 0 16
89 13 66 0 0
89 13 65 0 0
89 13 64 0 0
89 13 63 0 0
89 13 62 0 0
89 13 61 0 0
89 13 60 0 0
89 13 59 0 0
89 13 58 0 0
89 13 57 0 0
89 13 56 0 0
89 13 55 0 0
89 13 54 0 0
89 13 53 0 0
89 13 52 0 0
89 13 51 0 0
89 13 50 0 0
89 13 49 0 0
89 13 48 0 80
89 14 71 0 50
89 14 70 0 16
89 14 69 0 0
89 14 68 0 0
89 14 67 0 0
89 14 66 0 0
89 14 65 0 0
89 14 64 0 0
89 14 63 0 0
89 14 62 0 0
89 14 61 0 0
89 14 60 0 0
89 14 59 0 0
89 14 58 0 0
89 14 57 0 0
89 14 56 0 0
89 14 55 0 0
89 14 54 0 0
89 14 53 0 0
89 14 52 0 0
89 14 51 0 0
89 14 50 0 0
89 14 49 0 0
89 14 48 0 0
89 14 47 0 82
89 15 72 0 50
89 15 71 0 0
89 15 70 0 0
89 15 69 0 0
89 15 68 0 0
89 15 67 0 0
89 15 66 0 0
89 15 65 0 0
89 15 64 0 0
89 15 63 0 0
89 15 62 0 0
89 15 61 0 0
89 15 60 0 0
89 15 59 0 0
89 15 58 0 0
89 15 57 0 0
89 15 56 0 0
89 15 55 0 0
89 15 54 0 0
89 15 53 0 0
89 15 52 0 0
89 15 51 0 0
89 15 50 0 0
89 15 49 0 0
89 15 48 0 0
89 15 47 0 64
89 16 72 0 42
89 16 71 0 0
89 16 70 0 0
89 16 69 0 0
89 16 68 0 0
89 16 67 0 0
89 16 66 0 0
89 16 65 0 0
89 16 64 0 0
89 16 63 0 0
89 16 62 0 0
89 16 61 0 0
89 16 60 0 0
89 16 59 0 0
89 16 58 0 0
89 16 57 0 0
89 16 56 0 0
89 16 55 0 0
89 16 54 0 0
89 16 53 0 0
89 16 52 0 0
89 16 51 0 0
89 16 50 0 0
89 16 49 0 0
89 16 48 0 0
89 16 47 0 0
89 16 46 0 80
89 17 71 0 40
89 17 70 0 8
89 17 69 0 0
89 17 68 0 0
89 17 67 0 0
89 17 66 0 0
89 17 65 0 0
89 17 64 0 0
89 17 63 0 0
89 17 62 0 0
89 17 61 0 0
89 17 60 0 0
89 17 59 0 0
89 17 58 0 0
89 17 57 0 0
89 17 56 0 0
89 17 55 0 0
89 17 54 0 0
89 17 53 0 0
89 17 52 0 0
89 17 51 0 0
89 17 50 0 0
89 17 49 0 0
89 17 48 0 0
89 17 47 0 0
89 17 46 0 74
89 18 69 0 42
89 18 68 0 8
89 18 67 0 8
89 18 66 0 8
89 18 65 0 0
89 18 64 0 0
89 18 63 0 0
89 18 62 0 0
89 18 61 0 0
89 18 60 0 0
89 18 59 0 0
89 18 58 0 0
89 18 57 0 0
89 18 56 0 0
89 18 55 0 0
89 18 54 0 0
89 18 53 0 0
89 18 52 0 8
89 18 51 0 0
89 18 50 0 0
89 18 49 0 0
89 18 48 0 0
89 18 47 0 72
89 19 65 0 40
89 19 64 0 0
89 19 63 0 0
89 19 62 0 0
89 19 61 0 0
89 19 60 0 0
89 19 59 0 0
89 19 58 0 8
89 19 57 0 8
89 19 56 0 8
89 19 55 0 8
89 19 54 0 8
89 19 53 0 72
89 19 51 0 40
89 19 50 0 8
89 19 49 0 8
89 19 48 0 74
89 20 64 0 40
89 20 63 0 8
89 20 62 0 8
89 20 61 0 8
89 20 60 0 8
89 20 59 0 72
90 3 61 21 58
90 3 60 21 24
90 3 59 21 16
90 3 58 21 24
90 3 57 21 90
90 4 59 21 98
90 5 59 21 98
90 6 59 21 96
90 7 59 21 96
90 8 59 21 106
90 9 56 0 50
90 9 55 0 16
90 9 54 0 16
90 9 53 0 80
90 10 63 0 50
90 10 62 0 16
90 10 61 0 16
90 10 60 0 16
90 10 59 0 16
90 10 58 0 16
90 10 57 0 16
90 10 56 0 0
90 10 55 0 0
90 10 54 0 0
90 10 53 0 0
90 10 52 0 16
90 10 51 0 80
90 11 65 0 48
90 11 64 0 16
90 11 63 0 0
90 11 62 0 0
90 11 61 0 0
90 11 60 0 0
90 11 59 0 0
90 11 58 0 0
90 11 57 0 0
90 11 56 0 0
90 11 55 0 0
90 11 54 0 0
90 11 53 0 0
90 11 52 0 0
90 11 51 0 64
90 12 66 0 48
90 12 65 0 0
90 12 64 0 0
90 12 63 0 0
90 12 62 0 0
90 12 61 0 0
90 12 60 0 0
90 12 59 0 0
90 12 58 0 0
90 12 57 0 0
90 12 56 0 0
90 12 55 0 0
90 12 54 0 0
90 12 53 0 0
90 12 52 0 0
90 12 51 0 0
90 12 50 0 16
90 12 49 0 82
90 13 68 0 48
90 13 67 0 16
90 13 66 0 0
90 13 65 0 0
90 13 64 0 0
90 13 63 0 0
90 13 62 0 0
90 13 61 0 0
90 13 60 0 0
90 13 59 0 0
90 13 58 0 0
90 13 57 0 0
90 13 56 0 0
90 13 55 0 0
90 13 54 0 0
90 13 53 0 0
90 13 52 0 0
90 13 51 0 0
90 13 50 0 0
90 13 49 0 2
90 13 48 0 82
90 14 70 0 48
90 14 69 0 16
90 14 68 0 0
90 14 67 0 0
90 14 66 0 0
90 14 65 0 0
90 14 64 0 0
90 14 63 0 0
90 14 62 0 0
90 14 61 0 0
90 14 60 0 0
90 14 59 0 0
90 14 58 0 0
90 14 57 0 0
90 14 56 0 0
90 14 55 0 0
90 14 54 0 0
90 14 53 0 0
90 14 52 0 0
90 14 51 0 0
90 14 50 0 0
90 14 49 0 0
90 14 48 0 64
90 15 71 0 48
90 15 70 0 0
90 15 69 0 0
90 15 68 0 0
90 15 67 0 0
90 15 66 0 0
90 15 65 0 0
90 15 64 0 0
90 15 63 0 0
90 15 62 0 0
90 15 61 0 0
90 15 60 0 0
90 15 59 0 0
90 15 58 0 0
90 15 57 0 0
90 15 56 0 0
90 15 55 0 0
90 15 54 0 0
90 15 53 0 0
90 15 52 0 0
90 15 51 0 0
90 15 50 0 0
90 15 49 0 0
90 15 48 0 0
90 15 47 0 80
90 16 71 0 32
90 16 70 0 0
90 16 69 0 0
90 16 68 0 0
90 16 67 0 0
90 16 66 0 0
90 16 65 0 0
90 16 64 0 0
90 16 63 0 0
90 16 62 0 0
90 16 61 0 0
90 16 60 0 0
90 16 59 0 0
90 16 58 0 0
90 16 57 0 0
90 16 56 0 0
90 16 55 0 0
90 16 54 0 0
90 16 53 0 0
90 16 52 0 0
90 16 51 0 0
90 16 50 0 0
90 16 49 0 0
90 16 48 0 0
90 16 47 0 0
90 16 46 0 90
90 17 71 0 42
90 17 70 0 8
90 17 69 0 8
90 17 68 0 0
90 17 67 0 0
90 17 66 0 0
90 17 65 0 0
90 17 64 0 0
90 17 63 0 0
90 17 62 0 0
90 17 61 0 0
90 17 60 0 0
90 17 59 0 0
90 17 58 0 0
90 17 57 0 0
90 17 56 0 0
90 17 55 0 0
90 17 54 0 0
90 17 53 0 0
90 17 52 0 0
90 17 51 0 0
90 17 50 0 0
90 17 49 0 0
90 17 48 0 0
90 17 47 0 64
90 18 68 0 40
90 18 67 0 8
90 18 66 0 8
90 18 65 0 0
90 18 64 0 0
90 18 63 0 0
90 18 62 0 0
90 18 61 0 0
90 18 60 0 0
90 18 59 0 0
90 18 58 0 0
90 18 57 0 0
90 18 56 0 0
90 18 55 0 0
90 18 54 0 0
90 18 53 0 0
90 18 52 0 8
90 18 51 0 0
90 18 50 0 0
90 18 49 0 0
90 18 48 0 8
90 18 47 0 74
90 19 65 0 32
90 19 64 0 0
90 19 63 0 0
90 19 62 0 0
90 19 61 0 0
90 19 60 0 0
90 19 59 0 0
90 19 58 0 0
90 19 57 0 8
90 19 56 0 8
90 19 55 0 8
90 19 54 0 8
90 19 53 0 72
90 19 51 0 42
90 19 50 0 8
90 19 49 0 74
90 20 65 0 44
90 20 64 0 8
90 20 63 0 8
90 20 62 0 8
90 20 61 0 8
90 20 60 0 8
90 20 59 0 8
90 20 58 0 76
91 3 60 21 58
91 3 59 21 24
91 3 58 21 90
91 6 59 21 114
91 7 59 21 104
91 9 55 0 50
91 9 54 0 18
91 9 53 0 82
91 10 62 0 50
91 10 61 0 16
91 10 60 0 16
91 10 59 0 16
91 10 58 0 16
91 10 57 0 16
91 10 56 0 16
91 10 55 0 0
91 10 54 0 0
91 10 53 0 0
91 10 52 0 18
91 10 51 0 82
91 11 65 0 50
91 11 64 0 18
91 11 63 0 16
91 11 62 0 0
91 11 61 0 0
91 11 60 0 0
91 11 59 0 0
91 11 58 0 0
91 11 57 0 0
91 11 56 0 0
91 11 55 0 0
91 11 54 0 0
91 11 53 0 0
91 11 52 0 0
91 11 51 0 66
91 12 66 0 50
91 12 65 0 0
91 12 64 0 0
91 12 63 0 0
91 12 62 0 0
91 12 61 0 0
91 12 60 0 0
91 12 59 0 0
91 12 58 0 0
91 12 57 0 0
91 12 56 0 0
91 12 55 0 0
91 12 54 0 0
91 12 53 0 0
91 12 52 0 0
91 12 51 0 2
91 12 50 0 82
91 13 68 0 50
91 13 67 0 16
91 13 66 0 0
91 13 65 0 0
91 13 64 0 0
91 13 63 0 0
91 13 62 0 0
91 13 61 0 0
91 13 60 0 0
91 13 59 0 0
91 13 58 0 0
91 13 57 0 0
91 13 56 0 0
91 13 55 0 0
91 13 54 0 0
91 13 53 0 0
91 13 52 0 0
91 13 51 0 2
91 13 50 0 66
91 14 70 0 48
91 14 69 0 16
91 14 68 0 0
91 14 67 0 0
91 14 66 0 0
91 14 65 0 0
91 14 64 0 0
91 14 63 0 0
91 14 62 0 0
91 14 61 0 0
91 14 60 0 0
91 14 59 0 0
91 14 58 0 0
91 14 57 0 0
91 14 56 0 0
91 14 55 0 0
91 14 54 0 0
91 14 53 0 0
91 14 52 0 0
91 14 51 0 0
91 14 50 0 0
91 14 49 0 16
91 14 48 0 82
91 15 71 0 50
91 15 70 0 0
91 15 69 0 0
91 15 68 0 0
91 15 67 0 0
91 15 66 0 0
91 15 65 0 0
91 15 64 0 0
91 15 63 0 0
91 15 62 0 0
91 15 61 0 0
91 15 60 0 0
91 15 59 0 0
91 15 58 0 0
91 15 57 0 0
91 15 56 0 0
91 15 55 0 0
91 15 54 0 0
91 15 53 0 0
91 15 52 0 0
91 15 51 0 0
91 15 50 0 0
91 15 49 0 0
91 15 48 0 0
91 15 47 0 82
91 16 71 0 42
91 16 70 0 0
91 16 69 0 0
91 16 68 0 0
91 16 67 0 0
91 16 66 0 0
91 16 65 0 0
91 16 64 0 0
91 16 63 0 0
91 16 62 0 0
91 16 61 0 0
91 16 60 0 0
91 16 59 0 0
91 16 58 0 0
91 16 57 0 0
91 16 56 0 0
91 16 55 0 0
91 16 54 0 0
91 16 53 0 0
91 16 52 0 0
91 16 51 0 0
91 16 50 0 0
91 16 49 0 0
91 16 48 0 0
91 16 47 0 64
91 17 70 0 40
91 17 69 0 8
91 17 68 0 0
91 17 67 0 0
91 17 66 0 0
91 17 65 0 0
91 17 64 0 0
91 17 63 0 0
91 17 62 0 0
91 17 61 0 0
91 17 60 0 0
