Qubicle Exchange Format
Version 0.2
www.minddesk.com
172 49 92
78
0.000000 0.000000 0.000000
0.015686 0.011765 0.000000
0.035294 0.231373 0.352941
0.039216 0.278431 0.423529
0.047059 0.168627 0.298039
0.062745 0.258824 0.600000
0.070588 0.141176 0.086275
0.086275 0.086275 0.086275
0.090196 0.211765 0.117647
0.094118 0.203922 0.321569
0.105882 0.298039 0.188235
0.113725 0.054902 0.121569
0.121569 0.125490 0.125490
0.125490 0.125490 0.125490
0.137255 0.223529 0.172549
0.149020 0.345098 0.227451
0.156863 0.741176 0.380392
0.184314 0.329412 0.247059
0.192157 0.250980 0.388235
0.200000 0.086275 0.211765
0.227451 0.090196 0.113725
0.227451 0.415686 0.737255
0.231373 0.490196 0.329412
0.243137 0.278431 0.313725
0.266667 0.156863 0.000000
0.266667 0.588235 0.388235
0.282353 0.203922 0.047059
0.286275 0.090196 0.098039
0.290196 0.172549 0.301961
0.290196 0.298039 0.301961
0.294118 0.341176 0.388235
0.313725 0.321569 0.321569
0.321569 0.384314 0.031373
0.329412 0.682353 0.466667
0.337255 0.200000 0.007843
0.341176 0.227451 0.000000
0.352941 0.211765 0.047059
0.368627 0.270588 0.070588
0.376471 0.384314 0.392157
0.380392 0.435294 0.490196
0.419608 0.431373 0.431373
0.439216 0.321569 0.086275
0.458824 0.368627 0.027451
0.462745 0.105882 0.156863
0.486275 0.309804 0.054902
0.505882 0.247059 0.058824
0.513725 0.411765 0.031373
0.529412 0.364706 0.031373
0.541176 0.466667 0.003922
0.576471 0.345098 0.180392
0.588235 0.529412 0.627451
0.600000 0.713725 0.062745
0.615686 0.498039 0.062745
0.623529 0.298039 0.062745
0.631373 0.921569 0.968627
0.643137 0.450980 0.039216
0.666667 0.572549 0.035294
0.682353 0.466667 0.019608
0.694118 0.552941 0.043137
0.713725 0.372549 0.125490
0.713725 0.478431 0.003922
0.717647 0.576471 0.058824
0.741176 0.494118 0.000000
0.764706 0.600000 0.003922
0.780392 0.780392 0.780392
0.796078 0.803922 0.807843
0.803922 0.682353 0.243137
0.811765 0.639216 0.000000
0.909804 0.682353 0.219608
0.929412 0.925490 0.925490
0.980392 0.827451 0.784314
0.984314 0.858824 0.823529
0.984314 0.937255 0.850980
0.988235 0.784314 0.031373
0.988235 0.811765 0.760784
0.988235 0.858824 0.823529
1.000000 0.905882 0.003922
1.000000 1.000000 1.000000
57 6 75 52 52
57 6 74 52 20
57 6 73 52 84
57 7 75 58 36
57 7 74 58 4
57 7 73 58 68
57 8 75 67 44
57 8 74 63 12
57 8 73 67 76
58 6 75 52 48
58 6 74 52 16
58 6 73 52 80
58 7 89 55 60
58 7 88 55 30
58 7 87 55 30
58 7 86 55 30
58 7 85 55 30
58 7 84 55 30
58 7 83 55 30
58 7 82 55 30
58 7 81 55 30
58 7 80 55 30
58 7 79 55 30
58 7 78 55 30
58 7 77 55 30
58 7 76 55 30
58 7 75 58 0
58 7 74 58 0
58 7 73 58 0
58 7 72 55 30
58 7 71 55 30
58 7 70 55 30
58 7 69 55 30
58 7 68 55 30
58 7 67 55 30
58 7 66 55 30
58 7 65 55 30
58 7 64 55 30
58 7 63 55 94
58 8 75 63 40
58 8 74 55 8
58 8 73 63 72
58 22 89 61 52
58 22 88 35 20
58 22 87 35 20
58 22 86 35 20
58 22 85 35 20
58 22 84 35 20
58 22 83 35 20
58 22 82 35 20
58 22 81 35 20
58 22 80 35 20
58 22 79 35 20
58 22 78 35 20
58 22 77 35 20
58 22 76 35 20
58 22 75 35 20
58 22 74 35 20
58 22 73 35 20
58 22 72 35 20
58 22 71 35 20
58 22 70 35 20
58 22 69 35 20
58 22 68 35 20
58 22 67 35 20
58 22 66 35 20
58 22 65 35 20
58 22 64 35 20
58 22 63 61 84
58 23 89 76 44
58 23 88 61 12
58 23 87 35 12
58 23 86 35 12
58 23 85 35 12
58 23 84 35 12
58 23 83 35 12
58 23 82 35 12
58 23 81 35 12
58 23 80 35 12
58 23 79 35 12
58 23 78 35 12
58 23 77 35 12
58 23 76 35 12
58 23 75 35 12
58 23 74 35 12
58 23 73 35 12
58 23 72 35 12
58 23 71 35 12
58 23 70 35 12
58 23 69 35 12
58 23 68 35 12
58 23 67 35 12
58 23 66 35 12
58 23 65 35 12
58 23 64 61 12
58 23 63 76 76
59 6 75 52 50
59 6 74 52 18
59 6 73 52 82
59 7 89 55 120
59 7 75 58 34
59 7 74 58 0
59 7 73 58 66
59 8 75 67 42
59 8 74 63 10
59 8 73 67 74
59 21 88 35 52
59 21 87 35 20
59 21 86 35 20
59 21 85 35 20
59 21 84 35 20
59 21 83 35 20
59 21 82 35 20
59 21 81 35 20
59 21 80 35 20
59 21 79 35 20
59 21 78 35 20
59 21 77 35 20
59 21 76 35 20
59 21 75 35 20
59 21 74 35 20
59 21 73 35 20
59 21 72 35 20
59 21 71 35 20
59 21 70 35 20
59 21 69 35 20
59 21 68 35 20
59 21 67 35 20
59 21 66 35 20
59 21 65 35 20
59 21 64 35 20
59 21 63 35 84
59 22 89 35 48
59 22 88 35 0
59 22 87 35 0
59 22 86 35 0
59 22 85 35 0
59 22 84 35 0
59 22 83 35 0
59 22 82 35 0
59 22 81 35 0
59 22 80 35 0
59 22 79 35 0
59 22 78 35 0
59 22 77 35 0
59 22 76 35 0
59 22 75 35 0
59 22 74 35 0
59 22 73 35 0
59 22 72 35 0
59 22 71 35 0
59 22 70 35 0
59 22 69 35 0
59 22 68 35 0
59 22 67 35 0
59 22 66 35 0
59 22 65 35 0
59 22 64 35 0
59 22 63 35 64
59 23 89 61 40
59 23 88 24 8
59 23 87 24 8
59 23 86 24 8
59 23 85 24 8
59 23 84 24 8
59 23 83 24 8
59 23 82 24 8
59 23 81 24 8
59 23 80 24 8
59 23 79 24 8
59 23 78 24 8
59 23 77 24 8
59 23 76 24 8
59 23 75 24 8
59 23 74 24 8
59 23 73 24 8
59 23 72 24 8
59 23 71 24 8
59 23 70 24 8
59 23 69 24 8
59 23 68 24 8
59 23 67 24 8
59 23 66 24 8
59 23 65 24 8
59 23 64 24 8
59 23 63 61 72
60 7 89 55 120
60 7 74 52 120
60 20 87 35 52
60 20 86 35 20
60 20 85 35 20
60 20 84 35 20
60 20 83 35 20
60 20 82 35 20
60 20 81 35 20
60 20 80 35 20
60 20 79 35 20
60 20 78 35 20
60 20 77 35 20
60 20 76 35 20
60 20 75 35 20
60 20 74 35 20
60 20 73 35 20
60 20 72 35 20
60 20 71 35 20
60 20 70 35 20
60 20 69 35 20
60 20 68 35 20
60 20 67 35 20
60 20 66 35 20
60 20 65 35 20
60 20 64 35 20
60 20 63 35 84
60 21 88 35 48
60 21 87 35 0
60 21 86 35 0
60 21 85 35 0
60 21 84 35 0
60 21 83 35 0
60 21 82 35 0
60 21 81 35 0
60 21 80 35 0
60 21 79 35 0
60 21 78 35 0
60 21 77 35 0
60 21 76 35 0
60 21 75 35 0
60 21 74 35 0
60 21 73 35 0
60 21 72 35 0
60 21 71 35 0
60 21 70 35 0
60 21 69 35 0
60 21 68 35 0
60 21 67 35 0
60 21 66 35 0
60 21 65 35 0
60 21 64 35 0
60 21 63 35 64
60 22 89 35 48
60 22 88 35 0
60 22 87 35 0
60 22 86 35 0
60 22 85 35 0
60 22 84 35 0
60 22 83 35 0
60 22 82 35 0
60 22 81 35 0
60 22 80 35 0
60 22 79 35 0
60 22 78 35 0
60 22 77 35 0
60 22 76 35 0
60 22 75 35 0
60 22 74 35 0
60 22 73 35 0
60 22 72 35 0
60 22 71 35 0
60 22 70 35 0
60 22 69 35 0
60 22 68 35 0
60 22 67 35 0
60 22 66 35 0
60 22 65 35 0
60 22 64 35 0
60 22 63 35 64
60 23 89 35 40
60 23 88 24 8
60 23 87 35 8
60 23 86 35 8
60 23 85 35 8
60 23 84 35 8
60 23 83 35 8
60 23 82 35 8
60 23 81 35 8
60 23 80 35 8
60 23 79 35 8
60 23 78 35 8
60 23 77 35 8
60 23 76 35 8
60 23 75 35 8
60 23 74 35 8
60 23 73 35 8
60 23 72 35 8
60 23 71 35 8
60 23 70 35 8
60 23 69 35 8
60 23 68 35 8
60 23 67 35 8
60 23 66 35 8
60 23 65 35 8
60 23 64 24 8
60 23 63 35 72
61 7 89 55 120
61 7 74 52 120
61 19 86 35 52
61 19 85 35 20
61 19 84 35 20
61 19 83 35 20
61 19 82 35 20
61 19 81 35 20
61 19 80 35 20
61 19 79 35 20
61 19 78 35 20
61 19 77 35 20
61 19 76 35 20
61 19 75 35 20
61 19 74 35 20
61 19 73 35 20
61 19 72 35 20
61 19 71 35 20
61 19 70 35 20
61 19 69 35 20
61 19 68 35 20
61 19 67 35 20
61 19 66 35 20
61 19 65 35 20
61 19 64 35 20
61 19 63 35 84
61 20 87 35 48
61 20 86 35 0
61 20 85 35 0
61 20 84 35 0
61 20 83 35 0
61 20 82 35 0
61 20 81 35 0
61 20 80 35 0
61 20 79 35 0
61 20 78 35 0
61 20 77 35 0
61 20 76 35 0
61 20 75 35 0
61 20 74 35 0
61 20 73 35 0
61 20 72 35 0
61 20 71 35 0
61 20 70 35 0
61 20 69 35 0
61 20 68 35 0
61 20 67 35 0
61 20 66 35 0
61 20 65 35 0
61 20 64 35 0
61 20 63 35 64
61 21 88 35 48
61 21 87 35 0
61 21 86 35 0
61 21 85 35 0
61 21 84 35 0
61 21 83 35 0
61 21 82 35 0
61 21 81 35 0
61 21 80 35 0
61 21 79 35 0
61 21 78 35 0
61 21 77 35 0
61 21 76 35 0
61 21 75 35 0
61 21 74 35 0
61 21 73 35 0
61 21 72 35 0
61 21 71 35 0
61 21 70 35 0
61 21 69 35 0
61 21 68 35 0
61 21 67 35 0
61 21 66 35 0
61 21 65 35 0
61 21 64 35 0
61 21 63 35 64
61 22 89 35 48
61 22 88 35 0
61 22 87 35 0
61 22 86 35 0
61 22 85 35 0
61 22 84 35 0
61 22 83 35 0
61 22 82 35 0
61 22 81 35 0
61 22 80 35 0
61 22 79 35 0
61 22 78 35 0
61 22 77 35 0
61 22 76 35 0
61 22 75 35 0
61 22 74 35 0
61 22 73 35 0
61 22 72 35 0
61 22 71 35 0
61 22 70 35 0
61 22 69 35 0
61 22 68 35 0
61 22 67 35 0
61 22 66 35 0
61 22 65 35 0
61 22 64 35 0
61 22 63 35 64
61 23 89 35 40
61 23 88 24 8
61 23 87 35 8
61 23 86 23 8
61 23 85 23 8
61 23 84 23 8
61 23 83 23 8
61 23 82 23 8
61 23 81 23 8
61 23 80 23 8
61 23 79 23 8
61 23 78 23 8
61 23 77 23 8
61 23 76 23 8
61 23 75 23 8
61 23 74 23 8
61 23 73 23 8
61 23 72 23 8
61 23 71 23 8
61 23 70 23 8
61 23 69 23 8
61 23 68 23 8
61 23 67 23 8
61 23 66 23 8
61 23 65 35 8
61 23 64 24 8
61 23 63 35 72
62 1 85 42 52
62 1 84 42 20
62 1 83 42 20
62 1 82 42 20
62 1 81 42 20
62 1 80 42 20
62 1 79 42 20
62 1 78 42 20
62 1 77 42 20
62 1 76 42 20
62 1 75 42 20
62 1 74 42 20
62 1 73 42 20
62 1 72 42 20
62 1 71 42 20
62 1 70 42 20
62 1 69 42 20
62 1 68 42 20
62 1 67 42 20
62 1 66 42 20
62 1 65 42 20
62 1 64 42 20
62 1 63 42 84
62 2 85 46 36
62 2 84 42 4
62 2 83 42 4
62 2 82 42 4
62 2 81 42 4
62 2 80 42 4
62 2 79 42 4
62 2 78 42 4
62 2 77 42 4
62 2 76 42 4
62 2 75 42 4
62 2 74 42 4
62 2 73 42 4
62 2 72 42 4
62 2 71 42 4
62 2 70 42 4
62 2 69 42 4
62 2 68 42 4
62 2 67 42 4
62 2 66 42 4
62 2 65 42 4
62 2 64 42 4
62 2 63 46 68
62 3 85 46 36
62 3 84 42 4
62 3 83 37 4
62 3 82 37 4
62 3 81 35 4
62 3 80 37 4
62 3 79 37 4
62 3 78 35 4
62 3 77 37 4
62 3 76 37 4
62 3 75 35 4
62 3 74 37 4
62 3 73 37 4
62 3 72 35 4
62 3 71 37 4
62 3 70 37 4
62 3 69 35 4
62 3 68 37 4
62 3 67 37 4
62 3 66 35 4
62 3 65 37 4
62 3 64 42 4
62 3 63 46 68
62 4 85 46 36
62 4 84 42 4
62 4 83 37 4
62 4 82 37 4
62 4 81 35 4
62 4 80 37 4
62 4 79 37 4
62 4 78 35 4
62 4 77 37 4
62 4 76 37 4
62 4 75 35 4
62 4 74 37 4
62 4 73 37 4
62 4 72 35 4
62 4 71 37 4
62 4 70 37 4
62 4 69 35 4
62 4 68 37 4
62 4 67 37 4
62 4 66 35 4
62 4 65 37 4
62 4 64 42 4
62 4 63 46 68
62 5 85 46 36
62 5 84 42 4
62 5 83 37 4
62 5 82 37 4
62 5 81 35 4
62 5 80 37 4
62 5 79 37 4
62 5 78 35 4
62 5 77 37 4
62 5 76 37 4
62 5 75 35 4
62 5 74 37 4
62 5 73 37 4
62 5 72 35 4
62 5 71 37 4
62 5 70 37 4
62 5 69 35 4
62 5 68 37 4
62 5 67 37 4
62 5 66 35 4
62 5 65 37 4
62 5 64 42 4
62 5 63 46 68
62 6 85 46 36
62 6 84 42 4
62 6 83 37 4
62 6 82 37 4
62 6 81 35 4
62 6 80 37 4
62 6 79 37 4
62 6 78 35 4
62 6 77 37 4
62 6 76 37 4
62 6 75 35 4
62 6 74 37 4
62 6 73 37 4
62 6 72 35 4
62 6 71 37 4
62 6 70 37 4
62 6 69 35 4
62 6 68 37 4
62 6 67 37 4
62 6 66 35 4
62 6 65 37 4
62 6 64 42 4
62 6 63 46 68
62 7 89 55 120
62 7 85 46 36
62 7 84 42 4
62 7 83 37 4
62 7 82 37 4
62 7 81 35 4
62 7 80 37 4
62 7 79 37 4
62 7 78 35 4
62 7 77 37 4
62 7 76 37 4
62 7 75 35 4
62 7 74 37 0
62 7 73 37 4
62 7 72 35 4
62 7 71 37 4
62 7 70 37 4
62 7 69 35 4
62 7 68 37 4
62 7 67 37 4
62 7 66 35 4
62 7 65 37 4
62 7 64 42 4
62 7 63 46 68
62 8 85 46 36
62 8 84 42 4
62 8 83 37 4
62 8 82 37 4
62 8 81 35 4
62 8 80 37 4
62 8 79 37 4
62 8 78 35 4
62 8 77 37 4
62 8 76 37 4
62 8 75 35 4
62 8 74 37 4
62 8 73 37 4
62 8 72 35 4
62 8 71 37 4
62 8 70 37 4
62 8 69 35 4
62 8 68 37 4
62 8 67 37 4
62 8 66 35 4
62 8 65 37 4
62 8 64 42 4
62 8 63 46 68
62 9 85 46 36
62 9 84 42 4
62 9 83 37 4
62 9 82 37 4
62 9 81 35 4
62 9 80 37 4
62 9 79 37 4
62 9 78 35 4
62 9 77 37 4
62 9 76 37 4
62 9 75 35 4
62 9 74 37 4
62 9 73 37 4
62 9 72 35 4
62 9 71 37 4
62 9 70 37 4
62 9 69 35 4
62 9 68 37 4
62 9 67 37 4
62 9 66 35 4
62 9 65 37 4
62 9 64 42 4
62 9 63 46 68
62 10 85 46 36
62 10 84 42 4
62 10 83 37 4
62 10 82 37 4
62 10 81 35 4
62 10 80 37 4
62 10 79 37 4
62 10 78 35 4
62 10 77 37 4
62 10 76 37 4
62 10 75 35 4
62 10 74 37 4
62 10 73 37 4
62 10 72 35 4
62 10 71 37 4
62 10 70 37 4
62 10 69 35 4
62 10 68 37 4
62 10 67 37 4
62 10 66 35 4
62 10 65 37 4
62 10 64 42 4
62 10 63 46 68
62 11 85 46 36
62 11 84 42 4
62 11 83 37 4
62 11 82 37 4
62 11 81 35 4
62 11 80 37 4
62 11 79 37 4
62 11 78 35 4
62 11 77 37 4
62 11 76 37 4
62 11 75 35 4
62 11 74 37 4
62 11 73 37 4
62 11 72 35 4
62 11 71 37 4
62 11 70 37 4
62 11 69 35 4
62 11 68 37 4
62 11 67 37 4
62 11 66 35 4
62 11 65 37 4
62 11 64 42 4
62 11 63 46 68
62 12 85 46 36
62 12 84 42 4
62 12 83 37 4
62 12 82 37 4
62 12 81 35 4
62 12 80 37 4
62 12 79 37 4
62 12 78 35 4
62 12 77 37 4
62 12 76 37 4
62 12 75 35 4
62 12 74 37 4
62 12 73 37 4
62 12 72 35 4
62 12 71 37 4
62 12 70 37 4
62 12 69 35 4
62 12 68 37 4
62 12 67 37 4
62 12 66 35 4
62 12 65 37 4
62 12 64 42 4
62 12 63 46 68
62 13 85 46 36
62 13 84 42 4
62 13 83 37 4
62 13 82 37 4
62 13 81 35 4
62 13 80 37 4
62 13 79 37 4
62 13 78 35 4
62 13 77 37 4
62 13 76 37 4
62 13 75 35 4
62 13 74 37 4
62 13 73 37 4
62 13 72 35 4
62 13 71 37 4
62 13 70 37 4
62 13 69 35 4
62 13 68 37 4
62 13 67 37 4
62 13 66 35 4
62 13 65 37 4
62 13 64 42 4
62 13 63 46 68
62 14 85 46 36
62 14 84 42 4
62 14 83 37 4
62 14 82 37 4
62 14 81 35 4
62 14 80 37 4
62 14 79 37 4
62 14 78 35 4
62 14 77 37 4
62 14 76 37 4
62 14 75 35 4
62 14 74 37 4
62 14 73 37 4
62 14 72 35 4
62 14 71 37 4
62 14 70 37 4
62 14 69 35 4
62 14 68 37 4
62 14 67 37 4
62 14 66 35 4
62 14 65 37 4
62 14 64 42 4
62 14 63 46 68
62 15 85 46 36
62 15 84 42 4
62 15 83 37 4
62 15 82 37 4
62 15 81 35 4
62 15 80 37 4
62 15 79 37 4
62 15 78 35 4
62 15 77 37 4
62 15 76 37 4
62 15 75 35 4
62 15 74 37 4
62 15 73 37 4
62 15 72 35 4
62 15 71 37 4
62 15 70 37 4
62 15 69 35 4
62 15 68 37 4
62 15 67 37 4
62 15 66 35 4
62 15 65 37 4
62 15 64 42 4
62 15 63 46 68
62 16 85 46 36
62 16 84 42 4
62 16 83 37 4
62 16 82 37 4
62 16 81 35 4
62 16 80 37 4
62 16 79 37 4
62 16 78 35 4
62 16 77 37 4
62 16 76 37 4
62 16 75 35 4
62 16 74 37 4
62 16 73 37 4
62 16 72 35 4
62 16 71 37 4
62 16 70 37 4
62 16 69 35 4
62 16 68 37 4
62 16 67 37 4
62 16 66 35 4
62 16 65 37 4
62 16 64 42 4
62 16 63 46 68
62 17 85 46 36
62 17 84 42 4
62 17 83 42 4
62 17 82 42 4
62 17 81 42 4
62 17 80 42 4
62 17 79 42 4
62 17 78 42 4
62 17 77 42 4
62 17 76 42 4
62 17 75 42 4
62 17 74 42 4
62 17 73 42 4
62 17 72 42 4
62 17 71 42 4
62 17 70 42 4
62 17 69 42 4
62 17 68 42 4
62 17 67 42 4
62 17 66 42 4
62 17 65 42 4
62 17 64 42 4
62 17 63 46 68
62 18 85 42 36
62 18 84 42 4
62 18 83 42 4
62 18 82 42 4
62 18 81 42 4
62 18 80 42 4
62 18 79 42 4
62 18 78 42 4
62 18 77 42 4
62 18 76 42 4
62 18 75 42 4
62 18 74 42 4
62 18 73 42 4
62 18 72 42 4
62 18 71 42 4
62 18 70 42 4
62 18 69 42 4
62 18 68 42 4
62 18 67 42 4
62 18 66 42 4
62 18 65 42 4
62 18 64 42 4
62 18 63 42 68
62 19 86 35 48
62 19 85 35 0
62 19 84 35 0
62 19 83 35 0
62 19 82 35 0
62 19 81 35 0
62 19 80 35 0
62 19 79 35 0
62 19 78 35 0
62 19 77 35 0
62 19 76 35 0
62 19 75 35 0
62 19 74 35 0
62 19 73 35 0
62 19 72 35 0
62 19 71 35 0
62 19 70 35 0
62 19 69 35 0
62 19 68 35 0
62 19 67 35 0
62 19 66 35 0
62 19 65 35 0
62 19 64 35 0
62 19 63 35 64
62 20 87 35 48
62 20 86 35 0
62 20 85 35 0
62 20 84 35 0
62 20 83 35 0
62 20 82 35 0
62 20 81 35 0
62 20 80 35 0
62 20 79 35 0
62 20 78 35 0
62 20 77 35 0
62 20 76 35 0
62 20 75 35 0
62 20 74 35 0
62 20 73 35 0
62 20 72 35 0
62 20 71 35 0
62 20 70 35 0
62 20 69 35 0
62 20 68 35 0
62 20 67 35 0
62 20 66 35 0
62 20 65 35 0
62 20 64 35 0
62 20 63 35 64
62 21 88 35 48
62 21 87 35 0
62 21 86 35 0
62 21 85 35 0
62 21 84 35 0
62 21 83 35 0
62 21 82 35 0
62 21 81 35 0
62 21 80 35 0
62 21 79 35 0
62 21 78 35 0
62 21 77 35 0
62 21 76 35 0
62 21 75 35 0
62 21 74 35 0
62 21 73 35 0
62 21 72 35 0
62 21 71 35 0
62 21 70 35 0
62 21 69 35 0
62 21 68 35 0
62 21 67 35 0
62 21 66 35 0
62 21 65 35 0
62 21 64 35 0
62 21 63 35 64
62 22 89 35 48
62 22 88 35 0
62 22 87 35 0
62 22 86 35 0
62 22 85 35 0
62 22 84 35 0
62 22 83 35 0
62 22 82 35 0
62 22 81 35 0
62 22 80 35 0
62 22 79 35 0
62 22 78 35 0
62 22 77 35 0
62 22 76 35 0
62 22 75 35 0
62 22 74 35 0
62 22 73 35 0
62 22 72 35 0
62 22 71 35 0
62 22 70 35 0
62 22 69 35 0
62 22 68 35 0
62 22 67 35 0
62 22 66 35 0
62 22 65 35 0
62 22 64 35 0
62 22 63 35 64
62 23 89 35 40
62 23 88 24 8
62 23 87 35 8
62 23 86 23 8
62 23 85 23 8
62 23 84 23 8
62 23 83 23 8
62 23 82 23 8
62 23 81 23 8
62 23 80 23 8
62 23 79 23 8
62 23 78 23 8
62 23 77 23 8
62 23 76 23 8
62 23 75 23 8
62 23 74 23 8
62 23 73 23 8
62 23 72 23 8
62 23 71 23 8
62 23 70 23 8
62 23 69 23 8
62 23 68 23 8
62 23 67 23 8
62 23 66 23 8
62 23 65 35 8
62 23 64 24 8
62 23 63 35 72
63 1 85 42 48
63 1 84 42 16
63 1 83 42 16
63 1 82 42 16
63 1 81 42 16
63 1 80 42 16
63 1 79 42 16
63 1 78 42 16
63 1 77 42 16
63 1 76 42 16
63 1 75 42 16
63 1 74 42 16
63 1 73 42 16
63 1 72 42 16
63 1 71 42 16
63 1 70 42 16
63 1 69 42 16
63 1 68 42 16
63 1 67 42 16
63 1 66 42 16
63 1 65 42 16
63 1 64 42 16
63 1 63 42 80
63 2 85 42 32
63 2 84 42 0
63 2 83 42 0
63 2 82 42 0
63 2 81 42 0
63 2 80 42 0
63 2 79 42 0
63 2 78 42 0
63 2 77 42 0
63 2 76 42 0
63 2 75 42 0
63 2 74 42 0
63 2 73 42 0
63 2 72 42 0
63 2 71 42 0
63 2 70 42 0
63 2 69 42 0
63 2 68 42 0
63 2 67 42 0
63 2 66 42 0
63 2 65 42 0
63 2 64 42 0
63 2 63 42 64
63 3 85 42 32
63 3 84 42 0
63 3 83 37 0
63 3 82 37 0
63 3 81 37 0
63 3 80 37 0
63 3 79 37 0
63 3 78 37 0
63 3 77 37 0
63 3 76 37 0
63 3 75 37 0
63 3 74 37 0
63 3 73 37 0
63 3 72 37 0
63 3 71 37 0
63 3 70 37 0
63 3 69 37 0
63 3 68 37 0
63 3 67 37 0
63 3 66 37 0
63 3 65 37 0
63 3 64 42 0
63 3 63 42 64
63 4 85 42 32
63 4 84 42 0
63 4 83 37 0
63 4 82 37 0
63 4 81 37 0
63 4 80 37 0
63 4 79 37 0
63 4 78 37 0
63 4 77 37 0
63 4 76 37 0
63 4 75 37 0
63 4 74 37 0
63 4 73 37 0
63 4 72 37 0
63 4 71 37 0
63 4 70 37 0
63 4 69 37 0
63 4 68 37 0
63 4 67 37 0
63 4 66 37 0
63 4 65 37 0
63 4 64 42 0
63 4 63 42 64
63 5 85 42 32
63 5 84 42 0
63 5 83 37 0
63 5 82 37 0
63 5 81 37 0
63 5 80 37 0
63 5 79 37 0
63 5 78 37 0
63 5 77 37 0
63 5 76 37 0
63 5 75 37 0
63 5 74 37 0
63 5 73 37 0
63 5 72 37 0
63 5 71 37 0
63 5 70 37 0
63 5 69 37 0
63 5 68 37 0
63 5 67 37 0
63 5 66 37 0
63 5 65 37 0
63 5 64 42 0
63 5 63 42 64
63 6 85 42 32
63 6 84 42 0
63 6 83 37 0
63 6 82 37 0
63 6 81 37 0
63 6 80 37 0
63 6 79 37 0
63 6 78 37 0
63 6 77 37 0
63 6 76 37 0
63 6 75 37 0
63 6 74 37 0
63 6 73 37 0
63 6 72 37 0
63 6 71 37 0
63 6 70 37 0
63 6 69 37 0
63 6 68 37 0
63 6 67 37 0
63 6 66 37 0
63 6 65 37 0
63 6 64 42 0
63 6 63 42 64
63 7 89 55 120
63 7 85 42 32
63 7 84 42 0
63 7 83 37 0
63 7 82 37 0
63 7 81 37 0
63 7 80 37 0
63 7 79 37 0
63 7 78 37 0
63 7 77 37 0
63 7 76 37 0
63 7 75 37 0
63 7 74 37 0
63 7 73 37 0
63 7 72 37 0
63 7 71 37 0
63 7 70 37 0
63 7 69 37 0
63 7 68 37 0
63 7 67 37 0
63 7 66 37 0
63 7 65 37 0
63 7 64 42 0
63 7 63 42 64
63 8 85 42 32
63 8 84 42 0
63 8 83 37 0
63 8 82 37 0
63 8 81 37 0
63 8 80 37 0
63 8 79 37 0
63 8 78 37 0
63 8 77 37 0
63 8 76 37 0
63 8 75 37 0
63 8 74 37 0
63 8 73 37 0
63 8 72 37 0
63 8 71 37 0
63 8 70 37 0
63 8 69 37 0
63 8 68 37 0
63 8 67 37 0
63 8 66 37 0
63 8 65 37 0
63 8 64 42 0
63 8 63 42 64
63 9 85 42 32
63 9 84 42 0
63 9 83 37 0
63 9 82 37 0
63 9 81 37 0
63 9 80 37 0
63 9 79 37 0
63 9 78 37 0
63 9 77 37 0
63 9 76 37 0
63 9 75 37 0
63 9 74 37 0
63 9 73 37 0
63 9 72 37 0
63 9 71 37 0
63 9 70 37 0
63 9 69 37 0
63 9 68 37 0
63 9 67 37 0
63 9 66 37 0
63 9 65 37 0
63 9 64 42 0
63 9 63 42 64
63 10 85 42 32
63 10 84 42 0
63 10 83 37 0
63 10 82 37 0
63 10 81 37 0
63 10 80 37 0
63 10 79 37 0
63 10 78 37 0
63 10 77 37 0
63 10 76 37 0
63 10 75 37 0
63 10 74 37 0
63 10 73 37 0
63 10 72 37 0
63 10 71 37 0
63 10 70 37 0
63 10 69 37 0
63 10 68 37 0
63 10 67 37 0
63 10 66 37 0
63 10 65 37 0
63 10 64 42 0
63 10 63 42 64
63 11 85 42 32
63 11 84 42 0
63 11 83 37 0
63 11 82 37 0
63 11 81 37 0
63 11 80 37 0
63 11 79 37 0
63 11 78 37 0
63 11 77 37 0
63 11 76 37 0
63 11 75 37 0
63 11 74 37 0
63 11 73 37 0
63 11 72 37 0
63 11 71 37 0
63 11 70 37 0
63 11 69 37 0
63 11 68 37 0
63 11 67 37 0
63 11 66 37 0
63 11 65 37 0
63 11 64 42 0
63 11 63 42 64
63 12 85 42 32
63 12 84 42 0
63 12 83 37 0
63 12 82 37 0
63 12 81 37 0
63 12 80 37 0
63 12 79 37 0
63 12 78 37 0
63 12 77 37 0
63 12 76 37 0
63 12 75 37 0
63 12 74 37 0
63 12 73 37 0
63 12 72 37 0
63 12 71 37 0
63 12 70 37 0
63 12 69 37 0
63 12 68 37 0
63 12 67 37 0
63 12 66 37 0
63 12 65 37 0
63 12 64 42 0
63 12 63 42 64
63 13 85 42 32
63 13 84 42 0
63 13 83 37 0
63 13 82 37 0
63 13 81 37 0
63 13 80 37 0
63 13 79 37 0
63 13 78 37 0
63 13 77 37 0
63 13 76 37 0
63 13 75 37 0
63 13 74 37 0
63 13 73 37 0
63 13 72 37 0
63 13 71 37 0
63 13 70 37 0
63 13 69 37 0
63 13 68 37 0
63 13 67 37 0
63 13 66 37 0
63 13 65 37 0
63 13 64 42 0
63 13 63 42 64
63 14 85 42 32
63 14 84 42 0
63 14 83 37 0
63 14 82 37 0
63 14 81 37 0
63 14 80 37 0
63 14 79 37 0
63 14 78 37 0
63 14 77 37 0
63 14 76 37 0
63 14 75 37 0
63 14 74 37 0
63 14 73 37 0
63 14 72 37 0
63 14 71 37 0
63 14 70 37 0
63 14 69 37 0
63 14 68 37 0
63 14 67 37 0
63 14 66 37 0
63 14 65 37 0
63 14 64 42 0
63 14 63 42 64
63 15 85 42 32
63 15 84 42 0
63 15 83 37 0
63 15 82 37 0
63 15 81 37 0
63 15 80 37 0
63 15 79 37 0
63 15 78 37 0
63 15 77 37 0
63 15 76 37 0
63 15 75 37 0
63 15 74 37 0
63 15 73 37 0
63 15 72 37 0
63 15 71 37 0
63 15 70 37 0
63 15 69 37 0
63 15 68 37 0
63 15 67 37 0
63 15 66 37 0
63 15 65 37 0
63 15 64 42 0
63 15 63 42 64
63 16 85 42 32
63 16 84 42 0
63 16 83 37 0
63 16 82 37 0
63 16 81 37 0
63 16 80 37 0
63 16 79 37 0
63 16 78 37 0
63 16 77 37 0
63 16 76 37 0
63 16 75 37 0
63 16 74 37 0
63 16 73 37 0
63 16 72 37 0
63 16 71 37 0
63 16 70 37 0
63 16 69 37 0
63 16 68 37 0
63 16 67 37 0
63 16 66 37 0
63 16 65 37 0
63 16 64 42 0
63 16 63 42 64
63 17 85 42 32
63 17 84 42 0
63 17 83 42 0
63 17 82 42 0
63 17 81 42 0
63 17 80 42 0
63 17 79 42 0
63 17 78 42 0
63 17 77 42 0
63 17 76 42 0
63 17 75 42 0
63 17 74 42 0
63 17 73 42 0
63 17 72 42 0
63 17 71 42 0
63 17 70 42 0
63 17 69 42 0
63 17 68 42 0
63 17 67 42 0
63 17 66 42 0
63 17 65 42 0
63 17 64 42 0
63 17 63 42 64
63 18 85 42 32
63 18 84 42 0
63 18 83 42 0
63 18 82 42 0
63 18 81 42 0
63 18 80 42 0
63 18 79 42 0
63 18 78 42 0
63 18 77 42 0
63 18 76 42 0
63 18 75 42 0
63 18 74 42 0
63 18 73 42 0
63 18 72 42 0
63 18 71 42 0
63 18 70 42 0
63 18 69 42 0
63 18 68 42 0
63 18 67 42 0
63 18 66 42 0
63 18 65 42 0
63 18 64 42 0
63 18 63 42 64
63 19 86 35 48
63 19 85 35 0
63 19 84 35 0
63 19 83 35 0
63 19 82 35 0
63 19 81 35 0
63 19 80 35 0
63 19 79 35 0
63 19 78 35 0
63 19 77 35 0
63 19 76 35 0
63 19 75 35 0
63 19 74 35 0
63 19 73 35 0
63 19 72 35 0
63 19 71 35 0
63 19 70 35 0
63 19 69 35 0
63 19 68 35 0
63 19 67 35 0
63 19 66 35 0
63 19 65 35 0
63 19 64 35 0
63 19 63 35 64
63 20 87 35 48
63 20 86 35 0
63 20 85 35 0
63 20 84 35 0
63 20 83 35 0
63 20 82 35 0
63 20 81 35 0
63 20 80 35 0
63 20 79 35 0
63 20 78 35 0
63 20 77 35 0
63 20 76 35 0
63 20 75 35 0
63 20 74 35 0
63 20 73 35 0
63 20 72 35 0
63 20 71 35 0
63 20 70 35 0
63 20 69 35 0
63 20 68 35 0
63 20 67 35 0
63 20 66 35 0
63 20 65 35 0
63 20 64 35 0
63 20 63 35 64
63 21 88 35 48
63 21 87 35 0
63 21 86 35 0
63 21 85 35 0
63 21 84 35 0
63 21 83 35 0
63 21 82 35 0
63 21 81 35 0
63 21 80 35 0
63 21 79 35 0
63 21 78 35 0
63 21 77 35 0
63 21 76 35 0
63 21 75 35 0
63 21 74 35 0
63 21 73 35 0
63 21 72 35 0
63 21 71 35 0
63 21 70 35 0
63 21 69 35 0
63 21 68 35 0
63 21 67 35 0
63 21 66 35 0
63 21 65 35 0
63 21 64 35 0
63 21 63 35 64
63 22 89 35 48
63 22 88 35 0
63 22 87 35 0
63 22 86 35 0
63 22 85 35 0
63 22 84 35 0
63 22 83 35 0
63 22 82 35 0
63 22 81 35 0
63 22 80 35 0
63 22 79 35 0
63 22 78 35 0
63 22 77 35 0
63 22 76 35 0
63 22 75 35 0
63 22 74 35 0
63 22 73 35 0
63 22 72 35 0
63 22 71 35 0
63 22 70 35 0
63 22 69 35 0
63 22 68 35 0
63 22 67 35 0
63 22 66 35 0
63 22 65 35 0
63 22 64 35 0
63 22 63 35 64
63 23 89 35 40
63 23 88 24 8
63 23 87 35 8
63 23 86 23 8
63 23 85 23 8
63 23 84 23 8
63 23 83 23 8
63 23 82 23 8
63 23 81 23 8
63 23 80 23 8
63 23 79 23 8
63 23 78 23 8
63 23 77 23 8
63 23 76 23 8
63 23 75 23 8
63 23 74 23 8
63 23 73 23 8
63 23 72 23 8
63 23 71 23 8
63 23 70 23 8
63 23 69 23 8
63 23 68 23 8
63 23 67 23 8
63 23 66 23 8
63 23 65 35 8
63 23 64 24 8
63 23 63 35 72
64 1 85 42 48
64 1 84 42 16
64 1 83 42 16
64 1 82 42 16
64 1 81 42 16
64 1 80 42 16
64 1 79 42 16
64 1 78 42 16
64 1 77 42 16
64 1 76 42 16
64 1 75 42 16
64 1 74 42 16
64 1 73 42 16
64 1 72 42 16
64 1 71 42 16
64 1 70 42 16
64 1 69 42 16
64 1 68 42 16
64 1 67 42 16
64 1 66 42 16
64 1 65 42 16
64 1 64 42 16
64 1 63 42 80
64 2 85 42 32
64 2 84 42 0
64 2 83 42 0
64 2 82 42 0
64 2 81 42 0
64 2 80 42 0
64 2 79 42 0
64 2 78 42 0
64 2 77 42 0
64 2 76 42 0
64 2 75 42 0
64 2 74 42 0
64 2 73 42 0
64 2 72 42 0
64 2 71 42 0
64 2 70 42 0
64 2 69 42 0
64 2 68 42 0
64 2 67 42 0
64 2 66 42 0
64 2 65 42 0
64 2 64 42 0
64 2 63 42 64
64 3 85 37 32
64 3 84 37 0
64 3 83 37 0
64 3 82 37 0
64 3 81 37 0
64 3 80 37 0
64 3 79 37 0
64 3 78 37 0
64 3 77 37 0
64 3 76 37 0
64 3 75 37 0
64 3 74 37 0
64 3 73 37 0
64 3 72 37 0
64 3 71 37 0
64 3 70 37 0
64 3 69 37 0
64 3 68 37 0
64 3 67 37 0
64 3 66 37 0
64 3 65 37 0
64 3 64 37 0
64 3 63 37 64
64 4 85 37 32
64 4 84 37 0
64 4 83 37 0
64 4 82 37 0
64 4 81 37 0
64 4 80 37 0
64 4 79 37 0
64 4 78 37 0
64 4 77 37 0
64 4 76 37 0
64 4 75 37 0
64 4 74 37 0
64 4 73 37 0
64 4 72 37 0
64 4 71 37 0
64 4 70 37 0
64 4 69 37 0
64 4 68 37 0
64 4 67 37 0
64 4 66 37 0
64 4 65 37 0
64 4 64 37 0
64 4 63 37 64
64 5 85 37 32
64 5 84 37 0
64 5 83 37 0
64 5 82 37 0
64 5 81 37 0
64 5 80 37 0
64 5 79 37 0
64 5 78 37 0
64 5 77 37 0
64 5 76 37 0
64 5 75 37 0
64 5 74 37 0
64 5 73 37 0
64 5 72 37 0
64 5 71 37 0
64 5 70 37 0
64 5 69 37 0
64 5 68 37 0
64 5 67 37 0
64 5 66 37 0
64 5 65 37 0
64 5 64 37 0
64 5 63 37 64
64 6 85 37 32
64 6 84 37 0
64 6 83 37 0
64 6 82 37 0
64 6 81 37 0
64 6 80 37 0
64 6 79 37 0
64 6 78 37 0
64 6 77 37 0
64 6 76 37 0
64 6 75 37 0
64 6 74 37 0
64 6 73 37 0
64 6 72 37 0
64 6 71 37 0
64 6 70 37 0
64 6 69 37 0
64 6 68 37 0
64 6 67 37 0
64 6 66 37 0
64 6 65 37 0
64 6 64 37 0
64 6 63 37 64
64 7 89 55 120
64 7 85 37 32
64 7 84 37 0
64 7 83 37 0
64 7 82 37 0
64 7 81 37 0
64 7 80 37 0
64 7 79 37 0
64 7 78 37 0
64 7 77 37 0
64 7 76 37 0
64 7 75 37 0
64 7 74 37 0
64 7 73 37 0
64 7 72 37 0
64 7 71 37 0
64 7 70 37 0
64 7 69 37 0
64 7 68 37 0
64 7 67 37 0
64 7 66 37 0
64 7 65 37 0
64 7 64 37 0
64 7 63 37 64
64 8 85 37 32
64 8 84 37 0
64 8 83 37 0
64 8 82 37 0
64 8 81 37 0
64 8 80 37 0
64 8 79 37 0
64 8 78 37 0
64 8 77 37 0
64 8 76 37 0
64 8 75 37 0
64 8 74 37 0
64 8 73 37 0
64 8 72 37 0
64 8 71 37 0
64 8 70 37 0
64 8 69 37 0
64 8 68 37 0
64 8 67 37 0
64 8 66 37 0
64 8 65 37 0
64 8 64 37 0
64 8 63 37 64
64 9 85 37 32
64 9 84 37 0
64 9 83 37 0
64 9 82 37 0
64 9 81 37 0
64 9 80 37 0
64 9 79 37 0
64 9 78 37 0
64 9 77 37 0
64 9 76 37 0
64 9 75 37 0
64 9 74 37 0
64 9 73 37 0
64 9 72 37 0
64 9 71 37 0
64 9 70 37 0
64 9 69 37 0
64 9 68 37 0
64 9 67 37 0
64 9 66 37 0
64 9 65 37 0
64 9 64 37 0
64 9 63 37 64
64 10 85 37 32
64 10 84 37 0
64 10 83 37 0
64 10 82 37 0
64 10 81 37 0
64 10 80 37 0
64 10 79 37 0
64 10 78 37 0
64 10 77 37 0
64 10 76 37 0
64 10 75 37 0
64 10 74 37 0
64 10 73 37 0
64 10 72 37 0
64 10 71 37 0
64 10 70 37 0
64 10 69 37 0
64 10 68 37 0
64 10 67 37 0
64 10 66 37 0
64 10 65 37 0
64 10 64 37 0
64 10 63 37 64
64 11 85 37 32
64 11 84 37 0
64 11 83 37 0
64 11 82 37 0
64 11 81 37 0
64 11 80 37 0
64 11 79 37 0
64 11 78 37 0
64 11 77 37 0
64 11 76 37 0
64 11 75 37 0
64 11 74 37 0
64 11 73 37 0
64 11 72 37 0
64 11 71 37 0
64 11 70 37 0
64 11 69 37 0
64 11 68 37 0
64 11 67 37 0
64 11 66 37 0
64 11 65 37 0
64 11 64 37 0
64 11 63 37 64
64 12 85 37 32
64 12 84 37 0
64 12 83 37 0
64 12 82 37 0
64 12 81 37 0
64 12 80 37 0
64 12 79 37 0
64 12 78 37 0
64 12 77 37 0
64 12 76 37 0
64 12 75 37 0
64 12 74 37 0
64 12 73 37 0
64 12 72 37 0
64 12 71 37 0
64 12 70 37 0
64 12 69 37 0
64 12 68 37 0
64 12 67 37 0
64 12 66 37 0
64 12 65 37 0
64 12 64 37 0
64 12 63 37 64
64 13 85 37 32
64 13 84 37 0
64 13 83 37 0
64 13 82 37 0
64 13 81 37 0
64 13 80 37 0
64 13 79 37 0
64 13 78 37 0
64 13 77 37 0
64 13 76 37 0
64 13 75 37 0
64 13 74 37 0
64 13 73 37 0
64 13 72 37 0
64 13 71 37 0
64 13 70 37 0
64 13 69 37 0
64 13 68 37 0
64 13 67 37 0
64 13 66 37 0
64 13 65 37 0
64 13 64 37 0
64 13 63 37 64
64 14 85 37 32
64 14 84 37 0
64 14 83 37 0
64 14 82 37 0
64 14 81 37 0
64 14 80 37 0
64 14 79 37 0
64 14 78 37 0
64 14 77 37 0
64 14 76 37 0
64 14 75 37 0
64 14 74 37 0
64 14 73 37 0
64 14 72 37 0
64 14 71 37 0
64 14 70 37 0
64 14 69 37 0
64 14 68 37 0
64 14 67 37 0
64 14 66 37 0
64 14 65 37 0
64 14 64 37 0
64 14 63 37 64
64 15 85 37 32
64 15 84 37 0
64 15 83 37 0
64 15 82 37 0
64 15 81 37 0
64 15 80 37 0
64 15 79 37 0
64 15 78 37 0
64 15 77 37 0
64 15 76 37 0
64 15 75 37 0
64 15 74 37 0
64 15 73 37 0
64 15 72 37 0
64 15 71 37 0
64 15 70 37 0
64 15 69 37 0
64 15 68 37 0
64 15 67 37 0
64 15 66 37 0
64 15 65 37 0
64 15 64 37 0
64 15 63 37 64
64 16 85 37 32
64 16 84 37 0
64 16 83 37 0
64 16 82 37 0
64 16 81 37 0
64 16 80 37 0
64 16 79 37 0
64 16 78 37 0
64 16 77 37 0
64 16 76 37 0
64 16 75 37 0
64 16 74 37 0
64 16 73 37 0
64 16 72 37 0
64 16 71 37 0
64 16 70 37 0
64 16 69 37 0
64 16 68 37 0
64 16 67 37 0
64 16 66 37 0
64 16 65 37 0
64 16 64 37 0
64 16 63 37 64
64 17 85 42 32
64 17 84 42 0
64 17 83 42 0
64 17 82 42 0
64 17 81 42 0
64 17 80 42 0
64 17 79 42 0
64 17 78 42 0
64 17 77 42 0
64 17 76 42 0
64 17 75 42 0
64 17 74 42 0
64 17 73 42 0
64 17 72 42 0
64 17 71 42 0
64 17 70 42 0
64 17 69 42 0
64 17 68 42 0
64 17 67 42 0
64 17 66 42 0
64 17 65 42 0
64 17 64 42 0
64 17 63 42 64
64 18 85 42 32
64 18 84 42 0
64 18 83 42 0
64 18 82 42 0
64 18 81 42 0
64 18 80 42 0
64 18 79 42 0
64 18 78 42 0
64 18 77 42 0
64 18 76 42 0
64 18 75 42 0
64 18 74 42 0
64 18 73 42 0
64 18 72 42 0
64 18 71 42 0
64 18 70 42 0
64 18 69 42 0
64 18 68 42 0
64 18 67 42 0
64 18 66 42 0
64 18 65 42 0
64 18 64 42 0
64 18 63 42 64
64 19 86 35 48
64 19 85 35 0
64 19 84 35 0
64 19 83 35 0
64 19 82 35 0
64 19 81 35 0
64 19 80 35 0
64 19 79 35 0
64 19 78 35 0
64 19 77 35 0
64 19 76 35 0
64 19 75 35 0
64 19 74 35 0
64 19 73 35 0
64 19 72 35 0
64 19 71 35 0
64 19 70 35 0
64 19 69 35 0
64 19 68 35 0
64 19 67 35 0
64 19 66 35 0
64 19 65 35 0
64 19 64 35 0
64 19 63 35 64
64 20 87 35 48
64 20 86 35 0
64 20 85 35 0
64 20 84 35 0
64 20 83 35 0
64 20 82 35 0
64 20 81 35 0
64 20 80 35 0
64 20 79 35 0
64 20 78 35 0
64 20 77 35 0
64 20 76 35 0
64 20 75 35 0
64 20 74 35 0
64 20 73 35 0
64 20 72 35 0
64 20 71 35 0
64 20 70 35 0
64 20 69 35 0
64 20 68 35 0
64 20 67 35 0
64 20 66 35 0
64 20 65 35 0
64 20 64 35 0
64 20 63 35 64
64 21 88 35 48
64 21 87 35 0
64 21 86 35 0
64 21 85 35 0
64 21 84 35 0
64 21 83 35 0
64 21 82 35 0
64 21 81 35 0
64 21 80 35 0
64 21 79 35 0
64 21 78 35 0
64 21 77 35 0
64 21 76 35 0
64 21 75 35 0
64 21 74 35 0
64 21 73 35 0
64 21 72 35 0
64 21 71 35 0
64 21 70 35 0
64 21 69 35 0
64 21 68 35 0
64 21 67 35 0
64 21 66 35 0
64 21 65 35 0
64 21 64 35 0
64 21 63 35 64
64 22 89 35 48
64 22 88 35 0
64 22 87 35 0
64 22 86 35 0
64 22 85 35 0
64 22 84 35 0
64 22 83 35 0
64 22 82 35 0
64 22 81 35 0
64 22 80 35 0
64 22 79 35 0
64 22 78 35 0
64 22 77 35 0
64 22 76 35 0
64 22 75 35 0
64 22 74 35 0
64 22 73 35 0
64 22 72 35 0
64 22 71 35 0
64 22 70 35 0
64 22 69 35 0
64 22 68 35 0
64 22 67 35 0
64 22 66 35 0
64 22 65 35 0
64 22 64 35 0
64 22 63 35 64
64 23 89 35 40
64 23 88 24 8
64 23 87 35 8
64 23 86 23 8
64 23 85 23 8
64 23 84 23 8
64 23 83 23 8
64 23 82 23 8
64 23 81 23 8
64 23 80 23 8
64 23 79 23 8
64 23 78 23 8
64 23 77 23 8
64 23 76 23 8
64 23 75 23 8
64 23 74 23 8
64 23 73 23 8
64 23 72 23 8
64 23 71 23 8
64 23 70 23 8
64 23 69 23 8
64 23 68 23 8
64 23 67 23 8
64 23 66 23 8
64 23 65 35 8
64 23 64 24 8
64 23 63 35 72
65 1 85 42 48
65 1 84 42 16
65 1 83 42 16
65 1 82 39 16
65 1 81 39 16
65 1 80 39 16
65 1 79 39 16
65 1 78 39 16
65 1 77 39 16
65 1 76 39 16
65 1 75 39 16
65 1 74 39 16
65 1 73 39 16
65 1 72 39 16
65 1 71 39 16
65 1 70 39 16
65 1 69 42 16
65 1 68 42 16
65 1 67 42 16
65 1 66 42 16
65 1 65 42 16
65 1 64 42 16
65 1 63 42 80
65 2 85 42 32
65 2 84 42 0
65 2 83 42 0
65 2 82 39 0
65 2 81 39 0
65 2 80 39 0
65 2 79 39 0
65 2 78 39 0
65 2 77 39 0
65 2 76 39 0
65 2 75 39 0
65 2 74 39 0
65 2 73 39 0
65 2 72 39 0
65 2 71 39 0
65 2 70 39 0
65 2 69 42 0
65 2 68 42 0
65 2 67 42 0
65 2 66 42 0
65 2 65 42 0
65 2 64 42 0
65 2 63 42 64
65 3 85 37 32
65 3 84 37 0
65 3 83 37 0
65 3 82 39 0
65 3 81 39 0
65 3 80 39 0
65 3 79 39 0
65 3 78 39 0
65 3 77 39 0
65 3 76 39 0
65 3 75 39 0
65 3 74 39 0
65 3 73 39 0
65 3 72 39 0
65 3 71 39 0
65 3 70 39 0
65 3 69 37 0
65 3 68 37 0
65 3 67 37 0
65 3 66 37 0
65 3 65 37 0
65 3 64 37 0
65 3 63 37 64
65 4 85 37 32
65 4 84 37 0
65 4 83 37 0
65 4 82 39 0
65 4 81 39 0
65 4 80 39 0
65 4 79 39 0
65 4 78 39 0
65 4 77 39 0
65 4 76 39 0
65 4 75 39 0
65 4 74 39 0
65 4 73 39 0
65 4 72 39 0
65 4 71 39 0
65 4 70 39 0
65 4 69 37 0
65 4 68 37 0
65 4 67 37 0
65 4 66 37 0
65 4 65 37 0
65 4 64 37 0
65 4 63 37 64
65 5 85 37 32
65 5 84 37 0
65 5 83 37 0
65 5 82 39 0
65 5 81 39 0
65 5 80 39 0
65 5 79 39 0
65 5 78 39 0
65 5 77 39 0
65 5 76 39 0
65 5 75 39 0
65 5 74 39 0
65 5 73 39 0
65 5 72 39 0
65 5 71 39 0
65 5 70 39 0
65 5 69 37 0
65 5 68 37 0
65 5 67 37 0
65 5 66 37 0
65 5 65 37 0
65 5 64 37 0
65 5 63 37 64
65 6 85 37 32
65 6 84 37 0
65 6 83 37 0
65 6 82 39 0
65 6 81 39 0
65 6 80 39 0
65 6 79 39 0
65 6 78 39 0
65 6 77 39 0
65 6 76 39 0
65 6 75 39 0
65 6 74 39 0
65 6 73 39 0
65 6 72 39 0
65 6 71 39 0
65 6 70 39 0
65 6 69 37 0
65 6 68 37 0
65 6 67 37 0
65 6 66 37 0
65 6 65 37 0
65 6 64 37 0
65 6 63 37 64
65 7 89 55 120
65 7 85 37 32
65 7 84 37 0
65 7 83 37 0
65 7 82 39 0
65 7 81 39 0
65 7 80 39 0
65 7 79 39 0
65 7 78 39 0
65 7 77 39 0
65 7 76 39 0
65 7 75 39 0
65 7 74 39 0
65 7 73 39 0
65 7 72 39 0
65 7 71 39 0
65 7 70 39 0
65 7 69 37 0
65 7 68 37 0
65 7 67 37 0
65 7 66 37 0
65 7 65 37 0
65 7 64 37 0
65 7 63 37 64
65 8 85 37 32
65 8 84 37 0
65 8 83 37 0
65 8 82 39 0
65 8 81 39 0
65 8 80 39 0
65 8 79 39 0
65 8 78 39 0
65 8 77 39 0
65 8 76 39 0
65 8 75 39 0
65 8 74 39 0
65 8 73 39 0
65 8 72 39 0
65 8 71 39 0
65 8 70 39 0
65 8 69 37 0
65 8 68 37 0
65 8 67 37 0
65 8 66 37 0
65 8 65 37 0
65 8 64 37 0
65 8 63 37 64
65 9 85 37 32
65 9 84 37 0
65 9 83 37 0
65 9 82 39 0
65 9 81 39 0
65 9 80 39 0
65 9 79 39 0
65 9 78 39 0
65 9 77 39 0
65 9 76 39 0
65 9 75 39 0
65 9 74 39 0
65 9 73 39 0
65 9 72 39 0
65 9 71 39 0
65 9 70 39 0
65 9 69 37 0
65 9 68 37 0
65 9 67 37 0
65 9 66 37 0
65 9 65 37 0
65 9 64 37 0
65 9 63 37 64
65 10 85 37 32
65 10 84 37 0
65 10 83 37 0
65 10 82 39 0
65 10 81 39 0
65 10 80 39 0
65 10 79 39 0
65 10 78 39 0
65 10 77 39 0
65 10 76 39 0
65 10 75 39 0
65 10 74 39 0
65 10 73 39 0
65 10 72 39 0
65 10 71 39 0
65 10 70 39 0
65 10 69 37 0
65 10 68 37 0
65 10 67 37 0
65 10 66 37 0
65 10 65 37 0
65 10 64 37 0
65 10 63 37 64
65 11 85 37 32
65 11 84 37 0
65 11 83 37 0
65 11 82 39 0
65 11 81 39 0
65 11 80 39 0
65 11 79 39 0
65 11 78 39 0
65 11 77 39 0
65 11 76 39 0
65 11 75 39 0
65 11 74 39 0
65 11 73 39 0
65 11 72 39 0
65 11 71 39 0
65 11 70 39 0
65 11 69 37 0
65 11 68 37 0
65 11 67 37 0
65 11 66 37 0
65 11 65 37 0
65 11 64 37 0
65 11 63 37 64
65 12 85 37 32
65 12 84 37 0
65 12 83 37 0
65 12 82 39 0
65 12 81 39 0
65 12 80 39 0
65 12 79 39 0
65 12 78 39 0
65 12 77 39 0
65 12 76 39 0
65 12 75 39 0
65 12 74 39 0
65 12 73 39 0
65 12 72 39 0
65 12 71 39 0
65 12 70 39 0
65 12 69 37 0
65 12 68 37 0
65 12 67 37 0
65 12 66 37 0
65 12 65 37 0
65 12 64 37 0
65 12 63 37 64
65 13 85 37 32
65 13 84 37 0
65 13 83 37 0
65 13 82 39 0
65 13 81 39 0
65 13 80 39 0
65 13 79 39 0
65 13 78 39 0
65 13 77 39 0
65 13 76 39 0
65 13 75 39 0
65 13 74 39 0
65 13 73 39 0
65 13 72 39 0
65 13 71 39 0
65 13 70 39 0
65 13 69 37 0
65 13 68 37 0
65 13 67 37 0
65 13 66 37 0
65 13 65 37 0
65 13 64 37 0
65 13 63 37 64
65 14 85 37 32
65 14 84 37 0
65 14 83 37 0
65 14 82 39 0
65 14 81 39 0
65 14 80 39 0
65 14 79 39 0
65 14 78 39 0
65 14 77 39 0
65 14 76 39 0
65 14 75 39 0
65 14 74 39 0
65 14 73 39 0
65 14 72 39 0
65 14 71 39 0
65 14 70 39 0
65 14 69 37 0
65 14 68 37 0
65 14 67 37 0
65 14 66 37 0
65 14 65 37 0
65 14 64 37 0
65 14 63 37 64
65 15 85 37 32
65 15 84 37 0
65 15 83 37 0
65 15 82 39 0
65 15 81 39 0
65 15 80 39 0
65 15 79 39 0
65 15 78 39 0
65 15 77 39 0
65 15 76 39 0
65 15 75 39 0
65 15 74 39 0
65 15 73 39 0
65 15 72 39 0
65 15 71 39 0
65 15 70 39 0
65 15 69 37 0
65 15 68 37 0
65 15 67 37 0
65 15 66 37 0
65 15 65 37 0
65 15 64 37 0
65 15 63 37 64
65 16 85 37 32
65 16 84 37 0
65 16 83 37 0
65 16 82 39 0
65 16 81 39 0
65 16 80 39 0
65 16 79 39 0
65 16 78 39 0
65 16 77 39 0
65 16 76 39 0
65 16 75 39 0
65 16 74 39 0
65 16 73 39 0
65 16 72 39 0
65 16 71 39 0
65 16 70 39 0
65 16 69 37 0
65 16 68 37 0
65 16 67 37 0
65 16 66 37 0
65 16 65 37 0
65 16 64 37 0
65 16 63 37 64
65 17 85 42 32
65 17 84 42 0
65 17 83 42 0
65 17 82 39 0
65 17 81 39 0
65 17 80 39 0
65 17 79 39 0
65 17 78 39 0
65 17 77 39 0
65 17 76 39 0
65 17 75 39 0
65 17 74 39 0
65 17 73 39 0
65 17 72 39 0
65 17 71 39 0
65 17 70 39 0
65 17 69 42 0
65 17 68 42 0
65 17 67 42 0
65 17 66 42 0
65 17 65 42 0
65 17 64 42 0
65 17 63 42 64
65 18 85 42 32
65 18 84 42 0
65 18 83 42 0
65 18 82 39 0
65 18 81 39 0
65 18 80 39 0
65 18 79 39 0
65 18 78 39 0
65 18 77 39 0
65 18 76 39 0
65 18 75 39 0
65 18 74 39 0
65 18 73 39 0
65 18 72 39 0
65 18 71 39 0
65 18 70 39 0
65 18 69 42 0
65 18 68 42 0
65 18 67 42 0
65 18 66 42 0
65 18 65 42 0
65 18 64 42 0
65 18 63 42 64
65 19 86 35 48
65 19 85 35 0
65 19 84 35 0
65 19 83 35 0
65 19 82 39 0
65 19 81 39 0
65 19 80 39 0
65 19 79 39 0
65 19 78 39 0
65 19 77 39 0
65 19 76 39 0
65 19 75 39 0
65 19 74 39 0
65 19 73 39 0
65 19 72 39 0
65 19 71 39 0
65 19 70 39 0
65 19 69 35 0
65 19 68 35 0
65 19 67 35 0
65 19 66 35 0
65 19 65 35 0
65 19 64 35 0
65 19 63 35 64
65 20 87 35 48
65 20 86 35 0
65 20 85 35 0
65 20 84 35 0
65 20 83 35 0
65 20 82 39 0
65 20 81 39 0
65 20 80 39 0
65 20 79 39 0
65 20 78 39 0
65 20 77 39 0
65 20 76 39 0
65 20 75 39 0
65 20 74 39 0
65 20 73 39 0
65 20 72 39 0
65 20 71 39 0
65 20 70 39 0
65 20 69 35 0
65 20 68 35 0
65 20 67 35 0
65 20 66 35 0
65 20 65 35 0
65 20 64 35 0
65 20 63 35 64
65 21 88 35 48
65 21 87 35 0
65 21 86 35 0
65 21 85 35 0
65 21 84 35 0
65 21 83 35 0
65 21 82 39 0
65 21 81 39 0
65 21 80 39 0
65 21 79 39 0
65 21 78 39 0
65 21 77 39 0
65 21 76 39 0
65 21 75 39 0
65 21 74 39 0
65 21 73 39 0
65 21 72 39 0
65 21 71 39 0
65 21 70 39 0
65 21 69 35 0
65 21 68 35 0
65 21 67 35 0
65 21 66 35 0
65 21 65 35 0
65 21 64 35 0
65 21 63 35 64
65 22 89 35 48
65 22 88 35 0
65 22 87 35 0
65 22 86 35 0
65 22 85 35 0
65 22 84 35 0
65 22 83 35 0
65 22 82 39 0
65 22 81 39 0
65 22 80 39 0
65 22 79 39 0
65 22 78 39 0
65 22 77 39 0
65 22 76 39 0
65 22 75 39 0
65 22 74 39 0
65 22 73 39 0
65 22 72 39 0
65 22 71 39 0
65 22 70 39 0
65 22 69 35 0
65 22 68 35 0
65 22 67 35 0
65 22 66 35 0
65 22 65 35 0
65 22 64 35 0
65 22 63 35 64
65 23 89 35 40
65 23 88 24 8
65 23 87 35 8
65 23 86 23 8
65 23 85 23 8
65 23 84 23 8
65 23 83 23 8
65 23 82 39 8
65 23 81 39 8
65 23 80 39 8
65 23 79 39 8
65 23 78 39 8
65 23 77 39 8
65 23 76 39 8
65 23 75 39 8
65 23 74 39 8
65 23 73 39 8
65 23 72 39 8
65 23 71 39 8
65 23 70 39 8
65 23 69 23 8
65 23 68 23 8
65 23 67 23 8
65 23 66 23 8
65 23 65 35 8
65 23 64 24 8
65 23 63 35 72
66 1 85 42 48
66 1 84 42 16
66 1 83 42 16
66 1 82 39 16
66 1 81 39 16
66 1 80 39 16
66 1 79 39 16
66 1 78 39 16
66 1 77 39 16
66 1 76 39 16
66 1 75 39 16
66 1 74 39 16
66 1 73 39 16
66 1 72 39 16
66 1 71 39 16
66 1 70 39 16
66 1 69 42 16
66 1 68 42 16
66 1 67 42 16
66 1 66 42 16
66 1 65 42 16
66 1 64 42 16
66 1 63 42 80
66 2 85 42 32
66 2 84 42 0
66 2 83 42 0
66 2 82 39 0
66 2 81 39 0
66 2 80 39 0
66 2 79 39 0
66 2 78 39 0
66 2 77 39 0
66 2 76 39 0
66 2 75 39 0
66 2 74 39 0
66 2 73 39 0
66 2 72 39 0
66 2 71 39 0
66 2 70 39 0
66 2 69 42 0
66 2 68 42 0
66 2 67 42 0
66 2 66 42 0
66 2 65 42 0
66 2 64 42 0
66 2 63 42 64
66 3 85 35 32
66 3 84 37 0
66 3 83 37 0
66 3 82 39 0
66 3 81 39 0
66 3 80 39 0
66 3 79 39 0
66 3 78 39 0
66 3 77 39 0
66 3 76 39 0
66 3 75 39 0
66 3 74 39 0
66 3 73 39 0
66 3 72 39 0
66 3 71 39 0
66 3 70 39 0
66 3 69 37 0
66 3 68 37 0
66 3 67 37 0
66 3 66 37 0
66 3 65 37 0
66 3 64 37 0
66 3 63 37 64
66 4 85 35 32
66 4 84 37 0
66 4 83 37 0
66 4 82 39 0
66 4 81 39 0
66 4 80 39 0
66 4 79 39 0
66 4 78 39 0
66 4 77 39 0
66 4 76 39 0
66 4 75 39 0
66 4 74 39 0
66 4 73 39 0
66 4 72 39 0
66 4 71 39 0
66 4 70 39 0
66 4 69 37 0
66 4 68 37 0
66 4 67 37 0
66 4 66 37 0
66 4 65 37 0
66 4 64 37 0
66 4 63 37 64
66 5 85 35 32
66 5 84 37 0
66 5 83 37 0
66 5 82 39 0
66 5 81 39 0
66 5 80 39 0
66 5 79 39 0
66 5 78 39 0
66 5 77 39 0
66 5 76 39 0
66 5 75 39 0
66 5 74 39 0
66 5 73 39 0
66 5 72 39 0
66 5 71 39 0
66 5 70 39 0
66 5 69 37 0
66 5 68 37 0
66 5 67 37 0
66 5 66 37 0
66 5 65 37 0
66 5 64 37 0
66 5 63 37 64
66 6 85 35 32
66 6 84 37 0
66 6 83 37 0
66 6 82 39 0
66 6 81 39 0
66 6 80 39 0
66 6 79 39 0
66 6 78 39 0
66 6 77 39 0
66 6 76 39 0
66 6 75 39 0
66 6 74 39 0
66 6 73 39 0
66 6 72 39 0
66 6 71 39 0
66 6 70 39 0
66 6 69 37 0
66 6 68 37 0
66 6 67 37 0
66 6 66 37 0
66 6 65 37 0
66 6 64 37 0
66 6 63 37 64
66 7 89 55 120
66 7 85 35 32
66 7 84 37 0
66 7 83 37 0
66 7 82 39 0
66 7 81 39 0
66 7 80 39 0
66 7 79 39 0
66 7 78 39 0
66 7 77 39 0
66 7 76 39 0
66 7 75 39 0
66 7 74 39 0
66 7 73 39 0
66 7 72 39 0
66 7 71 39 0
66 7 70 39 0
66 7 69 37 0
66 7 68 37 0
66 7 67 37 0
66 7 66 37 0
66 7 65 37 0
66 7 64 37 0
66 7 63 37 64
66 8 85 35 32
66 8 84 37 0
66 8 83 37 0
66 8 82 39 0
66 8 81 39 0
66 8 80 39 0
66 8 79 39 0
66 8 78 39 0
66 8 77 39 0
66 8 76 39 0
66 8 75 39 0
66 8 74 39 0
66 8 73 39 0
66 8 72 39 0
66 8 71 39 0
66 8 70 39 0
66 8 69 37 0
66 8 68 37 0
66 8 67 37 0
66 8 66 37 0
66 8 65 37 0
66 8 64 37 0
66 8 63 37 64
66 9 85 35 32
66 9 84 37 0
66 9 83 37 0
66 9 82 39 0
66 9 81 39 0
66 9 80 39 0
66 9 79 39 0
66 9 78 39 0
66 9 77 39 0
66 9 76 39 0
66 9 75 39 0
66 9 74 39 0
66 9 73 39 0
66 9 72 39 0
66 9 71 39 0
66 9 70 39 0
66 9 69 37 0
66 9 68 37 0
66 9 67 37 0
66 9 66 37 0
66 9 65 37 0
66 9 64 37 0
66 9 63 37 64
66 10 85 35 32
66 10 84 37 0
66 10 83 37 0
66 10 82 39 0
66 10 81 39 0
66 10 80 39 0
66 10 79 39 0
66 10 78 39 0
66 10 77 39 0
66 10 76 39 0
66 10 75 39 0
66 10 74 39 0
66 10 73 39 0
66 10 72 39 0
66 10 71 39 0
66 10 70 39 0
66 10 69 37 0
66 10 68 37 0
66 10 67 37 0
66 10 66 37 0
66 10 65 37 0
66 10 64 37 0
66 10 63 37 64
66 11 85 35 32
66 11 84 37 0
66 11 83 37 0
66 11 82 39 0
66 11 81 39 0
66 11 80 39 0
66 11 79 39 0
66 11 78 39 0
66 11 77 39 0
66 11 76 39 0
66 11 75 39 0
66 11 74 39 0
66 11 73 39 0
66 11 72 39 0
66 11 71 39 0
66 11 70 39 0
66 11 69 37 0
66 11 68 37 0
66 11 67 37 0
66 11 66 37 0
66 11 65 37 0
66 11 64 37 0
66 11 63 37 64
66 12 85 35 32
66 12 84 37 0
66 12 83 37 0
66 12 82 39 0
66 12 81 39 0
66 12 80 39 0
66 12 79 39 0
66 12 78 39 0
66 12 77 39 0
66 12 76 39 0
66 12 75 39 0
66 12 74 39 0
66 12 73 39 0
66 12 72 39 0
66 12 71 39 0
66 12 70 39 0
66 12 69 37 0
66 12 68 37 0
66 12 67 37 0
66 12 66 37 0
66 12 65 37 0
66 12 64 37 0
66 12 63 37 64
66 13 85 35 32
66 13 84 37 0
66 13 83 37 0
66 13 82 39 0
66 13 81 39 0
66 13 80 39 0
66 13 79 39 0
66 13 78 39 0
66 13 77 39 0
66 13 76 39 0
66 13 75 39 0
66 13 74 39 0
66 13 73 39 0
66 13 72 39 0
66 13 71 39 0
66 13 70 39 0
66 13 69 37 0
66 13 68 37 0
66 13 67 37 0
66 13 66 37 0
66 13 65 37 0
66 13 64 37 0
66 13 63 37 64
66 14 85 35 32
66 14 84 37 0
66 14 83 37 0
66 14 82 39 0
66 14 81 39 0
66 14 80 39 0
66 14 79 39 0
66 14 78 39 0
66 14 77 39 0
66 14 76 39 0
66 14 75 39 0
66 14 74 39 0
66 14 73 39 0
66 14 72 39 0
66 14 71 39 0
66 14 70 39 0
66 14 69 37 0
66 14 68 37 0
66 14 67 37 0
66 14 66 37 0
66 14 65 37 0
66 14 64 37 0
66 14 63 37 64
66 15 85 35 32
66 15 84 37 0
66 15 83 37 0
66 15 82 39 0
66 15 81 39 0
66 15 80 39 0
66 15 79 39 0
66 15 78 39 0
66 15 77 39 0
66 15 76 39 0
66 15 75 39 0
66 15 74 39 0
66 15 73 39 0
66 15 72 39 0
66 15 71 39 0
66 15 70 39 0
66 15 69 37 0
66 15 68 37 0
66 15 67 37 0
66 15 66 37 0
66 15 65 37 0
66 15 64 37 0
66 15 63 37 64
66 16 85 35 32
66 16 84 37 0
66 16 83 37 0
66 16 82 39 0
66 16 81 39 0
66 16 80 39 0
66 16 79 39 0
66 16 78 39 0
66 16 77 39 0
66 16 76 39 0
66 16 75 39 0
66 16 74 39 0
66 16 73 39 0
66 16 72 39 0
66 16 71 39 0
66 16 70 39 0
66 16 69 37 0
66 16 68 37 0
66 16 67 37 0
66 16 66 37 0
66 16 65 37 0
66 16 64 37 0
66 16 63 37 64
66 17 85 42 32
66 17 84 42 0
66 17 83 42 0
66 17 82 39 0
66 17 81 39 0
66 17 80 39 0
66 17 79 39 0
66 17 78 39 0
66 17 77 39 0
66 17 76 39 0
66 17 75 39 0
66 17 74 39 0
66 17 73 39 0
66 17 72 39 0
66 17 71 39 0
66 17 70 39 0
66 17 69 42 0
66 17 68 42 0
66 17 67 42 0
66 17 66 42 0
66 17 65 42 0
66 17 64 42 0
66 17 63 42 64
66 18 85 42 32
66 18 84 42 0
66 18 83 42 0
66 18 82 39 0
66 18 81 39 0
66 18 80 39 0
66 18 79 39 0
66 18 78 39 0
66 18 77 39 0
66 18 76 39 0
66 18 75 39 0
66 18 74 39 0
66 18 73 39 0
66 18 72 39 0
66 18 71 39 0
66 18 70 39 0
66 18 69 42 0
66 18 68 42 0
66 18 67 42 0
66 18 66 42 0
66 18 65 42 0
66 18 64 42 0
66 18 63 42 64
66 19 86 35 48
66 19 85 35 0
66 19 84 35 0
66 19 83 35 0
66 19 82 39 0
66 19 81 39 0
66 19 80 39 0
66 19 79 39 0
66 19 78 39 0
66 19 77 39 0
66 19 76 39 0
66 19 75 39 0
66 19 74 39 0
66 19 73 39 0
66 19 72 39 0
66 19 71 39 0
66 19 70 39 0
66 19 69 35 0
66 19 68 35 0
66 19 67 35 0
66 19 66 35 0
66 19 65 35 0
66 19 64 35 0
66 19 63 35 64
66 20 87 35 48
66 20 86 35 0
66 20 85 35 0
66 20 84 35 0
66 20 83 35 0
66 20 82 39 0
66 20 81 39 0
66 20 80 39 0
66 20 79 39 0
66 20 78 39 0
66 20 77 39 0
66 20 76 39 0
66 20 75 39 0
66 20 74 39 0
66 20 73 39 0
66 20 72 39 0
66 20 71 39 0
66 20 70 39 0
66 20 69 35 0
66 20 68 35 0
66 20 67 35 0
66 20 66 35 0
66 20 65 35 0
66 20 64 35 0
66 20 63 35 64
66 21 88 35 48
66 21 87 35 0
66 21 86 35 0
66 21 85 35 0
66 21 84 35 0
66 21 83 35 0
66 21 82 39 0
66 21 81 39 0
66 21 80 39 0
66 21 79 39 0
66 21 78 39 0
66 21 77 39 0
66 21 76 39 0
66 21 75 39 0
66 21 74 39 0
66 21 73 39 0
66 21 72 39 0
66 21 71 39 0
66 21 70 39 0
66 21 69 35 0
66 21 68 35 0
66 21 67 35 0
66 21 66 35 0
66 21 65 35 0
66 21 64 35 0
66 21 63 35 64
66 22 89 35 48
66 22 88 35 0
66 22 87 35 0
66 22 86 35 0
66 22 85 35 0
66 22 84 35 0
66 22 83 35 0
66 22 82 39 0
66 22 81 39 0
66 22 80 39 0
66 22 79 39 0
66 22 78 39 0
66 22 77 39 0
66 22 76 39 0
66 22 75 39 0
66 22 74 39 0
66 22 73 39 0
66 22 72 39 0
66 22 71 39 0
66 22 70 39 0
66 22 69 35 0
66 22 68 35 0
66 22 67 35 0
66 22 66 35 0
66 22 65 35 0
66 22 64 35 0
66 22 63 35 64
66 23 89 35 40
66 23 88 24 8
66 23 87 35 8
66 23 86 23 8
66 23 85 23 8
66 23 84 23 8
66 23 83 23 8
66 23 82 39 8
66 23 81 39 8
66 23 80 39 8
66 23 79 39 8
66 23 78 39 8
66 23 77 39 8
66 23 76 39 8
66 23 75 39 8
66 23 74 39 8
66 23 73 39 8
66 23 72 39 8
66 23 71 39 8
66 23 70 39 8
66 23 69 23 8
66 23 68 23 8
66 23 67 23 8
66 23 66 23 8
66 23 65 35 8
66 23 64 24 8
66 23 63 35 72
67 1 85 42 48
67 1 84 42 16
67 1 83 42 16
67 1 82 39 16
67 1 81 39 16
67 1 80 39 16
67 1 79 39 16
67 1 78 39 16
67 1 77 39 16
67 1 76 39 16
67 1 75 39 16
67 1 74 39 16
67 1 73 39 16
67 1 72 39 16
67 1 71 39 16
67 1 70 39 16
67 1 69 42 16
67 1 68 42 16
67 1 67 42 16
67 1 66 42 16
67 1 65 42 16
67 1 64 42 16
67 1 63 42 80
67 2 85 42 32
67 2 84 42 0
67 2 83 42 0
67 2 82 39 0
67 2 81 39 0
67 2 80 39 0
67 2 79 39 0
67 2 78 39 0
67 2 77 39 0
67 2 76 39 0
67 2 75 39 0
67 2 74 39 0
67 2 73 39 0
67 2 72 39 0
67 2 71 39 0
67 2 70 39 0
67 2 69 42 0
67 2 68 42 0
67 2 67 42 0
67 2 66 42 0
67 2 65 42 0
67 2 64 42 0
67 2 63 42 64
67 3 85 37 32
67 3 84 37 0
67 3 83 37 0
67 3 82 39 0
67 3 81 39 0
67 3 80 39 0
67 3 79 39 0
67 3 78 39 0
67 3 77 39 0
67 3 76 39 0
67 3 75 39 0
67 3 74 39 0
67 3 73 39 0
67 3 72 39 0
67 3 71 39 0
67 3 70 39 0
67 3 69 37 0
67 3 68 37 0
67 3 67 37 0
67 3 66 37 0
67 3 65 37 0
67 3 64 37 0
67 3 63 37 64
67 4 85 37 32
67 4 84 37 0
67 4 83 37 0
67 4 82 39 0
67 4 81 39 0
67 4 80 39 0
67 4 79 39 0
67 4 78 39 0
67 4 77 39 0
67 4 76 39 0
67 4 75 39 0
67 4 74 39 0
67 4 73 39 0
67 4 72 39 0
67 4 71 39 0
67 4 70 39 0
67 4 69 37 0
67 4 68 37 0
67 4 67 37 0
67 4 66 37 0
67 4 65 37 0
67 4 64 37 0
67 4 63 37 64
67 5 85 37 32
67 5 84 37 0
67 5 83 37 0
67 5 82 39 0
67 5 81 39 0
67 5 80 39 0
67 5 79 39 0
67 5 78 39 0
67 5 77 39 0
67 5 76 39 0
67 5 75 39 0
67 5 74 39 0
67 5 73 39 0
67 5 72 39 0
67 5 71 39 0
67 5 70 39 0
67 5 69 37 0
67 5 68 37 0
67 5 67 37 0
67 5 66 37 0
67 5 65 37 0
67 5 64 37 0
67 5 63 37 64
67 6 90 52 52
67 6 89 52 20
67 6 88 52 84
67 6 85 37 32
67 6 84 37 0
67 6 83 37 0
67 6 82 39 0
67 6 81 39 0
67 6 80 39 0
67 6 79 39 0
67 6 78 39 0
67 6 77 39 0
67 6 76 39 0
67 6 75 39 0
67 6 74 39 0
67 6 73 39 0
67 6 72 39 0
67 6 71 39 0
67 6 70 39 0
67 6 69 37 0
67 6 68 37 0
67 6 67 37 0
67 6 66 37 0
67 6 65 37 0
67 6 64 37 0
67 6 63 37 64
67 7 90 58 36
67 7 89 58 0
67 7 88 58 68
67 7 85 37 32
67 7 84 37 0
67 7 83 37 0
67 7 82 39 0
67 7 81 39 0
67 7 80 39 0
67 7 79 39 0
67 7 78 39 0
67 7 77 39 0
67 7 76 39 0
67 7 75 39 0
67 7 74 39 0
67 7 73 39 0
67 7 72 39 0
67 7 71 39 0
67 7 70 39 0
67 7 69 37 0
67 7 68 37 0
67 7 67 37 0
67 7 66 37 0
67 7 65 37 0
67 7 64 37 0
67 7 63 37 64
67 8 90 67 44
67 8 89 63 12
67 8 88 67 76
67 8 85 37 32
67 8 84 37 0
67 8 83 37 0
67 8 82 39 0
67 8 81 39 0
67 8 80 39 0
67 8 79 39 0
67 8 78 39 0
67 8 77 39 0
67 8 76 39 0
67 8 75 39 0
67 8 74 39 0
67 8 73 39 0
67 8 72 39 0
67 8 71 39 0
67 8 70 39 0
67 8 69 37 0
67 8 68 37 0
67 8 67 37 0
67 8 66 37 0
67 8 65 37 0
67 8 64 37 0
67 8 63 37 64
67 9 85 37 32
67 9 84 37 0
67 9 83 37 0
67 9 82 39 0
67 9 81 39 0
67 9 80 39 0
67 9 79 39 0
67 9 78 39 0
67 9 77 39 0
67 9 76 39 0
67 9 75 39 0
67 9 74 39 0
67 9 73 39 0
67 9 72 39 0
67 9 71 39 0
67 9 70 39 0
67 9 69 37 0
67 9 68 37 0
67 9 67 37 0
67 9 66 37 0
67 9 65 37 0
67 9 64 37 0
67 9 63 37 64
67 10 85 37 32
67 10 84 37 0
67 10 83 37 0
67 10 82 39 0
67 10 81 39 0
67 10 80 39 0
67 10 79 39 0
67 10 78 39 0
67 10 77 39 0
67 10 76 39 0
67 10 75 39 0
67 10 74 39 0
67 10 73 39 0
67 10 72 39 0
67 10 71 39 0
67 10 70 39 0
67 10 69 37 0
67 10 68 37 0
67 10 67 37 0
67 10 66 37 0
67 10 65 37 0
67 10 64 37 0
67 10 63 37 64
67 11 85 37 32
67 11 84 37 0
67 11 83 37 0
67 11 82 39 0
67 11 81 39 0
67 11 80 39 0
67 11 79 39 0
67 11 78 39 0
67 11 77 39 0
67 11 76 39 0
67 11 75 39 0
67 11 74 39 0
67 11 73 39 0
67 11 72 39 0
67 11 71 39 0
67 11 70 39 0
67 11 69 37 0
67 11 68 37 0
67 11 67 37 0
67 11 66 37 0
67 11 65 37 0
67 11 64 37 0
67 11 63 37 64
67 12 85 37 32
67 12 84 37 0
67 12 83 37 0
67 12 82 39 0
67 12 81 39 0
67 12 80 39 0
67 12 79 39 0
67 12 78 39 0
67 12 77 39 0
67 12 76 39 0
67 12 75 39 0
67 12 74 39 0
67 12 73 39 0
67 12 72 39 0
67 12 71 39 0
67 12 70 39 0
67 12 69 37 0
67 12 68 37 0
67 12 67 37 0
67 12 66 37 0
67 12 65 37 0
67 12 64 37 0
67 12 63 37 64
67 13 85 37 32
67 13 84 37 0
67 13 83 37 0
67 13 82 39 0
67 13 81 39 0
67 13 80 39 0
67 13 79 39 0
67 13 78 39 0
67 13 77 39 0
67 13 76 39 0
67 13 75 39 0
67 13 74 39 0
67 13 73 39 0
67 13 72 39 0
67 13 71 39 0
67 13 70 39 0
67 13 69 37 0
67 13 68 37 0
67 13 67 37 0
67 13 66 37 0
67 13 65 37 0
67 13 64 37 0
67 13 63 37 64
67 14 85 37 32
67 14 84 37 0
67 14 83 37 0
67 14 82 39 0
67 14 81 39 0
67 14 80 39 0
67 14 79 39 0
67 14 78 39 0
67 14 77 39 0
67 14 76 39 0
67 14 75 39 0
67 14 74 39 0
67 14 73 39 0
67 14 72 39 0
67 14 71 39 0
67 14 70 39 0
67 14 69 37 0
67 14 68 37 0
67 14 67 37 0
67 14 66 37 0
67 14 65 37 0
67 14 64 37 0
67 14 63 37 64
67 15 85 37 32
67 15 84 37 0
67 15 83 37 0
67 15 82 39 0
67 15 81 39 0
67 15 80 39 0
67 15 79 39 0
67 15 78 39 0
67 15 77 39 0
67 15 76 39 0
67 15 75 39 0
67 15 74 39 0
67 15 73 39 0
67 15 72 39 0
67 15 71 39 0
67 15 70 39 0
67 15 69 37 0
67 15 68 37 0
67 15 67 37 0
67 15 66 37 0
67 15 65 37 0
67 15 64 37 0
67 15 63 37 64
67 16 85 37 32
67 16 84 37 0
67 16 83 37 0
67 16 82 39 0
67 16 81 39 0
67 16 80 39 0
67 16 79 39 0
67 16 78 39 0
67 16 77 39 0
67 16 76 39 0
67 16 75 39 0
67 16 74 39 0
67 16 73 39 0
67 16 72 39 0
67 16 71 39 0
67 16 70 39 0
67 16 69 37 0
67 16 68 37 0
67 16 67 37 0
67 16 66 37 0
67 16 65 37 0
67 16 64 37 0
67 16 63 37 64
67 17 85 42 32
67 17 84 42 0
67 17 83 42 0
67 17 82 39 0
67 17 81 39 0
67 17 80 39 0
67 17 79 39 0
67 17 78 39 0
67 17 77 39 0
67 17 76 39 0
67 17 75 39 0
67 17 74 39 0
67 17 73 39 0
67 17 72 39 0
67 17 71 39 0
67 17 70 39 0
67 17 69 42 0
67 17 68 42 0
67 17 67 42 0
67 17 66 42 0
67 17 65 42 0
67 17 64 42 0
67 17 63 42 64
67 18 85 42 32
67 18 84 42 0
67 18 83 42 0
67 18 82 39 0
67 18 81 39 0
67 18 80 39 0
67 18 79 39 0
67 18 78 39 0
67 18 77 39 0
67 18 76 39 0
67 18 75 39 0
67 18 74 39 0
67 18 73 39 0
67 18 72 39 0
67 18 71 39 0
67 18 70 39 0
67 18 69 42 0
67 18 68 42 0
67 18 67 42 0
67 18 66 42 0
67 18 65 42 0
67 18 64 42 0
67 18 63 42 64
67 19 86 35 48
67 19 85 35 0
67 19 84 35 0
67 19 83 35 0
67 19 82 39 0
67 19 81 39 0
67 19 80 39 0
67 19 79 39 0
67 19 78 39 0
67 19 77 39 0
67 19 76 39 0
67 19 75 39 0
67 19 74 39 0
67 19 73 39 0
67 19 72 39 0
67 19 71 39 0
67 19 70 39 0
67 19 69 35 0
67 19 68 35 0
67 19 67 35 0
67 19 66 35 0
67 19 65 35 0
67 19 64 35 0
67 19 63 35 64
67 20 87 35 48
67 20 86 35 0
67 20 85 35 0
67 20 84 35 0
67 20 83 35 0
67 20 82 39 0
67 20 81 39 0
67 20 80 39 0
67 20 79 39 0
67 20 78 39 0
67 20 77 39 0
67 20 76 39 0
67 20 75 39 0
67 20 74 39 0
67 20 73 39 0
67 20 72 39 0
67 20 71 39 0
67 20 70 39 0
67 20 69 35 0
67 20 68 35 0
67 20 67 35 0
67 20 66 35 0
67 20 65 35 0
67 20 64 35 0
67 20 63 35 64
67 21 88 35 48
67 21 87 35 0
67 21 86 35 0
67 21 85 35 0
67 21 84 35 0
67 21 83 35 0
67 21 82 39 0
67 21 81 39 0
67 21 80 39 0
67 21 79 39 0
67 21 78 39 0
67 21 77 39 0
67 21 76 39 0
67 21 75 39 0
67 21 74 39 0
67 21 73 39 0
67 21 72 39 0
67 21 71 39 0
67 21 70 39 0
67 21 69 35 0
67 21 68 35 0
67 21 67 35 0
67 21 66 35 0
67 21 65 35 0
67 21 64 35 0
67 21 63 35 64
67 22 89 35 48
67 22 88 35 0
67 22 87 35 0
67 22 86 35 0
67 22 85 35 0
67 22 84 35 0
67 22 83 35 0
67 22 82 39 0
67 22 81 39 0
67 22 80 39 0
67 22 79 39 0
67 22 78 39 0
67 22 77 39 0
67 22 76 39 0
67 22 75 39 0
67 22 74 39 0
67 22 73 39 0
67 22 72 39 0
67 22 71 39 0
67 22 70 39 0
67 22 69 35 0
67 22 68 35 0
67 22 67 35 0
67 22 66 35 0
67 22 65 35 0
67 22 64 35 0
67 22 63 35 64
67 23 89 35 40
67 23 88 24 8
67 23 87 35 8
67 23 86 23 8
67 23 85 23 8
67 23 84 23 8
67 23 83 23 8
67 23 82 39 8
67 23 81 39 8
67 23 80 39 8
67 23 79 39 8
67 23 78 39 8
67 23 77 39 8
67 23 76 39 8
67 23 75 39 8
67 23 74 39 8
67 23 73 39 8
67 23 72 39 8
67 23 71 39 8
67 23 70 39 8
67 23 69 23 8
67 23 68 23 8
67 23 67 23 8
67 23 66 23 8
67 23 65 35 8
67 23 64 24 8
67 23 63 35 72
68 1 85 42 48
68 1 84 42 16
68 1 83 42 16
68 1 82 39 16
68 1 81 39 16
68 1 80 39 16
68 1 79 39 16
68 1 78 39 16
68 1 77 39 16
68 1 76 39 16
68 1 75 39 16
68 1 74 39 16
68 1 73 39 16
68 1 72 39 16
68 1 71 39 16
68 1 70 39 16
68 1 69 42 16
68 1 68 42 16
68 1 67 42 16
68 1 66 42 16
68 1 65 42 16
68 1 64 42 16
68 1 63 42 80
68 2 85 42 32
68 2 84 42 0
68 2 83 42 0
68 2 82 39 0
68 2 81 39 0
68 2 80 39 0
68 2 79 39 0
68 2 78 39 0
68 2 77 39 0
68 2 76 39 0
68 2 75 39 0
68 2 74 39 0
68 2 73 39 0
68 2 72 39 0
68 2 71 39 0
68 2 70 39 0
68 2 69 42 0
68 2 68 42 0
68 2 67 42 0
68 2 66 42 0
68 2 65 42 0
68 2 64 42 0
68 2 63 42 64
68 3 85 37 32
68 3 84 37 0
68 3 83 37 0
68 3 82 39 0
68 3 81 39 0
68 3 80 39 0
68 3 79 39 0
68 3 78 39 0
68 3 77 39 0
68 3 76 39 0
68 3 75 39 0
68 3 74 39 0
68 3 73 39 0
68 3 72 39 0
68 3 71 39 0
68 3 70 39 0
68 3 69 37 0
68 3 68 37 0
68 3 67 37 0
68 3 66 37 0
68 3 65 37 0
68 3 64 37 0
68 3 63 37 64
68 4 85 37 32
68 4 84 37 0
68 4 83 37 0
68 4 82 39 0
68 4 81 39 0
68 4 80 39 0
68 4 79 39 0
68 4 78 39 0
68 4 77 39 0
68 4 76 39 0
68 4 75 39 0
68 4 74 39 0
68 4 73 39 0
68 4 72 39 0
68 4 71 39 0
68 4 70 39 0
68 4 69 37 0
68 4 68 37 0
68 4 67 37 0
68 4 66 37 0
68 4 65 37 0
68 4 64 37 0
68 4 63 37 64
68 5 85 37 32
68 5 84 37 0
68 5 83 37 0
68 5 82 39 0
68 5 81 39 0
68 5 80 39 0
68 5 79 39 0
68 5 78 39 0
68 5 77 39 0
68 5 76 39 0
68 5 75 39 0
68 5 74 39 0
68 5 73 39 0
68 5 72 39 0
68 5 71 39 0
68 5 70 39 0
68 5 69 37 0
68 5 68 37 0
68 5 67 37 0
68 5 66 37 0
68 5 65 37 0
68 5 64 37 0
68 5 63 37 64
68 6 90 52 48
68 6 89 52 16
68 6 88 52 80
68 6 85 37 32
68 6 84 37 0
68 6 83 37 0
68 6 82 39 0
68 6 81 39 0
68 6 80 39 0
68 6 79 39 0
68 6 78 39 0
68 6 77 39 0
68 6 76 39 0
68 6 75 39 0
68 6 74 39 0
68 6 73 39 0
68 6 72 39 0
68 6 71 39 0
68 6 70 39 0
68 6 69 37 0
68 6 68 37 0
68 6 67 37 0
68 6 66 37 0
68 6 65 37 0
68 6 64 37 0
68 6 63 37 64
68 7 90 58 32
68 7 89 58 0
68 7 88 58 0
68 7 87 52 30
68 7 86 52 30
68 7 85 37 0
68 7 84 37 0
68 7 83 37 0
68 7 82 39 0
68 7 81 39 0
68 7 80 39 0
68 7 79 39 0
68 7 78 39 0
68 7 77 39 0
68 7 76 39 0
68 7 75 39 0
68 7 74 39 0
68 7 73 39 0
68 7 72 39 0
68 7 71 39 0
68 7 70 39 0
68 7 69 37 0
68 7 68 37 0
68 7 67 37 0
68 7 66 37 0
68 7 65 37 0
68 7 64 37 0
68 7 63 37 64
68 8 90 63 40
68 8 89 55 8
68 8 88 63 72
68 8 85 37 32
68 8 84 37 0
68 8 83 37 0
68 8 82 39 0
68 8 81 39 0
68 8 80 39 0
68 8 79 39 0
68 8 78 39 0
68 8 77 39 0
68 8 76 39 0
68 8 75 39 0
68 8 74 39 0
68 8 73 39 0
68 8 72 39 0
68 8 71 39 0
68 8 70 39 0
68 8 69 37 0
68 8 68 37 0
68 8 67 37 0
68 8 66 37 0
68 8 65 37 0
68 8 64 37 0
68 8 63 37 64
68 9 85 37 32
68 9 84 37 0
68 9 83 37 0
68 9 82 39 0
68 9 81 39 0
68 9 80 39 0
68 9 79 39 0
68 9 78 39 0
68 9 77 39 0
68 9 76 39 0
68 9 75 39 0
68 9 74 39 0
68 9 73 39 0
68 9 72 39 0
68 9 71 39 0
68 9 70 39 0
68 9 69 37 0
68 9 68 37 0
68 9 67 37 0
68 9 66 37 0
68 9 65 37 0
68 9 64 37 0
68 9 63 37 64
68 10 85 37 32
68 10 84 37 0
68 10 83 37 0
68 10 82 39 0
68 10 81 39 0
68 10 80 39 0
68 10 79 39 0
68 10 78 39 0
68 10 77 39 0
68 10 76 39 0
68 10 75 39 0
68 10 74 39 0
68 10 73 39 0
68 10 72 39 0
68 10 71 39 0
68 10 70 39 0
68 10 69 37 0
68 10 68 37 0
68 10 67 37 0
68 10 66 37 0
68 10 65 37 0
68 10 64 37 0
68 10 63 37 64
68 11 85 37 32
68 11 84 37 0
68 11 83 37 0
68 11 82 39 0
68 11 81 39 0
68 11 80 39 0
68 11 79 39 0
68 11 78 39 0
68 11 77 39 0
68 11 76 39 0
68 11 75 39 0
68 11 74 39 0
68 11 73 39 0
68 11 72 39 0
68 11 71 39 0
68 11 70 39 0
68 11 69 37 0
68 11 68 37 0
68 11 67 37 0
68 11 66 37 0
68 11 65 37 0
68 11 64 37 0
68 11 63 37 64
68 12 85 37 32
68 12 84 37 0
68 12 83 37 0
68 12 82 39 0
68 12 81 39 0
68 12 80 39 0
68 12 79 39 0
68 12 78 39 0
68 12 77 39 0
68 12 76 39 0
68 12 75 39 0
68 12 74 39 0
68 12 73 39 0
68 12 72 39 0
68 12 71 39 0
68 12 70 39 0
68 12 69 37 0
68 12 68 37 0
68 12 67 37 0
68 12 66 37 0
68 12 65 37 0
68 12 64 37 0
68 12 63 37 64
68 13 85 37 32
68 13 84 37 0
68 13 83 37 0
68 13 82 39 0
68 13 81 39 0
68 13 80 39 0
68 13 79 39 0
68 13 78 39 0
68 13 77 39 0
68 13 76 39 0
68 13 75 39 0
68 13 74 39 0
68 13 73 39 0
68 13 72 39 0
68 13 71 39 0
68 13 70 39 0
68 13 69 37 0
68 13 68 37 0
68 13 67 37 0
68 13 66 37 0
68 13 65 37 0
68 13 64 37 0
68 13 63 37 64
68 14 85 37 32
68 14 84 37 0
68 14 83 37 0
68 14 82 39 0
68 14 81 39 0
68 14 80 39 0
68 14 79 39 0
68 14 78 39 0
68 14 77 39 0
68 14 76 39 0
68 14 75 39 0
68 14 74 39 0
68 14 73 39 0
68 14 72 39 0
68 14 71 39 0
68 14 70 39 0
68 14 69 37 0
68 14 68 37 0
68 14 67 37 0
68 14 66 37 0
68 14 65 37 0
68 14 64 37 0
68 14 63 37 64
68 15 85 37 32
68 15 84 37 0
68 15 83 37 0
68 15 82 39 0
68 15 81 39 0
68 15 80 39 0
68 15 79 39 0
68 15 78 39 0
68 15 77 39 0
68 15 76 39 0
68 15 75 39 0
68 15 74 39 0
68 15 73 39 0
68 15 72 39 0
68 15 71 39 0
68 15 70 39 0
68 15 69 37 0
68 15 68 37 0
68 15 67 37 0
68 15 66 37 0
68 15 65 37 0
68 15 64 37 0
68 15 63 37 64
68 16 85 37 32
68 16 84 37 0
68 16 83 37 0
68 16 82 39 0
68 16 81 39 0
68 16 80 39 0
68 16 79 39 0
68 16 78 39 0
68 16 77 39 0
68 16 76 39 0
68 16 75 39 0
68 16 74 39 0
68 16 73 39 0
68 16 72 39 0
68 16 71 39 0
68 16 70 39 0
68 16 69 37 0
68 16 68 37 0
68 16 67 37 0
68 16 66 37 0
68 16 65 37 0
68 16 64 37 0
68 16 63 37 64
68 17 85 42 32
68 17 84 42 0
68 17 83 42 0
68 17 82 39 0
68 17 81 39 0
68 17 80 39 0
68 17 79 39 0
68 17 78 39 0
68 17 77 39 0
68 17 76 39 0
68 17 75 39 0
68 17 74 39 0
68 17 73 39 0
68 17 72 39 0
68 17 71 39 0
68 17 70 39 0
68 17 69 42 0
68 17 68 42 0
68 17 67 42 0
68 17 66 42 0
68 17 65 42 0
68 17 64 42 0
68 17 63 42 64
68 18 85 42 32
68 18 84 42 0
68 18 83 42 0
68 18 82 39 0
68 18 81 39 0
68 18 80 39 0
68 18 79 39 0
68 18 78 39 0
68 18 77 39 0
68 18 76 39 0
68 18 75 39 0
68 18 74 39 0
68 18 73 39 0
68 18 72 39 0
68 18 71 39 0
68 18 70 39 0
68 18 69 42 0
68 18 68 42 0
68 18 67 42 0
68 18 66 42 0
68 18 65 42 0
68 18 64 42 0
68 18 63 42 64
68 19 86 35 48
68 19 85 35 0
68 19 84 35 0
68 19 83 35 0
68 19 82 39 0
68 19 81 39 0
68 19 80 39 0
68 19 79 39 0
68 19 78 39 0
68 19 77 39 0
68 19 76 39 0
68 19 75 39 0
68 19 74 39 0
68 19 73 39 0
68 19 72 39 0
68 19 71 39 0
68 19 70 39 0
68 19 69 35 0
68 19 68 35 0
68 19 67 35 0
68 19 66 35 0
68 19 65 35 0
68 19 64 35 0
68 19 63 35 64
68 20 87 35 48
68 20 86 35 0
68 20 85 35 0
68 20 84 35 0
68 20 83 35 0
68 20 82 39 0
68 20 81 39 0
68 20 80 39 0
68 20 79 39 0
68 20 78 39 0
68 20 77 39 0
68 20 76 39 0
68 20 75 39 0
68 20 74 39 0
68 20 73 39 0
68 20 72 39 0
68 20 71 39 0
68 20 70 39 0
68 20 69 35 0
68 20 68 35 0
68 20 67 35 0
68 20 66 35 0
68 20 65 35 0
68 20 64 35 0
68 20 63 35 64
68 21 88 35 48
68 21 87 35 0
68 21 86 35 0
68 21 85 35 0
68 21 84 35 0
68 21 83 35 0
68 21 82 39 0
68 21 81 39 0
68 21 80 39 0
68 21 79 39 0
68 21 78 39 0
68 21 77 39 0
68 21 76 39 0
68 21 75 39 0
68 21 74 39 0
68 21 73 39 0
68 21 72 39 0
68 21 71 39 0
68 21 70 39 0
68 21 69 35 0
68 21 68 35 0
68 21 67 35 0
68 21 66 35 0
68 21 65 35 0
68 21 64 35 0
68 21 63 35 64
68 22 89 35 48
68 22 88 35 0
68 22 87 35 0
68 22 86 35 0
68 22 85 35 0
68 22 84 35 0
68 22 83 35 0
68 22 82 39 0
68 22 81 39 0
68 22 80 39 0
68 22 79 39 0
68 22 78 39 0
68 22 77 39 0
68 22 76 39 0
68 22 75 39 0
68 22 74 39 0
68 22 73 39 0
68 22 72 39 0
68 22 71 39 0
68 22 70 39 0
68 22 69 35 0
68 22 68 35 0
68 22 67 35 0
68 22 66 35 0
68 22 65 35 0
68 22 64 35 0
68 22 63 35 64
68 23 89 35 40
68 23 88 24 8
68 23 87 35 8
68 23 86 23 8
68 23 85 23 8
68 23 84 23 8
68 23 83 23 8
68 23 82 39 8
68 23 81 39 8
68 23 80 39 8
68 23 79 39 8
68 23 78 39 8
68 23 77 39 8
68 23 76 39 8
68 23 75 39 8
68 23 74 39 8
68 23 73 39 8
68 23 72 39 8
68 23 71 39 8
68 23 70 39 8
68 23 69 23 8
68 23 68 23 8
68 23 67 23 8
68 23 66 23 8
68 23 65 35 8
68 23 64 24 8
68 23 63 35 72
69 1 85 42 48
69 1 84 42 16
69 1 83 42 16
69 1 82 39 16
69 1 81 39 16
69 1 80 39 16
69 1 79 39 16
69 1 78 39 16
69 1 77 39 16
69 1 76 39 16
69 1 75 39 16
69 1 74 39 16
69 1 73 39 16
69 1 72 39 16
69 1 71 39 16
69 1 70 39 16
69 1 69 42 16
69 1 68 42 16
69 1 67 42 16
69 1 66 42 16
69 1 65 42 16
69 1 64 42 16
69 1 63 42 80
69 2 85 42 32
69 2 84 42 0
69 2 83 42 0
69 2 82 39 0
69 2 81 39 0
69 2 80 39 0
69 2 79 39 0
69 2 78 39 0
69 2 77 39 0
69 2 76 39 0
69 2 75 39 0
69 2 74 39 0
69 2 73 39 0
69 2 72 39 0
69 2 71 39 0
69 2 70 39 0
69 2 69 42 0
69 2 68 42 0
69 2 67 42 0
69 2 66 42 0
69 2 65 42 0
69 2 64 42 0
69 2 63 42 64
69 3 85 35 32
69 3 84 37 0
69 3 83 37 0
69 3 82 39 0
69 3 81 39 0
69 3 80 39 0
69 3 79 39 0
69 3 78 39 0
69 3 77 39 0
69 3 76 39 0
69 3 75 39 0
69 3 74 39 0
69 3 73 39 0
69 3 72 39 0
69 3 71 39 0
69 3 70 39 0
69 3 69 37 0
69 3 68 37 0
69 3 67 37 0
69 3 66 37 0
69 3 65 37 0
69 3 64 37 0
69 3 63 37 64
69 4 85 35 32
69 4 84 37 0
69 4 83 37 0
69 4 82 39 0
69 4 81 39 0
69 4 80 39 0
69 4 79 39 0
69 4 78 39 0
69 4 77 39 0
69 4 76 39 0
69 4 75 39 0
69 4 74 39 0
69 4 73 39 0
69 4 72 39 0
69 4 71 39 0
69 4 70 39 0
69 4 69 37 0
69 4 68 37 0
69 4 67 37 0
69 4 66 37 0
69 4 65 37 0
69 4 64 37 0
69 4 63 37 64
69 5 85 35 32
69 5 84 37 0
69 5 83 37 0
69 5 82 39 0
69 5 81 39 0
69 5 80 39 0
69 5 79 39 0
69 5 78 39 0
69 5 77 39 0
69 5 76 39 0
69 5 75 39 0
69 5 74 39 0
69 5 73 39 0
69 5 72 39 0
69 5 71 39 0
69 5 70 39 0
69 5 69 37 0
69 5 68 37 0
69 5 67 37 0
69 5 66 37 0
69 5 65 37 0
69 5 64 37 0
69 5 63 37 64
69 6 90 52 50
69 6 89 52 18
69 6 88 52 82
69 6 85 35 32
69 6 84 37 0
69 6 83 37 0
69 6 82 39 0
69 6 81 39 0
69 6 80 39 0
69 6 79 39 0
69 6 78 39 0
69 6 77 39 0
69 6 76 39 0
69 6 75 39 0
69 6 74 39 0
69 6 73 39 0
69 6 72 39 0
69 6 71 39 0
69 6 70 39 0
69 6 69 37 0
69 6 68 37 0
69 6 67 37 0
69 6 66 37 0
69 6 65 37 0
69 6 64 37 0
69 6 63 37 64
69 7 90 58 34
69 7 89 58 0
69 7 88 58 66
69 7 85 35 32
69 7 84 37 0
69 7 83 37 0
69 7 82 39 0
69 7 81 39 0
69 7 80 39 0
69 7 79 39 0
69 7 78 39 0
69 7 77 39 0
69 7 76 39 0
69 7 75 39 0
69 7 74 39 0
69 7 73 39 0
69 7 72 39 0
69 7 71 39 0
69 7 70 39 0
69 7 69 37 0
69 7 68 37 0
69 7 67 37 0
69 7 66 37 0
69 7 65 37 0
69 7 64 37 0
69 7 63 37 64
69 8 90 67 42
69 8 89 63 10
69 8 88 67 74
69 8 85 35 32
69 8 84 37 0
69 8 83 37 0
69 8 82 39 0
69 8 81 39 0
69 8 80 39 0
69 8 79 39 0
69 8 78 39 0
69 8 77 39 0
69 8 76 39 0
69 8 75 39 0
69 8 74 39 0
69 8 73 39 0
69 8 72 39 0
69 8 71 39 0
69 8 70 39 0
69 8 69 37 0
69 8 68 37 0
69 8 67 37 0
69 8 66 37 0
69 8 65 37 0
69 8 64 37 0
69 8 63 37 64
69 9 85 35 32
69 9 84 37 0
69 9 83 37 0
69 9 82 39 0
69 9 81 39 0
69 9 80 39 0
69 9 79 39 0
69 9 78 39 0
69 9 77 39 0
69 9 76 39 0
69 9 75 39 0
69 9 74 39 0
69 9 73 39 0
69 9 72 39 0
69 9 71 39 0
69 9 70 39 0
69 9 69 37 0
69 9 68 37 0
69 9 67 37 0
69 9 66 37 0
69 9 65 37 0
69 9 64 37 0
69 9 63 37 64
69 10 85 35 32
69 10 84 37 0
69 10 83 37 0
69 10 82 39 0
69 10 81 39 0
69 10 80 39 0
69 10 79 39 0
69 10 78 39 0
69 10 77 39 0
69 10 76 39 0
69 10 75 39 0
69 10 74 39 0
69 10 73 39 0
69 10 72 39 0
69 10 71 39 0
69 10 70 39 0
69 10 69 37 0
69 10 68 37 0
69 10 67 37 0
69 10 66 37 0
69 10 65 37 0
69 10 64 37 0
69 10 63 37 64
69 11 85 35 32
69 11 84 37 0
69 11 83 37 0
69 11 82 39 0
69 11 81 39 0
69 11 80 39 0
69 11 79 39 0
69 11 78 39 0
69 11 77 39 0
69 11 76 39 0
69 11 75 39 0
69 11 74 39 0
69 11 73 39 0
69 11 72 39 0
69 11 71 39 0
69 11 70 39 0
69 11 69 37 0
69 11 68 37 0
69 11 67 37 0
69 11 66 37 0
69 11 65 37 0
69 11 64 37 0
69 11 63 37 64
69 12 85 35 32
69 12 84 37 0
69 12 83 37 0
69 12 82 39 0
69 12 81 39 0
69 12 80 39 0
69 12 79 39 0
69 12 78 39 0
69 12 77 39 0
69 12 76 39 0
69 12 75 39 0
69 12 74 39 0
69 12 73 39 0
69 12 72 39 0
69 12 71 39 0
69 12 70 39 0
69 12 69 37 0
69 12 68 37 0
69 12 67 37 0
69 12 66 37 0
69 12 65 37 0
69 12 64 37 0
69 12 63 37 64
69 13 85 35 32
69 13 84 37 0
69 13 83 37 0
69 13 82 39 0
69 13 81 39 0
69 13 80 39 0
69 13 79 39 0
69 13 78 39 0
69 13 77 39 0
69 13 76 39 0
69 13 75 39 0
69 13 74 39 0
69 13 73 39 0
69 13 72 39 0
69 13 71 39 0
69 13 70 39 0
69 13 69 37 0
69 13 68 37 0
69 13 67 37 0
69 13 66 37 0
69 13 65 37 0
69 13 64 37 0
69 13 63 37 64
69 14 85 35 32
69 14 84 37 0
69 14 83 37 0
69 14 82 39 0
69 14 81 39 0
69 14 80 39 0
69 14 79 39 0
69 14 78 39 0
69 14 77 39 0
69 14 76 39 0
69 14 75 39 0
69 14 74 39 0
69 14 73 39 0
69 14 72 39 0
69 14 71 39 0
69 14 70 39 0
69 14 69 37 0
69 14 68 37 0
69 14 67 37 0
69 14 66 37 0
69 14 65 37 0
69 14 64 37 0
69 14 63 37 64
69 15 85 35 32
69 15 84 37 0
69 15 83 37 0
69 15 82 39 0
69 15 81 39 0
69 15 80 39 0
69 15 79 39 0
69 15 78 39 0
69 15 77 39 0
69 15 76 39 0
69 15 75 39 0
69 15 74 39 0
69 15 73 39 0
69 15 72 39 0
69 15 71 39 0
69 15 70 39 0
69 15 69 37 0
69 15 68 37 0
69 15 67 37 0
69 15 66 37 0
69 15 65 37 0
69 15 64 37 0
69 15 63 37 64
69 16 85 35 32
69 16 84 37 0
69 16 83 37 0
69 16 82 39 0
69 16 81 39 0
69 16 80 39 0
69 16 79 39 0
69 16 78 39 0
69 16 77 39 0
69 16 76 39 0
69 16 75 39 0
69 16 74 39 0
69 16 73 39 0
69 16 72 39 0
69 16 71 39 0
69 16 70 39 0
69 16 69 37 0
69 16 68 37 0
69 16 67 37 0
69 16 66 37 0
69 16 65 37 0
69 16 64 37 0
69 16 63 37 64
69 17 85 42 32
69 17 84 42 0
69 17 83 42 0
69 17 82 39 0
69 17 81 39 0
69 17 80 39 0
69 17 79 39 0
69 17 78 39 0
69 17 77 39 0
69 17 76 39 0
69 17 75 39 0
69 17 74 39 0
69 17 73 39 0
69 17 72 39 0
69 17 71 39 0
69 17 70 39 0
69 17 69 42 0
69 17 68 42 0
69 17 67 42 0
69 17 66 42 0
69 17 65 42 0
69 17 64 42 0
69 17 63 42 64
69 18 85 42 32
69 18 84 42 0
69 18 83 42 0
69 18 82 39 0
69 18 81 39 0
69 18 80 39 0
69 18 79 39 0
69 18 78 39 0
69 18 77 39 0
69 18 76 39 0
69 18 75 39 0
69 18 74 39 0
69 18 73 39 0
69 18 72 39 0
69 18 71 39 0
69 18 70 39 0
69 18 69 42 0
69 18 68 42 0
69 18 67 42 0
69 18 66 42 0
69 18 65 42 0
69 18 64 42 0
69 18 63 42 64
69 19 86 35 48
69 19 85 35 0
69 19 84 35 0
69 19 83 35 0
69 19 82 39 0
69 19 81 39 0
69 19 80 39 0
69 19 79 39 0
69 19 78 39 0
69 19 77 39 0
69 19 76 39 0
69 19 75 39 0
69 19 74 39 0
69 19 73 39 0
69 19 72 39 0
69 19 71 39 0
69 19 70 39 0
69 19 69 35 0
69 19 68 35 0
69 19 67 35 0
69 19 66 35 0
69 19 65 35 0
69 19 64 35 0
69 19 63 35 64
69 20 87 35 48
69 20 86 35 0
69 20 85 35 0
69 20 84 35 0
69 20 83 35 0
69 20 82 39 0
69 20 81 39 0
69 20 80 39 0
69 20 79 39 0
69 20 78 39 0
69 20 77 39 0
69 20 76 39 0
69 20 75 39 0
69 20 74 39 0
69 20 73 39 0
69 20 72 39 0
69 20 71 39 0
69 20 70 39 0
69 20 69 35 0
69 20 68 35 0
69 20 67 35 0
69 20 66 35 0
69 20 65 35 0
69 20 64 35 0
69 20 63 35 64
69 21 88 35 48
69 21 87 35 0
69 21 86 35 0
69 21 85 35 0
69 21 84 35 0
69 21 83 35 0
69 21 82 39 0
69 21 81 39 0
69 21 80 39 0
69 21 79 39 0
69 21 78 39 0
69 21 77 39 0
69 21 76 39 0
69 21 75 39 0
69 21 74 39 0
69 21 73 39 0
69 21 72 39 0
69 21 71 39 0
69 21 70 39 0
69 21 69 35 0
69 21 68 35 0
69 21 67 35 0
69 21 66 35 0
69 21 65 35 0
69 21 64 35 0
69 21 63 35 64
69 22 89 35 48
69 22 88 35 0
69 22 87 35 0
69 22 86 35 0
69 22 85 35 0
69 22 84 35 0
69 22 83 35 0
69 22 82 39 0
69 22 81 39 0
69 22 80 39 0
69 22 79 39 0
69 22 78 39 0
69 22 77 39 0
69 22 76 39 0
69 22 75 39 0
69 22 74 39 0
69 22 73 39 0
69 22 72 39 0
69 22 71 39 0
69 22 70 39 0
69 22 69 35 0
69 22 68 35 0
69 22 67 35 0
69 22 66 35 0
69 22 65 35 0
69 22 64 35 0
69 22 63 35 64
69 23 89 35 40
69 23 88 24 8
69 23 87 35 8
69 23 86 23 8
69 23 85 23 8
69 23 84 23 8
69 23 83 23 8
69 23 82 39 8
69 23 81 39 8
69 23 80 39 8
69 23 79 39 8
69 23 78 39 8
69 23 77 39 8
69 23 76 39 8
69 23 75 39 8
69 23 74 39 8
69 23 73 39 8
69 23 72 39 8
69 23 71 39 8
69 23 70 39 8
69 23 69 23 8
69 23 68 23 8
69 23 67 23 8
69 23 66 23 8
69 23 65 35 8
69 23 64 24 8
69 23 63 35 72
70 1 85 42 48
70 1 84 42 16
70 1 83 42 16
70 1 82 39 16
70 1 81 39 16
70 1 80 39 16
70 1 79 39 16
70 1 78 39 16
70 1 77 39 16
70 1 76 39 16
70 1 75 39 16
70 1 74 39 16
70 1 73 39 16
70 1 72 39 16
70 1 71 39 16
70 1 70 39 16
70 1 69 42 16
70 1 68 42 16
70 1 67 42 16
70 1 66 42 16
70 1 65 42 16
70 1 64 42 16
70 1 63 42 80
70 2 85 42 32
70 2 84 42 0
70 2 83 42 0
70 2 82 39 0
70 2 81 39 0
70 2 80 39 0
70 2 79 39 0
70 2 78 39 0
70 2 77 39 0
70 2 76 39 0
70 2 75 39 0
70 2 74 39 0
70 2 73 39 0
70 2 72 39 0
70 2 71 39 0
70 2 70 39 0
70 2 69 42 0
70 2 68 42 0
70 2 67 42 0
70 2 66 42 0
70 2 65 42 0
70 2 64 42 0
70 2 63 42 64
70 3 85 37 32
70 3 84 37 0
70 3 83 37 0
70 3 82 39 0
70 3 81 39 0
70 3 80 39 0
70 3 79 39 0
70 3 78 39 0
70 3 77 39 0
70 3 76 39 0
70 3 75 39 0
70 3 74 39 0
70 3 73 39 0
70 3 72 39 0
70 3 71 39 0
70 3 70 39 0
70 3 69 37 0
70 3 68 37 0
70 3 67 37 0
70 3 66 37 0
70 3 65 37 0
70 3 64 37 0
70 3 63 37 64
70 4 85 37 32
70 4 84 37 0
70 4 83 37 0
70 4 82 39 0
70 4 81 39 0
70 4 80 39 0
70 4 79 39 0
70 4 78 39 0
70 4 77 39 0
70 4 76 39 0
70 4 75 39 0
70 4 74 39 0
70 4 73 39 0
70 4 72 39 0
70 4 71 39 0
70 4 70 39 0
70 4 69 37 0
70 4 68 37 0
70 4 67 37 0
70 4 66 37 0
70 4 65 37 0
70 4 64 37 0
70 4 63 37 64
70 5 85 37 32
70 5 84 37 0
70 5 83 37 0
70 5 82 39 0
70 5 81 39 0
70 5 80 39 0
70 5 79 39 0
70 5 78 39 0
70 5 77 39 0
70 5 76 39 0
70 5 75 39 0
70 5 74 39 0
70 5 73 39 0
70 5 72 39 0
70 5 71 39 0
70 5 70 39 0
70 5 69 37 0
70 5 68 37 0
70 5 67 37 0
70 5 66 37 0
70 5 65 37 0
70 5 64 37 0
70 5 63 37 64
70 6 85 37 32
70 6 84 37 0
70 6 83 37 0
70 6 82 39 0
70 6 81 39 0
70 6 80 39 0
70 6 79 39 0
70 6 78 39 0
70 6 77 39 0
70 6 76 39 0
70 6 75 39 0
70 6 74 39 0
70 6 73 39 0
70 6 72 39 0
70 6 71 39 0
70 6 70 39 0
70 6 69 37 0
70 6 68 37 0
70 6 67 37 0
70 6 66 37 0
70 6 65 37 0
70 6 64 37 0
70 6 63 37 64
70 7 89 55 120
70 7 85 37 32
70 7 84 37 0
70 7 83 37 0
70 7 82 39 0
70 7 81 39 0
70 7 80 39 0
70 7 79 39 0
70 7 78 39 0
70 7 77 39 0
70 7 76 39 0
70 7 75 39 0
70 7 74 39 0
70 7 73 39 0
70 7 72 39 0
70 7 71 39 0
70 7 70 39 0
70 7 69 37 0
70 7 68 37 0
70 7 67 37 0
70 7 66 37 0
70 7 65 37 0
70 7 64 37 0
70 7 63 37 64
70 8 85 37 32
70 8 84 37 0
70 8 83 37 0
70 8 82 39 0
70 8 81 39 0
70 8 80 39 0
70 8 79 39 0
70 8 78 39 0
70 8 77 39 0
70 8 76 39 0
70 8 75 39 0
70 8 74 39 0
70 8 73 39 0
70 8 72 39 0
70 8 71 39 0
70 8 70 39 0
70 8 69 37 0
70 8 68 37 0
70 8 67 37 0
70 8 66 37 0
70 8 65 37 0
70 8 64 37 0
70 8 63 37 64
70 9 85 37 32
70 9 84 37 0
70 9 83 37 0
70 9 82 39 0
70 9 81 39 0
70 9 80 39 0
70 9 79 39 0
70 9 78 39 0
70 9 77 39 0
70 9 76 39 0
70 9 75 39 0
70 9 74 39 0
70 9 73 39 0
70 9 72 39 0
70 9 71 39 0
70 9 70 39 0
70 9 69 37 0
70 9 68 37 0
70 9 67 37 0
70 9 66 37 0
70 9 65 37 0
70 9 64 37 0
70 9 63 37 64
70 10 85 37 32
70 10 84 37 0
70 10 83 37 0
70 10 82 39 0
70 10 81 39 0
70 10 80 39 0
70 10 79 39 0
70 10 78 39 0
70 10 77 39 0
70 10 76 39 0
70 10 75 39 0
70 10 74 39 0
70 10 73 39 0
70 10 72 39 0
70 10 71 39 0
70 10 70 39 0
70 10 69 37 0
70 10 68 37 0
70 10 67 37 0
70 10 66 37 0
70 10 65 37 0
70 10 64 37 0
70 10 63 37 64
70 11 85 37 32
70 11 84 37 0
70 11 83 37 0
70 11 82 39 0
70 11 81 39 0
70 11 80 39 0
70 11 79 39 0
70 11 78 39 0
70 11 77 39 0
70 11 76 39 0
70 11 75 39 0
70 11 74 39 0
70 11 73 39 0
70 11 72 39 0
70 11 71 39 0
70 11 70 39 0
70 11 69 37 0
70 11 68 37 0
70 11 67 37 0
70 11 66 37 0
70 11 65 37 0
70 11 64 37 0
70 11 63 37 64
70 12 85 37 32
70 12 84 37 0
70 12 83 37 0
70 12 82 39 0
70 12 81 39 0
70 12 80 39 0
70 12 79 39 0
70 12 78 39 0
70 12 77 39 0
70 12 76 39 0
70 12 75 39 0
70 12 74 39 0
70 12 73 39 0
70 12 72 39 0
70 12 71 39 0
70 12 70 39 0
70 12 69 37 0
70 12 68 37 0
70 12 67 37 0
70 12 66 37 0
70 12 65 37 0
70 12 64 37 0
70 12 63 37 64
70 13 85 37 32
70 13 84 37 0
70 13 83 37 0
70 13 82 39 0
70 13 81 39 0
70 13 80 39 0
70 13 79 39 0
70 13 78 39 0
70 13 77 39 0
70 13 76 39 0
70 13 75 39 0
70 13 74 39 0
70 13 73 39 0
70 13 72 39 0
70 13 71 39 0
70 13 70 39 0
70 13 69 37 0
70 13 68 37 0
70 13 67 37 0
70 13 66 37 0
70 13 65 37 0
70 13 64 37 0
70 13 63 37 64
70 14 85 37 32
70 14 84 37 0
70 14 83 37 0
70 14 82 39 0
70 14 81 39 0
70 14 80 39 0
70 14 79 39 0
70 14 78 39 0
70 14 77 39 0
70 14 76 39 0
70 14 75 39 0
70 14 74 39 0
70 14 73 39 0
70 14 72 39 0
70 14 71 39 0
70 14 70 39 0
70 14 69 37 0
70 14 68 37 0
70 14 67 37 0
70 14 66 37 0
70 14 65 37 0
70 14 64 37 0
70 14 63 37 64
70 15 85 37 32
70 15 84 37 0
70 15 83 37 0
70 15 82 39 0
70 15 81 39 0
70 15 80 39 0
70 15 79 39 0
70 15 78 39 0
70 15 77 39 0
70 15 76 39 0
70 15 75 39 0
70 15 74 39 0
70 15 73 39 0
70 15 72 39 0
70 15 71 39 0
70 15 70 39 0
70 15 69 37 0
70 15 68 37 0
70 15 67 37 0
70 15 66 37 0
70 15 65 37 0
70 15 64 37 0
70 15 63 37 64
70 16 85 37 32
70 16 84 37 0
70 16 83 37 0
70 16 82 39 0
70 16 81 39 0
70 16 80 39 0
70 16 79 39 0
70 16 78 39 0
70 16 77 39 0
70 16 76 39 0
70 16 75 39 0
70 16 74 39 0
70 16 73 39 0
70 16 72 39 0
70 16 71 39 0
70 16 70 39 0
70 16 69 37 0
70 16 68 37 0
70 16 67 37 0
70 16 66 37 0
70 16 65 37 0
70 16 64 37 0
70 16 63 37 64
70 17 85 42 32
70 17 84 42 0
70 17 83 42 0
70 17 82 39 0
70 17 81 39 0
70 17 80 39 0
70 17 79 39 0
70 17 78 39 0
70 17 77 39 0
70 17 76 39 0
70 17 75 39 0
70 17 74 39 0
70 17 73 39 0
70 17 72 39 0
70 17 71 39 0
70 17 70 39 0
70 17 69 42 0
70 17 68 42 0
70 17 67 42 0
70 17 66 42 0
70 17 65 42 0
70 17 64 42 0
70 17 63 42 64
70 18 85 42 32
70 18 84 42 0
70 18 83 42 0
70 18 82 39 0
70 18 81 39 0
70 18 80 39 0
70 18 79 39 0
70 18 78 39 0
70 18 77 39 0
70 18 76 39 0
70 18 75 39 0
70 18 74 39 0
70 18 73 39 0
70 18 72 39 0
70 18 71 39 0
70 18 70 39 0
70 18 69 42 0
70 18 68 42 0
70 18 67 42 0
70 18 66 42 0
70 18 65 42 0
70 18 64 42 0
70 18 63 42 64
70 19 86 35 48
70 19 85 35 0
70 19 84 35 0
70 19 83 35 0
70 19 82 39 0
70 19 81 39 0
70 19 80 39 0
70 19 79 39 0
70 19 78 39 0
70 19 77 39 0
70 19 76 39 0
70 19 75 39 0
70 19 74 39 0
70 19 73 39 0
70 19 72 39 0
70 19 71 39 0
70 19 70 39 0
70 19 69 35 0
70 19 68 35 0
70 19 67 35 0
70 19 66 35 0
70 19 65 35 0
70 19 64 35 0
70 19 63 35 64
70 20 87 35 48
70 20 86 35 0
70 20 85 35 0
70 20 84 35 0
70 20 83 35 0
70 20 82 39 0
70 20 81 39 0
70 20 80 39 0
70 20 79 39 0
70 20 78 39 0
70 20 77 39 0
70 20 76 39 0
70 20 75 39 0
70 20 74 39 0
70 20 73 39 0
70 20 72 39 0
70 20 71 39 0
70 20 70 39 0
70 20 69 35 0
70 20 68 35 0
70 20 67 35 0
70 20 66 35 0
70 20 65 35 0
70 20 64 35 0
70 20 63 35 64
70 21 88 35 48
70 21 87 35 0
70 21 86 35 0
70 21 85 35 0
70 21 84 35 0
70 21 83 35 0
70 21 82 39 0
70 21 81 39 0
70 21 80 39 0
70 21 79 39 0
70 21 78 39 0
70 21 77 39 0
70 21 76 39 0
70 21 75 39 0
70 21 74 39 0
70 21 73 39 0
70 21 72 39 0
70 21 71 39 0
70 21 70 39 0
70 21 69 35 0
70 21 68 35 0
70 21 67 35 0
70 21 66 35 0
70 21 65 35 0
70 21 64 35 0
70 21 63 35 64
70 22 89 35 48
70 22 88 35 0
70 22 87 35 0
70 22 86 35 0
70 22 85 35 0
70 22 84 35 0
70 22 83 35 0
70 22 82 39 0
70 22 81 39 0
70 22 80 39 0
70 22 79 39 0
70 22 78 39 0
70 22 77 39 0
70 22 76 39 0
70 22 75 39 0
70 22 74 39 0
70 22 73 39 0
70 22 72 39 0
70 22 71 39 0
70 22 70 39 0
70 22 69 35 0
70 22 68 35 0
70 22 67 35 0
70 22 66 35 0
70 22 65 35 0
70 22 64 35 0
70 22 63 35 64
70 23 89 35 40
70 23 88 24 8
70 23 87 35 8
70 23 86 23 8
70 23 85 23 8
70 23 84 23 8
70 23 83 23 8
70 23 82 39 8
70 23 81 39 8
70 23 80 39 8
70 23 79 39 8
70 23 78 39 8
70 23 77 39 8
70 23 76 39 8
70 23 75 39 8
70 23 74 39 8
70 23 73 39 8
70 23 72 39 8
70 23 71 39 8
70 23 70 39 8
70 23 69 23 8
70 23 68 23 8
70 23 67 23 8
70 23 66 23 8
70 23 65 35 8
70 23 64 24 8
70 23 63 35 72
71 1 85 42 48
71 1 84 42 16
71 1 83 42 16
71 1 82 39 16
71 1 81 39 16
71 1 80 39 16
71 1 79 39 16
71 1 78 39 16
71 1 77 39 16
71 1 76 39 16
71 1 75 39 16
71 1 74 39 16
71 1 73 39 16
71 1 72 39 16
71 1 71 39 16
71 1 70 39 16
71 1 69 42 16
71 1 68 42 16
71 1 67 42 16
71 1 66 42 16
71 1 65 42 16
71 1 64 42 16
71 1 63 42 80
71 2 85 42 32
71 2 84 42 0
71 2 83 42 0
71 2 82 39 0
71 2 81 39 0
71 2 80 39 0
71 2 79 39 0
71 2 78 39 0
71 2 77 39 0
71 2 76 39 0
71 2 75 39 0
71 2 74 39 0
71 2 73 39 0
71 2 72 39 0
71 2 71 39 0
71 2 70 39 0
71 2 69 42 0
71 2 68 42 0
71 2 67 42 0
71 2 66 42 0
71 2 65 42 0
71 2 64 42 0
71 2 63 42 64
71 3 85 37 32
71 3 84 37 0
71 3 83 37 0
71 3 82 39 0
71 3 81 39 0
71 3 80 39 0
71 3 79 39 0
71 3 78 39 0
71 3 77 39 0
71 3 76 39 0
71 3 75 39 0
71 3 74 39 0
71 3 73 39 0
71 3 72 39 0
71 3 71 39 0
71 3 70 39 0
71 3 69 37 0
71 3 68 37 0
71 3 67 37 0
71 3 66 37 0
71 3 65 37 0
71 3 64 37 0
71 3 63 37 64
71 4 85 37 32
71 4 84 37 0
71 4 83 37 0
71 4 82 39 0
71 4 81 39 0
71 4 80 39 0
71 4 79 39 0
71 4 78 39 0
71 4 77 39 0
71 4 76 39 0
71 4 75 39 0
71 4 74 39 0
71 4 73 39 0
71 4 72 39 0
71 4 71 39 0
71 4 70 39 0
71 4 69 37 0
71 4 68 37 0
71 4 67 37 0
71 4 66 37 0
71 4 65 37 0
71 4 64 37 0
71 4 63 37 64
71 5 85 37 32
71 5 84 37 0
71 5 83 37 0
71 5 82 39 0
71 5 81 39 0
71 5 80 39 0
71 5 79 39 0
71 5 78 39 0
71 5 77 39 0
71 5 76 39 0
71 5 75 39 0
71 5 74 39 0
71 5 73 39 0
71 5 72 39 0
71 5 71 39 0
71 5 70 39 0
71 5 69 37 0
71 5 68 37 0
71 5 67 37 0
71 5 66 37 0
71 5 65 37 0
71 5 64 37 0
71 5 63 37 64
71 6 85 37 32
71 6 84 37 0
71 6 83 37 0
71 6 82 39 0
71 6 81 39 0
71 6 80 39 0
71 6 79 39 0
71 6 78 39 0
71 6 77 39 0
71 6 76 39 0
71 6 75 39 0
71 6 74 39 0
71 6 73 39 0
71 6 72 39 0
71 6 71 39 0
71 6 70 39 0
71 6 69 37 0
71 6 68 37 0
71 6 67 37 0
71 6 66 37 0
71 6 65 37 0
71 6 64 37 0
71 6 63 37 64
71 7 89 55 120
71 7 85 37 32
71 7 84 37 0
71 7 83 37 0
71 7 82 39 0
71 7 81 39 0
71 7 80 39 0
71 7 79 39 0
71 7 78 39 0
71 7 77 39 0
71 7 76 39 0
71 7 75 39 0
71 7 74 39 0
71 7 73 39 0
71 7 72 39 0
71 7 71 39 0
71 7 70 39 0
71 7 69 37 0
71 7 68 37 0
71 7 67 37 0
71 7 66 37 0
71 7 65 37 0
71 7 64 37 0
71 7 63 37 64
71 8 85 37 32
71 8 84 37 0
71 8 83 37 0
71 8 82 39 0
71 8 81 39 0
71 8 80 39 0
71 8 79 39 0
71 8 78 39 0
71 8 77 39 0
71 8 76 39 0
71 8 75 39 0
71 8 74 39 0
71 8 73 39 0
71 8 72 39 0
71 8 71 39 0
71 8 70 39 0
71 8 69 37 0
71 8 68 37 0
71 8 67 37 0
71 8 66 37 0
71 8 65 37 0
71 8 64 37 0
71 8 63 37 64
71 9 85 37 32
71 9 84 37 0
71 9 83 37 0
71 9 82 39 0
71 9 81 39 0
71 9 80 39 0
71 9 79 39 0
71 9 78 39 0
71 9 77 39 0
71 9 76 39 0
71 9 75 39 0
71 9 74 39 0
71 9 73 39 0
71 9 72 39 0
71 9 71 39 0
71 9 70 39 0
71 9 69 37 0
71 9 68 37 0
71 9 67 37 0
71 9 66 37 0
71 9 65 37 0
71 9 64 37 0
71 9 63 37 64
71 10 85 37 32
71 10 84 37 0
71 10 83 37 0
71 10 82 39 0
71 10 81 39 0
71 10 80 39 0
71 10 79 39 0
71 10 78 39 0
71 10 77 39 0
71 10 76 39 0
71 10 75 39 0
71 10 74 39 0
71 10 73 39 0
71 10 72 39 0
71 10 71 39 0
71 10 70 39 0
71 10 69 37 0
71 10 68 37 0
71 10 67 37 0
71 10 66 37 0
71 10 65 37 0
71 10 64 37 0
71 10 63 37 64
71 11 85 37 32
71 11 84 37 0
71 11 83 37 0
71 11 82 39 0
71 11 81 39 0
71 11 80 39 0
71 11 79 39 0
71 11 78 39 0
71 11 77 39 0
71 11 76 39 0
71 11 75 39 0
71 11 74 39 0
71 11 73 39 0
71 11 72 39 0
71 11 71 39 0
71 11 70 39 0
71 11 69 37 0
71 11 68 37 0
71 11 67 37 0
71 11 66 37 0
71 11 65 37 0
71 11 64 37 0
71 11 63 37 64
71 12 85 37 32
71 12 84 37 0
71 12 83 37 0
71 12 82 39 0
71 12 81 39 0
71 12 80 39 0
71 12 79 39 0
71 12 78 39 0
71 12 77 39 0
71 12 76 39 0
71 12 75 39 0
71 12 74 39 0
71 12 73 39 0
71 12 72 39 0
71 12 71 39 0
71 12 70 39 0
71 12 69 37 0
71 12 68 37 0
71 12 67 37 0
71 12 66 37 0
71 12 65 37 0
71 12 64 37 0
71 12 63 37 64
71 13 85 37 32
71 13 84 37 0
71 13 83 37 0
71 13 82 39 0
71 13 81 39 0
71 13 80 39 0
71 13 79 39 0
71 13 78 39 0
71 13 77 39 0
71 13 76 39 0
71 13 75 39 0
71 13 74 39 0
71 13 73 39 0
71 13 72 39 0
71 13 71 39 0
71 13 70 39 0
71 13 69 37 0
71 13 68 37 0
71 13 67 37 0
71 13 66 37 0
71 13 65 37 0
71 13 64 37 0
71 13 63 37 64
71 14 85 37 32
71 14 84 37 0
71 14 83 37 0
71 14 82 39 0
71 14 81 39 0
71 14 80 39 0
71 14 79 39 0
71 14 78 39 0
71 14 77 39 0
71 14 76 39 0
71 14 75 39 0
71 14 74 39 0
71 14 73 39 0
71 14 72 39 0
71 14 71 39 0
71 14 70 39 0
71 14 69 37 0
71 14 68 37 0
71 14 67 37 0
71 14 66 37 0
71 14 65 37 0
71 14 64 37 0
71 14 63 37 64
71 15 85 37 32
71 15 84 37 0
71 15 83 37 0
71 15 82 39 0
71 15 81 39 0
71 15 80 39 0
71 15 79 39 0
71 15 78 39 0
71 15 77 39 0
71 15 76 39 0
71 15 75 39 0
71 15 74 39 0
71 15 73 39 0
71 15 72 39 0
71 15 71 39 0
71 15 70 39 0
71 15 69 37 0
71 15 68 37 0
71 15 67 37 0
71 15 66 37 0
71 15 65 37 0
71 15 64 37 0
71 15 63 37 64
71 16 85 37 32
71 16 84 37 0
71 16 83 37 0
71 16 82 39 0
71 16 81 39 0
71 16 80 39 0
71 16 79 39 0
71 16 78 39 0
71 16 77 39 0
71 16 76 39 0
71 16 75 39 0
71 16 74 39 0
71 16 73 39 0
71 16 72 39 0
71 16 71 39 0
71 16 70 39 0
71 16 69 37 0
71 16 68 37 0
71 16 67 37 0
71 16 66 37 0
71 16 65 37 0
71 16 64 37 0
71 16 63 37 64
71 17 85 42 32
71 17 84 42 0
71 17 83 42 0
71 17 82 39 0
71 17 81 39 0
71 17 80 39 0
71 17 79 39 0
71 17 78 39 0
71 17 77 39 0
71 17 76 39 0
71 17 75 39 0
71 17 74 39 0
71 17 73 39 0
71 17 72 39 0
71 17 71 39 0
71 17 70 39 0
71 17 69 42 0
71 17 68 42 0
71 17 67 42 0
71 17 66 42 0
71 17 65 42 0
71 17 64 42 0
71 17 63 42 64
71 18 85 42 32
71 18 84 42 0
71 18 83 42 0
71 18 82 39 0
71 18 81 39 0
71 18 80 39 0
71 18 79 39 0
71 18 78 39 0
71 18 77 39 0
71 18 76 39 0
71 18 75 39 0
71 18 74 39 0
71 18 73 39 0
71 18 72 39 0
71 18 71 39 0
71 18 70 39 0
71 18 69 42 0
71 18 68 42 0
71 18 67 42 0
71 18 66 42 0
71 18 65 42 0
71 18 64 42 0
71 18 63 42 64
71 19 86 35 48
71 19 85 35 0
71 19 84 35 0
71 19 83 35 0
71 19 82 39 0
71 19 81 39 0
71 19 80 39 0
71 19 79 39 0
71 19 78 39 0
71 19 77 39 0
71 19 76 39 0
71 19 75 39 0
71 19 74 39 0
71 19 73 39 0
71 19 72 39 0
71 19 71 39 0
71 19 70 39 0
71 19 69 35 0
71 19 68 35 0
71 19 67 35 0
71 19 66 35 0
71 19 65 35 0
71 19 64 35 0
71 19 63 35 64
71 20 87 35 48
71 20 86 35 0
71 20 85 35 0
71 20 84 35 0
71 20 83 35 0
71 20 82 39 0
71 20 81 39 0
71 20 80 39 0
71 20 79 39 0
71 20 78 39 0
71 20 77 39 0
71 20 76 39 0
71 20 75 39 0
71 20 74 39 0
71 20 73 39 0
71 20 72 39 0
71 20 71 39 0
71 20 70 39 0
71 20 69 35 0
71 20 68 35 0
71 20 67 35 0
71 20 66 35 0
71 20 65 35 0
71 20 64 35 0
71 20 63 35 64
71 21 88 35 48
71 21 87 35 0
71 21 86 35 0
71 21 85 35 0
71 21 84 35 0
71 21 83 35 0
71 21 82 39 0
71 21 81 39 0
71 21 80 39 0
71 21 79 39 0
71 21 78 39 0
71 21 77 39 0
71 21 76 39 0
71 21 75 39 0
71 21 74 39 0
71 21 73 39 0
71 21 72 39 0
71 21 71 39 0
71 21 70 39 0
71 21 69 35 0
71 21 68 35 0
71 21 67 35 0
71 21 66 35 0
71 21 65 35 0
71 21 64 35 0
71 21 63 35 64
71 22 89 35 48
71 22 88 35 0
71 22 87 35 0
71 22 86 35 0
71 22 85 35 0
71 22 84 35 0
71 22 83 35 0
71 22 82 39 0
71 22 81 39 0
71 22 80 39 0
71 22 79 39 0
71 22 78 39 0
71 22 77 39 0
71 22 76 39 0
71 22 75 39 0
71 22 74 39 0
71 22 73 39 0
71 22 72 39 0
71 22 71 39 0
71 22 70 39 0
71 22 69 35 0
71 22 68 35 0
71 22 67 35 0
71 22 66 35 0
71 22 65 35 0
71 22 64 35 0
71 22 63 35 64
71 23 89 35 40
71 23 88 24 8
71 23 87 35 8
71 23 86 23 8
71 23 85 23 8
71 23 84 23 8
71 23 83 23 8
71 23 82 39 8
71 23 81 39 8
71 23 80 39 8
71 23 79 39 8
71 23 78 39 8
71 23 77 39 8
71 23 76 39 8
71 23 75 39 8
71 23 74 39 8
71 23 73 39 8
71 23 72 39 8
71 23 71 39 8
71 23 70 39 8
71 23 69 23 8
71 23 68 23 8
71 23 67 23 8
71 23 66 23 8
71 23 65 35 8
71 23 64 24 8
71 23 63 35 72
72 1 85 42 48
72 1 84 42 16
72 1 83 42 16
72 1 82 39 16
72 1 81 39 16
72 1 80 39 16
72 1 79 39 16
72 1 78 39 16
72 1 77 39 16
72 1 76 39 16
72 1 75 39 16
72 1 74 39 16
72 1 73 39 16
72 1 72 39 16
72 1 71 39 16
72 1 70 39 16
72 1 69 42 16
72 1 68 42 16
72 1 67 42 16
72 1 66 42 16
72 1 65 42 16
72 1 64 42 16
72 1 63 42 80
72 2 85 42 32
72 2 84 42 0
72 2 83 42 0
72 2 82 39 0
72 2 81 39 0
72 2 80 39 0
72 2 79 39 0
72 2 78 39 0
72 2 77 39 0
72 2 76 39 0
72 2 75 39 0
72 2 74 39 0
72 2 73 39 0
72 2 72 39 0
72 2 71 39 0
72 2 70 39 0
72 2 69 42 0
72 2 68 42 0
72 2 67 42 0
72 2 66 42 0
72 2 65 42 0
72 2 64 42 0
72 2 63 42 64
72 3 85 35 32
72 3 84 37 0
72 3 83 37 0
72 3 82 39 0
72 3 81 39 0
72 3 80 39 0
72 3 79 39 0
72 3 78 39 0
72 3 77 39 0
72 3 76 39 0
72 3 75 39 0
72 3 74 39 0
72 3 73 39 0
72 3 72 39 0
72 3 71 39 0
72 3 70 39 0
72 3 69 37 0
72 3 68 37 0
72 3 67 37 0
72 3 66 37 0
72 3 65 37 0
72 3 64 37 0
72 3 63 37 64
72 4 85 35 32
72 4 84 37 0
72 4 83 37 0
72 4 82 39 0
72 4 81 39 0
72 4 80 39 0
72 4 79 39 0
72 4 78 39 0
72 4 77 39 0
72 4 76 39 0
72 4 75 39 0
72 4 74 39 0
72 4 73 39 0
72 4 72 39 0
72 4 71 39 0
72 4 70 39 0
72 4 69 37 0
72 4 68 37 0
72 4 67 37 0
72 4 66 37 0
72 4 65 37 0
72 4 64 37 0
72 4 63 37 64
72 5 85 35 32
72 5 84 37 0
72 5 83 37 0
72 5 82 39 0
72 5 81 39 0
72 5 80 39 0
72 5 79 39 0
72 5 78 39 0
72 5 77 39 0
72 5 76 39 0
72 5 75 39 0
72 5 74 39 0
72 5 73 39 0
72 5 72 39 0
72 5 71 39 0
72 5 70 39 0
72 5 69 37 0
72 5 68 37 0
72 5 67 37 0
72 5 66 37 0
72 5 65 37 0
72 5 64 37 0
72 5 63 37 64
72 6 85 35 32
72 6 84 37 0
72 6 83 37 0
72 6 82 39 0
72 6 81 39 0
72 6 80 39 0
72 6 79 39 0
72 6 78 39 0
72 6 77 39 0
72 6 76 39 0
72 6 75 39 0
72 6 74 39 0
72 6 73 39 0
72 6 72 39 0
72 6 71 39 0
72 6 70 39 0
72 6 69 37 0
72 6 68 37 0
72 6 67 37 0
72 6 66 37 0
72 6 65 37 0
72 6 64 37 0
72 6 63 37 64
72 7 89 55 120
72 7 85 35 32
72 7 84 37 0
72 7 83 37 0
72 7 82 39 0
72 7 81 39 0
72 7 80 39 0
72 7 79 39 0
72 7 78 39 0
72 7 77 39 0
72 7 76 39 0
72 7 75 39 0
72 7 74 39 0
72 7 73 39 0
72 7 72 39 0
72 7 71 39 0
72 7 70 39 0
72 7 69 37 0
72 7 68 37 0
72 7 67 37 0
72 7 66 37 0
72 7 65 37 0
72 7 64 37 0
72 7 63 37 64
72 8 85 35 32
72 8 84 37 0
72 8 83 37 0
72 8 82 39 0
72 8 81 39 0
72 8 80 39 0
72 8 79 39 0
72 8 78 39 0
72 8 77 39 0
72 8 76 39 0
72 8 75 39 0
72 8 74 39 0
72 8 73 39 0
72 8 72 39 0
72 8 71 39 0
72 8 70 39 0
72 8 69 37 0
72 8 68 37 0
72 8 67 37 0
72 8 66 37 0
72 8 65 37 0
72 8 64 37 0
72 8 63 37 64
72 9 85 35 32
72 9 84 37 0
72 9 83 37 0
72 9 82 39 0
72 9 81 39 0
72 9 80 39 0
72 9 79 39 0
72 9 78 39 0
72 9 77 39 0
72 9 76 39 0
72 9 75 39 0
72 9 74 39 0
72 9 73 39 0
72 9 72 39 0
72 9 71 39 0
72 9 70 39 0
72 9 69 37 0
72 9 68 37 0
72 9 67 37 0
72 9 66 37 0
72 9 65 37 0
72 9 64 37 0
72 9 63 37 64
72 10 85 35 32
72 10 84 37 0
72 10 83 37 0
72 10 82 39 0
72 10 81 39 0
72 10 80 39 0
72 10 79 39 0
72 10 78 39 0
72 10 77 39 0
72 10 76 39 0
72 10 75 39 0
72 10 74 39 0
72 10 73 39 0
72 10 72 39 0
72 10 71 39 0
72 10 70 39 0
72 10 69 37 0
72 10 68 37 0
72 10 67 37 0
72 10 66 37 0
72 10 65 37 0
72 10 64 37 0
72 10 63 37 64
72 11 85 35 32
72 11 84 37 0
72 11 83 37 0
72 11 82 39 0
72 11 81 39 0
72 11 80 39 0
72 11 79 39 0
72 11 78 39 0
72 11 77 39 0
72 11 76 39 0
72 11 75 39 0
72 11 74 39 0
72 11 73 39 0
72 11 72 39 0
72 11 71 39 0
72 11 70 39 0
72 11 69 37 0
72 11 68 37 0
72 11 67 37 0
72 11 66 37 0
72 11 65 37 0
72 11 64 37 0
72 11 63 37 64
72 12 85 35 32
72 12 84 37 0
72 12 83 37 0
72 12 82 39 0
72 12 81 39 0
72 12 80 39 0
72 12 79 39 0
72 12 78 39 0
72 12 77 39 0
72 12 76 39 0
72 12 75 39 0
72 12 74 39 0
72 12 73 39 0
72 12 72 39 0
72 12 71 39 0
72 12 70 39 0
72 12 69 37 0
72 12 68 37 0
72 12 67 37 0
72 12 66 37 0
72 12 65 37 0
72 12 64 37 0
72 12 63 37 64
72 13 85 35 32
72 13 84 37 0
72 13 83 37 0
72 13 82 39 0
72 13 81 39 0
72 13 80 39 0
72 13 79 39 0
72 13 78 39 0
72 13 77 39 0
72 13 76 39 0
72 13 75 39 0
72 13 74 39 0
72 13 73 39 0
72 13 72 39 0
72 13 71 39 0
72 13 70 39 0
72 13 69 37 0
72 13 68 37 0
72 13 67 37 0
72 13 66 37 0
72 13 65 37 0
72 13 64 37 0
72 13 63 37 64
72 14 85 35 32
72 14 84 37 0
72 14 83 37 0
72 14 82 39 0
72 14 81 39 0
72 14 80 39 0
72 14 79 39 0
72 14 78 39 0
72 14 77 39 0
72 14 76 39 0
72 14 75 39 0
72 14 74 39 0
72 14 73 39 0
72 14 72 39 0
72 14 71 39 0
72 14 70 39 0
72 14 69 37 0
72 14 68 37 0
72 14 67 37 0
72 14 66 37 0
72 14 65 37 0
72 14 64 37 0
72 14 63 37 64
72 15 85 35 32
72 15 84 37 0
72 15 83 37 0
72 15 82 39 0
72 15 81 39 0
72 15 80 39 0
72 15 79 39 0
72 15 78 39 0
72 15 77 39 0
72 15 76 39 0
72 15 75 39 0
72 15 74 39 0
72 15 73 39 0
72 15 72 39 0
72 15 71 39 0
72 15 70 39 0
72 15 69 37 0
72 15 68 37 0
72 15 67 37 0
72 15 66 37 0
72 15 65 37 0
72 15 64 37 0
72 15 63 37 64
72 16 85 35 32
72 16 84 37 0
72 16 83 37 0
72 16 82 39 0
72 16 81 39 0
72 16 80 39 0
72 16 79 39 0
72 16 78 39 0
72 16 77 39 0
72 16 76 39 0
72 16 75 39 0
72 16 74 39 0
72 16 73 39 0
72 16 72 39 0
72 16 71 39 0
72 16 70 39 0
72 16 69 37 0
72 16 68 37 0
72 16 67 37 0
72 16 66 37 0
72 16 65 37 0
72 16 64 37 0
72 16 63 37 64
72 17 85 42 32
72 17 84 42 0
72 17 83 42 0
72 17 82 39 0
72 17 81 39 0
72 17 80 39 0
72 17 79 39 0
72 17 78 39 0
72 17 77 39 0
72 17 76 39 0
72 17 75 39 0
72 17 74 39 0
72 17 73 39 0
72 17 72 39 0
72 17 71 39 0
72 17 70 39 0
72 17 69 42 0
72 17 68 42 0
72 17 67 42 0
72 17 66 42 0
72 17 65 42 0
72 17 64 42 0
72 17 63 42 64
72 18 85 42 32
72 18 84 42 0
72 18 83 42 0
72 18 82 39 0
72 18 81 39 0
72 18 80 39 0
72 18 79 39 0
72 18 78 39 0
72 18 77 39 0
72 18 76 39 0
72 18 75 39 0
72 18 74 39 0
72 18 73 39 0
72 18 72 39 0
72 18 71 39 0
72 18 70 39 0
72 18 69 42 0
72 18 68 42 0
72 18 67 42 0
72 18 66 42 0
72 18 65 42 0
72 18 64 42 0
72 18 63 42 64
72 19 86 35 48
72 19 85 35 0
72 19 84 35 0
72 19 83 35 0
72 19 82 39 0
72 19 81 39 0
72 19 80 39 0
72 19 79 39 0
72 19 78 39 0
72 19 77 39 0
72 19 76 39 0
72 19 75 39 0
72 19 74 39 0
72 19 73 39 0
72 19 72 39 0
72 19 71 39 0
72 19 70 39 0
72 19 69 35 0
72 19 68 35 0
72 19 67 35 0
72 19 66 35 0
72 19 65 35 0
72 19 64 35 0
72 19 63 35 64
72 20 87 35 48
72 20 86 35 0
72 20 85 35 0
72 20 84 35 0
72 20 83 35 0
72 20 82 39 0
72 20 81 39 0
72 20 80 39 0
72 20 79 39 0
72 20 78 39 0
72 20 77 39 0
72 20 76 39 0
72 20 75 39 0
72 20 74 39 0
72 20 73 39 0
72 20 72 39 0
72 20 71 39 0
72 20 70 39 0
72 20 69 35 0
72 20 68 35 0
72 20 67 35 0
72 20 66 35 0
72 20 65 35 0
72 20 64 35 0
72 20 63 35 64
72 21 88 35 48
72 21 87 35 0
72 21 86 35 0
72 21 85 35 0
72 21 84 35 0
72 21 83 35 0
72 21 82 39 0
72 21 81 39 0
72 21 80 39 0
72 21 79 39 0
72 21 78 39 0
72 21 77 39 0
72 21 76 39 0
72 21 75 39 0
72 21 74 39 0
72 21 73 39 0
72 21 72 39 0
72 21 71 39 0
72 21 70 39 0
72 21 69 35 0
72 21 68 35 0
72 21 67 35 0
72 21 66 35 0
72 21 65 35 0
72 21 64 35 0
72 21 63 35 64
72 22 89 35 48
72 22 88 35 0
72 22 87 35 0
72 22 86 35 0
72 22 85 35 0
72 22 84 35 0
72 22 83 35 0
72 22 82 39 0
72 22 81 39 0
72 22 80 39 0
72 22 79 39 0
72 22 78 39 0
72 22 77 39 0
72 22 76 39 0
72 22 75 39 0
72 22 74 39 0
72 22 73 39 0
72 22 72 39 0
72 22 71 39 0
72 22 70 39 0
72 22 69 35 0
72 22 68 35 0
72 22 67 35 0
72 22 66 35 0
72 22 65 35 0
72 22 64 35 0
72 22 63 35 64
72 23 89 35 40
72 23 88 24 8
72 23 87 35 8
72 23 86 23 8
72 23 85 23 8
72 23 84 23 8
72 23 83 23 8
72 23 82 39 8
72 23 81 39 8
72 23 80 39 8
72 23 79 39 8
72 23 78 39 8
72 23 77 39 8
72 23 76 39 8
72 23 75 39 8
72 23 74 39 8
72 23 73 39 8
72 23 72 39 8
72 23 71 39 8
72 23 70 39 8
72 23 69 23 8
72 23 68 23 8
72 23 67 23 8
72 23 66 23 8
72 23 65 35 8
72 23 64 24 8
72 23 63 35 72
73 1 85 42 48
73 1 84 42 16
73 1 83 42 16
73 1 82 39 16
73 1 81 39 16
73 1 80 39 16
73 1 79 39 16
73 1 78 39 16
73 1 77 39 16
73 1 76 39 16
73 1 75 39 16
73 1 74 39 16
73 1 73 39 16
73 1 72 39 16
73 1 71 39 16
73 1 70 39 16
73 1 69 42 16
73 1 68 42 16
73 1 67 42 16
73 1 66 42 16
73 1 65 42 16
73 1 64 42 16
73 1 63 42 80
73 2 85 42 32
73 2 84 42 0
73 2 83 42 0
73 2 82 39 0
73 2 81 39 0
73 2 80 39 0
73 2 79 39 0
73 2 78 39 0
73 2 77 39 0
73 2 76 39 0
73 2 75 39 0
73 2 74 39 0
73 2 73 39 0
73 2 72 39 0
73 2 71 39 0
73 2 70 39 0
73 2 69 42 0
73 2 68 42 0
73 2 67 42 0
73 2 66 42 0
73 2 65 42 0
73 2 64 42 0
73 2 63 42 64
73 3 85 37 32
73 3 84 37 0
73 3 83 37 0
73 3 82 39 0
73 3 81 39 0
73 3 80 39 0
73 3 79 39 0
73 3 78 39 0
73 3 77 39 0
73 3 76 39 0
73 3 75 39 0
73 3 74 39 0
73 3 73 39 0
73 3 72 39 0
73 3 71 39 0
73 3 70 39 0
73 3 69 37 0
73 3 68 37 0
73 3 67 37 0
73 3 66 37 0
73 3 65 37 0
73 3 64 37 0
73 3 63 37 64
73 4 85 37 32
73 4 84 37 0
73 4 83 37 0
73 4 82 39 0
73 4 81 39 0
73 4 80 39 0
73 4 79 39 0
73 4 78 39 0
73 4 77 39 0
73 4 76 39 0
73 4 75 39 0
73 4 74 39 0
73 4 73 39 0
73 4 72 39 0
73 4 71 39 0
73 4 70 39 0
73 4 69 37 0
73 4 68 37 0
73 4 67 37 0
73 4 66 37 0
73 4 65 37 0
73 4 64 37 0
73 4 63 37 64
73 5 85 37 32
73 5 84 37 0
73 5 83 37 0
73 5 82 39 0
73 5 81 39 0
73 5 80 39 0
73 5 79 39 0
73 5 78 39 0
73 5 77 39 0
73 5 76 39 0
73 5 75 39 0
73 5 74 39 0
73 5 73 39 0
73 5 72 39 0
73 5 71 39 0
73 5 70 39 0
73 5 69 37 0
73 5 68 37 0
73 5 67 37 0
73 5 66 37 0
73 5 65 37 0
73 5 64 37 0
73 5 63 37 64
73 6 85 37 32
73 6 84 37 0
73 6 83 37 0
73 6 82 39 0
73 6 81 39 0
73 6 80 39 0
73 6 79 39 0
73 6 78 39 0
73 6 77 39 0
73 6 76 39 0
73 6 75 39 0
73 6 74 39 0
73 6 73 39 0
73 6 72 39 0
73 6 71 39 0
73 6 70 39 0
73 6 69 37 0
73 6 68 37 0
73 6 67 37 0
73 6 66 37 0
73 6 65 37 0
73 6 64 37 0
73 6 63 37 64
73 7 89 55 120
73 7 85 37 32
73 7 84 37 0
73 7 83 37 0
73 7 82 39 0
73 7 81 39 0
73 7 80 39 0
73 7 79 39 0
73 7 78 39 0
73 7 77 39 0
73 7 76 39 0
73 7 75 39 0
73 7 74 39 0
73 7 73 39 0
73 7 72 39 0
73 7 71 39 0
73 7 70 39 0
73 7 69 37 0
73 7 68 37 0
73 7 67 37 0
73 7 66 37 0
73 7 65 37 0
73 7 64 37 0
73 7 63 37 64
73 8 85 37 32
73 8 84 37 0
73 8 83 37 0
73 8 82 39 0
73 8 81 39 0
73 8 80 39 0
73 8 79 39 0
73 8 78 39 0
73 8 77 39 0
73 8 76 39 0
73 8 75 39 0
73 8 74 39 0
73 8 73 39 0
73 8 72 39 0
73 8 71 39 0
73 8 70 39 0
73 8 69 37 0
73 8 68 37 0
73 8 67 37 0
73 8 66 37 0
73 8 65 37 0
73 8 64 37 0
73 8 63 37 64
73 9 85 37 32
73 9 84 37 0
73 9 83 37 0
73 9 82 39 0
73 9 81 39 0
73 9 80 39 0
73 9 79 39 0
73 9 78 39 0
73 9 77 39 0
73 9 76 39 0
73 9 75 39 0
73 9 74 39 0
73 9 73 39 0
73 9 72 39 0
73 9 71 39 0
73 9 70 39 0
73 9 69 37 0
73 9 68 37 0
73 9 67 37 0
73 9 66 37 0
73 9 65 37 0
73 9 64 37 0
73 9 63 37 64
73 10 85 37 32
73 10 84 37 0
73 10 83 37 0
73 10 82 39 0
73 10 81 39 0
73 10 80 39 0
73 10 79 39 0
73 10 78 39 0
73 10 77 39 0
73 10 76 39 0
73 10 75 39 0
73 10 74 39 0
73 10 73 39 0
73 10 72 39 0
73 10 71 39 0
73 10 70 39 0
73 10 69 37 0
73 10 68 37 0
73 10 67 37 0
73 10 66 37 0
73 10 65 37 0
73 10 64 37 0
73 10 63 37 64
73 11 85 37 32
73 11 84 37 0
73 11 83 37 0
73 11 82 39 0
73 11 81 39 0
73 11 80 39 0
73 11 79 39 0
73 11 78 39 0
73 11 77 39 0
73 11 76 39 0
73 11 75 39 0
73 11 74 39 0
73 11 73 39 0
73 11 72 39 0
73 11 71 39 0
73 11 70 39 0
73 11 69 37 0
73 11 68 37 0
73 11 67 37 0
73 11 66 37 0
73 11 65 37 0
73 11 64 37 0
73 11 63 37 64
73 12 85 37 32
73 12 84 37 0
73 12 83 37 0
73 12 82 39 0
73 12 81 39 0
73 12 80 39 0
73 12 79 39 0
73 12 78 39 0
73 12 77 39 0
73 12 76 39 0
73 12 75 39 0
73 12 74 39 0
73 12 73 39 0
73 12 72 39 0
73 12 71 39 0
73 12 70 39 0
73 12 69 37 0
73 12 68 37 0
73 12 67 37 0
73 12 66 37 0
73 12 65 37 0
73 12 64 37 0
73 12 63 37 64
73 13 85 37 32
73 13 84 37 0
73 13 83 37 0
73 13 82 39 0
73 13 81 39 0
73 13 80 39 0
73 13 79 39 0
73 13 78 39 0
73 13 77 39 0
73 13 76 39 0
73 13 75 39 0
73 13 74 39 0
73 13 73 39 0
73 13 72 39 0
73 13 71 39 0
73 13 70 39 0
73 13 69 37 0
73 13 68 37 0
73 13 67 37 0
73 13 66 37 0
73 13 65 37 0
73 13 64 37 0
73 13 63 37 64
73 14 85 37 32
73 14 84 37 0
73 14 83 37 0
73 14 82 39 0
73 14 81 39 0
73 14 80 39 0
73 14 79 39 0
73 14 78 39 0
73 14 77 39 0
73 14 76 39 0
73 14 75 39 0
73 14 74 39 0
73 14 73 39 0
73 14 72 39 0
73 14 71 39 0
73 14 70 39 0
73 14 69 37 0
73 14 68 37 0
73 14 67 37 0
73 14 66 37 0
73 14 65 37 0
73 14 64 37 0
73 14 63 37 64
73 15 85 37 32
73 15 84 37 0
73 15 83 37 0
73 15 82 39 0
73 15 81 39 0
73 15 80 39 0
73 15 79 39 0
73 15 78 39 0
73 15 77 39 0
73 15 76 39 0
73 15 75 39 0
73 15 74 39 0
73 15 73 39 0
73 15 72 39 0
73 15 71 39 0
73 15 70 39 0
73 15 69 37 0
73 15 68 37 0
73 15 67 37 0
73 15 66 37 0
73 15 65 37 0
73 15 64 37 0
73 15 63 37 64
73 16 85 37 32
73 16 84 37 0
73 16 83 37 0
73 16 82 39 0
73 16 81 39 0
73 16 80 39 0
73 16 79 39 0
73 16 78 39 0
73 16 77 39 0
73 16 76 39 0
73 16 75 39 0
73 16 74 39 0
73 16 73 39 0
73 16 72 39 0
73 16 71 39 0
73 16 70 39 0
73 16 69 37 0
73 16 68 37 0
73 16 67 37 0
73 16 66 37 0
73 16 65 37 0
73 16 64 37 0
73 16 63 37 64
73 17 85 42 32
73 17 84 42 0
73 17 83 42 0
73 17 82 39 0
73 17 81 39 0
73 17 80 39 0
73 17 79 39 0
73 17 78 39 0
73 17 77 39 0
73 17 76 39 0
73 17 75 39 0
73 17 74 39 0
73 17 73 39 0
73 17 72 39 0
73 17 71 39 0
73 17 70 39 0
73 17 69 42 0
73 17 68 42 0
73 17 67 42 0
73 17 66 42 0
73 17 65 42 0
73 17 64 42 0
73 17 63 42 64
73 18 85 42 32
73 18 84 42 0
73 18 83 42 0
73 18 82 39 0
73 18 81 39 0
73 18 80 39 0
73 18 79 39 0
73 18 78 39 0
73 18 77 39 0
73 18 76 39 0
73 18 75 39 0
73 18 74 39 0
73 18 73 39 0
73 18 72 39 0
73 18 71 39 0
73 18 70 39 0
73 18 69 42 0
73 18 68 42 0
73 18 67 42 0
73 18 66 42 0
73 18 65 42 0
73 18 64 42 0
73 18 63 42 64
73 19 86 35 48
73 19 85 35 0
73 19 84 35 0
73 19 83 35 0
73 19 82 39 0
73 19 81 39 0
73 19 80 39 0
73 19 79 39 0
73 19 78 39 0
73 19 77 39 0
73 19 76 39 0
73 19 75 39 0
73 19 74 39 0
73 19 73 39 0
73 19 72 39 0
73 19 71 39 0
73 19 70 39 0
73 19 69 35 0
73 19 68 35 0
73 19 67 35 0
73 19 66 35 0
73 19 65 35 0
73 19 64 35 0
73 19 63 35 64
73 20 87 35 48
73 20 86 35 0
73 20 85 35 0
73 20 84 35 0
73 20 83 35 0
73 20 82 39 0
73 20 81 39 0
73 20 80 39 0
73 20 79 39 0
73 20 78 39 0
73 20 77 39 0
73 20 76 39 0
73 20 75 39 0
73 20 74 39 0
73 20 73 39 0
73 20 72 39 0
73 20 71 39 0
73 20 70 39 0
73 20 69 35 0
73 20 68 35 0
73 20 67 35 0
73 20 66 35 0
73 20 65 35 0
73 20 64 35 0
73 20 63 35 64
73 21 88 35 48
73 21 87 35 0
73 21 86 35 0
73 21 85 35 0
73 21 84 35 0
73 21 83 35 0
73 21 82 39 0
73 21 81 39 0
73 21 80 39 0
73 21 79 39 0
73 21 78 39 0
73 21 77 39 0
73 21 76 39 0
73 21 75 39 0
73 21 74 39 0
73 21 73 39 0
73 21 72 39 0
73 21 71 39 0
73 21 70 39 0
73 21 69 35 0
73 21 68 35 0
73 21 67 35 0
73 21 66 35 0
73 21 65 35 0
73 21 64 35 0
73 21 63 35 64
73 22 89 35 48
73 22 88 35 0
73 22 87 35 0
73 22 86 35 0
73 22 85 35 0
73 22 84 35 0
73 22 83 35 0
73 22 82 39 0
73 22 81 39 0
73 22 80 39 0
73 22 79 39 0
73 22 78 39 0
73 22 77 39 0
73 22 76 39 0
73 22 75 39 0
73 22 74 39 0
73 22 73 39 0
73 22 72 39 0
73 22 71 39 0
73 22 70 39 0
73 22 69 35 0
73 22 68 35 0
73 22 67 35 0
73 22 66 35 0
73 22 65 35 0
73 22 64 35 0
73 22 63 35 64
73 23 89 35 40
73 23 88 24 8
73 23 87 35 8
73 23 86 23 8
73 23 85 23 8
73 23 84 23 8
73 23 83 23 8
73 23 82 39 8
73 23 81 39 8
73 23 80 39 8
73 23 79 39 8
73 23 78 39 8
73 23 77 39 8
73 23 76 39 8
73 23 75 39 8
73 23 74 39 8
73 23 73 39 8
73 23 72 39 8
73 23 71 39 8
73 23 70 39 8
73 23 69 23 8
73 23 68 23 8
73 23 67 23 8
73 23 66 23 8
73 23 65 35 8
73 23 64 24 8
73 23 63 35 72
74 1 85 42 48
74 1 84 42 16
74 1 83 42 16
74 1 82 39 16
74 1 81 39 16
74 1 80 39 16
74 1 79 39 16
74 1 78 39 16
74 1 77 39 16
74 1 76 39 16
74 1 75 39 16
74 1 74 39 16
74 1 73 39 16
74 1 72 39 16
74 1 71 39 16
74 1 70 39 16
74 1 69 42 16
74 1 68 42 16
74 1 67 42 16
74 1 66 42 16
74 1 65 42 16
74 1 64 42 16
74 1 63 42 80
74 2 85 42 32
74 2 84 42 0
74 2 83 42 0
74 2 82 39 0
74 2 81 39 0
74 2 80 39 0
74 2 79 39 0
74 2 78 39 0
74 2 77 39 0
74 2 76 39 0
74 2 75 39 0
74 2 74 39 0
74 2 73 39 0
74 2 72 39 0
74 2 71 39 0
74 2 70 39 0
74 2 69 42 0
74 2 68 42 0
74 2 67 42 0
74 2 66 42 0
74 2 65 42 0
74 2 64 42 0
74 2 63 42 64
74 3 85 37 32
74 3 84 37 0
74 3 83 37 0
74 3 82 39 0
74 3 81 39 0
74 3 80 39 0
74 3 79 39 0
74 3 78 39 0
74 3 77 39 0
74 3 76 39 0
74 3 75 39 0
74 3 74 39 0
74 3 73 39 0
74 3 72 39 0
74 3 71 39 0
74 3 70 39 0
74 3 69 37 0
74 3 68 37 0
74 3 67 37 0
74 3 66 37 0
74 3 65 37 0
74 3 64 37 0
74 3 63 37 64
74 4 85 37 32
74 4 84 37 0
74 4 83 37 0
74 4 82 39 0
74 4 81 39 0
74 4 80 39 0
74 4 79 39 0
74 4 78 39 0
74 4 77 39 0
74 4 76 39 0
74 4 75 39 0
74 4 74 39 0
74 4 73 39 0
74 4 72 39 0
74 4 71 39 0
74 4 70 39 0
74 4 69 37 0
74 4 68 37 0
74 4 67 37 0
74 4 66 37 0
74 4 65 37 0
74 4 64 37 0
74 4 63 37 64
74 5 85 37 32
74 5 84 37 0
74 5 83 37 0
74 5 82 39 0
74 5 81 39 0
74 5 80 39 0
74 5 79 39 0
74 5 78 39 0
74 5 77 39 0
74 5 76 39 0
74 5 75 39 0
74 5 74 39 0
74 5 73 39 0
74 5 72 39 0
74 5 71 39 0
74 5 70 39 0
74 5 69 37 0
74 5 68 37 0
74 5 67 37 0
74 5 66 37 0
74 5 65 37 0
74 5 64 37 0
74 5 63 37 64
74 6 85 37 32
74 6 84 37 0
74 6 83 37 0
74 6 82 39 0
74 6 81 39 0
74 6 80 39 0
74 6 79 39 0
74 6 78 39 0
74 6 77 39 0
74 6 76 39 0
