Qubicle Exchange Format
Version 0.2
www.minddesk.com
70 57 129
70
0.000000 0.000000 0.000000
0.047059 0.168627 0.298039
0.094118 0.203922 0.321569
0.121569 0.125490 0.125490
0.141176 0.211765 0.392157
0.164706 0.254902 0.482353
0.172549 0.596078 0.329412
0.188235 0.192157 0.196078
0.192157 0.250980 0.388235
0.192157 0.254902 0.411765
0.203922 0.141176 0.007843
0.215686 0.388235 0.623529
0.219608 0.615686 0.364706
0.227451 0.415686 0.737255
0.247059 0.666667 0.403922
0.266667 0.156863 0.000000
0.266667 0.333333 0.494118
0.274510 0.141176 0.176471
0.282353 0.192157 0.007843
0.290196 0.298039 0.301961
0.313725 0.384314 0.556863
0.341176 0.227451 0.000000
0.360784 0.231373 0.047059
0.376471 0.384314 0.392157
0.380392 0.662745 0.486275
0.411765 0.305882 0.090196
0.419608 0.580392 0.854902
0.450980 0.286275 0.050980
0.454902 0.466667 0.474510
0.454902 0.545098 0.556863
0.482353 0.105882 0.117647
0.486275 0.309804 0.054902
0.501961 0.415686 0.286275
0.537255 0.364706 0.019608
0.537255 0.537255 0.321569
0.541176 0.419608 0.176471
0.549020 0.450980 0.309804
0.552941 0.564706 0.572549
0.588235 0.588235 0.364706
0.592157 0.466667 0.207843
0.635294 0.647059 0.650980
0.647059 0.498039 0.192157
0.658824 0.658824 0.474510
0.670588 0.670588 0.505882
0.745098 0.635294 0.003922
0.776471 0.729412 0.400000
0.776471 0.776471 0.615686
0.796078 0.690196 0.070588
0.796078 0.803922 0.807843
0.800000 0.694118 0.494118
0.823529 0.823529 0.635294
0.827451 0.784314 0.490196
0.835294 0.666667 0.043137
0.847059 0.705882 0.062745
0.850980 0.745098 0.545098
0.854902 0.815686 0.501961
0.858824 0.752941 0.552941
0.862745 0.780392 0.309804
0.866667 0.737255 0.588235
0.870588 0.709804 0.549020
0.874510 0.874510 0.725490
0.882353 0.835294 0.549020
0.894118 0.200000 0.203922
0.909804 0.811765 0.639216
0.909804 0.866667 0.541176
0.909804 0.913725 0.913725
0.960784 0.533333 0.086275
0.988235 0.784314 0.031373
1.000000 0.905882 0.003922
1.000000 0.941176 0.411765
1 24 98 28 60
1 24 97 28 28
1 24 96 28 92
1 24 66 28 60
1 24 65 28 28
1 24 64 28 92
2 23 97 67 52
2 23 96 53 20
2 23 95 66 86
2 23 67 66 54
2 23 66 52 20
2 23 65 67 84
2 24 98 28 56
2 24 97 18 8
2 24 96 18 0
2 24 95 18 4
2 24 94 18 20
2 24 93 18 20
2 24 92 18 20
2 24 91 18 20
2 24 90 18 20
2 24 89 18 20
2 24 88 18 20
2 24 87 18 20
2 24 86 18 20
2 24 85 18 20
2 24 84 18 20
2 24 83 18 20
2 24 82 30 84
2 24 80 30 52
2 24 79 18 20
2 24 78 18 20
2 24 77 18 20
2 24 76 18 20
2 24 75 18 20
2 24 74 18 20
2 24 73 18 20
2 24 72 18 20
2 24 71 18 20
2 24 70 18 20
2 24 69 18 20
2 24 68 18 20
2 24 67 18 4
2 24 66 18 0
2 24 65 18 8
2 24 64 28 88
2 25 96 18 44
2 25 95 18 12
2 25 94 18 12
2 25 93 18 12
2 25 92 18 12
2 25 91 18 12
2 25 90 18 12
2 25 89 18 12
2 25 88 18 12
2 25 87 18 12
2 25 86 18 12
2 25 85 18 12
2 25 84 18 12
2 25 83 18 4
2 25 82 18 4
2 25 81 30 20
2 25 80 18 4
2 25 79 18 4
2 25 78 18 12
2 25 77 18 12
2 25 76 18 12
2 25 75 18 12
2 25 74 18 12
2 25 73 18 12
2 25 72 18 12
2 25 71 18 12
2 25 70 18 12
2 25 69 18 12
2 25 68 18 12
2 25 67 18 12
2 25 66 18 76
2 26 83 18 44
2 26 82 18 4
2 26 81 30 4
2 26 80 18 4
2 26 79 18 76
2 27 82 18 44
2 27 81 30 14
2 27 80 18 78
3 23 97 53 48
3 23 96 66 82
3 23 66 66 50
3 23 65 52 80
3 24 98 28 58
3 24 97 18 0
3 24 96 21 0
3 24 95 21 16
3 24 94 21 16
3 24 93 21 16
3 24 92 21 16
3 24 91 21 16
3 24 90 21 16
3 24 89 21 16
3 24 88 21 16
3 24 87 21 16
3 24 86 21 16
3 24 85 21 16
3 24 84 21 16
3 24 83 21 16
3 24 82 30 82
3 24 80 30 50
3 24 79 21 16
3 24 78 21 16
3 24 77 21 16
3 24 76 21 16
3 24 75 21 16
3 24 74 21 16
3 24 73 21 16
3 24 72 21 16
3 24 71 21 16
3 24 70 21 16
3 24 69 21 16
3 24 68 21 16
3 24 67 21 16
3 24 66 21 0
3 24 65 18 0
3 24 64 28 90
3 25 97 18 44
3 25 96 65 0
3 25 95 65 0
3 25 94 65 0
3 25 93 65 0
3 25 92 65 0
3 25 91 65 0
3 25 90 65 0
3 25 89 65 0
3 25 88 65 0
3 25 87 65 0
3 25 86 65 0
3 25 85 65 0
3 25 84 65 0
3 25 83 65 0
3 25 82 30 0
3 25 81 30 16
3 25 80 30 0
3 25 79 65 0
3 25 78 65 0
3 25 77 65 0
3 25 76 65 0
3 25 75 65 0
3 25 74 65 0
3 25 73 65 0
3 25 72 65 0
3 25 71 65 0
3 25 70 65 0
3 25 69 65 0
3 25 68 65 0
3 25 67 65 0
3 25 66 65 0
3 25 65 18 76
3 26 96 65 36
3 26 95 65 4
3 26 94 65 4
3 26 93 65 4
3 26 92 65 4
3 26 91 65 4
3 26 90 65 4
3 26 89 65 4
3 26 88 65 4
3 26 87 65 4
3 26 86 65 4
3 26 85 65 4
3 26 84 65 4
3 26 83 65 0
3 26 82 30 0
3 26 81 65 8
3 26 80 65 8
3 26 79 65 8
3 26 78 65 12
3 26 77 65 12
3 26 76 65 12
3 26 75 65 12
3 26 74 65 12
3 26 73 65 12
3 26 72 65 12
3 26 71 65 12
3 26 70 65 12
3 26 69 65 12
3 26 68 65 12
3 26 67 65 12
3 26 66 65 76
3 27 96 65 44
3 27 95 65 12
3 27 94 65 12
3 27 93 65 12
3 27 92 65 12
3 27 91 65 12
3 27 90 65 12
3 27 89 65 12
3 27 88 65 12
3 27 87 65 12
3 27 86 65 12
3 27 85 65 12
3 27 84 65 12
3 27 83 65 12
3 27 82 65 72
4 23 97 66 114
4 23 65 66 114
4 24 97 18 32
4 24 96 21 16
4 24 95 18 16
4 24 94 18 16
4 24 93 18 16
4 24 92 18 16
4 24 91 18 16
4 24 90 18 16
4 24 89 18 16
4 24 88 18 16
4 24 87 18 16
4 24 86 18 16
4 24 85 18 16
4 24 84 18 16
4 24 83 21 80
4 24 79 21 48
4 24 78 18 16
4 24 77 18 16
4 24 76 18 16
4 24 75 18 16
4 24 74 18 16
4 24 73 18 16
4 24 72 18 16
4 24 71 18 16
4 24 70 18 16
4 24 69 18 16
4 24 68 18 16
4 24 67 18 16
4 24 66 21 16
4 24 65 18 64
4 25 97 18 40
4 25 96 65 0
4 25 95 21 0
4 25 94 21 0
4 25 93 21 0
4 25 92 21 0
4 25 91 21 0
4 25 90 21 0
4 25 89 65 0
4 25 88 21 0
4 25 87 21 0
4 25 86 21 0
4 25 85 21 0
4 25 84 21 0
4 25 83 21 0
4 25 82 18 16
4 25 81 30 16
4 25 80 18 16
4 25 79 21 0
4 25 78 21 0
4 25 77 21 0
4 25 76 21 0
4 25 75 21 0
4 25 74 21 0
4 25 73 65 0
4 25 72 21 0
4 25 71 21 0
4 25 70 21 0
4 25 69 21 0
4 25 68 21 0
4 25 67 21 0
4 25 66 65 0
4 25 65 18 72
4 26 96 65 32
4 26 95 21 0
4 26 94 21 0
4 26 93 21 0
4 26 92 21 0
4 26 91 21 0
4 26 90 21 0
4 26 89 65 0
4 26 88 21 0
4 26 87 21 0
4 26 86 21 0
4 26 85 21 0
4 26 84 21 0
4 26 83 21 0
4 26 82 18 0
4 26 81 43 8
4 26 80 65 8
4 26 79 50 8
4 26 78 50 8
4 26 77 50 8
4 26 76 50 8
4 26 75 60 8
4 26 74 60 8
4 26 73 65 8
4 26 72 46 8
4 26 71 46 8
4 26 70 50 8
4 26 69 50 8
4 26 68 46 8
4 26 67 46 8
4 26 66 65 72
4 27 96 65 40
4 27 95 50 8
4 27 94 46 8
4 27 93 46 8
4 27 92 46 8
4 27 91 50 8
4 27 90 50 8
4 27 89 65 8
4 27 88 68 8
4 27 87 69 8
4 27 86 7 8
4 27 85 7 8
4 27 84 69 8
4 27 83 68 8
4 27 82 65 72
5 24 97 18 48
5 24 96 21 16
5 24 95 18 16
5 24 94 21 16
5 24 93 21 16
5 24 92 21 16
5 24 91 21 16
5 24 90 21 16
5 24 89 21 16
5 24 88 21 16
5 24 87 21 16
5 24 86 21 16
5 24 85 21 16
5 24 84 18 16
5 24 83 21 16
5 24 82 30 84
5 24 80 30 52
5 24 79 21 16
5 24 78 18 16
5 24 77 21 16
5 24 76 21 16
5 24 75 21 16
5 24 74 21 16
5 24 73 21 16
5 24 72 21 16
5 24 71 21 16
5 24 70 21 16
5 24 69 21 16
5 24 68 21 16
5 24 67 18 16
5 24 66 21 16
5 24 65 18 80
5 25 97 18 40
5 25 96 65 0
5 25 95 21 0
5 25 94 21 0
5 25 93 21 0
5 25 92 21 0
5 25 91 21 0
5 25 90 21 0
5 25 89 65 0
5 25 88 21 0
5 25 87 21 0
5 25 86 21 0
5 25 85 21 0
5 25 84 21 0
5 25 83 21 0
5 25 82 18 0
5 25 81 30 16
5 25 80 18 0
5 25 79 21 0
5 25 78 21 0
5 25 77 21 0
5 25 76 21 0
5 25 75 21 0
5 25 74 21 0
5 25 73 65 0
5 25 72 21 0
5 25 71 21 0
5 25 70 21 0
5 25 69 21 0
5 25 68 21 0
5 25 67 21 0
5 25 66 65 0
5 25 65 18 72
5 26 96 65 32
5 26 95 21 0
5 26 94 21 0
5 26 93 21 0
5 26 92 21 0
5 26 91 21 0
5 26 90 21 0
5 26 89 65 0
5 26 88 21 0
5 26 87 21 0
5 26 86 21 0
5 26 85 21 0
5 26 84 21 0
5 26 83 21 0
5 26 82 18 0
5 26 81 43 8
5 26 80 65 8
5 26 79 46 8
5 26 78 46 8
5 26 77 46 8
5 26 76 50 8
5 26 75 50 8
5 26 74 50 8
5 26 73 65 8
5 26 72 50 8
5 26 71 50 8
5 26 70 60 8
5 26 69 60 8
5 26 68 60 8
5 26 67 50 8
5 26 66 65 72
5 27 96 65 40
5 27 95 60 8
5 27 94 60 8
5 27 93 60 8
5 27 92 50 8
5 27 91 50 8
5 27 90 50 8
5 27 89 65 8
5 27 88 68 8
5 27 87 69 8
5 27 86 7 8
5 27 85 7 8
5 27 84 69 8
5 27 83 68 8
5 27 82 65 72
6 1 103 23 52
6 1 102 23 20
6 1 101 23 22
6 1 100 23 22
6 1 99 23 22
6 1 98 23 22
6 1 97 23 22
6 1 96 23 22
6 1 95 23 22
6 1 94 23 22
6 1 93 23 22
6 1 92 23 22
6 1 91 23 22
6 1 90 23 22
6 1 89 23 22
6 1 88 23 22
6 1 87 23 22
6 1 86 23 22
6 1 85 23 22
6 1 84 23 22
6 1 83 23 22
6 1 82 23 22
6 1 81 23 22
6 1 80 23 22
6 1 79 23 22
6 1 78 23 22
6 1 77 23 22
6 1 76 23 22
6 1 75 23 22
6 1 74 23 22
6 1 73 23 22
6 1 72 23 22
6 1 71 23 22
6 1 70 23 22
6 1 69 23 22
6 1 68 23 22
6 1 67 23 22
6 1 66 23 22
6 1 65 23 22
6 1 64 23 22
6 1 63 23 22
6 1 62 23 22
6 1 61 23 22
6 1 60 23 22
6 1 59 23 22
6 1 58 23 22
6 1 57 23 22
6 1 56 23 22
6 1 55 23 22
6 1 54 23 22
6 1 53 23 20
6 1 52 23 20
6 1 51 23 22
6 1 50 23 22
6 1 49 23 22
6 1 48 23 22
6 1 47 23 22
6 1 46 23 22
6 1 45 23 22
6 1 44 23 22
6 1 43 23 22
6 1 42 23 22
6 1 41 23 22
6 1 40 23 22
6 1 39 23 22
6 1 38 23 22
6 1 37 23 22
6 1 36 23 22
6 1 35 23 22
6 1 34 23 22
6 1 33 23 22
6 1 32 23 22
6 1 31 23 22
6 1 30 23 22
6 1 29 23 22
6 1 28 23 22
6 1 27 23 22
6 1 26 23 22
6 1 25 23 22
6 1 24 23 22
6 1 23 23 22
6 1 22 23 22
6 1 21 23 22
6 1 20 23 22
6 1 19 23 22
6 1 18 23 22
6 1 17 23 22
6 1 16 23 22
6 1 15 23 22
6 1 14 23 22
6 1 13 23 22
6 1 12 23 22
6 1 11 23 22
6 1 10 23 22
6 1 9 23 22
6 1 8 23 22
6 1 7 23 22
6 1 6 23 22
6 1 5 23 22
6 1 4 23 22
6 1 3 23 20
6 1 2 23 84
6 2 103 23 44
6 2 102 23 12
6 2 101 23 12
6 2 100 23 12
6 2 99 23 12
6 2 98 23 12
6 2 97 23 12
6 2 96 23 12
6 2 95 23 12
6 2 94 23 12
6 2 93 23 12
6 2 92 23 12
6 2 91 23 12
6 2 90 23 12
6 2 89 23 12
6 2 88 23 12
6 2 87 23 12
6 2 86 23 12
6 2 85 23 12
6 2 84 23 12
6 2 83 23 12
6 2 82 23 12
6 2 81 23 12
6 2 80 23 12
6 2 79 23 12
6 2 78 23 12
6 2 77 23 12
6 2 76 23 12
6 2 75 23 12
6 2 74 23 12
6 2 73 23 12
6 2 72 23 12
6 2 71 23 12
6 2 70 23 12
6 2 69 23 12
6 2 68 23 12
6 2 67 23 12
6 2 66 23 12
6 2 65 23 12
6 2 64 23 12
6 2 63 23 12
6 2 62 23 12
6 2 61 23 12
6 2 60 23 12
6 2 59 23 12
6 2 58 23 12
6 2 57 23 12
6 2 56 23 12
6 2 55 23 12
6 2 54 23 12
6 2 53 23 12
6 2 52 23 12
6 2 51 23 12
6 2 50 23 12
6 2 49 23 12
6 2 48 23 12
6 2 47 23 12
6 2 46 23 12
6 2 45 23 12
6 2 44 23 12
6 2 43 23 12
6 2 42 23 12
6 2 41 23 12
6 2 40 23 12
6 2 39 23 12
6 2 38 23 12
6 2 37 23 12
6 2 36 23 12
6 2 35 23 12
6 2 34 23 12
6 2 33 23 12
6 2 32 23 12
6 2 31 23 12
6 2 30 23 12
6 2 29 23 12
6 2 28 23 12
6 2 27 23 12
6 2 26 23 12
6 2 25 23 12
6 2 24 23 12
6 2 23 23 12
6 2 22 23 12
6 2 21 23 12
6 2 20 23 12
6 2 19 23 12
6 2 18 23 12
6 2 17 23 12
6 2 16 23 12
6 2 15 23 12
6 2 14 23 12
6 2 13 23 12
6 2 12 23 12
6 2 11 23 12
6 2 10 23 12
6 2 9 23 12
6 2 8 23 12
6 2 7 23 12
6 2 6 23 12
6 2 5 23 12
6 2 4 23 12
6 2 3 23 12
6 2 2 23 76
6 24 97 18 48
6 24 96 21 16
6 24 95 18 16
6 24 94 21 16
6 24 93 21 16
6 24 92 21 16
6 24 91 21 16
6 24 90 21 16
6 24 89 21 16
6 24 88 21 16
6 24 87 21 16
6 24 86 21 16
6 24 85 21 16
6 24 84 18 16
6 24 83 21 16
6 24 82 30 80
6 24 80 30 48
6 24 79 21 16
6 24 78 18 16
6 24 77 21 16
6 24 76 21 16
6 24 75 21 16
6 24 74 21 16
6 24 73 21 16
6 24 72 21 16
6 24 71 21 16
6 24 70 21 16
6 24 69 21 16
6 24 68 21 16
6 24 67 18 16
6 24 66 21 16
6 24 65 18 80
6 25 97 18 40
6 25 96 65 0
6 25 95 21 0
6 25 94 21 0
6 25 93 21 0
6 25 92 21 0
6 25 91 21 0
6 25 90 21 0
6 25 89 65 0
6 25 88 21 0
6 25 87 21 0
6 25 86 21 0
6 25 85 21 0
6 25 84 21 0
6 25 83 21 0
6 25 82 30 0
6 25 81 30 16
6 25 80 30 0
6 25 79 21 0
6 25 78 21 0
6 25 77 21 0
6 25 76 21 0
6 25 75 21 0
6 25 74 21 0
6 25 73 65 0
6 25 72 21 0
6 25 71 21 0
6 25 70 21 0
6 25 69 21 0
6 25 68 21 0
6 25 67 21 0
6 25 66 65 0
6 25 65 18 72
6 26 96 65 32
6 26 95 21 0
6 26 94 21 0
6 26 93 21 0
6 26 92 21 0
6 26 91 21 0
6 26 90 21 0
6 26 89 65 0
6 26 88 21 0
6 26 87 21 0
6 26 86 21 0
6 26 85 21 0
6 26 84 21 0
6 26 83 21 0
6 26 82 30 0
6 26 81 43 8
6 26 80 65 8
6 26 79 50 8
6 26 78 50 8
6 26 77 60 8
6 26 76 60 8
6 26 75 60 8
6 26 74 60 8
6 26 73 65 8
6 26 72 50 8
6 26 71 46 8
6 26 70 46 8
6 26 69 46 8
6 26 68 50 8
6 26 67 50 8
6 26 66 65 72
6 27 96 65 40
6 27 95 50 8
6 27 94 50 8
6 27 93 46 8
6 27 92 46 8
6 27 91 46 8
6 27 90 50 8
6 27 89 65 8
6 27 88 69 8
6 27 87 68 8
6 27 86 50 8
6 27 85 50 8
6 27 84 68 8
6 27 83 69 8
6 27 82 65 72
7 1 103 23 48
7 1 102 23 80
7 1 53 23 48
7 1 52 23 80
7 1 3 23 48
7 1 2 23 80
7 2 103 23 40
7 2 102 23 0
7 2 101 23 18
7 2 100 23 18
7 2 99 23 18
7 2 98 23 18
7 2 97 23 18
7 2 96 23 18
7 2 95 23 18
7 2 94 23 18
7 2 93 23 18
7 2 92 23 18
7 2 91 23 18
7 2 90 23 18
7 2 89 23 18
7 2 88 23 18
7 2 87 23 18
7 2 86 23 18
7 2 85 23 18
7 2 84 23 18
7 2 83 23 18
7 2 82 23 18
7 2 81 23 18
7 2 80 23 18
7 2 79 23 18
7 2 78 23 18
7 2 77 23 18
7 2 76 23 18
7 2 75 23 18
7 2 74 23 18
7 2 73 23 18
7 2 72 23 18
7 2 71 23 18
7 2 70 23 18
7 2 69 23 18
7 2 68 23 18
7 2 67 23 18
7 2 66 23 18
7 2 65 23 18
7 2 64 23 18
7 2 63 23 18
7 2 62 23 18
7 2 61 23 18
7 2 60 23 18
7 2 59 23 18
7 2 58 23 18
7 2 57 23 18
7 2 56 23 18
7 2 55 23 18
7 2 54 23 18
7 2 53 23 0
7 2 52 23 0
7 2 51 23 18
7 2 50 23 18
7 2 49 23 18
7 2 48 23 18
7 2 47 23 18
7 2 46 23 18
7 2 45 23 18
7 2 44 23 18
7 2 43 23 18
7 2 42 23 18
7 2 41 23 18
7 2 40 23 18
7 2 39 23 18
7 2 38 23 18
7 2 37 23 18
7 2 36 23 18
7 2 35 23 18
7 2 34 23 18
7 2 33 23 18
7 2 32 23 18
7 2 31 23 18
7 2 30 23 18
7 2 29 23 18
7 2 28 23 18
7 2 27 23 18
7 2 26 23 18
7 2 25 23 18
7 2 24 23 18
7 2 23 23 18
7 2 22 23 18
7 2 21 23 18
7 2 20 23 18
7 2 19 23 18
7 2 18 23 18
7 2 17 23 18
7 2 16 23 18
7 2 15 23 18
7 2 14 23 18
7 2 13 23 18
7 2 12 23 18
7 2 11 23 18
7 2 10 23 18
7 2 9 23 18
7 2 8 23 18
7 2 7 23 18
7 2 6 23 18
7 2 5 23 18
7 2 4 23 18
7 2 3 23 0
7 2 2 23 72
7 3 102 41 36
7 3 101 41 4
7 3 100 41 12
7 3 99 41 12
7 3 98 41 12
7 3 97 41 12
7 3 96 41 12
7 3 95 41 12
7 3 94 41 12
7 3 93 41 12
7 3 92 41 12
7 3 91 41 12
7 3 90 41 12
7 3 89 41 12
7 3 88 41 12
7 3 87 41 12
7 3 86 41 12
7 3 85 41 12
7 3 84 41 12
7 3 83 41 12
7 3 82 41 12
7 3 81 41 12
7 3 80 41 12
7 3 79 41 12
7 3 78 41 12
7 3 77 41 12
7 3 76 41 12
7 3 75 41 12
7 3 74 41 12
7 3 73 41 12
7 3 72 41 12
7 3 71 41 12
7 3 70 41 12
7 3 69 41 12
7 3 68 41 12
7 3 67 41 12
7 3 66 41 12
7 3 65 41 12
7 3 64 41 12
7 3 63 41 12
7 3 62 41 12
7 3 61 41 12
7 3 60 41 12
7 3 59 41 12
7 3 58 41 12
7 3 57 41 12
7 3 56 41 12
7 3 55 41 12
7 3 54 41 4
7 3 53 41 4
7 3 52 41 4
7 3 51 41 4
7 3 50 41 12
7 3 49 41 12
7 3 48 41 12
7 3 47 41 12
7 3 46 41 12
7 3 45 41 12
7 3 44 41 12
7 3 43 41 12
7 3 42 41 12
7 3 41 41 12
7 3 40 41 12
7 3 39 41 12
7 3 38 41 12
7 3 37 41 12
7 3 36 41 12
7 3 35 41 12
7 3 34 41 12
7 3 33 41 12
7 3 32 41 12
7 3 31 41 12
7 3 30 41 12
7 3 29 41 12
7 3 28 41 12
7 3 27 41 12
7 3 26 41 12
7 3 25 41 12
7 3 24 41 12
7 3 23 41 12
7 3 22 41 12
7 3 21 41 12
7 3 20 41 12
7 3 19 41 12
7 3 18 41 12
7 3 17 41 12
7 3 16 41 12
7 3 15 41 12
7 3 14 41 12
7 3 13 41 12
7 3 12 41 12
7 3 11 41 12
7 3 10 41 12
7 3 9 41 12
7 3 8 41 12
7 3 7 41 12
7 3 6 41 12
7 3 5 41 12
7 3 4 41 4
7 3 3 41 68
7 4 102 41 36
7 4 101 41 68
7 4 54 41 36
7 4 53 41 4
7 4 52 41 4
7 4 51 41 68
7 4 4 41 36
7 4 3 41 68
7 5 102 41 36
7 5 101 41 68
7 5 54 41 36
7 5 53 41 4
7 5 52 41 4
7 5 51 41 68
7 5 4 41 36
7 5 3 41 68
7 6 102 41 36
7 6 101 41 68
7 6 98 39 52
7 6 97 39 20
7 6 96 39 20
7 6 95 39 20
7 6 94 39 20
7 6 93 39 20
7 6 92 39 20
7 6 91 39 20
7 6 90 39 20
7 6 89 39 20
7 6 88 39 20
7 6 87 39 20
7 6 86 39 20
7 6 85 39 20
7 6 84 39 20
7 6 83 39 20
7 6 82 39 20
7 6 81 39 20
7 6 80 39 20
7 6 79 39 20
7 6 78 39 20
7 6 77 39 20
7 6 76 39 20
7 6 75 39 20
7 6 74 39 20
7 6 73 39 20
7 6 72 39 20
7 6 71 39 20
7 6 70 39 20
7 6 69 39 20
7 6 68 39 20
7 6 67 39 20
7 6 66 39 20
7 6 65 39 20
7 6 64 39 20
7 6 63 39 20
7 6 62 39 20
7 6 61 39 20
7 6 60 39 20
7 6 59 39 20
7 6 58 39 20
7 6 57 39 84
7 6 54 41 36
7 6 53 41 4
7 6 52 41 4
7 6 51 41 68
7 6 48 39 52
7 6 47 39 20
7 6 46 39 20
7 6 45 39 20
7 6 44 39 20
7 6 43 39 20
7 6 42 39 20
7 6 41 39 20
7 6 40 39 20
7 6 39 39 20
7 6 38 39 20
7 6 37 39 20
7 6 36 39 20
7 6 35 39 20
7 6 34 39 20
7 6 33 39 20
7 6 32 39 20
7 6 31 39 20
7 6 30 39 20
7 6 29 39 20
7 6 28 39 20
7 6 27 39 20
7 6 26 39 20
7 6 25 39 20
7 6 24 39 20
7 6 23 39 20
7 6 22 39 20
7 6 21 39 20
7 6 20 39 20
7 6 19 39 20
7 6 18 39 20
7 6 17 39 20
7 6 16 39 20
7 6 15 39 20
7 6 14 39 20
7 6 13 39 20
7 6 12 39 20
7 6 11 39 20
7 6 10 39 20
7 6 9 39 20
7 6 8 39 20
7 6 7 39 84
7 6 4 41 36
7 6 3 41 68
7 7 102 41 36
7 7 101 41 68
7 7 98 39 36
7 7 97 39 4
7 7 96 39 4
7 7 95 39 4
7 7 94 39 4
7 7 93 39 4
7 7 92 39 4
7 7 91 39 4
7 7 90 39 4
7 7 89 39 4
7 7 88 39 4
7 7 87 39 4
7 7 86 39 4
7 7 85 39 4
7 7 84 39 4
7 7 83 39 4
7 7 82 39 4
7 7 81 39 4
7 7 80 39 4
7 7 79 39 4
7 7 78 39 4
7 7 77 39 4
7 7 76 39 4
7 7 75 39 4
7 7 74 39 4
7 7 73 39 4
7 7 72 39 4
7 7 71 39 4
7 7 70 39 4
7 7 69 39 4
7 7 68 39 4
7 7 67 39 4
7 7 66 39 4
7 7 65 39 4
7 7 64 39 4
7 7 63 39 4
7 7 62 39 4
7 7 61 39 4
7 7 60 39 4
7 7 59 39 4
7 7 58 39 4
7 7 57 39 68
7 7 54 41 36
7 7 53 41 4
7 7 52 41 4
7 7 51 41 68
7 7 48 39 36
7 7 47 39 4
7 7 46 39 4
7 7 45 39 4
7 7 44 39 4
7 7 43 39 4
7 7 42 39 4
7 7 41 39 4
7 7 40 39 4
7 7 39 39 4
7 7 38 39 4
7 7 37 39 4
7 7 36 39 4
7 7 35 39 4
7 7 34 39 4
7 7 33 39 4
7 7 32 39 4
7 7 31 39 4
7 7 30 39 4
7 7 29 39 4
7 7 28 39 4
7 7 27 39 4
7 7 26 39 4
7 7 25 39 4
7 7 24 39 4
7 7 23 39 4
7 7 22 39 4
7 7 21 39 4
7 7 20 39 4
7 7 19 39 4
7 7 18 39 4
7 7 17 39 4
7 7 16 39 4
7 7 15 39 4
7 7 14 39 4
7 7 13 39 4
7 7 12 39 4
7 7 11 39 4
7 7 10 39 4
7 7 9 39 4
7 7 8 39 4
7 7 7 39 68
7 7 4 41 36
7 7 3 41 68
7 8 102 41 36
7 8 101 41 68
7 8 98 39 36
7 8 97 39 4
7 8 96 39 4
7 8 95 39 4
7 8 94 39 4
7 8 93 39 4
7 8 92 39 4
7 8 91 39 4
7 8 90 39 4
7 8 89 39 4
7 8 88 39 4
7 8 87 39 4
7 8 86 39 4
7 8 85 39 4
7 8 84 39 4
7 8 83 39 4
7 8 82 39 4
7 8 81 39 4
7 8 80 39 4
7 8 79 39 4
7 8 78 39 4
7 8 77 39 4
7 8 76 39 4
7 8 75 39 4
7 8 74 39 4
7 8 73 39 4
7 8 72 39 4
7 8 71 39 4
7 8 70 39 4
7 8 69 39 4
7 8 68 39 4
7 8 67 39 4
7 8 66 39 4
7 8 65 39 4
7 8 64 39 4
7 8 63 39 4
7 8 62 39 4
7 8 61 39 4
7 8 60 39 4
7 8 59 39 4
7 8 58 39 4
7 8 57 39 68
7 8 54 41 36
7 8 53 41 4
7 8 52 41 4
7 8 51 41 68
7 8 48 39 36
7 8 47 39 4
7 8 46 39 4
7 8 45 39 4
7 8 44 39 4
7 8 43 39 4
7 8 42 39 4
7 8 41 39 4
7 8 40 39 4
7 8 39 39 4
7 8 38 39 4
7 8 37 39 4
7 8 36 39 4
7 8 35 39 4
7 8 34 39 4
7 8 33 39 4
7 8 32 39 4
7 8 31 39 4
7 8 30 39 4
7 8 29 39 4
7 8 28 39 4
7 8 27 39 4
7 8 26 39 4
7 8 25 39 4
7 8 24 39 4
7 8 23 39 4
7 8 22 39 4
7 8 21 39 4
7 8 20 39 4
7 8 19 39 4
7 8 18 39 4
7 8 17 39 4
7 8 16 39 4
7 8 15 39 4
7 8 14 39 4
7 8 13 39 4
7 8 12 39 4
7 8 11 39 4
7 8 10 39 4
7 8 9 39 4
7 8 8 39 4
7 8 7 39 68
7 8 4 41 36
7 8 3 41 68
7 9 102 41 36
7 9 101 41 68
7 9 98 39 36
7 9 97 39 4
7 9 96 39 4
7 9 95 39 4
7 9 94 39 4
7 9 93 39 4
7 9 92 39 4
7 9 91 39 4
7 9 90 39 4
7 9 89 39 4
7 9 88 39 4
7 9 87 39 4
7 9 86 39 4
7 9 85 39 4
7 9 84 39 4
7 9 83 39 4
7 9 82 39 4
7 9 81 39 4
7 9 80 39 4
7 9 79 39 4
7 9 78 39 4
7 9 77 39 4
7 9 76 39 4
7 9 75 39 4
7 9 74 39 4
7 9 73 39 4
7 9 72 39 4
7 9 71 39 4
7 9 70 39 4
7 9 69 39 4
7 9 68 39 4
7 9 67 39 4
7 9 66 39 4
7 9 65 39 4
7 9 64 39 4
7 9 63 39 4
7 9 62 39 4
7 9 61 39 4
7 9 60 39 4
7 9 59 39 4
7 9 58 39 4
7 9 57 39 68
7 9 54 41 36
7 9 53 41 4
7 9 52 41 4
7 9 51 41 68
7 9 48 39 36
7 9 47 39 4
7 9 46 39 4
7 9 45 39 4
7 9 44 39 4
7 9 43 39 4
7 9 42 39 4
7 9 41 39 4
7 9 40 39 4
7 9 39 39 4
7 9 38 39 4
7 9 37 39 4
7 9 36 39 4
7 9 35 39 4
7 9 34 39 4
7 9 33 39 4
7 9 32 39 4
7 9 31 39 4
7 9 30 39 4
7 9 29 39 4
7 9 28 39 4
7 9 27 39 4
7 9 26 39 4
7 9 25 39 4
7 9 24 39 4
7 9 23 39 4
7 9 22 39 4
7 9 21 39 4
7 9 20 39 4
7 9 19 39 4
7 9 18 39 4
7 9 17 39 4
7 9 16 39 4
7 9 15 39 4
7 9 14 39 4
7 9 13 39 4
7 9 12 39 4
7 9 11 39 4
7 9 10 39 4
7 9 9 39 4
7 9 8 39 4
7 9 7 39 68
7 9 4 41 36
7 9 3 41 68
7 10 102 41 36
7 10 101 41 68
7 10 98 39 36
7 10 97 39 4
7 10 96 39 4
7 10 95 39 4
7 10 94 39 4
7 10 93 39 4
7 10 92 39 4
7 10 91 39 4
7 10 90 39 4
7 10 89 39 4
7 10 88 39 4
7 10 87 39 4
7 10 86 39 4
7 10 85 39 4
7 10 84 39 4
7 10 83 39 4
7 10 82 39 4
7 10 81 39 4
7 10 80 39 4
7 10 79 39 4
7 10 78 39 4
7 10 77 39 4
7 10 76 39 4
7 10 75 39 4
7 10 74 39 4
7 10 73 39 4
7 10 72 39 4
7 10 71 39 4
7 10 70 39 4
7 10 69 39 4
7 10 68 39 4
7 10 67 39 4
7 10 66 39 4
7 10 65 39 4
7 10 64 39 4
7 10 63 39 4
7 10 62 39 4
7 10 61 39 4
7 10 60 39 4
7 10 59 39 4
7 10 58 39 4
7 10 57 39 68
7 10 54 41 36
7 10 53 41 4
7 10 52 41 4
7 10 51 41 68
7 10 48 39 36
7 10 47 39 4
7 10 46 39 4
7 10 45 39 4
7 10 44 39 4
7 10 43 39 4
7 10 42 39 4
7 10 41 39 4
7 10 40 39 4
7 10 39 39 4
7 10 38 39 4
7 10 37 39 4
7 10 36 39 4
7 10 35 39 4
7 10 34 39 4
7 10 33 39 4
7 10 32 39 4
7 10 31 39 4
7 10 30 39 4
7 10 29 39 4
7 10 28 39 4
7 10 27 39 4
7 10 26 39 4
7 10 25 39 4
7 10 24 39 4
7 10 23 39 4
7 10 22 39 4
7 10 21 39 4
7 10 20 39 4
7 10 19 39 4
7 10 18 39 4
7 10 17 39 4
7 10 16 39 4
7 10 15 39 4
7 10 14 39 4
7 10 13 39 4
7 10 12 39 4
7 10 11 39 4
7 10 10 39 4
7 10 9 39 4
7 10 8 39 4
7 10 7 39 68
7 10 4 41 36
7 10 3 41 68
7 11 102 41 36
7 11 101 41 68
7 11 98 39 36
7 11 97 39 4
7 11 96 39 4
7 11 95 39 4
7 11 94 39 4
7 11 93 39 4
7 11 92 39 4
7 11 91 39 4
7 11 90 39 4
7 11 89 39 4
7 11 88 39 4
7 11 87 39 4
7 11 86 39 4
7 11 85 39 4
7 11 84 39 4
7 11 83 39 4
7 11 82 39 4
7 11 81 39 4
7 11 80 39 4
7 11 79 39 4
7 11 78 39 4
7 11 77 39 4
7 11 76 39 4
7 11 75 39 4
7 11 74 39 4
7 11 73 39 4
7 11 72 39 4
7 11 71 39 4
7 11 70 39 4
7 11 69 39 4
7 11 68 39 4
7 11 67 39 4
7 11 66 39 4
7 11 65 39 4
7 11 64 39 4
7 11 63 39 4
7 11 62 39 4
7 11 61 39 4
7 11 60 39 4
7 11 59 39 4
7 11 58 39 4
7 11 57 39 68
7 11 54 41 36
7 11 53 41 4
7 11 52 41 4
7 11 51 41 68
7 11 48 39 36
7 11 47 39 4
7 11 46 39 4
7 11 45 39 4
7 11 44 39 4
7 11 43 39 4
7 11 42 39 4
7 11 41 39 4
7 11 40 39 4
7 11 39 39 4
7 11 38 39 4
7 11 37 39 4
7 11 36 39 4
7 11 35 39 4
7 11 34 39 4
7 11 33 39 4
7 11 32 39 4
7 11 31 39 4
7 11 30 39 4
7 11 29 39 4
7 11 28 39 4
7 11 27 39 4
7 11 26 39 4
7 11 25 39 4
7 11 24 39 4
7 11 23 39 4
7 11 22 39 4
7 11 21 39 4
7 11 20 39 4
7 11 19 39 4
7 11 18 39 4
7 11 17 39 4
7 11 16 39 4
7 11 15 39 4
7 11 14 39 4
7 11 13 39 4
7 11 12 39 4
7 11 11 39 4
7 11 10 39 4
7 11 9 39 4
7 11 8 39 4
7 11 7 39 68
7 11 4 41 36
7 11 3 41 68
7 12 102 41 36
7 12 101 41 68
7 12 98 39 36
7 12 97 39 4
7 12 96 39 4
7 12 95 39 4
7 12 94 39 4
7 12 93 39 4
7 12 92 39 4
7 12 91 39 4
7 12 90 39 4
7 12 89 39 4
7 12 88 39 4
7 12 87 39 4
7 12 86 39 4
7 12 85 39 4
7 12 84 39 4
7 12 83 39 4
7 12 82 39 4
7 12 81 39 4
7 12 80 39 4
7 12 79 39 4
7 12 78 39 4
7 12 77 39 4
7 12 76 39 4
7 12 75 39 4
7 12 74 39 4
7 12 73 39 4
7 12 72 39 4
7 12 71 39 4
7 12 70 39 4
7 12 69 39 4
7 12 68 39 4
7 12 67 39 4
7 12 66 39 4
7 12 65 39 4
7 12 64 39 4
7 12 63 39 4
7 12 62 39 4
7 12 61 39 4
7 12 60 39 4
7 12 59 39 4
7 12 58 39 4
7 12 57 39 68
7 12 54 41 36
7 12 53 41 4
7 12 52 41 4
7 12 51 41 68
7 12 48 39 36
7 12 47 39 4
7 12 46 39 4
7 12 45 39 4
7 12 44 39 4
7 12 43 39 4
7 12 42 39 4
7 12 41 39 4
7 12 40 39 4
7 12 39 39 4
7 12 38 39 4
7 12 37 39 4
7 12 36 39 4
7 12 35 39 4
7 12 34 39 4
7 12 33 39 4
7 12 32 39 4
7 12 31 39 4
7 12 30 39 4
7 12 29 39 4
7 12 28 39 4
7 12 27 39 4
7 12 26 39 4
7 12 25 39 4
7 12 24 39 4
7 12 23 39 4
7 12 22 39 4
7 12 21 39 4
7 12 20 39 4
7 12 19 39 4
7 12 18 39 4
7 12 17 39 4
7 12 16 39 4
7 12 15 39 4
7 12 14 39 4
7 12 13 39 4
7 12 12 39 4
7 12 11 39 4
7 12 10 39 4
7 12 9 39 4
7 12 8 39 4
7 12 7 39 68
7 12 4 41 36
7 12 3 41 68
7 13 102 41 36
7 13 101 41 68
7 13 98 39 36
7 13 97 39 4
7 13 96 39 4
7 13 95 39 4
7 13 94 39 4
7 13 93 39 4
7 13 92 39 4
7 13 91 39 4
7 13 90 39 4
7 13 89 39 4
7 13 88 39 4
7 13 87 39 4
7 13 86 39 4
7 13 85 39 4
7 13 84 39 4
7 13 83 39 4
7 13 82 39 4
7 13 81 39 4
7 13 80 39 4
7 13 79 39 4
7 13 78 39 4
7 13 77 39 4
7 13 76 39 4
7 13 75 39 4
7 13 74 39 4
7 13 73 39 4
7 13 72 39 4
7 13 71 39 4
7 13 70 39 4
7 13 69 39 4
7 13 68 39 4
7 13 67 39 4
7 13 66 39 4
7 13 65 39 4
7 13 64 39 4
7 13 63 39 4
7 13 62 39 4
7 13 61 39 4
7 13 60 39 4
7 13 59 39 4
7 13 58 39 4
7 13 57 39 68
7 13 54 41 36
7 13 53 41 4
7 13 52 41 4
7 13 51 41 68
7 13 48 39 36
7 13 47 39 4
7 13 46 39 4
7 13 45 39 4
7 13 44 39 4
7 13 43 39 4
7 13 42 39 4
7 13 41 39 4
7 13 40 39 4
7 13 39 39 4
7 13 38 39 4
7 13 37 39 4
7 13 36 39 4
7 13 35 39 4
7 13 34 39 4
7 13 33 39 4
7 13 32 39 4
7 13 31 39 4
7 13 30 39 4
7 13 29 39 4
7 13 28 39 4
7 13 27 39 4
7 13 26 39 4
7 13 25 39 4
7 13 24 39 4
7 13 23 39 4
7 13 22 39 4
7 13 21 39 4
7 13 20 39 4
7 13 19 39 4
7 13 18 39 4
7 13 17 39 4
7 13 16 39 4
7 13 15 39 4
7 13 14 39 4
7 13 13 39 4
7 13 12 39 4
7 13 11 39 4
7 13 10 39 4
7 13 9 39 4
7 13 8 39 4
7 13 7 39 68
7 13 4 41 36
7 13 3 41 68
7 14 102 41 36
7 14 101 41 68
7 14 98 39 36
7 14 97 39 4
7 14 96 39 4
7 14 95 39 4
7 14 94 39 4
7 14 93 39 4
7 14 92 39 4
7 14 91 39 4
7 14 90 39 4
7 14 89 39 4
7 14 88 39 4
7 14 87 39 4
7 14 86 39 4
7 14 85 39 4
7 14 84 39 4
7 14 83 39 4
7 14 82 39 4
7 14 81 39 4
7 14 80 39 4
7 14 79 39 4
7 14 78 39 4
7 14 77 39 4
7 14 76 39 4
7 14 75 39 4
7 14 74 39 4
7 14 73 39 4
7 14 72 39 4
7 14 71 39 4
7 14 70 39 4
7 14 69 39 4
7 14 68 39 4
7 14 67 39 4
7 14 66 39 4
7 14 65 39 4
7 14 64 39 4
7 14 63 39 4
7 14 62 39 4
7 14 61 39 4
7 14 60 39 4
7 14 59 39 4
7 14 58 39 4
7 14 57 39 68
7 14 54 41 36
7 14 53 41 4
7 14 52 41 4
7 14 51 41 68
7 14 48 39 36
7 14 47 39 4
7 14 46 39 4
7 14 45 39 4
7 14 44 39 4
7 14 43 39 4
7 14 42 39 4
7 14 41 39 4
7 14 40 39 4
7 14 39 39 4
7 14 38 39 4
7 14 37 39 4
7 14 36 39 4
7 14 35 39 4
7 14 34 39 4
7 14 33 39 4
7 14 32 39 4
7 14 31 39 4
7 14 30 39 4
7 14 29 39 4
7 14 28 39 4
7 14 27 39 4
7 14 26 39 4
7 14 25 39 4
7 14 24 39 4
7 14 23 39 4
7 14 22 39 4
7 14 21 39 4
7 14 20 39 4
7 14 19 39 4
7 14 18 39 4
7 14 17 39 4
7 14 16 39 4
7 14 15 39 4
7 14 14 39 4
7 14 13 39 4
7 14 12 39 4
7 14 11 39 4
7 14 10 39 4
7 14 9 39 4
7 14 8 39 4
7 14 7 39 68
7 14 4 41 36
7 14 3 41 68
7 15 102 41 36
7 15 101 41 68
7 15 98 39 36
7 15 97 39 4
7 15 96 39 4
7 15 95 39 4
7 15 94 39 4
7 15 93 39 4
7 15 92 39 4
7 15 91 39 4
7 15 90 39 4
7 15 89 39 4
7 15 88 39 4
7 15 87 39 4
7 15 86 39 4
7 15 85 39 4
7 15 84 39 4
7 15 83 39 4
7 15 82 39 4
7 15 81 39 4
7 15 80 39 4
7 15 79 39 4
7 15 78 39 4
7 15 77 39 4
7 15 76 39 4
7 15 75 39 4
7 15 74 39 4
7 15 73 39 4
7 15 72 39 4
7 15 71 39 4
7 15 70 39 4
7 15 69 39 4
7 15 68 39 4
7 15 67 39 4
7 15 66 39 4
7 15 65 39 4
7 15 64 39 4
7 15 63 39 4
7 15 62 39 4
7 15 61 39 4
7 15 60 39 4
7 15 59 39 4
7 15 58 39 4
7 15 57 39 68
7 15 54 41 36
7 15 53 41 4
7 15 52 41 4
7 15 51 41 68
7 15 48 39 36
7 15 47 39 4
7 15 46 39 4
7 15 45 39 4
7 15 44 39 4
7 15 43 39 4
7 15 42 39 4
7 15 41 39 4
7 15 40 39 4
7 15 39 39 4
7 15 38 39 4
7 15 37 39 4
7 15 36 39 4
7 15 35 39 4
7 15 34 39 4
7 15 33 39 4
7 15 32 39 4
7 15 31 39 4
7 15 30 39 4
7 15 29 39 4
7 15 28 39 4
7 15 27 39 4
7 15 26 39 4
7 15 25 39 4
7 15 24 39 4
7 15 23 39 4
7 15 22 39 4
7 15 21 39 4
7 15 20 39 4
7 15 19 39 4
7 15 18 39 4
7 15 17 39 4
7 15 16 39 4
7 15 15 39 4
7 15 14 39 4
7 15 13 39 4
7 15 12 39 4
7 15 11 39 4
7 15 10 39 4
7 15 9 39 4
7 15 8 39 4
7 15 7 39 68
7 15 4 41 36
7 15 3 41 68
7 16 102 41 36
7 16 101 41 68
7 16 98 39 36
7 16 97 39 4
7 16 96 39 4
7 16 95 39 4
7 16 94 39 4
7 16 93 39 4
7 16 92 39 4
7 16 91 39 4
7 16 90 39 4
7 16 89 39 4
7 16 88 39 4
7 16 87 39 4
7 16 86 39 4
7 16 85 39 4
7 16 84 39 4
7 16 83 39 4
7 16 82 39 4
7 16 81 39 4
7 16 80 39 4
7 16 79 39 4
7 16 78 39 4
7 16 77 39 4
7 16 76 39 4
7 16 75 39 4
7 16 74 39 4
7 16 73 39 4
7 16 72 39 4
7 16 71 39 4
7 16 70 39 4
7 16 69 39 4
7 16 68 39 4
7 16 67 39 4
7 16 66 39 4
7 16 65 39 4
7 16 64 39 4
7 16 63 39 4
7 16 62 39 4
7 16 61 39 4
7 16 60 39 4
7 16 59 39 4
7 16 58 39 4
7 16 57 39 68
7 16 54 41 36
7 16 53 41 4
7 16 52 41 4
7 16 51 41 68
7 16 48 39 36
7 16 47 39 4
7 16 46 39 4
7 16 45 39 4
7 16 44 39 4
7 16 43 39 4
7 16 42 39 4
7 16 41 39 4
7 16 40 39 4
7 16 39 39 4
7 16 38 39 4
7 16 37 39 4
7 16 36 39 4
7 16 35 39 4
7 16 34 39 4
7 16 33 39 4
7 16 32 39 4
7 16 31 39 4
7 16 30 39 4
7 16 29 39 4
7 16 28 39 4
7 16 27 39 4
7 16 26 39 4
7 16 25 39 4
7 16 24 39 4
7 16 23 39 4
7 16 22 39 4
7 16 21 39 4
7 16 20 39 4
7 16 19 39 4
7 16 18 39 4
7 16 17 39 4
7 16 16 39 4
7 16 15 39 4
7 16 14 39 4
7 16 13 39 4
7 16 12 39 4
7 16 11 39 4
7 16 10 39 4
7 16 9 39 4
7 16 8 39 4
7 16 7 39 68
7 16 4 41 36
7 16 3 41 68
7 17 102 41 36
7 17 101 41 68
7 17 98 39 36
7 17 97 39 4
7 17 96 39 4
7 17 95 39 4
7 17 94 39 4
7 17 93 39 4
7 17 92 39 4
7 17 91 39 4
7 17 90 39 4
7 17 89 39 4
7 17 88 39 4
7 17 87 39 4
7 17 86 39 4
7 17 85 39 4
7 17 84 39 4
7 17 83 39 4
7 17 82 39 4
7 17 81 39 4
7 17 80 39 4
7 17 79 39 4
7 17 78 39 4
7 17 77 39 4
7 17 76 39 4
7 17 75 39 4
7 17 74 39 4
7 17 73 39 4
7 17 72 39 4
7 17 71 39 4
7 17 70 39 4
7 17 69 39 4
7 17 68 39 4
7 17 67 39 4
7 17 66 39 4
7 17 65 39 4
7 17 64 39 4
7 17 63 39 4
7 17 62 39 4
7 17 61 39 4
7 17 60 39 4
7 17 59 39 4
7 17 58 39 4
7 17 57 39 68
7 17 54 41 36
7 17 53 41 4
7 17 52 41 4
7 17 51 41 68
7 17 48 39 36
7 17 47 39 4
7 17 46 39 4
7 17 45 39 4
7 17 44 39 4
7 17 43 39 4
7 17 42 39 4
7 17 41 39 4
7 17 40 39 4
7 17 39 39 4
7 17 38 39 4
7 17 37 39 4
7 17 36 39 4
7 17 35 39 4
7 17 34 39 4
7 17 33 39 4
7 17 32 39 4
7 17 31 39 4
7 17 30 39 4
7 17 29 39 4
7 17 28 39 4
7 17 27 39 4
7 17 26 39 4
7 17 25 39 4
7 17 24 39 4
7 17 23 39 4
7 17 22 39 4
7 17 21 39 4
7 17 20 39 4
7 17 19 39 4
7 17 18 39 4
7 17 17 39 4
7 17 16 39 4
7 17 15 39 4
7 17 14 39 4
7 17 13 39 4
7 17 12 39 4
7 17 11 39 4
7 17 10 39 4
7 17 9 39 4
7 17 8 39 4
7 17 7 39 68
7 17 4 41 36
7 17 3 41 68
7 18 102 41 36
7 18 101 41 68
7 18 98 39 44
7 18 97 39 12
7 18 96 39 12
7 18 95 39 12
7 18 94 39 12
7 18 93 39 12
7 18 92 39 12
7 18 91 39 12
7 18 90 39 12
7 18 89 39 12
7 18 88 39 12
7 18 87 39 12
7 18 86 39 12
7 18 85 39 12
7 18 84 39 12
7 18 83 39 12
7 18 82 39 12
7 18 81 39 12
7 18 80 39 12
7 18 79 39 12
7 18 78 39 12
7 18 77 39 12
7 18 76 39 12
7 18 75 39 12
7 18 74 39 12
7 18 73 39 12
7 18 72 39 12
7 18 71 39 12
7 18 70 39 12
7 18 69 39 12
7 18 68 39 12
7 18 67 39 12
7 18 66 39 12
7 18 65 39 12
7 18 64 39 12
7 18 63 39 12
7 18 62 39 12
7 18 61 39 12
7 18 60 39 12
7 18 59 39 12
7 18 58 39 12
7 18 57 39 76
7 18 54 41 36
7 18 53 41 4
7 18 52 41 4
7 18 51 41 68
7 18 48 39 44
7 18 47 39 12
7 18 46 39 12
7 18 45 39 12
7 18 44 39 12
7 18 43 39 12
7 18 42 39 12
7 18 41 39 12
7 18 40 39 12
7 18 39 39 12
7 18 38 39 12
7 18 37 39 12
7 18 36 39 12
7 18 35 39 12
7 18 34 39 12
7 18 33 39 12
7 18 32 39 12
7 18 31 39 12
7 18 30 39 12
7 18 29 39 12
7 18 28 39 12
7 18 27 39 12
7 18 26 39 12
7 18 25 39 12
7 18 24 39 12
7 18 23 39 12
7 18 22 39 12
7 18 21 39 12
7 18 20 39 12
7 18 19 39 12
7 18 18 39 12
7 18 17 39 12
7 18 16 39 12
7 18 15 39 12
7 18 14 39 12
7 18 13 39 12
7 18 12 39 12
7 18 11 39 12
7 18 10 39 12
7 18 9 39 12
7 18 8 39 12
7 18 7 39 76
7 18 4 41 36
7 18 3 41 68
7 19 102 41 36
7 19 101 41 68
7 19 54 41 36
7 19 53 41 4
7 19 52 41 4
7 19 51 41 68
7 19 4 41 36
7 19 3 41 68
7 20 102 41 36
7 20 101 41 68
7 20 54 41 36
7 20 53 41 4
7 20 52 41 4
7 20 51 41 68
7 20 4 41 36
7 20 3 41 68
7 21 102 41 36
7 21 101 41 4
7 21 100 41 20
7 21 99 41 20
7 21 98 41 20
7 21 97 41 20
7 21 96 41 20
7 21 95 41 20
7 21 94 41 20
7 21 93 41 20
7 21 92 41 20
7 21 91 41 20
7 21 90 41 20
7 21 89 41 20
7 21 88 41 20
7 21 87 41 20
7 21 86 41 20
7 21 85 41 20
7 21 84 41 20
7 21 83 41 20
7 21 82 41 20
7 21 81 41 20
7 21 80 41 20
7 21 79 41 20
7 21 78 41 20
7 21 77 41 20
7 21 76 41 20
7 21 75 41 20
7 21 74 41 20
7 21 73 41 20
7 21 72 41 20
7 21 71 41 20
7 21 70 41 20
7 21 69 41 20
7 21 68 41 20
7 21 67 41 20
7 21 66 41 20
7 21 65 41 20
7 21 64 41 20
7 21 63 41 20
7 21 62 41 20
7 21 61 41 20
7 21 60 41 20
7 21 59 41 20
7 21 58 41 20
7 21 57 41 20
7 21 56 41 20
7 21 55 41 20
7 21 54 41 4
7 21 53 41 4
7 21 52 41 4
7 21 51 41 4
7 21 50 41 20
7 21 49 41 20
7 21 48 41 20
7 21 47 41 20
7 21 46 41 20
7 21 45 41 20
7 21 44 41 20
7 21 43 41 20
7 21 42 41 20
7 21 41 41 20
7 21 40 41 20
7 21 39 41 20
7 21 38 41 20
7 21 37 41 20
7 21 36 41 20
7 21 35 41 20
7 21 34 41 20
7 21 33 41 20
7 21 32 41 20
7 21 31 41 20
7 21 30 41 20
7 21 29 41 20
7 21 28 41 20
7 21 27 41 20
7 21 26 41 20
7 21 25 41 20
7 21 24 41 20
7 21 23 41 20
7 21 22 41 20
7 21 21 41 20
7 21 20 41 20
7 21 19 41 20
7 21 18 41 20
7 21 17 41 20
7 21 16 41 20
7 21 15 41 20
7 21 14 41 20
7 21 13 41 20
7 21 12 41 20
7 21 11 41 20
7 21 10 41 20
7 21 9 41 20
7 21 8 41 20
7 21 7 41 20
7 21 6 41 20
7 21 5 41 20
7 21 4 41 4
7 21 3 41 68
7 22 102 17 44
7 22 101 17 12
7 22 100 17 12
7 22 99 17 12
7 22 98 17 12
7 22 97 17 12
7 22 96 17 12
7 22 95 17 12
7 22 94 17 12
7 22 93 17 12
7 22 92 17 12
7 22 91 17 12
7 22 90 17 12
7 22 89 17 12
7 22 88 17 12
7 22 87 17 12
7 22 86 17 12
7 22 85 17 12
7 22 84 17 12
7 22 83 17 12
7 22 82 17 12
7 22 81 17 12
7 22 80 17 12
7 22 79 17 12
7 22 78 17 12
7 22 77 17 12
7 22 76 17 12
7 22 75 17 12
7 22 74 17 12
7 22 73 17 12
7 22 72 17 12
7 22 71 17 12
7 22 70 17 12
7 22 69 17 12
7 22 68 17 12
7 22 67 17 12
7 22 66 17 12
7 22 65 17 12
7 22 64 17 12
7 22 63 17 12
7 22 62 17 12
7 22 61 17 12
7 22 60 17 12
7 22 59 17 12
7 22 58 17 12
7 22 57 17 12
7 22 56 17 12
7 22 55 17 12
7 22 54 17 12
7 22 53 17 12
7 22 52 17 12
7 22 51 17 12
7 22 50 17 12
7 22 49 17 12
7 22 48 17 12
7 22 47 17 12
7 22 46 17 12
7 22 45 17 12
7 22 44 17 12
7 22 43 17 12
7 22 42 17 12
7 22 41 17 12
7 22 40 17 12
7 22 39 17 12
7 22 38 17 12
7 22 37 17 12
7 22 36 17 12
7 22 35 17 12
7 22 34 17 12
7 22 33 17 12
7 22 32 17 12
7 22 31 17 12
7 22 30 17 12
7 22 29 17 12
7 22 28 17 12
7 22 27 17 12
7 22 26 17 12
7 22 25 17 12
7 22 24 17 12
7 22 23 17 12
7 22 22 17 12
7 22 21 17 12
7 22 20 17 12
7 22 19 17 12
7 22 18 17 12
7 22 17 17 12
7 22 16 17 12
7 22 15 17 12
7 22 14 17 12
7 22 13 17 12
7 22 12 17 12
7 22 11 17 12
7 22 10 17 12
7 22 9 17 12
7 22 8 17 12
7 22 7 17 12
7 22 6 17 12
7 22 5 17 12
7 22 4 17 12
7 22 3 17 76
7 24 97 18 48
7 24 96 21 16
7 24 95 18 16
7 24 94 21 16
7 24 93 21 16
7 24 92 21 16
7 24 91 21 16
7 24 90 21 16
7 24 89 21 16
7 24 88 21 16
7 24 87 21 16
7 24 86 21 16
7 24 85 21 16
7 24 84 18 16
7 24 83 21 16
7 24 82 30 82
7 24 80 30 50
7 24 79 21 16
7 24 78 18 16
7 24 77 21 16
7 24 76 21 16
7 24 75 21 16
7 24 74 21 16
7 24 73 21 16
7 24 72 21 16
7 24 71 21 16
7 24 70 21 16
7 24 69 21 16
7 24 68 21 16
7 24 67 18 16
7 24 66 21 16
7 24 65 18 80
7 25 97 18 40
7 25 96 65 0
7 25 95 21 0
7 25 94 21 0
7 25 93 21 0
7 25 92 21 0
7 25 91 21 0
7 25 90 21 0
7 25 89 65 0
7 25 88 21 0
7 25 87 21 0
7 25 86 21 0
7 25 85 21 0
7 25 84 21 0
7 25 83 21 0
7 25 82 30 0
7 25 81 30 16
7 25 80 30 0
7 25 79 21 0
7 25 78 21 0
7 25 77 21 0
7 25 76 21 0
7 25 75 21 0
7 25 74 21 0
7 25 73 65 0
7 25 72 21 0
7 25 71 21 0
7 25 70 21 0
7 25 69 21 0
7 25 68 21 0
7 25 67 21 0
7 25 66 65 0
7 25 65 18 72
7 26 96 65 32
7 26 95 21 0
7 26 94 21 0
7 26 93 21 0
7 26 92 21 0
7 26 91 21 0
7 26 90 21 0
7 26 89 65 0
7 26 88 21 0
7 26 87 21 0
7 26 86 21 0
7 26 85 21 0
7 26 84 21 0
7 26 83 21 0
7 26 82 30 0
7 26 81 43 8
7 26 80 65 8
7 26 79 50 8
7 26 78 46 8
7 26 77 46 8
7 26 76 46 8
7 26 75 50 8
7 26 74 50 8
7 26 73 65 8
7 26 72 60 8
7 26 71 60 8
7 26 70 60 8
7 26 69 60 8
7 26 68 50 8
7 26 67 50 8
7 26 66 65 72
7 27 96 65 40
7 27 95 60 8
7 27 94 60 8
7 27 93 60 8
7 27 92 50 8
7 27 91 60 8
7 27 90 60 8
7 27 89 65 8
7 27 88 68 8
7 27 87 7 8
7 27 86 50 8
7 27 85 50 8
7 27 84 7 8
7 27 83 68 8
7 27 82 65 72
7 37 50 55 52
7 37 49 45 20
7 37 48 45 20
7 37 47 45 84
7 38 51 45 52
7 38 50 13 4
7 38 49 13 4
7 38 48 45 4
7 38 47 45 4
7 38 46 55 84
7 39 52 45 52
7 39 51 13 4
7 39 50 13 4
7 39 49 13 4
7 39 48 13 4
7 39 47 55 4
7 39 46 45 4
7 39 45 45 84
7 40 52 45 36
7 40 51 13 4
7 40 50 13 4
7 40 49 13 4
7 40 48 13 4
7 40 47 13 4
7 40 46 45 4
7 40 45 45 68
7 41 53 13 52
7 41 52 13 4
7 41 51 13 4
7 41 50 13 4
7 41 49 13 4
7 41 48 13 4
7 41 47 13 4
7 41 46 45 4
7 41 45 45 4
7 41 44 13 84
7 42 53 13 44
7 42 52 13 4
7 42 51 13 4
7 42 50 13 4
7 42 49 14 4
7 42 48 13 4
7 42 47 45 4
7 42 46 45 4
7 42 45 13 4
7 42 44 13 76
7 43 52 13 36
7 43 51 13 4
7 43 50 14 4
7 43 49 13 4
7 43 48 13 4
7 43 47 45 4
7 43 46 45 4
7 43 45 45 68
7 44 52 13 44
7 44 51 13 4
7 44 50 6 4
7 44 49 14 4
7 44 48 13 4
7 44 47 13 4
7 44 46 45 4
7 44 45 45 76
7 45 51 13 44
7 45 50 13 4
7 45 49 14 4
7 45 48 13 4
7 45 47 13 4
7 45 46 13 76
7 46 50 6 44
7 46 49 14 12
7 46 48 13 12
7 46 47 13 76
8 1 103 23 48
8 1 102 23 80
8 1 53 23 48
8 1 52 23 80
8 1 3 23 48
8 1 2 23 80
8 2 103 23 40
8 2 102 23 64
8 2 53 23 32
8 2 52 23 64
8 2 3 23 32
8 2 2 23 72
8 3 102 41 32
8 3 101 41 16
8 3 100 41 16
8 3 99 41 16
8 3 98 41 16
8 3 97 41 16
8 3 96 41 16
8 3 95 41 16
8 3 94 41 16
8 3 93 41 16
8 3 92 41 16
8 3 91 41 16
8 3 90 41 16
8 3 89 41 16
8 3 88 41 16
8 3 87 41 16
8 3 86 41 16
8 3 85 41 16
8 3 84 41 16
8 3 83 41 16
8 3 82 41 16
8 3 81 41 16
8 3 80 41 16
8 3 79 41 16
8 3 78 41 16
8 3 77 41 16
8 3 76 41 16
8 3 75 41 16
8 3 74 41 16
8 3 73 41 16
8 3 72 41 16
8 3 71 41 16
8 3 70 41 16
8 3 69 41 16
8 3 68 41 16
8 3 67 41 16
8 3 66 41 16
8 3 65 41 16
8 3 64 41 16
8 3 63 41 16
8 3 62 41 16
8 3 61 41 16
8 3 60 41 16
8 3 59 41 16
8 3 58 41 16
8 3 57 41 16
8 3 56 41 16
8 3 55 41 16
8 3 54 41 16
8 3 53 41 0
8 3 52 41 0
8 3 51 41 16
8 3 50 41 16
8 3 49 41 16
8 3 48 41 16
8 3 47 41 16
8 3 46 41 16
8 3 45 41 16
8 3 44 41 16
8 3 43 41 16
8 3 42 41 16
8 3 41 41 16
8 3 40 41 16
8 3 39 41 16
8 3 38 41 16
8 3 37 41 16
8 3 36 41 16
8 3 35 41 16
8 3 34 41 16
8 3 33 41 16
8 3 32 41 16
8 3 31 41 16
8 3 30 41 16
8 3 29 41 16
8 3 28 41 16
8 3 27 41 16
8 3 26 41 16
8 3 25 41 16
8 3 24 41 16
8 3 23 41 16
8 3 22 41 16
8 3 21 41 16
8 3 20 41 16
8 3 19 41 16
8 3 18 41 16
8 3 17 41 16
8 3 16 41 16
8 3 15 41 16
8 3 14 41 16
8 3 13 41 16
8 3 12 41 16
8 3 11 41 16
8 3 10 41 16
8 3 9 41 16
8 3 8 41 16
8 3 7 41 16
8 3 6 41 16
8 3 5 41 16
8 3 4 41 16
8 3 3 41 64
8 4 102 41 34
8 4 101 41 0
8 4 100 35 4
8 4 99 35 4
8 4 98 35 4
8 4 97 35 4
8 4 96 35 4
8 4 95 35 4
8 4 94 35 4
8 4 93 35 4
8 4 92 35 4
8 4 91 35 4
8 4 90 35 4
8 4 89 35 4
8 4 88 35 4
8 4 87 35 4
8 4 86 35 4
8 4 85 35 4
8 4 84 35 4
8 4 83 35 4
8 4 82 35 4
8 4 81 35 4
8 4 80 35 4
8 4 79 35 4
8 4 78 35 4
8 4 77 35 4
8 4 76 35 4
8 4 75 35 4
8 4 74 35 4
8 4 73 35 4
8 4 72 35 4
8 4 71 35 4
8 4 70 35 4
8 4 69 35 4
8 4 68 35 4
8 4 67 35 4
8 4 66 35 4
8 4 65 35 4
8 4 64 35 4
8 4 63 35 4
8 4 62 35 4
8 4 61 35 4
8 4 60 35 4
8 4 59 35 4
8 4 58 35 4
8 4 57 35 4
8 4 56 35 4
8 4 55 35 4
8 4 54 41 0
8 4 53 41 2
8 4 52 41 2
8 4 51 41 0
8 4 50 35 4
8 4 49 35 4
8 4 48 35 4
8 4 47 35 4
8 4 46 35 4
8 4 45 35 4
8 4 44 35 4
8 4 43 35 4
8 4 42 35 4
8 4 41 35 4
8 4 40 35 4
8 4 39 35 4
8 4 38 35 4
8 4 37 35 4
8 4 36 35 4
8 4 35 35 4
8 4 34 35 4
8 4 33 35 4
8 4 32 35 4
8 4 31 35 4
8 4 30 35 4
8 4 29 35 4
8 4 28 35 4
8 4 27 35 4
8 4 26 35 4
8 4 25 35 4
8 4 24 35 4
8 4 23 35 4
8 4 22 35 4
8 4 21 35 4
8 4 20 35 4
8 4 19 35 4
8 4 18 35 4
8 4 17 35 4
8 4 16 35 4
8 4 15 35 4
8 4 14 35 4
8 4 13 35 4
8 4 12 35 4
8 4 11 35 4
8 4 10 35 4
8 4 9 35 4
8 4 8 35 4
8 4 7 35 4
8 4 6 35 4
8 4 5 35 4
8 4 4 41 0
8 4 3 41 66
8 5 102 41 34
8 5 101 41 0
8 5 100 35 4
8 5 99 35 4
8 5 98 35 4
8 5 97 35 4
8 5 96 35 4
8 5 95 35 4
8 5 94 35 4
8 5 93 35 4
8 5 92 35 4
8 5 91 35 4
8 5 90 35 4
8 5 89 35 4
8 5 88 35 4
8 5 87 35 4
8 5 86 35 4
8 5 85 35 4
8 5 84 35 4
8 5 83 35 4
8 5 82 35 4
8 5 81 35 4
8 5 80 35 4
8 5 79 35 4
8 5 78 35 4
8 5 77 35 4
8 5 76 35 4
8 5 75 35 4
8 5 74 35 4
8 5 73 35 4
8 5 72 35 4
8 5 71 35 4
8 5 70 35 4
8 5 69 35 4
8 5 68 35 4
8 5 67 35 4
8 5 66 35 4
8 5 65 35 4
8 5 64 35 4
8 5 63 35 4
8 5 62 35 4
8 5 61 35 4
8 5 60 35 4
8 5 59 35 4
8 5 58 35 4
8 5 57 35 4
8 5 56 35 4
8 5 55 35 4
8 5 54 41 0
8 5 53 41 2
8 5 52 41 2
8 5 51 41 0
8 5 50 35 4
8 5 49 35 4
8 5 48 35 4
8 5 47 35 4
8 5 46 35 4
8 5 45 35 4
8 5 44 35 4
8 5 43 35 4
8 5 42 35 4
8 5 41 35 4
8 5 40 35 4
8 5 39 35 4
8 5 38 35 4
8 5 37 35 4
8 5 36 35 4
8 5 35 35 4
8 5 34 35 4
8 5 33 35 4
8 5 32 35 4
8 5 31 35 4
8 5 30 35 4
8 5 29 35 4
8 5 28 35 4
8 5 27 35 4
8 5 26 35 4
8 5 25 35 4
8 5 24 35 4
8 5 23 35 4
8 5 22 35 4
8 5 21 35 4
8 5 20 35 4
8 5 19 35 4
8 5 18 35 4
8 5 17 35 4
8 5 16 35 4
8 5 15 35 4
8 5 14 35 4
8 5 13 35 4
8 5 12 35 4
8 5 11 35 4
8 5 10 35 4
8 5 9 35 4
8 5 8 35 4
8 5 7 35 4
8 5 6 35 4
8 5 5 35 4
8 5 4 41 0
8 5 3 41 66
8 6 102 41 34
8 6 101 41 0
8 6 100 35 4
8 6 99 35 4
8 6 98 41 0
8 6 97 41 0
8 6 96 41 0
8 6 95 41 0
8 6 94 41 0
8 6 93 41 0
8 6 92 41 0
8 6 91 41 0
8 6 90 41 0
8 6 89 41 0
8 6 88 41 0
8 6 87 41 0
8 6 86 41 0
8 6 85 41 0
8 6 84 41 0
8 6 83 41 0
8 6 82 41 0
8 6 81 41 0
8 6 80 41 0
8 6 79 41 0
8 6 78 41 0
8 6 77 41 0
8 6 76 41 0
8 6 75 41 0
8 6 74 41 0
8 6 73 41 0
8 6 72 41 0
8 6 71 41 0
8 6 70 41 0
8 6 69 41 0
8 6 68 41 0
8 6 67 41 0
8 6 66 41 0
8 6 65 41 0
8 6 64 41 0
8 6 63 41 0
8 6 62 41 0
8 6 61 41 0
8 6 60 41 0
8 6 59 41 0
8 6 58 41 0
8 6 57 41 0
8 6 56 35 4
8 6 55 35 4
8 6 54 41 0
8 6 53 41 2
8 6 52 41 2
8 6 51 41 0
8 6 50 35 4
8 6 49 35 4
8 6 48 41 0
8 6 47 41 0
8 6 46 41 0
8 6 45 41 0
8 6 44 41 0
8 6 43 41 0
8 6 42 41 0
8 6 41 41 0
8 6 40 41 0
8 6 39 41 0
8 6 38 41 0
8 6 37 41 0
8 6 36 41 0
8 6 35 41 0
8 6 34 41 0
8 6 33 41 0
8 6 32 41 0
8 6 31 41 0
8 6 30 41 0
8 6 29 41 0
8 6 28 41 0
8 6 27 41 0
8 6 26 41 0
8 6 25 41 0
8 6 24 41 0
8 6 23 41 0
8 6 22 41 0
8 6 21 41 0
8 6 20 41 0
8 6 19 41 0
8 6 18 41 0
8 6 17 41 0
8 6 16 41 0
8 6 15 41 0
8 6 14 41 0
8 6 13 41 0
8 6 12 41 0
8 6 11 41 0
8 6 10 41 0
8 6 9 41 0
8 6 8 41 0
8 6 7 41 0
8 6 6 35 4
8 6 5 35 4
8 6 4 41 0
8 6 3 41 66
8 7 102 41 34
8 7 101 41 0
8 7 100 35 4
8 7 99 35 4
8 7 98 41 0
8 7 97 41 0
8 7 96 41 0
8 7 95 41 0
8 7 94 41 0
8 7 93 41 0
8 7 92 41 0
8 7 91 41 0
8 7 90 41 0
8 7 89 41 0
8 7 88 41 0
8 7 87 41 0
8 7 86 41 0
8 7 85 41 0
8 7 84 41 0
8 7 83 41 0
8 7 82 41 0
8 7 81 41 0
8 7 80 41 0
8 7 79 41 0
8 7 78 41 0
8 7 77 41 0
8 7 76 41 0
8 7 75 41 0
8 7 74 41 0
8 7 73 41 0
8 7 72 41 0
8 7 71 41 0
8 7 70 41 0
8 7 69 41 0
8 7 68 41 0
8 7 67 41 0
8 7 66 41 0
8 7 65 41 0
8 7 64 41 0
8 7 63 41 0
8 7 62 41 0
8 7 61 41 0
8 7 60 41 0
8 7 59 41 0
8 7 58 41 0
8 7 57 41 0
8 7 56 35 4
8 7 55 35 4
8 7 54 41 0
8 7 53 41 2
8 7 52 41 2
8 7 51 41 0
8 7 50 35 4
8 7 49 35 4
8 7 48 41 0
8 7 47 41 0
8 7 46 41 0
8 7 45 41 0
8 7 44 41 0
8 7 43 41 0
8 7 42 41 0
8 7 41 41 0
8 7 40 41 0
8 7 39 41 0
8 7 38 41 0
8 7 37 41 0
8 7 36 41 0
8 7 35 41 0
8 7 34 41 0
8 7 33 41 0
8 7 32 41 0
8 7 31 41 0
8 7 30 41 0
8 7 29 41 0
8 7 28 41 0
8 7 27 41 0
8 7 26 41 0
8 7 25 41 0
8 7 24 41 0
8 7 23 41 0
8 7 22 41 0
8 7 21 41 0
8 7 20 41 0
8 7 19 41 0
8 7 18 41 0
8 7 17 41 0
8 7 16 41 0
8 7 15 41 0
8 7 14 41 0
8 7 13 41 0
8 7 12 41 0
8 7 11 41 0
8 7 10 41 0
8 7 9 41 0
8 7 8 41 0
8 7 7 41 0
8 7 6 35 4
8 7 5 35 4
8 7 4 41 0
8 7 3 41 66
8 8 102 41 34
8 8 101 41 0
8 8 100 35 4
8 8 99 35 4
8 8 98 41 0
8 8 97 41 0
8 8 96 41 0
8 8 95 41 0
8 8 94 41 0
8 8 93 41 0
8 8 92 41 0
8 8 91 41 0
8 8 90 41 0
8 8 89 41 0
8 8 88 41 0
8 8 87 41 0
8 8 86 41 0
8 8 85 41 0
8 8 84 41 0
8 8 83 41 0
8 8 82 41 0
8 8 81 41 0
8 8 80 41 0
8 8 79 41 0
8 8 78 41 0
8 8 77 41 0
8 8 76 41 0
8 8 75 41 0
8 8 74 41 0
8 8 73 41 0
8 8 72 41 0
8 8 71 41 0
8 8 70 41 0
8 8 69 41 0
8 8 68 41 0
8 8 67 41 0
8 8 66 41 0
8 8 65 41 0
8 8 64 41 0
8 8 63 41 0
8 8 62 41 0
8 8 61 41 0
8 8 60 41 0
8 8 59 41 0
8 8 58 41 0
8 8 57 41 0
8 8 56 35 4
8 8 55 35 4
8 8 54 41 0
8 8 53 41 2
8 8 52 41 2
8 8 51 41 0
8 8 50 35 4
8 8 49 35 4
8 8 48 41 0
8 8 47 41 0
8 8 46 41 0
8 8 45 41 0
8 8 44 41 0
8 8 43 41 0
8 8 42 41 0
8 8 41 41 0
8 8 40 41 0
8 8 39 41 0
8 8 38 41 0
8 8 37 41 0
8 8 36 41 0
8 8 35 41 0
8 8 34 41 0
8 8 33 41 0
8 8 32 41 0
8 8 31 41 0
8 8 30 41 0
8 8 29 41 0
8 8 28 41 0
8 8 27 41 0
8 8 26 41 0
8 8 25 41 0
8 8 24 41 0
8 8 23 41 0
8 8 22 41 0
8 8 21 41 0
8 8 20 41 0
8 8 19 41 0
8 8 18 41 0
8 8 17 41 0
8 8 16 41 0
8 8 15 41 0
8 8 14 41 0
8 8 13 41 0
8 8 12 41 0
8 8 11 41 0
8 8 10 41 0
8 8 9 41 0
8 8 8 41 0
8 8 7 41 0
8 8 6 35 4
8 8 5 35 4
8 8 4 41 0
8 8 3 41 66
8 9 102 41 34
8 9 101 41 0
8 9 100 35 4
8 9 99 35 4
8 9 98 41 0
8 9 97 41 0
8 9 96 41 0
8 9 95 41 0
8 9 94 41 0
8 9 93 41 0
8 9 92 41 0
8 9 91 41 0
8 9 90 41 0
8 9 89 41 0
8 9 88 41 0
8 9 87 41 0
8 9 86 41 0
8 9 85 41 0
8 9 84 41 0
8 9 83 41 0
8 9 82 41 0
8 9 81 41 0
8 9 80 41 0
8 9 79 41 0
8 9 78 41 0
8 9 77 41 0
8 9 76 41 0
8 9 75 41 0
8 9 74 41 0
8 9 73 41 0
8 9 72 41 0
8 9 71 41 0
8 9 70 41 0
8 9 69 41 0
8 9 68 41 0
8 9 67 41 0
8 9 66 41 0
8 9 65 41 0
8 9 64 41 0
8 9 63 41 0
8 9 62 41 0
8 9 61 41 0
8 9 60 41 0
8 9 59 41 0
8 9 58 41 0
8 9 57 41 0
8 9 56 35 4
8 9 55 35 4
8 9 54 41 0
8 9 53 41 2
8 9 52 41 2
8 9 51 41 0
8 9 50 35 4
8 9 49 35 4
8 9 48 41 0
8 9 47 41 0
8 9 46 41 0
8 9 45 41 0
8 9 44 41 0
8 9 43 41 0
8 9 42 41 0
8 9 41 41 0
8 9 40 41 0
8 9 39 41 0
8 9 38 41 0
8 9 37 41 0
8 9 36 41 0
8 9 35 41 0
8 9 34 41 0
8 9 33 41 0
8 9 32 41 0
8 9 31 41 0
8 9 30 41 0
8 9 29 41 0
8 9 28 41 0
8 9 27 41 0
8 9 26 41 0
8 9 25 41 0
8 9 24 41 0
8 9 23 41 0
8 9 22 41 0
8 9 21 41 0
8 9 20 41 0
8 9 19 41 0
8 9 18 41 0
8 9 17 41 0
8 9 16 41 0
8 9 15 41 0
8 9 14 41 0
8 9 13 41 0
8 9 12 41 0
8 9 11 41 0
8 9 10 41 0
8 9 9 41 0
8 9 8 41 0
8 9 7 41 0
8 9 6 35 4
8 9 5 35 4
8 9 4 41 0
8 9 3 41 66
8 10 102 41 34
8 10 101 41 0
8 10 100 35 4
8 10 99 35 4
8 10 98 41 0
8 10 97 41 0
8 10 96 41 0
8 10 95 41 0
8 10 94 41 0
8 10 93 41 0
8 10 92 41 0
8 10 91 41 0
8 10 90 41 0
8 10 89 41 0
8 10 88 41 0
8 10 87 41 0
8 10 86 41 0
8 10 85 41 0
8 10 84 41 0
8 10 83 41 0
8 10 82 41 0
8 10 81 41 0
8 10 80 41 0
8 10 79 41 0
8 10 78 41 0
8 10 77 41 0
8 10 76 41 0
8 10 75 41 0
8 10 74 41 0
8 10 73 41 0
8 10 72 41 0
8 10 71 41 0
8 10 70 41 0
8 10 69 41 0
8 10 68 41 0
8 10 67 41 0
8 10 66 41 0
8 10 65 41 0
8 10 64 41 0
8 10 63 41 0
8 10 62 41 0
8 10 61 41 0
8 10 60 41 0
8 10 59 41 0
8 10 58 41 0
8 10 57 41 0
8 10 56 35 4
8 10 55 35 4
8 10 54 41 0
8 10 53 41 2
8 10 52 41 2
8 10 51 41 0
8 10 50 35 4
8 10 49 35 4
8 10 48 41 0
8 10 47 41 0
8 10 46 41 0
8 10 45 41 0
8 10 44 41 0
8 10 43 41 0
8 10 42 41 0
8 10 41 41 0
8 10 40 41 0
8 10 39 41 0
8 10 38 41 0
8 10 37 41 0
8 10 36 41 0
8 10 35 41 0
8 10 34 41 0
8 10 33 41 0
8 10 32 41 0
8 10 31 41 0
8 10 30 41 0
8 10 29 41 0
8 10 28 41 0
8 10 27 41 0
8 10 26 41 0
8 10 25 41 0
8 10 24 41 0
8 10 23 41 0
8 10 22 41 0
8 10 21 41 0
8 10 20 41 0
8 10 19 41 0
8 10 18 41 0
8 10 17 41 0
8 10 16 41 0
8 10 15 41 0
8 10 14 41 0
8 10 13 41 0
8 10 12 41 0
8 10 11 41 0
8 10 10 41 0
8 10 9 41 0
8 10 8 41 0
8 10 7 41 0
8 10 6 35 4
8 10 5 35 4
8 10 4 41 0
8 10 3 41 66
8 11 102 41 34
8 11 101 41 0
8 11 100 35 4
8 11 99 35 4
8 11 98 41 0
8 11 97 41 0
8 11 96 41 0
8 11 95 41 0
8 11 94 41 0
8 11 93 41 0
8 11 92 41 0
8 11 91 41 0
8 11 90 41 0
8 11 89 41 0
8 11 88 41 0
8 11 87 41 0
8 11 86 41 0
8 11 85 41 0
8 11 84 41 0
8 11 83 41 0
8 11 82 41 0
8 11 81 41 0
8 11 80 41 0
8 11 79 41 0
8 11 78 41 0
8 11 77 41 0
8 11 76 41 0
8 11 75 41 0
8 11 74 41 0
8 11 73 41 0
8 11 72 41 0
8 11 71 41 0
8 11 70 41 0
8 11 69 41 0
8 11 68 41 0
8 11 67 41 0
8 11 66 41 0
8 11 65 41 0
8 11 64 41 0
8 11 63 41 0
8 11 62 41 0
8 11 61 41 0
8 11 60 41 0
8 11 59 41 0
8 11 58 41 0
8 11 57 41 0
8 11 56 35 4
8 11 55 35 4
8 11 54 41 0
8 11 53 41 2
8 11 52 41 2
8 11 51 41 0
8 11 50 35 4
8 11 49 35 4
8 11 48 41 0
8 11 47 41 0
8 11 46 41 0
8 11 45 41 0
8 11 44 41 0
8 11 43 41 0
8 11 42 41 0
8 11 41 41 0
8 11 40 41 0
8 11 39 41 0
8 11 38 41 0
8 11 37 41 0
8 11 36 41 0
8 11 35 41 0
8 11 34 41 0
8 11 33 41 0
8 11 32 41 0
8 11 31 41 0
8 11 30 41 0
8 11 29 41 0
8 11 28 41 0
8 11 27 41 0
8 11 26 41 0
8 11 25 41 0
8 11 24 41 0
8 11 23 41 0
8 11 22 41 0
8 11 21 41 0
8 11 20 41 0
8 11 19 41 0
8 11 18 41 0
8 11 17 41 0
8 11 16 41 0
8 11 15 41 0
8 11 14 41 0
8 11 13 41 0
8 11 12 41 0
8 11 11 41 0
8 11 10 41 0
8 11 9 41 0
8 11 8 41 0
8 11 7 41 0
8 11 6 35 4
8 11 5 35 4
8 11 4 41 0
8 11 3 41 66
8 12 102 41 34
8 12 101 41 0
8 12 100 35 4
8 12 99 35 4
8 12 98 41 0
8 12 97 41 0
8 12 96 41 0
8 12 95 41 0
8 12 94 41 0
8 12 93 41 0
8 12 92 41 0
8 12 91 41 0
8 12 90 41 0
8 12 89 41 0
8 12 88 41 0
8 12 87 41 0
8 12 86 41 0
8 12 85 41 0
8 12 84 41 0
8 12 83 41 0
8 12 82 41 0
8 12 81 41 0
8 12 80 41 0
8 12 79 41 0
8 12 78 41 0
8 12 77 41 0
8 12 76 41 0
8 12 75 41 0
8 12 74 41 0
8 12 73 41 0
8 12 72 41 0
8 12 71 41 0
8 12 70 41 0
8 12 69 41 0
8 12 68 41 0
8 12 67 41 0
8 12 66 41 0
8 12 65 41 0
8 12 64 41 0
8 12 63 41 0
8 12 62 41 0
8 12 61 41 0
8 12 60 41 0
8 12 59 41 0
8 12 58 41 0
8 12 57 41 0
8 12 56 35 4
8 12 55 35 4
8 12 54 41 0
8 12 53 41 2
8 12 52 41 2
8 12 51 41 0
8 12 50 35 4
8 12 49 35 4
8 12 48 41 0
8 12 47 41 0
8 12 46 41 0
8 12 45 41 0
8 12 44 41 0
8 12 43 41 0
8 12 42 41 0
8 12 41 41 0
8 12 40 41 0
8 12 39 41 0
8 12 38 41 0
8 12 37 41 0
8 12 36 41 0
8 12 35 41 0
8 12 34 41 0
8 12 33 41 0
8 12 32 41 0
8 12 31 41 0
8 12 30 41 0
8 12 29 41 0
8 12 28 41 0
8 12 27 41 0
8 12 26 41 0
8 12 25 41 0
8 12 24 41 0
8 12 23 41 0
8 12 22 41 0
8 12 21 41 0
8 12 20 41 0
8 12 19 41 0
8 12 18 41 0
8 12 17 41 0
8 12 16 41 0
8 12 15 41 0
8 12 14 41 0
8 12 13 41 0
8 12 12 41 0
8 12 11 41 0
8 12 10 41 0
8 12 9 41 0
8 12 8 41 0
8 12 7 41 0
8 12 6 35 4
8 12 5 35 4
8 12 4 41 0
8 12 3 41 66
8 13 102 41 34
8 13 101 41 0
8 13 100 35 4
8 13 99 35 4
8 13 98 41 0
8 13 97 41 0
8 13 96 41 0
8 13 95 41 0
8 13 94 41 0
8 13 93 41 0
8 13 92 41 0
8 13 91 41 0
8 13 90 41 0
8 13 89 41 0
8 13 88 41 0
8 13 87 41 0
8 13 86 41 0
8 13 85 41 0
8 13 84 41 0
8 13 83 41 0
8 13 82 41 0
8 13 81 41 0
8 13 80 41 0
8 13 79 41 0
8 13 78 41 0
8 13 77 41 0
8 13 76 41 0
8 13 75 41 0
8 13 74 41 0
8 13 73 41 0
8 13 72 41 0
8 13 71 41 0
8 13 70 41 0
8 13 69 41 0
8 13 68 41 0
8 13 67 41 0
8 13 66 41 0
8 13 65 41 0
8 13 64 41 0
8 13 63 41 0
8 13 62 41 0
8 13 61 41 0
8 13 60 41 0
8 13 59 41 0
8 13 58 41 0
8 13 57 41 0
8 13 56 35 4
8 13 55 35 4
8 13 54 41 0
8 13 53 41 2
8 13 52 41 2
8 13 51 41 0
8 13 50 35 4
8 13 49 35 4
8 13 48 41 0
8 13 47 41 0
8 13 46 41 0
8 13 45 41 0
8 13 44 41 0
8 13 43 41 0
8 13 42 41 0
8 13 41 41 0
8 13 40 41 0
8 13 39 41 0
8 13 38 41 0
8 13 37 41 0
8 13 36 41 0
8 13 35 41 0
8 13 34 41 0
8 13 33 41 0
8 13 32 41 0
8 13 31 41 0
8 13 30 41 0
8 13 29 41 0
8 13 28 41 0
8 13 27 41 0
8 13 26 41 0
8 13 25 41 0
8 13 24 41 0
8 13 23 41 0
8 13 22 41 0
8 13 21 41 0
8 13 20 41 0
8 13 19 41 0
8 13 18 41 0
8 13 17 41 0
8 13 16 41 0
8 13 15 41 0
8 13 14 41 0
8 13 13 41 0
8 13 12 41 0
8 13 11 41 0
8 13 10 41 0
8 13 9 41 0
8 13 8 41 0
8 13 7 41 0
8 13 6 35 4
8 13 5 35 4
8 13 4 41 0
8 13 3 41 66
8 14 102 41 34
8 14 101 41 0
8 14 100 35 4
8 14 99 35 4
8 14 98 41 0
8 14 97 41 0
8 14 96 41 0
8 14 95 41 0
8 14 94 41 0
8 14 93 41 0
8 14 92 41 0
8 14 91 41 0
8 14 90 41 0
8 14 89 41 0
8 14 88 41 0
8 14 87 41 0
8 14 86 41 0
8 14 85 41 0
8 14 84 41 0
8 14 83 41 0
8 14 82 41 0
8 14 81 41 0
8 14 80 41 0
8 14 79 41 0
8 14 78 41 0
8 14 77 41 0
8 14 76 41 0
8 14 75 41 0
8 14 74 41 0
8 14 73 41 0
8 14 72 41 0
8 14 71 41 0
8 14 70 41 0
8 14 69 41 0
8 14 68 41 0
8 14 67 41 0
8 14 66 41 0
8 14 65 41 0
8 14 64 41 0
8 14 63 41 0
8 14 62 41 0
8 14 61 41 0
8 14 60 41 0
8 14 59 41 0
8 14 58 41 0
8 14 57 41 0
8 14 56 35 4
8 14 55 35 4
8 14 54 41 0
8 14 53 41 2
8 14 52 41 2
8 14 51 41 0
8 14 50 35 4
8 14 49 35 4
8 14 48 41 0
8 14 47 41 0
8 14 46 41 0
8 14 45 41 0
8 14 44 41 0
8 14 43 41 0
8 14 42 41 0
8 14 41 41 0
8 14 40 41 0
8 14 39 41 0
8 14 38 41 0
8 14 37 41 0
8 14 36 41 0
8 14 35 41 0
8 14 34 41 0
8 14 33 41 0
8 14 32 41 0
8 14 31 41 0
8 14 30 41 0
8 14 29 41 0
8 14 28 41 0
8 14 27 41 0
8 14 26 41 0
8 14 25 41 0
8 14 24 41 0
8 14 23 41 0
8 14 22 41 0
8 14 21 41 0
8 14 20 41 0
8 14 19 41 0
8 14 18 41 0
8 14 17 41 0
8 14 16 41 0
8 14 15 41 0
8 14 14 41 0
8 14 13 41 0
8 14 12 41 0
8 14 11 41 0
8 14 10 41 0
8 14 9 41 0
8 14 8 41 0
8 14 7 41 0
8 14 6 35 4
8 14 5 35 4
8 14 4 41 0
8 14 3 41 66
8 15 102 41 34
8 15 101 41 0
8 15 100 35 4
8 15 99 35 4
8 15 98 41 0
8 15 97 41 0
8 15 96 41 0
8 15 95 41 0
8 15 94 41 0
8 15 93 41 0
8 15 92 41 0
8 15 91 41 0
8 15 90 41 0
8 15 89 41 0
8 15 88 41 0
8 15 87 41 0
8 15 86 41 0
8 15 85 41 0
8 15 84 41 0
8 15 83 41 0
8 15 82 41 0
8 15 81 41 0
8 15 80 41 0
8 15 79 41 0
8 15 78 41 0
8 15 77 41 0
8 15 76 41 0
8 15 75 41 0
8 15 74 41 0
8 15 73 41 0
8 15 72 41 0
8 15 71 41 0
8 15 70 41 0
8 15 69 41 0
8 15 68 41 0
8 15 67 41 0
8 15 66 41 0
8 15 65 41 0
8 15 64 41 0
8 15 63 41 0
8 15 62 41 0
8 15 61 41 0
8 15 60 41 0
8 15 59 41 0
8 15 58 41 0
8 15 57 41 0
8 15 56 35 4
8 15 55 35 4
8 15 54 41 0
8 15 53 41 2
8 15 52 41 2
8 15 51 41 0
8 15 50 35 4
8 15 49 35 4
8 15 48 41 0
8 15 47 41 0
8 15 46 41 0
8 15 45 41 0
8 15 44 41 0
8 15 43 41 0
8 15 42 41 0
8 15 41 41 0
8 15 40 41 0
8 15 39 41 0
8 15 38 41 0
8 15 37 41 0
8 15 36 41 0
8 15 35 41 0
8 15 34 41 0
8 15 33 41 0
8 15 32 41 0
8 15 31 41 0
8 15 30 41 0
8 15 29 41 0
8 15 28 41 0
8 15 27 41 0
8 15 26 41 0
8 15 25 41 0
8 15 24 41 0
8 15 23 41 0
8 15 22 41 0
8 15 21 41 0
8 15 20 41 0
8 15 19 41 0
8 15 18 41 0
8 15 17 41 0
8 15 16 41 0
8 15 15 41 0
8 15 14 41 0
8 15 13 41 0
8 15 12 41 0
8 15 11 41 0
8 15 10 41 0
8 15 9 41 0
8 15 8 41 0
8 15 7 41 0
8 15 6 35 4
8 15 5 35 4
8 15 4 41 0
8 15 3 41 66
8 16 102 41 34
8 16 101 41 0
8 16 100 35 4
8 16 99 35 4
8 16 98 41 0
8 16 97 41 0
8 16 96 41 0
8 16 95 41 0
8 16 94 41 0
8 16 93 41 0
8 16 92 41 0
8 16 91 41 0
8 16 90 41 0
8 16 89 41 0
8 16 88 41 0
8 16 87 41 0
8 16 86 41 0
8 16 85 41 0
8 16 84 41 0
8 16 83 41 0
8 16 82 41 0
8 16 81 41 0
8 16 80 41 0
8 16 79 41 0
8 16 78 41 0
8 16 77 41 0
8 16 76 41 0
8 16 75 41 0
8 16 74 41 0
8 16 73 41 0
8 16 72 41 0
8 16 71 41 0
8 16 70 41 0
8 16 69 41 0
8 16 68 41 0
8 16 67 41 0
8 16 66 41 0
8 16 65 41 0
8 16 64 41 0
8 16 63 41 0
8 16 62 41 0
8 16 61 41 0
8 16 60 41 0
8 16 59 41 0
8 16 58 41 0
8 16 57 41 0
8 16 56 35 4
8 16 55 35 4
8 16 54 41 0
8 16 53 41 2
8 16 52 41 2
8 16 51 41 0
8 16 50 35 4
8 16 49 35 4
8 16 48 41 0
8 16 47 41 0
8 16 46 41 0
8 16 45 41 0
8 16 44 41 0
8 16 43 41 0
8 16 42 41 0
8 16 41 41 0
8 16 40 41 0
8 16 39 41 0
8 16 38 41 0
8 16 37 41 0
8 16 36 41 0
8 16 35 41 0
8 16 34 41 0
8 16 33 41 0
8 16 32 41 0
8 16 31 41 0
8 16 30 41 0
8 16 29 41 0
8 16 28 41 0
8 16 27 41 0
8 16 26 41 0
8 16 25 41 0
8 16 24 41 0
8 16 23 41 0
8 16 22 41 0
8 16 21 41 0
8 16 20 41 0
8 16 19 41 0
8 16 18 41 0
8 16 17 41 0
8 16 16 41 0
8 16 15 41 0
8 16 14 41 0
8 16 13 41 0
8 16 12 41 0
8 16 11 41 0
8 16 10 41 0
8 16 9 41 0
8 16 8 41 0
8 16 7 41 0
8 16 6 35 4
8 16 5 35 4
8 16 4 41 0
8 16 3 41 66
8 17 102 41 34
8 17 101 41 0
8 17 100 35 4
8 17 99 35 4
8 17 98 41 0
8 17 97 41 0
8 17 96 41 0
8 17 95 41 0
8 17 94 41 0
8 17 93 41 0
8 17 92 41 0
8 17 91 41 0
8 17 90 41 0
8 17 89 41 0
8 17 88 41 0
8 17 87 41 0
8 17 86 41 0
8 17 85 41 0
8 17 84 41 0
8 17 83 41 0
8 17 82 41 0
8 17 81 41 0
8 17 80 41 0
8 17 79 41 0
8 17 78 41 0
8 17 77 41 0
8 17 76 41 0
8 17 75 41 0
8 17 74 41 0
8 17 73 41 0
8 17 72 41 0
8 17 71 41 0
8 17 70 41 0
8 17 69 41 0
8 17 68 41 0
8 17 67 41 0
8 17 66 41 0
8 17 65 41 0
8 17 64 41 0
8 17 63 41 0
8 17 62 41 0
8 17 61 41 0
8 17 60 41 0
8 17 59 41 0
8 17 58 41 0
8 17 57 41 0
8 17 56 35 4
8 17 55 35 4
8 17 54 41 0
8 17 53 41 2
8 17 52 41 2
8 17 51 41 0
8 17 50 35 4
8 17 49 35 4
8 17 48 41 0
8 17 47 41 0
8 17 46 41 0
8 17 45 41 0
8 17 44 41 0
8 17 43 41 0
8 17 42 41 0
8 17 41 41 0
8 17 40 41 0
8 17 39 41 0
8 17 38 41 0
8 17 37 41 0
8 17 36 41 0
8 17 35 41 0
8 17 34 41 0
8 17 33 41 0
8 17 32 41 0
8 17 31 41 0
8 17 30 41 0
8 17 29 41 0
8 17 28 41 0
8 17 27 41 0
8 17 26 41 0
8 17 25 41 0
8 17 24 41 0
8 17 23 41 0
8 17 22 41 0
8 17 21 41 0
8 17 20 41 0
8 17 19 41 0
8 17 18 41 0
8 17 17 41 0
8 17 16 41 0
8 17 15 41 0
8 17 14 41 0
8 17 13 41 0
8 17 12 41 0
8 17 11 41 0
8 17 10 41 0
8 17 9 41 0
8 17 8 41 0
8 17 7 41 0
8 17 6 35 4
8 17 5 35 4
8 17 4 41 0
8 17 3 41 66
8 18 102 41 34
8 18 101 41 0
8 18 100 35 4
8 18 99 35 4
8 18 98 41 0
8 18 97 41 0
8 18 96 41 0
8 18 95 41 0
8 18 94 41 0
8 18 93 41 0
8 18 92 41 0
8 18 91 41 0
8 18 90 41 0
8 18 89 41 0
8 18 88 41 0
8 18 87 41 0
8 18 86 41 0
8 18 85 41 0
8 18 84 41 0
8 18 83 41 0
8 18 82 41 0
8 18 81 41 0
8 18 80 41 0
8 18 79 41 0
8 18 78 41 0
8 18 77 41 0
8 18 76 41 0
8 18 75 41 0
8 18 74 41 0
8 18 73 41 0
8 18 72 41 0
8 18 71 41 0
8 18 70 41 0
8 18 69 41 0
8 18 68 41 0
8 18 67 41 0
8 18 66 41 0
8 18 65 41 0
8 18 64 41 0
8 18 63 41 0
8 18 62 41 0
8 18 61 41 0
8 18 60 41 0
8 18 59 41 0
8 18 58 41 0
8 18 57 41 0
8 18 56 35 4
8 18 55 35 4
8 18 54 41 0
8 18 53 41 2
8 18 52 41 2
8 18 51 41 0
8 18 50 35 4
8 18 49 35 4
8 18 48 41 0
8 18 47 41 0
8 18 46 41 0
8 18 45 41 0
8 18 44 41 0
8 18 43 41 0
8 18 42 41 0
8 18 41 41 0
8 18 40 41 0
8 18 39 41 0
8 18 38 41 0
8 18 37 41 0
8 18 36 41 0
8 18 35 41 0
8 18 34 41 0
8 18 33 41 0
8 18 32 41 0
8 18 31 41 0
8 18 30 41 0
8 18 29 41 0
8 18 28 41 0
8 18 27 41 0
8 18 26 41 0
8 18 25 41 0
8 18 24 41 0
8 18 23 41 0
8 18 22 41 0
8 18 21 41 0
8 18 20 41 0
8 18 19 41 0
8 18 18 41 0
8 18 17 41 0
8 18 16 41 0
8 18 15 41 0
8 18 14 41 0
8 18 13 41 0
8 18 12 41 0
8 18 11 41 0
8 18 10 41 0
8 18 9 41 0
8 18 8 41 0
8 18 7 41 0
8 18 6 35 4
8 18 5 35 4
8 18 4 41 0
8 18 3 41 66
8 19 102 41 34
8 19 101 41 0
8 19 100 35 4
8 19 99 35 4
8 19 98 35 4
8 19 97 35 4
8 19 96 35 4
8 19 95 35 4
8 19 94 35 4
8 19 93 35 4
8 19 92 35 4
8 19 91 35 4
8 19 90 35 4
8 19 89 35 4
8 19 88 35 4
8 19 87 35 4
8 19 86 35 4
8 19 85 35 4
8 19 84 35 4
8 19 83 35 4
8 19 82 35 4
8 19 81 35 4
8 19 80 35 4
8 19 79 35 4
8 19 78 35 4
8 19 77 35 4
8 19 76 35 4
8 19 75 35 4
8 19 74 35 4
8 19 73 35 4
8 19 72 35 4
8 19 71 35 4
8 19 70 35 4
8 19 69 35 4
8 19 68 35 4
8 19 67 35 4
8 19 66 35 4
8 19 65 35 4
8 19 64 35 4
8 19 63 35 4
8 19 62 35 4
8 19 61 35 4
8 19 60 35 4
8 19 59 35 4
8 19 58 35 4
8 19 57 35 4
8 19 56 35 4
8 19 55 35 4
8 19 54 41 0
8 19 53 41 2
8 19 52 41 2
8 19 51 41 0
8 19 50 35 4
8 19 49 35 4
8 19 48 35 4
8 19 47 35 4
8 19 46 35 4
8 19 45 35 4
8 19 44 35 4
8 19 43 35 4
8 19 42 35 4
8 19 41 35 4
8 19 40 35 4
8 19 39 35 4
8 19 38 35 4
8 19 37 35 4
8 19 36 35 4
8 19 35 35 4
8 19 34 35 4
8 19 33 35 4
8 19 32 35 4
8 19 31 35 4
8 19 30 35 4
8 19 29 35 4
8 19 28 35 4
8 19 27 35 4
8 19 26 35 4
8 19 25 35 4
8 19 24 35 4
8 19 23 35 4
8 19 22 35 4
8 19 21 35 4
8 19 20 35 4
8 19 19 35 4
8 19 18 35 4
8 19 17 35 4
8 19 16 35 4
8 19 15 35 4
8 19 14 35 4
8 19 13 35 4
8 19 12 35 4
8 19 11 35 4
8 19 10 35 4
8 19 9 35 4
8 19 8 35 4
8 19 7 35 4
8 19 6 35 4
8 19 5 35 4
8 19 4 41 0
8 19 3 41 66
8 20 102 41 34
8 20 101 41 0
8 20 100 35 4
8 20 99 35 4
8 20 98 35 4
8 20 97 35 4
8 20 96 35 4
8 20 95 35 4
8 20 94 35 4
8 20 93 35 4
8 20 92 35 4
8 20 91 35 4
8 20 90 35 4
8 20 89 35 4
8 20 88 35 4
8 20 87 35 4
8 20 86 35 4
8 20 85 35 4
8 20 84 35 4
8 20 83 35 4
8 20 82 35 4
8 20 81 35 4
8 20 80 35 4
8 20 79 35 4
8 20 78 35 4
8 20 77 35 4
8 20 76 35 4
8 20 75 35 4
8 20 74 35 4
8 20 73 35 4
8 20 72 35 4
8 20 71 35 4
8 20 70 35 4
8 20 69 35 4
8 20 68 35 4
8 20 67 35 4
8 20 66 35 4
8 20 65 35 4
8 20 64 35 4
8 20 63 35 4
8 20 62 35 4
8 20 61 35 4
8 20 60 35 4
8 20 59 35 4
8 20 58 35 4
8 20 57 35 4
8 20 56 35 4
8 20 55 35 4
8 20 54 41 0
8 20 53 41 2
8 20 52 41 2
8 20 51 41 0
8 20 50 35 4
8 20 49 35 4
8 20 48 35 4
8 20 47 35 4
8 20 46 35 4
8 20 45 35 4
8 20 44 35 4
8 20 43 35 4
8 20 42 35 4
8 20 41 35 4
8 20 40 35 4
8 20 39 35 4
8 20 38 35 4
8 20 37 35 4
8 20 36 35 4
8 20 35 35 4
8 20 34 35 4
8 20 33 35 4
8 20 32 35 4
8 20 31 35 4
8 20 30 35 4
8 20 29 35 4
8 20 28 35 4
8 20 27 35 4
8 20 26 35 4
8 20 25 35 4
8 20 24 35 4
8 20 23 35 4
8 20 22 35 4
8 20 21 35 4
8 20 20 35 4
8 20 19 35 4
8 20 18 35 4
8 20 17 35 4
8 20 16 35 4
8 20 15 35 4
8 20 14 35 4
8 20 13 35 4
8 20 12 35 4
8 20 11 35 4
8 20 10 35 4
8 20 9 35 4
8 20 8 35 4
8 20 7 35 4
8 20 6 35 4
8 20 5 35 4
8 20 4 41 0
8 20 3 41 66
8 21 102 41 32
8 21 101 41 0
8 21 100 41 0
8 21 99 41 0
8 21 98 41 0
8 21 97 41 0
8 21 96 41 0
8 21 95 41 0
8 21 94 41 0
8 21 93 41 0
8 21 92 41 0
8 21 91 41 0
8 21 90 41 0
8 21 89 41 0
8 21 88 41 0
8 21 87 41 0
8 21 86 41 0
8 21 85 41 0
8 21 84 41 0
8 21 83 41 0
8 21 82 41 0
8 21 81 41 0
8 21 80 41 0
8 21 79 41 0
8 21 78 41 0
8 21 77 41 0
8 21 76 41 0
8 21 75 41 0
8 21 74 41 0
8 21 73 41 0
8 21 72 41 0
8 21 71 41 0
8 21 70 41 0
8 21 69 41 0
8 21 68 41 0
8 21 67 41 0
8 21 66 41 0
8 21 65 41 0
8 21 64 41 0
8 21 63 41 0
8 21 62 41 0
8 21 61 41 0
8 21 60 41 0
8 21 59 41 0
8 21 58 41 0
8 21 57 41 0
8 21 56 41 0
8 21 55 41 0
8 21 54 41 0
8 21 53 41 0
8 21 52 41 0
8 21 51 41 0
8 21 50 41 0
8 21 49 41 0
8 21 48 41 0
8 21 47 41 0
8 21 46 41 0
8 21 45 41 0
8 21 44 41 0
8 21 43 41 0
8 21 42 41 0
8 21 41 41 0
8 21 40 41 0
8 21 39 41 0
8 21 38 41 0
8 21 37 41 0
8 21 36 41 0
8 21 35 41 0
8 21 34 41 0
8 21 33 41 0
8 21 32 41 0
8 21 31 41 0
8 21 30 41 0
8 21 29 41 0
8 21 28 41 0
8 21 27 41 0
8 21 26 41 0
8 21 25 41 0
8 21 24 41 0
8 21 23 41 0
8 21 22 41 0
8 21 21 41 0
8 21 20 41 0
8 21 19 41 0
8 21 18 41 0
8 21 17 41 0
8 21 16 41 0
8 21 15 41 0
8 21 14 41 0
8 21 13 41 0
8 21 12 41 0
8 21 11 41 0
8 21 10 41 0
8 21 9 41 0
8 21 8 41 0
8 21 7 41 0
8 21 6 41 0
8 21 5 41 0
8 21 4 41 0
8 21 3 41 64
8 22 102 17 40
8 22 101 17 8
8 22 100 17 8
8 22 99 17 8
8 22 98 17 8
8 22 97 17 8
8 22 96 17 8
8 22 95 17 8
8 22 94 17 8
8 22 93 17 8
8 22 92 17 8
8 22 91 17 8
8 22 90 17 8
8 22 89 17 8
8 22 88 17 8
8 22 87 17 8
8 22 86 17 8
8 22 85 17 8
8 22 84 17 8
8 22 83 17 8
8 22 82 17 8
8 22 81 17 8
8 22 80 17 8
8 22 79 17 8
8 22 78 17 8
8 22 77 17 8
8 22 76 17 8
8 22 75 17 8
8 22 74 17 8
8 22 73 17 8
8 22 72 17 8
8 22 71 17 8
8 22 70 17 8
8 22 69 17 8
8 22 68 17 8
8 22 67 17 8
8 22 66 17 8
8 22 65 17 8
8 22 64 17 8
8 22 63 17 8
8 22 62 17 8
8 22 61 17 8
8 22 60 17 8
8 22 59 17 8
8 22 58 17 8
8 22 57 17 8
8 22 56 17 8
8 22 55 17 8
8 22 54 17 8
8 22 53 17 8
8 22 52 17 8
8 22 51 17 8
8 22 50 17 8
8 22 49 17 8
8 22 48 17 8
8 22 47 17 8
8 22 46 17 8
8 22 45 17 8
8 22 44 17 8
8 22 43 17 8
8 22 42 17 8
8 22 41 17 8
8 22 40 17 8
8 22 39 17 8
8 22 38 17 8
8 22 37 17 8
8 22 36 17 8
8 22 35 17 8
8 22 34 17 8
8 22 33 17 8
8 22 32 17 8
8 22 31 17 8
8 22 30 17 8
8 22 29 17 8
8 22 28 17 8
8 22 27 17 8
8 22 26 17 8
8 22 25 17 8
8 22 24 17 8
8 22 23 17 8
8 22 22 17 8
8 22 21 17 8
8 22 20 17 8
8 22 19 17 8
8 22 18 17 8
8 22 17 17 8
8 22 16 17 8
8 22 15 17 8
8 22 14 17 8
8 22 13 17 8
8 22 12 17 8
8 22 11 17 8
8 22 10 17 8
8 22 9 17 8
8 22 8 17 8
8 22 7 17 8
8 22 6 17 8
8 22 5 17 8
8 22 4 17 8
8 22 3 17 72
8 24 97 18 48
8 24 96 21 16
8 24 95 18 16
8 24 94 21 16
8 24 93 21 16
8 24 92 21 16
8 24 91 21 16
8 24 90 21 16
8 24 89 21 16
8 24 88 21 16
8 24 87 21 16
8 24 86 21 16
8 24 85 21 16
8 24 84 18 16
8 24 83 21 80
8 24 79 21 48
8 24 78 18 16
8 24 77 21 16
8 24 76 21 16
8 24 75 21 16
8 24 74 21 16
8 24 73 21 16
8 24 72 21 16
8 24 71 21 16
8 24 70 21 16
8 24 69 21 16
8 24 68 21 16
8 24 67 18 16
8 24 66 21 16
8 24 65 18 80
8 25 97 18 40
8 25 96 65 0
8 25 95 21 0
8 25 94 21 0
8 25 93 21 0
8 25 92 21 0
8 25 91 21 0
8 25 90 21 0
8 25 89 65 0
8 25 88 21 0
8 25 87 21 0
8 25 86 21 0
8 25 85 21 0
8 25 84 21 0
8 25 83 21 0
8 25 82 18 16
8 25 81 30 16
8 25 80 18 16
8 25 79 21 0
8 25 78 21 0
8 25 77 21 0
8 25 76 21 0
8 25 75 21 0
8 25 74 21 0
8 25 73 65 0
8 25 72 21 0
8 25 71 21 0
8 25 70 21 0
8 25 69 21 0
8 25 68 21 0
8 25 67 21 0
8 25 66 65 0
8 25 65 18 72
8 26 96 65 32
8 26 95 21 0
8 26 94 21 0
8 26 93 21 0
8 26 92 21 0
8 26 91 21 0
8 26 90 21 0
8 26 89 65 0
8 26 88 21 0
8 26 87 21 0
8 26 86 21 0
8 26 85 21 0
8 26 84 21 0
8 26 83 21 0
8 26 82 18 0
8 26 81 43 8
8 26 80 65 8
8 26 79 60 8
8 26 78 60 8
8 26 77 60 8
8 26 76 50 8
8 26 75 46 8
8 26 74 46 8
8 26 73 65 8
8 26 72 46 8
8 26 71 46 8
8 26 70 46 8
8 26 69 46 8
8 26 68 46 8
8 26 67 50 8
8 26 66 65 72
8 27 96 65 40
8 27 95 46 8
8 27 94 46 8
8 27 93 50 8
8 27 92 46 8
8 27 91 46 8
8 27 90 46 8
8 27 89 65 8
8 27 88 7 8
8 27 87 50 8
8 27 86 7 8
8 27 85 7 8
8 27 84 50 8
8 27 83 7 8
8 27 82 65 72
8 35 50 45 52
8 35 49 45 20
8 35 48 45 20
8 35 47 55 84
8 36 52 13 52
8 36 51 45 20
8 36 50 55 4
8 36 49 55 4
8 36 48 55 4
8 36 47 45 4
8 36 46 55 20
8 36 45 45 84
8 37 53 13 52
8 37 52 13 4
8 37 51 45 4
8 37 50 13 0
8 37 49 13 0
8 37 48 13 0
8 37 47 13 0
8 37 46 45 4
8 37 45 45 4
8 37 44 45 84
8 38 54 13 52
8 38 53 13 4
8 38 52 45 4
8 38 51 13 0
8 38 50 13 0
8 38 49 13 0
8 38 48 13 0
8 38 47 13 0
8 38 46 13 0
8 38 45 45 4
8 38 44 45 4
8 38 43 13 84
8 39 54 13 36
8 39 53 45 4
8 39 52 13 0
8 39 51 13 0
8 39 50 13 0
8 39 49 13 0
8 39 48 13 0
8 39 47 13 0
8 39 46 13 0
8 39 45 13 0
8 39 44 13 4
8 39 43 13 68
8 40 54 13 36
8 40 53 13 4
8 40 52 13 0
8 40 51 13 0
8 40 50 13 0
8 40 49 13 0
8 40 48 13 0
8 40 47 13 0
8 40 46 13 0
8 40 45 13 0
8 40 44 13 4
8 40 43 13 68
8 41 54 13 36
8 41 53 13 0
8 41 52 13 0
8 41 51 13 0
8 41 50 13 0
8 41 49 13 0
8 41 48 13 0
8 41 47 13 0
8 41 46 13 0
8 41 45 13 0
8 41 44 13 0
8 41 43 13 68
8 42 54 13 36
8 42 53 13 0
8 42 52 13 0
8 42 51 13 0
8 42 50 13 0
8 42 49 13 0
8 42 48 13 0
8 42 47 13 0
8 42 46 13 0
8 42 45 13 0
8 42 44 13 0
8 42 43 13 68
8 43 54 13 36
8 43 53 13 4
8 43 52 13 0
8 43 51 13 0
8 43 50 13 0
8 43 49 13 0
8 43 48 13 0
8 43 47 13 0
8 43 46 13 0
8 43 45 13 0
8 43 44 13 4
8 43 43 13 68
8 44 54 13 36
8 44 53 13 4
8 44 52 13 0
8 44 51 13 0
8 44 50 13 0
8 44 49 13 0
8 44 48 13 0
8 44 47 13 0
8 44 46 13 0
8 44 45 13 0
8 44 44 45 4
8 44 43 45 68
8 45 54 13 44
8 45 53 13 4
8 45 52 13 4
8 45 51 13 0
8 45 50 13 0
8 45 49 13 0
8 45 48 13 0
8 45 47 13 0
8 45 46 13 0
8 45 45 13 4
8 45 44 45 4
8 45 43 13 76
8 46 53 13 44
8 46 52 14 4
8 46 51 12 4
8 46 50 13 0
8 46 49 13 0
8 46 48 13 0
8 46 47 13 0
8 46 46 13 4
8 46 45 13 4
8 46 44 13 76
8 47 52 12 44
8 47 51 14 12
8 47 50 14 4
8 47 49 13 4
8 47 48 13 4
8 47 47 13 4
8 47 46 13 12
8 47 45 13 76
8 48 50 13 44
8 48 49 13 12
8 48 48 13 12
8 48 47 13 76
9 1 103 23 48
9 1 102 23 80
9 1 53 23 48
9 1 52 23 80
9 1 3 23 48
9 1 2 23 80
9 2 103 23 40
9 2 102 23 64
9 2 53 23 32
9 2 52 23 64
9 2 3 23 32
9 2 2 23 72
9 3 102 41 40
9 3 101 41 16
9 3 100 41 16
9 3 99 41 16
9 3 98 41 16
9 3 97 41 16
9 3 96 41 16
9 3 95 41 16
9 3 94 41 16
9 3 93 41 16
9 3 92 41 16
9 3 91 41 16
9 3 90 41 16
9 3 89 41 16
9 3 88 41 16
9 3 87 41 16
9 3 86 41 16
9 3 85 41 16
9 3 84 41 16
9 3 83 41 16
9 3 82 41 16
9 3 81 41 16
9 3 80 41 16
9 3 79 41 16
9 3 78 41 16
9 3 77 41 16
9 3 76 41 16
9 3 75 41 16
9 3 74 41 16
9 3 73 41 16
9 3 72 41 16
9 3 71 41 16
9 3 70 41 16
9 3 69 41 16
9 3 68 41 16
9 3 67 41 16
9 3 66 41 16
9 3 65 41 16
9 3 64 41 16
9 3 63 41 16
9 3 62 41 16
9 3 61 41 16
9 3 60 41 16
9 3 59 41 16
9 3 58 41 16
9 3 57 41 16
9 3 56 41 16
9 3 55 41 16
9 3 54 41 16
9 3 53 41 8
9 3 52 41 8
9 3 51 41 16
9 3 50 41 16
9 3 49 41 16
9 3 48 41 16
9 3 47 41 16
9 3 46 41 16
9 3 45 41 16
9 3 44 41 16
9 3 43 41 16
9 3 42 41 16
9 3 41 41 16
9 3 40 41 16
9 3 39 41 16
9 3 38 41 16
9 3 37 41 16
9 3 36 41 16
9 3 35 41 16
9 3 34 41 16
9 3 33 41 16
9 3 32 41 16
9 3 31 41 16
9 3 30 41 16
9 3 29 41 16
9 3 28 41 16
9 3 27 41 16
9 3 26 41 16
9 3 25 41 16
9 3 24 41 16
9 3 23 41 16
9 3 22 41 16
9 3 21 41 16
9 3 20 41 16
9 3 19 41 16
9 3 18 41 16
9 3 17 41 16
9 3 16 41 16
9 3 15 41 16
9 3 14 41 16
9 3 13 41 16
9 3 12 41 16
9 3 11 41 16
9 3 10 41 16
9 3 9 41 16
9 3 8 41 16
9 3 7 41 16
9 3 6 41 16
9 3 5 41 16
9 3 4 41 16
9 3 3 41 72
9 4 101 35 32
9 4 100 41 0
9 4 99 41 0
9 4 98 41 0
9 4 97 41 0
9 4 96 41 0
9 4 95 41 0
9 4 94 41 0
9 4 93 41 0
9 4 92 41 0
9 4 91 41 0
9 4 90 41 0
9 4 89 41 0
9 4 88 41 0
9 4 87 41 0
9 4 86 41 0
9 4 85 41 0
9 4 84 41 0
9 4 83 41 0
9 4 82 41 0
9 4 81 41 0
9 4 80 41 0
9 4 79 41 0
9 4 78 41 0
9 4 77 41 0
9 4 76 41 0
9 4 75 41 0
9 4 74 41 0
9 4 73 41 0
9 4 72 41 0
9 4 71 41 0
9 4 70 41 0
9 4 69 41 0
9 4 68 41 0
9 4 67 41 0
9 4 66 41 0
9 4 65 41 0
9 4 64 41 0
9 4 63 41 0
9 4 62 41 0
9 4 61 41 0
9 4 60 41 0
9 4 59 41 0
9 4 58 41 0
9 4 57 41 0
9 4 56 41 0
9 4 55 41 0
9 4 54 35 64
9 4 51 35 32
9 4 50 41 0
9 4 49 41 0
9 4 48 41 0
9 4 47 41 0
9 4 46 41 0
9 4 45 41 0
9 4 44 41 0
9 4 43 41 0
9 4 42 41 0
9 4 41 41 0
9 4 40 41 0
9 4 39 41 0
9 4 38 41 0
9 4 37 41 0
9 4 36 41 0
9 4 35 41 0
9 4 34 41 0
9 4 33 41 0
9 4 32 41 0
9 4 31 41 0
9 4 30 41 0
9 4 29 41 0
9 4 28 41 0
9 4 27 41 0
9 4 26 41 0
9 4 25 41 0
9 4 24 41 0
9 4 23 41 0
9 4 22 41 0
9 4 21 41 0
9 4 20 41 0
9 4 19 41 0
9 4 18 41 0
9 4 17 41 0
9 4 16 41 0
9 4 15 41 0
9 4 14 41 0
9 4 13 41 0
9 4 12 41 0
9 4 11 41 0
9 4 10 41 0
9 4 9 41 0
9 4 8 41 0
9 4 7 41 0
9 4 6 41 0
9 4 5 41 0
9 4 4 35 64
9 5 101 35 32
9 5 100 41 0
9 5 99 41 0
9 5 98 41 0
9 5 97 41 0
9 5 96 41 0
9 5 95 41 0
9 5 94 41 0
9 5 93 41 0
9 5 92 41 0
9 5 91 41 0
9 5 90 41 0
9 5 89 41 0
9 5 88 41 0
9 5 87 41 0
9 5 86 41 0
9 5 85 41 0
9 5 84 41 0
9 5 83 41 0
9 5 82 41 0
9 5 81 41 0
9 5 80 41 0
9 5 79 41 0
9 5 78 41 0
9 5 77 41 0
9 5 76 41 0
9 5 75 41 0
9 5 74 41 0
9 5 73 41 0
9 5 72 41 0
9 5 71 41 0
9 5 70 41 0
9 5 69 41 0
9 5 68 41 0
9 5 67 41 0
9 5 66 41 0
9 5 65 41 0
9 5 64 41 0
9 5 63 41 0
9 5 62 41 0
9 5 61 41 0
9 5 60 41 0
9 5 59 41 0
9 5 58 41 0
9 5 57 41 0
9 5 56 41 0
9 5 55 41 0
9 5 54 35 64
9 5 51 35 32
9 5 50 41 0
9 5 49 41 0
9 5 48 41 0
9 5 47 41 0
9 5 46 41 0
9 5 45 41 0
9 5 44 41 0
9 5 43 41 0
9 5 42 41 0
9 5 41 41 0
9 5 40 41 0
9 5 39 41 0
9 5 38 41 0
9 5 37 41 0
9 5 36 41 0
9 5 35 41 0
9 5 34 41 0
9 5 33 41 0
9 5 32 41 0
9 5 31 41 0
9 5 30 41 0
9 5 29 41 0
9 5 28 41 0
9 5 27 41 0
9 5 26 41 0
9 5 25 41 0
9 5 24 41 0
9 5 23 41 0
9 5 22 41 0
9 5 21 41 0
9 5 20 41 0
9 5 19 41 0
9 5 18 41 0
9 5 17 41 0
9 5 16 41 0
9 5 15 41 0
9 5 14 41 0
9 5 13 41 0
9 5 12 41 0
9 5 11 41 0
9 5 10 41 0
9 5 9 41 0
9 5 8 41 0
9 5 7 41 0
9 5 6 41 0
9 5 5 41 0
9 5 4 35 64
9 6 101 35 32
9 6 100 41 0
9 6 99 41 0
9 6 98 41 0
9 6 97 41 0
9 6 96 41 0
9 6 95 41 0
9 6 94 41 0
9 6 93 41 0
9 6 92 41 0
9 6 91 41 0
9 6 90 41 0
9 6 89 41 0
9 6 88 41 0
9 6 87 41 0
9 6 86 41 0
9 6 85 41 0
9 6 84 41 0
9 6 83 41 0
9 6 82 41 0
9 6 81 41 0
9 6 80 41 0
9 6 79 41 0
9 6 78 41 0
9 6 77 41 0
9 6 76 41 0
9 6 75 41 0
9 6 74 41 0
9 6 73 41 0
9 6 72 41 0
9 6 71 41 0
9 6 70 41 0
9 6 69 41 0
9 6 68 41 0
9 6 67 41 0
9 6 66 41 0
9 6 65 41 0
9 6 64 41 0
9 6 63 41 0
9 6 62 41 0
9 6 61 41 0
9 6 60 41 0
9 6 59 41 0
9 6 58 41 0
9 6 57 41 0
9 6 56 41 0
9 6 55 41 0
9 6 54 35 64
9 6 51 35 32
9 6 50 41 0
9 6 49 41 0
9 6 48 41 0
9 6 47 41 0
9 6 46 41 0
9 6 45 41 0
9 6 44 41 0
9 6 43 41 0
9 6 42 41 0
9 6 41 41 0
9 6 40 41 0
9 6 39 41 0
9 6 38 41 0
9 6 37 41 0
9 6 36 41 0
9 6 35 41 0
9 6 34 41 0
9 6 33 41 0
9 6 32 41 0
9 6 31 41 0
9 6 30 41 0
9 6 29 41 0
9 6 28 41 0
9 6 27 41 0
9 6 26 41 0
9 6 25 41 0
9 6 24 41 0
9 6 23 41 0
9 6 22 41 0
9 6 21 41 0
9 6 20 41 0
9 6 19 41 0
9 6 18 41 0
9 6 17 41 0
9 6 16 41 0
9 6 15 41 0
9 6 14 41 0
9 6 13 41 0
9 6 12 41 0
9 6 11 41 0
9 6 10 41 0
9 6 9 41 0
9 6 8 41 0
9 6 7 41 0
9 6 6 41 0
9 6 5 41 0
9 6 4 35 64
9 7 101 35 32
9 7 100 41 0
9 7 99 41 0
9 7 98 41 0
9 7 97 41 0
9 7 96 41 0
9 7 95 41 0
9 7 94 41 0
9 7 93 41 0
9 7 92 41 0
9 7 91 41 0
9 7 90 41 0
9 7 89 41 0
9 7 88 41 0
9 7 87 41 0
9 7 86 41 0
9 7 85 41 0
9 7 84 41 0
9 7 83 41 0
9 7 82 41 0
9 7 81 41 0
9 7 80 41 0
9 7 79 41 0
9 7 78 41 0
9 7 77 41 0
9 7 76 41 0
9 7 75 41 0
9 7 74 41 0
9 7 73 41 0
9 7 72 41 0
9 7 71 41 0
9 7 70 41 0
9 7 69 41 0
9 7 68 41 0
9 7 67 41 0
9 7 66 41 0
9 7 65 41 0
9 7 64 41 0
9 7 63 41 0
9 7 62 41 0
9 7 61 41 0
9 7 60 41 0
9 7 59 41 0
9 7 58 41 0
9 7 57 41 0
9 7 56 41 0
9 7 55 41 0
9 7 54 35 64
9 7 51 35 32
9 7 50 41 0
9 7 49 41 0
9 7 48 41 0
9 7 47 41 0
9 7 46 41 0
9 7 45 41 0
9 7 44 41 0
9 7 43 41 0
9 7 42 41 0
9 7 41 41 0
9 7 40 41 0
9 7 39 41 0
9 7 38 41 0
9 7 37 41 0
9 7 36 41 0
9 7 35 41 0
9 7 34 41 0
9 7 33 41 0
9 7 32 41 0
9 7 31 41 0
9 7 30 41 0
9 7 29 41 0
9 7 28 41 0
9 7 27 41 0
9 7 26 41 0
9 7 25 41 0
9 7 24 41 0
9 7 23 41 0
9 7 22 41 0
9 7 21 41 0
9 7 20 41 0
9 7 19 41 0
9 7 18 41 0
9 7 17 41 0
9 7 16 41 0
9 7 15 41 0
9 7 14 41 0
9 7 13 41 0
9 7 12 41 0
9 7 11 41 0
9 7 10 41 0
9 7 9 41 0
9 7 8 41 0
9 7 7 41 0
9 7 6 41 0
9 7 5 41 0
9 7 4 35 64
9 8 101 35 32
9 8 100 41 0
9 8 99 41 0
9 8 98 41 0
9 8 97 41 0
9 8 96 41 0
9 8 95 41 0
9 8 94 41 0
9 8 93 41 0
9 8 92 41 0
9 8 91 41 0
9 8 90 41 0
9 8 89 41 0
9 8 88 41 0
9 8 87 41 0
9 8 86 41 0
9 8 85 41 0
9 8 84 41 0
9 8 83 41 0
9 8 82 41 0
9 8 81 41 0
9 8 80 41 0
9 8 79 41 0
9 8 78 41 0
9 8 77 41 0
9 8 76 41 0
9 8 75 41 0
9 8 74 41 0
9 8 73 41 0
9 8 72 41 0
9 8 71 41 0
9 8 70 41 0
9 8 69 41 0
9 8 68 41 0
9 8 67 41 0
9 8 66 41 0
9 8 65 41 0
9 8 64 41 0
9 8 63 41 0
9 8 62 41 0
9 8 61 41 0
9 8 60 41 0
9 8 59 41 0
9 8 58 41 0
9 8 57 41 0
9 8 56 41 0
9 8 55 41 0
9 8 54 35 64
9 8 51 35 32
9 8 50 41 0
9 8 49 41 0
9 8 48 41 0
9 8 47 41 0
9 8 46 41 0
9 8 45 41 0
9 8 44 41 0
9 8 43 41 0
9 8 42 41 0
9 8 41 41 0
9 8 40 41 0
9 8 39 41 0
9 8 38 41 0
9 8 37 41 0
9 8 36 41 0
9 8 35 41 0
9 8 34 41 0
9 8 33 41 0
9 8 32 41 0
9 8 31 41 0
9 8 30 41 0
9 8 29 41 0
9 8 28 41 0
9 8 27 41 0
9 8 26 41 0
9 8 25 41 0
9 8 24 41 0
9 8 23 41 0
9 8 22 41 0
9 8 21 41 0
9 8 20 41 0
9 8 19 41 0
9 8 18 41 0
9 8 17 41 0
9 8 16 41 0
9 8 15 41 0
9 8 14 41 0
9 8 13 41 0
9 8 12 41 0
9 8 11 41 0
9 8 10 41 0
9 8 9 41 0
9 8 8 41 0
9 8 7 41 0
9 8 6 41 0
9 8 5 41 0
9 8 4 35 64
9 9 101 35 32
9 9 100 41 0
9 9 99 41 0
9 9 98 41 0
9 9 97 41 0
9 9 96 41 0
9 9 95 41 0
9 9 94 41 0
9 9 93 41 0
9 9 92 41 0
9 9 91 41 0
9 9 90 41 0
9 9 89 41 0
9 9 88 41 0
9 9 87 41 0
9 9 86 41 0
9 9 85 41 0
9 9 84 41 0
9 9 83 41 0
9 9 82 41 0
9 9 81 41 0
9 9 80 41 0
9 9 79 41 0
9 9 78 41 0
9 9 77 41 0
9 9 76 41 0
9 9 75 41 0
9 9 74 41 0
9 9 73 41 0
9 9 72 41 0
9 9 71 41 0
9 9 70 41 0
9 9 69 41 0
9 9 68 41 0
9 9 67 41 0
9 9 66 41 0
9 9 65 41 0
9 9 64 41 0
9 9 63 41 0
9 9 62 41 0
9 9 61 41 0
9 9 60 41 0
9 9 59 41 0
9 9 58 41 0
9 9 57 41 0
9 9 56 41 0
9 9 55 41 0
9 9 54 35 64
9 9 51 35 32
9 9 50 41 0
9 9 49 41 0
9 9 48 41 0
9 9 47 41 0
9 9 46 41 0
9 9 45 41 0
9 9 44 41 0
9 9 43 41 0
9 9 42 41 0
9 9 41 41 0
9 9 40 41 0
9 9 39 41 0
9 9 38 41 0
9 9 37 41 0
9 9 36 41 0
9 9 35 41 0
9 9 34 41 0
9 9 33 41 0
9 9 32 41 0
9 9 31 41 0
9 9 30 41 0
9 9 29 41 0
9 9 28 41 0
9 9 27 41 0
9 9 26 41 0
9 9 25 41 0
9 9 24 41 0
9 9 23 41 0
9 9 22 41 0
9 9 21 41 0
9 9 20 41 0
9 9 19 41 0
9 9 18 41 0
9 9 17 41 0
9 9 16 41 0
9 9 15 41 0
9 9 14 41 0
9 9 13 41 0
9 9 12 41 0
9 9 11 41 0
9 9 10 41 0
9 9 9 41 0
9 9 8 41 0
9 9 7 41 0
9 9 6 41 0
9 9 5 41 0
9 9 4 35 64
9 10 101 35 32
9 10 100 41 0
9 10 99 41 0
9 10 98 41 0
9 10 97 41 0
9 10 96 41 0
9 10 95 41 0
9 10 94 41 0
9 10 93 41 0
9 10 92 41 0
9 10 91 41 0
9 10 90 41 0
9 10 89 41 0
9 10 88 41 0
9 10 87 41 0
9 10 86 41 0
9 10 85 41 0
9 10 84 41 0
9 10 83 41 0
9 10 82 41 0
9 10 81 41 0
9 10 80 41 0
9 10 79 41 0
9 10 78 41 0
9 10 77 41 0
9 10 76 41 0
9 10 75 41 0
9 10 74 41 0
9 10 73 41 0
9 10 72 41 0
9 10 71 41 0
9 10 70 41 0
9 10 69 41 0
9 10 68 41 0
9 10 67 41 0
9 10 66 41 0
9 10 65 41 0
9 10 64 41 0
9 10 63 41 0
9 10 62 41 0
9 10 61 41 0
9 10 60 41 0
9 10 59 41 0
9 10 58 41 0
9 10 57 41 0
9 10 56 41 0
9 10 55 41 0
9 10 54 35 64
9 10 51 35 32
9 10 50 41 0
9 10 49 41 0
9 10 48 41 0
9 10 47 41 0
9 10 46 41 0
9 10 45 41 0
9 10 44 41 0
9 10 43 41 0
9 10 42 41 0
9 10 41 41 0
9 10 40 41 0
9 10 39 41 0
9 10 38 41 0
9 10 37 41 0
9 10 36 41 0
9 10 35 41 0
9 10 34 41 0
9 10 33 41 0
9 10 32 41 0
9 10 31 41 0
9 10 30 41 0
9 10 29 41 0
9 10 28 41 0
9 10 27 41 0
9 10 26 41 0
9 10 25 41 0
9 10 24 41 0
9 10 23 41 0
9 10 22 41 0
9 10 21 41 0
9 10 20 41 0
9 10 19 41 0
9 10 18 41 0
9 10 17 41 0
9 10 16 41 0
9 10 15 41 0
9 10 14 41 0
9 10 13 41 0
9 10 12 41 0
9 10 11 41 0
9 10 10 41 0
9 10 9 41 0
9 10 8 41 0
9 10 7 41 0
9 10 6 41 0
9 10 5 41 0
9 10 4 35 64
9 11 101 35 32
9 11 100 41 0
9 11 99 41 0
9 11 98 41 0
9 11 97 41 0
9 11 96 41 0
9 11 95 41 0
9 11 94 41 0
9 11 93 41 0
9 11 92 41 0
9 11 91 41 0
9 11 90 41 0
9 11 89 41 0
9 11 88 41 0
9 11 87 41 0
9 11 86 41 0
9 11 85 41 0
9 11 84 41 0
9 11 83 41 0
9 11 82 41 0
9 11 81 41 0
9 11 80 41 0
9 11 79 41 0
9 11 78 41 0
9 11 77 41 0
9 11 76 41 0
9 11 75 41 0
9 11 74 41 0
9 11 73 41 0
9 11 72 41 0
9 11 71 41 0
9 11 70 41 0
9 11 69 41 0
9 11 68 41 0
9 11 67 41 0
9 11 66 41 0
9 11 65 41 0
9 11 64 41 0
9 11 63 41 0
9 11 62 41 0
9 11 61 41 0
9 11 60 41 0
9 11 59 41 0
9 11 58 41 0
9 11 57 41 0
9 11 56 41 0
9 11 55 41 0
9 11 54 35 64
9 11 51 35 32
9 11 50 41 0
9 11 49 41 0
9 11 48 41 0
9 11 47 41 0
9 11 46 41 0
9 11 45 41 0
9 11 44 41 0
9 11 43 41 0
9 11 42 41 0
9 11 41 41 0
9 11 40 41 0
9 11 39 41 0
9 11 38 41 0
9 11 37 41 0
9 11 36 41 0
9 11 35 41 0
9 11 34 41 0
9 11 33 41 0
9 11 32 41 0
9 11 31 41 0
9 11 30 41 0
9 11 29 41 0
9 11 28 41 0
9 11 27 41 0
9 11 26 41 0
9 11 25 41 0
9 11 24 41 0
9 11 23 41 0
9 11 22 41 0
9 11 21 41 0
9 11 20 41 0
9 11 19 41 0
9 11 18 41 0
9 11 17 41 0
9 11 16 41 0
9 11 15 41 0
9 11 14 41 0
9 11 13 41 0
9 11 12 41 0
9 11 11 41 0
9 11 10 41 0
9 11 9 41 0
9 11 8 41 0
9 11 7 41 0
9 11 6 41 0
9 11 5 41 0
9 11 4 35 64
9 12 101 35 32
9 12 100 41 0
9 12 99 41 0
9 12 98 41 0
9 12 97 41 0
9 12 96 41 0
9 12 95 41 0
9 12 94 41 0
9 12 93 41 0
9 12 92 41 0
9 12 91 41 0
9 12 90 41 0
9 12 89 41 0
9 12 88 41 0
9 12 87 41 0
9 12 86 41 0
9 12 85 41 0
9 12 84 41 0
9 12 83 41 0
9 12 82 41 0
9 12 81 41 0
9 12 80 41 0
9 12 79 41 0
9 12 78 41 0
9 12 77 41 0
9 12 76 41 0
9 12 75 41 0
9 12 74 41 0
9 12 73 41 0
9 12 72 41 0
9 12 71 41 0
9 12 70 41 0
9 12 69 41 0
9 12 68 41 0
9 12 67 41 0
9 12 66 41 0
9 12 65 41 0
9 12 64 41 0
9 12 63 41 0
9 12 62 41 0
9 12 61 41 0
9 12 60 41 0
9 12 59 41 0
9 12 58 41 0
9 12 57 41 0
9 12 56 41 0
9 12 55 41 0
9 12 54 35 64
9 12 51 35 32
9 12 50 41 0
9 12 49 41 0
9 12 48 41 0
9 12 47 41 0
9 12 46 41 0
9 12 45 41 0
9 12 44 41 0
9 12 43 41 0
9 12 42 41 0
9 12 41 41 0
9 12 40 41 0
9 12 39 41 0
9 12 38 41 0
9 12 37 41 0
9 12 36 41 0
9 12 35 41 0
9 12 34 41 0
9 12 33 41 0
9 12 32 41 0
9 12 31 41 0
9 12 30 41 0
9 12 29 41 0
9 12 28 41 0
9 12 27 41 0
9 12 26 41 0
9 12 25 41 0
9 12 24 41 0
9 12 23 41 0
9 12 22 41 0
9 12 21 41 0
9 12 20 41 0
9 12 19 41 0
9 12 18 41 0
9 12 17 41 0
9 12 16 41 0
9 12 15 41 0
9 12 14 41 0
9 12 13 41 0
9 12 12 41 0
9 12 11 41 0
9 12 10 41 0
9 12 9 41 0
9 12 8 41 0
9 12 7 41 0
9 12 6 41 0
9 12 5 41 0
9 12 4 35 64
9 13 101 35 32
9 13 100 41 0
9 13 99 41 0
9 13 98 41 0
9 13 97 41 0
9 13 96 41 0
9 13 95 41 0
9 13 94 41 0
9 13 93 41 0
9 13 92 41 0
9 13 91 41 0
9 13 90 41 0
9 13 89 41 0
9 13 88 41 0
9 13 87 41 0
9 13 86 41 0
9 13 85 41 0
9 13 84 41 0
9 13 83 41 0
9 13 82 41 0
9 13 81 41 0
9 13 80 41 0
9 13 79 41 0
9 13 78 41 0
9 13 77 41 0
9 13 76 41 0
9 13 75 41 0
9 13 74 41 0
9 13 73 41 0
9 13 72 41 0
9 13 71 41 0
9 13 70 41 0
9 13 69 41 0
9 13 68 41 0
9 13 67 41 0
9 13 66 41 0
9 13 65 41 0
9 13 64 41 0
9 13 63 41 0
9 13 62 41 0
9 13 61 41 0
9 13 60 41 0
9 13 59 41 0
9 13 58 41 0
9 13 57 41 0
9 13 56 41 0
9 13 55 41 0
9 13 54 35 64
9 13 51 35 32
9 13 50 41 0
9 13 49 41 0
9 13 48 41 0
9 13 47 41 0
9 13 46 41 0
9 13 45 41 0
9 13 44 41 0
9 13 43 41 0
9 13 42 41 0
9 13 41 41 0
9 13 40 41 0
9 13 39 41 0
9 13 38 41 0
9 13 37 41 0
9 13 36 41 0
9 13 35 41 0
9 13 34 41 0
9 13 33 41 0
9 13 32 41 0
9 13 31 41 0
9 13 30 41 0
9 13 29 41 0
9 13 28 41 0
9 13 27 41 0
9 13 26 41 0
9 13 25 41 0
9 13 24 41 0
9 13 23 41 0
9 13 22 41 0
9 13 21 41 0
9 13 20 41 0
9 13 19 41 0
9 13 18 41 0
9 13 17 41 0
9 13 16 41 0
9 13 15 41 0
9 13 14 41 0
9 13 13 41 0
9 13 12 41 0
9 13 11 41 0
9 13 10 41 0
9 13 9 41 0
9 13 8 41 0
9 13 7 41 0
9 13 6 41 0
9 13 5 41 0
9 13 4 35 64
9 14 101 35 32
9 14 100 41 0
9 14 99 41 0
9 14 98 41 0
9 14 97 41 0
9 14 96 41 0
9 14 95 41 0
9 14 94 41 0
9 14 93 41 0
9 14 92 41 0
9 14 91 41 0
9 14 90 41 0
9 14 89 41 0
9 14 88 41 0
9 14 87 41 0
9 14 86 41 0
9 14 85 41 0
9 14 84 41 0
9 14 83 41 0
9 14 82 41 0
9 14 81 41 0
9 14 80 41 0
9 14 79 41 0
9 14 78 41 0
9 14 77 41 0
9 14 76 41 0
9 14 75 41 0
9 14 74 41 0
9 14 73 41 0
9 14 72 41 0
9 14 71 41 0
9 14 70 41 0
9 14 69 41 0
9 14 68 41 0
9 14 67 41 0
9 14 66 41 0
9 14 65 41 0
9 14 64 41 0
9 14 63 41 0
9 14 62 41 0
9 14 61 41 0
9 14 60 41 0
9 14 59 41 0
9 14 58 41 0
9 14 57 41 0
9 14 56 41 0
9 14 55 41 0
9 14 54 35 64
9 14 51 35 32
9 14 50 41 0
9 14 49 41 0
9 14 48 41 0
9 14 47 41 0
9 14 46 41 0
9 14 45 41 0
9 14 44 41 0
9 14 43 41 0
9 14 42 41 0
9 14 41 41 0
9 14 40 41 0
9 14 39 41 0
9 14 38 41 0
9 14 37 41 0
9 14 36 41 0
9 14 35 41 0
9 14 34 41 0
9 14 33 41 0
9 14 32 41 0
9 14 31 41 0
9 14 30 41 0
9 14 29 41 0
9 14 28 41 0
9 14 27 41 0
9 14 26 41 0
9 14 25 41 0
9 14 24 41 0
9 14 23 41 0
9 14 22 41 0
9 14 21 41 0
9 14 20 41 0
9 14 19 41 0
9 14 18 41 0
9 14 17 41 0
9 14 16 41 0
9 14 15 41 0
9 14 14 41 0
9 14 13 41 0
9 14 12 41 0
9 14 11 41 0
9 14 10 41 0
9 14 9 41 0
9 14 8 41 0
9 14 7 41 0
9 14 6 41 0
9 14 5 41 0
9 14 4 35 64
9 15 101 35 32
9 15 100 41 0
9 15 99 41 0
9 15 98 41 0
9 15 97 41 0
9 15 96 41 0
9 15 95 41 0
9 15 94 41 0
9 15 93 41 0
9 15 92 41 0
9 15 91 41 0
9 15 90 41 0
9 15 89 41 0
9 15 88 41 0
9 15 87 41 0
9 15 86 41 0
9 15 85 41 0
9 15 84 41 0
9 15 83 41 0
9 15 82 41 0
9 15 81 41 0
9 15 80 41 0
9 15 79 41 0
9 15 78 41 0
9 15 77 41 0
9 15 76 41 0
9 15 75 41 0
9 15 74 41 0
9 15 73 41 0
9 15 72 41 0
9 15 71 41 0
9 15 70 41 0
9 15 69 41 0
9 15 68 41 0
9 15 67 41 0
9 15 66 41 0
9 15 65 41 0
9 15 64 41 0
9 15 63 41 0
9 15 62 41 0
9 15 61 41 0
9 15 60 41 0
9 15 59 41 0
9 15 58 41 0
9 15 57 41 0
9 15 56 41 0
9 15 55 41 0
9 15 54 35 64
9 15 51 35 32
9 15 50 41 0
9 15 49 41 0
9 15 48 41 0
9 15 47 41 0
9 15 46 41 0
9 15 45 41 0
9 15 44 41 0
9 15 43 41 0
9 15 42 41 0
9 15 41 41 0
9 15 40 41 0
9 15 39 41 0
9 15 38 41 0
9 15 37 41 0
9 15 36 41 0
9 15 35 41 0
9 15 34 41 0
9 15 33 41 0
9 15 32 41 0
9 15 31 41 0
9 15 30 41 0
9 15 29 41 0
9 15 28 41 0
9 15 27 41 0
9 15 26 41 0
9 15 25 41 0
9 15 24 41 0
9 15 23 41 0
9 15 22 41 0
9 15 21 41 0
9 15 20 41 0
9 15 19 41 0
9 15 18 41 0
9 15 17 41 0
9 15 16 41 0
9 15 15 41 0
9 15 14 41 0
9 15 13 41 0
9 15 12 41 0
9 15 11 41 0
9 15 10 41 0
9 15 9 41 0
9 15 8 41 0
9 15 7 41 0
9 15 6 41 0
9 15 5 41 0
9 15 4 35 64
9 16 101 35 32
9 16 100 41 0
9 16 99 41 0
9 16 98 41 0
9 16 97 41 0
9 16 96 41 0
9 16 95 41 0
9 16 94 41 0
9 16 93 41 0
9 16 92 41 0
9 16 91 41 0
9 16 90 41 0
9 16 89 41 0
9 16 88 41 0
9 16 87 41 0
9 16 86 41 0
9 16 85 41 0
9 16 84 41 0
9 16 83 41 0
9 16 82 41 0
9 16 81 41 0
9 16 80 41 0
9 16 79 41 0
9 16 78 41 0
9 16 77 41 0
9 16 76 41 0
9 16 75 41 0
9 16 74 41 0
9 16 73 41 0
9 16 72 41 0
9 16 71 41 0
9 16 70 41 0
9 16 69 41 0
9 16 68 41 0
9 16 67 41 0
9 16 66 41 0
9 16 65 41 0
9 16 64 41 0
9 16 63 41 0
9 16 62 41 0
9 16 61 41 0
9 16 60 41 0
9 16 59 41 0
9 16 58 41 0
9 16 57 41 0
9 16 56 41 0
9 16 55 41 0
9 16 54 35 64
9 16 51 35 32
9 16 50 41 0
9 16 49 41 0
9 16 48 41 0
9 16 47 41 0
9 16 46 41 0
9 16 45 41 0
9 16 44 41 0
9 16 43 41 0
9 16 42 41 0
9 16 41 41 0
9 16 40 41 0
9 16 39 41 0
9 16 38 41 0
9 16 37 41 0
9 16 36 41 0
9 16 35 41 0
9 16 34 41 0
9 16 33 41 0
9 16 32 41 0
9 16 31 41 0
9 16 30 41 0
9 16 29 41 0
9 16 28 41 0
9 16 27 41 0
9 16 26 41 0
9 16 25 41 0
9 16 24 41 0
9 16 23 41 0
9 16 22 41 0
9 16 21 41 0
9 16 20 41 0
9 16 19 41 0
9 16 18 41 0
9 16 17 41 0
9 16 16 41 0
9 16 15 41 0
9 16 14 41 0
9 16 13 41 0
9 16 12 41 0
9 16 11 41 0
9 16 10 41 0
9 16 9 41 0
9 16 8 41 0
9 16 7 41 0
9 16 6 41 0
9 16 5 41 0
9 16 4 35 64
9 17 101 35 32
9 17 100 41 0
9 17 99 41 0
9 17 98 41 0
9 17 97 41 0
9 17 96 41 0
9 17 95 41 0
9 17 94 41 0
9 17 93 41 0
9 17 92 41 0
9 17 91 41 0
9 17 90 41 0
9 17 89 41 0
9 17 88 41 0
9 17 87 41 0
9 17 86 41 0
9 17 85 41 0
9 17 84 41 0
9 17 83 41 0
9 17 82 41 0
9 17 81 41 0
9 17 80 41 0
9 17 79 41 0
9 17 78 41 0
9 17 77 41 0
9 17 76 41 0
9 17 75 41 0
9 17 74 41 0
9 17 73 41 0
9 17 72 41 0
9 17 71 41 0
9 17 70 41 0
9 17 69 41 0
9 17 68 41 0
9 17 67 41 0
9 17 66 41 0
9 17 65 41 0
9 17 64 41 0
9 17 63 41 0
9 17 62 41 0
9 17 61 41 0
9 17 60 41 0
9 17 59 41 0
9 17 58 41 0
9 17 57 41 0
9 17 56 41 0
9 17 55 41 0
9 17 54 35 64
9 17 51 35 32
9 17 50 41 0
9 17 49 41 0
9 17 48 41 0
9 17 47 41 0
9 17 46 41 0
9 17 45 41 0
9 17 44 41 0
9 17 43 41 0
9 17 42 41 0
9 17 41 41 0
9 17 40 41 0
9 17 39 41 0
9 17 38 41 0
9 17 37 41 0
9 17 36 41 0
9 17 35 41 0
9 17 34 41 0
9 17 33 41 0
9 17 32 41 0
9 17 31 41 0
9 17 30 41 0
9 17 29 41 0
9 17 28 41 0
9 17 27 41 0
9 17 26 41 0
9 17 25 41 0
9 17 24 41 0
9 17 23 41 0
9 17 22 41 0
9 17 21 41 0
9 17 20 41 0
9 17 19 41 0
9 17 18 41 0
9 17 17 41 0
9 17 16 41 0
9 17 15 41 0
9 17 14 41 0
9 17 13 41 0
9 17 12 41 0
9 17 11 41 0
9 17 10 41 0
9 17 9 41 0
9 17 8 41 0
9 17 7 41 0
9 17 6 41 0
9 17 5 41 0
9 17 4 35 64
9 18 101 35 32
9 18 100 41 0
9 18 99 41 0
9 18 98 41 0
9 18 97 41 0
9 18 96 41 0
9 18 95 41 0
9 18 94 41 0
9 18 93 41 0
9 18 92 41 0
9 18 91 41 0
9 18 90 41 0
9 18 89 41 0
9 18 88 41 0
9 18 87 41 0
9 18 86 41 0
9 18 85 41 0
9 18 84 41 0
9 18 83 41 0
9 18 82 41 0
9 18 81 41 0
9 18 80 41 0
9 18 79 41 0
9 18 78 41 0
9 18 77 41 0
9 18 76 41 0
9 18 75 41 0
9 18 74 41 0
9 18 73 41 0
9 18 72 41 0
9 18 71 41 0
9 18 70 41 0
9 18 69 41 0
9 18 68 41 0
9 18 67 41 0
9 18 66 41 0
9 18 65 41 0
9 18 64 41 0
9 18 63 41 0
9 18 62 41 0
9 18 61 41 0
9 18 60 41 0
9 18 59 41 0
9 18 58 41 0
9 18 57 41 0
9 18 56 41 0
9 18 55 41 0
9 18 54 35 64
9 18 51 35 32
9 18 50 41 0
9 18 49 41 0
9 18 48 41 0
9 18 47 41 0
9 18 46 41 0
9 18 45 41 0
9 18 44 41 0
9 18 43 41 0
9 18 42 41 0
9 18 41 41 0
9 18 40 41 0
9 18 39 41 0
9 18 38 41 0
9 18 37 41 0
9 18 36 41 0
9 18 35 41 0
9 18 34 41 0
9 18 33 41 0
9 18 32 41 0
9 18 31 41 0
9 18 30 41 0
9 18 29 41 0
9 18 28 41 0
9 18 27 41 0
9 18 26 41 0
9 18 25 41 0
9 18 24 41 0
9 18 23 41 0
9 18 22 41 0
9 18 21 41 0
9 18 20 41 0
9 18 19 41 0
9 18 18 41 0
9 18 17 41 0
9 18 16 41 0
9 18 15 41 0
9 18 14 41 0
9 18 13 41 0
9 18 12 41 0
9 18 11 41 0
9 18 10 41 0
9 18 9 41 0
9 18 8 41 0
9 18 7 41 0
9 18 6 41 0
9 18 5 41 0
9 18 4 35 64
9 19 101 35 32
9 19 100 41 0
9 19 99 41 0
9 19 98 41 0
9 19 97 41 0
9 19 96 41 0
9 19 95 41 0
9 19 94 41 0
9 19 93 41 0
9 19 92 41 0
9 19 91 41 0
9 19 90 41 0
9 19 89 41 0
9 19 88 41 0
9 19 87 41 0
9 19 86 41 0
9 19 85 41 0
9 19 84 41 0
9 19 83 41 0
9 19 82 41 0
9 19 81 41 0
9 19 80 41 0
9 19 79 41 0
9 19 78 41 0
9 19 77 41 0
9 19 76 41 0
9 19 75 41 0
9 19 74 41 0
9 19 73 41 0
9 19 72 41 0
9 19 71 41 0
9 19 70 41 0
9 19 69 41 0
9 19 68 41 0
9 19 67 41 0
9 19 66 41 0
9 19 65 41 0
9 19 64 41 0
9 19 63 41 0
9 19 62 41 0
9 19 61 41 0
9 19 60 41 0
9 19 59 41 0
9 19 58 41 0
9 19 57 41 0
9 19 56 41 0
9 19 55 41 0
9 19 54 35 64
9 19 51 35 32
9 19 50 41 0
9 19 49 41 0
9 19 48 41 0
9 19 47 41 0
9 19 46 41 0
9 19 45 41 0
9 19 44 41 0
9 19 43 41 0
9 19 42 41 0
9 19 41 41 0
9 19 40 41 0
9 19 39 41 0
9 19 38 41 0
9 19 37 41 0
9 19 36 41 0
9 19 35 41 0
9 19 34 41 0
9 19 33 41 0
9 19 32 41 0
9 19 31 41 0
9 19 30 41 0
9 19 29 41 0
9 19 28 41 0
9 19 27 41 0
9 19 26 41 0
9 19 25 41 0
9 19 24 41 0
9 19 23 41 0
9 19 22 41 0
9 19 21 41 0
9 19 20 41 0
9 19 19 41 0
9 19 18 41 0
9 19 17 41 0
9 19 16 41 0
9 19 15 41 0
9 19 14 41 0
9 19 13 41 0
9 19 12 41 0
9 19 11 41 0
9 19 10 41 0
9 19 9 41 0
9 19 8 41 0
9 19 7 41 0
9 19 6 41 0
9 19 5 41 0
9 19 4 35 64
9 20 101 35 32
9 20 100 41 0
9 20 99 41 0
9 20 98 41 0
9 20 97 41 0
9 20 96 41 0
9 20 95 41 0
9 20 94 41 0
9 20 93 41 0
9 20 92 41 0
9 20 91 41 0
9 20 90 41 0
9 20 89 41 0
9 20 88 41 0
9 20 87 41 0
9 20 86 41 0
9 20 85 41 0
9 20 84 41 0
9 20 83 41 0
9 20 82 41 0
9 20 81 41 0
9 20 80 41 0
9 20 79 41 0
9 20 78 41 0
9 20 77 41 0
9 20 76 41 0
9 20 75 41 0
9 20 74 41 0
9 20 73 41 0
9 20 72 41 0
9 20 71 41 0
9 20 70 41 0
9 20 69 41 0
9 20 68 41 0
9 20 67 41 0
9 20 66 41 0
9 20 65 41 0
9 20 64 41 0
9 20 63 41 0
9 20 62 41 0
9 20 61 41 0
9 20 60 41 0
9 20 59 41 0
9 20 58 41 0
9 20 57 41 0
9 20 56 41 0
9 20 55 41 0
9 20 54 35 64
9 20 51 35 32
9 20 50 41 0
9 20 49 41 0
9 20 48 41 0
9 20 47 41 0
9 20 46 41 0
9 20 45 41 0
9 20 44 41 0
9 20 43 41 0
9 20 42 41 0
9 20 41 41 0
9 20 40 41 0
9 20 39 41 0
9 20 38 41 0
9 20 37 41 0
9 20 36 41 0
9 20 35 41 0
9 20 34 41 0
9 20 33 41 0
9 20 32 41 0
9 20 31 41 0
9 20 30 41 0
9 20 29 41 0
9 20 28 41 0
9 20 27 41 0
9 20 26 41 0
9 20 25 41 0
9 20 24 41 0
9 20 23 41 0
9 20 22 41 0
9 20 21 41 0
9 20 20 41 0
9 20 19 41 0
9 20 18 41 0
9 20 17 41 0
9 20 16 41 0
9 20 15 41 0
9 20 14 41 0
9 20 13 41 0
9 20 12 41 0
9 20 11 41 0
9 20 10 41 0
9 20 9 41 0
9 20 8 41 0
9 20 7 41 0
9 20 6 41 0
9 20 5 41 0
9 20 4 35 64
9 21 102 41 48
9 21 101 41 0
9 21 100 41 0
9 21 99 41 0
9 21 98 41 0
9 21 97 41 0
9 21 96 41 0
9 21 95 41 0
9 21 94 41 0
9 21 93 41 0
9 21 92 41 0
9 21 91 41 0
9 21 90 41 0
9 21 89 41 0
9 21 88 41 0
9 21 87 41 0
9 21 86 41 0
9 21 85 41 0
9 21 84 41 0
9 21 83 41 0
9 21 82 41 0
9 21 81 41 0
9 21 80 41 0
9 21 79 41 0
9 21 78 41 0
9 21 77 41 0
9 21 76 41 0
9 21 75 41 0
9 21 74 41 0
9 21 73 41 0
9 21 72 41 0
9 21 71 41 0
9 21 70 41 0
9 21 69 41 0
9 21 68 41 0
9 21 67 41 0
9 21 66 41 0
9 21 65 41 0
9 21 64 41 0
9 21 63 41 0
9 21 62 41 0
9 21 61 41 0
9 21 60 41 0
9 21 59 41 0
9 21 58 41 0
9 21 57 41 0
9 21 56 41 0
9 21 55 41 0
9 21 54 41 0
9 21 53 41 16
9 21 52 41 16
9 21 51 41 0
9 21 50 41 0
9 21 49 41 0
9 21 48 41 0
9 21 47 41 0
9 21 46 41 0
9 21 45 41 0
9 21 44 41 0
9 21 43 41 0
9 21 42 41 0
9 21 41 41 0
9 21 40 41 0
9 21 39 41 0
9 21 38 41 0
9 21 37 41 0
9 21 36 41 0
9 21 35 41 0
9 21 34 41 0
9 21 33 41 0
9 21 32 41 0
9 21 31 41 0
9 21 30 41 0
9 21 29 41 0
9 21 28 41 0
9 21 27 41 0
9 21 26 41 0
9 21 25 41 0
9 21 24 41 0
9 21 23 41 0
9 21 22 41 0
9 21 21 41 0
9 21 20 41 0
9 21 19 41 0
9 21 18 41 0
9 21 17 41 0
9 21 16 41 0
9 21 15 41 0
9 21 14 41 0
9 21 13 41 0
9 21 12 41 0
9 21 11 41 0
9 21 10 41 0
9 21 9 41 0
9 21 8 41 0
9 21 7 41 0
9 21 6 41 0
9 21 5 41 0
9 21 4 41 0
9 21 3 41 80
9 22 102 17 40
9 22 101 17 8
9 22 100 17 8
9 22 99 17 8
9 22 98 17 8
9 22 97 17 8
9 22 96 17 0
9 22 95 17 0
9 22 94 17 8
9 22 93 17 8
9 22 92 17 8
9 22 91 17 8
9 22 90 17 8
9 22 89 17 8
9 22 88 17 8
9 22 87 17 8
9 22 86 17 8
9 22 85 17 8
9 22 84 17 8
9 22 83 17 8
9 22 82 17 8
9 22 81 17 8
9 22 80 17 8
9 22 79 17 8
9 22 78 17 8
9 22 77 17 8
9 22 76 17 8
9 22 75 17 8
9 22 74 17 8
9 22 73 17 8
9 22 72 17 8
9 22 71 17 8
9 22 70 17 8
9 22 69 17 8
9 22 68 17 8
9 22 67 17 8
9 22 66 17 0
9 22 65 17 0
9 22 64 17 8
9 22 63 17 8
9 22 62 17 8
9 22 61 17 8
9 22 60 17 8
9 22 59 17 8
9 22 58 17 8
9 22 57 17 8
9 22 56 17 8
9 22 55 17 8
9 22 54 17 8
9 22 53 17 8
9 22 52 17 8
9 22 51 17 8
9 22 50 17 8
9 22 49 17 8
9 22 48 17 8
9 22 47 17 8
9 22 46 17 8
9 22 45 17 8
9 22 44 17 8
9 22 43 17 8
9 22 42 17 8
9 22 41 17 8
9 22 40 17 8
9 22 39 17 8
9 22 38 17 8
9 22 37 17 8
9 22 36 17 8
9 22 35 17 8
9 22 34 17 8
9 22 33 17 8
9 22 32 17 8
9 22 31 17 8
9 22 30 17 8
9 22 29 17 8
9 22 28 17 8
9 22 27 17 8
9 22 26 17 8
9 22 25 17 8
9 22 24 17 8
9 22 23 17 8
9 22 22 17 8
9 22 21 17 8
9 22 20 17 8
9 22 19 17 8
9 22 18 17 8
9 22 17 17 8
9 22 16 17 8
9 22 15 17 8
9 22 14 17 8
9 22 13 17 8
9 22 12 17 8
9 22 11 17 8
9 22 10 17 8
9 22 9 17 8
9 22 8 17 8
9 22 7 17 8
9 22 6 17 8
9 22 5 17 8
9 22 4 17 8
9 22 3 17 72
9 23 96 37 36
9 23 95 37 68
9 23 66 37 36
9 23 65 37 68
9 24 97 18 48
9 24 96 21 0
9 24 95 21 0
9 24 94 21 16
9 24 93 21 16
9 24 92 21 16
9 24 91 21 16
9 24 90 21 16
9 24 89 21 16
9 24 88 21 16
9 24 87 21 16
9 24 86 21 16
9 24 85 21 16
9 24 84 18 16
9 24 83 21 16
9 24 82 30 84
9 24 80 30 52
9 24 79 21 16
9 24 78 18 16
9 24 77 21 16
9 24 76 21 16
9 24 75 21 16
9 24 74 21 16
9 24 73 21 16
9 24 72 21 16
9 24 71 21 16
9 24 70 21 16
9 24 69 21 16
9 24 68 21 16
9 24 67 18 16
9 24 66 21 0
9 24 65 18 64
9 25 97 18 40
9 25 96 65 0
9 25 95 21 0
9 25 94 21 0
9 25 93 21 0
9 25 92 21 0
9 25 91 21 0
9 25 90 21 0
9 25 89 65 0
9 25 88 21 0
9 25 87 21 0
9 25 86 21 0
9 25 85 21 0
9 25 84 21 0
9 25 83 21 0
9 25 82 18 0
9 25 81 30 16
9 25 80 18 0
9 25 79 21 0
9 25 78 21 0
9 25 77 21 0
9 25 76 21 0
9 25 75 21 0
9 25 74 21 0
9 25 73 65 0
9 25 72 21 0
9 25 71 21 0
9 25 70 21 0
9 25 69 21 0
9 25 68 21 0
9 25 67 21 0
9 25 66 65 0
9 25 65 18 72
9 26 96 65 32
9 26 95 21 0
9 26 94 21 0
9 26 93 21 0
9 26 92 21 0
9 26 91 21 0
9 26 90 21 0
9 26 89 65 0
9 26 88 21 0
9 26 87 21 0
9 26 86 21 0
9 26 85 21 0
9 26 84 21 0
9 26 83 21 0
9 26 82 18 0
9 26 81 43 8
9 26 80 65 8
9 26 79 50 8
9 26 78 50 8
9 26 77 50 8
9 26 76 60 8
9 26 75 60 8
9 26 74 60 8
9 26 73 65 8
9 26 72 50 8
9 26 71 60 8
9 26 70 60 8
9 26 69 60 8
9 26 68 60 8
9 26 67 60 8
9 26 66 65 72
9 27 96 65 40
9 27 95 50 8
9 27 94 60 8
9 27 93 60 8
9 27 92 60 8
9 27 91 60 8
9 27 90 50 8
9 27 89 65 8
9 27 88 7 8
9 27 87 69 8
9 27 86 50 8
9 27 85 50 8
9 27 84 69 8
9 27 83 7 8
9 27 82 65 72
9 34 52 13 52
9 34 51 13 20
9 34 50 45 20
9 34 49 45 20
9 34 48 45 20
9 34 47 45 20
9 34 46 55 20
9 34 45 45 84
9 35 53 13 52
9 35 52 13 4
9 35 51 45 4
9 35 50 13 0
9 35 49 13 0
9 35 48 13 0
9 35 47 13 0
9 35 46 45 4
9 35 45 55 4
9 35 44 45 84
9 36 54 13 52
9 36 53 13 4
9 36 52 13 0
9 36 51 13 0
9 36 50 13 0
9 36 49 13 0
9 36 48 13 0
9 36 47 13 0
9 36 46 13 0
9 36 45 13 0
9 36 44 45 4
9 36 43 13 84
9 37 55 13 52
9 37 54 13 4
9 37 53 13 0
9 37 52 13 0
9 37 51 13 0
9 37 50 13 0
9 37 49 13 0
9 37 48 13 0
9 37 47 13 0
9 37 46 13 0
9 37 45 13 0
9 37 44 13 0
9 37 43 13 4
9 37 42 13 84
9 38 55 13 36
9 38 54 13 0
9 38 53 13 0
9 38 52 13 0
9 38 51 13 0
9 38 50 13 0
9 38 49 13 0
9 38 48 13 0
9 38 47 13 0
9 38 46 13 0
9 38 45 13 0
9 38 44 13 0
9 38 43 13 0
9 38 42 13 68
9 39 55 13 36
9 39 54 13 0
9 39 53 13 0
9 39 52 13 0
9 39 51 13 0
9 39 50 13 0
9 39 49 13 0
9 39 48 13 0
9 39 47 13 0
9 39 46 13 0
9 39 45 13 0
9 39 44 13 0
9 39 43 13 0
9 39 42 13 68
9 40 56 13 52
9 40 55 13 4
9 40 54 13 0
9 40 53 13 0
9 40 52 13 0
9 40 51 13 0
9 40 50 13 0
9 40 49 13 0
9 40 48 13 0
9 40 47 13 0
9 40 46 13 0
9 40 45 13 0
9 40 44 13 0
9 40 43 13 0
9 40 42 13 4
9 40 41 13 84
9 41 56 13 36
9 41 55 13 4
9 41 54 13 0
9 41 53 13 0
9 41 52 13 0
9 41 51 13 0
9 41 50 13 0
9 41 49 13 0
9 41 48 13 0
9 41 47 13 0
9 41 46 13 0
9 41 45 13 0
9 41 44 13 0
9 41 43 13 0
9 41 42 13 4
9 41 41 13 68
9 42 56 13 36
9 42 55 13 4
9 42 54 13 0
9 42 53 13 0
9 42 52 13 0
9 42 51 13 0
9 42 50 13 0
9 42 49 13 0
9 42 48 13 0
9 42 47 13 0
9 42 46 13 0
9 42 45 13 0
9 42 44 13 0
9 42 43 13 0
9 42 42 13 4
9 42 41 13 68
9 43 56 13 44
9 43 55 13 4
9 43 54 13 0
9 43 53 13 0
9 43 52 13 0
9 43 51 13 0
9 43 50 13 0
9 43 49 13 0
9 43 48 13 0
9 43 47 13 0
9 43 46 13 0
9 43 45 13 0
9 43 44 13 0
9 43 43 13 0
9 43 42 13 4
9 43 41 13 76
9 44 55 13 36
9 44 54 13 0
9 44 53 13 0
9 44 52 13 0
9 44 51 13 0
9 44 50 13 0
9 44 49 13 0
9 44 48 13 0
9 44 47 13 0
9 44 46 13 0
9 44 45 13 0
9 44 44 13 0
9 44 43 13 0
9 44 42 13 68
9 45 55 13 36
9 45 54 13 0
9 45 53 13 0
9 45 52 13 0
9 45 51 13 0
9 45 50 13 0
9 45 49 13 0
9 45 48 13 0
9 45 47 13 0
9 45 46 13 0
9 45 45 13 0
9 45 44 13 0
9 45 43 13 0
9 45 42 13 68
9 46 55 13 44
9 46 54 13 4
9 46 53 13 0
9 46 52 13 0
9 46 51 13 0
9 46 50 13 0
9 46 49 13 0
9 46 48 13 0
9 46 47 13 0
9 46 46 13 0
9 46 45 13 0
9 46 44 13 0
9 46 43 13 4
9 46 42 13 76
9 47 54 6 44
9 47 53 14 4
9 47 52 13 0
9 47 51 13 0
9 47 50 13 0
9 47 49 13 0
9 47 48 13 0
9 47 47 13 0
9 47 46 13 0
9 47 45 13 0
9 47 44 13 4
9 47 43 13 76
9 48 53 12 44
9 48 52 14 4
9 48 51 14 4
9 48 50 13 0
9 48 49 13 0
9 48 48 13 0
9 48 47 13 0
9 48 46 13 4
9 48 45 13 4
9 48 44 13 76
9 49 52 45 44
9 49 51 14 12
9 49 50 14 12
9 49 49 13 12
9 49 48 13 12
9 49 47 13 12
9 49 46 13 12
9 49 45 13 76
10 1 103 23 48
10 1 102 23 16
10 1 101 23 22
10 1 100 23 22
10 1 99 23 22
10 1 98 23 22
10 1 97 23 22
10 1 96 23 22
10 1 95 23 22
10 1 94 23 22
10 1 93 23 22
10 1 92 23 22
10 1 91 23 22
10 1 90 23 22
10 1 89 23 22
10 1 88 23 22
10 1 87 23 22
10 1 86 23 22
10 1 85 23 22
10 1 84 23 22
10 1 83 23 22
10 1 82 23 22
10 1 81 23 22
10 1 80 23 22
10 1 79 23 22
10 1 78 23 22
10 1 77 23 22
10 1 76 23 22
10 1 75 23 22
10 1 74 23 22
10 1 73 23 22
10 1 72 23 22
10 1 71 23 22
10 1 70 23 22
10 1 69 23 22
10 1 68 23 22
10 1 67 23 22
10 1 66 23 22
10 1 65 23 22
10 1 64 23 22
10 1 63 23 22
10 1 62 23 22
10 1 61 23 22
10 1 60 23 22
10 1 59 23 22
10 1 58 23 22
10 1 57 23 22
10 1 56 23 22
10 1 55 23 22
10 1 54 23 22
10 1 53 23 16
10 1 52 23 80
10 1 3 23 48
10 1 2 23 80
10 2 103 23 40
10 2 102 23 0
10 2 101 23 4
10 2 100 23 4
10 2 99 23 4
10 2 98 23 4
10 2 97 23 4
10 2 96 23 4
10 2 95 23 4
10 2 94 23 4
10 2 93 23 4
10 2 92 23 4
10 2 91 23 4
10 2 90 23 4
10 2 89 23 4
10 2 88 23 4
10 2 87 23 4
10 2 86 23 4
10 2 85 23 4
10 2 84 23 4
10 2 83 23 4
10 2 82 23 4
10 2 81 23 4
10 2 80 23 4
10 2 79 23 4
10 2 78 23 4
10 2 77 23 4
10 2 76 23 4
10 2 75 23 4
10 2 74 23 4
10 2 73 23 4
10 2 72 23 4
10 2 71 23 4
10 2 70 23 4
10 2 69 23 4
10 2 68 23 4
10 2 67 23 4
10 2 66 23 4
10 2 65 23 4
10 2 64 23 4
10 2 63 23 4
10 2 62 23 4
10 2 61 23 4
10 2 60 23 4
10 2 59 23 4
10 2 58 23 4
10 2 57 23 4
10 2 56 23 4
10 2 55 23 4
10 2 54 23 4
10 2 53 23 0
10 2 52 23 64
10 2 3 23 32
10 2 2 23 72
10 3 102 41 40
10 3 101 41 0
10 3 100 41 0
10 3 99 41 0
10 3 98 41 0
10 3 97 41 0
10 3 96 41 0
10 3 95 41 0
10 3 94 41 0
10 3 93 41 0
10 3 92 41 0
10 3 91 41 0
10 3 90 41 0
10 3 89 41 0
10 3 88 41 0
10 3 87 41 0
10 3 86 41 0
10 3 85 41 0
10 3 84 41 0
10 3 83 41 0
10 3 82 41 0
10 3 81 41 0
10 3 80 41 0
10 3 79 41 0
10 3 78 41 0
10 3 77 41 0
10 3 76 41 0
10 3 75 41 0
10 3 74 41 0
10 3 73 41 0
10 3 72 41 0
10 3 71 41 0
10 3 70 41 0
10 3 69 41 0
10 3 68 41 0
10 3 67 41 0
10 3 66 41 0
10 3 65 41 0
10 3 64 41 0
10 3 63 41 0
10 3 62 41 0
10 3 61 41 0
10 3 60 41 0
10 3 59 41 0
10 3 58 41 0
10 3 57 41 0
10 3 56 41 0
10 3 55 41 0
10 3 54 41 0
10 3 53 41 8
10 3 52 41 8
10 3 51 41 16
10 3 50 41 16
10 3 49 41 16
10 3 48 41 16
10 3 47 41 16
10 3 46 41 16
10 3 45 41 16
10 3 44 41 16
10 3 43 41 16
10 3 42 41 16
10 3 41 41 16
10 3 40 41 16
10 3 39 41 16
10 3 38 41 16
10 3 37 41 16
10 3 36 41 16
10 3 35 41 16
10 3 34 41 16
10 3 33 41 16
10 3 32 41 16
10 3 31 41 16
10 3 30 41 16
10 3 29 41 16
10 3 28 41 16
10 3 27 41 16
10 3 26 41 16
10 3 25 41 16
10 3 24 41 16
10 3 23 41 16
10 3 22 41 16
10 3 21 41 16
10 3 20 41 16
10 3 19 41 16
10 3 18 41 16
10 3 17 41 16
10 3 16 41 16
10 3 15 41 16
10 3 14 41 16
10 3 13 41 16
10 3 12 41 16
10 3 11 41 16
10 3 10 41 16
10 3 9 41 16
10 3 8 41 16
10 3 7 41 16
10 3 6 41 16
10 3 5 41 16
10 3 4 41 16
10 3 3 41 72
10 4 101 35 32
10 4 100 41 0
10 4 99 41 0
10 4 98 41 0
10 4 97 41 0
10 4 96 41 0
10 4 95 41 0
10 4 94 41 0
10 4 93 41 0
10 4 92 41 0
10 4 91 41 0
10 4 90 41 0
10 4 89 41 0
10 4 88 41 0
10 4 87 41 0
10 4 86 41 0
10 4 85 41 0
10 4 84 41 0
10 4 83 41 0
10 4 82 41 0
10 4 81 41 0
10 4 80 41 0
10 4 79 41 0
10 4 78 41 0
10 4 77 41 0
10 4 76 41 0
10 4 75 41 0
10 4 74 41 0
10 4 73 41 0
10 4 72 41 0
10 4 71 41 0
10 4 70 41 0
10 4 69 41 0
10 4 68 41 0
10 4 67 41 0
10 4 66 41 0
10 4 65 41 0
10 4 64 41 0
10 4 63 41 0
10 4 62 41 0
10 4 61 41 0
10 4 60 41 0
10 4 59 41 0
10 4 58 41 0
10 4 57 41 0
10 4 56 41 0
10 4 55 41 0
10 4 54 35 64
10 4 51 35 32
10 4 50 41 0
10 4 49 41 0
10 4 48 41 0
10 4 47 41 0
10 4 46 41 0
10 4 45 41 0
10 4 44 41 0
10 4 43 41 0
10 4 42 41 0
10 4 41 41 0
10 4 40 41 0
10 4 39 41 0
10 4 38 41 0
10 4 37 41 0
10 4 36 41 0
10 4 35 41 0
10 4 34 41 0
10 4 33 41 0
10 4 32 41 0
10 4 31 41 0
10 4 30 41 0
10 4 29 41 0
10 4 28 41 0
10 4 27 41 0
10 4 26 41 0
10 4 25 41 0
10 4 24 41 0
10 4 23 41 0
10 4 22 41 0
10 4 21 41 0
10 4 20 41 0
10 4 19 41 0
10 4 18 41 0
10 4 17 41 0
10 4 16 41 0
10 4 15 41 0
10 4 14 41 0
10 4 13 41 0
10 4 12 41 0
10 4 11 41 0
10 4 10 41 0
10 4 9 41 0
10 4 8 41 0
10 4 7 41 0
10 4 6 41 0
10 4 5 41 0
10 4 4 35 64
10 5 101 35 32
10 5 100 41 0
10 5 99 41 0
10 5 98 41 0
10 5 97 41 0
10 5 96 41 0
10 5 95 41 0
10 5 94 41 0
10 5 93 41 0
10 5 92 41 0
10 5 91 41 0
10 5 90 41 0
10 5 89 41 0
10 5 88 41 0
10 5 87 41 0
10 5 86 41 0
10 5 85 41 0
10 5 84 41 0
10 5 83 41 0
10 5 82 41 0
10 5 81 41 0
10 5 80 41 0
10 5 79 41 0
10 5 78 41 0
10 5 77 41 0
10 5 76 41 0
10 5 75 41 0
10 5 74 41 0
10 5 73 41 0
10 5 72 41 0
10 5 71 41 0
10 5 70 41 0
10 5 69 41 0
10 5 68 41 0
10 5 67 41 0
10 5 66 41 0
10 5 65 41 0
10 5 64 41 0
10 5 63 41 0
10 5 62 41 0
10 5 61 41 0
10 5 60 41 0
10 5 59 41 0
10 5 58 41 0
10 5 57 41 0
10 5 56 41 0
10 5 55 41 0
10 5 54 35 64
10 5 51 35 32
10 5 50 41 0
10 5 49 41 0
10 5 48 41 0
10 5 47 41 0
10 5 46 41 0
10 5 45 41 0
10 5 44 41 0
10 5 43 41 0
10 5 42 41 0
10 5 41 41 0
10 5 40 41 0
10 5 39 41 0
10 5 38 41 0
10 5 37 41 0
10 5 36 41 0
10 5 35 41 0
10 5 34 41 0
10 5 33 41 0
10 5 32 41 0
10 5 31 41 0
10 5 30 41 0
10 5 29 41 0
10 5 28 41 0
10 5 27 41 0
10 5 26 41 0
10 5 25 41 0
10 5 24 41 0
10 5 23 41 0
10 5 22 41 0
10 5 21 41 0
10 5 20 41 0
10 5 19 41 0
10 5 18 41 0
10 5 17 41 0
10 5 16 41 0
10 5 15 41 0
10 5 14 41 0
10 5 13 41 0
10 5 12 41 0
10 5 11 41 0
10 5 10 41 0
10 5 9 41 0
10 5 8 41 0
10 5 7 41 0
10 5 6 41 0
10 5 5 41 0
10 5 4 35 64
10 6 101 35 32
10 6 100 41 0
10 6 99 41 0
10 6 98 41 0
10 6 97 41 0
10 6 96 41 0
10 6 95 41 0
10 6 94 41 0
10 6 93 41 0
10 6 92 41 0
10 6 91 41 0
10 6 90 41 0
10 6 89 41 0
10 6 88 41 0
10 6 87 41 0
10 6 86 41 0
10 6 85 41 0
10 6 84 41 0
10 6 83 41 0
10 6 82 41 0
10 6 81 41 0
10 6 80 41 0
10 6 79 41 0
10 6 78 41 0
10 6 77 41 0
10 6 76 41 0
10 6 75 41 0
10 6 74 41 0
10 6 73 41 0
10 6 72 41 0
10 6 71 41 0
10 6 70 41 0
10 6 69 41 0
10 6 68 41 0
10 6 67 41 0
10 6 66 41 0
10 6 65 41 0
10 6 64 41 0
10 6 63 41 0
10 6 62 41 0
10 6 61 41 0
10 6 60 41 0
10 6 59 41 0
10 6 58 41 0
10 6 57 41 0
10 6 56 41 0
10 6 55 41 0
10 6 54 35 64
10 6 51 35 32
10 6 50 41 0
10 6 49 41 0
10 6 48 41 0
10 6 47 41 0
10 6 46 41 0
10 6 45 41 0
10 6 44 41 0
10 6 43 41 0
10 6 42 41 0
10 6 41 41 0
10 6 40 41 0
10 6 39 41 0
10 6 38 41 0
10 6 37 41 0
10 6 36 41 0
10 6 35 41 0
10 6 34 41 0
10 6 33 41 0
10 6 32 41 0
10 6 31 41 0
10 6 30 41 0
10 6 29 41 0
10 6 28 41 0
10 6 27 41 0
10 6 26 41 0
10 6 25 41 0
10 6 24 41 0
10 6 23 41 0
10 6 22 41 0
10 6 21 41 0
10 6 20 41 0
10 6 19 41 0
10 6 18 41 0
10 6 17 41 0
10 6 16 41 0
10 6 15 41 0
10 6 14 41 0
10 6 13 41 0
10 6 12 41 0
10 6 11 41 0
10 6 10 41 0
10 6 9 41 0
10 6 8 41 0
10 6 7 41 0
10 6 6 41 0
10 6 5 41 0
10 6 4 35 64
10 7 101 35 32
10 7 100 41 0
10 7 99 41 0
10 7 98 41 0
10 7 97 41 0
10 7 96 41 0
