Qubicle Exchange Format
Version 0.2
www.minddesk.com
186 74 107
90
0.015686 0.011765 0.000000
0.078431 0.513725 0.776471
0.121569 0.125490 0.125490
0.168627 0.447059 0.619608
0.188235 0.192157 0.196078
0.227451 0.164706 0.070588
0.227451 0.227451 0.227451
0.227451 0.415686 0.737255
0.239216 0.505882 0.749020
0.250980 0.403922 0.666667
0.258824 0.478431 0.678431
0.266667 0.156863 0.000000
0.286275 0.286275 0.286275
0.290196 0.298039 0.301961
0.294118 0.341176 0.388235
0.298039 0.211765 0.086275
0.301961 0.317647 0.427451
0.309804 0.458824 0.709804
0.313725 0.321569 0.321569
0.317647 0.490196 0.784314
0.329412 0.345098 0.458824
0.341176 0.227451 0.000000
0.345098 0.462745 0.670588
0.345098 0.486275 0.619608
0.356863 0.254902 0.113725
0.368627 0.270588 0.070588
0.376471 0.384314 0.392157
0.380392 0.482353 0.654902
0.419608 0.431373 0.431373
0.435294 0.568627 0.690196
0.458824 0.368627 0.027451
0.458824 0.690196 0.027451
0.478431 0.623529 0.690196
0.486275 0.309804 0.054902
0.505882 0.560784 0.611765
0.513725 0.411765 0.031373
0.521569 0.521569 0.521569
0.521569 0.729412 0.137255
0.525490 0.509804 0.450980
0.541176 0.776471 0.098039
0.552941 0.564706 0.572549
0.552941 0.811765 0.070588
0.560784 0.709804 0.780392
0.580392 0.745098 0.270588
0.611765 0.686275 0.752941
0.611765 0.690196 0.729412
0.619608 0.631373 0.705882
0.635294 0.647059 0.650980
0.670588 0.682353 0.756863
0.678431 0.635294 0.439216
0.682353 0.466667 0.019608
0.701961 0.690196 0.674510
0.749020 0.549020 0.141176
0.772549 0.831373 0.662745
0.776471 0.435294 0.623529
0.776471 0.913725 1.000000
0.780392 0.709804 0.039216
0.780392 0.745098 0.427451
0.796078 0.803922 0.807843
0.819608 0.501961 0.050980
0.819608 0.784314 0.454902
0.823529 0.917647 0.996078
0.827451 0.623529 0.337255
0.831373 0.729412 0.568627
0.835294 0.200000 0.309804
0.839216 0.917647 0.686275
0.843137 0.937255 1.000000
0.847059 0.764706 0.023529
0.894118 0.200000 0.203922
0.898039 0.847059 0.556863
0.905882 0.956863 1.000000
0.929412 0.925490 0.925490
0.949020 0.854902 0.000000
0.960784 0.533333 0.086275
0.960784 0.831373 0.090196
0.980392 0.827451 0.784314
0.984314 0.858824 0.823529
0.984314 0.937255 0.850980
0.988235 0.811765 0.760784
0.988235 0.858824 0.823529
1.000000 0.568627 0.003922
1.000000 0.619608 0.003922
1.000000 0.670588 0.003922
1.000000 0.701961 0.003922
1.000000 0.737255 0.003922
1.000000 0.784314 0.003922
1.000000 0.792157 0.219608
1.000000 0.850980 0.003922
1.000000 0.905882 0.003922
1.000000 1.000000 1.000000
1 14 102 52 52
1 14 101 52 28
1 14 100 52 28
1 14 99 52 28
1 14 98 52 28
1 14 97 52 28
1 14 96 52 28
1 14 95 52 28
1 14 94 52 28
1 14 93 52 28
1 14 92 52 28
1 14 91 52 28
1 14 90 52 28
1 14 89 52 28
1 14 88 52 28
1 14 87 52 28
1 14 86 52 28
1 14 85 52 28
1 14 84 52 28
1 14 83 52 28
1 14 82 52 28
1 14 81 52 28
1 14 80 52 28
1 14 79 52 28
1 14 78 52 28
1 14 77 52 28
1 14 76 52 28
1 14 75 52 28
1 14 74 52 28
1 14 73 52 28
1 14 72 52 28
1 14 71 52 28
1 14 70 52 28
1 14 69 52 28
1 14 68 52 28
1 14 67 52 28
1 14 66 52 28
1 14 65 52 28
1 14 64 52 84
1 15 102 52 100
1 15 64 52 100
1 16 102 52 100
1 16 64 52 100
1 17 102 52 100
1 17 64 52 100
1 18 102 52 100
1 18 64 52 100
1 19 102 52 100
1 19 64 52 100
1 20 102 52 44
1 20 101 52 28
1 20 100 52 28
1 20 99 52 28
1 20 98 52 28
1 20 97 52 28
1 20 96 52 28
1 20 95 52 28
1 20 94 52 28
1 20 93 52 28
1 20 92 52 28
1 20 91 52 28
1 20 90 52 28
1 20 89 52 28
1 20 88 52 28
1 20 87 52 28
1 20 86 52 28
1 20 85 52 28
1 20 84 52 28
1 20 83 52 28
1 20 82 52 28
1 20 81 52 28
1 20 80 52 28
1 20 79 52 28
1 20 78 52 28
1 20 77 52 28
1 20 76 52 28
1 20 75 52 28
1 20 74 52 28
1 20 73 52 28
1 20 72 52 28
1 20 71 52 28
1 20 70 52 28
1 20 69 52 28
1 20 68 52 28
1 20 67 52 28
1 20 66 52 28
1 20 65 52 28
1 20 64 52 76
2 13 104 50 52
2 13 103 50 20
2 13 102 50 20
2 13 101 50 20
2 13 100 50 20
2 13 99 50 20
2 13 98 50 20
2 13 97 50 20
2 13 96 50 20
2 13 95 50 20
2 13 94 50 20
2 13 93 50 20
2 13 92 50 20
2 13 91 50 20
2 13 90 50 20
2 13 89 50 20
2 13 88 50 20
2 13 87 50 20
2 13 86 50 20
2 13 85 50 20
2 13 84 50 20
2 13 83 50 20
2 13 82 50 20
2 13 81 50 20
2 13 80 50 20
2 13 79 50 20
2 13 78 50 20
2 13 77 50 20
2 13 76 50 20
2 13 75 50 20
2 13 74 50 20
2 13 73 50 20
2 13 72 50 20
2 13 71 50 20
2 13 70 50 20
2 13 69 50 20
2 13 68 50 20
2 13 67 50 20
2 13 66 50 20
2 13 65 50 20
2 13 64 50 20
2 13 63 50 20
2 13 62 50 84
2 14 104 50 36
2 14 103 50 6
2 14 102 50 2
2 14 101 50 2
2 14 100 50 2
2 14 99 50 2
2 14 98 50 2
2 14 97 50 2
2 14 96 50 2
2 14 95 50 2
2 14 94 50 2
2 14 93 50 2
2 14 92 50 2
2 14 91 50 2
2 14 90 50 2
2 14 89 50 2
2 14 88 50 2
2 14 87 50 2
2 14 86 50 2
2 14 85 50 2
2 14 84 50 2
2 14 83 50 2
2 14 82 50 2
2 14 81 50 2
2 14 80 50 2
2 14 79 50 2
2 14 78 50 2
2 14 77 50 2
2 14 76 50 2
2 14 75 50 2
2 14 74 50 2
2 14 73 50 2
2 14 72 50 2
2 14 71 50 2
2 14 70 50 2
2 14 69 50 2
2 14 68 50 2
2 14 67 50 2
2 14 66 50 2
2 14 65 50 2
2 14 64 50 2
2 14 63 50 6
2 14 62 50 68
2 15 104 50 36
2 15 103 50 6
2 15 102 50 2
2 15 101 50 6
2 15 100 50 6
2 15 99 50 6
2 15 98 50 6
2 15 97 50 6
2 15 96 50 6
2 15 95 50 6
2 15 94 50 6
2 15 93 50 6
2 15 92 50 6
2 15 91 50 6
2 15 90 50 6
2 15 89 50 6
2 15 88 50 6
2 15 87 50 6
2 15 86 50 6
2 15 85 50 6
2 15 84 50 6
2 15 83 50 6
2 15 82 50 6
2 15 81 50 6
2 15 80 50 6
2 15 79 50 6
2 15 78 50 6
2 15 77 50 6
2 15 76 50 6
2 15 75 50 6
2 15 74 50 6
2 15 73 50 6
2 15 72 50 6
2 15 71 50 6
2 15 70 50 6
2 15 69 50 6
2 15 68 50 6
2 15 67 50 6
2 15 66 50 6
2 15 65 50 6
2 15 64 50 2
2 15 63 50 6
2 15 62 50 68
2 16 104 50 36
2 16 103 50 6
2 16 102 50 2
2 16 101 50 6
2 16 100 50 6
2 16 99 50 6
2 16 98 50 6
2 16 97 50 6
2 16 96 50 6
2 16 95 50 6
2 16 94 50 6
2 16 93 50 6
2 16 92 50 6
2 16 91 50 6
2 16 90 50 6
2 16 89 50 6
2 16 88 50 6
2 16 87 50 6
2 16 86 50 6
2 16 85 50 6
2 16 84 50 6
2 16 83 50 6
2 16 82 50 6
2 16 81 50 6
2 16 80 50 6
2 16 79 50 6
2 16 78 50 6
2 16 77 50 6
2 16 76 50 6
2 16 75 50 6
2 16 74 50 6
2 16 73 50 6
2 16 72 50 6
2 16 71 50 6
2 16 70 50 6
2 16 69 50 6
2 16 68 50 6
2 16 67 50 6
2 16 66 50 6
2 16 65 50 6
2 16 64 50 2
2 16 63 50 6
2 16 62 50 68
2 17 104 50 36
2 17 103 50 6
2 17 102 50 2
2 17 101 50 6
2 17 100 50 6
2 17 99 50 6
2 17 98 50 6
2 17 97 50 6
2 17 96 50 6
2 17 95 50 6
2 17 94 50 6
2 17 93 50 6
2 17 92 50 6
2 17 91 50 6
2 17 90 50 6
2 17 89 50 6
2 17 88 50 6
2 17 87 50 6
2 17 86 50 6
2 17 85 50 6
2 17 84 50 6
2 17 83 50 6
2 17 82 50 6
2 17 81 50 6
2 17 80 50 6
2 17 79 50 6
2 17 78 50 6
2 17 77 50 6
2 17 76 50 6
2 17 75 50 6
2 17 74 50 6
2 17 73 50 6
2 17 72 50 6
2 17 71 50 6
2 17 70 50 6
2 17 69 50 6
2 17 68 50 6
2 17 67 50 6
2 17 66 50 6
2 17 65 50 6
2 17 64 50 2
2 17 63 50 6
2 17 62 50 68
2 18 104 50 36
2 18 103 50 6
2 18 102 50 2
2 18 101 50 6
2 18 100 50 6
2 18 99 50 6
2 18 98 50 6
2 18 97 50 6
2 18 96 50 6
2 18 95 50 6
2 18 94 50 6
2 18 93 50 6
2 18 92 50 6
2 18 91 50 6
2 18 90 50 6
2 18 89 50 6
2 18 88 50 6
2 18 87 50 6
2 18 86 50 6
2 18 85 50 6
2 18 84 50 6
2 18 83 50 6
2 18 82 50 6
2 18 81 50 6
2 18 80 50 6
2 18 79 50 6
2 18 78 50 6
2 18 77 50 6
2 18 76 50 6
2 18 75 50 6
2 18 74 50 6
2 18 73 50 6
2 18 72 50 6
2 18 71 50 6
2 18 70 50 6
2 18 69 50 6
2 18 68 50 6
2 18 67 50 6
2 18 66 50 6
2 18 65 50 6
2 18 64 50 2
2 18 63 50 6
2 18 62 50 68
2 19 104 50 36
2 19 103 50 6
2 19 102 50 2
2 19 101 50 6
2 19 100 50 6
2 19 99 50 6
2 19 98 50 6
2 19 97 50 6
2 19 96 50 6
2 19 95 50 6
2 19 94 50 6
2 19 93 50 6
2 19 92 50 6
2 19 91 50 6
2 19 90 50 6
2 19 89 50 6
2 19 88 50 6
2 19 87 50 6
2 19 86 50 6
2 19 85 50 6
2 19 84 50 6
2 19 83 50 6
2 19 82 50 6
2 19 81 50 6
2 19 80 50 6
2 19 79 50 6
2 19 78 50 6
2 19 77 50 6
2 19 76 50 6
2 19 75 50 6
2 19 74 50 6
2 19 73 50 6
2 19 72 50 6
2 19 71 50 6
2 19 70 50 6
2 19 69 50 6
2 19 68 50 6
2 19 67 50 6
2 19 66 50 6
2 19 65 50 6
2 19 64 50 2
2 19 63 50 6
2 19 62 50 68
2 20 104 50 36
2 20 103 50 6
2 20 102 50 2
2 20 101 50 2
2 20 100 50 2
2 20 99 50 2
2 20 98 50 2
2 20 97 50 2
2 20 96 50 2
2 20 95 50 2
2 20 94 50 2
2 20 93 50 2
2 20 92 50 2
2 20 91 50 2
2 20 90 50 2
2 20 89 50 2
2 20 88 50 2
2 20 87 50 2
2 20 86 50 2
2 20 85 50 2
2 20 84 50 2
2 20 83 50 2
2 20 82 50 2
2 20 81 50 2
2 20 80 50 2
2 20 79 50 2
2 20 78 50 2
2 20 77 50 2
2 20 76 50 2
2 20 75 50 2
2 20 74 50 2
2 20 73 50 2
2 20 72 50 2
2 20 71 50 2
2 20 70 50 2
2 20 69 50 2
2 20 68 50 2
2 20 67 50 2
2 20 66 50 2
2 20 65 50 2
2 20 64 50 2
2 20 63 50 6
2 20 62 50 68
2 21 104 50 36
2 21 103 50 6
2 21 102 50 6
2 21 101 50 6
2 21 100 50 6
2 21 99 50 6
2 21 98 50 6
2 21 97 50 6
2 21 96 50 6
2 21 95 50 6
2 21 94 50 6
2 21 93 50 6
2 21 92 50 6
2 21 91 50 6
2 21 90 50 6
2 21 89 50 6
2 21 88 50 6
2 21 87 50 6
2 21 86 50 6
2 21 85 50 6
2 21 84 50 6
2 21 83 50 6
2 21 82 50 6
2 21 81 50 6
2 21 80 50 6
2 21 79 50 6
2 21 78 50 6
2 21 77 50 6
2 21 76 50 6
2 21 75 50 6
2 21 74 50 6
2 21 73 50 6
2 21 72 50 6
2 21 71 50 6
2 21 70 50 6
2 21 69 50 6
2 21 68 50 6
2 21 67 50 6
2 21 66 50 6
2 21 65 50 6
2 21 64 50 6
2 21 63 50 6
2 21 62 50 68
2 22 104 50 44
2 22 103 50 12
2 22 102 50 12
2 22 101 50 12
2 22 100 50 12
2 22 99 50 12
2 22 98 50 12
2 22 97 50 12
2 22 96 50 12
2 22 95 50 12
2 22 94 50 12
2 22 93 50 12
2 22 92 50 12
2 22 91 50 12
2 22 90 50 12
2 22 89 50 12
2 22 88 50 12
2 22 87 50 12
2 22 86 50 12
2 22 85 50 12
2 22 84 50 12
2 22 83 50 12
2 22 82 50 12
2 22 81 50 12
2 22 80 50 12
2 22 79 50 12
2 22 78 50 12
2 22 77 50 12
2 22 76 50 12
2 22 75 50 12
2 22 74 50 12
2 22 73 50 12
2 22 72 50 12
2 22 71 50 12
2 22 70 50 12
2 22 69 50 12
2 22 68 50 12
2 22 67 50 12
2 22 66 50 12
2 22 65 50 12
2 22 64 50 12
2 22 63 50 12
2 22 62 50 76
3 2 103 50 52
3 2 102 50 20
3 2 101 50 20
3 2 100 50 84
3 2 66 50 52
3 2 65 50 20
3 2 64 50 20
3 2 63 50 84
3 3 103 50 36
3 3 102 50 6
3 3 101 50 6
3 3 100 50 68
3 3 66 50 36
3 3 65 50 6
3 3 64 50 6
3 3 63 50 68
3 4 103 50 36
3 4 102 50 6
3 4 101 50 6
3 4 100 50 68
3 4 66 50 36
3 4 65 50 6
3 4 64 50 6
3 4 63 50 68
3 5 103 50 36
3 5 102 50 6
3 5 101 50 6
3 5 100 50 70
3 5 66 50 38
3 5 65 50 6
3 5 64 50 6
3 5 63 50 68
3 6 103 50 36
3 6 102 50 6
3 6 101 50 6
3 6 100 50 70
3 6 66 50 38
3 6 65 50 6
3 6 64 50 6
3 6 63 50 68
3 7 103 50 36
3 7 102 50 6
3 7 101 50 6
3 7 100 50 68
3 7 66 50 36
3 7 65 50 6
3 7 64 50 6
3 7 63 50 68
3 8 103 50 36
3 8 102 50 6
3 8 101 50 6
3 8 100 50 68
3 8 66 50 36
3 8 65 50 6
3 8 64 50 6
3 8 63 50 68
3 9 103 50 36
3 9 102 50 6
3 9 101 50 6
3 9 100 50 68
3 9 66 50 36
3 9 65 50 6
3 9 64 50 6
3 9 63 50 68
3 10 103 50 36
3 10 102 50 6
3 10 101 50 6
3 10 100 50 68
3 10 66 50 36
3 10 65 50 6
3 10 64 50 6
3 10 63 50 68
3 11 103 50 36
3 11 102 50 6
3 11 101 50 6
3 11 100 50 68
3 11 66 50 36
3 11 65 50 6
3 11 64 50 6
3 11 63 50 68
3 12 103 50 36
3 12 102 50 6
3 12 101 50 6
3 12 100 50 68
3 12 66 50 36
3 12 65 50 6
3 12 64 50 6
3 12 63 50 68
3 13 104 50 48
3 13 103 50 8
3 13 102 50 8
3 13 101 50 8
3 13 100 50 8
3 13 99 50 24
3 13 98 50 24
3 13 97 50 24
3 13 96 50 24
3 13 95 50 24
3 13 94 50 24
3 13 93 50 24
3 13 92 50 24
3 13 91 50 24
3 13 90 50 24
3 13 89 50 24
3 13 88 50 24
3 13 87 50 24
3 13 86 50 24
3 13 85 50 24
3 13 84 50 24
3 13 83 50 24
3 13 82 50 24
3 13 81 50 24
3 13 80 50 24
3 13 79 50 24
3 13 78 50 24
3 13 77 50 24
3 13 76 50 24
3 13 75 50 24
3 13 74 50 24
3 13 73 50 24
3 13 72 50 24
3 13 71 50 24
3 13 70 50 24
3 13 69 50 24
3 13 68 50 24
3 13 67 50 24
3 13 66 50 8
3 13 65 50 8
3 13 64 50 8
3 13 63 50 8
3 13 62 50 80
3 14 104 50 96
3 14 62 50 96
3 15 104 50 96
3 15 62 50 96
3 16 104 50 96
3 16 62 50 96
3 17 104 50 96
3 17 62 50 96
3 18 104 50 96
3 18 62 50 96
3 19 104 50 96
3 19 62 50 96
3 20 104 50 96
3 20 62 50 96
3 21 104 50 96
3 21 62 50 96
3 22 104 50 40
3 22 103 50 16
3 22 102 50 16
3 22 101 50 16
3 22 100 50 16
3 22 99 50 16
3 22 98 50 16
3 22 97 50 16
3 22 96 50 16
3 22 95 50 16
3 22 94 50 16
3 22 93 50 16
3 22 92 50 16
3 22 91 50 16
3 22 90 50 16
3 22 89 50 16
3 22 88 50 16
3 22 87 50 16
3 22 86 50 16
3 22 85 50 16
3 22 84 50 16
3 22 83 50 16
3 22 82 50 16
3 22 81 50 16
3 22 80 50 16
3 22 79 50 16
3 22 78 50 16
3 22 77 50 16
3 22 76 50 16
3 22 75 50 16
3 22 74 50 16
3 22 73 50 16
3 22 72 50 16
3 22 71 50 16
3 22 70 50 16
3 22 69 50 16
3 22 68 50 16
3 22 67 50 16
3 22 66 50 16
3 22 65 50 16
3 22 64 50 16
3 22 63 50 16
3 22 62 50 72
3 23 103 62 36
3 23 102 62 4
3 23 101 62 4
3 23 100 62 4
3 23 99 62 6
3 23 98 62 4
3 23 97 62 4
3 23 96 62 4
3 23 95 62 6
3 23 94 62 4
3 23 93 62 6
3 23 92 62 4
3 23 91 62 4
3 23 90 62 4
3 23 89 62 4
3 23 88 62 6
3 23 87 62 4
3 23 86 62 4
3 23 85 62 4
3 23 84 62 6
3 23 83 62 4
3 23 82 62 6
3 23 81 62 4
3 23 80 62 6
3 23 79 62 4
3 23 78 62 6
3 23 77 62 4
3 23 76 62 4
3 23 75 62 4
3 23 74 62 6
3 23 73 62 4
3 23 72 62 4
3 23 71 62 4
3 23 70 62 6
3 23 69 62 4
3 23 68 62 6
3 23 67 62 4
3 23 66 62 6
3 23 65 62 4
3 23 64 62 6
3 23 63 62 68
3 24 103 62 36
3 24 102 62 6
3 24 101 62 6
3 24 100 62 6
3 24 99 62 6
3 24 98 62 6
3 24 97 62 6
3 24 96 62 4
3 24 95 62 6
3 24 94 62 6
3 24 93 62 6
3 24 92 62 6
3 24 91 62 6
3 24 90 62 6
3 24 89 62 6
3 24 88 62 6
3 24 87 62 6
3 24 86 62 6
3 24 85 62 4
3 24 84 62 6
3 24 83 62 6
3 24 82 62 6
3 24 81 62 6
3 24 80 62 6
3 24 79 62 6
3 24 78 62 6
3 24 77 62 6
3 24 76 62 6
3 24 75 62 6
3 24 74 62 6
3 24 73 62 6
3 24 72 62 6
3 24 71 62 4
3 24 70 62 6
3 24 69 62 6
3 24 68 62 6
3 24 67 62 6
3 24 66 62 6
3 24 65 62 6
3 24 64 62 6
3 24 63 62 68
3 25 103 62 36
3 25 102 62 6
3 25 101 62 6
3 25 100 62 6
3 25 99 62 6
3 25 98 62 6
3 25 97 62 6
3 25 96 62 6
3 25 95 62 6
3 25 94 62 6
3 25 93 62 6
3 25 92 62 6
3 25 91 62 6
3 25 90 62 6
3 25 89 62 6
3 25 88 62 6
3 25 87 62 6
3 25 86 62 6
3 25 85 62 6
3 25 84 62 6
3 25 83 62 6
3 25 82 62 6
3 25 81 62 6
3 25 80 62 6
3 25 79 62 6
3 25 78 62 6
3 25 77 62 6
3 25 76 62 6
3 25 75 62 6
3 25 74 62 6
3 25 73 62 6
3 25 72 62 6
3 25 71 62 6
3 25 70 62 6
3 25 69 62 6
3 25 68 62 6
3 25 67 62 6
3 25 66 62 6
3 25 65 62 6
3 25 64 62 6
3 25 63 62 68
3 26 103 62 44
3 26 102 62 14
3 26 101 62 14
3 26 100 62 14
3 26 99 62 14
3 26 98 62 14
3 26 97 62 14
3 26 96 62 14
3 26 95 62 14
3 26 94 62 14
3 26 93 62 14
3 26 92 62 14
3 26 91 62 14
3 26 90 62 14
3 26 89 62 14
3 26 88 62 14
3 26 87 62 14
3 26 86 62 14
3 26 85 62 14
3 26 84 62 14
3 26 83 62 14
3 26 82 62 14
3 26 81 62 14
3 26 80 62 14
3 26 79 62 14
3 26 78 62 14
3 26 77 62 14
3 26 76 62 14
3 26 75 62 14
3 26 74 62 14
3 26 73 62 14
3 26 72 62 14
3 26 71 62 14
3 26 70 62 14
3 26 69 62 14
3 26 68 62 14
3 26 67 62 14
3 26 66 62 14
3 26 65 62 14
3 26 64 62 14
3 26 63 62 76
4 2 103 50 48
4 2 102 50 24
4 2 101 50 24
4 2 100 50 80
4 2 66 50 48
4 2 65 50 24
4 2 64 50 24
4 2 63 50 80
4 3 103 50 96
4 3 100 50 96
4 3 66 50 96
4 3 63 50 96
4 4 103 50 96
4 4 100 50 104
4 4 66 50 104
4 4 63 50 96
4 5 103 50 96
4 5 99 33 54
4 5 98 33 22
4 5 97 33 22
4 5 96 33 22
4 5 95 33 22
4 5 94 33 22
4 5 93 33 22
4 5 92 33 22
4 5 91 33 22
4 5 90 33 22
4 5 89 33 22
4 5 88 33 22
4 5 87 33 22
4 5 86 33 22
4 5 85 33 22
4 5 84 33 22
4 5 83 33 22
4 5 82 33 22
4 5 81 33 22
4 5 80 33 22
4 5 79 33 22
4 5 78 33 22
4 5 77 33 22
4 5 76 33 22
4 5 75 33 22
4 5 74 33 22
4 5 73 33 22
4 5 72 33 22
4 5 71 33 22
4 5 70 33 22
4 5 69 33 22
4 5 68 33 22
4 5 67 33 86
4 5 63 50 96
4 6 103 50 96
4 6 99 33 46
4 6 98 33 14
4 6 97 33 14
4 6 96 33 14
4 6 95 33 14
4 6 94 33 14
4 6 93 33 14
4 6 92 33 14
4 6 91 33 14
4 6 90 33 14
4 6 89 33 14
4 6 88 33 14
4 6 87 33 14
4 6 86 33 14
4 6 85 33 14
4 6 84 33 14
4 6 83 33 14
4 6 82 33 14
4 6 81 33 14
4 6 80 33 14
4 6 79 33 14
4 6 78 33 14
4 6 77 33 14
4 6 76 33 14
4 6 75 33 14
4 6 74 33 14
4 6 73 33 14
4 6 72 33 14
4 6 71 33 14
4 6 70 33 14
4 6 69 33 14
4 6 68 33 14
4 6 67 33 78
4 6 63 50 96
4 7 103 50 96
4 7 100 50 112
4 7 66 50 112
4 7 63 50 96
4 8 103 50 96
4 8 100 50 96
4 8 66 50 96
4 8 63 50 96
4 9 103 50 96
4 9 100 50 96
4 9 66 50 96
4 9 63 50 96
4 10 103 50 96
4 10 100 50 96
4 10 66 50 96
4 10 63 50 96
4 11 103 50 96
4 11 100 50 96
4 11 66 50 96
4 11 63 50 96
4 12 103 50 96
4 12 100 50 96
4 12 66 50 96
4 12 63 50 96
4 13 104 50 48
4 13 103 50 8
4 13 102 50 24
4 13 101 50 24
4 13 100 50 8
4 13 99 50 24
4 13 98 50 24
4 13 97 50 24
4 13 96 50 24
4 13 95 50 24
4 13 94 50 24
4 13 93 50 24
4 13 92 50 24
4 13 91 50 24
4 13 90 50 24
4 13 89 50 24
4 13 88 50 24
4 13 87 50 24
4 13 86 50 24
4 13 85 50 24
4 13 84 50 24
4 13 83 50 24
4 13 82 50 24
4 13 81 50 24
4 13 80 50 24
4 13 79 50 24
4 13 78 50 24
4 13 77 50 24
4 13 76 50 24
4 13 75 50 24
4 13 74 50 24
4 13 73 50 24
4 13 72 50 24
4 13 71 50 24
4 13 70 50 24
4 13 69 50 24
4 13 68 50 24
4 13 67 50 24
4 13 66 50 8
4 13 65 50 24
4 13 64 50 24
4 13 63 50 8
4 13 62 50 80
4 14 105 52 52
4 14 104 50 64
4 14 62 50 32
4 14 61 52 84
4 15 105 52 38
4 15 104 50 64
4 15 62 50 32
4 15 61 52 70
4 16 105 52 38
4 16 104 50 64
4 16 62 50 32
4 16 61 52 70
4 17 105 52 38
4 17 104 50 64
4 17 62 50 32
4 17 61 52 70
4 18 105 52 38
4 18 104 50 64
4 18 62 50 32
4 18 61 52 70
4 19 105 52 38
4 19 104 50 64
4 19 62 50 32
4 19 61 52 70
4 20 105 52 44
4 20 104 50 64
4 20 62 50 32
4 20 61 52 76
4 21 104 50 96
4 21 62 50 96
4 22 104 50 40
4 22 103 50 16
4 22 102 50 16
4 22 101 50 16
4 22 100 50 16
4 22 99 50 24
4 22 98 50 16
4 22 97 50 16
4 22 96 50 16
4 22 95 50 24
4 22 94 50 16
4 22 93 50 24
4 22 92 50 16
4 22 91 50 16
4 22 90 50 16
4 22 89 50 16
4 22 88 50 24
4 22 87 50 16
4 22 86 50 16
4 22 85 50 16
4 22 84 50 24
4 22 83 50 16
4 22 82 50 24
4 22 81 50 16
4 22 80 50 24
4 22 79 50 16
4 22 78 50 24
4 22 77 50 16
4 22 76 50 16
4 22 75 50 16
4 22 74 50 24
4 22 73 50 16
4 22 72 50 16
4 22 71 50 16
4 22 70 50 24
4 22 69 50 16
4 22 68 50 24
4 22 67 50 16
4 22 66 50 24
4 22 65 50 16
4 22 64 50 24
4 22 63 50 16
4 22 62 50 72
4 23 103 62 32
4 23 102 89 10
4 23 101 61 8
4 23 100 61 74
4 23 98 89 42
4 23 97 89 10
4 23 96 89 66
4 23 94 89 106
4 23 92 61 42
4 23 91 89 8
4 23 90 61 8
4 23 89 61 72
4 23 87 89 42
4 23 86 89 10
4 23 85 89 66
4 23 83 89 106
4 23 81 61 106
4 23 79 61 106
4 23 77 89 42
4 23 76 61 8
4 23 75 61 74
4 23 73 89 42
4 23 72 89 10
4 23 71 89 66
4 23 69 89 106
4 23 67 61 106
4 23 65 61 106
4 23 63 62 96
4 24 103 62 96
4 24 96 61 106
4 24 85 61 106
4 24 71 61 106
4 24 63 62 96
4 25 103 62 96
4 25 63 62 96
4 26 103 62 104
4 26 63 62 104
5 2 103 50 50
5 2 102 50 18
5 2 101 50 18
5 2 100 50 82
5 2 66 50 50
5 2 65 50 18
5 2 64 50 18
5 2 63 50 82
5 3 103 50 34
5 3 102 50 6
5 3 101 50 6
5 3 100 50 66
5 3 66 50 34
5 3 65 50 6
5 3 64 50 6
5 3 63 50 66
5 4 103 50 34
5 4 102 50 14
5 4 101 50 14
5 4 100 50 66
5 4 66 50 34
5 4 65 50 14
5 4 64 50 14
5 4 63 50 66
5 5 103 50 98
5 5 100 50 102
5 5 66 50 102
5 5 63 50 98
5 6 103 50 98
5 6 100 50 102
5 6 66 50 102
5 6 63 50 98
5 7 103 50 34
5 7 102 50 22
5 7 101 50 22
5 7 100 50 66
5 7 66 50 34
5 7 65 50 22
5 7 64 50 22
5 7 63 50 66
5 8 103 50 34
5 8 102 50 6
5 8 101 50 6
5 8 100 50 66
5 8 66 50 34
5 8 65 50 6
5 8 64 50 6
5 8 63 50 66
5 9 103 50 34
5 9 102 50 6
5 9 101 50 6
5 9 100 50 66
5 9 66 50 34
5 9 65 50 6
5 9 64 50 6
5 9 63 50 66
5 10 103 50 34
5 10 102 50 6
5 10 101 50 6
5 10 100 50 66
5 10 66 50 34
5 10 65 50 6
5 10 64 50 6
5 10 63 50 66
5 11 103 50 34
5 11 102 50 6
5 11 101 50 6
5 11 100 50 66
5 11 66 50 34
5 11 65 50 6
5 11 64 50 6
5 11 63 50 66
5 12 103 50 34
5 12 102 50 6
5 12 101 50 6
5 12 100 50 66
5 12 66 50 34
5 12 65 50 6
5 12 64 50 6
5 12 63 50 66
5 13 104 50 48
5 13 103 50 8
5 13 102 50 8
5 13 101 50 8
5 13 100 50 8
5 13 99 50 24
5 13 98 50 24
5 13 97 50 24
5 13 96 50 24
5 13 95 50 24
5 13 94 50 24
5 13 93 50 24
5 13 92 50 24
5 13 91 50 24
5 13 90 50 24
5 13 89 50 24
5 13 88 50 24
5 13 87 50 24
5 13 86 50 24
5 13 85 50 24
5 13 84 50 24
5 13 83 50 24
5 13 82 50 24
5 13 81 50 24
5 13 80 50 24
5 13 79 50 24
5 13 78 50 24
5 13 77 50 24
5 13 76 50 24
5 13 75 50 24
5 13 74 50 24
5 13 73 50 24
5 13 72 50 24
5 13 71 50 24
5 13 70 50 24
5 13 69 50 24
5 13 68 50 24
5 13 67 50 24
5 13 66 50 8
5 13 65 50 8
5 13 64 50 8
5 13 63 50 8
5 13 62 50 80
5 14 105 52 56
5 14 104 50 64
5 14 62 50 32
5 14 61 52 88
5 15 104 50 96
5 15 62 50 96
5 16 104 50 96
5 16 62 50 96
5 17 104 50 96
5 17 62 50 96
5 18 104 50 96
5 18 62 50 96
5 19 104 50 96
5 19 62 50 96
5 20 105 52 56
5 20 104 50 64
5 20 62 50 32
5 20 61 52 88
5 21 104 50 96
5 21 62 50 96
5 22 104 50 40
5 22 103 50 16
5 22 102 50 24
5 22 101 50 16
5 22 100 50 24
5 22 99 50 16
5 22 98 50 24
5 22 97 50 24
5 22 96 50 24
5 22 95 50 16
5 22 94 50 24
5 22 93 50 16
5 22 92 50 24
5 22 91 50 16
5 22 90 50 16
5 22 89 50 16
5 22 88 50 16
5 22 87 50 24
5 22 86 50 24
5 22 85 50 24
5 22 84 50 16
5 22 83 50 24
5 22 82 50 16
5 22 81 50 24
5 22 80 50 16
5 22 79 50 24
5 22 78 50 16
5 22 77 50 24
5 22 76 50 16
5 22 75 50 24
5 22 74 50 16
5 22 73 50 24
5 22 72 50 24
5 22 71 50 24
5 22 70 50 16
5 22 69 50 24
5 22 68 50 16
5 22 67 50 24
5 22 66 50 16
5 22 65 50 24
5 22 64 50 16
5 22 63 50 16
5 22 62 50 72
5 23 103 62 96
5 23 101 61 104
5 23 99 89 108
5 23 95 89 108
5 23 93 89 108
5 23 91 61 32
5 23 90 61 10
5 23 89 61 8
5 23 88 89 78
5 23 84 89 110
5 23 82 89 108
5 23 80 61 100
5 23 78 61 110
5 23 76 61 104
5 23 74 89 110
5 23 70 89 108
5 23 68 89 110
5 23 66 61 102
5 23 64 61 46
5 23 63 62 64
5 24 103 62 96
5 24 91 89 110
5 24 80 89 110
5 24 66 89 110
5 24 63 62 96
5 25 103 62 96
5 25 63 62 96
5 26 103 62 104
5 26 63 62 104
6 5 102 33 52
6 5 101 33 84
6 5 65 33 52
6 5 64 33 84
6 6 102 33 44
6 6 101 33 76
6 6 65 33 44
6 6 64 33 76
6 13 104 50 48
6 13 103 50 24
6 13 102 50 24
6 13 101 50 24
6 13 100 50 24
6 13 99 50 24
6 13 98 50 24
6 13 97 50 24
6 13 96 50 24
6 13 95 50 24
6 13 94 50 24
6 13 93 50 24
6 13 92 50 24
6 13 91 50 24
6 13 90 50 24
6 13 89 50 24
6 13 88 50 24
6 13 87 50 24
6 13 86 50 24
6 13 85 50 24
6 13 84 50 24
6 13 83 50 24
6 13 82 50 24
6 13 81 50 24
6 13 80 50 24
6 13 79 50 24
6 13 78 50 24
6 13 77 50 24
6 13 76 50 24
6 13 75 50 24
6 13 74 50 24
6 13 73 50 24
6 13 72 50 24
6 13 71 50 24
6 13 70 50 24
6 13 69 50 24
6 13 68 50 24
6 13 67 50 24
6 13 66 50 24
6 13 65 50 24
6 13 64 50 24
6 13 63 50 24
6 13 62 50 80
6 14 105 52 56
6 14 104 50 64
6 14 62 50 32
6 14 61 52 88
6 15 104 50 96
6 15 62 50 96
6 16 104 50 96
6 16 62 50 96
6 17 104 50 96
6 17 62 50 96
6 18 104 50 96
6 18 62 50 96
6 19 104 50 96
6 19 62 50 96
6 20 105 52 56
6 20 104 50 64
6 20 62 50 32
6 20 61 52 88
6 21 104 50 96
6 21 62 50 96
6 22 104 50 40
6 22 103 50 16
6 22 102 50 24
6 22 101 50 16
6 22 100 50 24
6 22 99 50 16
6 22 98 50 24
6 22 97 50 16
6 22 96 50 24
6 22 95 50 16
6 22 94 50 24
6 22 93 50 16
6 22 92 50 24
6 22 91 50 16
6 22 90 50 24
6 22 89 50 16
6 22 88 50 24
6 22 87 50 16
6 22 86 50 24
6 22 85 50 16
6 22 84 50 24
6 22 83 50 16
6 22 82 50 16
6 22 81 50 24
6 22 80 50 16
6 22 79 50 16
6 22 78 50 24
6 22 77 50 16
6 22 76 50 16
6 22 75 50 16
6 22 74 50 24
6 22 73 50 16
6 22 72 50 16
6 22 71 50 16
6 22 70 50 16
6 22 69 50 16
6 22 68 50 24
6 22 67 50 16
6 22 66 50 24
6 22 65 50 16
6 22 64 50 24
6 22 63 50 16
6 22 62 50 72
6 23 103 62 96
6 23 101 89 104
6 23 99 61 106
6 23 97 89 108
6 23 95 61 106
6 23 93 61 106
6 23 91 70 106
6 23 89 89 106
6 23 87 61 110
6 23 85 61 110
6 23 83 89 46
6 23 82 89 72
6 23 80 89 42
6 23 79 89 76
6 23 77 89 44
6 23 76 61 8
6 23 75 61 68
6 23 73 89 44
6 23 72 89 6
6 23 71 89 14
6 23 70 89 8
6 23 69 61 78
6 23 67 89 108
6 23 65 61 110
6 23 63 62 96
6 24 103 62 96
6 24 75 61 110
6 24 72 89 110
6 24 63 62 96
6 25 103 62 96
6 25 91 23 52
6 25 90 23 86
6 25 63 62 96
6 26 103 62 104
6 26 91 23 36
6 26 90 23 6
6 26 89 23 22
6 26 88 23 86
6 26 63 62 104
6 27 91 23 36
6 27 90 23 6
6 27 89 23 6
6 27 88 29 78
6 28 91 29 44
6 28 90 29 14
6 28 89 29 78
7 5 102 33 48
7 5 101 33 80
7 5 65 33 48
7 5 64 33 80
7 6 102 33 40
7 6 101 33 72
7 6 65 33 40
7 6 64 33 72
7 13 104 50 48
7 13 103 50 24
7 13 102 50 24
7 13 101 50 24
7 13 100 50 24
7 13 99 50 24
7 13 98 50 24
7 13 97 50 24
7 13 96 50 24
7 13 95 50 24
7 13 94 50 24
7 13 93 50 24
7 13 92 50 24
7 13 91 50 24
7 13 90 50 24
7 13 89 50 24
7 13 88 50 24
7 13 87 50 24
7 13 86 50 24
7 13 85 50 24
7 13 84 50 24
7 13 83 50 24
7 13 82 50 24
7 13 81 50 24
7 13 80 50 24
7 13 79 50 24
7 13 78 50 24
7 13 77 50 24
7 13 76 50 24
7 13 75 50 24
7 13 74 50 24
7 13 73 50 24
7 13 72 50 24
7 13 71 50 24
7 13 70 50 24
7 13 69 50 24
7 13 68 50 24
7 13 67 50 24
7 13 66 50 24
7 13 65 50 24
7 13 64 50 24
7 13 63 50 24
7 13 62 50 80
7 14 105 52 56
7 14 104 50 64
7 14 62 50 32
7 14 61 52 88
7 15 104 50 96
7 15 62 50 96
7 16 104 50 96
7 16 62 50 96
7 17 104 50 96
7 17 62 50 96
7 18 104 50 96
7 18 62 50 96
7 19 104 50 96
7 19 62 50 96
7 20 105 52 56
7 20 104 50 64
7 20 62 50 32
7 20 61 52 88
7 21 104 50 96
7 21 62 50 96
7 22 104 50 40
7 22 103 50 16
7 22 102 50 16
7 22 101 50 16
7 22 100 50 16
7 22 99 50 24
7 22 98 50 16
7 22 97 50 16
7 22 96 50 16
7 22 95 50 24
7 22 94 50 16
7 22 93 50 24
7 22 92 50 16
7 22 91 50 24
7 22 90 50 16
7 22 89 50 24
7 22 88 50 16
7 22 87 50 24
7 22 86 50 16
7 22 85 50 24
7 22 84 50 16
7 22 83 50 24
7 22 82 50 16
7 22 81 50 16
7 22 80 50 24
7 22 79 50 16
7 22 78 50 24
7 22 77 50 16
7 22 76 50 16
7 22 75 50 16
7 22 74 50 16
7 22 73 50 16
7 22 72 50 24
7 22 71 50 24
7 22 70 50 16
7 22 69 50 24
7 22 68 50 16
7 22 67 50 16
7 22 66 50 24
7 22 65 50 24
7 22 64 50 16
7 22 63 50 16
7 22 62 50 72
7 23 103 62 32
7 23 102 61 14
7 23 101 61 8
7 23 100 61 78
7 23 98 61 46
7 23 97 61 8
7 23 96 61 78
7 23 94 61 108
7 23 92 89 100
7 23 90 61 108
7 23 88 89 108
7 23 86 89 108
7 23 84 61 108
7 23 82 61 40
7 23 81 61 68
7 23 79 89 104
7 23 77 89 40
7 23 76 89 8
7 23 75 61 8
7 23 74 89 12
7 23 73 89 72
7 23 70 61 104
7 23 68 61 44
7 23 67 61 74
7 23 64 61 46
7 23 63 62 64
7 24 103 62 96
7 24 92 61 100
7 24 81 61 110
7 24 63 62 96
7 25 103 62 96
7 25 93 23 54
7 25 92 23 6
7 25 91 23 82
7 25 63 62 96
7 26 103 62 104
7 26 94 23 54
7 26 93 23 6
7 26 92 23 6
7 26 91 23 66
7 26 63 62 104
7 27 94 29 46
7 27 93 23 6
7 27 92 23 6
7 27 91 23 66
7 28 93 29 46
7 28 92 29 14
7 28 91 29 74
8 5 102 33 48
8 5 101 33 80
8 5 65 33 48
8 5 64 33 80
8 6 102 33 40
8 6 101 33 72
8 6 65 33 40
8 6 64 33 72
8 13 104 50 48
8 13 103 50 24
8 13 102 50 24
8 13 101 50 24
8 13 100 50 24
8 13 99 50 24
8 13 98 50 24
8 13 97 50 24
8 13 96 50 24
8 13 95 50 24
8 13 94 50 24
8 13 93 50 24
8 13 92 50 24
8 13 91 50 24
8 13 90 50 24
8 13 89 50 24
8 13 88 50 24
8 13 87 50 24
8 13 86 50 24
8 13 85 50 24
8 13 84 50 24
8 13 83 50 24
8 13 82 50 24
8 13 81 50 24
8 13 80 50 24
8 13 79 50 24
8 13 78 50 24
8 13 77 50 24
8 13 76 50 24
8 13 75 50 24
8 13 74 50 24
8 13 73 50 24
8 13 72 50 24
8 13 71 50 24
8 13 70 50 24
8 13 69 50 24
8 13 68 50 24
8 13 67 50 24
8 13 66 50 24
8 13 65 50 24
8 13 64 50 24
8 13 63 50 24
8 13 62 50 80
8 14 105 52 56
8 14 104 50 64
8 14 62 50 32
8 14 61 52 88
8 15 104 50 96
8 15 62 50 96
8 16 104 50 96
8 16 62 50 96
8 17 104 50 96
8 17 62 50 96
8 18 104 50 96
8 18 62 50 96
8 19 104 50 96
8 19 62 50 96
8 20 105 52 56
8 20 104 50 64
8 20 62 50 32
8 20 61 52 88
8 21 104 50 96
8 21 62 50 96
8 22 104 50 40
8 22 103 50 16
8 22 102 50 24
8 22 101 50 16
8 22 100 50 24
8 22 99 50 16
8 22 98 50 24
8 22 97 50 16
8 22 96 50 24
8 22 95 50 16
8 22 94 50 16
8 22 93 50 16
8 22 92 50 16
8 22 91 50 16
8 22 90 50 16
8 22 89 50 16
8 22 88 50 16
8 22 87 50 16
8 22 86 50 16
8 22 85 50 24
8 22 84 50 16
8 22 83 50 24
8 22 82 50 16
8 22 81 50 16
8 22 80 50 16
8 22 79 50 16
8 22 78 50 24
8 22 77 50 16
8 22 76 50 16
8 22 75 50 16
8 22 74 50 16
8 22 73 50 16
8 22 72 50 24
8 22 71 50 16
8 22 70 50 16
8 22 69 50 24
8 22 68 50 16
8 22 67 50 24
8 22 66 50 16
8 22 65 50 16
8 22 64 50 24
8 22 63 50 16
8 22 62 50 72
8 23 103 62 96
8 23 101 61 106
8 23 99 61 102
8 23 97 61 96
8 23 95 61 36
8 23 94 29 0
8 23 93 29 4
8 23 92 89 2
8 23 91 29 4
8 23 90 89 0
8 23 89 29 6
8 23 88 70 0
8 23 87 89 4
8 23 86 89 64
8 23 84 89 106
8 23 82 61 40
8 23 81 89 8
8 23 80 61 14
8 23 79 61 72
8 23 77 61 42
8 23 76 61 8
8 23 75 61 10
8 23 74 89 8
8 23 73 61 72
8 23 71 89 46
8 23 70 61 74
8 23 68 89 106
8 23 66 89 46
8 23 65 89 70
8 23 63 62 96
8 24 103 62 96
8 24 99 89 110
8 24 97 29 38
8 24 96 29 22
8 24 95 89 6
8 24 94 29 6
8 24 93 29 14
8 24 92 29 10
8 24 91 29 14
8 24 90 29 6
8 24 89 29 6
8 24 88 29 4
8 24 87 29 6
8 24 86 29 68
8 24 65 61 110
8 24 63 62 96
8 25 103 62 96
8 25 98 29 52
8 25 97 29 6
8 25 96 29 6
8 25 95 29 6
8 25 94 29 78
8 25 90 23 38
8 25 89 29 6
8 25 88 29 6
8 25 87 29 6
8 25 86 29 70
8 25 63 62 96
8 26 103 62 104
8 26 98 23 46
8 26 97 23 6
8 26 96 23 6
8 26 95 23 70
8 26 90 23 38
8 26 89 23 6
8 26 88 23 6
8 26 87 23 6
8 26 86 23 6
8 26 85 23 86
8 26 63 62 104
8 27 97 23 38
8 27 96 2 6
8 27 95 23 70
8 27 90 23 38
8 27 89 23 6
8 27 88 23 6
8 27 87 23 6
8 27 86 23 6
8 27 85 23 70
8 28 97 23 46
8 28 96 23 14
8 28 95 23 6
8 28 94 23 86
8 28 90 23 38
8 28 89 23 6
8 28 88 23 6
8 28 87 23 6
8 28 86 23 6
8 28 85 23 78
8 29 95 23 46
8 29 94 23 14
8 29 93 23 22
8 29 92 23 22
8 29 91 23 22
8 29 90 23 6
8 29 89 23 6
8 29 88 23 6
8 29 87 23 14
8 29 86 23 76
8 30 93 23 46
8 30 92 23 14
8 30 91 23 14
8 30 90 23 14
8 30 89 23 14
8 30 88 23 76
9 5 102 33 48
9 5 101 33 80
9 5 65 33 48
9 5 64 33 80
9 6 102 33 40
9 6 101 33 72
9 6 65 33 40
9 6 64 33 72
9 13 104 50 48
9 13 103 50 24
9 13 102 50 24
9 13 101 50 24
9 13 100 50 24
9 13 99 50 24
9 13 98 50 24
9 13 97 50 24
9 13 96 50 24
9 13 95 50 24
9 13 94 50 24
9 13 93 50 24
9 13 92 50 24
9 13 91 50 24
9 13 90 50 24
9 13 89 50 24
9 13 88 50 24
9 13 87 50 24
9 13 86 50 24
9 13 85 50 24
9 13 84 50 24
9 13 83 50 24
9 13 82 50 24
9 13 81 50 24
9 13 80 50 24
9 13 79 50 24
9 13 78 50 24
9 13 77 50 24
9 13 76 50 24
9 13 75 50 24
9 13 74 50 24
9 13 73 50 24
9 13 72 50 24
9 13 71 50 24
9 13 70 50 24
9 13 69 50 24
9 13 68 50 24
9 13 67 50 24
9 13 66 50 24
9 13 65 50 24
9 13 64 50 24
9 13 63 50 24
9 13 62 50 80
9 14 105 52 56
9 14 104 50 64
9 14 62 50 32
9 14 61 52 88
9 15 104 50 96
9 15 62 50 96
9 16 104 50 96
9 16 62 50 96
9 17 104 50 96
9 17 62 50 96
9 18 104 50 96
9 18 62 50 96
9 19 104 50 96
9 19 62 50 96
9 20 105 52 56
9 20 104 50 64
9 20 62 50 32
9 20 61 52 88
9 21 104 50 96
9 21 62 50 96
9 22 104 50 40
9 22 103 50 16
9 22 102 50 16
9 22 101 50 24
9 22 100 50 16
9 22 99 50 24
9 22 98 50 16
9 22 97 50 16
9 22 96 50 16
9 22 95 50 16
9 22 94 50 16
9 22 93 50 16
9 22 92 50 24
9 22 91 50 16
9 22 90 50 16
9 22 89 50 24
9 22 88 50 16
9 22 87 50 16
9 22 86 50 16
9 22 85 50 24
9 22 84 50 24
9 22 83 50 16
9 22 82 50 16
9 22 81 50 16
9 22 80 50 24
9 22 79 50 16
9 22 78 50 16
9 22 77 50 24
9 22 76 50 16
9 22 75 50 24
9 22 74 50 16
9 22 73 50 16
9 22 72 50 16
9 22 71 50 24
9 22 70 50 24
9 22 69 50 16
9 22 68 50 24
9 22 67 50 16
9 22 66 50 24
9 22 65 50 24
9 22 64 50 16
9 22 63 50 16
9 22 62 50 72
9 23 103 62 32
9 23 102 89 78
9 23 100 61 110
9 23 98 89 38
9 23 97 45 8
9 23 96 61 12
9 23 95 45 8
9 23 94 89 10
9 23 93 61 72
9 23 91 61 42
9 23 90 70 74
9 23 88 61 32
9 23 87 29 8
9 23 86 89 64
9 23 83 61 46
9 23 82 61 8
9 23 81 89 66
9 23 79 61 42
9 23 78 89 76
9 23 76 61 96
9 23 74 61 40
9 23 73 89 8
9 23 72 61 78
9 23 69 61 108
9 23 67 61 108
9 23 64 70 46
9 23 63 62 64
9 24 103 62 96
9 24 98 45 100
9 24 88 61 106
9 24 86 61 42
9 24 85 29 84
9 24 81 61 108
9 24 76 61 110
9 24 63 62 96
9 25 103 62 96
9 25 98 29 106
9 25 85 29 46
9 25 84 29 84
9 25 63 62 96
9 26 103 62 104
9 26 99 10 124
9 26 84 29 102
9 26 63 62 104
9 27 98 10 116
9 27 84 23 102
9 28 98 10 108
9 28 84 10 108
9 29 97 10 62
9 29 96 23 86
9 29 86 10 58
9 29 85 10 94
9 30 96 10 46
9 30 95 10 30
9 30 94 10 94
9 30 88 10 58
9 30 87 10 94
9 31 93 10 62
9 31 92 10 30
9 31 91 10 30
9 31 90 10 30
9 31 89 10 94
10 5 102 33 48
10 5 101 33 80
10 5 65 33 48
10 5 64 33 80
10 6 102 33 40
10 6 101 33 72
10 6 65 33 40
10 6 64 33 72
10 13 104 50 48
10 13 103 50 24
10 13 102 50 24
10 13 101 50 24
10 13 100 50 24
10 13 99 50 24
10 13 98 50 24
10 13 97 50 24
10 13 96 50 24
10 13 95 50 24
10 13 94 50 24
10 13 93 50 24
10 13 92 50 24
10 13 91 50 24
10 13 90 50 24
10 13 89 50 24
10 13 88 50 24
10 13 87 50 24
10 13 86 50 24
10 13 85 50 24
10 13 84 50 24
10 13 83 50 24
10 13 82 50 24
10 13 81 50 24
10 13 80 50 24
10 13 79 50 24
10 13 78 50 24
10 13 77 50 24
10 13 76 50 24
10 13 75 50 24
10 13 74 50 24
10 13 73 50 24
10 13 72 50 24
10 13 71 50 24
10 13 70 50 24
10 13 69 50 24
10 13 68 50 24
10 13 67 50 24
10 13 66 50 24
10 13 65 50 24
10 13 64 50 24
10 13 63 50 24
10 13 62 50 80
10 14 105 52 56
10 14 104 50 64
10 14 62 50 32
10 14 61 52 88
10 15 104 50 96
10 15 62 50 96
10 16 104 50 96
10 16 62 50 96
10 17 104 50 96
10 17 62 50 96
10 18 104 50 96
10 18 62 50 96
10 19 104 50 96
10 19 62 50 96
10 20 105 52 56
10 20 104 50 64
10 20 62 50 32
10 20 61 52 88
10 21 104 50 96
10 21 62 50 96
10 22 104 50 40
10 22 103 50 16
10 22 102 50 24
10 22 101 50 16
10 22 100 50 24
10 22 99 50 16
10 22 98 50 24
10 22 97 50 16
10 22 96 50 16
10 22 95 50 16
10 22 94 50 24
10 22 93 50 16
10 22 92 50 16
10 22 91 50 24
10 22 90 50 24
10 22 89 50 16
10 22 88 50 16
10 22 87 50 16
10 22 86 50 16
10 22 85 50 24
10 22 84 50 16
10 22 83 50 24
10 22 82 50 16
10 22 81 50 24
10 22 80 50 16
10 22 79 50 24
10 22 78 50 16
10 22 77 50 24
10 22 76 50 16
10 22 75 50 16
10 22 74 50 16
10 22 73 50 16
10 22 72 50 24
10 22 71 50 16
10 22 70 50 24
10 22 69 50 16
10 22 68 50 24
10 22 67 50 16
10 22 66 50 16
10 22 65 50 16
10 22 64 50 24
10 22 63 50 16
10 22 62 50 72
10 23 103 62 96
10 23 101 89 108
10 23 99 89 110
10 23 97 89 40
10 23 96 45 8
10 23 95 89 72
10 23 93 61 42
10 23 92 89 78
10 23 89 61 46
10 23 88 89 8
10 23 87 29 8
10 23 86 61 72
10 23 84 89 108
10 23 82 61 106
10 23 80 89 100
10 23 78 61 104
10 23 76 89 40
10 23 75 61 12
10 23 74 89 8
10 23 73 61 72
10 23 71 61 108
10 23 69 89 106
10 23 67 70 42
10 23 66 89 14
10 23 65 61 78
10 23 63 62 96
10 24 103 62 96
10 24 98 45 120
10 24 85 29 120
10 24 81 29 50
10 24 80 8 6
10 24 79 29 86
10 24 63 62 96
10 25 103 62 96
10 25 99 29 118
10 25 84 29 120
10 25 82 29 54
10 25 81 8 6
10 25 80 73 6
10 25 79 69 78
10 25 63 62 96
10 26 103 62 104
10 26 99 8 104
10 26 83 29 54
10 26 82 8 6
10 26 81 73 6
10 26 80 69 70
10 26 63 62 104
10 27 98 8 112
10 27 83 23 46
10 27 82 8 6
10 27 81 73 6
10 27 80 69 70
10 28 98 8 96
10 28 84 59 112
10 28 82 23 46
10 28 81 8 6
10 28 80 73 6
10 28 79 69 86
10 29 98 59 102
10 29 84 59 102
10 29 81 23 46
10 29 80 8 6
10 29 79 23 78
10 30 98 73 46
10 30 97 59 86
10 30 86 59 54
10 30 85 59 22
10 30 84 73 6
10 30 83 73 86
10 30 80 23 110
10 31 97 73 46
10 31 96 59 22
10 31 95 59 22
10 31 94 59 86
10 31 88 59 54
10 31 87 59 22
10 31 86 73 6
10 31 85 73 6
10 31 84 73 6
10 31 83 74 70
10 32 96 73 46
10 32 95 73 14
10 32 94 73 6
10 32 93 73 22
10 32 92 73 22
10 32 91 73 22
10 32 90 73 22
10 32 89 73 22
10 32 88 73 6
10 32 87 73 6
10 32 86 73 6
10 32 85 74 6
10 32 84 74 6
10 32 83 74 78
10 33 94 74 46
10 33 93 74 14
10 33 92 74 14
10 33 91 74 14
10 33 90 74 14
10 33 89 74 14
10 33 88 74 14
10 33 87 74 14
10 33 86 74 14
10 33 85 74 14
10 33 84 74 78
11 5 102 33 48
11 5 101 33 80
11 5 65 33 48
11 5 64 33 80
11 6 102 33 40
11 6 101 33 72
11 6 65 33 40
11 6 64 33 72
11 13 104 50 48
11 13 103 50 24
11 13 102 50 24
11 13 101 50 24
11 13 100 50 24
11 13 99 50 24
11 13 98 50 24
11 13 97 50 24
11 13 96 50 24
11 13 95 50 24
11 13 94 50 24
11 13 93 50 24
11 13 92 50 24
11 13 91 50 24
11 13 90 50 24
11 13 89 50 24
11 13 88 50 24
11 13 87 50 24
11 13 86 50 24
11 13 85 50 24
11 13 84 50 24
11 13 83 50 24
11 13 82 50 24
11 13 81 50 24
11 13 80 50 24
11 13 79 50 24
11 13 78 50 24
11 13 77 50 24
11 13 76 50 24
11 13 75 50 24
11 13 74 50 24
11 13 73 50 24
11 13 72 50 24
11 13 71 50 24
11 13 70 50 24
11 13 69 50 24
11 13 68 50 24
11 13 67 50 24
11 13 66 50 24
11 13 65 50 24
11 13 64 50 24
11 13 63 50 24
11 13 62 50 80
11 14 105 52 56
11 14 104 50 64
11 14 62 50 32
11 14 61 52 88
11 15 104 50 96
11 15 62 50 96
11 16 104 50 96
11 16 62 50 96
11 17 104 50 96
11 17 62 50 96
11 18 104 50 96
11 18 62 50 96
11 19 104 50 96
11 19 62 50 96
11 20 105 52 56
11 20 104 50 64
11 20 62 50 32
11 20 61 52 88
11 21 104 50 96
11 21 62 50 96
11 22 104 50 40
11 22 103 50 16
11 22 102 50 24
11 22 101 50 16
11 22 100 50 16
11 22 99 50 24
11 22 98 50 24
11 22 97 50 16
11 22 96 50 16
11 22 95 50 16
11 22 94 50 16
11 22 93 50 24
11 22 92 50 24
11 22 91 50 16
11 22 90 50 16
11 22 89 50 24
11 22 88 50 16
11 22 87 50 16
11 22 86 50 16
11 22 85 50 16
11 22 84 50 16
11 22 83 50 24
11 22 82 50 24
11 22 81 50 16
11 22 80 50 16
11 22 79 50 24
11 22 78 50 16
11 22 77 50 16
11 22 76 50 16
11 22 75 50 16
11 22 74 50 16
11 22 73 50 16
11 22 72 50 24
11 22 71 50 16
11 22 70 50 16
11 22 69 50 24
11 22 68 50 16
11 22 67 50 24
11 22 66 50 24
11 22 65 50 24
11 22 64 50 16
11 22 63 50 16
11 22 62 50 72
11 23 103 62 96
11 23 101 89 40
11 23 100 89 78
11 23 97 89 40
11 23 96 89 10
11 23 95 45 8
11 23 94 61 76
11 23 91 61 44
11 23 90 89 76
11 23 88 29 40
11 23 87 61 8
11 23 86 29 8
11 23 85 89 6
11 23 84 89 72
11 23 81 61 46
11 23 80 89 72
11 23 78 89 42
11 23 77 89 12
11 23 76 61 10
11 23 75 89 8
11 23 74 89 10
11 23 73 61 72
11 23 71 89 42
11 23 70 61 78
11 23 68 61 108
11 23 64 89 46
11 23 63 62 64
11 24 103 62 96
11 24 98 45 114
11 24 85 29 98
11 24 63 62 96
11 25 103 62 96
11 25 98 29 108
11 25 85 29 46
11 25 84 29 82
11 25 63 62 96
11 26 103 62 104
11 26 99 10 122
11 26 84 29 102
11 26 63 62 104
11 27 98 10 114
11 27 84 23 102
11 28 98 10 106
11 28 84 10 106
11 29 97 10 62
11 29 96 23 86
11 29 86 10 60
11 29 85 10 94
11 30 96 10 46
11 30 95 10 30
11 30 94 10 94
11 30 88 10 60
11 30 87 10 94
11 31 93 10 62
11 31 92 10 30
11 31 91 10 30
11 31 90 10 30
11 31 89 10 94
12 5 102 33 48
12 5 101 33 80
12 5 65 33 48
12 5 64 33 80
12 6 102 33 40
12 6 101 33 72
12 6 65 33 40
12 6 64 33 72
12 13 104 50 48
12 13 103 50 24
12 13 102 50 24
12 13 101 50 24
12 13 100 50 24
12 13 99 50 24
12 13 98 50 24
12 13 97 50 24
12 13 96 50 24
12 13 95 50 24
12 13 94 50 24
12 13 93 50 24
12 13 92 50 24
12 13 91 50 24
12 13 90 50 24
12 13 89 50 24
12 13 88 50 24
12 13 87 50 24
12 13 86 50 24
12 13 85 50 24
12 13 84 50 24
12 13 83 50 24
12 13 82 50 24
12 13 81 50 24
12 13 80 50 24
12 13 79 50 24
12 13 78 50 24
12 13 77 50 24
12 13 76 50 24
12 13 75 50 24
12 13 74 50 24
12 13 73 50 24
12 13 72 50 24
12 13 71 50 24
12 13 70 50 24
12 13 69 50 24
12 13 68 50 24
12 13 67 50 24
12 13 66 50 24
12 13 65 50 24
12 13 64 50 24
12 13 63 50 24
12 13 62 50 80
12 14 105 52 56
12 14 104 50 64
12 14 62 50 32
12 14 61 52 88
12 15 104 50 96
12 15 62 50 96
12 16 104 50 96
12 16 62 50 96
12 17 104 50 96
12 17 62 50 96
12 18 104 50 96
12 18 62 50 96
12 19 104 50 96
12 19 62 50 96
12 20 105 52 56
12 20 104 50 64
12 20 62 50 32
12 20 61 52 88
12 21 104 50 96
12 21 62 50 96
12 22 104 50 40
12 22 103 50 16
12 22 102 50 24
12 22 101 50 16
12 22 100 50 24
12 22 99 50 16
12 22 98 50 24
12 22 97 50 16
12 22 96 50 24
12 22 95 50 16
12 22 94 50 16
12 22 93 50 16
12 22 92 50 16
12 22 91 50 16
12 22 90 50 16
12 22 89 50 16
12 22 88 50 16
12 22 87 50 16
12 22 86 50 16
12 22 85 50 24
12 22 84 50 16
12 22 83 50 16
12 22 82 50 16
12 22 81 50 24
12 22 80 50 16
12 22 79 50 16
12 22 78 50 24
12 22 77 50 16
12 22 76 50 24
12 22 75 50 16
12 22 74 50 24
12 22 73 50 16
12 22 72 50 16
12 22 71 50 24
12 22 70 50 24
12 22 69 50 24
12 22 68 50 16
12 22 67 50 16
12 22 66 50 16
12 22 65 50 16
12 22 64 50 24
12 22 63 50 16
12 22 62 50 72
12 23 103 62 96
12 23 101 89 98
12 23 99 89 110
12 23 97 89 98
12 23 95 89 34
12 23 94 89 0
12 23 93 61 6
12 23 92 61 4
12 23 91 29 2
12 23 90 29 0
12 23 89 61 4
12 23 88 29 2
12 23 87 61 0
12 23 86 89 66
12 23 84 61 40
12 23 83 61 14
12 23 82 61 76
12 23 80 61 40
12 23 79 61 78
12 23 77 89 104
12 23 75 61 96
12 23 73 89 32
12 23 72 61 78
12 23 68 89 42
12 23 67 61 6
12 23 66 70 12
12 23 65 89 78
12 23 63 62 96
12 24 103 62 96
12 24 101 61 110
12 24 97 61 38
12 24 96 29 20
12 24 95 29 6
12 24 94 29 6
12 24 93 29 14
12 24 92 29 14
12 24 91 29 14
12 24 90 29 6
12 24 89 29 6
12 24 88 29 6
12 24 87 29 6
12 24 86 29 70
12 24 75 61 110
12 24 73 61 110
12 24 67 61 110
12 24 63 62 96
12 25 103 62 96
12 25 98 29 50
12 25 97 29 6
12 25 96 29 6
12 25 95 29 6
12 25 94 29 78
12 25 90 23 38
12 25 89 29 6
12 25 88 29 6
12 25 87 29 6
12 25 86 29 70
12 25 63 62 96
12 26 103 62 104
12 26 98 23 46
12 26 97 23 6
12 26 96 23 6
12 26 95 23 70
12 26 90 23 38
12 26 89 23 6
12 26 88 23 6
12 26 87 23 6
12 26 86 23 6
12 26 85 23 86
12 26 63 62 104
12 27 97 23 38
12 27 96 2 6
12 27 95 23 70
12 27 90 23 38
12 27 89 23 6
12 27 88 23 6
12 27 87 23 6
12 27 86 23 6
12 27 85 23 70
12 28 97 23 46
12 28 96 23 14
12 28 95 23 6
12 28 94 23 86
12 28 90 23 38
12 28 89 23 6
12 28 88 23 6
12 28 87 23 6
12 28 86 23 6
12 28 85 23 78
12 29 95 23 46
12 29 94 23 14
12 29 93 23 22
12 29 92 23 22
12 29 91 23 22
12 29 90 23 6
12 29 89 23 6
12 29 88 23 6
12 29 87 23 14
12 29 86 23 74
12 30 93 23 46
12 30 92 23 14
12 30 91 23 14
12 30 90 23 14
12 30 89 23 14
12 30 88 23 74
13 5 102 33 48
13 5 101 33 80
13 5 65 33 48
13 5 64 33 80
13 6 102 33 40
13 6 101 33 72
13 6 65 33 40
13 6 64 33 72
13 13 104 50 48
13 13 103 50 24
13 13 102 50 24
13 13 101 50 24
13 13 100 50 24
13 13 99 50 24
13 13 98 50 24
13 13 97 50 24
13 13 96 50 24
13 13 95 50 24
13 13 94 50 24
13 13 93 50 24
13 13 92 50 24
13 13 91 50 24
13 13 90 50 24
13 13 89 50 24
13 13 88 50 24
13 13 87 50 24
13 13 86 50 24
13 13 85 50 24
13 13 84 50 24
13 13 83 50 24
13 13 82 50 24
13 13 81 50 24
13 13 80 50 24
13 13 79 50 24
13 13 78 50 24
13 13 77 50 24
13 13 76 50 24
13 13 75 50 24
13 13 74 50 24
13 13 73 50 24
13 13 72 50 24
13 13 71 50 24
13 13 70 50 24
13 13 69 50 24
13 13 68 50 24
13 13 67 50 24
13 13 66 50 24
13 13 65 50 24
13 13 64 50 24
13 13 63 50 24
13 13 62 50 80
13 14 105 52 56
13 14 104 50 64
13 14 62 50 32
13 14 61 52 88
13 15 104 50 96
13 15 62 50 96
13 16 104 50 96
13 16 62 50 96
13 17 104 50 96
13 17 62 50 96
13 18 104 50 96
13 18 62 50 96
13 19 104 50 96
13 19 62 50 96
13 20 105 52 56
13 20 104 50 64
13 20 62 50 32
13 20 61 52 88
13 21 104 50 96
13 21 62 50 96
13 22 104 50 40
13 22 103 50 16
13 22 102 50 16
13 22 101 50 24
13 22 100 50 16
13 22 99 50 24
13 22 98 50 16
13 22 97 50 24
13 22 96 50 16
13 22 95 50 24
13 22 94 50 16
13 22 93 50 24
13 22 92 50 16
13 22 91 50 24
13 22 90 50 16
13 22 89 50 16
13 22 88 50 24
13 22 87 50 16
13 22 86 50 24
13 22 85 50 24
13 22 84 50 16
13 22 83 50 24
13 22 82 50 16
13 22 81 50 24
13 22 80 50 16
13 22 79 50 24
13 22 78 50 16
13 22 77 50 16
13 22 76 50 16
13 22 75 50 16
13 22 74 50 16
13 22 73 50 16
13 22 72 50 24
13 22 71 50 16
13 22 70 50 16
13 22 69 50 16
13 22 68 50 24
13 22 67 50 24
13 22 66 50 16
13 22 65 50 24
13 22 64 50 16
13 22 63 50 16
13 22 62 50 72
13 23 103 62 32
13 23 102 89 78
13 23 100 89 100
13 23 98 89 110
13 23 96 89 100
13 23 94 89 104
13 23 92 89 106
13 23 90 61 42
13 23 89 89 74
13 23 87 89 106
13 23 84 89 106
13 23 82 89 106
13 23 80 61 106
13 23 78 61 44
13 23 77 61 10
13 23 76 61 12
13 23 75 61 10
13 23 74 61 12
13 23 73 61 72
13 23 71 89 46
13 23 70 61 12
13 23 69 61 78
13 23 66 89 104
13 23 64 61 46
13 23 63 62 64
13 24 103 62 96
13 24 100 61 110
13 24 96 61 106
13 24 63 62 96
13 25 103 62 96
13 25 93 23 54
13 25 92 23 22
13 25 91 23 84
13 25 63 62 96
13 26 103 62 104
13 26 94 23 54
13 26 93 23 6
13 26 92 23 6
13 26 91 23 68
13 26 63 62 104
13 27 94 29 46
13 27 93 23 6
13 27 92 23 6
13 27 91 23 68
13 28 93 29 46
13 28 92 29 14
13 28 91 29 76
14 5 102 33 48
14 5 101 33 80
14 5 65 33 48
14 5 64 33 80
14 6 102 33 40
14 6 101 33 72
14 6 65 33 40
14 6 64 33 72
14 13 104 50 48
14 13 103 50 24
14 13 102 50 24
14 13 101 50 24
14 13 100 50 24
14 13 99 50 24
14 13 98 50 24
14 13 97 50 24
14 13 96 50 24
14 13 95 50 24
14 13 94 50 24
14 13 93 50 24
14 13 92 50 24
14 13 91 50 24
14 13 90 50 24
14 13 89 50 24
14 13 88 50 24
14 13 87 50 24
14 13 86 50 24
14 13 85 50 24
14 13 84 50 24
14 13 83 50 24
14 13 82 50 24
14 13 81 50 24
14 13 80 50 24
14 13 79 50 24
14 13 78 50 24
14 13 77 50 24
14 13 76 50 24
14 13 75 50 24
14 13 74 50 24
14 13 73 50 24
14 13 72 50 24
14 13 71 50 24
14 13 70 50 24
14 13 69 50 24
14 13 68 50 24
14 13 67 50 24
14 13 66 50 24
14 13 65 50 24
14 13 64 50 24
14 13 63 50 24
14 13 62 50 80
14 14 105 52 56
14 14 104 50 64
14 14 62 50 32
14 14 61 52 88
14 15 104 50 96
14 15 62 50 96
14 16 104 50 96
14 16 62 50 96
14 17 104 50 96
14 17 62 50 96
14 18 104 50 96
14 18 62 50 96
14 19 104 50 96
14 19 62 50 96
14 20 105 52 56
14 20 104 50 64
14 20 62 50 32
14 20 61 52 88
14 21 104 50 96
14 21 62 50 96
14 22 104 50 40
14 22 103 50 16
14 22 102 50 24
14 22 101 50 16
14 22 100 50 16
14 22 99 50 24
14 22 98 50 24
14 22 97 50 16
14 22 96 50 16
14 22 95 50 24
14 22 94 50 16
14 22 93 50 24
14 22 92 50 24
14 22 91 50 16
14 22 90 50 24
14 22 89 50 24
14 22 88 50 16
14 22 87 50 24
14 22 86 50 16
14 22 85 50 16
14 22 84 50 24
14 22 83 50 16
14 22 82 50 24
14 22 81 50 16
14 22 80 50 24
14 22 79 50 16
14 22 78 50 16
14 22 77 50 24
14 22 76 50 16
14 22 75 50 24
14 22 74 50 16
14 22 73 50 16
14 22 72 50 16
14 22 71 50 24
14 22 70 50 16
14 22 69 50 24
14 22 68 50 16
14 22 67 50 16
14 22 66 50 16
14 22 65 50 16
14 22 64 50 24
14 22 63 50 16
14 22 62 50 72
14 23 103 62 96
14 23 101 89 46
14 23 100 89 72
14 23 97 89 46
14 23 96 89 72
14 23 94 89 96
14 23 91 61 110
14 23 88 61 110
14 23 86 61 44
14 23 85 89 78
14 23 83 89 110
14 23 81 61 110
14 23 79 61 44
14 23 78 61 74
14 23 76 89 106
14 23 74 89 42
14 23 73 89 8
14 23 72 61 76
14 23 70 89 106
14 23 68 61 46
14 23 67 89 6
14 23 66 89 10
14 23 65 89 78
14 23 63 62 96
14 24 103 62 96
14 24 94 89 110
14 24 67 61 110
14 24 63 62 96
14 25 103 62 96
14 25 91 23 50
14 25 90 23 86
14 25 63 62 96
14 26 103 62 104
14 26 91 23 34
14 26 90 23 6
14 26 89 23 20
14 26 88 23 84
14 26 63 62 104
14 27 91 23 34
14 27 90 23 6
14 27 89 23 4
14 27 88 29 76
14 28 91 29 42
14 28 90 29 14
14 28 89 29 76
15 5 102 33 48
15 5 101 33 80
15 5 65 33 48
15 5 64 33 80
15 6 102 33 40
15 6 101 33 72
15 6 65 33 40
15 6 64 33 72
15 13 104 50 48
15 13 103 50 24
15 13 102 50 24
15 13 101 50 24
15 13 100 50 24
15 13 99 50 24
15 13 98 50 24
15 13 97 50 24
15 13 96 50 24
15 13 95 50 24
15 13 94 50 24
15 13 93 50 24
15 13 92 50 24
15 13 91 50 24
15 13 90 50 24
15 13 89 50 24
15 13 88 50 24
15 13 87 50 24
15 13 86 50 24
15 13 85 50 24
15 13 84 50 24
15 13 83 50 24
15 13 82 50 24
15 13 81 50 24
15 13 80 50 24
15 13 79 50 24
15 13 78 50 24
15 13 77 50 24
15 13 76 50 24
15 13 75 50 24
15 13 74 50 24
15 13 73 50 24
15 13 72 50 24
15 13 71 50 24
15 13 70 50 24
15 13 69 50 24
15 13 68 50 24
15 13 67 50 24
15 13 66 50 24
15 13 65 50 24
15 13 64 50 24
15 13 63 50 24
15 13 62 50 80
15 14 105 52 56
15 14 104 50 64
15 14 62 50 32
15 14 61 52 88
15 15 104 50 96
15 15 62 50 96
15 16 104 50 96
15 16 62 50 96
15 17 104 50 96
15 17 62 50 96
15 18 104 50 96
15 18 62 50 96
15 19 104 50 96
15 19 62 50 96
15 20 105 52 56
15 20 104 50 64
15 20 62 50 32
15 20 61 52 88
15 21 104 50 96
15 21 62 50 96
15 22 104 50 40
15 22 103 50 16
15 22 102 50 16
15 22 101 50 24
15 22 100 50 16
15 22 99 50 24
15 22 98 50 16
15 22 97 50 24
15 22 96 50 16
15 22 95 50 24
15 22 94 50 16
15 22 93 50 16
15 22 92 50 16
15 22 91 50 24
15 22 90 50 16
15 22 89 50 16
15 22 88 50 24
15 22 87 50 16
15 22 86 50 16
15 22 85 50 24
15 22 84 50 16
15 22 83 50 24
15 22 82 50 24
15 22 81 50 24
15 22 80 50 16
15 22 79 50 16
15 22 78 50 24
15 22 77 50 16
15 22 76 50 24
15 22 75 50 16
15 22 74 50 24
15 22 73 50 16
15 22 72 50 16
15 22 71 50 24
15 22 70 50 24
15 22 69 50 16
15 22 68 50 24
15 22 67 50 24
15 22 66 50 24
15 22 65 50 24
15 22 64 50 16
15 22 63 50 16
15 22 62 50 72
15 23 103 62 32
15 23 102 89 78
15 23 100 89 106
15 23 98 89 110
15 23 96 89 106
15 23 94 89 42
15 23 93 89 14
15 23 92 61 76
15 23 90 61 46
15 23 89 61 76
15 23 87 61 44
15 23 86 89 72
15 23 84 89 110
15 23 80 61 38
15 23 79 89 72
15 23 77 89 110
15 23 75 61 108
15 23 73 89 40
15 23 72 89 74
15 23 69 89 108
15 23 64 61 46
15 23 63 62 64
15 24 103 62 96
15 24 80 61 110
15 24 76 61 126
15 24 63 62 96
15 25 103 62 96
15 25 89 23 52
15 25 88 23 86
15 25 63 62 96
15 26 103 62 104
15 26 89 23 32
15 26 88 23 2
15 26 87 23 22
15 26 86 23 86
15 26 63 62 104
15 27 89 23 32
15 27 88 23 2
15 27 87 23 6
15 27 86 29 78
15 28 89 29 40
15 28 88 29 14
15 28 87 29 78
16 5 102 33 48
16 5 101 33 80
16 5 65 33 48
16 5 64 33 80
16 6 102 33 40
16 6 101 33 72
16 6 65 33 40
16 6 64 33 72
16 13 104 50 48
16 13 103 50 24
16 13 102 50 24
16 13 101 50 24
16 13 100 50 24
16 13 99 50 24
16 13 98 50 24
16 13 97 50 24
16 13 96 50 24
16 13 95 50 24
16 13 94 50 24
16 13 93 50 24
16 13 92 50 24
16 13 91 50 24
16 13 90 50 24
16 13 89 50 24
16 13 88 50 24
16 13 87 50 24
16 13 86 50 24
16 13 85 50 24
16 13 84 50 24
16 13 83 50 24
16 13 82 50 24
16 13 81 50 24
16 13 80 50 24
16 13 79 50 24
16 13 78 50 24
16 13 77 50 24
16 13 76 50 24
16 13 75 50 24
16 13 74 50 24
16 13 73 50 24
16 13 72 50 24
16 13 71 50 24
16 13 70 50 24
16 13 69 50 24
16 13 68 50 24
16 13 67 50 24
16 13 66 50 24
16 13 65 50 24
16 13 64 50 24
16 13 63 50 24
16 13 62 50 80
16 14 105 52 56
16 14 104 50 64
16 14 62 50 32
16 14 61 52 88
16 15 104 50 96
16 15 62 50 96
16 16 104 50 96
16 16 62 50 96
16 17 104 50 96
16 17 62 50 96
16 18 104 50 96
16 18 62 50 96
16 19 104 50 96
16 19 62 50 96
16 20 105 52 56
16 20 104 50 64
16 20 62 50 32
16 20 61 52 88
16 21 104 50 96
16 21 62 50 96
16 22 104 50 40
16 22 103 50 16
16 22 102 50 24
16 22 101 50 16
16 22 100 50 24
16 22 99 50 16
16 22 98 50 24
16 22 97 50 16
16 22 96 50 24
16 22 95 50 16
16 22 94 50 24
16 22 93 50 24
16 22 92 50 16
16 22 91 50 16
16 22 90 50 24
16 22 89 50 16
16 22 88 50 24
16 22 87 50 16
16 22 86 50 16
16 22 85 50 24
16 22 84 50 24
16 22 83 50 16
16 22 82 50 24
16 22 81 50 16
16 22 80 50 24
16 22 79 50 16
16 22 78 50 24
16 22 77 61 24
16 22 76 50 16
16 22 75 50 16
16 22 74 50 16
16 22 73 50 16
16 22 72 50 24
16 22 71 50 16
16 22 70 50 16
16 22 69 50 16
16 22 68 50 16
16 22 67 50 24
16 22 66 50 16
16 22 65 50 16
16 22 64 50 24
16 22 63 50 16
16 22 62 50 72
16 23 103 62 96
16 23 101 61 110
16 23 99 89 110
16 23 97 61 110
16 23 95 89 110
16 23 92 89 40
16 23 91 61 76
16 23 89 89 104
16 23 87 61 40
16 23 86 89 72
16 23 83 61 108
16 23 81 61 110
16 23 79 89 106
16 23 76 61 44
16 23 75 61 8
16 23 74 61 12
16 23 73 89 64
16 23 71 89 46
16 23 70 61 12
16 23 69 89 10
16 23 68 89 78
16 23 66 89 46
16 23 65 61 78
16 23 63 62 96
16 24 103 62 96
16 24 73 61 110
16 24 63 62 96
16 25 103 62 96
16 25 91 23 54
16 25 90 23 22
16 25 89 23 82
16 25 63 62 96
16 26 103 62 104
16 26 92 23 54
16 26 91 23 6
16 26 90 23 6
16 26 89 23 66
16 26 63 62 104
16 27 92 29 46
16 27 91 23 6
16 27 90 23 6
16 27 89 23 66
16 28 91 29 46
16 28 90 29 14
16 28 89 29 74
17 5 102 33 48
17 5 101 33 80
17 5 65 33 48
17 5 64 33 80
17 6 102 33 40
17 6 101 33 72
17 6 65 33 40
17 6 64 33 72
17 13 104 50 48
17 13 103 50 24
17 13 102 50 24
17 13 101 50 24
17 13 100 50 24
17 13 99 50 24
17 13 98 50 24
17 13 97 50 24
17 13 96 50 24
17 13 95 50 24
17 13 94 50 24
17 13 93 50 24
17 13 92 50 24
17 13 91 50 24
17 13 90 50 24
17 13 89 50 24
17 13 88 50 24
17 13 87 50 24
17 13 86 50 24
17 13 85 50 24
17 13 84 50 24
17 13 83 50 24
17 13 82 50 24
17 13 81 50 24
17 13 80 50 24
17 13 79 50 24
17 13 78 50 24
17 13 77 50 24
17 13 76 50 24
17 13 75 50 24
17 13 74 50 24
17 13 73 50 24
17 13 72 50 24
17 13 71 50 24
17 13 70 50 24
17 13 69 50 24
17 13 68 50 24
17 13 67 50 24
17 13 66 50 24
17 13 65 50 24
17 13 64 50 24
17 13 63 50 24
17 13 62 50 80
17 14 105 52 56
17 14 104 50 64
17 14 62 50 32
17 14 61 52 88
17 15 104 50 96
17 15 62 50 96
17 16 104 50 96
17 16 62 50 96
17 17 104 50 96
17 17 62 50 96
17 18 104 50 96
17 18 62 50 96
17 19 104 50 96
17 19 62 50 96
17 20 105 52 56
17 20 104 50 64
17 20 62 50 32
17 20 61 52 88
17 21 104 50 96
17 21 62 50 96
17 22 104 50 40
17 22 103 50 16
17 22 102 50 16
17 22 101 50 24
17 22 100 50 16
17 22 99 50 24
17 22 98 50 16
17 22 97 50 24
17 22 96 50 16
17 22 95 50 24
17 22 94 50 16
17 22 93 50 16
17 22 92 50 16
17 22 91 50 16
17 22 90 50 16
17 22 89 50 16
17 22 88 50 16
17 22 87 50 16
17 22 86 50 16
17 22 85 50 16
17 22 84 50 24
17 22 83 50 16
17 22 82 50 24
17 22 81 50 24
17 22 80 50 16
17 22 79 50 24
17 22 78 50 16
17 22 77 50 16
17 22 76 50 16
17 22 75 50 16
17 22 74 50 16
17 22 73 50 16
17 22 72 50 16
17 22 71 50 24
17 22 70 50 16
17 22 69 50 24
17 22 68 50 24
17 22 67 50 16
17 22 66 50 24
17 22 65 50 24
17 22 64 50 16
17 22 63 50 16
17 22 62 50 72
17 23 103 62 32
17 23 102 61 70
17 23 100 61 108
17 23 98 61 102
17 23 96 61 108
17 23 94 61 36
17 23 93 61 4
17 23 92 29 0
17 23 91 29 0
17 23 90 29 6
17 23 89 29 0
17 23 88 29 6
17 23 87 29 2
17 23 86 29 0
17 23 85 61 68
17 23 83 89 106
17 23 80 61 110
17 23 78 61 46
17 23 77 89 12
17 23 76 61 10
17 23 75 89 8
17 23 74 61 2
17 23 73 89 8
17 23 72 89 78
17 23 70 61 104
17 23 67 61 108
17 23 64 89 44
17 23 63 62 64
17 24 103 62 32
17 24 102 89 78
17 24 98 89 110
17 24 95 29 54
17 24 94 29 6
17 24 93 29 6
17 24 92 29 6
17 24 91 29 14
17 24 90 29 14
17 24 89 29 14
17 24 88 29 6
17 24 87 29 6
17 24 86 29 6
17 24 85 29 6
17 24 84 29 86
17 24 74 61 110
17 24 63 62 96
17 25 103 62 96
17 25 96 29 52
17 25 95 29 6
17 25 94 29 6
17 25 93 29 6
17 25 92 29 78
17 25 88 23 38
17 25 87 29 6
17 25 86 29 6
17 25 85 29 6
17 25 84 29 70
17 25 63 62 96
17 26 103 62 104
17 26 96 23 46
17 26 95 23 6
17 26 94 23 6
17 26 93 23 70
17 26 88 23 38
17 26 87 23 6
17 26 86 23 6
17 26 85 23 6
17 26 84 23 6
17 26 83 23 86
17 26 63 62 104
17 27 95 23 38
17 27 94 2 6
17 27 93 23 70
17 27 88 23 38
17 27 87 23 6
17 27 86 23 6
17 27 85 23 6
17 27 84 23 6
17 27 83 23 70
17 28 95 23 46
17 28 94 23 14
17 28 93 23 6
17 28 92 23 86
17 28 88 23 38
17 28 87 23 6
17 28 86 23 6
17 28 85 23 6
17 28 84 23 6
17 28 83 23 78
17 29 93 23 46
17 29 92 23 14
17 29 91 23 22
17 29 90 23 22
17 29 89 23 22
17 29 88 23 6
17 29 87 23 6
17 29 86 23 6
17 29 85 23 14
17 29 84 23 76
17 30 91 23 46
17 30 90 23 14
17 30 89 23 14
17 30 88 23 14
17 30 87 23 14
17 30 86 23 76
18 5 102 33 48
18 5 101 33 80
18 5 65 33 48
18 5 64 33 80
18 6 102 33 40
18 6 101 33 72
18 6 65 33 40
18 6 64 33 72
18 13 104 50 48
18 13 103 50 24
18 13 102 50 24
18 13 101 50 24
18 13 100 50 24
18 13 99 50 24
18 13 98 50 24
18 13 97 50 24
18 13 96 50 24
18 13 95 50 24
18 13 94 50 24
18 13 93 50 24
18 13 92 50 24
18 13 91 50 24
18 13 90 50 24
18 13 89 50 24
18 13 88 50 24
18 13 87 50 24
18 13 86 50 24
18 13 85 50 24
18 13 84 50 24
18 13 83 50 24
18 13 82 50 24
18 13 81 50 24
18 13 80 50 24
18 13 79 50 24
18 13 78 50 24
18 13 77 50 24
18 13 76 50 24
18 13 75 50 24
18 13 74 50 24
18 13 73 50 24
18 13 72 50 24
18 13 71 50 24
18 13 70 50 24
18 13 69 50 24
18 13 68 50 24
18 13 67 50 24
18 13 66 50 24
18 13 65 50 24
18 13 64 50 24
18 13 63 50 24
18 13 62 50 80
18 14 105 52 56
18 14 104 50 64
18 14 62 50 32
18 14 61 52 88
18 15 104 50 96
18 15 62 50 96
18 16 104 50 96
18 16 62 50 96
18 17 104 50 96
18 17 62 50 96
18 18 104 50 96
18 18 62 50 96
18 19 104 50 96
18 19 62 50 96
18 20 105 52 56
18 20 104 50 64
18 20 62 50 32
18 20 61 52 88
18 21 104 50 96
18 21 62 50 96
18 22 104 50 40
18 22 103 50 16
18 22 102 50 24
18 22 101 50 16
18 22 100 50 16
18 22 99 50 16
18 22 98 50 24
18 22 97 50 16
18 22 96 50 16
18 22 95 50 16
18 22 94 50 16
18 22 93 50 16
18 22 92 50 16
18 22 91 45 16
18 22 90 45 24
18 22 89 45 16
18 22 88 45 24
18 22 87 45 24
18 22 86 50 16
18 22 85 50 16
18 22 84 50 16
18 22 83 50 24
18 22 82 50 24
18 22 81 50 16
18 22 80 50 24
18 22 79 50 16
18 22 78 50 24
18 22 77 50 16
18 22 76 50 24
18 22 75 50 16
18 22 74 50 24
18 22 73 50 16
18 22 72 50 24
18 22 71 50 16
18 22 70 50 16
18 22 69 50 24
18 22 68 50 16
18 22 67 50 16
18 22 66 50 16
18 22 65 50 16
18 22 64 50 16
18 22 63 50 16
18 22 62 50 72
18 23 103 62 96
18 23 101 61 46
18 23 100 61 8
18 23 99 61 78
18 23 97 61 46
18 23 96 61 0
18 23 95 45 12
18 23 94 45 8
18 23 93 45 8
18 23 92 45 8
18 23 91 61 74
18 23 89 61 104
18 23 86 29 42
18 23 85 29 8
18 23 84 29 76
18 23 81 61 108
18 23 79 61 108
18 23 77 61 104
18 23 75 61 104
18 23 73 89 104
18 23 71 89 46
18 23 70 61 74
18 23 68 61 46
18 23 67 61 8
18 23 66 61 12
18 23 65 61 12
18 23 64 89 10
18 23 63 62 64
18 24 103 62 96
18 24 96 45 100
18 24 83 29 116
18 24 63 62 96
18 25 103 62 96
18 25 96 29 106
18 25 83 29 46
18 25 82 29 84
18 25 63 62 96
18 26 103 62 104
18 26 97 10 124
18 26 82 29 102
18 26 63 62 104
18 27 96 10 116
18 27 82 23 102
18 28 96 10 108
18 28 82 10 108
18 29 95 10 62
18 29 94 23 86
18 29 84 10 58
18 29 83 10 94
18 30 94 10 46
18 30 93 10 30
18 30 92 10 94
18 30 86 10 58
18 30 85 10 94
18 31 91 10 62
18 31 90 10 30
18 31 89 10 30
18 31 88 10 30
18 31 87 10 94
19 5 102 33 48
19 5 101 33 80
19 5 65 33 48
19 5 64 33 80
19 6 102 33 40
19 6 101 33 72
19 6 65 33 40
19 6 64 33 72
19 13 104 50 48
19 13 103 50 24
19 13 102 50 24
19 13 101 50 24
19 13 100 50 24
19 13 99 50 24
19 13 98 50 24
19 13 97 50 24
19 13 96 50 24
19 13 95 50 24
19 13 94 50 24
19 13 93 50 24
19 13 92 50 24
19 13 91 50 24
19 13 90 50 24
19 13 89 50 24
19 13 88 50 24
19 13 87 50 24
19 13 86 50 24
19 13 85 50 24
19 13 84 50 24
19 13 83 50 24
19 13 82 50 24
19 13 81 50 24
19 13 80 50 24
19 13 79 50 24
19 13 78 50 24
19 13 77 50 24
19 13 76 50 24
19 13 75 50 24
19 13 74 50 24
19 13 73 50 24
19 13 72 50 24
19 13 71 50 24
19 13 70 50 24
19 13 69 50 24
19 13 68 50 24
19 13 67 50 24
19 13 66 50 24
19 13 65 50 24
19 13 64 50 24
19 13 63 50 24
19 13 62 50 80
19 14 105 52 56
19 14 104 50 64
19 14 62 50 32
19 14 61 52 88
19 15 104 50 96
19 15 62 50 96
19 16 104 50 96
19 16 62 50 96
19 17 104 50 96
19 17 62 50 96
19 18 104 50 96
19 18 62 50 96
19 19 104 50 96
19 19 62 50 96
19 20 105 52 56
19 20 104 50 64
19 20 62 50 32
19 20 61 52 88
19 21 104 50 96
19 21 62 50 96
19 22 104 50 40
19 22 103 50 16
19 22 102 50 16
19 22 101 50 24
19 22 100 50 16
19 22 99 50 24
19 22 98 50 16
19 22 97 50 24
19 22 96 50 16
19 22 95 50 16
19 22 94 50 16
19 22 93 50 16
19 22 92 45 16
19 22 91 45 24
19 22 90 45 24
19 22 89 45 16
19 22 88 45 16
19 22 87 45 16
19 22 86 45 24
19 22 85 50 16
19 22 84 50 16
19 22 83 50 16
19 22 82 50 24
19 22 81 50 16
19 22 80 50 24
19 22 79 50 16
19 22 78 50 16
19 22 77 50 16
19 22 76 50 16
19 22 75 50 16
19 22 74 50 16
19 22 73 50 16
19 22 72 50 16
19 22 71 50 24
19 22 70 50 24
19 22 69 50 16
19 22 68 50 24
19 22 67 50 16
19 22 66 50 16
19 22 65 50 16
19 22 64 50 24
19 22 63 50 16
19 22 62 50 72
19 23 103 62 32
19 23 102 61 78
19 23 100 89 106
19 23 98 61 110
19 23 96 89 34
19 23 95 45 8
19 23 94 45 8
19 23 93 45 8
19 23 92 61 72
19 23 89 89 40
19 23 88 89 12
19 23 87 61 78
19 23 85 29 40
19 23 84 29 8
19 23 83 89 68
19 23 81 89 104
19 23 79 89 32
19 23 78 29 4
19 23 77 89 2
19 23 76 61 12
19 23 75 89 8
19 23 74 61 12
19 23 73 89 8
19 23 72 61 78
19 23 69 61 108
19 23 67 89 34
19 23 66 89 8
19 23 65 61 66
19 23 63 62 96
19 24 103 62 96
19 24 96 45 104
19 24 83 29 104
19 24 79 29 38
19 24 78 8 6
19 24 77 29 70
19 24 67 61 110
19 24 65 61 110
19 24 63 62 96
19 25 103 62 96
19 25 97 29 118
19 25 82 29 120
19 25 80 29 54
19 25 79 8 6
19 25 78 73 6
19 25 77 69 78
19 25 63 62 96
19 26 103 62 104
19 26 97 8 104
19 26 81 29 54
19 26 80 8 6
19 26 79 73 6
19 26 78 69 70
19 26 63 62 104
19 27 96 8 112
19 27 81 23 46
19 27 80 8 6
19 27 79 73 6
19 27 78 69 70
19 28 96 8 96
19 28 82 59 112
19 28 80 23 46
19 28 79 8 6
19 28 78 73 6
19 28 77 69 86
19 29 96 59 102
19 29 82 59 102
19 29 79 23 46
19 29 78 8 6
19 29 77 23 78
19 30 96 73 46
19 30 95 59 86
19 30 84 59 54
19 30 83 59 22
19 30 82 73 6
19 30 81 73 86
19 30 78 23 110
19 31 95 73 46
19 31 94 59 22
19 31 93 59 22
19 31 92 59 86
19 31 86 59 54
19 31 85 59 22
19 31 84 73 6
19 31 83 73 6
19 31 82 73 6
19 31 81 74 70
19 32 94 73 46
19 32 93 73 14
19 32 92 73 6
19 32 91 73 22
19 32 90 73 22
19 32 89 73 22
19 32 88 73 22
19 32 87 73 22
19 32 86 73 6
19 32 85 73 6
19 32 84 73 6
19 32 83 74 6
19 32 82 74 6
19 32 81 74 78
19 33 92 74 46
19 33 91 74 14
19 33 90 74 14
19 33 89 74 14
19 33 88 74 14
19 33 87 74 14
19 33 86 74 14
19 33 85 74 14
19 33 84 74 14
19 33 83 74 14
19 33 82 74 78
20 5 102 33 48
20 5 101 33 80
20 5 65 33 48
20 5 64 33 80
20 6 102 33 40
20 6 101 33 72
20 6 65 33 40
20 6 64 33 72
20 13 104 50 48
20 13 103 50 24
20 13 102 50 24
20 13 101 50 24
20 13 100 50 24
20 13 99 50 24
20 13 98 50 24
20 13 97 50 24
20 13 96 50 24
20 13 95 50 24
20 13 94 50 24
20 13 93 50 24
20 13 92 50 24
20 13 91 50 24
20 13 90 50 24
20 13 89 50 24
20 13 88 50 24
20 13 87 50 24
20 13 86 50 24
20 13 85 50 24
20 13 84 50 24
20 13 83 50 24
20 13 82 50 24
20 13 81 50 24
20 13 80 50 24
20 13 79 50 24
20 13 78 50 24
20 13 77 50 24
20 13 76 50 24
20 13 75 50 24
20 13 74 50 24
20 13 73 50 24
20 13 72 50 24
20 13 71 50 24
20 13 70 50 24
20 13 69 50 24
20 13 68 50 24
20 13 67 50 24
20 13 66 50 24
20 13 65 50 24
20 13 64 50 24
20 13 63 50 24
20 13 62 50 80
20 14 105 52 56
20 14 104 50 64
20 14 62 50 32
20 14 61 52 88
20 15 104 50 96
20 15 62 50 96
20 16 104 50 96
20 16 62 50 96
20 17 104 50 96
20 17 62 50 96
20 18 104 50 96
20 18 62 50 96
20 19 104 50 96
20 19 62 50 96
20 20 105 52 56
20 20 104 50 64
20 20 62 50 32
20 20 61 52 88
20 21 104 50 96
20 21 62 50 96
20 22 104 50 40
20 22 103 50 16
20 22 102 50 24
20 22 101 50 16
20 22 100 50 24
20 22 99 50 16
20 22 98 50 24
20 22 97 50 16
20 22 96 50 24
20 22 95 50 16
20 22 94 50 16
20 22 93 50 16
20 22 92 50 16
20 22 91 45 16
20 22 90 45 24
20 22 89 45 16
20 22 88 45 16
20 22 87 45 24
20 22 86 50 16
20 22 85 50 16
20 22 84 50 16
20 22 83 50 16
20 22 82 50 16
20 22 81 50 16
20 22 80 50 16
20 22 79 50 16
20 22 78 50 16
20 22 77 50 24
20 22 76 50 16
20 22 75 50 16
20 22 74 50 16
20 22 73 50 16
20 22 72 50 24
20 22 71 50 16
20 22 70 50 16
20 22 69 50 16
20 22 68 50 16
20 22 67 50 24
20 22 66 50 16
20 22 65 50 24
20 22 64 50 16
20 22 63 50 16
20 22 62 50 72
20 23 103 62 96
20 23 101 61 110
20 23 99 61 110
20 23 97 70 110
20 23 95 45 42
20 23 94 45 8
20 23 93 45 10
20 23 92 45 8
20 23 91 61 76
20 23 89 89 40
20 23 88 89 72
20 23 86 29 44
20 23 85 29 8
20 23 84 29 10
20 23 83 89 0
20 23 82 70 12
20 23 81 89 8
20 23 80 89 12
20 23 79 89 8
20 23 78 61 74
20 23 76 61 40
20 23 75 61 8
20 23 74 89 8
20 23 73 61 64
20 23 71 61 46
20 23 70 61 12
20 23 69 89 10
20 23 68 89 76
20 23 66 61 104
20 23 64 89 44
20 23 63 62 64
20 24 103 62 96
20 24 96 45 114
20 24 83 29 96
20 24 73 61 110
20 24 63 62 96
20 25 103 62 96
20 25 96 29 108
20 25 83 29 46
20 25 82 29 82
20 25 63 62 96
20 26 103 62 104
20 26 97 10 122
20 26 82 29 102
20 26 63 62 104
20 27 96 10 114
20 27 82 23 102
20 28 96 10 106
20 28 82 10 106
20 29 95 10 62
20 29 94 23 86
20 29 84 10 60
20 29 83 10 94
20 30 94 10 46
20 30 93 10 30
20 30 92 10 94
20 30 86 10 60
20 30 85 10 94
20 31 91 10 62
20 31 90 10 30
20 31 89 10 30
20 31 88 10 30
20 31 87 10 94
21 5 102 33 48
21 5 101 33 80
21 5 65 33 48
21 5 64 33 80
21 6 102 33 40
21 6 101 33 72
21 6 65 33 40
21 6 64 33 72
21 13 104 50 48
21 13 103 50 24
21 13 102 50 24
21 13 101 50 24
21 13 100 50 24
21 13 99 50 24
21 13 98 50 24
21 13 97 50 24
21 13 96 50 24
21 13 95 50 24
21 13 94 50 24
21 13 93 50 24
21 13 92 50 24
21 13 91 50 24
21 13 90 50 24
21 13 89 50 24
21 13 88 50 24
21 13 87 50 24
21 13 86 50 24
21 13 85 50 24
21 13 84 50 24
21 13 83 50 24
21 13 82 50 24
21 13 81 50 24
21 13 80 50 24
21 13 79 50 24
21 13 78 50 24
21 13 77 50 24
21 13 76 50 24
21 13 75 50 24
21 13 74 50 24
21 13 73 50 24
21 13 72 50 24
21 13 71 50 24
21 13 70 50 24
21 13 69 50 24
21 13 68 50 24
21 13 67 50 24
21 13 66 50 24
21 13 65 50 24
21 13 64 50 24
21 13 63 50 24
21 13 62 50 80
21 14 105 52 56
21 14 104 50 64
21 14 62 50 32
21 14 61 52 88
21 15 104 50 96
21 15 62 50 96
21 16 104 50 96
21 16 62 50 96
21 17 104 50 96
21 17 62 50 96
21 18 104 50 96
21 18 62 50 96
21 19 104 50 96
21 19 62 50 96
21 20 105 52 56
21 20 104 50 64
21 20 62 50 32
21 20 61 52 88
21 21 104 50 96
21 21 62 50 96
21 22 104 50 40
21 22 103 50 16
21 22 102 50 16
21 22 101 50 24
21 22 100 50 16
21 22 99 50 24
21 22 98 50 16
21 22 97 50 24
21 22 96 50 16
21 22 95 50 24
21 22 94 50 16
21 22 93 50 24
21 22 92 50 16
21 22 91 50 16
21 22 90 50 16
21 22 89 50 16
21 22 88 50 16
21 22 87 50 16
21 22 86 50 16
21 22 85 50 16
21 22 84 50 24
21 22 83 50 16
21 22 82 50 16
21 22 81 50 16
21 22 80 50 16
21 22 79 50 16
21 22 78 50 24
21 22 77 50 16
21 22 76 50 16
21 22 75 50 16
21 22 74 50 16
21 22 73 50 16
21 22 72 50 16
21 22 71 50 24
21 22 70 50 16
21 22 69 50 24
21 22 68 50 16
21 22 67 50 16
21 22 66 50 16
21 22 65 50 16
21 22 64 50 16
21 22 63 50 16
21 22 62 50 72
21 23 103 62 32
21 23 102 61 78
21 23 100 61 110
21 23 98 89 100
21 23 96 61 108
21 23 94 89 96
21 23 92 29 32
21 23 91 29 2
21 23 90 29 4
21 23 89 29 2
21 23 88 29 0
21 23 87 29 4
21 23 86 29 0
21 23 85 61 64
21 23 83 89 32
21 23 82 89 8
21 23 81 61 8
21 23 80 89 8
21 23 79 89 72
21 23 77 89 44
21 23 76 61 10
21 23 75 61 8
21 23 74 89 10
21 23 73 89 8
21 23 72 61 68
21 23 70 61 104
21 23 68 89 40
21 23 67 61 12
21 23 66 61 8
21 23 65 89 12
21 23 64 89 10
21 23 63 62 64
21 24 103 62 96
21 24 98 61 110
21 24 95 29 54
21 24 94 29 6
21 24 93 29 22
21 24 92 29 6
21 24 91 29 14
21 24 90 29 14
21 24 89 29 14
21 24 88 29 6
21 24 87 29 6
21 24 86 29 4
21 24 85 29 6
21 24 84 29 22
21 24 83 61 74
21 24 72 61 110
21 24 63 62 96
21 25 103 62 96
21 25 96 29 50
21 25 95 29 6
21 25 94 29 6
21 25 93 29 6
21 25 92 29 78
21 25 88 23 38
21 25 87 29 6
21 25 86 29 6
21 25 85 29 6
21 25 84 29 70
21 25 63 62 96
21 26 103 62 104
21 26 96 23 46
21 26 95 23 6
21 26 94 23 6
21 26 93 23 70
21 26 88 23 38
21 26 87 23 6
21 26 86 23 6
21 26 85 23 6
21 26 84 23 6
21 26 83 23 86
21 26 63 62 104
21 27 95 23 38
21 27 94 2 6
21 27 93 23 70
21 27 88 23 38
21 27 87 23 6
21 27 86 23 6
21 27 85 23 6
21 27 84 23 6
21 27 83 23 70
21 28 95 23 46
21 28 94 23 14
21 28 93 23 6
21 28 92 23 86
21 28 88 23 38
21 28 87 23 6
21 28 86 23 6
21 28 85 23 6
21 28 84 23 6
21 28 83 23 78
21 29 93 23 46
21 29 92 23 14
21 29 91 23 22
21 29 90 23 22
21 29 89 23 22
21 29 88 23 6
21 29 87 23 6
21 29 86 23 6
21 29 85 23 14
21 29 84 23 74
21 30 91 23 46
21 30 90 23 14
21 30 89 23 14
21 30 88 23 14
21 30 87 23 14
21 30 86 23 74
22 5 102 33 48
22 5 101 33 80
22 5 65 33 48
22 5 64 33 80
22 6 102 33 40
22 6 101 33 72
22 6 65 33 40
22 6 64 33 72
22 13 104 50 48
22 13 103 50 24
22 13 102 50 24
22 13 101 50 24
22 13 100 50 24
22 13 99 50 24
22 13 98 50 24
22 13 97 50 24
22 13 96 50 24
22 13 95 50 24
22 13 94 50 24
22 13 93 50 24
22 13 92 50 24
22 13 91 50 24
22 13 90 50 24
22 13 89 50 24
22 13 88 50 24
22 13 87 50 24
22 13 86 50 24
22 13 85 50 24
22 13 84 50 24
22 13 83 50 24
22 13 82 50 24
22 13 81 50 24
22 13 80 50 24
22 13 79 50 24
22 13 78 50 24
22 13 77 50 24
22 13 76 50 24
22 13 75 50 24
22 13 74 50 24
22 13 73 50 24
22 13 72 50 24
22 13 71 50 24
22 13 70 50 24
22 13 69 50 24
22 13 68 50 24
22 13 67 50 24
22 13 66 50 24
22 13 65 50 24
22 13 64 50 24
22 13 63 50 24
22 13 62 50 80
22 14 105 52 56
22 14 104 50 64
22 14 62 50 32
22 14 61 52 88
22 15 104 50 96
22 15 62 50 96
22 16 104 50 96
22 16 62 50 96
22 17 104 50 96
22 17 62 50 96
22 18 104 50 96
22 18 62 50 96
22 19 104 50 96
22 19 62 50 96
22 20 105 52 56
22 20 104 50 64
22 20 62 50 32
22 20 61 52 88
22 21 104 50 96
22 21 62 50 96
22 22 104 50 40
22 22 103 50 16
22 22 102 50 24
22 22 101 50 16
22 22 100 50 24
22 22 99 50 24
22 22 98 50 16
22 22 97 50 24
22 22 96 50 16
22 22 95 50 24
22 22 94 50 16
22 22 93 50 16
22 22 92 50 16
22 22 91 50 24
22 22 90 50 16
22 22 89 50 24
22 22 88 50 16
22 22 87 50 16
22 22 86 50 16
22 22 85 50 16
22 22 84 50 24
22 22 83 50 16
22 22 82 50 16
22 22 81 50 16
22 22 80 50 16
22 22 79 50 16
22 22 78 50 16
22 22 77 50 16
22 22 76 50 24
22 22 75 50 16
22 22 74 50 24
22 22 73 50 16
22 22 72 50 16
22 22 71 50 16
22 22 70 50 16
22 22 69 50 16
22 22 68 50 16
22 22 67 50 16
22 22 66 50 16
22 22 65 50 16
22 22 64 50 24
22 22 63 50 16
22 22 62 50 72
22 23 103 62 96
22 23 101 61 102
22 23 98 89 106
22 23 96 89 104
22 23 94 70 40
22 23 93 89 14
22 23 92 89 72
22 23 90 89 106
22 23 88 61 40
22 23 87 89 8
22 23 86 61 2
22 23 85 61 72
22 23 83 89 42
22 23 82 61 8
22 23 81 89 8
22 23 80 89 10
22 23 79 70 8
22 23 78 89 14
22 23 77 89 72
22 23 75 61 104
22 23 73 61 40
22 23 72 61 8
22 23 71 61 14
22 23 70 61 8
22 23 69 89 12
22 23 68 61 10
22 23 67 89 8
22 23 66 61 8
22 23 65 89 72
22 23 63 62 96
22 24 103 62 96
22 24 101 89 110
22 24 86 89 106
22 24 63 62 96
22 25 103 62 96
22 25 91 23 54
22 25 90 23 22
22 25 89 23 84
22 25 63 62 96
22 26 103 62 104
22 26 92 23 54
22 26 91 23 6
22 26 90 23 6
22 26 89 23 68
22 26 63 62 104
22 27 92 29 46
22 27 91 23 6
22 27 90 23 6
22 27 89 23 68
22 27 75 73 60
22 27 74 73 28
22 27 73 73 28
22 27 72 73 28
22 27 71 73 28
22 27 70 73 28
22 27 69 73 28
22 27 68 73 28
22 27 67 73 94
22 28 91 29 46
22 28 90 29 14
22 28 89 29 76
23 5 102 33 48
23 5 101 33 80
23 5 65 33 48
23 5 64 33 80
23 6 102 33 40
23 6 101 33 72
23 6 65 33 40
23 6 64 33 72
23 13 104 50 48
23 13 103 50 24
23 13 102 50 24
23 13 101 50 24
23 13 100 50 24
23 13 99 50 24
23 13 98 50 24
23 13 97 50 24
23 13 96 50 24
23 13 95 50 24
23 13 94 50 24
23 13 93 50 24
23 13 92 50 24
23 13 91 50 24
23 13 90 50 24
23 13 89 50 24
23 13 88 50 24
23 13 87 50 24
23 13 86 50 24
23 13 85 50 24
23 13 84 50 24
23 13 83 50 24
23 13 82 50 24
23 13 81 50 24
23 13 80 50 24
23 13 79 50 24
23 13 78 50 24
23 13 77 50 24
23 13 76 50 24
23 13 75 50 24
23 13 74 50 24
23 13 73 50 24
23 13 72 50 24
23 13 71 50 24
23 13 70 50 24
23 13 69 50 24
23 13 68 50 24
23 13 67 50 24
23 13 66 50 24
23 13 65 50 24
23 13 64 50 24
23 13 63 50 24
23 13 62 50 80
23 14 105 52 56
23 14 104 50 64
23 14 62 50 32
23 14 61 52 88
23 15 104 50 96
23 15 62 50 96
23 16 104 50 96
23 16 62 50 96
23 17 104 50 96
23 17 62 50 96
23 18 104 50 96
23 18 62 50 96
23 19 104 50 96
23 19 62 50 96
23 20 105 52 56
23 20 104 50 64
23 20 62 50 32
23 20 61 52 88
23 21 104 50 96
23 21 62 50 96
23 22 104 50 40
23 22 103 50 16
23 22 102 50 16
23 22 101 50 24
23 22 100 50 16
23 22 99 50 16
23 22 98 50 24
23 22 97 50 16
23 22 96 50 16
23 22 95 50 24
23 22 94 50 16
23 22 93 50 24
23 22 92 50 16
23 22 91 50 24
23 22 90 50 24
23 22 89 50 16
23 22 88 50 16
23 22 87 50 16
23 22 86 50 24
23 22 85 50 16
23 22 84 50 16
23 22 83 50 24
23 22 82 50 16
23 22 81 50 16
23 22 80 50 24
23 22 79 50 16
23 22 78 50 24
23 22 77 50 16
23 22 76 50 16
23 22 75 50 16
23 22 74 50 16
23 22 73 50 16
23 22 72 50 16
23 22 71 50 24
23 22 70 50 16
23 22 69 50 16
23 22 68 50 24
23 22 67 50 16
23 22 66 50 16
23 22 65 50 16
23 22 64 50 16
23 22 63 50 16
23 22 62 50 72
23 23 103 62 32
23 23 102 61 78
23 23 100 89 46
23 23 99 61 76
23 23 97 61 46
23 23 96 70 74
23 23 94 61 96
23 23 92 89 96
23 23 89 61 46
23 23 88 61 8
23 23 87 61 66
23 23 85 89 42
23 23 84 61 76
23 23 82 61 32
23 23 81 70 74
23 23 79 61 96
23 23 77 89 32
23 23 76 61 14
23 23 75 61 8
23 23 74 61 14
23 23 73 61 8
23 23 72 89 64
23 23 70 61 42
23 23 69 61 72
23 23 67 61 32
23 23 66 89 8
23 23 65 89 8
23 23 64 89 14
23 23 63 62 64
23 24 103 62 96
23 24 94 61 110
23 24 92 61 110
23 24 87 61 110
23 24 82 61 110
23 24 79 61 110
23 24 77 61 110
23 24 72 61 110
23 24 67 61 108
23 24 63 62 96
23 25 103 62 96
23 25 89 23 50
23 25 88 23 86
23 25 63 62 96
23 26 103 62 104
23 26 89 23 34
23 26 88 23 6
23 26 87 23 22
23 26 86 23 86
23 26 63 62 104
23 27 89 23 34
23 27 88 23 6
23 27 87 23 6
23 27 86 29 78
23 27 75 73 50
23 27 74 73 18
23 27 73 73 18
23 27 72 73 18
23 27 71 73 18
23 27 70 73 18
23 27 69 73 18
23 27 68 73 90
23 28 89 29 42
23 28 88 29 14
23 28 87 29 78
23 28 76 80 60
23 28 75 80 12
23 28 74 80 12
23 28 73 80 12
23 28 72 80 12
23 28 71 80 14
23 28 70 80 14
23 28 69 80 78
24 5 102 33 48
24 5 101 33 80
24 5 65 33 48
24 5 64 33 80
24 6 102 33 40
24 6 101 33 72
24 6 65 33 40
24 6 64 33 72
24 13 104 50 48
24 13 103 50 24
24 13 102 50 24
24 13 101 50 24
24 13 100 50 24
24 13 99 50 24
24 13 98 50 24
24 13 97 50 24
24 13 96 50 24
24 13 95 50 24
24 13 94 50 24
24 13 93 50 24
24 13 92 50 24
24 13 91 50 24
24 13 90 50 24
24 13 89 50 24
24 13 88 50 24
24 13 87 50 24
24 13 86 50 24
24 13 85 50 24
24 13 84 50 24
24 13 83 50 24
24 13 82 50 24
24 13 81 50 24
24 13 80 50 24
24 13 79 50 24
24 13 78 50 24
24 13 77 50 24
24 13 76 50 24
24 13 75 50 24
24 13 74 50 24
24 13 73 50 24
24 13 72 50 24
24 13 71 50 24
24 13 70 50 24
24 13 69 50 24
24 13 68 50 24
24 13 67 50 24
24 13 66 50 24
24 13 65 50 24
24 13 64 50 24
24 13 63 50 24
24 13 62 50 80
24 14 105 52 56
24 14 104 50 64
24 14 62 50 32
24 14 61 52 88
24 15 104 50 96
24 15 62 50 96
24 16 104 50 96
24 16 62 50 96
24 17 104 50 96
24 17 62 50 96
24 18 104 50 96
24 18 62 50 96
24 19 104 50 96
24 19 62 50 96
24 20 105 52 56
24 20 104 50 64
24 20 62 50 32
24 20 61 52 88
24 21 104 50 96
24 21 62 50 96
24 22 104 50 40
24 22 103 50 16
24 22 102 50 24
24 22 101 50 16
24 22 100 50 24
24 22 99 50 16
24 22 98 50 16
24 22 97 50 24
24 22 96 50 24
24 22 95 50 16
24 22 94 50 16
24 22 93 50 24
24 22 92 50 16
24 22 91 50 24
24 22 90 50 16
24 22 89 50 24
24 22 88 50 16
24 22 87 50 24
24 22 86 50 16
24 22 85 50 24
24 22 84 50 16
24 22 83 50 16
24 22 82 50 16
24 22 81 50 24
24 22 80 50 16
24 22 79 50 16
24 22 78 50 24
24 22 77 50 16
24 22 76 50 24
24 22 75 50 16
24 22 74 50 24
24 22 73 50 16
24 22 72 50 16
24 22 71 50 16
24 22 70 50 24
24 22 69 50 16
24 22 68 50 16
24 22 67 50 16
24 22 66 50 16
24 22 65 50 16
24 22 64 50 24
24 22 63 50 16
24 22 62 50 72
24 23 103 62 96
24 23 101 89 110
24 23 99 61 42
24 23 98 89 78
24 23 95 61 46
24 23 94 89 74
24 23 92 61 106
24 23 90 89 108
24 23 88 61 106
24 23 86 89 108
24 23 84 61 40
24 23 83 89 12
24 23 82 89 72
24 23 80 61 46
24 23 79 89 72
24 23 77 61 104
24 23 75 61 104
24 23 73 61 34
24 23 72 61 8
24 23 71 61 76
24 23 69 61 40
24 23 68 89 12
24 23 67 61 2
24 23 66 61 8
24 23 65 89 74
24 23 63 62 96
24 24 103 62 96
24 24 73 61 110
24 24 67 61 106
24 24 63 62 96
24 25 103 62 96
24 25 63 62 96
24 26 103 62 104
24 26 63 62 104
24 28 76 73 50
24 28 75 73 18
24 28 74 73 18
24 28 73 73 18
24 28 72 73 82
24 29 77 81 60
24 29 76 81 12
24 29 75 81 12
24 29 74 81 12
24 29 73 81 12
24 29 72 81 78
25 5 102 33 48
25 5 101 33 80
25 5 65 33 48
25 5 64 33 80
25 6 102 33 40
25 6 101 33 72
25 6 65 33 40
25 6 64 33 72
25 13 104 50 48
25 13 103 50 24
25 13 102 50 24
25 13 101 50 24
25 13 100 50 24
25 13 99 50 24
25 13 98 50 24
25 13 97 50 24
25 13 96 50 24
25 13 95 50 24
25 13 94 50 24
25 13 93 50 24
25 13 92 50 24
25 13 91 50 24
25 13 90 50 24
25 13 89 50 24
25 13 88 50 24
25 13 87 50 24
25 13 86 50 24
25 13 85 50 24
25 13 84 50 24
25 13 83 50 24
25 13 82 50 24
25 13 81 50 24
25 13 80 50 24
25 13 79 50 24
25 13 78 50 24
25 13 77 50 24
25 13 76 50 24
25 13 75 50 24
25 13 74 50 24
25 13 73 50 24
25 13 72 50 24
25 13 71 50 24
25 13 70 50 24
25 13 69 50 24
25 13 68 50 24
25 13 67 50 24
25 13 66 50 24
25 13 65 50 24
25 13 64 50 24
25 13 63 50 24
25 13 62 50 80
25 14 105 52 56
25 14 104 50 64
25 14 62 50 32
25 14 61 52 88
25 15 104 50 96
25 15 62 50 96
25 16 104 50 96
25 16 62 50 96
25 17 104 50 96
25 17 62 50 96
25 18 104 50 96
25 18 62 50 96
25 19 104 50 96
25 19 62 50 96
25 20 105 52 56
25 20 104 50 64
25 20 62 50 32
25 20 61 52 88
25 21 104 50 96
25 21 62 50 96
25 22 104 50 40
25 22 103 50 16
25 22 102 50 16
25 22 101 50 24
25 22 100 50 16
25 22 99 50 24
25 22 98 50 24
25 22 97 50 16
25 22 96 50 16
25 22 95 50 24
25 22 94 50 24
25 22 93 50 16
25 22 92 50 24
25 22 91 50 16
25 22 90 50 16
25 22 89 50 24
25 22 88 50 24
25 22 87 50 16
25 22 86 50 16
25 22 85 50 16
25 22 84 50 16
25 22 83 50 16
25 22 82 50 16
25 22 81 50 16
25 22 80 50 24
25 22 79 50 16
25 22 78 50 16
25 22 77 50 16
25 22 76 50 16
25 22 75 50 16
25 22 74 50 16
25 22 73 50 24
25 22 72 50 16
25 22 71 50 16
25 22 70 50 16
25 22 69 50 16
25 22 68 50 16
25 22 67 50 24
25 22 66 50 16
25 22 65 50 24
25 22 64 50 16
25 22 63 50 16
25 22 62 50 72
25 23 103 62 32
25 23 102 89 78
25 23 100 61 108
25 23 97 61 46
25 23 96 89 78
25 23 93 61 108
25 23 91 89 46
25 23 90 89 72
25 23 87 89 46
25 23 86 89 8
25 23 85 61 12
25 23 84 89 8
25 23 83 61 8
25 23 82 61 10
25 23 81 89 76
25 23 79 89 42
25 23 78 61 12
25 23 77 89 8
25 23 76 61 14
25 23 75 89 8
25 23 74 61 76
25 23 72 61 40
25 23 71 61 8
25 23 70 61 4
25 23 69 89 10
25 23 68 61 72
25 23 66 61 104
25 23 64 89 46
25 23 63 62 64
25 24 103 62 96
25 24 70 61 110
25 24 63 62 96
25 25 103 62 96
25 25 63 62 96
25 26 103 62 104
25 26 63 62 104
25 29 77 81 50
25 29 76 81 18
25 29 75 81 18
25 29 74 81 18
25 29 73 81 82
25 30 77 84 38
25 30 76 84 6
25 30 75 84 6
25 30 74 84 14
25 30 73 84 78
25 31 78 85 60
25 31 77 85 12
25 31 76 85 12
25 31 75 85 76
26 5 102 33 48
26 5 101 33 80
26 5 65 33 48
26 5 64 33 80
26 6 102 33 40
26 6 101 33 72
26 6 65 33 40
26 6 64 33 72
26 13 104 50 48
26 13 103 50 24
26 13 102 50 24
26 13 101 50 24
26 13 100 50 24
26 13 99 50 24
26 13 98 50 24
26 13 97 50 24
26 13 96 50 24
26 13 95 50 24
26 13 94 50 24
26 13 93 50 24
26 13 92 50 24
26 13 91 50 24
26 13 90 50 24
26 13 89 50 24
26 13 88 50 24
26 13 87 50 24
26 13 86 50 24
26 13 85 50 24
26 13 84 50 24
26 13 83 50 24
26 13 82 50 24
26 13 81 50 24
26 13 80 50 24
26 13 79 50 24
26 13 78 50 24
26 13 77 50 24
26 13 76 50 24
26 13 75 50 24
26 13 74 50 24
26 13 73 50 24
26 13 72 50 24
26 13 71 50 24
26 13 70 50 24
26 13 69 50 24
26 13 68 50 24
26 13 67 50 24
26 13 66 50 24
26 13 65 50 24
26 13 64 50 24
26 13 63 50 24
26 13 62 50 80
26 14 105 52 56
26 14 104 50 64
26 14 62 50 32
26 14 61 52 88
26 15 104 50 96
26 15 62 50 96
26 16 104 50 96
26 16 62 50 96
26 17 104 50 96
26 17 62 50 96
26 18 104 50 96
26 18 62 50 96
26 19 104 50 96
26 19 62 50 96
26 20 105 52 56
26 20 104 50 64
26 20 62 50 32
26 20 61 52 88
26 21 104 50 96
26 21 62 50 96
26 22 104 50 40
26 22 103 50 16
26 22 102 50 24
26 22 101 50 16
26 22 100 50 16
26 22 99 50 16
26 22 98 50 16
26 22 97 50 24
26 22 96 50 24
26 22 95 50 16
26 22 94 50 24
26 22 93 50 16
26 22 92 50 16
26 22 91 50 24
26 22 90 50 16
26 22 89 50 16
26 22 88 50 16
26 22 87 50 24
26 22 86 50 16
26 22 85 50 16
26 22 84 50 16
26 22 83 50 16
26 22 82 50 24
26 22 81 50 16
26 22 80 50 16
26 22 79 50 24
26 22 78 50 16
26 22 77 50 16
26 22 76 50 24
26 22 75 50 16
26 22 74 50 16
26 22 73 50 16
26 22 72 50 16
26 22 71 50 16
26 22 70 50 16
26 22 69 50 24
26 22 68 50 16
26 22 67 50 24
26 22 66 50 16
26 22 65 50 16
26 22 64 50 24
26 22 63 50 16
26 22 62 50 72
26 23 103 62 96
26 23 101 89 46
26 23 100 89 8
26 23 99 61 14
26 23 98 61 76
26 23 95 61 108
26 23 93 61 40
26 23 92 89 78
26 23 90 61 40
26 23 89 61 14
26 23 88 61 76
26 23 86 89 40
26 23 85 89 8
26 23 84 61 8
26 23 83 61 72
26 23 81 61 32
26 23 80 61 76
26 23 78 61 40
26 23 77 89 72
26 23 75 89 32
26 23 74 61 10
26 23 73 61 12
26 23 72 89 10
26 23 71 61 8
26 23 70 61 74
26 23 68 89 106
26 23 66 89 32
26 23 65 89 78
26 23 63 62 96
26 24 103 62 96
26 24 81 61 110
26 24 79 61 126
26 24 75 61 110
26 24 66 61 110
26 24 64 61 62
26 24 63 62 64
26 25 103 62 96
26 25 63 62 96
26 26 103 62 104
26 26 63 62 104
26 31 78 85 58
26 31 77 85 26
26 31 76 85 26
26 31 75 85 90
27 5 102 33 48
27 5 101 33 80
27 5 65 33 48
27 5 64 33 80
27 6 102 33 40
27 6 101 33 72
27 6 65 33 40
27 6 64 33 72
27 13 104 50 48
27 13 103 50 24
27 13 102 50 24
27 13 101 50 24
27 13 100 50 24
27 13 99 50 24
27 13 98 50 24
27 13 97 50 24
27 13 96 50 24
27 13 95 50 24
27 13 94 50 24
27 13 93 50 24
27 13 92 50 24
27 13 91 50 24
27 13 90 50 24
27 13 89 50 24
27 13 88 50 24
27 13 87 50 24
27 13 86 50 24
27 13 85 50 24
27 13 84 50 24
27 13 83 50 24
27 13 82 50 24
27 13 81 50 24
27 13 80 50 24
27 13 79 50 24
27 13 78 50 24
27 13 77 50 24
27 13 76 50 24
27 13 75 50 24
27 13 74 50 24
27 13 73 50 24
27 13 72 50 24
27 13 71 50 24
27 13 70 50 24
27 13 69 50 24
27 13 68 50 24
27 13 67 50 24
27 13 66 50 24
27 13 65 50 24
27 13 64 50 24
27 13 63 50 24
27 13 62 50 80
27 14 105 52 56
27 14 104 50 64
27 14 62 50 32
27 14 61 52 88
27 15 104 50 96
27 15 62 50 96
27 16 104 50 96
27 16 62 50 96
27 17 104 50 96
27 17 62 50 96
27 18 104 50 96
27 18 62 50 96
27 19 104 50 96
27 19 62 50 96
27 20 105 52 56
27 20 104 50 64
27 20 62 50 32
27 20 61 52 88
27 21 104 50 96
27 21 62 50 96
27 22 104 50 40
27 22 103 50 16
27 22 102 50 16
27 22 101 50 24
27 22 100 50 16
27 22 99 50 24
27 22 98 50 16
27 22 97 50 24
27 22 96 50 16
27 22 95 50 16
27 22 94 50 24
27 22 93 50 16
27 22 92 50 24
27 22 91 50 24
27 22 90 50 16
27 22 89 50 24
27 22 88 50 16
27 22 87 50 16
27 22 86 50 16
27 22 85 50 16
27 22 84 50 16
27 22 83 50 16
27 22 82 50 16
27 22 81 50 16
27 22 80 50 16
27 22 79 50 16
27 22 78 50 16
27 22 77 50 16
27 22 76 50 16
27 22 75 50 16
27 22 74 50 24
27 22 73 50 16
27 22 72 50 24
27 22 71 50 16
27 22 70 50 24
27 22 69 50 16
27 22 68 50 24
27 22 67 50 16
27 22 66 50 16
27 22 65 50 24
27 22 64 50 16
27 22 63 50 16
27 22 62 50 72
27 23 103 62 32
27 23 102 89 68
27 23 100 89 104
27 23 98 89 106
27 23 96 61 46
27 23 95 89 74
27 23 93 89 106
27 23 90 89 106
27 23 88 89 42
27 23 87 89 4
27 23 86 61 10
27 23 85 89 8
27 23 84 61 8
27 23 83 89 10
27 23 82 61 12
27 23 81 61 10
27 23 80 89 8
27 23 79 89 12
27 23 78 89 10
27 23 77 89 8
27 23 76 89 12
27 23 75 89 74
27 23 73 89 106
27 23 71 89 106
27 23 69 89 108
27 23 67 89 44
27 23 66 61 74
27 23 64 89 46
27 23 63 62 64
27 24 103 62 32
27 24 102 61 78
27 24 87 61 110
27 24 74 61 126
27 24 70 61 126
27 24 63 62 96
27 25 103 62 96
27 25 63 62 96
27 26 103 62 104
27 26 77 68 54
27 26 76 64 22
27 26 75 68 86
27 26 63 62 104
27 27 79 68 54
27 27 78 68 22
27 27 77 68 6
27 27 76 64 6
27 27 75 68 6
27 27 74 68 22
27 27 73 68 86
27 28 79 68 38
27 28 78 68 6
27 28 77 68 6
27 28 76 64 6
27 28 75 68 6
27 28 74 68 6
27 28 73 68 70
27 29 80 68 54
27 29 79 68 6
27 29 78 68 6
27 29 77 68 6
27 29 76 64 6
27 29 75 68 6
27 29 74 68 6
27 29 73 68 6
27 29 72 68 86
27 30 80 68 38
27 30 79 68 6
27 30 78 68 14
27 30 77 68 14
27 30 76 64 14
27 30 75 68 14
27 30 74 68 6
27 30 73 68 6
27 30 72 68 70
27 31 80 68 46
27 31 79 68 70
27 31 74 68 38
27 31 73 68 6
27 31 72 68 78
27 32 79 68 38
27 32 78 68 22
27 32 77 68 22
27 32 76 64 22
27 32 75 68 22
27 32 74 68 6
27 32 73 68 70
27 33 79 68 46
27 33 78 68 14
27 33 77 68 6
27 33 76 64 6
27 33 75 68 6
27 33 74 68 14
27 33 73 68 78
27 34 77 68 46
27 34 76 64 14
27 34 75 68 78
28 5 102 33 48
28 5 101 33 80
28 5 65 33 48
28 5 64 33 80
28 6 102 33 40
28 6 101 33 72
28 6 65 33 40
28 6 64 33 72
28 13 104 50 48
28 13 103 50 24
28 13 102 50 24
28 13 101 50 24
28 13 100 50 24
28 13 99 50 24
28 13 98 50 24
28 13 97 50 24
28 13 96 50 24
28 13 95 50 24
28 13 94 50 24
28 13 93 50 24
28 13 92 50 24
28 13 91 50 24
28 13 90 50 24
28 13 89 50 24
28 13 88 50 24
28 13 87 50 24
28 13 86 50 24
28 13 85 50 24
28 13 84 50 24
28 13 83 50 24
28 13 82 50 24
28 13 81 50 24
28 13 80 50 24
28 13 79 50 24
28 13 78 50 24
28 13 77 50 24
28 13 76 50 24
28 13 75 50 24
28 13 74 50 24
28 13 73 50 24
28 13 72 50 24
28 13 71 50 24
28 13 70 50 24
28 13 69 50 24
28 13 68 50 24
28 13 67 50 24
28 13 66 50 24
28 13 65 50 24
28 13 64 50 24
28 13 63 50 24
28 13 62 50 80
28 14 105 52 56
28 14 104 50 64
28 14 62 50 32
28 14 61 52 88
28 15 104 50 96
28 15 62 50 96
28 16 104 50 96
28 16 62 50 96
28 17 104 50 96
28 17 62 50 96
28 18 104 50 96
28 18 62 50 96
28 19 104 50 96
28 19 62 50 96
28 20 105 52 56
28 20 104 50 64
28 20 62 50 32
28 20 61 52 88
28 21 104 50 96
28 21 62 50 96
28 22 104 50 40
28 22 103 50 16
28 22 102 50 16
28 22 101 50 24
28 22 100 50 16
28 22 99 50 24
28 22 98 50 24
28 22 97 50 16
28 22 96 50 24
28 22 95 50 24
28 22 94 50 16
28 22 93 50 24
28 22 92 50 16
28 22 91 50 16
28 22 90 50 24
28 22 89 50 16
28 22 88 50 24
28 22 87 50 16
28 22 86 50 24
28 22 85 50 16
28 22 84 50 16
28 22 83 50 24
28 22 82 50 16
28 22 81 50 24
28 22 80 50 16
28 22 79 50 16
28 22 78 50 24
28 22 77 50 16
28 22 76 50 16
28 22 75 50 24
28 22 74 50 16
28 22 73 50 24
28 22 72 50 16
28 22 71 50 24
28 22 70 50 16
28 22 69 50 16
28 22 68 50 24
28 22 67 50 16
28 22 66 50 24
28 22 65 50 16
28 22 64 50 24
28 22 63 50 16
28 22 62 50 72
28 23 103 62 32
28 23 102 89 72
28 23 100 89 96
28 23 97 61 110
28 23 94 61 110
28 23 92 61 44
28 23 91 89 78
28 23 89 89 110
28 23 87 89 104
28 23 85 89 32
28 23 84 61 72
28 23 82 61 106
28 23 80 89 40
28 23 79 61 72
28 23 77 61 40
28 23 76 89 64
28 23 74 89 110
28 23 72 61 110
28 23 70 61 44
28 23 69 61 74
28 23 67 61 104
28 23 65 89 110
28 23 63 62 96
28 24 103 62 96
28 24 100 89 110
28 24 85 89 110
28 24 76 68 102
28 24 63 62 96
28 25 103 62 96
28 25 79 64 54
28 25 78 68 22
28 25 77 68 30
28 25 76 64 14
28 25 75 64 30
28 25 74 68 22
28 25 73 68 86
28 25 63 62 96
28 26 103 62 104
28 26 80 64 54
28 26 79 64 14
28 26 78 68 78
28 26 74 68 46
28 26 73 68 14
28 26 72 68 86
28 26 63 62 104
28 27 81 68 54
28 27 80 64 70
28 27 72 68 38
28 27 71 68 86
28 28 81 64 38
28 28 80 64 78
28 28 72 68 46
28 28 71 68 70
28 29 81 64 102
28 29 71 68 102
28 30 82 68 62
28 30 81 64 70
28 30 71 68 38
28 30 70 64 94
28 31 81 64 102
28 31 71 64 102
28 32 81 64 38
28 32 80 68 86
28 32 72 68 54
28 32 71 64 70
28 33 81 64 46
28 33 80 68 70
28 33 72 68 38
28 33 71 64 78
28 34 80 68 46
28 34 79 68 22
28 34 78 68 86
28 34 74 68 54
28 34 73 68 22
28 34 72 64 78
28 35 79 68 46
28 35 78 68 14
28 35 77 64 30
28 35 76 64 22
28 35 75 68 30
28 35 74 68 14
28 35 73 68 78
28 36 76 64 110
29 5 102 33 48
29 5 101 33 80
29 5 65 33 48
29 5 64 33 80
29 6 102 33 40
29 6 101 33 72
29 6 65 33 40
29 6 64 33 72
29 13 104 50 48
29 13 103 50 24
29 13 102 50 24
29 13 101 50 24
29 13 100 50 24
29 13 99 50 24
29 13 98 50 24
29 13 97 50 24
29 13 96 50 24
29 13 95 50 24
29 13 94 50 24
29 13 93 50 24
29 13 92 50 24
29 13 91 50 24
29 13 90 50 24
29 13 89 50 24
29 13 88 50 24
29 13 87 50 24
29 13 86 50 24
29 13 85 50 24
29 13 84 50 24
29 13 83 50 24
29 13 82 50 24
29 13 81 50 24
29 13 80 50 24
29 13 79 50 24
29 13 78 50 24
29 13 77 50 24
29 13 76 50 24
29 13 75 50 24
29 13 74 50 24
29 13 73 50 24
29 13 72 50 24
29 13 71 50 24
29 13 70 50 24
29 13 69 50 24
29 13 68 50 24
29 13 67 50 24
29 13 66 50 24
29 13 65 50 24
29 13 64 50 24
29 13 63 50 24
29 13 62 50 80
29 14 105 52 56
29 14 104 50 64
29 14 62 50 32
29 14 61 52 88
29 15 104 50 96
29 15 62 50 96
29 16 104 50 96
29 16 62 50 96
29 17 104 50 96
29 17 62 50 96
29 18 104 50 96
29 18 62 50 96
29 19 104 50 96
29 19 62 50 96
29 20 105 52 56
29 20 104 50 64
29 20 62 50 32
29 20 61 52 88
29 21 104 50 96
29 21 62 50 96
29 22 104 50 40
29 22 103 50 16
29 22 102 50 16
29 22 101 50 24
29 22 100 50 16
29 22 99 50 16
29 22 98 50 16
29 22 97 50 24
29 22 96 50 16
29 22 95 50 16
29 22 94 50 24
29 22 93 50 16
29 22 92 50 16
29 22 91 50 24
29 22 90 50 16
29 22 89 50 24
29 22 88 50 24
29 22 87 50 16
29 22 86 50 16
29 22 85 50 16
29 22 84 50 16
29 22 83 50 16
29 22 82 50 24
29 22 81 50 16
29 22 80 50 16
29 22 79 50 16
29 22 78 50 16
29 22 77 50 16
29 22 76 50 16
29 22 75 50 16
29 22 74 50 24
29 22 73 50 24
29 22 72 50 24
29 22 71 50 16
29 22 70 50 16
29 22 69 50 24
29 22 68 50 24
29 22 67 50 16
29 22 66 50 24
29 22 65 50 24
29 22 64 50 16
29 22 63 50 16
29 22 62 50 72
29 23 103 62 32
29 23 102 89 74
29 23 100 89 42
29 23 99 89 14
29 23 98 61 76
29 23 96 61 46
29 23 95 61 76
29 23 93 61 44
29 23 92 89 72
29 23 90 89 110
29 23 87 89 40
29 23 86 61 4
29 23 85 89 8
29 23 84 89 10
29 23 83 61 76
29 23 81 61 44
29 23 80 61 8
29 23 79 89 0
29 23 78 61 4
29 23 77 68 0
29 23 76 68 10
29 23 75 68 68
29 23 71 61 38
29 23 70 89 72
29 23 67 61 98
29 23 64 89 46
29 23 63 62 64
29 24 103 62 96
29 24 86 61 110
29 24 82 61 126
29 24 79 64 44
29 24 78 64 14
29 24 77 68 78
29 24 75 64 46
29 24 74 64 30
29 24 73 68 94
29 24 71 61 100
29 24 67 61 110
29 24 63 62 96
29 25 103 62 96
29 25 81 68 54
29 25 80 68 94
29 25 72 68 62
29 25 71 68 70
29 25 63 62 96
29 26 103 62 104
29 26 81 68 110
29 26 71 68 110
29 26 63 62 104
29 27 82 68 118
29 27 70 64 118
29 28 82 68 102
29 28 70 64 102
29 29 83 64 52
29 29 82 68 78
29 29 70 64 46
29 29 69 68 84
29 30 83 64 102
29 30 69 68 102
29 31 83 64 46
29 31 82 68 86
29 31 70 68 54
29 31 69 68 76
29 32 82 68 102
29 32 70 68 102
29 33 82 68 110
29 33 70 68 110
29 34 81 64 118
29 34 71 68 118
29 35 81 64 46
29 35 80 68 94
29 35 72 64 62
29 35 71 68 78
29 36 79 68 62
29 36 78 68 30
29 36 77 64 86
29 36 75 68 54
29 36 74 68 30
29 36 73 64 94
29 37 77 64 44
29 37 76 68 30
29 37 75 68 76
30 5 102 33 48
30 5 101 33 80
30 5 65 33 48
30 5 64 33 80
30 6 102 33 40
30 6 101 33 72
30 6 65 33 40
30 6 64 33 72
30 13 104 50 48
30 13 103 50 24
30 13 102 50 24
30 13 101 50 24
30 13 100 50 24
30 13 99 50 24
30 13 98 50 24
30 13 97 50 24
30 13 96 50 24
30 13 95 50 24
30 13 94 50 24
30 13 93 50 24
30 13 92 50 24
30 13 91 50 24
30 13 90 50 24
30 13 89 50 24
30 13 88 50 24
30 13 87 50 24
30 13 86 50 24
30 13 85 50 24
30 13 84 50 24
30 13 83 50 24
30 13 82 50 24
30 13 81 50 24
30 13 80 50 24
30 13 79 50 24
30 13 78 50 24
30 13 77 50 24
30 13 76 50 24
30 13 75 50 24
30 13 74 50 24
30 13 73 50 24
30 13 72 50 24
30 13 71 50 24
30 13 70 50 24
30 13 69 50 24
30 13 68 50 24
30 13 67 50 24
30 13 66 50 24
30 13 65 50 24
30 13 64 50 24
30 13 63 50 24
30 13 62 50 80
30 14 105 52 56
30 14 104 50 64
30 14 62 50 32
30 14 61 52 88
30 15 104 50 96
30 15 62 50 96
30 16 104 50 96
30 16 62 50 96
30 17 104 50 96
30 17 62 50 96
30 18 104 50 96
30 18 62 50 96
30 19 104 50 96
30 19 62 50 96
30 20 105 52 56
30 20 104 50 64
30 20 62 50 32
30 20 61 52 88
30 21 104 50 96
30 21 62 50 96
30 22 104 50 40
30 22 103 50 16
30 22 102 50 24
30 22 101 50 16
30 22 100 50 24
30 22 99 50 24
30 22 98 50 16
30 22 97 50 16
30 22 96 50 24
30 22 95 50 16
30 22 94 50 24
30 22 93 50 16
30 22 92 50 16
30 22 91 50 24
30 22 90 50 24
30 22 89 50 16
30 22 88 50 24
30 22 87 50 16
30 22 86 50 16
30 22 85 50 16
30 22 84 50 24
30 22 83 50 16
30 22 82 50 16
30 22 81 50 16
30 22 80 50 16
30 22 79 50 16
30 22 78 50 16
30 22 77 50 16
30 22 76 68 24
30 22 75 50 16
30 22 74 50 16
30 22 73 50 16
30 22 72 50 16
30 22 71 50 24
30 22 70 50 16
30 22 69 50 24
30 22 68 50 24
30 22 67 50 24
30 22 66 50 16
30 22 65 50 16
30 22 64 50 24
30 22 63 50 16
30 22 62 50 72
30 23 103 62 96
30 23 101 89 110
30 23 98 89 40
30 23 97 61 78
30 23 95 89 106
30 23 93 61 40
30 23 92 89 74
30 23 89 61 108
30 23 87 61 40
30 23 86 89 8
30 23 85 89 74
30 23 83 89 40
30 23 82 61 12
30 23 81 61 0
30 23 80 89 0
30 23 79 68 0
30 23 78 64 8
30 23 77 68 74
30 23 75 68 42
30 23 74 64 12
30 23 73 68 14
30 23 72 61 68
30 23 70 89 106
30 23 66 61 46
30 23 65 61 76
30 23 63 62 96
30 24 103 62 96
30 24 81 64 46
30 24 80 68 12
30 24 79 61 74
30 24 72 68 46
30 24 71 68 90
30 24 64 61 62
30 24 63 62 64
30 25 103 62 96
30 25 82 64 118
30 25 70 64 118
30 25 63 62 96
30 26 103 62 104
30 26 82 64 110
30 26 70 64 110
30 26 63 62 104
30 27 83 64 118
30 27 69 68 118
30 28 83 64 102
30 28 69 68 102
30 29 83 68 106
30 29 69 68 106
30 30 84 68 116
30 30 68 64 124
30 31 84 68 100
30 31 69 64 114
30 32 84 2 36
30 32 83 64 86
30 32 69 64 102
30 33 84 64 44
30 33 83 64 78
30 33 69 64 110
30 34 82 68 118
30 34 70 64 118
30 35 82 68 110
30 35 70 64 110
30 36 81 64 62
30 36 80 68 94
30 36 72 68 62
30 36 71 68 94
30 37 79 68 62
30 37 78 68 30
30 37 77 64 90
30 37 75 68 58
30 37 74 68 30
30 37 73 64 94
30 38 76 68 124
31 5 102 33 48
31 5 101 33 80
31 5 65 33 48
31 5 64 33 80
31 6 102 33 40
31 6 101 33 72
31 6 65 33 40
31 6 64 33 72
31 13 104 50 48
31 13 103 50 24
31 13 102 50 24
31 13 101 50 24
31 13 100 50 24
31 13 99 50 24
31 13 98 50 24
31 13 97 50 24
31 13 96 50 24
31 13 95 50 24
31 13 94 50 24
31 13 93 50 24
31 13 92 50 24
31 13 91 50 24
31 13 90 50 24
31 13 89 50 24
31 13 88 50 24
31 13 87 50 24
31 13 86 50 24
31 13 85 50 24
31 13 84 50 24
31 13 83 50 24
31 13 82 50 24
31 13 81 50 24
31 13 80 50 24
31 13 79 50 24
31 13 78 50 24
31 13 77 50 24
31 13 76 50 24
31 13 75 50 24
31 13 74 50 24
31 13 73 50 24
31 13 72 50 24
31 13 71 50 24
31 13 70 50 24
31 13 69 50 24
31 13 68 50 24
31 13 67 50 24
31 13 66 50 24
31 13 65 50 24
31 13 64 50 24
31 13 63 50 24
31 13 62 50 80
31 14 105 52 56
31 14 104 50 64
31 14 62 50 32
31 14 61 52 88
31 15 104 50 96
31 15 62 50 96
31 16 104 50 96
31 16 62 50 96
31 17 104 50 96
31 17 62 50 96
31 18 104 50 96
31 18 62 50 96
31 19 104 50 96
31 19 62 50 96
31 20 105 52 56
31 20 104 50 64
31 20 62 50 32
31 20 61 52 88
31 21 104 50 96
31 21 62 50 96
31 22 104 50 40
31 22 103 50 16
31 22 102 50 16
31 22 101 50 24
31 22 100 50 16
31 22 99 50 16
31 22 98 50 16
31 22 97 50 24
31 22 96 50 16
31 22 95 50 24
31 22 94 50 24
31 22 93 50 16
31 22 92 50 24
31 22 91 50 16
31 22 90 50 24
31 22 89 50 16
31 22 88 50 24
31 22 87 50 16
31 22 86 50 16
31 22 85 50 24
31 22 84 50 16
31 22 83 50 16
31 22 82 50 16
31 22 81 50 16
31 22 80 50 16
31 22 79 68 16
31 22 78 64 16
31 22 77 64 24
31 22 76 68 16
31 22 75 68 24
31 22 74 64 16
31 22 73 64 24
31 22 72 50 16
31 22 71 50 16
31 22 70 50 24
31 22 69 50 16
31 22 68 50 16
31 22 67 50 16
31 22 66 50 24
31 22 65 50 16
31 22 64 50 16
31 22 63 50 16
31 22 62 50 72
31 23 103 62 32
31 23 102 61 76
31 23 100 61 36
31 23 99 61 14
31 23 98 61 74
31 23 96 61 110
31 23 93 61 106
31 23 91 61 110
31 23 89 89 106
31 23 87 61 40
31 23 86 61 72
31 23 84 61 46
31 23 83 61 8
31 23 82 61 0
31 23 81 64 8
31 23 80 68 0
31 23 79 89 8
31 23 78 61 74
31 23 76 61 110
31 23 74 89 106
31 23 72 68 40
31 23 71 68 76
31 23 69 61 46
31 23 68 61 12
31 23 67 61 78
31 23 65 89 34
31 23 64 89 12
31 23 63 62 64
31 24 103 62 96
31 24 100 61 110
31 24 85 61 126
31 24 82 68 108
31 24 80 61 106
31 24 70 64 124
31 24 65 61 110
31 24 63 62 96
31 25 103 62 96
31 25 83 68 116
31 25 69 68 116
31 25 63 62 96
31 26 103 62 104
31 26 83 68 110
31 26 69 68 110
31 26 63 62 104
31 27 84 68 116
31 27 68 64 116
31 28 84 68 100
31 28 68 64 100
31 29 84 68 102
31 29 68 64 102
31 30 84 68 98
31 30 68 68 98
31 31 84 68 98
31 31 68 68 102
31 32 84 68 96
31 32 68 68 100
31 33 84 64 104
31 33 68 68 108
31 34 83 68 118
31 34 69 68 118
31 35 83 68 108
31 35 69 68 108
31 36 82 68 124
31 36 70 64 124
31 37 81 64 60
31 37 80 68 94
31 37 72 68 62
31 37 71 68 92
31 38 79 68 60
31 38 78 64 28
31 38 77 64 30
31 38 76 68 26
31 38 75 68 30
31 38 74 64 28
31 38 73 68 92
32 5 102 33 48
32 5 101 33 80
32 5 65 33 48
32 5 64 33 80
32 6 102 33 40
32 6 101 33 72
32 6 65 33 40
32 6 64 33 72
32 13 104 50 48
32 13 103 50 24
32 13 102 50 24
32 13 101 50 24
32 13 100 50 24
32 13 99 50 24
32 13 98 50 24
32 13 97 50 24
32 13 96 50 24
32 13 95 50 24
32 13 94 50 24
32 13 93 50 24
32 13 92 50 24
32 13 91 50 24
32 13 90 50 24
32 13 89 50 24
32 13 88 50 24
32 13 87 50 24
32 13 86 50 24
32 13 85 50 24
32 13 84 50 24
32 13 83 50 24
32 13 82 50 24
32 13 81 50 24
32 13 80 50 24
32 13 79 50 24
32 13 78 50 24
32 13 77 50 24
32 13 76 50 24
32 13 75 50 24
32 13 74 50 24
32 13 73 50 24
32 13 72 50 24
32 13 71 50 24
32 13 70 50 24
32 13 69 50 24
32 13 68 50 24
32 13 67 50 24
32 13 66 50 24
32 13 65 50 24
32 13 64 50 24
32 13 63 50 24
32 13 62 50 80
32 14 105 52 56
32 14 104 50 64
32 14 62 50 32
32 14 61 52 88
32 15 104 50 96
32 15 62 50 96
32 16 104 50 96
32 16 62 50 96
32 17 104 50 96
32 17 62 50 96
32 18 104 50 96
32 18 62 50 96
32 19 104 50 96
32 19 62 50 96
32 20 105 52 56
32 20 104 50 64
32 20 62 50 32
32 20 61 52 88
32 21 104 50 96
32 21 77 64 52
32 21 76 68 20
32 21 75 68 84
32 21 62 50 96
32 22 104 50 40
32 22 103 50 16
32 22 102 50 16
32 22 101 50 16
32 22 100 50 16
32 22 99 50 24
32 22 98 50 24
32 22 97 50 16
32 22 96 50 24
32 22 95 50 16
32 22 94 50 24
32 22 93 50 24
32 22 92 50 16
32 22 91 50 24
32 22 90 50 16
32 22 89 50 24
32 22 88 50 24
32 22 87 50 16
32 22 86 50 16
32 22 85 50 16
32 22 84 50 24
32 22 83 50 16
32 22 82 50 16
32 22 81 50 16
32 22 80 64 16
32 22 79 68 16
32 22 78 68 24
32 22 77 50 0
32 22 76 50 8
32 22 75 50 0
32 22 74 68 24
32 22 73 64 24
32 22 72 68 16
32 22 71 50 16
32 22 70 50 16
32 22 69 50 24
32 22 68 50 16
32 22 67 50 24
32 22 66 50 16
32 22 65 50 24
32 22 64 50 16
32 22 63 50 16
32 22 62 50 72
32 23 103 62 32
32 23 102 61 8
32 23 101 61 14
32 23 100 61 72
32 23 97 61 110
32 23 95 61 108
32 23 92 89 110
32 23 90 61 110
32 23 87 61 40
32 23 86 61 10
32 23 85 61 76
32 23 83 61 40
32 23 82 61 0
32 23 81 64 8
32 23 80 61 8
32 23 79 89 72
32 23 77 89 110
32 23 75 61 110
32 23 72 61 40
32 23 71 68 10
32 23 70 61 68
32 23 68 61 104
32 23 66 61 108
32 23 64 89 40
32 23 63 62 64
32 24 103 62 96
32 24 82 68 106
32 24 70 64 106
32 24 63 62 96
32 25 103 62 96
32 25 83 68 122
32 25 69 68 122
32 25 63 62 96
32 26 103 62 104
32 26 84 68 116
32 26 68 64 116
32 26 63 62 104
32 27 84 68 98
32 27 68 64 98
32 28 84 68 106
32 28 68 68 106
32 29 85 68 116
32 29 67 68 116
32 30 85 68 100
32 30 67 68 100
32 31 85 68 108
32 31 67 68 108
32 32 84 68 114
32 32 68 68 114
32 33 84 64 98
32 33 68 68 98
32 34 84 64 108
32 34 68 68 108
32 35 83 68 122
32 35 69 68 122
32 36 82 68 122
32 36 70 64 122
32 37 81 64 122
32 37 71 64 122
32 38 80 68 60
32 38 79 68 26
32 38 78 64 90
32 38 74 64 58
32 38 73 68 26
32 38 72 68 92
32 39 77 68 60
32 39 76 68 28
32 39 75 68 92
33 5 102 33 48
33 5 101 33 80
33 5 65 33 48
33 5 64 33 80
33 6 102 33 40
33 6 101 33 72
33 6 65 33 40
33 6 64 33 72
33 13 104 50 48
33 13 103 50 24
33 13 102 50 24
33 13 101 50 24
33 13 100 50 24
33 13 99 50 24
33 13 98 50 24
33 13 97 50 24
33 13 96 50 24
33 13 95 50 24
33 13 94 50 24
33 13 93 50 24
33 13 92 50 24
33 13 91 50 24
33 13 90 50 24
33 13 89 50 24
33 13 88 50 24
33 13 87 50 24
33 13 86 50 24
33 13 85 50 24
33 13 84 50 24
33 13 83 50 24
33 13 82 50 24
33 13 81 50 24
33 13 80 50 24
33 13 79 50 24
33 13 78 50 24
33 13 77 50 24
33 13 76 50 24
33 13 75 50 24
33 13 74 50 24
33 13 73 50 24
33 13 72 50 24
33 13 71 50 24
33 13 70 50 24
33 13 69 50 24
33 13 68 50 24
33 13 67 50 24
33 13 66 50 24
33 13 65 50 24
33 13 64 50 24
33 13 63 50 24
33 13 62 50 80
33 14 105 52 56
33 14 104 50 64
33 14 62 50 32
33 14 61 52 88
33 15 104 50 96
33 15 62 50 96
33 16 104 50 96
33 16 62 50 96
33 17 104 50 96
33 17 62 50 96
33 18 104 50 96
33 18 62 50 96
33 19 104 50 96
33 19 62 50 96
33 20 105 52 56
33 20 104 50 64
33 20 62 50 32
33 20 61 52 88
33 21 104 50 96
33 21 79 68 52
33 21 78 68 20
33 21 77 64 16
33 21 76 68 16
33 21 75 68 16
33 21 74 68 20
33 21 73 64 84
33 21 62 50 96
33 22 104 50 40
33 22 103 50 16
33 22 102 50 16
33 22 101 50 24
33 22 100 50 16
33 22 99 50 16
33 22 98 50 16
33 22 97 50 24
33 22 96 50 24
33 22 95 50 16
33 22 94 50 16
33 22 93 50 16
33 22 92 50 24
33 22 91 50 16
33 22 90 50 24
33 22 89 50 16
33 22 88 50 24
33 22 87 50 16
33 22 86 50 24
33 22 85 50 16
33 22 84 50 16
33 22 83 50 16
33 22 82 50 16
33 22 81 68 16
33 22 80 64 16
33 22 79 50 0
33 22 78 50 0
33 22 77 50 8
33 22 76 50 0
33 22 75 50 8
33 22 74 50 0
33 22 73 50 8
33 22 72 68 16
33 22 71 68 24
33 22 70 50 16
33 22 69 50 24
33 22 68 50 16
33 22 67 50 16
33 22 66 50 16
33 22 65 50 24
33 22 64 50 16
33 22 63 50 16
33 22 62 50 72
33 23 103 62 32
33 23 102 89 74
33 23 100 89 42
33 23 99 89 12
33 23 98 61 78
33 23 95 89 40
33 23 94 89 14
33 23 93 61 76
33 23 91 89 108
33 23 89 89 108
33 23 87 89 106
33 23 85 89 40
33 23 84 89 12
33 23 83 61 0
33 23 82 64 8
33 23 81 89 8
33 23 80 89 8
33 23 79 89 8
33 23 78 61 76
33 23 76 89 108
33 23 74 89 108
33 23 72 89 106
33 23 70 64 104
33 23 68 89 40
33 23 67 61 14
33 23 66 89 72
33 23 64 89 40
33 23 63 62 64
33 24 103 62 96
33 24 83 64 108
33 24 69 68 124
33 24 63 62 96
33 25 103 62 96
33 25 97 43 60
33 25 96 65 92
33 25 93 65 60
33 25 92 41 92
33 25 84 64 116
33 25 68 64 116
33 25 63 62 96
33 26 103 62 104
33 26 84 64 104
33 26 68 64 104
33 26 63 62 104
33 27 85 64 116
33 27 67 68 116
33 28 85 68 102
33 28 67 68 100
33 29 85 68 98
33 29 67 64 96
33 30 85 68 98
33 30 67 64 96
33 31 85 68 98
33 31 67 64 96
33 32 85 68 102
33 32 67 68 100
33 33 85 68 108
33 33 67 68 108
33 34 84 68 112
33 34 68 68 112
33 35 84 64 108
33 35 68 68 108
33 36 83 68 124
33 36 69 68 124
33 37 82 68 124
33 37 70 68 124
33 38 81 64 60
33 38 80 68 88
33 38 72 64 56
33 38 71 64 92
33 39 79 68 60
33 39 78 64 28
33 39 77 68 24
33 39 76 68 24
33 39 75 68 24
33 39 74 64 28
33 39 73 68 92
34 5 102 33 48
34 5 101 33 80
34 5 65 33 48
34 5 64 33 80
34 6 102 33 40
34 6 101 33 72
34 6 65 33 40
34 6 64 33 72
34 13 104 50 48
34 13 103 50 24
34 13 102 50 24
34 13 101 50 24
34 13 100 50 24
34 13 99 50 24
34 13 98 50 24
34 13 97 50 24
34 13 96 50 24
34 13 95 50 24
34 13 94 50 24
34 13 93 50 24
34 13 92 50 24
34 13 91 50 24
34 13 90 50 24
34 13 89 50 24
34 13 88 50 24
34 13 87 50 24
34 13 86 50 24
34 13 85 50 24
34 13 84 50 24
34 13 83 50 24
34 13 82 50 24
34 13 81 50 24
34 13 80 50 24
34 13 79 50 24
34 13 78 50 24
34 13 77 50 24
34 13 76 50 24
34 13 75 50 24
34 13 74 50 24
34 13 73 50 24
34 13 72 50 24
34 13 71 50 24
34 13 70 50 24
34 13 69 50 24
34 13 68 50 24
34 13 67 50 24
34 13 66 50 24
34 13 65 50 24
34 13 64 50 24
34 13 63 50 24
34 13 62 50 80
34 14 105 52 56
34 14 104 50 64
34 14 62 50 32
34 14 61 52 88
34 15 104 50 96
34 15 62 50 96
34 16 104 50 96
34 16 62 50 96
34 17 104 50 96
34 17 62 50 96
34 18 104 50 96
34 18 62 50 96
34 19 104 50 96
34 19 62 50 96
34 20 105 52 56
34 20 104 50 64
34 20 62 50 32
34 20 61 52 88
34 21 104 50 96
34 21 79 64 48
34 21 78 68 16
34 21 77 64 16
34 21 76 64 16
34 21 75 68 16
34 21 74 68 16
34 21 73 64 80
34 21 62 50 96
34 22 104 50 40
34 22 103 50 16
34 22 102 50 24
34 22 101 50 16
34 22 100 50 24
34 22 99 50 16
34 22 98 50 24
34 22 97 50 16
34 22 96 50 24
34 22 95 50 16
34 22 94 50 24
34 22 93 50 16
