Qubicle Exchange Format
Version 0.2
www.minddesk.com
186 82 74
49
0.015686 0.011765 0.000000
0.047059 0.168627 0.298039
0.078431 0.513725 0.776471
0.094118 0.203922 0.321569
0.121569 0.125490 0.125490
0.188235 0.192157 0.196078
0.192157 0.250980 0.388235
0.223529 0.588235 0.815686
0.227451 0.164706 0.070588
0.227451 0.227451 0.227451
0.258824 0.180392 0.070588
0.286275 0.286275 0.286275
0.290196 0.298039 0.301961
0.298039 0.211765 0.086275
0.349020 0.435294 0.172549
0.356863 0.254902 0.113725
0.400000 0.509804 0.192157
0.411765 0.407843 0.266667
0.439216 0.572549 0.184314
0.443137 0.333333 0.180392
0.466667 0.356863 0.164706
0.482353 0.639216 0.188235
0.486275 0.309804 0.054902
0.513725 0.501961 0.337255
0.529412 0.466667 0.341176
0.533333 0.678431 0.254902
0.545098 0.439216 0.250980
0.552941 0.564706 0.572549
0.635294 0.647059 0.650980
0.682353 0.466667 0.019608
0.709804 0.756863 0.600000
0.749020 0.549020 0.141176
0.768627 0.345098 0.345098
0.803922 0.313725 0.313725
0.827451 0.623529 0.337255
0.850980 0.325490 0.325490
0.890196 0.890196 0.737255
0.894118 0.200000 0.203922
0.909804 0.913725 0.913725
0.945098 0.913725 0.603922
0.960784 0.533333 0.086275
0.964706 0.913725 0.450980
0.964706 0.925490 0.545098
0.980392 0.827451 0.784314
0.984314 0.858824 0.823529
0.984314 0.937255 0.850980
0.988235 0.811765 0.760784
0.988235 0.858824 0.823529
1.000000 0.905882 0.003922
154 4 26 9 52
154 4 25 9 20
154 4 24 9 20
154 4 23 9 84
154 5 26 11 36
154 5 25 11 4
154 5 24 11 4
154 5 23 11 68
154 6 26 11 36
154 6 25 11 4
154 6 24 11 4
154 6 23 11 68
154 7 26 9 44
154 7 25 9 12
154 7 24 9 12
154 7 23 9 76
154 20 26 9 52
154 20 25 9 20
154 20 24 9 20
154 20 23 9 84
154 21 26 11 36
154 21 25 11 4
154 21 24 11 4
154 21 23 11 68
154 22 26 11 36
154 22 25 11 4
154 22 24 11 4
154 22 23 11 68
154 23 26 9 44
154 23 25 9 12
154 23 24 9 12
154 23 23 9 76
155 1 26 19 52
155 1 25 19 20
155 1 24 19 20
155 1 23 19 84
155 2 26 19 38
155 2 25 19 6
155 2 24 19 6
155 2 23 19 70
155 3 26 19 38
155 3 25 19 6
155 3 24 19 6
155 3 23 19 70
155 4 30 9 54
155 4 29 9 22
155 4 28 9 22
155 4 27 9 22
155 4 26 19 2
155 4 25 19 2
155 4 24 19 2
155 4 23 19 2
155 4 22 9 22
155 4 21 9 22
155 4 20 9 22
155 4 19 9 86
155 5 30 11 38
155 5 29 11 6
155 5 28 11 6
155 5 27 11 6
155 5 26 19 2
155 5 25 19 2
155 5 24 19 2
155 5 23 19 2
155 5 22 11 6
155 5 21 11 6
155 5 20 11 6
155 5 19 11 70
155 6 30 11 38
155 6 29 11 6
155 6 28 11 6
155 6 27 11 6
155 6 26 19 2
155 6 25 19 2
155 6 24 19 2
155 6 23 19 2
155 6 22 11 6
155 6 21 11 6
155 6 20 11 6
155 6 19 11 70
155 7 30 9 46
155 7 29 9 14
155 7 28 9 14
155 7 27 9 14
155 7 26 19 2
155 7 25 19 2
155 7 24 19 2
155 7 23 19 2
155 7 22 9 14
155 7 21 9 14
155 7 20 9 14
155 7 19 9 78
155 8 26 19 38
155 8 25 19 6
155 8 24 19 6
155 8 23 19 70
155 9 26 19 38
155 9 25 19 6
155 9 24 19 6
155 9 23 19 70
155 10 26 19 38
155 10 25 19 6
155 10 24 19 6
155 10 23 19 70
155 11 26 19 38
155 11 25 19 6
155 11 24 19 6
155 11 23 19 70
155 12 26 19 38
155 12 25 19 6
155 12 24 19 6
155 12 23 19 70
155 13 26 19 38
155 13 25 19 6
155 13 24 19 6
155 13 23 19 70
155 14 26 19 38
155 14 25 19 6
155 14 24 19 6
155 14 23 19 70
155 15 26 19 38
155 15 25 19 6
155 15 24 19 6
155 15 23 19 70
155 16 26 19 38
155 16 25 19 6
155 16 24 19 6
155 16 23 19 70
155 17 26 19 38
155 17 25 19 6
155 17 24 19 6
155 17 23 19 70
155 18 26 19 38
155 18 25 19 6
155 18 24 19 6
155 18 23 19 70
155 19 26 19 38
155 19 25 19 6
155 19 24 19 6
155 19 23 19 70
155 20 30 9 54
155 20 29 9 22
155 20 28 9 22
155 20 27 9 22
155 20 26 19 2
155 20 25 19 2
155 20 24 19 2
155 20 23 19 2
155 20 22 9 22
155 20 21 9 22
155 20 20 9 22
155 20 19 9 86
155 21 30 11 38
155 21 29 11 6
155 21 28 11 6
155 21 27 11 6
155 21 26 19 2
155 21 25 19 2
155 21 24 19 2
155 21 23 19 2
155 21 22 11 6
155 21 21 11 6
155 21 20 11 6
155 21 19 11 70
155 22 30 11 38
155 22 29 11 6
155 22 28 11 6
155 22 27 11 6
155 22 26 19 2
155 22 25 19 2
155 22 24 19 2
155 22 23 19 2
155 22 22 11 6
155 22 21 11 6
155 22 20 11 6
155 22 19 11 70
155 23 30 9 46
155 23 29 9 14
155 23 28 9 14
155 23 27 9 14
155 23 26 19 2
155 23 25 19 2
155 23 24 19 2
155 23 23 19 2
155 23 22 9 14
155 23 21 9 14
155 23 20 9 14
155 23 19 9 78
155 24 26 19 38
155 24 25 19 6
155 24 24 19 6
155 24 23 19 70
155 25 26 19 38
155 25 25 19 6
155 25 24 19 6
155 25 23 19 70
155 26 26 19 44
155 26 25 19 12
155 26 24 19 12
155 26 23 19 76
156 1 30 15 52
156 1 29 15 20
156 1 28 15 20
156 1 27 15 20
156 1 26 8 24
156 1 25 8 24
156 1 24 8 24
156 1 23 8 24
156 1 22 15 20
156 1 21 15 20
156 1 20 15 20
156 1 19 15 84
156 2 30 15 38
156 2 29 15 6
156 2 28 15 6
156 2 27 15 70
156 2 22 15 38
156 2 21 15 6
156 2 20 15 6
156 2 19 15 70
156 3 30 15 46
156 3 29 15 14
156 3 28 15 14
156 3 27 15 78
156 3 22 15 46
156 3 21 15 14
156 3 20 15 14
156 3 19 15 78
156 4 32 9 52
156 4 31 9 84
156 4 18 9 52
156 4 17 9 84
156 5 32 11 36
156 5 31 11 68
156 5 18 11 36
156 5 17 11 68
156 6 32 11 36
156 6 31 11 68
156 6 18 11 36
156 6 17 11 68
156 7 32 9 44
156 7 31 9 76
156 7 18 9 44
156 7 17 9 76
156 8 30 15 54
156 8 29 15 22
156 8 28 15 22
156 8 27 15 86
156 8 22 15 54
156 8 21 15 22
156 8 20 15 22
156 8 19 15 86
156 9 30 15 38
156 9 29 15 6
156 9 28 15 6
156 9 27 15 70
156 9 22 15 38
156 9 21 15 6
156 9 20 15 6
156 9 19 15 70
156 10 30 15 38
156 10 29 15 6
156 10 28 15 6
156 10 27 15 70
156 10 22 15 38
156 10 21 15 6
156 10 20 15 6
156 10 19 15 70
156 11 30 15 38
156 11 29 15 6
156 11 28 15 6
156 11 27 15 70
156 11 22 15 38
156 11 21 15 6
156 11 20 15 6
156 11 19 15 70
156 12 30 15 38
156 12 29 15 6
156 12 28 15 6
156 12 27 15 70
156 12 22 15 38
156 12 21 15 6
156 12 20 15 6
156 12 19 15 70
156 13 30 15 38
156 13 29 15 6
156 13 28 15 6
156 13 27 15 70
156 13 22 15 38
156 13 21 15 6
156 13 20 15 6
156 13 19 15 70
156 14 30 15 38
156 14 29 15 6
156 14 28 15 6
156 14 27 15 70
156 14 22 15 38
156 14 21 15 6
156 14 20 15 6
156 14 19 15 70
156 15 30 15 38
156 15 29 15 6
156 15 28 15 6
156 15 27 15 70
156 15 22 15 38
156 15 21 15 6
156 15 20 15 6
156 15 19 15 70
156 16 30 15 36
156 16 29 15 4
156 16 28 15 4
156 16 27 15 70
156 16 22 15 38
156 16 21 15 6
156 16 20 15 6
156 16 19 15 70
156 17 30 15 38
156 17 29 15 6
156 17 28 15 6
156 17 27 15 70
156 17 22 15 38
156 17 21 15 6
156 17 20 15 6
156 17 19 15 70
156 18 30 15 38
156 18 29 15 6
156 18 28 15 6
156 18 27 15 70
156 18 22 15 38
156 18 21 15 6
156 18 20 15 6
156 18 19 15 70
156 19 30 15 46
156 19 29 15 14
156 19 28 15 14
156 19 27 15 78
156 19 22 15 44
156 19 21 15 12
156 19 20 15 12
156 19 19 15 78
156 20 32 9 52
156 20 31 9 84
156 20 18 9 52
156 20 17 9 84
156 21 32 11 36
156 21 31 11 68
156 21 18 11 36
156 21 17 11 68
156 22 32 11 36
156 22 31 11 68
156 22 18 11 36
156 22 17 11 68
156 23 32 9 44
156 23 31 9 76
156 23 18 9 44
156 23 17 9 76
156 24 30 15 54
156 24 29 15 22
156 24 28 15 22
156 24 27 15 84
156 24 22 15 52
156 24 21 15 22
156 24 20 15 22
156 24 19 15 86
156 25 30 15 38
156 25 29 15 6
156 25 28 15 6
156 25 27 15 68
156 25 22 15 36
156 25 21 15 6
156 25 20 15 6
156 25 19 15 70
156 26 30 15 44
156 26 29 15 12
156 26 28 15 12
156 26 27 15 12
156 26 26 8 24
156 26 25 8 24
156 26 24 8 24
156 26 23 8 24
156 26 22 15 12
156 26 21 15 12
156 26 20 15 12
156 26 19 15 76
157 1 32 19 52
157 1 31 19 20
157 1 30 8 24
157 1 29 8 24
157 1 28 8 24
157 1 27 8 26
157 1 26 8 26
157 1 25 8 26
157 1 24 8 26
157 1 23 8 26
157 1 22 8 26
157 1 21 8 24
157 1 20 8 24
157 1 19 8 24
157 1 18 19 20
157 1 17 19 84
157 2 32 19 36
157 2 31 19 70
157 2 18 19 38
157 2 17 19 68
157 3 32 19 36
157 3 31 19 70
157 3 18 19 38
157 3 17 19 68
157 4 33 9 52
157 4 32 19 0
157 4 31 19 66
157 4 18 19 34
157 4 17 19 0
157 4 16 9 84
157 5 33 11 36
157 5 32 19 0
157 5 31 19 66
157 5 18 19 34
157 5 17 19 0
157 5 16 11 68
157 6 33 11 36
157 6 32 19 0
157 6 31 19 66
157 6 18 19 34
157 6 17 19 0
157 6 16 11 68
157 7 33 9 44
157 7 32 19 0
157 7 31 19 66
157 7 18 19 34
157 7 17 19 0
157 7 16 9 76
157 8 32 19 36
157 8 31 19 70
157 8 18 19 38
157 8 17 19 68
157 9 32 19 36
157 9 31 19 70
157 9 18 19 38
157 9 17 19 68
157 10 32 19 36
157 10 31 19 70
157 10 18 19 38
157 10 17 19 68
157 11 32 19 36
157 11 31 19 70
157 11 18 19 38
157 11 17 19 68
157 12 32 19 36
157 12 31 19 70
157 12 18 19 38
157 12 17 19 68
157 13 32 19 36
157 13 31 19 70
157 13 18 19 38
157 13 17 19 68
157 14 32 19 36
157 14 31 19 70
157 14 18 19 38
157 14 17 19 68
157 15 32 19 36
157 15 31 19 70
157 15 18 19 38
157 15 17 19 68
157 16 32 19 36
157 16 31 19 6
157 16 30 10 26
157 16 29 10 26
157 16 28 10 90
157 16 18 19 38
157 16 17 19 68
157 17 32 19 36
157 17 31 19 70
157 17 18 19 38
157 17 17 19 68
157 18 32 19 36
157 18 31 19 70
157 18 18 19 38
157 18 17 19 68
157 19 32 19 36
157 19 31 19 70
157 19 22 10 48
157 19 21 10 24
157 19 20 10 88
157 19 18 19 38
157 19 17 19 68
157 20 33 9 52
157 20 32 19 0
157 20 31 19 66
157 20 27 15 54
157 20 26 15 22
157 20 25 15 22
157 20 24 15 22
157 20 23 15 22
157 20 22 15 70
157 20 18 19 34
157 20 17 19 0
157 20 16 9 84
157 21 33 11 36
157 21 32 19 0
157 21 31 19 66
157 21 27 11 38
157 21 26 11 6
157 21 25 11 6
157 21 24 11 6
157 21 23 11 6
157 21 22 11 70
157 21 18 19 34
157 21 17 19 0
157 21 16 11 68
157 22 33 11 36
157 22 32 19 0
157 22 31 19 66
157 22 27 11 38
157 22 26 11 6
157 22 25 11 6
157 22 24 11 6
157 22 23 11 6
157 22 22 11 70
157 22 18 19 34
157 22 17 19 0
157 22 16 11 68
157 23 33 9 44
157 23 32 19 0
157 23 31 19 66
157 23 27 15 38
157 23 26 15 6
157 23 25 15 6
157 23 24 15 6
157 23 23 15 6
157 23 22 15 70
157 23 18 19 34
157 23 17 19 0
157 23 16 9 76
157 24 32 19 36
157 24 31 19 70
157 24 27 15 34
157 24 26 15 6
157 24 25 15 6
157 24 24 15 6
157 24 23 15 6
157 24 22 15 66
157 24 18 19 38
157 24 17 19 68
157 25 32 19 36
157 25 31 19 70
157 25 27 15 34
157 25 26 15 6
157 25 25 15 6
157 25 24 15 6
157 25 23 15 6
157 25 22 15 66
157 25 18 19 38
157 25 17 19 68
157 26 32 19 44
157 26 31 19 12
157 26 30 8 24
157 26 29 8 24
157 26 28 8 24
157 26 27 8 10
157 26 26 8 8
157 26 25 8 8
157 26 24 8 8
157 26 23 8 10
157 26 22 8 10
157 26 21 8 24
157 26 20 8 24
157 26 19 8 24
157 26 18 19 12
157 26 17 19 76
158 1 33 19 52
158 1 32 19 16
158 1 31 8 24
158 1 30 8 26
158 1 29 8 26
158 1 28 8 90
158 1 21 8 58
158 1 20 8 26
158 1 19 8 26
158 1 18 8 24
158 1 17 19 16
158 1 16 19 84
158 2 33 19 38
158 2 32 19 66
158 2 27 15 60
158 2 26 15 28
158 2 25 15 28
158 2 24 15 28
158 2 23 15 28
158 2 22 15 92
158 2 17 19 34
158 2 16 19 70
158 3 33 19 38
158 3 32 19 66
158 3 17 19 34
158 3 16 19 70
158 4 34 9 54
158 4 33 19 2
158 4 32 19 66
158 4 17 19 34
158 4 16 19 2
158 4 15 9 86
158 5 34 11 38
158 5 33 19 2
158 5 32 19 66
158 5 17 19 34
158 5 16 19 2
158 5 15 11 70
158 6 34 11 38
158 6 33 19 2
158 6 32 19 66
158 6 17 19 34
158 6 16 19 2
158 6 15 11 70
158 7 34 9 46
158 7 33 19 2
158 7 32 19 66
158 7 17 19 34
158 7 16 19 2
158 7 15 9 78
158 8 33 19 38
158 8 32 19 66
158 8 17 19 34
158 8 16 19 70
158 9 33 19 38
158 9 32 19 66
158 9 17 19 34
158 9 16 19 70
158 10 33 19 38
158 10 32 19 66
158 10 17 19 34
158 10 16 19 70
158 11 33 19 38
158 11 32 19 66
158 11 17 19 34
158 11 16 19 70
158 12 33 19 38
158 12 32 19 66
158 12 17 19 34
158 12 16 19 70
158 13 33 19 38
158 13 32 19 66
158 13 17 19 34
158 13 16 19 70
158 14 33 19 38
158 14 32 19 66
158 14 17 19 34
158 14 16 19 70
158 15 33 19 38
158 15 32 19 66
158 15 17 19 34
158 15 16 19 70
158 16 33 19 38
158 16 32 19 66
158 16 17 19 34
158 16 16 19 70
158 17 33 19 38
158 17 32 19 66
158 17 17 19 34
158 17 16 19 70
158 18 33 19 38
158 18 32 19 66
158 18 17 19 34
158 18 16 19 70
158 19 33 19 38
158 19 32 19 66
158 19 27 10 60
158 19 26 10 28
158 19 25 10 28
158 19 24 10 28
158 19 23 10 28
158 19 22 10 24
158 19 21 10 16
158 19 20 10 80
158 19 17 19 34
158 19 16 19 70
158 20 34 9 54
158 20 33 19 2
158 20 32 19 66
158 20 30 15 54
158 20 29 15 22
158 20 28 15 86
158 20 21 15 38
158 20 20 15 6
158 20 19 15 86
158 20 17 19 34
158 20 16 19 2
158 20 15 9 86
158 21 34 11 38
158 21 33 19 2
158 21 32 19 66
158 21 30 11 38
158 21 29 11 6
158 21 28 11 70
158 21 21 11 36
158 21 20 11 6
158 21 19 11 70
158 21 17 19 34
158 21 16 19 2
158 21 15 11 70
158 22 34 11 38
158 22 33 19 2
158 22 32 19 66
158 22 30 11 38
158 22 29 11 6
158 22 28 11 70
158 22 21 11 36
158 22 20 11 4
158 22 19 11 70
158 22 17 19 34
158 22 16 19 2
158 22 15 11 70
158 23 34 9 46
158 23 33 19 2
158 23 32 19 66
158 23 30 15 38
158 23 29 15 6
158 23 28 15 70
158 23 21 15 36
158 23 20 15 4
158 23 19 15 70
158 23 17 19 34
158 23 16 19 2
158 23 15 9 78
158 24 33 19 38
158 24 32 19 66
158 24 30 15 38
158 24 29 15 6
158 24 28 15 70
158 24 21 15 36
158 24 20 15 6
158 24 19 15 70
158 24 17 19 34
158 24 16 19 70
158 25 33 19 38
158 25 32 19 66
158 25 30 15 38
158 25 29 15 6
158 25 28 15 70
158 25 21 15 38
158 25 20 15 6
158 25 19 15 70
158 25 17 19 34
158 25 16 19 70
158 26 33 19 44
158 26 32 19 8
158 26 31 8 24
158 26 30 8 10
158 26 29 8 10
158 26 28 8 74
158 26 26 32 48
158 26 25 32 16
158 26 24 32 80
158 26 21 8 42
158 26 20 8 10
158 26 19 8 10
158 26 18 8 24
158 26 17 19 8
158 26 16 19 76
158 27 27 35 52
158 27 26 35 4
158 27 25 35 4
158 27 24 35 4
158 27 23 35 84
158 28 27 35 44
158 28 26 35 4
158 28 25 35 4
158 28 24 35 4
158 28 23 35 76
158 29 26 35 44
158 29 25 35 12
158 29 24 35 76
159 1 34 15 52
159 1 33 15 24
159 1 32 8 24
159 1 31 8 90
159 1 18 8 58
159 1 17 8 24
159 1 16 15 24
159 1 15 15 84
159 2 34 15 102
159 2 30 15 60
159 2 29 15 28
159 2 28 15 28
159 2 27 15 24
159 2 26 15 24
159 2 25 15 24
159 2 24 15 24
159 2 23 15 24
159 2 22 15 24
159 2 21 15 28
159 2 20 15 28
159 2 19 15 92
159 2 15 15 102
159 3 34 15 110
159 3 15 15 110
159 4 35 9 118
159 4 14 9 118
159 5 35 11 102
159 5 14 11 102
159 6 35 11 102
159 6 14 11 102
159 7 35 9 110
159 7 14 9 110
159 8 34 15 118
159 8 15 15 118
159 9 34 15 102
159 9 15 15 102
159 10 34 15 102
159 10 15 15 102
159 11 34 15 102
159 11 15 15 102
159 12 34 15 102
159 12 15 15 102
159 13 34 15 102
159 13 15 15 102
159 14 34 15 102
159 14 15 15 102
159 15 34 15 102
159 15 15 15 102
159 16 34 15 102
159 16 15 15 102
159 17 34 15 102
159 17 15 15 102
159 18 34 15 102
159 18 15 15 102
159 19 34 15 110
159 19 30 10 60
159 19 29 10 28
159 19 28 10 28
159 19 27 10 24
159 19 26 10 24
159 19 25 10 24
159 19 24 10 24
159 19 23 10 24
159 19 22 10 24
159 19 21 10 24
159 19 20 10 24
159 19 19 10 92
159 19 15 15 110
159 20 35 9 118
159 20 31 15 118
159 20 18 15 118
159 20 14 9 118
159 21 35 11 102
159 21 31 11 102
159 21 23 32 52
159 21 22 32 20
159 21 21 32 80
159 21 18 11 102
159 21 14 11 102
159 22 35 11 102
159 22 31 11 102
159 22 24 35 52
159 22 23 35 4
159 22 22 35 4
159 22 21 35 0
159 22 20 35 80
159 22 18 11 102
159 22 14 11 102
159 23 35 9 110
159 23 31 15 102
159 23 24 35 44
159 23 23 35 4
159 23 22 35 4
159 23 21 35 0
159 23 20 35 72
159 23 18 15 102
159 23 14 9 110
159 24 34 15 118
159 24 31 15 102
159 24 23 35 44
159 24 22 35 12
159 24 21 35 72
159 24 18 15 102
159 24 15 15 118
159 25 34 15 102
159 25 31 15 102
159 25 26 32 52
159 25 25 32 20
159 25 24 32 84
159 25 18 15 102
159 25 15 15 102
159 26 34 15 44
159 26 33 15 24
159 26 32 8 24
159 26 31 8 74
159 26 27 32 52
159 26 26 32 0
159 26 25 32 0
159 26 24 32 0
159 26 23 32 84
159 26 18 8 42
159 26 17 8 24
159 26 16 15 24
159 26 15 15 76
159 27 28 35 52
159 27 27 35 0
159 27 26 35 0
159 27 25 35 0
159 27 24 35 0
159 27 23 35 0
159 27 22 35 84
159 28 28 35 44
159 28 27 35 0
159 28 26 35 0
159 28 25 35 0
159 28 24 35 0
159 28 23 35 0
159 28 22 35 76
159 29 27 35 44
159 29 26 35 0
159 29 25 35 0
159 29 24 35 0
159 29 23 35 76
159 30 26 35 44
159 30 25 35 12
159 30 24 35 76
160 1 35 15 52
160 1 34 15 24
160 1 33 8 24
160 1 32 8 90
160 1 17 8 58
160 1 16 8 24
160 1 15 15 24
160 1 14 15 84
160 2 35 15 102
160 2 31 13 60
160 2 30 13 24
160 2 29 13 24
160 2 28 13 24
160 2 27 13 24
160 2 26 13 24
160 2 25 13 24
160 2 24 13 24
160 2 23 13 24
160 2 22 13 24
160 2 21 13 24
160 2 20 13 24
160 2 19 13 24
160 2 18 13 92
160 2 14 15 102
160 3 35 15 110
160 3 14 15 110
160 4 36 9 116
160 4 13 9 116
160 5 36 11 100
160 5 13 11 100
160 6 36 11 100
160 6 13 11 100
160 7 36 9 108
160 7 13 9 108
160 8 35 15 118
160 8 14 15 118
160 9 35 15 102
160 9 14 15 102
160 10 35 15 102
160 10 14 15 102
160 11 35 15 102
160 11 14 15 102
160 12 35 15 102
160 12 14 15 102
160 13 35 15 102
160 13 14 15 102
160 14 35 15 102
160 14 14 15 102
160 15 35 15 102
160 15 14 15 102
160 16 35 15 102
160 16 14 15 102
160 17 35 15 102
160 17 14 15 102
160 18 35 15 102
160 18 14 15 102
160 19 35 15 110
160 19 31 10 60
160 19 30 10 24
160 19 29 10 24
160 19 28 10 24
160 19 27 10 24
160 19 26 10 24
160 19 25 10 24
160 19 24 10 24
160 19 23 10 16
160 19 22 10 16
160 19 21 10 16
160 19 20 10 24
160 19 19 10 24
160 19 18 10 92
160 19 14 15 110
160 20 36 9 116
160 20 32 15 118
160 20 23 32 36
160 20 22 32 4
160 20 21 32 68
160 20 17 15 118
160 20 13 9 116
160 21 36 11 100
160 21 32 11 102
160 21 24 32 52
160 21 23 32 0
160 21 22 32 0
160 21 21 32 0
160 21 20 32 84
160 21 17 11 102
160 21 13 11 100
160 22 36 11 100
160 22 32 11 102
160 22 25 35 52
160 22 24 35 0
160 22 23 35 0
160 22 22 35 0
160 22 21 35 0
160 22 20 35 0
160 22 19 35 84
160 22 17 11 102
160 22 13 11 100
160 23 36 9 108
160 23 32 15 102
160 23 25 35 44
160 23 24 35 0
160 23 23 35 0
160 23 22 35 0
160 23 21 35 0
160 23 20 35 0
160 23 19 35 76
160 23 17 15 102
160 23 13 9 108
160 24 35 15 118
160 24 32 15 102
160 24 24 35 36
160 24 23 35 0
160 24 22 35 0
160 24 21 35 0
160 24 20 35 76
160 24 17 15 102
160 24 14 15 118
160 25 35 15 102
160 25 32 15 102
160 25 27 32 52
160 25 26 32 16
160 25 25 32 16
160 25 24 32 0
160 25 23 32 4
160 25 22 35 4
160 25 21 35 76
160 25 17 15 102
160 25 14 15 102
160 26 35 15 44
160 26 34 15 24
160 26 33 8 24
160 26 32 8 74
160 26 28 32 52
160 26 27 32 0
160 26 26 32 0
160 26 25 32 0
160 26 24 32 0
160 26 23 32 0
160 26 22 32 68
160 26 17 8 42
160 26 16 8 24
160 26 15 15 24
160 26 14 15 76
160 27 28 35 32
160 27 27 35 0
160 27 26 35 0
160 27 25 35 0
160 27 24 35 0
160 27 23 35 0
160 27 22 35 64
160 28 28 35 32
160 28 27 35 0
160 28 26 35 0
160 28 25 35 0
160 28 24 35 0
160 28 23 35 0
160 28 22 35 64
160 29 28 35 44
160 29 27 35 0
160 29 26 35 0
160 29 25 35 0
160 29 24 35 0
160 29 23 35 0
160 29 22 35 76
160 30 27 35 44
160 30 26 35 8
160 30 25 35 8
160 30 24 35 8
160 30 23 35 76
161 1 36 19 52
161 1 35 15 24
161 1 34 8 24
161 1 33 8 90
161 1 16 8 58
161 1 15 8 24
161 1 14 15 24
161 1 13 19 84
161 2 36 19 102
161 2 32 13 60
161 2 31 13 24
161 2 30 13 24
161 2 29 13 24
161 2 28 13 24
161 2 27 13 24
161 2 26 13 24
161 2 25 13 24
161 2 24 13 24
161 2 23 13 24
161 2 22 13 24
161 2 21 13 24
161 2 20 13 24
161 2 19 13 24
161 2 18 13 24
161 2 17 13 92
161 2 13 19 100
161 3 36 19 102
161 3 13 19 100
161 4 37 9 52
161 4 36 19 66
161 4 13 19 32
161 4 12 9 84
161 5 37 11 36
161 5 36 19 66
161 5 13 19 32
161 5 12 11 68
161 6 37 11 36
161 6 36 19 66
161 6 13 19 32
161 6 12 11 68
161 7 37 9 44
161 7 36 19 66
161 7 13 19 32
161 7 12 9 76
161 8 36 19 102
161 8 13 19 100
161 9 36 19 102
161 9 13 19 100
161 10 36 19 102
161 10 13 19 100
161 11 36 19 102
161 11 13 19 100
161 12 36 19 102
161 12 13 19 100
161 13 36 19 102
161 13 13 19 100
161 14 36 19 102
161 14 13 19 100
161 15 36 19 102
161 15 13 19 100
161 16 36 19 102
161 16 13 19 100
161 17 36 19 102
161 17 13 19 100
161 18 36 19 102
161 18 13 19 100
161 19 36 19 102
161 19 32 10 60
161 19 31 10 24
161 19 30 10 24
161 19 29 10 24
161 19 28 10 24
161 19 27 10 24
161 19 26 10 24
161 19 25 10 24
161 19 24 10 16
161 19 23 10 16
161 19 22 10 16
161 19 21 10 16
161 19 20 10 16
161 19 19 10 24
161 19 18 10 24
161 19 17 10 92
161 19 13 19 100
161 20 37 9 52
161 20 36 19 66
161 20 33 15 118
161 20 24 32 36
161 20 23 32 0
161 20 22 32 0
161 20 21 32 0
161 20 20 32 68
161 20 16 15 118
161 20 13 19 32
161 20 12 9 84
161 21 37 11 36
161 21 36 19 66
161 21 33 11 102
161 21 30 18 52
161 21 29 18 20
161 21 28 18 84
161 21 25 32 52
161 21 24 32 0
161 21 23 32 0
161 21 22 32 0
161 21 21 32 0
161 21 20 32 0
161 21 19 32 84
161 21 16 11 102
161 21 13 19 32
161 21 12 11 68
161 22 37 11 36
161 22 36 19 66
161 22 33 11 102
161 22 31 21 52
161 22 30 21 4
161 22 29 21 4
161 22 28 21 4
161 22 27 21 84
161 22 25 35 32
161 22 24 35 0
161 22 23 35 0
161 22 22 35 0
161 22 21 35 0
161 22 20 35 0
161 22 19 35 64
161 22 16 11 102
161 22 13 19 32
161 22 12 11 68
161 23 37 9 44
161 23 36 19 66
161 23 33 15 102
161 23 31 21 44
161 23 30 21 4
161 23 29 21 4
161 23 28 21 4
161 23 27 21 76
161 23 25 35 32
161 23 24 35 0
161 23 23 35 0
161 23 22 35 0
161 23 21 35 0
161 23 20 35 0
161 23 19 35 64
161 23 16 15 102
161 23 13 19 32
161 23 12 9 76
161 24 36 19 102
161 24 33 15 102
161 24 30 21 44
161 24 29 21 12
161 24 28 21 76
161 24 25 35 36
161 24 24 35 0
161 24 23 35 0
161 24 22 35 0
161 24 21 35 0
161 24 20 35 0
161 24 19 35 76
161 24 16 15 102
161 24 13 19 100
161 25 36 19 102
161 25 33 15 102
161 25 27 32 48
161 25 26 32 16
161 25 25 32 0
161 25 24 32 0
161 25 23 32 0
161 25 22 35 0
161 25 21 35 8
161 25 20 35 76
161 25 16 15 102
161 25 13 19 100
161 26 36 19 44
161 26 35 15 24
161 26 34 8 24
161 26 33 8 74
161 26 28 32 48
161 26 27 32 0
161 26 26 32 0
161 26 25 32 0
161 26 24 32 0
161 26 23 32 0
161 26 22 32 64
161 26 16 8 42
161 26 15 8 24
161 26 14 15 24
161 26 13 19 76
161 27 28 35 32
161 27 27 35 0
161 27 26 35 0
161 27 25 35 0
161 27 24 35 0
161 27 23 35 0
161 27 22 35 64
161 28 28 35 32
161 28 27 35 0
161 28 26 35 0
161 28 25 35 0
161 28 24 35 0
161 28 23 35 0
161 28 22 35 64
161 29 28 35 40
161 29 27 35 0
161 29 26 35 0
161 29 25 35 0
161 29 24 35 0
161 29 23 35 0
161 29 22 35 72
161 30 27 35 40
161 30 26 35 8
161 30 25 35 0
161 30 24 35 8
161 30 23 35 72
161 31 25 24 110
162 1 37 19 52
162 1 36 19 24
162 1 35 8 24
162 1 34 8 90
162 1 15 8 58
162 1 14 8 24
162 1 13 19 16
162 1 12 19 84
162 2 37 19 100
162 2 33 15 60
162 2 32 15 24
162 2 31 15 24
162 2 30 15 24
162 2 29 15 24
162 2 28 15 24
162 2 27 15 24
162 2 26 15 24
162 2 25 15 24
162 2 24 15 24
162 2 23 15 24
162 2 22 15 24
162 2 21 15 24
162 2 20 15 24
162 2 19 15 24
162 2 18 15 24
162 2 17 15 24
162 2 16 15 92
162 2 13 19 34
162 2 12 19 68
162 3 37 19 100
162 3 13 19 34
162 3 12 19 68
162 4 38 9 52
162 4 37 19 64
162 4 13 19 34
162 4 12 19 0
162 4 11 9 84
162 5 38 11 36
162 5 37 19 64
162 5 13 19 34
162 5 12 19 0
162 5 11 11 68
162 6 38 11 36
162 6 37 19 64
162 6 13 19 34
162 6 12 19 0
162 6 11 11 68
162 7 38 9 44
162 7 37 19 64
162 7 13 19 34
162 7 12 19 0
162 7 11 9 76
162 8 37 19 100
162 8 13 19 34
162 8 12 19 68
162 9 37 19 100
162 9 13 19 34
162 9 12 19 68
162 10 37 19 100
162 10 13 19 34
162 10 12 19 68
162 11 37 19 100
162 11 13 19 34
162 11 12 19 68
162 12 37 19 100
162 12 13 19 34
162 12 12 19 68
162 13 37 19 100
162 13 13 19 34
162 13 12 19 68
162 14 37 19 100
162 14 13 19 34
162 14 12 19 68
162 15 37 19 100
162 15 13 19 34
162 15 12 19 68
162 16 37 19 100
162 16 13 19 34
162 16 12 19 68
162 17 37 19 100
162 17 13 19 34
162 17 12 19 68
162 18 37 19 100
162 18 13 19 34
162 18 12 19 68
162 19 37 19 100
162 19 33 10 60
162 19 32 10 24
162 19 31 10 24
162 19 30 10 16
162 19 29 10 16
162 19 28 10 16
162 19 27 10 24
162 19 26 10 24
162 19 25 10 24
162 19 24 10 16
162 19 23 10 16
162 19 22 10 16
162 19 21 10 16
162 19 20 10 16
162 19 19 10 24
162 19 18 10 24
162 19 17 10 24
162 19 16 10 92
162 19 13 19 34
162 19 12 19 68
162 20 38 9 52
162 20 37 19 64
162 20 34 15 118
162 20 30 18 36
162 20 29 18 4
162 20 28 18 68
162 20 24 32 32
162 20 23 32 0
162 20 22 32 0
162 20 21 32 0
162 20 20 32 64
162 20 15 15 118
162 20 13 19 34
162 20 12 19 0
162 20 11 9 84
162 21 38 11 36
162 21 37 19 64
162 21 34 11 102
162 21 31 18 52
162 21 30 18 0
162 21 29 18 0
162 21 28 18 0
162 21 27 18 84
162 21 25 32 48
162 21 24 32 0
162 21 23 32 0
162 21 22 32 0
162 21 21 32 0
162 21 20 32 0
162 21 19 32 80
162 21 15 11 102
162 21 13 19 34
162 21 12 19 0
162 21 11 11 68
162 22 38 11 36
162 22 37 19 64
162 22 34 11 102
162 22 32 21 52
162 22 31 21 0
162 22 30 21 0
162 22 29 21 0
162 22 28 21 0
162 22 27 21 0
162 22 26 21 20
162 22 25 35 0
162 22 24 35 0
162 22 23 35 0
162 22 22 35 0
162 22 21 35 0
162 22 20 35 0
162 22 19 35 64
162 22 15 11 102
162 22 13 19 34
162 22 12 19 0
162 22 11 11 68
162 23 38 9 44
162 23 37 19 64
162 23 34 15 102
162 23 32 21 44
162 23 31 21 0
162 23 30 21 0
162 23 29 21 0
162 23 28 21 0
162 23 27 21 0
162 23 26 21 12
162 23 25 35 0
162 23 24 35 0
162 23 23 35 0
162 23 22 35 0
162 23 21 35 0
162 23 20 35 0
162 23 19 35 64
162 23 15 15 102
162 23 13 19 34
162 23 12 19 0
162 23 11 9 76
162 24 37 19 100
162 24 34 15 102
162 24 31 21 44
162 24 30 21 0
162 24 29 21 0
162 24 28 21 0
162 24 27 21 68
162 24 25 35 32
162 24 24 35 0
162 24 23 35 0
162 24 22 35 0
162 24 21 35 0
162 24 20 35 0
162 24 19 35 72
162 24 15 15 102
162 24 13 19 34
162 24 12 19 68
162 25 37 19 100
162 25 34 15 102
162 25 30 21 44
162 25 29 21 12
162 25 28 21 4
162 25 27 32 0
162 25 26 32 16
162 25 25 32 0
162 25 24 32 0
162 25 23 32 0
162 25 22 35 0
162 25 21 35 8
162 25 20 35 72
162 25 15 15 102
162 25 13 19 34
162 25 12 19 68
162 26 37 19 44
162 26 36 19 24
162 26 35 8 24
162 26 34 8 74
162 26 28 32 34
162 26 27 32 0
162 26 26 32 0
162 26 25 32 0
162 26 24 32 0
162 26 23 32 0
162 26 22 32 66
162 26 15 8 42
162 26 14 8 24
162 26 13 19 8
162 26 12 19 76
162 27 28 35 32
162 27 27 35 0
162 27 26 35 0
162 27 25 35 0
162 27 24 35 0
162 27 23 35 0
162 27 22 35 64
162 28 28 35 32
162 28 27 35 0
162 28 26 35 0
162 28 25 35 0
162 28 24 35 0
162 28 23 35 0
162 28 22 35 64
162 29 28 35 42
162 29 27 35 0
162 29 26 35 0
162 29 25 35 0
162 29 24 35 0
162 29 23 35 0
162 29 22 35 74
162 30 27 35 42
162 30 26 35 8
162 30 25 35 8
162 30 24 35 8
162 30 23 35 74
163 1 37 19 48
163 1 36 8 24
163 1 35 8 90
163 1 14 8 58
163 1 13 8 24
163 1 12 19 80
163 2 37 19 98
163 2 34 15 60
163 2 33 15 24
163 2 32 15 24
163 2 31 15 24
163 2 30 15 24
163 2 29 15 24
163 2 28 15 24
163 2 27 15 24
163 2 26 15 24
163 2 25 15 24
163 2 24 15 24
163 2 23 15 24
163 2 22 15 24
163 2 21 15 24
163 2 20 15 24
163 2 19 15 24
163 2 18 15 24
163 2 17 15 24
163 2 16 15 24
163 2 15 15 92
163 2 12 19 98
163 3 37 19 98
163 3 12 19 98
163 4 38 9 50
163 4 37 19 66
163 4 12 19 34
163 4 11 9 82
163 5 38 11 34
163 5 37 19 66
163 5 12 19 34
163 5 11 11 66
163 6 38 11 34
163 6 37 19 66
163 6 12 19 34
163 6 11 11 66
163 7 38 9 42
163 7 37 19 66
163 7 12 19 34
163 7 11 9 74
163 8 37 19 98
163 8 12 19 98
163 9 37 19 98
163 9 12 19 98
163 10 37 19 98
163 10 12 19 98
163 11 37 19 98
163 11 12 19 98
163 12 37 19 98
163 12 12 19 98
163 13 37 19 98
163 13 12 19 98
163 14 37 19 98
163 14 12 19 98
163 15 37 19 98
163 15 12 19 98
163 16 37 19 98
163 16 12 19 98
163 17 37 19 98
163 17 12 19 98
163 18 37 19 98
163 18 12 19 98
163 19 37 19 98
163 19 34 10 60
163 19 33 10 24
163 19 32 10 24
163 19 31 10 16
163 19 30 10 16
163 19 29 10 16
163 19 28 10 16
163 19 27 10 16
163 19 26 10 24
163 19 25 10 24
163 19 24 10 16
163 19 23 10 16
163 19 22 10 16
163 19 21 10 16
163 19 20 10 16
163 19 19 10 24
163 19 18 10 24
163 19 17 10 24
163 19 16 10 24
163 19 15 10 92
163 19 12 19 98
163 20 38 9 50
163 20 37 19 66
163 20 35 15 118
163 20 31 18 36
163 20 30 18 0
163 20 29 18 0
163 20 28 18 0
163 20 27 18 68
163 20 24 32 34
163 20 23 32 0
163 20 22 32 0
163 20 21 32 0
163 20 20 32 66
163 20 14 15 118
163 20 12 19 34
163 20 11 9 82
163 21 38 11 34
163 21 37 19 66
163 21 35 11 102
163 21 32 18 52
163 21 31 18 0
163 21 30 18 0
163 21 29 18 0
163 21 28 18 0
163 21 27 18 0
163 21 26 18 20
163 21 25 32 18
163 21 24 32 0
163 21 23 32 0
163 21 22 32 0
163 21 21 32 0
163 21 20 32 0
163 21 19 32 82
163 21 14 11 102
163 21 12 19 34
163 21 11 11 66
163 22 38 11 34
163 22 37 19 66
163 22 35 11 102
163 22 32 21 32
163 22 31 21 0
163 22 30 21 0
163 22 29 21 0
163 22 28 21 0
163 22 27 21 0
163 22 26 21 0
163 22 25 35 0
163 22 24 35 0
163 22 23 35 0
163 22 22 35 0
163 22 21 35 0
163 22 20 35 0
163 22 19 35 64
163 22 14 11 100
163 22 12 19 34
163 22 11 11 66
163 23 38 9 42
163 23 37 19 66
163 23 35 15 102
163 23 32 21 32
163 23 31 21 0
163 23 30 21 0
163 23 29 21 0
163 23 28 21 0
163 23 27 21 0
163 23 26 21 0
163 23 25 35 0
163 23 24 35 0
163 23 23 35 0
163 23 22 35 0
163 23 21 35 0
163 23 20 35 0
163 23 19 35 64
163 23 14 15 100
163 23 12 19 34
163 23 11 9 74
163 24 37 19 98
163 24 35 15 102
163 24 32 21 44
163 24 31 21 0
163 24 30 21 0
163 24 29 21 0
163 24 28 21 0
163 24 27 21 0
163 24 26 21 4
163 24 25 35 2
163 24 24 35 0
163 24 23 35 0
163 24 22 35 0
163 24 21 35 0
163 24 20 35 0
163 24 19 35 74
163 24 14 15 102
163 24 12 19 98
163 25 37 19 98
163 25 35 15 102
163 25 31 21 44
163 25 30 21 8
163 25 29 21 8
163 25 28 21 8
163 25 27 21 0
163 25 26 32 2
163 25 25 32 2
163 25 24 32 2
163 25 23 35 0
163 25 22 35 8
163 25 21 35 0
163 25 20 35 64
163 25 14 15 102
163 25 12 19 98
163 26 37 19 40
163 26 36 8 24
163 26 35 8 74
163 26 27 32 34
163 26 26 32 0
163 26 25 32 0
163 26 24 32 0
163 26 23 32 66
163 26 21 32 36
163 26 20 32 4
163 26 19 32 84
163 26 14 8 42
163 26 13 8 24
163 26 12 19 72
163 27 28 35 50
163 27 27 35 0
163 27 26 35 0
163 27 25 35 0
163 27 24 35 0
163 27 23 35 0
163 27 22 35 16
163 27 21 35 4
163 27 20 35 4
163 27 19 35 4
163 27 18 35 84
163 28 28 35 42
163 28 27 35 0
163 28 26 35 0
163 28 25 35 0
163 28 24 35 0
163 28 23 35 0
163 28 22 35 8
163 28 21 35 4
163 28 20 35 4
163 28 19 35 4
163 28 18 35 76
163 29 27 35 42
163 29 26 35 0
163 29 25 35 0
163 29 24 35 0
163 29 23 35 74
163 29 21 35 44
163 29 20 35 12
163 29 19 35 76
163 30 26 35 42
163 30 25 35 10
163 30 24 35 74
164 1 38 15 52
164 1 37 8 24
164 1 36 8 88
164 1 13 8 58
164 1 12 8 24
164 1 11 15 84
164 2 38 15 100
164 2 35 15 60
164 2 34 15 24
164 2 33 15 24
164 2 32 15 24
164 2 31 15 24
164 2 30 15 24
164 2 29 15 24
164 2 28 15 24
164 2 27 15 24
164 2 26 15 24
164 2 25 15 24
164 2 24 15 24
164 2 23 15 24
164 2 22 15 24
164 2 21 15 24
164 2 20 15 24
164 2 19 15 24
164 2 18 15 24
164 2 17 15 24
164 2 16 15 24
164 2 15 15 24
164 2 14 15 92
164 2 11 15 100
164 3 38 15 108
164 3 11 15 108
164 4 39 9 116
164 4 10 9 116
164 5 39 11 100
164 5 10 11 100
164 6 39 11 100
164 6 10 11 100
164 7 39 9 108
164 7 10 9 108
164 8 38 15 116
164 8 11 15 116
164 9 38 15 100
164 9 11 15 100
164 10 38 15 100
164 10 11 15 100
164 11 38 15 100
164 11 11 15 100
164 12 38 15 100
164 12 11 15 100
164 13 38 15 100
164 13 11 15 100
164 14 38 15 100
164 14 11 15 100
164 15 38 15 100
164 15 11 15 100
164 16 38 15 100
164 16 11 15 100
164 17 38 15 100
164 17 11 15 100
164 18 38 15 100
164 18 11 15 100
164 19 38 15 108
164 19 35 10 60
164 19 34 10 24
164 19 33 10 24
164 19 32 10 24
164 19 31 10 16
164 19 30 10 16
164 19 29 10 16
164 19 28 10 16
164 19 27 10 16
164 19 26 10 24
164 19 25 10 24
164 19 24 10 24
164 19 23 10 16
164 19 22 10 16
164 19 21 10 16
164 19 20 10 24
164 19 19 10 24
164 19 18 10 24
164 19 17 10 24
164 19 16 10 24
164 19 15 10 24
164 19 14 10 92
164 19 11 15 108
164 20 39 9 116
164 20 36 15 116
164 20 31 18 32
164 20 30 18 0
164 20 29 18 0
164 20 28 18 0
164 20 27 18 64
164 20 23 32 34
164 20 22 32 2
164 20 21 32 66
164 20 13 15 118
164 20 10 9 116
164 21 39 11 100
164 21 36 11 100
164 21 32 18 48
164 21 31 18 0
164 21 30 18 0
164 21 29 18 0
164 21 28 18 0
164 21 27 18 0
164 21 26 18 80
164 21 24 32 50
164 21 23 32 0
164 21 22 32 0
164 21 21 32 0
164 21 20 32 82
164 21 17 18 52
164 21 16 18 20
164 21 15 18 84
164 21 13 11 102
164 21 10 11 100
164 22 39 11 100
164 22 36 11 100
164 22 32 21 32
164 22 31 21 0
164 22 30 21 0
164 22 29 21 0
164 22 28 21 0
164 22 27 21 0
164 22 26 21 0
164 22 25 35 18
164 22 24 35 0
164 22 23 35 0
164 22 22 35 0
164 22 21 35 0
164 22 20 35 0
164 22 19 35 16
164 22 18 21 20
164 22 17 21 4
164 22 16 21 4
164 22 15 21 4
164 22 14 21 16
164 22 13 11 68
164 22 10 11 100
164 23 39 9 108
164 23 36 15 100
164 23 32 21 32
164 23 31 21 0
164 23 30 21 0
164 23 29 21 0
164 23 28 21 0
164 23 27 21 0
164 23 26 21 0
164 23 25 35 10
164 23 24 35 0
164 23 23 35 0
164 23 22 35 0
164 23 21 35 0
164 23 20 35 0
164 23 19 35 8
164 23 18 21 12
164 23 17 21 4
164 23 16 21 4
164 23 15 21 4
164 23 14 21 8
164 23 13 15 68
164 23 10 9 108
164 24 38 15 116
164 24 36 15 100
164 24 32 21 40
164 24 31 21 0
164 24 30 21 0
164 24 29 21 0
164 24 28 21 0
164 24 27 21 0
164 24 26 21 72
164 24 24 35 42
164 24 23 35 0
164 24 22 35 0
164 24 21 35 0
164 24 20 35 66
164 24 17 21 44
164 24 16 21 12
164 24 15 21 76
164 24 13 15 102
164 24 11 15 116
164 25 38 15 100
164 25 36 15 100
164 25 31 21 40
164 25 30 21 8
164 25 29 21 0
164 25 28 21 8
164 25 27 21 72
164 25 23 35 42
164 25 22 35 0
164 25 21 32 0
164 25 20 32 0
164 25 19 32 84
164 25 13 15 102
164 25 11 15 100
164 26 38 15 44
164 26 37 8 24
164 26 36 8 72
164 26 29 24 110
164 26 26 32 50
164 26 25 32 18
164 26 24 32 82
164 26 22 32 36
164 26 21 32 0
164 26 20 32 0
164 26 19 32 0
164 26 18 32 84
164 26 13 8 42
164 26 12 8 24
164 26 11 15 76
164 27 27 35 50
164 27 26 35 2
164 27 25 35 2
164 27 24 35 2
164 27 23 35 16
164 27 22 35 0
164 27 21 35 0
164 27 20 35 0
164 27 19 35 0
164 27 18 35 0
164 27 17 35 84
164 28 27 35 42
164 28 26 35 2
164 28 25 35 2
164 28 24 35 2
164 28 23 35 8
164 28 22 35 0
164 28 21 35 0
164 28 20 35 0
164 28 19 35 0
164 28 18 35 0
164 28 17 35 76
164 29 26 35 42
164 29 25 35 10
164 29 24 35 74
164 29 22 35 44
164 29 21 35 0
164 29 20 35 0
164 29 19 35 0
164 29 18 35 76
164 30 21 35 44
164 30 20 35 12
164 30 19 35 76
165 1 38 15 48
165 1 37 8 24
165 1 36 8 90
165 1 12 8 56
165 1 11 15 80
165 2 38 15 96
165 2 35 15 56
165 2 34 15 24
165 2 33 15 24
165 2 32 15 24
165 2 31 15 24
165 2 30 15 24
165 2 29 15 24
165 2 28 15 24
165 2 27 15 24
165 2 26 15 24
165 2 25 15 24
165 2 24 15 24
165 2 23 15 24
165 2 22 15 24
165 2 21 15 24
165 2 20 15 24
165 2 19 15 24
165 2 18 15 24
165 2 17 15 24
165 2 16 15 24
165 2 15 15 24
165 2 14 15 24
165 2 13 15 92
165 2 11 15 96
165 3 38 15 104
165 3 11 15 104
165 4 39 9 112
165 4 10 9 112
165 5 39 11 96
165 5 10 11 96
165 6 39 11 96
165 6 10 11 96
165 7 39 9 104
165 7 10 9 104
165 8 38 15 112
165 8 11 15 112
165 9 38 15 96
165 9 11 15 96
165 10 38 15 96
165 10 11 15 96
165 11 38 15 96
165 11 11 15 96
165 12 38 15 96
165 12 11 15 96
165 13 38 15 96
165 13 11 15 96
165 14 38 15 96
165 14 11 15 96
165 15 38 15 96
165 15 11 15 96
165 16 38 15 96
165 16 11 15 96
165 17 38 15 96
165 17 11 15 96
165 18 38 15 96
165 18 11 15 96
165 19 38 15 104
165 19 35 10 56
165 19 34 10 24
165 19 33 10 24
165 19 32 10 24
165 19 31 10 16
165 19 30 10 16
165 19 29 10 16
165 19 28 10 16
165 19 27 10 16
165 19 26 10 24
165 19 25 10 24
165 19 24 10 24
165 19 23 10 24
165 19 22 10 24
165 19 21 10 24
165 19 20 10 24
165 19 19 10 24
165 19 18 10 24
165 19 17 10 16
165 19 16 10 16
165 19 15 10 16
165 19 14 10 24
165 19 13 10 92
165 19 11 15 104
165 20 39 9 112
165 20 36 15 114
165 20 31 18 34
165 20 30 18 0
165 20 29 18 0
165 20 28 18 0
165 20 27 18 66
165 20 17 18 36
165 20 16 18 4
165 20 15 18 68
165 20 12 15 116
165 20 10 9 112
165 21 39 11 96
165 21 36 11 98
165 21 32 18 50
165 21 31 18 0
165 21 30 18 0
165 21 29 18 0
165 21 28 18 0
165 21 27 18 0
165 21 26 18 82
165 21 23 32 50
165 21 22 32 18
165 21 21 32 82
165 21 18 18 52
165 21 17 18 0
165 21 16 18 0
165 21 15 18 0
165 21 14 18 84
165 21 12 11 100
165 21 10 11 96
165 22 39 11 96
165 22 36 11 98
165 22 32 21 32
165 22 31 21 0
165 22 30 21 0
165 22 29 21 0
165 22 28 21 0
165 22 27 21 0
165 22 26 21 64
165 22 24 35 50
165 22 23 35 2
165 22 22 35 2
165 22 21 35 2
165 22 20 35 18
165 22 19 21 16
165 22 18 21 0
165 22 17 21 0
165 22 16 21 0
165 22 15 21 0
165 22 14 21 0
165 22 13 21 16
165 22 12 11 68
165 22 10 11 96
165 23 39 9 104
165 23 36 15 98
165 23 32 21 32
165 23 31 21 0
165 23 30 21 0
165 23 29 21 0
165 23 28 21 0
165 23 27 21 0
165 23 26 21 64
165 23 24 35 42
165 23 23 35 2
165 23 22 35 2
165 23 21 35 2
165 23 20 35 10
165 23 19 21 8
165 23 18 21 0
165 23 17 21 0
165 23 16 21 0
165 23 15 21 0
165 23 14 21 0
165 23 13 21 8
165 23 12 15 68
165 23 10 9 104
165 24 38 15 112
165 24 36 15 98
165 24 32 21 42
165 24 31 21 0
165 24 30 21 0
165 24 29 21 0
165 24 28 21 0
165 24 27 21 0
165 24 26 21 74
165 24 23 35 42
165 24 22 35 2
165 24 21 35 66
165 24 18 21 36
165 24 17 21 0
165 24 16 21 0
165 24 15 21 0
165 24 14 21 76
165 24 12 15 36
165 24 11 15 80
165 25 38 15 96
165 25 36 15 98
165 25 31 21 42
165 25 30 21 8
165 25 29 21 8
165 25 28 21 8
165 25 27 21 74
165 25 22 32 32
165 25 21 32 0
165 25 20 32 16
165 25 19 32 16
165 25 18 32 4
165 25 17 21 4
165 25 16 21 12
165 25 15 21 76
165 25 12 15 36
165 25 11 15 64
165 26 38 15 40
165 26 37 8 24
165 26 36 8 74
165 26 23 32 52
165 26 22 32 0
165 26 21 32 0
165 26 20 32 0
165 26 19 32 0
165 26 18 32 0
165 26 17 32 68
165 26 12 8 40
165 26 11 15 72
165 27 23 35 32
165 27 22 35 0
165 27 21 35 0
165 27 20 35 0
165 27 19 35 0
165 27 18 35 0
165 27 17 35 64
165 28 23 35 32
165 28 22 35 0
165 28 21 35 0
165 28 20 35 0
165 28 19 35 0
165 28 18 35 0
165 28 17 35 64
165 29 23 35 44
165 29 22 35 0
165 29 21 35 0
165 29 20 35 0
165 29 19 35 0
165 29 18 35 0
165 29 17 35 76
165 30 22 35 44
165 30 21 35 8
165 30 20 35 8
165 30 19 35 8
165 30 18 35 76
166 1 38 15 48
166 1 37 8 88
166 1 12 8 56
166 1 11 15 80
166 2 38 15 98
166 2 36 13 60
166 2 35 13 24
166 2 34 13 24
166 2 33 13 24
166 2 32 13 24
166 2 31 13 24
166 2 30 13 24
166 2 29 13 24
166 2 28 13 24
166 2 27 13 24
166 2 26 13 24
166 2 25 13 24
166 2 24 13 24
166 2 23 13 24
166 2 22 13 24
166 2 21 13 24
166 2 20 13 24
166 2 19 13 24
166 2 18 13 24
166 2 17 13 24
166 2 16 13 24
166 2 15 13 24
166 2 14 13 24
166 2 13 13 88
166 2 11 15 98
166 3 38 15 106
166 3 11 15 106
166 4 39 9 114
166 4 10 9 114
166 5 39 11 98
166 5 10 11 98
166 6 39 11 98
166 6 10 11 98
166 7 39 9 106
166 7 10 9 106
166 8 38 15 114
166 8 11 15 114
166 9 38 15 98
166 9 11 15 98
166 10 38 15 98
166 10 11 15 98
166 11 38 15 98
166 11 11 15 98
166 12 38 15 98
166 12 11 15 98
166 13 38 15 98
166 13 11 15 98
166 14 38 15 98
166 14 11 15 98
166 15 38 15 98
166 15 11 15 98
166 16 38 15 98
166 16 11 15 98
166 17 38 15 98
166 17 11 15 98
166 18 38 15 98
166 18 11 15 98
166 19 38 15 106
166 19 36 10 60
166 19 35 10 24
166 19 34 10 24
166 19 33 10 24
166 19 32 10 24
166 19 31 10 24
166 19 30 10 16
166 19 29 10 16
166 19 28 10 16
166 19 27 10 24
166 19 26 10 24
166 19 25 10 24
166 19 24 10 24
166 19 23 10 24
166 19 22 10 24
166 19 21 10 24
166 19 20 10 24
166 19 19 10 24
166 19 18 10 16
166 19 17 10 16
166 19 16 10 16
166 19 15 10 16
166 19 14 10 16
166 19 13 10 88
166 19 11 15 106
166 20 39 9 114
166 20 37 15 116
166 20 30 18 34
166 20 29 18 2
166 20 28 18 66
166 20 18 18 36
166 20 17 18 0
166 20 16 18 0
166 20 15 18 0
166 20 14 18 68
166 20 12 15 112
166 20 10 9 114
166 21 39 11 98
166 21 37 11 100
166 21 31 18 50
166 21 30 18 0
166 21 29 18 0
166 21 28 18 0
166 21 27 18 82
166 21 19 18 52
166 21 18 18 0
166 21 17 18 0
166 21 16 18 0
166 21 15 18 0
166 21 14 18 0
166 21 13 18 20
166 21 12 11 64
166 21 10 11 98
166 22 39 11 98
166 22 37 11 100
166 22 32 21 50
166 22 31 21 0
166 22 30 21 0
166 22 29 21 0
166 22 28 21 0
166 22 27 21 0
166 22 26 21 80
166 22 19 21 32
166 22 18 21 0
166 22 17 21 0
166 22 16 21 0
166 22 15 21 0
166 22 14 21 0
166 22 13 21 0
166 22 12 11 64
166 22 10 11 98
166 23 39 9 106
166 23 37 15 100
166 23 32 21 42
166 23 31 21 0
166 23 30 21 0
166 23 29 21 0
166 23 28 21 0
166 23 27 21 0
166 23 26 21 72
166 23 19 21 32
166 23 18 21 0
166 23 17 21 0
166 23 16 21 0
166 23 15 21 0
166 23 14 21 0
166 23 13 21 0
166 23 12 15 64
166 23 10 9 106
166 24 38 15 50
166 24 37 15 68
166 24 31 21 42
166 24 30 21 0
166 24 29 21 0
166 24 28 21 0
166 24 27 21 74
166 24 19 21 36
166 24 18 21 0
166 24 17 21 0
166 24 16 21 0
166 24 15 21 0
166 24 14 21 0
166 24 13 21 12
166 24 12 15 0
166 24 11 15 82
166 25 38 15 34
166 25 37 15 68
166 25 30 21 42
166 25 29 21 10
166 25 28 21 74
166 25 22 32 48
166 25 21 32 16
166 25 20 32 16
166 25 19 32 0
166 25 18 21 0
166 25 17 21 0
166 25 16 21 8
166 25 15 21 8
166 25 14 21 76
166 25 12 15 32
166 25 11 15 66
166 26 38 15 40
166 26 37 8 72
166 26 23 32 48
166 26 22 32 0
166 26 21 32 0
166 26 20 32 0
166 26 19 32 0
166 26 18 32 0
166 26 17 32 64
166 26 12 8 40
166 26 11 15 72
166 27 23 35 32
166 27 22 35 0
166 27 21 35 0
166 27 20 35 0
166 27 19 35 0
166 27 18 35 0
166 27 17 35 64
166 28 23 35 32
166 28 22 35 0
166 28 21 35 0
166 28 20 35 0
166 28 19 35 0
166 28 18 35 0
166 28 17 35 64
166 29 23 35 40
166 29 22 35 0
166 29 21 35 0
166 29 20 35 0
166 29 19 35 0
166 29 18 35 0
166 29 17 35 72
166 30 22 35 40
166 30 21 35 8
166 30 20 35 0
166 30 19 35 8
166 30 18 35 72
166 31 20 24 110
167 1 39 15 52
167 1 38 8 24
167 1 37 8 88
167 1 12 8 56
167 1 11 8 24
167 1 10 15 84
167 2 39 15 100
167 2 36 13 56
167 2 35 13 24
167 2 34 13 24
167 2 33 13 24
167 2 32 13 24
167 2 31 13 24
167 2 30 13 24
167 2 29 13 24
167 2 28 13 24
167 2 27 13 24
167 2 26 13 24
167 2 25 13 24
167 2 24 13 24
167 2 23 13 24
167 2 22 13 24
167 2 21 13 24
167 2 20 13 24
167 2 19 13 24
167 2 18 13 24
167 2 17 13 24
167 2 16 13 24
167 2 15 13 24
167 2 14 13 24
167 2 13 13 88
167 2 10 15 100
167 3 39 15 108
167 3 10 15 108
167 4 40 9 116
167 4 9 9 116
167 5 40 11 100
167 5 9 11 100
167 6 40 11 100
167 6 9 11 100
167 7 40 9 108
167 7 9 9 108
167 8 39 15 116
167 8 10 15 116
167 9 39 15 100
167 9 10 15 100
167 10 39 15 100
167 10 10 15 100
167 11 39 15 100
167 11 10 15 100
167 12 39 15 100
167 12 10 15 100
167 13 39 15 100
167 13 10 15 100
167 14 39 15 100
167 14 10 15 100
167 15 39 15 100
167 15 10 15 100
167 16 39 15 100
167 16 10 15 100
167 17 39 15 100
167 17 10 15 100
167 18 39 15 100
167 18 10 15 100
167 19 39 15 108
167 19 36 10 56
167 19 35 10 24
167 19 34 10 24
167 19 33 10 24
167 19 32 10 24
167 19 31 10 24
167 19 30 10 24
167 19 29 10 24
167 19 28 10 24
167 19 27 10 24
167 19 26 10 24
167 19 25 10 24
167 19 24 10 24
167 19 23 10 24
167 19 22 10 24
167 19 21 10 24
167 19 20 10 24
167 19 19 10 24
167 19 18 10 16
167 19 17 10 16
167 19 16 10 16
167 19 15 10 16
167 19 14 10 16
167 19 13 10 88
167 19 10 15 108
167 20 40 9 116
167 20 37 15 112
167 20 18 18 32
167 20 17 18 0
167 20 16 18 0
167 20 15 18 0
167 20 14 18 64
167 20 12 15 112
167 20 9 9 116
167 21 40 11 100
167 21 37 11 96
167 21 30 18 50
167 21 29 18 18
167 21 28 18 82
167 21 25 32 52
167 21 24 32 20
167 21 23 32 84
167 21 19 18 48
167 21 18 18 0
167 21 17 18 0
167 21 16 18 0
167 21 15 18 0
167 21 14 18 0
167 21 13 18 16
167 21 12 11 64
167 21 9 11 100
167 22 40 11 100
167 22 37 11 96
167 22 31 21 48
167 22 30 21 2
167 22 29 21 2
167 22 28 21 2
167 22 27 21 16
167 22 26 35 16
167 22 25 35 4
167 22 24 35 4
167 22 23 35 4
167 22 22 35 84
167 22 19 21 32
167 22 18 21 0
167 22 17 21 0
167 22 16 21 0
167 22 15 21 0
167 22 14 21 0
167 22 13 21 0
167 22 12 11 64
167 22 9 11 100
167 23 40 9 108
167 23 37 15 96
167 23 31 21 40
167 23 30 21 2
167 23 29 21 2
167 23 28 21 2
167 23 27 21 8
167 23 26 35 8
167 23 25 35 4
167 23 24 35 4
167 23 23 35 4
167 23 22 35 76
167 23 19 21 32
167 23 18 21 0
167 23 17 21 0
167 23 16 21 0
167 23 15 21 0
167 23 14 21 0
167 23 13 21 0
167 23 12 15 64
167 23 9 9 108
167 24 39 15 116
167 24 37 15 96
167 24 30 21 42
167 24 29 21 10
167 24 28 21 74
167 24 25 35 44
167 24 24 35 12
167 24 23 35 76
167 24 19 21 32
167 24 18 21 0
167 24 17 21 0
167 24 16 21 0
167 24 15 21 0
167 24 14 21 0
167 24 13 21 8
167 24 12 15 64
167 24 10 15 116
167 25 39 15 100
167 25 37 15 96
167 25 22 32 50
167 25 21 32 16
167 25 20 32 16
167 25 19 32 0
167 25 18 21 0
167 25 17 21 0
167 25 16 21 0
167 25 15 21 8
167 25 14 21 72
167 25 12 15 96
167 25 10 15 100
167 26 39 15 44
167 26 38 8 24
167 26 37 8 72
167 26 23 32 50
167 26 22 32 0
167 26 21 32 0
167 26 20 32 0
167 26 19 32 0
167 26 18 32 0
167 26 17 32 2
167 26 16 24 78
167 26 12 8 40
167 26 11 8 24
167 26 10 15 76
167 27 23 35 32
167 27 22 35 0
167 27 21 35 0
167 27 20 35 0
167 27 19 35 0
167 27 18 35 0
167 27 17 35 64
167 28 23 35 32
167 28 22 35 0
167 28 21 35 0
167 28 20 35 0
167 28 19 35 0
167 28 18 35 0
167 28 17 35 64
167 29 23 35 42
167 29 22 35 0
167 29 21 35 0
167 29 20 35 0
167 29 19 35 0
167 29 18 35 0
167 29 17 35 74
167 30 22 35 42
167 30 21 35 8
167 30 20 35 8
167 30 19 35 8
167 30 18 35 74
168 1 39 19 48
168 1 38 8 24
168 1 37 8 88
168 1 12 8 56
168 1 11 8 24
168 1 10 19 80
168 2 39 19 96
168 2 36 15 56
168 2 35 15 24
168 2 34 15 24
168 2 33 15 24
168 2 32 15 24
168 2 31 15 24
168 2 30 15 24
168 2 29 15 24
168 2 28 15 24
168 2 27 15 24
168 2 26 15 24
168 2 25 15 24
168 2 24 15 24
168 2 23 15 24
168 2 22 15 24
168 2 21 15 24
168 2 20 15 24
168 2 19 15 24
168 2 18 15 24
168 2 17 15 24
168 2 16 15 24
168 2 15 15 24
168 2 14 15 24
168 2 13 15 88
168 2 10 19 96
168 3 39 19 96
168 3 10 19 96
168 4 40 9 48
168 4 39 19 68
168 4 10 19 36
168 4 9 9 80
168 5 40 11 32
168 5 39 19 68
168 5 10 19 36
168 5 9 11 64
168 6 40 11 32
168 6 39 19 68
168 6 10 19 36
168 6 9 11 64
168 7 40 9 40
168 7 39 19 68
168 7 10 19 36
168 7 9 9 72
168 8 39 19 96
168 8 10 19 96
168 9 39 19 96
168 9 10 19 96
168 10 39 19 96
168 10 10 19 96
168 11 39 19 96
168 11 10 19 96
168 12 39 19 96
168 12 10 19 96
168 13 39 19 96
168 13 10 19 96
168 14 39 19 96
168 14 10 19 96
168 15 39 19 96
168 15 10 19 96
168 16 39 19 96
168 16 10 19 96
168 17 39 19 96
168 17 10 19 96
168 18 39 19 96
168 18 10 19 96
168 19 39 19 96
168 19 36 10 56
168 19 35 10 24
168 19 34 10 24
168 19 33 10 24
168 19 32 10 24
168 19 31 10 24
168 19 30 10 24
168 19 29 10 24
168 19 28 10 24
168 19 27 10 24
168 19 26 10 24
168 19 25 10 16
168 19 24 10 16
168 19 23 10 16
168 19 22 10 24
168 19 21 10 24
168 19 20 10 24
168 19 19 10 24
168 19 18 10 16
168 19 17 10 16
168 19 16 10 16
168 19 15 10 16
168 19 14 10 16
168 19 13 10 88
168 19 10 19 96
168 20 40 9 48
168 20 39 19 68
168 20 37 15 112
168 20 25 32 36
168 20 24 32 4
168 20 23 32 68
168 20 18 18 34
168 20 17 18 0
168 20 16 18 0
168 20 15 18 0
168 20 14 18 66
168 20 12 15 112
168 20 10 19 36
168 20 9 9 80
168 21 40 11 32
168 21 39 19 68
168 21 37 11 96
168 21 34 32 52
168 21 33 32 20
168 21 32 32 84
168 21 26 32 52
168 21 25 32 0
168 21 24 32 0
168 21 23 32 0
168 21 22 32 84
168 21 19 18 50
168 21 18 18 0
168 21 17 18 0
168 21 16 18 0
168 21 15 18 0
168 21 14 18 0
168 21 13 18 18
168 21 12 11 64
168 21 10 19 36
168 21 9 11 64
168 22 40 11 32
168 22 39 19 68
168 22 37 11 96
168 22 35 35 52
168 22 34 35 4
168 22 33 35 4
168 22 32 35 4
168 22 31 35 80
168 22 27 35 48
168 22 26 35 0
168 22 25 35 0
168 22 24 35 0
168 22 23 35 0
168 22 22 35 0
168 22 21 35 84
168 22 19 21 32
168 22 18 21 0
168 22 17 21 0
168 22 16 21 0
168 22 15 21 0
168 22 14 21 0
168 22 13 21 0
168 22 12 11 64
168 22 10 19 36
168 22 9 11 64
168 23 40 9 40
168 23 39 19 68
168 23 37 15 96
168 23 35 35 44
168 23 34 35 4
168 23 33 35 4
168 23 32 35 4
168 23 31 35 72
168 23 27 35 40
168 23 26 35 0
168 23 25 35 0
168 23 24 35 0
168 23 23 35 0
168 23 22 35 0
168 23 21 35 76
168 23 19 21 32
168 23 18 21 0
168 23 17 21 0
168 23 16 21 0
168 23 15 21 0
168 23 14 21 0
168 23 13 21 0
168 23 12 15 64
168 23 10 19 36
168 23 9 9 72
168 24 39 19 96
168 24 37 15 96
168 24 34 35 44
168 24 33 35 12
168 24 32 35 76
168 24 26 35 44
168 24 25 35 0
168 24 24 35 0
168 24 23 35 0
168 24 22 35 76
168 24 19 21 34
168 24 18 21 0
168 24 17 21 0
168 24 16 21 0
168 24 15 21 0
168 24 14 21 0
168 24 13 21 10
168 24 12 15 64
168 24 10 19 96
168 25 39 19 96
168 25 37 15 96
168 25 25 35 44
168 25 24 35 12
168 25 23 35 76
168 25 21 32 50
168 25 20 32 18
168 25 19 32 2
168 25 18 21 2
168 25 17 21 8
168 25 16 21 8
168 25 15 21 8
168 25 14 21 74
168 25 12 15 96
168 25 10 19 96
168 26 39 19 40
168 26 38 8 24
168 26 37 8 72
168 26 22 32 50
168 26 21 32 0
168 26 20 32 0
168 26 19 32 0
168 26 18 32 66
168 26 12 8 40
168 26 11 8 24
168 26 10 19 72
168 27 23 35 50
168 27 22 35 0
168 27 21 35 0
168 27 20 35 0
168 27 19 35 0
168 27 18 35 0
168 27 17 35 82
168 28 23 35 42
168 28 22 35 0
168 28 21 35 0
168 28 20 35 0
168 28 19 35 0
168 28 18 35 0
168 28 17 35 74
168 29 22 35 42
168 29 21 35 0
168 29 20 35 0
168 29 19 35 0
168 29 18 35 74
168 30 21 35 42
168 30 20 35 10
168 30 19 35 74
169 1 39 19 48
169 1 38 8 24
169 1 37 8 88
169 1 12 8 56
169 1 11 8 24
169 1 10 19 80
169 2 39 19 96
169 2 36 15 56
169 2 35 15 24
169 2 34 15 24
169 2 33 15 24
169 2 32 15 24
169 2 31 15 24
169 2 30 15 24
169 2 29 15 24
169 2 28 15 24
169 2 27 15 24
169 2 26 15 24
169 2 25 15 24
169 2 24 15 24
169 2 23 15 24
169 2 22 15 24
169 2 21 15 24
169 2 20 15 24
169 2 19 15 24
169 2 18 15 24
169 2 17 15 24
169 2 16 15 24
169 2 15 15 24
169 2 14 15 24
169 2 13 15 88
169 2 10 19 96
169 3 39 19 96
169 3 10 19 96
169 4 40 9 48
169 4 39 19 64
169 4 10 19 32
169 4 9 9 80
169 5 40 11 32
169 5 39 19 64
169 5 10 19 32
169 5 9 11 64
169 6 40 11 32
169 6 39 19 64
169 6 10 19 32
169 6 9 11 64
169 7 40 9 40
169 7 39 19 64
169 7 10 19 32
169 7 9 9 72
169 8 39 19 96
169 8 10 19 96
169 9 39 19 96
169 9 10 19 96
169 10 39 19 96
169 10 10 19 96
169 11 39 19 96
169 11 10 19 96
169 12 39 19 96
169 12 10 19 96
169 13 39 19 96
169 13 10 19 96
169 14 39 19 96
169 14 10 19 96
169 15 39 19 96
169 15 10 19 96
169 16 39 19 96
169 16 10 19 96
169 17 39 19 96
169 17 10 19 96
169 18 39 19 96
169 18 10 19 96
169 19 39 19 96
169 19 36 10 56
169 19 35 10 24
169 19 34 10 16
169 19 33 10 16
169 19 32 10 16
169 19 31 10 24
169 19 30 10 24
169 19 29 10 24
169 19 28 10 24
169 19 27 10 24
169 19 26 10 16
169 19 25 10 16
169 19 24 10 16
169 19 23 10 16
169 19 22 10 16
169 19 21 10 24
169 19 20 10 24
169 19 19 10 24
169 19 18 10 24
169 19 17 10 16
169 19 16 10 16
169 19 15 10 16
169 19 14 10 24
169 19 13 10 88
169 19 10 19 96
169 20 40 9 48
169 20 39 19 64
169 20 37 15 112
169 20 34 32 36
169 20 33 32 4
169 20 32 32 68
169 20 26 32 36
169 20 25 32 0
169 20 24 32 0
169 20 23 32 0
169 20 22 32 68
169 20 17 18 34
169 20 16 18 2
169 20 15 18 66
169 20 12 15 112
169 20 10 19 32
169 20 9 9 80
169 21 40 11 32
169 21 39 19 64
169 21 37 11 96
169 21 35 32 52
169 21 34 32 0
169 21 33 32 0
169 21 32 32 0
169 21 31 32 84
169 21 27 32 52
169 21 26 32 0
169 21 25 32 0
169 21 24 32 0
169 21 23 32 0
169 21 22 32 0
169 21 21 32 84
169 21 18 18 50
169 21 17 18 0
169 21 16 18 0
169 21 15 18 0
169 21 14 18 82
169 21 12 11 96
169 21 10 19 32
169 21 9 11 64
169 22 40 11 32
169 22 39 19 64
169 22 37 11 32
169 22 36 35 20
169 22 35 35 0
169 22 34 35 0
169 22 33 35 0
169 22 32 35 0
169 22 31 35 0
169 22 30 35 84
169 22 27 35 32
169 22 26 35 0
169 22 25 35 0
169 22 24 35 0
169 22 23 35 0
169 22 22 35 0
169 22 21 35 64
169 22 19 21 50
169 22 18 21 0
169 22 17 21 0
169 22 16 21 0
169 22 15 21 0
169 22 14 21 0
169 22 13 21 18
169 22 12 11 64
169 22 10 19 32
169 22 9 11 64
169 23 40 9 40
169 23 39 19 64
169 23 37 15 32
169 23 36 35 12
169 23 35 35 0
169 23 34 35 0
169 23 33 35 0
169 23 32 35 0
169 23 31 35 0
169 23 30 35 76
169 23 27 35 32
169 23 26 35 0
169 23 25 35 0
169 23 24 35 0
169 23 23 35 0
169 23 22 35 0
169 23 21 35 64
169 23 19 21 42
169 23 18 21 0
169 23 17 21 0
169 23 16 21 0
169 23 15 21 0
169 23 14 21 0
169 23 13 21 10
169 23 12 15 64
169 23 10 19 32
169 23 9 9 72
169 24 39 19 96
169 24 37 15 96
169 24 35 35 44
169 24 34 35 0
169 24 33 35 0
169 24 32 35 0
169 24 31 35 76
169 24 27 35 44
169 24 26 35 0
169 24 25 35 0
169 24 24 35 0
169 24 23 35 0
169 24 22 35 0
169 24 21 35 76
169 24 18 21 42
169 24 17 21 0
169 24 16 21 0
169 24 15 21 0
169 24 14 21 74
169 24 12 15 96
169 24 10 19 96
169 25 39 19 96
169 25 37 15 96
169 25 34 35 44
169 25 33 35 12
169 25 32 35 76
169 25 26 35 44
169 25 25 35 8
169 25 24 35 8
169 25 23 35 8
169 25 22 35 76
169 25 17 21 42
169 25 16 21 10
169 25 15 21 74
169 25 12 15 96
169 25 10 19 96
169 26 39 19 40
169 26 38 8 24
169 26 37 8 72
169 26 29 18 52
169 26 28 18 20
169 26 27 18 84
169 26 21 32 50
169 26 20 32 18
169 26 19 32 82
169 26 12 8 40
169 26 11 8 24
169 26 10 19 72
169 27 30 21 52
169 27 29 21 4
169 27 28 21 4
169 27 27 21 4
169 27 26 21 84
169 27 22 35 50
169 27 21 35 2
169 27 20 35 2
169 27 19 35 2
169 27 18 35 82
169 28 30 21 44
169 28 29 21 4
169 28 28 21 4
169 28 27 21 4
169 28 26 21 76
169 28 22 35 42
169 28 21 35 2
169 28 20 35 2
169 28 19 35 2
169 28 18 35 74
169 29 29 21 44
169 29 28 21 12
169 29 27 21 76
169 29 21 35 42
169 29 20 35 10
169 29 19 35 74
170 1 39 19 48
170 1 38 8 24
170 1 37 8 88
170 1 12 8 56
170 1 11 8 24
170 1 10 19 80
170 2 39 19 96
170 2 36 15 56
170 2 35 15 24
170 2 34 15 24
170 2 33 15 24
170 2 32 15 24
170 2 31 15 24
170 2 30 15 24
170 2 29 15 24
170 2 28 15 24
170 2 27 15 24
170 2 26 15 24
170 2 25 15 24
170 2 24 15 24
170 2 23 15 24
170 2 22 15 24
170 2 21 15 24
170 2 20 15 24
170 2 19 15 24
170 2 18 15 24
170 2 17 15 24
170 2 16 15 24
170 2 15 15 24
170 2 14 15 24
170 2 13 15 88
170 2 10 19 96
170 3 39 19 96
170 3 10 19 96
170 4 40 9 48
170 4 39 19 64
170 4 10 19 32
170 4 9 9 80
170 5 40 11 32
170 5 39 19 64
170 5 10 19 32
170 5 9 11 64
170 6 40 11 32
170 6 39 19 64
170 6 10 19 32
170 6 9 11 64
170 7 40 9 40
170 7 39 19 64
170 7 10 19 32
170 7 9 9 72
170 8 39 19 96
170 8 10 19 96
170 9 39 19 96
170 9 10 19 96
170 10 39 19 96
170 10 10 19 96
170 11 39 19 96
170 11 10 19 96
170 12 39 19 96
170 12 10 19 96
170 13 39 19 96
170 13 10 19 96
170 14 39 19 96
170 14 10 19 96
170 15 39 19 96
170 15 10 19 96
170 16 39 19 96
170 16 10 19 96
170 17 39 19 96
170 17 10 19 96
170 18 39 19 96
170 18 10 19 96
170 19 39 19 96
170 19 36 10 56
170 19 35 10 16
170 19 34 10 16
170 19 33 10 16
170 19 32 10 16
170 19 31 10 16
170 19 30 10 24
170 19 29 10 24
170 19 28 10 24
170 19 27 10 24
170 19 26 10 16
170 19 25 10 16
170 19 24 10 16
170 19 23 10 16
170 19 22 10 16
170 19 21 10 24
170 19 20 10 24
170 19 19 10 24
170 19 18 10 24
170 19 17 10 24
170 19 16 10 24
170 19 15 10 24
170 19 14 10 24
170 19 13 10 88
170 19 10 19 96
170 20 40 9 48
170 20 39 19 64
170 20 37 15 112
170 20 35 32 36
170 20 34 32 0
170 20 33 32 0
170 20 32 32 0
170 20 31 32 68
170 20 26 32 32
170 20 25 32 0
170 20 24 32 0
170 20 23 32 0
170 20 22 32 64
170 20 12 15 112
170 20 10 19 32
170 20 9 9 80
170 21 40 11 32
170 21 39 19 64
170 21 37 11 32
170 21 36 32 20
170 21 35 32 0
170 21 34 32 0
170 21 33 32 0
170 21 32 32 0
170 21 31 32 0
170 21 30 32 84
170 21 27 32 48
170 21 26 32 0
170 21 25 32 0
170 21 24 32 0
170 21 23 32 0
170 21 22 32 0
170 21 21 32 80
170 21 17 18 48
170 21 16 18 18
170 21 15 18 82
170 21 12 11 96
170 21 10 19 32
170 21 9 11 64
170 22 40 11 32
170 22 39 19 64
170 22 37 11 32
170 22 36 35 0
170 22 35 35 0
170 22 34 35 0
170 22 33 35 0
170 22 32 35 0
170 22 31 35 0
170 22 30 35 64
170 22 27 35 32
170 22 26 35 0
170 22 25 35 0
170 22 24 35 0
170 22 23 35 0
170 22 22 35 0
170 22 21 35 64
170 22 18 21 48
170 22 17 21 0
170 22 16 21 0
170 22 15 21 2
170 22 14 21 82
170 22 12 11 96
170 22 10 19 32
170 22 9 11 64
170 23 40 9 40
170 23 39 19 64
170 23 37 15 32
170 23 36 35 0
170 23 35 35 0
170 23 34 35 0
170 23 33 35 0
170 23 32 35 0
170 23 31 35 0
170 23 30 35 64
170 23 27 35 32
170 23 26 35 0
170 23 25 35 0
170 23 24 35 0
170 23 23 35 0
170 23 22 35 0
170 23 21 35 64
170 23 18 21 40
170 23 17 21 0
170 23 16 21 0
170 23 15 21 2
170 23 14 21 74
170 23 12 15 96
170 23 10 19 32
170 23 9 9 72
170 24 39 19 96
170 24 37 15 32
170 24 36 35 12
170 24 35 35 0
170 24 34 35 0
170 24 33 35 0
170 24 32 35 0
170 24 31 35 0
170 24 30 35 76
170 24 27 35 32
170 24 26 35 0
170 24 25 35 0
170 24 24 35 0
170 24 23 35 0
170 24 22 35 0
170 24 21 35 72
170 24 17 21 40
170 24 16 21 10
170 24 15 21 74
170 24 12 15 96
170 24 10 19 96
170 25 39 19 96
170 25 37 15 96
170 25 35 35 44
170 25 34 35 8
170 25 33 35 8
170 25 32 35 8
170 25 31 35 76
170 25 29 18 52
170 25 28 18 20
170 25 27 18 4
170 25 26 35 0
170 25 25 35 8
170 25 24 35 0
170 25 23 35 8
170 25 22 35 72
170 25 12 15 96
170 25 10 19 96
170 26 39 19 40
170 26 38 8 24
170 26 37 8 72
170 26 30 18 52
170 26 29 18 0
170 26 28 18 0
170 26 27 18 0
170 26 26 18 68
170 26 24 24 110
170 26 12 8 40
170 26 11 8 24
170 26 10 19 72
170 27 31 21 52
170 27 30 21 0
170 27 29 21 0
170 27 28 21 0
170 27 27 21 0
170 27 26 21 0
170 27 25 21 84
170 28 31 21 44
170 28 30 21 0
170 28 29 21 0
170 28 28 21 0
170 28 27 21 0
170 28 26 21 0
170 28 25 21 76
170 29 30 21 44
170 29 29 21 0
170 29 28 21 0
170 29 27 21 0
170 29 26 21 76
170 30 29 21 44
170 30 28 21 12
170 30 27 21 76
171 1 39 19 48
171 1 38 8 24
171 1 37 8 88
171 1 12 8 56
171 1 11 8 24
171 1 10 19 80
171 2 39 19 96
171 2 36 15 56
171 2 35 15 24
171 2 34 15 24
171 2 33 15 24
171 2 32 15 24
171 2 31 15 24
171 2 30 15 24
171 2 29 15 24
171 2 28 15 24
171 2 27 15 24
171 2 26 15 24
171 2 25 15 24
171 2 24 15 24
171 2 23 15 24
171 2 22 15 24
171 2 21 15 24
171 2 20 15 24
171 2 19 15 24
171 2 18 15 24
171 2 17 15 24
171 2 16 15 24
171 2 15 15 24
171 2 14 15 24
171 2 13 15 88
171 2 10 19 96
171 3 39 19 96
171 3 10 19 96
171 4 40 9 48
171 4 39 19 66
171 4 10 19 34
171 4 9 9 80
171 5 40 11 32
171 5 39 19 66
171 5 10 19 34
171 5 9 11 64
171 6 40 11 32
171 6 39 19 66
171 6 10 19 34
171 6 9 11 64
171 7 40 9 40
171 7 39 19 66
171 7 10 19 34
171 7 9 9 72
171 8 39 19 96
171 8 10 19 96
171 9 39 19 96
171 9 10 19 96
171 10 39 19 96
171 10 10 19 96
171 11 39 19 96
171 11 10 19 96
171 12 39 19 96
171 12 10 19 96
171 13 39 19 96
171 13 10 19 96
171 14 39 19 96
171 14 10 19 96
171 15 39 19 96
171 15 10 19 96
171 16 39 19 96
171 16 10 19 96
171 17 39 19 96
171 17 10 19 96
171 18 39 19 96
171 18 10 19 96
171 19 39 19 96
171 19 36 10 56
171 19 35 10 16
171 19 34 10 16
171 19 33 10 16
171 19 32 10 16
171 19 31 10 16
171 19 30 10 24
171 19 29 10 24
171 19 28 10 24
171 19 27 10 24
171 19 26 10 16
171 19 25 10 16
171 19 24 10 16
171 19 23 10 16
171 19 22 10 16
171 19 21 10 24
171 19 20 10 24
171 19 19 10 24
171 19 18 10 24
171 19 17 10 24
171 19 16 10 24
171 19 15 10 24
171 19 14 10 24
171 19 13 10 88
171 19 10 19 96
171 20 40 9 48
171 20 39 19 66
171 20 37 15 112
171 20 35 32 32
171 20 34 32 0
171 20 33 32 0
171 20 32 32 0
171 20 31 32 64
171 20 26 32 34
171 20 25 32 0
171 20 24 32 0
171 20 23 32 0
171 20 22 32 66
171 20 12 15 112
171 20 10 19 34
171 20 9 9 80
171 21 40 11 32
171 21 39 19 66
171 21 37 11 32
171 21 36 32 16
171 21 35 32 0
171 21 34 32 0
171 21 33 32 0
171 21 32 32 0
171 21 31 32 0
171 21 30 32 80
171 21 27 32 50
171 21 26 32 0
171 21 25 32 0
171 21 24 32 0
171 21 23 32 0
171 21 22 32 0
171 21 21 32 82
171 21 19 32 52
171 21 18 32 20
171 21 17 32 80
171 21 12 11 96
171 21 10 19 34
171 21 9 11 64
171 22 40 11 32
171 22 39 19 66
171 22 37 11 32
171 22 36 35 0
171 22 35 35 0
171 22 34 35 0
171 22 33 35 0
171 22 32 35 0
171 22 31 35 0
171 22 30 35 64
171 22 27 35 32
171 22 26 35 0
171 22 25 35 0
171 22 24 35 0
171 22 23 35 0
171 22 22 35 0
171 22 21 35 0
171 22 20 35 20
171 22 19 35 4
171 22 18 35 0
171 22 17 35 0
171 22 16 35 80
171 22 12 11 96
171 22 10 19 34
171 22 9 11 64
171 23 40 9 40
171 23 39 19 66
171 23 37 15 32
171 23 36 35 0
171 23 35 35 0
171 23 34 35 0
171 23 33 35 0
171 23 32 35 0
171 23 31 35 0
171 23 30 35 64
171 23 27 35 32
171 23 26 35 0
171 23 25 35 0
171 23 24 35 0
171 23 23 35 0
171 23 22 35 0
171 23 21 35 0
171 23 20 35 12
171 23 19 35 4
171 23 18 35 0
171 23 17 35 0
171 23 16 35 72
171 23 12 15 96
171 23 10 19 34
171 23 9 9 72
171 24 39 19 96
171 24 37 15 32
171 24 36 35 8
171 24 35 35 0
171 24 34 35 0
171 24 33 35 0
171 24 32 35 0
171 24 31 35 0
171 24 30 35 64
171 24 27 35 34
171 24 26 35 0
171 24 25 35 0
171 24 24 35 0
171 24 23 35 0
171 24 22 35 0
171 24 21 35 74
171 24 19 35 44
171 24 18 35 12
171 24 17 35 72
171 24 12 15 96
171 24 10 19 96
171 25 39 19 96
171 25 37 15 96
171 25 35 35 40
171 25 34 35 8
171 25 33 35 0
171 25 32 35 8
171 25 31 35 0
171 25 30 18 4
171 25 29 18 16
171 25 28 18 16
171 25 27 18 0
171 25 26 18 0
171 25 25 35 0
171 25 24 35 8
171 25 23 35 8
171 25 22 35 74
171 25 12 15 96
171 25 10 19 96
171 26 39 19 40
171 26 38 8 24
171 26 37 8 72
171 26 33 24 110
171 26 31 18 36
171 26 30 18 0
171 26 29 18 0
171 26 28 18 0
171 26 27 18 0
171 26 26 18 0
171 26 25 18 68
171 26 12 8 40
171 26 11 8 24
171 26 10 19 72
171 27 31 21 32
171 27 30 21 0
171 27 29 21 0
171 27 28 21 0
171 27 27 21 0
171 27 26 21 0
171 27 25 21 64
171 28 31 21 32
171 28 30 21 0
171 28 29 21 0
171 28 28 21 0
171 28 27 21 0
171 28 26 21 0
171 28 25 21 64
171 29 31 21 44
171 29 30 21 0
171 29 29 21 0
171 29 28 21 0
171 29 27 21 0
171 29 26 21 0
171 29 25 21 76
171 30 30 21 44
171 30 29 21 8
171 30 28 21 8
171 30 27 21 8
171 30 26 21 76
172 1 39 15 50
172 1 38 8 24
172 1 37 8 88
172 1 12 8 56
172 1 11 8 24
172 1 10 15 82
172 2 39 15 98
172 2 36 13 56
172 2 35 13 24
172 2 34 13 24
172 2 33 13 24
172 2 32 13 24
172 2 31 13 24
172 2 30 13 24
172 2 29 13 24
172 2 28 13 24
172 2 27 13 24
172 2 26 13 24
172 2 25 13 24
172 2 24 13 24
172 2 23 13 24
172 2 22 13 24
172 2 21 13 24
172 2 20 13 24
172 2 19 13 24
172 2 18 13 24
172 2 17 13 24
172 2 16 13 24
172 2 15 13 24
172 2 14 13 24
172 2 13 13 88
172 2 10 15 98
172 3 39 15 106
172 3 10 15 106
172 4 40 9 114
172 4 9 9 114
172 5 40 11 98
172 5 9 11 98
172 6 40 11 98
172 6 9 11 98
172 7 40 9 106
172 7 9 9 106
172 8 39 15 114
172 8 10 15 114
172 9 39 15 98
172 9 10 15 98
172 10 39 15 98
172 10 10 15 98
172 11 39 15 98
172 11 10 15 98
172 12 39 15 98
172 12 10 15 98
172 13 39 15 98
172 13 10 15 98
172 14 39 15 98
172 14 10 15 98
172 15 39 15 98
172 15 10 15 98
172 16 39 15 98
172 16 10 15 98
172 17 39 15 98
172 17 10 15 98
172 18 39 15 98
172 18 10 15 98
172 19 39 15 106
172 19 36 10 56
172 19 35 10 16
172 19 34 10 16
172 19 33 10 16
172 19 32 10 16
172 19 31 10 16
172 19 30 10 24
172 19 29 10 24
172 19 28 10 24
172 19 27 10 24
172 19 26 10 24
172 19 25 10 16
172 19 24 10 16
172 19 23 10 16
172 19 22 10 24
172 19 21 10 24
172 19 20 10 24
172 19 19 10 16
172 19 18 10 16
172 19 17 10 16
172 19 16 10 24
172 19 15 10 24
172 19 14 10 24
172 19 13 10 88
172 19 10 15 106
172 20 40 9 114
172 20 37 15 112
172 20 35 32 34
172 20 34 32 0
172 20 33 32 0
172 20 32 32 0
172 20 31 32 66
172 20 25 32 34
172 20 24 32 2
172 20 23 32 66
172 20 19 32 36
172 20 18 32 4
172 20 17 32 68
172 20 12 15 112
172 20 9 9 114
172 21 40 11 98
172 21 37 11 32
172 21 36 32 18
172 21 35 32 0
172 21 34 32 0
172 21 33 32 0
172 21 32 32 0
172 21 31 32 0
172 21 30 32 82
172 21 26 32 50
172 21 25 32 0
172 21 24 32 0
172 21 23 32 0
172 21 22 32 82
172 21 20 32 52
172 21 19 32 0
172 21 18 32 0
172 21 17 32 0
172 21 16 32 84
172 21 12 11 96
172 21 9 11 98
172 22 40 11 98
172 22 37 11 32
172 22 36 35 0
172 22 35 35 0
172 22 34 35 0
172 22 33 35 0
172 22 32 35 0
172 22 31 35 0
172 22 30 35 64
172 22 27 35 50
172 22 26 35 0
172 22 25 35 0
172 22 24 35 0
172 22 23 35 0
172 22 22 35 0
172 22 21 35 16
172 22 20 35 0
172 22 19 35 0
172 22 18 35 0
172 22 17 35 0
172 22 16 35 0
172 22 15 35 84
172 22 12 11 96
172 22 9 11 98
172 23 40 9 106
172 23 37 15 32
172 23 36 35 0
172 23 35 35 0
172 23 34 35 0
172 23 33 35 0
172 23 32 35 0
172 23 31 35 0
172 23 30 35 64
172 23 27 35 42
172 23 26 35 0
172 23 25 35 0
172 23 24 35 0
172 23 23 35 0
172 23 22 35 0
172 23 21 35 8
172 23 20 35 0
172 23 19 35 0
172 23 18 35 0
172 23 17 35 0
172 23 16 35 0
172 23 15 35 76
172 23 12 15 96
172 23 9 9 106
172 24 39 15 114
172 24 37 15 32
172 24 36 35 10
172 24 35 35 0
172 24 34 35 0
172 24 33 35 0
172 24 32 35 0
172 24 31 35 0
172 24 30 35 66
172 24 26 35 34
172 24 25 35 0
172 24 24 35 0
172 24 23 35 0
172 24 22 35 74
172 24 20 35 44
172 24 19 35 0
172 24 18 35 0
172 24 17 35 0
172 24 16 35 76
172 24 12 15 96
172 24 10 15 114
172 25 39 15 98
172 25 37 15 96
172 25 35 35 42
172 25 34 35 8
172 25 33 35 8
172 25 32 35 8
172 25 31 35 2
172 25 30 18 0
172 25 29 18 16
172 25 28 18 16
172 25 27 18 16
172 25 26 18 0
172 25 25 35 2
172 25 24 35 10
172 25 23 35 74
172 25 19 35 44
172 25 18 35 12
172 25 17 35 76
172 25 12 15 96
172 25 10 15 98
172 26 39 15 42
172 26 38 8 24
172 26 37 8 72
172 26 31 18 32
172 26 30 18 0
172 26 29 18 0
172 26 28 18 0
172 26 27 18 0
172 26 26 18 0
172 26 25 18 64
172 26 12 8 40
172 26 11 8 24
172 26 10 15 74
172 27 31 21 32
172 27 30 21 0
172 27 29 21 0
172 27 28 21 0
172 27 27 21 0
172 27 26 21 0
172 27 25 21 64
172 28 31 21 32
172 28 30 21 0
172 28 29 21 0
172 28 28 21 0
172 28 27 21 0
172 28 26 21 0
172 28 25 21 64
172 29 31 21 40
172 29 30 21 0
172 29 29 21 0
172 29 28 21 0
172 29 27 21 0
172 29 26 21 0
172 29 25 21 72
172 30 30 21 40
172 30 29 21 8
172 30 28 21 0
172 30 27 21 8
172 30 26 21 72
172 31 28 24 110
173 1 38 15 48
173 1 37 8 88
173 1 12 8 56
173 1 11 15 80
173 2 38 15 100
173 2 36 13 58
173 2 35 13 24
173 2 34 13 24
173 2 33 13 24
173 2 32 13 24
173 2 31 13 24
173 2 30 13 24
173 2 29 13 24
173 2 28 13 24
173 2 27 13 24
173 2 26 13 24
173 2 25 13 24
173 2 24 13 24
173 2 23 13 24
173 2 22 13 24
173 2 21 13 24
173 2 20 13 24
173 2 19 13 24
173 2 18 13 24
173 2 17 13 24
173 2 16 13 24
173 2 15 13 24
173 2 14 13 24
173 2 13 13 88
173 2 11 15 100
173 3 38 15 108
173 3 11 15 108
173 4 39 9 116
173 4 10 9 116
173 5 39 11 100
173 5 10 11 100
173 6 39 11 100
173 6 10 11 100
173 7 39 9 108
173 7 10 9 108
173 8 38 15 116
173 8 11 15 116
173 9 38 15 100
173 9 11 15 100
173 10 38 15 100
173 10 11 15 100
173 11 38 15 100
173 11 11 15 100
173 12 38 15 100
173 12 11 15 100
173 13 38 15 100
173 13 11 15 100
173 14 38 15 100
173 14 11 15 100
173 15 38 15 100
173 15 11 15 100
173 16 38 15 100
173 16 11 15 100
173 17 38 15 100
173 17 11 15 100
173 18 38 15 100
173 18 11 15 100
173 19 38 15 108
173 19 36 10 58
173 19 35 10 24
173 19 34 10 16
173 19 33 10 16
173 19 32 10 16
173 19 31 10 24
173 19 30 10 24
173 19 29 10 24
173 19 28 10 24
173 19 27 10 24
173 19 26 10 24
173 19 25 10 24
173 19 24 10 24
173 19 23 10 24
173 19 22 10 24
173 19 21 10 24
173 19 20 10 16
173 19 19 10 16
173 19 18 10 16
173 19 17 10 16
173 19 16 10 16
173 19 15 10 24
173 19 14 10 24
173 19 13 10 88
173 19 11 15 108
173 20 39 9 116
173 20 37 15 114
173 20 34 32 34
173 20 33 32 2
173 20 32 32 66
173 20 20 32 36
173 20 19 32 0
173 20 18 32 0
173 20 17 32 0
173 20 16 32 68
173 20 12 15 112
173 20 10 9 116
173 21 39 11 100
173 21 37 11 98
173 21 35 32 50
173 21 34 32 0
173 21 33 32 0
173 21 32 32 0
173 21 31 32 82
173 21 25 32 50
173 21 24 32 18
173 21 23 32 82
173 21 21 32 52
173 21 20 32 0
173 21 19 32 0
173 21 18 32 0
173 21 17 32 0
173 21 16 32 0
173 21 15 32 84
173 21 12 11 96
173 21 10 11 100
173 22 39 11 100
173 22 37 11 34
173 22 36 35 16
173 22 35 35 0
173 22 34 35 0
173 22 33 35 0
173 22 32 35 0
173 22 31 35 0
173 22 30 35 82
173 22 26 35 48
173 22 25 35 0
173 22 24 35 2
173 22 23 35 2
173 22 22 35 18
173 22 21 35 0
173 22 20 35 0
173 22 19 35 0
173 22 18 35 0
173 22 17 35 0
173 22 16 35 0
173 22 15 35 64
173 22 12 11 96
173 22 10 11 100
173 23 39 9 108
173 23 37 15 34
173 23 36 35 8
173 23 35 35 0
173 23 34 35 0
173 23 33 35 0
173 23 32 35 0
173 23 31 35 0
173 23 30 35 74
173 23 26 35 40
173 23 25 35 0
173 23 24 35 2
173 23 23 35 2
173 23 22 35 10
173 23 21 35 0
173 23 20 35 0
173 23 19 35 0
173 23 18 35 0
173 23 17 35 0
173 23 16 35 0
173 23 15 35 64
173 23 12 15 96
173 23 10 9 108
173 24 38 15 52
173 24 37 15 66
173 24 35 35 42
173 24 34 35 0
173 24 33 35 0
173 24 32 35 0
173 24 31 35 74
173 24 25 35 42
173 24 24 35 10
173 24 23 35 74
173 24 21 35 44
173 24 20 35 0
173 24 19 35 0
173 24 18 35 0
173 24 17 35 0
173 24 16 35 0
173 24 15 35 76
173 24 12 15 32
173 24 11 15 84
173 25 38 15 36
173 25 37 15 66
173 25 34 35 42
173 25 33 35 10
173 25 32 35 74
173 25 30 18 50
173 25 29 18 16
173 25 28 18 16
173 25 27 18 16
173 25 26 18 82
173 25 20 35 44
173 25 19 35 8
173 25 18 35 8
173 25 17 35 8
173 25 16 35 76
173 25 12 15 32
173 25 11 15 68
173 26 38 15 40
173 26 37 8 72
173 26 31 18 50
173 26 30 18 0
173 26 29 18 0
173 26 28 18 0
173 26 27 18 0
173 26 26 18 0
173 26 25 18 82
173 26 12 8 40
173 26 11 15 72
173 27 31 21 32
173 27 30 21 0
173 27 29 21 0
173 27 28 21 0
173 27 27 21 0
173 27 26 21 0
173 27 25 21 64
173 28 31 21 32
173 28 30 21 0
173 28 29 21 0
173 28 28 21 0
173 28 27 21 0
173 28 26 21 0
173 28 25 21 64
173 29 31 21 42
173 29 30 21 0
173 29 29 21 0
173 29 28 21 0
173 29 27 21 0
173 29 26 21 0
173 29 25 21 74
173 30 30 21 42
173 30 29 21 8
173 30 28 21 8
173 30 27 21 8
173 30 26 21 74
174 1 38 15 48
174 1 37 8 24
174 1 36 8 92
174 1 12 8 56
174 1 11 15 80
174 2 38 15 96
174 2 35 15 56
174 2 34 15 24
174 2 33 15 24
174 2 32 15 24
174 2 31 15 24
174 2 30 15 24
174 2 29 15 24
174 2 28 15 24
174 2 27 15 24
174 2 26 15 24
174 2 25 15 24
174 2 24 15 24
174 2 23 15 24
174 2 22 15 24
174 2 21 15 24
174 2 20 15 24
174 2 19 15 24
174 2 18 15 24
174 2 17 15 24
174 2 16 15 24
174 2 15 15 24
174 2 14 15 24
174 2 13 15 90
174 2 11 15 96
174 3 38 15 104
174 3 11 15 104
174 4 39 9 112
174 4 10 9 112
174 5 39 11 96
174 5 10 11 96
174 6 39 11 96
174 6 10 11 96
174 7 39 9 104
174 7 10 9 104
174 8 38 15 112
174 8 11 15 112
174 9 38 15 96
174 9 11 15 96
174 10 38 15 96
174 10 11 15 96
174 11 38 15 96
174 11 11 15 96
174 12 38 15 96
174 12 11 15 96
174 13 38 15 96
174 13 11 15 96
174 14 38 15 96
174 14 11 15 96
174 15 38 15 96
174 15 11 15 96
174 16 38 15 96
174 16 11 15 96
174 17 38 15 96
174 17 11 15 96
174 18 38 15 96
174 18 11 15 96
174 19 38 15 104
174 19 35 10 56
174 19 34 10 24
174 19 33 10 24
174 19 32 10 24
174 19 31 10 24
174 19 30 10 24
174 19 29 10 24
174 19 28 10 24
174 19 27 10 24
174 19 26 10 24
174 19 25 10 24
174 19 24 10 24
174 19 23 10 24
174 19 22 10 24
174 19 21 10 24
174 19 20 10 16
174 19 19 10 16
174 19 18 10 16
174 19 17 10 16
174 19 16 10 16
174 19 15 10 24
174 19 14 10 24
174 19 13 10 88
174 19 11 15 104
174 20 39 9 112
174 20 36 15 116
174 20 20 32 32
174 20 19 32 0
174 20 18 32 0
174 20 17 32 0
174 20 16 32 64
174 20 12 15 112
174 20 10 9 112
174 21 39 11 96
174 21 36 11 100
174 21 34 32 50
174 21 33 32 18
174 21 32 32 82
174 21 28 32 52
174 21 27 32 20
174 21 26 32 84
174 21 21 32 48
174 21 20 32 0
174 21 19 32 0
174 21 18 32 0
174 21 17 32 0
174 21 16 32 0
174 21 15 32 80
174 21 12 11 96
174 21 10 11 96
174 22 39 11 96
174 22 36 11 32
174 22 35 35 18
174 22 34 35 2
174 22 33 35 2
174 22 32 35 2
174 22 31 35 82
174 22 29 35 52
174 22 28 35 4
174 22 27 35 4
174 22 26 35 0
174 22 25 35 80
174 22 21 35 32
174 22 20 35 0
174 22 19 35 0
174 22 18 35 0
174 22 17 35 0
174 22 16 35 0
174 22 15 35 64
174 22 12 11 96
174 22 10 11 96
174 23 39 9 104
174 23 36 15 32
174 23 35 35 10
174 23 34 35 2
174 23 33 35 2
174 23 32 35 2
174 23 31 35 74
174 23 29 35 44
174 23 28 35 4
174 23 27 35 4
174 23 26 35 0
174 23 25 35 72
174 23 21 35 32
174 23 20 35 0
174 23 19 35 0
174 23 18 35 0
174 23 17 35 0
174 23 16 35 0
174 23 15 35 64
174 23 12 15 96
174 23 10 9 104
174 24 38 15 112
174 24 36 15 100
174 24 34 35 42
174 24 33 35 10
174 24 32 35 74
174 24 28 35 36
174 24 27 35 4
174 24 26 35 76
174 24 21 35 40
174 24 20 35 0
174 24 19 35 0
174 24 18 35 0
174 24 17 35 0
174 24 16 35 0
174 24 15 35 72
174 24 12 15 32
174 24 11 15 80
174 25 38 15 96
174 25 36 15 100
174 25 29 18 50
174 25 28 18 0
174 25 27 18 64
174 25 20 35 32
174 25 19 35 8
174 25 18 35 0
174 25 17 35 8
174 25 16 35 72
174 25 12 15 34
174 25 11 15 64
174 26 38 15 40
174 26 37 8 24
174 26 36 8 76
174 26 30 18 50
174 26 29 18 0
174 26 28 18 0
174 26 27 18 0
174 26 26 18 82
174 26 22 32 52
174 26 21 32 20
174 26 20 32 68
174 26 18 24 110
174 26 12 8 40
174 26 11 15 72
174 27 31 21 50
174 27 30 21 0
174 27 29 21 0
174 27 28 21 0
174 27 27 21 0
174 27 26 21 0
174 27 25 21 82
174 27 23 35 52
174 27 22 35 4
174 27 21 35 4
174 27 20 35 4
174 27 19 35 84
174 28 31 21 42
174 28 30 21 0
174 28 29 21 0
174 28 28 21 0
174 28 27 21 0
174 28 26 21 0
174 28 25 21 74
174 28 23 35 44
174 28 22 35 4
174 28 21 35 4
174 28 20 35 4
174 28 19 35 76
174 29 30 21 42
174 29 29 21 0
174 29 28 21 0
174 29 27 21 0
174 29 26 21 74
174 29 22 35 44
174 29 21 35 12
174 29 20 35 76
174 30 29 21 42
174 30 28 21 10
174 30 27 21 74
175 1 38 15 50
175 1 37 8 24
175 1 36 8 88
175 1 13 8 60
175 1 12 8 24
175 1 11 15 82
175 2 38 15 98
175 2 35 15 58
175 2 34 15 24
175 2 33 15 24
175 2 32 15 24
175 2 31 15 24
175 2 30 15 24
175 2 29 15 24
175 2 28 15 24
175 2 27 15 24
175 2 26 15 24
175 2 25 15 24
175 2 24 15 24
175 2 23 15 24
175 2 22 15 24
175 2 21 15 24
175 2 20 15 24
175 2 19 15 24
175 2 18 15 24
175 2 17 15 24
175 2 16 15 24
175 2 15 15 24
175 2 14 15 90
175 2 11 15 98
175 3 38 15 106
175 3 11 15 106
175 4 39 9 114
175 4 10 9 114
175 5 39 11 98
175 5 10 11 98
175 6 39 11 98
175 6 10 11 98
175 7 39 9 106
175 7 10 9 106
175 8 38 15 114
175 8 11 15 114
175 9 38 15 98
175 9 11 15 98
175 10 38 15 98
175 10 11 15 98
175 11 38 15 98
175 11 11 15 98
175 12 38 15 98
175 12 11 15 98
175 13 38 15 98
175 13 11 15 98
175 14 38 15 98
175 14 11 15 98
175 15 38 15 98
175 15 11 15 98
175 16 38 15 98
175 16 11 15 98
175 17 38 15 98
175 17 11 15 98
175 18 38 15 98
175 18 11 15 98
175 19 38 15 106
175 19 35 10 56
175 19 34 10 24
175 19 33 10 24
175 19 32 10 24
175 19 31 10 24
175 19 30 10 24
175 19 29 10 24
175 19 28 10 16
175 19 27 10 16
175 19 26 10 16
175 19 25 10 24
175 19 24 10 24
175 19 23 10 24
175 19 22 10 24
175 19 21 10 24
175 19 20 10 16
175 19 19 10 16
175 19 18 10 16
175 19 17 10 16
175 19 16 10 16
175 19 15 10 24
175 19 14 10 24
175 19 13 10 88
175 19 11 15 106
175 20 39 9 114
175 20 36 15 112
175 20 28 32 36
175 20 27 32 4
175 20 26 32 68
175 20 20 32 34
175 20 19 32 0
175 20 18 32 0
175 20 17 32 0
175 20 16 32 66
175 20 12 15 112
175 20 10 9 114
175 21 39 11 98
175 21 36 11 96
175 21 29 32 52
175 21 28 32 0
175 21 27 32 0
175 21 26 32 0
175 21 25 32 84
175 21 21 32 50
175 21 20 32 0
175 21 19 32 0
175 21 18 32 0
175 21 17 32 0
175 21 16 32 0
175 21 15 32 82
175 21 12 11 96
175 21 10 11 98
175 22 39 11 98
175 22 36 11 96
175 22 30 35 52
175 22 29 35 0
175 22 28 35 0
175 22 27 35 0
175 22 26 35 0
175 22 25 35 0
175 22 24 35 84
175 22 21 35 32
175 22 20 35 0
175 22 19 35 0
175 22 18 35 0
175 22 17 35 0
175 22 16 35 0
175 22 15 35 64
175 22 12 11 96
175 22 10 11 98
175 23 39 9 106
175 23 36 15 96
175 23 30 35 44
175 23 29 35 0
175 23 28 35 0
175 23 27 35 0
175 23 26 35 0
175 23 25 35 0
175 23 24 35 76
175 23 21 35 32
175 23 20 35 0
175 23 19 35 0
175 23 18 35 0
175 23 17 35 0
175 23 16 35 0
175 23 15 35 64
175 23 12 15 96
175 23 10 9 106
175 24 38 15 114
175 24 36 15 96
175 24 29 35 44
175 24 28 35 0
175 24 27 35 0
175 24 26 35 0
175 24 25 35 76
175 24 21 35 34
175 24 20 35 0
175 24 19 35 0
175 24 18 35 0
175 24 17 35 0
175 24 16 35 0
175 24 15 35 74
175 24 12 15 40
175 24 11 15 82
175 25 38 15 98
175 25 36 15 98
175 25 28 35 32
175 25 27 35 0
175 25 26 35 76
175 25 22 32 52
175 25 21 32 4
175 25 20 32 0
175 25 19 35 0
175 25 18 35 8
175 25 17 35 8
175 25 16 35 74
175 25 13 15 118
175 25 11 15 98
175 26 38 15 42
175 26 37 8 24
175 26 36 8 72
175 26 29 18 50
175 26 28 18 2
175 26 27 18 66
175 26 23 32 52
175 26 22 32 0
175 26 21 32 0
175 26 20 32 0
175 26 19 32 68
175 26 13 8 44
175 26 12 8 24
175 26 11 15 74
175 27 30 21 50
175 27 29 21 2
175 27 28 21 2
175 27 27 21 2
175 27 26 21 82
175 27 24 35 52
175 27 23 35 0
175 27 22 35 0
175 27 21 35 0
175 27 20 35 0
175 27 19 35 0
175 27 18 35 84
175 28 30 21 42
175 28 29 21 2
175 28 28 21 2
175 28 27 21 2
175 28 26 21 74
175 28 24 35 44
175 28 23 35 0
175 28 22 35 0
175 28 21 35 0
175 28 20 35 0
175 28 19 35 0
175 28 18 35 76
175 29 29 21 42
175 29 28 21 10
175 29 27 21 74
175 29 23 35 44
175 29 22 35 0
175 29 21 35 0
175 29 20 35 0
175 29 19 35 76
175 30 22 35 44
175 30 21 35 12
175 30 20 35 76
176 1 37 19 48
176 1 36 8 24
176 1 35 8 92
176 1 14 8 60
176 1 13 8 24
176 1 12 19 80
176 2 37 19 100
176 2 34 15 58
176 2 33 15 24
176 2 32 15 24
176 2 31 15 24
176 2 30 15 24
176 2 29 15 24
176 2 28 15 24
176 2 27 15 24
176 2 26 15 24
176 2 25 15 24
176 2 24 15 24
176 2 23 15 24
176 2 22 15 24
176 2 21 15 24
176 2 20 15 24
176 2 19 15 24
176 2 18 15 24
176 2 17 15 24
176 2 16 15 24
176 2 15 15 90
176 2 12 19 100
176 3 37 19 100
176 3 12 19 100
176 4 38 9 52
176 4 37 19 68
176 4 12 19 36
176 4 11 9 84
176 5 38 11 36
176 5 37 19 68
176 5 12 19 36
176 5 11 11 68
176 6 38 11 36
176 6 37 19 68
176 6 12 19 36
176 6 11 11 68
176 7 38 9 44
176 7 37 19 68
176 7 12 19 36
176 7 11 9 76
176 8 37 19 100
176 8 12 19 100
176 9 37 19 100
176 9 12 19 100
176 10 37 19 100
176 10 12 19 100
176 11 37 19 100
176 11 12 19 100
176 12 37 19 100
176 12 12 19 100
176 13 37 19 100
176 13 12 19 100
176 14 37 19 100
176 14 12 19 100
176 15 37 19 100
176 15 12 19 100
176 16 37 19 100
176 16 12 19 100
176 17 37 19 100
176 17 12 19 100
176 18 37 19 100
176 18 12 19 100
176 19 37 19 100
176 19 35 10 58
176 19 34 10 26
176 19 33 10 24
176 19 32 10 24
176 19 31 10 24
176 19 30 10 24
176 19 29 10 16
176 19 28 10 16
176 19 27 10 16
176 19 26 10 16
176 19 25 10 16
176 19 24 10 24
176 19 23 10 24
176 19 22 10 24
176 19 21 10 24
176 19 20 10 24
176 19 19 10 16
176 19 18 10 16
176 19 17 10 16
176 19 16 10 24
176 19 15 10 24
176 19 14 10 18
176 19 13 10 16
176 19 12 19 68
176 20 38 9 52
176 20 37 19 4
176 20 36 15 82
176 20 29 32 36
176 20 28 32 0
176 20 27 32 0
176 20 26 32 0
176 20 25 32 68
176 20 19 32 34
176 20 18 32 2
176 20 17 32 66
176 20 14 15 36
176 20 13 15 4
176 20 12 19 0
176 20 11 9 84
176 21 38 11 36
176 21 37 19 4
176 21 36 11 66
176 21 30 32 52
176 21 29 32 0
176 21 28 32 0
176 21 27 32 0
176 21 26 32 0
176 21 25 32 0
176 21 24 32 84
176 21 20 32 50
176 21 19 32 0
176 21 18 32 0
176 21 17 32 0
176 21 16 32 82
176 21 14 11 36
176 21 13 11 4
176 21 12 19 0
176 21 11 11 68
176 22 38 11 36
176 22 37 19 4
176 22 36 11 66
176 22 30 35 32
176 22 29 35 0
176 22 28 35 0
176 22 27 35 0
176 22 26 35 0
176 22 25 35 0
176 22 24 35 64
176 22 21 35 50
176 22 20 35 0
176 22 19 35 0
176 22 18 35 0
176 22 17 35 0
176 22 16 35 0
176 22 15 35 18
176 22 14 11 4
176 22 13 11 4
176 22 12 19 0
176 22 11 11 68
176 23 38 9 44
176 23 37 19 4
176 23 36 15 66
176 23 30 35 32
176 23 29 35 0
176 23 28 35 0
176 23 27 35 0
176 23 26 35 0
176 23 25 35 0
176 23 24 35 64
176 23 21 35 42
176 23 20 35 0
176 23 19 35 0
176 23 18 35 0
176 23 17 35 0
176 23 16 35 0
176 23 15 35 10
176 23 14 15 4
176 23 13 15 4
176 23 12 19 0
176 23 11 9 76
176 24 37 19 36
176 24 36 15 74
176 24 30 35 44
176 24 29 35 0
176 24 28 35 0
176 24 27 35 0
176 24 26 35 0
176 24 25 35 0
176 24 24 35 76
176 24 20 35 34
176 24 19 35 0
176 24 18 35 0
176 24 17 35 0
176 24 16 35 74
176 24 14 15 36
176 24 13 15 12
176 24 12 19 64
176 25 37 19 100
176 25 35 15 118
176 25 29 35 44
176 25 28 35 8
176 25 27 35 8
176 25 26 35 8
176 25 25 35 76
176 25 23 32 52
176 25 22 32 16
176 25 21 32 16
176 25 20 32 0
176 25 19 32 0
176 25 18 35 2
176 25 17 35 74
176 25 14 15 102
176 25 12 19 100
176 26 37 19 40
176 26 36 8 24
176 26 35 8 76
176 26 24 32 52
176 26 23 32 0
176 26 22 32 0
176 26 21 32 0
176 26 20 32 0
176 26 19 32 0
176 26 18 32 68
176 26 14 8 44
176 26 13 8 24
176 26 12 19 72
176 27 24 35 32
176 27 23 35 0
176 27 22 35 0
176 27 21 35 0
176 27 20 35 0
176 27 19 35 0
176 27 18 35 64
176 28 24 35 32
176 28 23 35 0
176 28 22 35 0
176 28 21 35 0
176 28 20 35 0
176 28 19 35 0
176 28 18 35 64
176 29 24 35 44
176 29 23 35 0
176 29 22 35 0
176 29 21 35 0
176 29 20 35 0
176 29 19 35 0
176 29 18 35 76
176 30 23 35 44
176 30 22 35 8
176 30 21 35 8
176 30 20 35 8
176 30 19 35 76
177 1 37 19 50
177 1 36 19 24
177 1 35 8 24
177 1 34 8 92
177 1 15 8 60
177 1 14 8 24
177 1 13 19 16
177 1 12 19 82
177 2 37 19 98
177 2 33 15 58
177 2 32 15 24
177 2 31 15 24
177 2 30 15 24
177 2 29 15 24
177 2 28 15 24
177 2 27 15 24
177 2 26 15 24
177 2 25 15 24
177 2 24 15 24
177 2 23 15 24
177 2 22 15 24
177 2 21 15 24
177 2 20 15 24
177 2 19 15 24
177 2 18 15 24
177 2 17 15 24
177 2 16 15 90
177 2 13 19 36
177 2 12 19 66
177 3 37 19 98
177 3 13 19 36
177 3 12 19 66
177 4 38 9 50
177 4 37 19 64
177 4 13 19 36
177 4 12 19 0
177 4 11 9 82
177 5 38 11 34
177 5 37 19 64
177 5 13 19 36
177 5 12 19 0
177 5 11 11 66
177 6 38 11 34
177 6 37 19 64
177 6 13 19 36
177 6 12 19 0
177 6 11 11 66
177 7 38 9 42
177 7 37 19 64
177 7 13 19 36
177 7 12 19 0
177 7 11 9 74
177 8 37 19 98
177 8 13 19 36
177 8 12 19 66
177 9 37 19 98
177 9 13 19 36
177 9 12 19 66
177 10 37 19 98
177 10 13 19 36
177 10 12 19 66
177 11 37 19 98
177 11 13 19 36
177 11 12 19 66
177 12 37 19 98
177 12 13 19 36
177 12 12 19 66
177 13 37 19 98
177 13 13 19 36
177 13 12 19 66
177 14 37 19 98
177 14 13 19 36
177 14 12 19 66
177 15 37 19 98
177 15 13 19 36
177 15 12 19 66
177 16 37 19 98
177 16 13 19 36
177 16 12 19 66
177 17 37 19 98
177 17 13 19 36
177 17 12 19 66
177 18 37 19 98
177 18 13 19 36
177 18 12 19 66
177 19 37 19 98
177 19 33 10 56
177 19 32 10 24
177 19 31 10 24
177 19 30 10 24
177 19 29 10 16
177 19 28 10 16
177 19 27 10 16
177 19 26 10 16
177 19 25 10 16
177 19 24 10 24
177 19 23 10 24
177 19 22 10 24
177 19 21 10 24
177 19 20 10 24
177 19 19 10 24
177 19 18 10 24
177 19 17 10 24
177 19 16 10 24
177 19 15 10 88
177 19 13 19 32
177 19 12 19 66
177 20 38 9 50
177 20 37 19 64
177 20 35 15 54
177 20 34 15 84
177 20 29 32 32
177 20 28 32 0
177 20 27 32 0
177 20 26 32 0
177 20 25 32 64
177 20 14 15 50
177 20 13 19 0
177 20 12 19 0
177 20 11 9 82
177 21 38 11 34
177 21 37 19 64
177 21 35 11 38
177 21 34 11 68
177 21 30 32 48
177 21 29 32 0
177 21 28 32 0
177 21 27 32 0
177 21 26 32 0
177 21 25 32 0
177 21 24 32 80
177 21 19 32 50
177 21 18 32 18
177 21 17 32 82
177 21 14 11 34
177 21 13 19 0
177 21 12 19 0
177 21 11 11 66
177 22 38 11 34
177 22 37 19 64
177 22 35 11 38
177 22 34 11 68
177 22 30 35 32
177 22 29 35 0
177 22 28 35 0
177 22 27 35 0
177 22 26 35 0
177 22 25 35 0
177 22 24 35 64
177 22 20 35 50
177 22 19 35 2
177 22 18 35 2
177 22 17 35 2
177 22 16 35 80
177 22 14 11 34
177 22 13 19 0
177 22 12 19 0
177 22 11 11 66
177 23 38 9 42
177 23 37 19 64
177 23 35 15 38
177 23 34 15 70
177 23 30 35 32
177 23 29 35 0
177 23 28 35 0
177 23 27 35 0
177 23 26 35 0
177 23 25 35 0
177 23 24 35 64
177 23 20 35 42
177 23 19 35 2
177 23 18 35 2
177 23 17 35 2
177 23 16 35 72
177 23 14 15 34
177 23 13 19 0
177 23 12 19 0
177 23 11 9 74
177 24 37 19 98
177 24 35 15 46
177 24 34 15 70
177 24 30 35 40
177 24 29 35 0
177 24 28 35 0
177 24 27 35 0
177 24 26 35 0
177 24 25 35 0
177 24 24 35 72
177 24 19 35 34
177 24 18 35 10
177 24 17 35 74
177 24 14 15 42
177 24 13 19 0
177 24 12 19 66
177 25 37 19 98
177 25 34 15 102
177 25 29 35 40
177 25 28 35 8
177 25 27 35 0
177 25 26 35 8
177 25 25 35 72
177 25 23 32 48
177 25 22 32 16
177 25 21 32 16
177 25 20 32 16
177 25 19 32 64
177 25 15 15 118
177 25 13 19 36
177 25 12 19 66
177 26 37 19 42
177 26 36 19 24
177 26 35 8 24
177 26 34 8 76
177 26 27 24 110
177 26 24 32 48
177 26 23 32 0
177 26 22 32 0
177 26 21 32 0
177 26 20 32 0
177 26 19 32 0
177 26 18 32 80
177 26 15 8 44
177 26 14 8 24
177 26 13 19 8
177 26 12 19 74
177 27 24 35 32
177 27 23 35 0
177 27 22 35 0
177 27 21 35 0
177 27 20 35 0
177 27 19 35 0
177 27 18 35 64
177 28 24 35 32
177 28 23 35 0
177 28 22 35 0
177 28 21 35 0
177 28 20 35 0
177 28 19 35 0
177 28 18 35 64
177 29 24 35 40
177 29 23 35 0
177 29 22 35 0
177 29 21 35 0
177 29 20 35 0
177 29 19 35 0
177 29 18 35 72
177 30 23 35 40
177 30 22 35 8
177 30 21 35 0
177 30 20 35 8
177 30 19 35 72
177 31 21 24 110
178 1 36 19 50
178 1 35 15 24
178 1 34 8 24
178 1 33 8 92
178 1 16 8 60
178 1 15 8 24
178 1 14 15 24
178 1 13 19 82
178 2 36 19 102
178 2 32 13 58
178 2 31 13 24
178 2 30 13 24
178 2 29 13 24
178 2 28 13 24
178 2 27 13 24
178 2 26 13 24
178 2 25 13 24
178 2 24 13 24
178 2 23 13 24
178 2 22 13 24
178 2 21 13 24
178 2 20 13 24
178 2 19 13 24
178 2 18 13 24
178 2 17 13 90
178 2 13 19 98
178 3 36 19 102
178 3 13 19 98
178 4 37 9 50
178 4 36 19 68
178 4 13 19 32
178 4 12 9 82
178 5 37 11 34
178 5 36 19 68
178 5 13 19 32
178 5 12 11 66
178 6 37 11 34
178 6 36 19 68
178 6 13 19 32
178 6 12 11 66
178 7 37 9 42
178 7 36 19 68
178 7 13 19 32
178 7 12 9 74
178 8 36 19 102
178 8 13 19 98
178 9 36 19 102
178 9 13 19 98
178 10 36 19 102
178 10 13 19 98
178 11 36 19 102
178 11 13 19 98
178 12 36 19 102
178 12 13 19 98
178 13 36 19 102
178 13 13 19 98
178 14 36 19 102
178 14 13 19 98
178 15 36 19 102
178 15 13 19 98
178 16 36 19 102
178 16 13 19 98
178 17 36 19 102
178 17 13 19 98
178 18 36 19 102
178 18 13 19 98
178 19 36 19 102
178 19 33 10 50
178 19 32 10 24
178 19 31 10 24
178 19 30 10 24
178 19 29 10 16
178 19 28 10 16
178 19 27 10 16
178 19 26 10 16
178 19 25 10 16
178 19 24 10 24
178 19 23 10 24
178 19 22 10 24
178 19 21 10 24
178 19 20 10 24
178 19 19 10 24
178 19 18 10 24
178 19 17 10 26
178 19 16 10 16
178 19 15 10 80
178 19 13 19 98
178 20 37 9 50
178 20 36 19 68
178 20 34 15 50
178 20 33 15 68
178 20 29 32 34
178 20 28 32 0
178 20 27 32 0
178 20 26 32 0
178 20 25 32 66
178 20 16 15 38
178 20 15 15 70
178 20 13 19 32
178 20 12 9 82
178 21 37 11 34
178 21 36 19 68
178 21 34 11 34
178 21 33 11 68
178 21 30 32 50
178 21 29 32 0
178 21 28 32 0
178 21 27 32 0
178 21 26 32 0
178 21 25 32 0
178 21 24 32 82
178 21 16 11 36
178 21 15 11 70
178 21 13 19 32
178 21 12 11 66
178 22 37 11 34
178 22 36 19 68
178 22 34 11 42
178 22 33 11 68
178 22 30 35 32
178 22 29 35 0
178 22 28 35 0
178 22 27 35 0
178 22 26 35 0
178 22 25 35 0
178 22 24 35 64
178 22 16 11 34
178 22 15 11 70
178 22 13 19 32
178 22 12 11 66
178 23 37 9 42
178 23 36 19 68
178 23 33 15 102
178 23 30 35 32
178 23 29 35 0
178 23 28 35 0
178 23 27 35 0
178 23 26 35 0
178 23 25 35 0
178 23 24 35 64
178 23 16 15 34
178 23 15 15 70
178 23 13 19 32
178 23 12 9 74
178 24 36 19 102
178 24 33 15 102
178 24 30 35 42
178 24 29 35 0
178 24 28 35 0
178 24 27 35 0
178 24 26 35 0
178 24 25 35 0
178 24 24 35 74
178 24 16 15 38
178 24 15 15 78
178 24 13 19 98
178 25 36 19 102
178 25 33 15 102
178 25 29 35 42
178 25 28 35 8
178 25 27 35 8
178 25 26 35 8
178 25 25 35 74
178 25 23 32 50
178 25 22 32 16
178 25 21 32 16
178 25 20 32 16
178 25 19 32 82
178 25 16 15 102
178 25 13 19 98
178 26 36 19 42
178 26 35 15 24
178 26 34 8 24
178 26 33 8 76
178 26 24 32 50
178 26 23 32 0
178 26 22 32 0
178 26 21 32 0
178 26 20 32 0
178 26 19 32 0
178 26 18 32 82
178 26 16 8 44
178 26 15 8 24
178 26 14 15 24
178 26 13 19 74
178 27 24 35 32
178 27 23 35 0
178 27 22 35 0
178 27 21 35 0
178 27 20 35 0
178 27 19 35 0
178 27 18 35 64
178 28 24 35 32
178 28 23 35 0
178 28 22 35 0
178 28 21 35 0
178 28 20 35 0
178 28 19 35 0
178 28 18 35 64
178 29 24 35 42
178 29 23 35 0
178 29 22 35 0
178 29 21 35 0
178 29 20 35 0
178 29 19 35 0
178 29 18 35 74
178 30 23 35 42
178 30 22 35 8
178 30 21 35 8
178 30 20 35 8
178 30 19 35 74
179 1 35 15 50
179 1 34 15 24
179 1 33 8 24
179 1 32 8 92
179 1 17 8 60
179 1 16 8 24
179 1 15 15 24
179 1 14 15 82
179 2 35 15 102
179 2 31 13 58
179 2 30 13 24
179 2 29 13 24
179 2 28 13 24
179 2 27 13 24
179 2 26 13 24
179 2 25 13 24
179 2 24 13 24
179 2 23 13 24
179 2 22 13 24
179 2 21 13 24
179 2 20 13 24
179 2 19 13 24
179 2 18 13 90
179 2 14 15 102
179 3 35 15 110
179 3 14 15 110
179 4 36 9 114
179 4 13 9 114
179 5 36 11 98
179 5 13 11 98
179 6 36 11 98
179 6 13 11 98
179 7 36 9 106
179 7 13 9 106
179 8 35 15 118
179 8 14 15 118
179 9 35 15 102
179 9 14 15 102
179 10 35 15 102
179 10 14 15 102
179 11 35 15 102
179 11 14 15 102
179 12 35 15 102
179 12 14 15 102
179 13 35 15 102
179 13 14 15 102
179 14 35 15 102
179 14 14 15 102
179 15 35 15 102
179 15 14 15 102
179 16 35 15 102
179 16 14 15 102
179 17 35 15 102
179 17 14 15 102
179 18 35 15 102
179 18 14 15 102
179 19 35 15 110
179 19 32 10 50
179 19 31 10 24
179 19 30 10 24
179 19 29 10 24
179 19 28 10 16
179 19 27 10 16
179 19 26 10 16
179 19 25 10 24
179 19 24 10 24
179 19 23 10 24
179 19 22 10 24
179 19 21 10 24
179 19 20 10 24
179 19 19 10 24
179 19 18 10 88
179 19 16 10 56
179 19 15 10 24
179 19 14 15 78
179 20 36 9 114
179 20 33 15 50
179 20 32 15 68
179 20 28 32 34
179 20 27 32 2
179 20 26 32 66
179 20 17 15 116
179 20 13 9 114
179 21 36 11 98
179 21 33 11 34
179 21 32 11 68
179 21 29 32 50
179 21 28 32 0
179 21 27 32 0
179 21 26 32 0
179 21 25 32 82
179 21 17 11 38
179 21 16 11 90
179 21 13 11 98
179 22 36 11 98
179 22 33 11 42
179 22 32 11 68
179 22 30 35 50
179 22 29 35 0
179 22 28 35 0
179 22 27 35 0
179 22 26 35 0
179 22 25 35 0
179 22 24 35 82
179 22 17 11 102
179 22 13 11 98
179 23 36 9 106
179 23 32 15 102
179 23 30 35 42
179 23 29 35 0
179 23 28 35 0
179 23 27 35 0
179 23 26 35 0
179 23 25 35 0
179 23 24 35 74
179 23 17 15 102
179 23 13 9 106
179 24 35 15 118
179 24 32 15 102
179 24 29 35 42
179 24 28 35 0
179 24 27 35 0
179 24 26 35 0
179 24 25 35 74
179 24 17 15 102
179 24 14 15 118
179 25 35 15 102
179 25 32 15 102
179 25 28 35 42
179 25 27 35 10
179 25 26 35 74
179 25 22 32 50
179 25 21 32 18
179 25 20 32 82
179 25 17 15 102
179 25 14 15 102
179 26 35 15 42
179 26 34 15 24
179 26 33 8 24
179 26 32 8 76
179 26 23 32 50
179 26 22 32 0
179 26 21 32 0
179 26 20 32 0
179 26 19 32 82
179 26 17 8 44
179 26 16 8 24
179 26 15 15 24
179 26 14 15 74
179 27 24 35 50
179 27 23 35 0
179 27 22 35 0
179 27 21 35 0
179 27 20 35 0
179 27 19 35 0
179 27 18 35 82
179 28 24 35 42
179 28 23 35 0
179 28 22 35 0
179 28 21 35 0
179 28 20 35 0
179 28 19 35 0
179 28 18 35 74
179 29 23 35 42
179 29 22 35 0
179 29 21 35 0
179 29 20 35 0
179 29 19 35 74
179 30 22 35 42
179 30 21 35 10
179 30 20 35 74
180 1 34 15 50
180 1 33 15 24
180 1 32 8 24
180 1 31 8 92
180 1 18 8 60
180 1 17 8 24
180 1 16 15 24
180 1 15 15 82
180 2 34 15 102
180 2 30 15 58
180 2 29 15 26
180 2 28 15 26
180 2 27 15 24
180 2 26 15 24
180 2 25 15 24
180 2 24 15 24
180 2 23 15 24
180 2 22 15 24
180 2 21 15 26
180 2 20 15 26
180 2 19 15 90
180 2 15 15 102
180 3 34 15 110
180 3 15 15 110
180 4 35 9 118
180 4 14 9 118
180 5 35 11 102
180 5 14 11 102
180 6 35 11 102
180 6 14 11 102
180 7 35 9 110
180 7 14 9 110
180 8 34 15 118
180 8 15 15 118
180 9 34 15 102
180 9 15 15 102
180 10 34 15 102
180 10 15 15 102
180 11 34 15 102
180 11 15 15 102
180 12 34 15 102
180 12 15 15 102
180 13 34 15 102
180 13 15 15 102
180 14 34 15 102
180 14 15 15 102
180 15 34 15 102
180 15 15 15 102
180 16 34 15 102
180 16 15 15 102
180 17 34 15 102
180 17 15 15 102
180 18 34 15 102
180 18 15 15 102
180 19 34 15 110
180 19 31 10 50
180 19 30 10 24
180 19 29 10 24
180 19 28 10 24
180 19 27 10 24
180 19 26 10 24
180 19 25 10 24
180 19 24 10 24
180 19 23 10 24
180 19 22 10 24
180 19 21 10 24
180 19 20 10 24
180 19 19 10 24
180 19 18 15 82
180 19 16 10 56
180 19 15 15 74
180 20 35 9 118
180 20 32 15 50
180 20 31 15 68
180 20 18 15 36
180 20 17 15 88
180 20 14 9 118
180 21 35 11 102
180 21 32 11 34
180 21 31 11 68
180 21 28 32 48
180 21 27 32 18
180 21 26 32 82
180 21 18 11 100
180 21 14 11 102
180 22 35 11 102
180 22 32 11 42
180 22 31 11 68
180 22 29 35 48
180 22 28 35 0
180 22 27 35 2
180 22 26 35 2
180 22 25 35 82
180 22 18 11 102
180 22 14 11 102
180 23 35 9 110
180 23 31 15 102
180 23 29 35 40
180 23 28 35 0
180 23 27 35 2
180 23 26 35 2
180 23 25 35 74
180 23 18 15 102
180 23 14 9 110
180 24 34 15 118
180 24 31 15 102
180 24 28 35 40
180 24 27 35 10
180 24 26 35 74
180 24 18 15 102
180 24 15 15 118
180 25 34 15 102
180 25 31 15 102
180 25 18 15 102
180 25 15 15 102
180 26 34 15 42
180 26 33 15 24
180 26 32 8 24
180 26 31 8 76
180 26 22 32 50
180 26 21 32 16
180 26 20 32 80
180 26 18 8 44
180 26 17 8 24
180 26 16 15 24
180 26 15 15 74
180 27 23 35 50
180 27 22 35 2
180 27 21 35 2
180 27 20 35 2
180 27 19 35 82
180 28 23 35 42
180 28 22 35 2
180 28 21 35 2
180 28 20 35 2
180 28 19 35 74
180 29 22 35 42
180 29 21 35 10
180 29 20 35 74
181 1 33 19 50
181 1 32 19 24
181 1 31 8 24
181 1 30 8 28
181 1 29 8 28
181 1 28 8 92
181 1 21 8 60
181 1 20 8 28
181 1 19 8 28
181 1 18 8 24
181 1 17 19 16
181 1 16 19 82
181 2 33 19 102
181 2 27 15 58
181 2 26 15 26
181 2 25 15 26
181 2 24 15 26
181 2 23 15 26
181 2 22 15 90
181 2 17 19 36
181 2 16 19 70
181 3 33 19 102
181 3 17 19 36
181 3 16 19 70
181 4 34 9 54
181 4 33 19 68
181 4 17 19 36
181 4 16 19 4
181 4 15 9 86
181 5 34 11 38
181 5 33 19 68
181 5 17 19 36
181 5 16 19 4
181 5 15 11 70
181 6 34 11 38
181 6 33 19 68
181 6 17 19 36
181 6 16 19 4
181 6 15 11 70
181 7 34 9 46
181 7 33 19 68
181 7 17 19 36
181 7 16 19 4
181 7 15 9 78
181 8 33 19 102
181 8 17 19 36
181 8 16 19 70
181 9 33 19 102
181 9 17 19 36
181 9 16 19 70
181 10 33 19 102
181 10 17 19 36
181 10 16 19 70
181 11 33 19 102
181 11 17 19 36
181 11 16 19 70
181 12 33 19 102
181 12 17 19 36
181 12 16 19 70
181 13 33 19 102
181 13 17 19 36
181 13 16 19 70
181 14 33 19 102
181 14 17 19 36
181 14 16 19 70
181 15 33 19 102
181 15 17 19 36
181 15 16 19 70
181 16 33 19 102
181 16 17 19 36
181 16 16 19 70
181 17 33 19 102
181 17 17 19 36
181 17 16 19 70
181 18 33 19 102
181 18 17 19 36
181 18 16 19 70
181 19 33 19 102
181 19 30 10 50
181 19 29 10 18
181 19 28 10 16
181 19 27 10 24
181 19 26 10 24
181 19 25 10 24
181 19 24 10 24
181 19 23 10 24
181 19 22 10 24
181 19 21 10 16
181 19 20 10 16
181 19 19 10 80
181 19 17 19 36
181 19 16 19 66
181 20 34 9 54
181 20 33 19 68
181 20 31 15 48
181 20 30 15 4
181 20 29 15 4
181 20 28 15 68
181 20 21 15 36
181 20 20 15 4
181 20 19 15 4
181 20 18 15 16
181 20 17 19 0
181 20 16 19 4
181 20 15 9 86
181 21 34 11 38
181 21 33 19 68
181 21 31 11 32
181 21 30 11 4
181 21 29 11 4
181 21 28 11 64
181 21 21 11 36
181 21 20 11 4
181 21 19 11 4
181 21 18 11 8
181 21 17 19 4
181 21 16 19 4
181 21 15 11 70
181 22 34 11 38
181 22 33 19 68
181 22 31 11 40
181 22 30 11 4
181 22 29 11 0
181 22 28 11 64
181 22 21 11 38
181 22 20 11 6
181 22 19 11 70
181 22 17 19 36
181 22 16 19 4
181 22 15 11 70
181 23 34 9 46
181 23 33 19 68
181 23 30 15 38
181 23 29 15 2
181 23 28 15 66
181 23 21 15 38
181 23 20 15 6
181 23 19 15 70
181 23 17 19 36
181 23 16 19 4
181 23 15 9 78
181 24 33 19 102
181 24 30 15 38
181 24 29 15 6
181 24 28 15 66
181 24 21 15 38
181 24 20 15 6
181 24 19 15 70
181 24 17 19 36
181 24 16 19 70
181 25 33 19 102
181 25 30 15 38
181 25 29 15 6
181 25 28 15 70
181 25 21 15 38
181 25 20 15 6
181 25 19 15 70
181 25 17 19 36
181 25 16 19 70
181 26 33 19 42
181 26 32 19 24
181 26 31 8 24
181 26 30 8 12
181 26 29 8 12
181 26 28 8 76
181 26 21 8 40
181 26 20 8 8
181 26 19 8 12
181 26 18 8 24
181 26 17 19 8
181 26 16 19 74
182 1 32 19 50
182 1 31 19 18
182 1 30 8 24
182 1 29 8 24
182 1 28 8 24
182 1 27 8 28
182 1 26 8 28
182 1 25 8 28
182 1 24 8 28
182 1 23 8 28
182 1 22 8 28
182 1 21 8 24
182 1 20 8 24
182 1 19 8 24
182 1 18 19 18
182 1 17 19 82
182 2 32 19 38
182 2 31 19 70
182 2 18 19 38
182 2 17 19 66
182 3 32 19 38
182 3 31 19 70
182 3 18 19 38
182 3 17 19 66
182 4 33 9 50
182 4 32 19 4
182 4 31 19 68
182 4 18 19 36
182 4 17 19 0
182 4 16 9 82
182 5 33 11 34
182 5 32 19 4
182 5 31 19 68
182 5 18 19 36
182 5 17 19 0
182 5 16 11 66
182 6 33 11 34
182 6 32 19 4
182 6 31 19 68
182 6 18 19 36
182 6 17 19 0
182 6 16 11 66
182 7 33 9 42
182 7 32 19 4
182 7 31 19 68
182 7 18 19 36
182 7 17 19 0
182 7 16 9 74
182 8 32 19 38
182 8 31 19 70
182 8 18 19 38
182 8 17 19 66
182 9 32 19 38
182 9 31 19 70
182 9 18 19 38
182 9 17 19 66
182 10 32 19 38
182 10 31 19 70
182 10 18 19 38
182 10 17 19 66
182 11 32 19 38
182 11 31 19 70
182 11 18 19 38
182 11 17 19 66
182 12 32 19 38
182 12 31 19 70
182 12 18 19 38
182 12 17 19 66
182 13 32 19 38
182 13 31 19 70
182 13 18 19 38
182 13 17 19 66
182 14 32 19 38
182 14 31 19 70
182 14 18 19 38
182 14 17 19 66
182 15 32 19 38
182 15 31 19 70
182 15 18 19 38
182 15 17 19 66
182 16 32 19 38
182 16 31 19 70
182 16 18 19 38
182 16 17 19 66
182 17 32 19 38
182 17 31 19 70
182 17 18 19 38
182 17 17 19 66
182 18 32 19 38
182 18 31 19 70
182 18 18 19 38
182 18 17 19 66
182 19 32 19 38
182 19 31 19 70
182 19 28 10 48
182 19 27 10 16
182 19 26 10 18
182 19 25 10 18
182 19 24 10 18
182 19 23 10 18
182 19 22 10 16
182 19 21 10 16
182 19 20 10 16
182 19 19 10 16
182 19 18 19 6
182 19 17 19 66
182 20 33 9 50
182 20 32 19 4
182 20 31 19 0
182 20 30 15 18
182 20 29 15 18
182 20 28 15 2
182 20 27 15 4
182 20 26 15 4
182 20 25 15 4
182 20 24 15 4
182 20 23 15 4
182 20 22 15 4
182 20 21 15 2
182 20 20 15 2
182 20 19 15 2
182 20 18 19 0
182 20 17 19 0
182 20 16 9 82
182 21 33 11 34
182 21 32 19 4
182 21 31 19 0
182 21 30 11 2
182 21 29 11 2
182 21 28 11 2
182 21 27 11 4
182 21 26 11 4
182 21 25 11 4
182 21 24 11 4
182 21 23 11 4
182 21 22 11 4
182 21 21 11 10
182 21 20 11 10
182 21 19 11 10
182 21 18 19 0
182 21 17 19 0
182 21 16 11 66
182 22 33 11 34
182 22 32 19 4
182 22 31 19 0
182 22 30 11 10
182 22 29 11 10
182 22 28 11 10
182 22 27 11 6
182 22 26 11 6
182 22 25 11 6
182 22 24 11 6
182 22 23 11 6
182 22 22 11 70
182 22 18 19 36
182 22 17 19 0
182 22 16 11 66
182 23 33 9 42
182 23 32 19 4
182 23 31 19 68
182 23 27 15 38
182 23 26 15 6
182 23 25 15 6
182 23 24 15 6
182 23 23 15 6
182 23 22 15 70
182 23 18 19 36
182 23 17 19 0
182 23 16 9 74
182 24 32 19 38
182 24 31 19 70
182 24 27 15 36
182 24 26 15 6
182 24 25 15 6
182 24 24 15 6
182 24 23 15 6
182 24 22 15 68
182 24 18 19 38
182 24 17 19 66
182 25 32 19 38
182 25 31 19 70
182 25 27 15 36
182 25 26 15 6
182 25 25 15 6
182 25 24 15 6
182 25 23 15 6
182 25 22 15 68
182 25 18 19 38
182 25 17 19 66
182 26 32 19 42
182 26 31 19 10
182 26 30 8 24
182 26 29 8 24
182 26 28 8 24
182 26 27 8 12
182 26 26 8 12
182 26 25 8 12
182 26 24 8 12
182 26 23 8 12
182 26 22 8 12
182 26 21 8 24
182 26 20 8 24
182 26 19 8 24
182 26 18 19 10
182 26 17 19 74
183 1 30 15 50
183 1 29 15 18
183 1 28 15 18
183 1 27 15 18
183 1 26 8 24
183 1 25 8 24
183 1 24 8 24
183 1 23 8 24
183 1 22 15 18
183 1 21 15 18
183 1 20 15 18
183 1 19 15 82
183 2 30 15 38
183 2 29 15 6
183 2 28 15 6
183 2 27 15 70
183 2 22 15 38
183 2 21 15 6
183 2 20 15 6
183 2 19 15 70
183 3 30 15 46
183 3 29 15 14
183 3 28 15 14
183 3 27 15 78
183 3 22 15 46
183 3 21 15 14
183 3 20 15 14
183 3 19 15 78
183 4 32 9 50
183 4 31 9 82
183 4 18 9 50
183 4 17 9 82
183 5 32 11 34
183 5 31 11 66
183 5 18 11 34
183 5 17 11 66
183 6 32 11 34
183 6 31 11 66
183 6 18 11 34
183 6 17 11 66
183 7 32 9 42
183 7 31 9 74
183 7 18 9 42
183 7 17 9 74
183 8 30 15 54
183 8 29 15 22
183 8 28 15 22
183 8 27 15 86
183 8 22 15 54
183 8 21 15 22
183 8 20 15 22
183 8 19 15 86
183 9 30 15 38
183 9 29 15 6
183 9 28 15 6
183 9 27 15 70
183 9 22 15 38
183 9 21 15 6
183 9 20 15 6
183 9 19 15 70
183 10 30 15 38
183 10 29 15 6
183 10 28 15 6
183 10 27 15 70
183 10 22 15 38
183 10 21 15 6
183 10 20 15 6
183 10 19 15 70
183 11 30 15 38
183 11 29 15 6
183 11 28 15 6
183 11 27 15 70
183 11 22 15 38
183 11 21 15 6
183 11 20 15 6
183 11 19 15 70
183 12 30 15 38
183 12 29 15 6
183 12 28 15 6
183 12 27 15 70
183 12 22 15 38
183 12 21 15 6
183 12 20 15 6
183 12 19 15 70
183 13 30 15 38
183 13 29 15 6
183 13 28 15 6
183 13 27 15 70
183 13 22 15 38
183 13 21 15 6
183 13 20 15 6
183 13 19 15 70
183 14 30 15 38
183 14 29 15 6
183 14 28 15 6
183 14 27 15 70
183 14 22 15 38
183 14 21 15 6
183 14 20 15 6
183 14 19 15 70
183 15 30 15 38
183 15 29 15 6
183 15 28 15 6
183 15 27 15 70
183 15 22 15 38
183 15 21 15 6
183 15 20 15 6
183 15 19 15 70
183 16 30 15 38
183 16 29 15 6
183 16 28 15 6
183 16 27 15 70
183 16 22 15 38
183 16 21 15 6
183 16 20 15 6
183 16 19 15 70
183 17 30 15 38
183 17 29 15 6
183 17 28 15 6
183 17 27 15 70
183 17 22 15 38
183 17 21 15 6
183 17 20 15 6
183 17 19 15 70
183 18 30 15 38
183 18 29 15 6
183 18 28 15 6
183 18 27 15 70
183 18 22 15 38
183 18 21 15 6
183 18 20 15 6
183 18 19 15 70
183 19 30 15 46
183 19 29 15 14
183 19 28 15 10
183 19 27 15 66
183 19 22 15 34
183 19 21 15 10
183 19 20 15 10
183 19 19 15 74
183 20 32 9 50
183 20 31 9 82
183 20 27 15 32
183 20 26 15 16
183 20 25 15 16
183 20 24 15 16
183 20 23 15 16
183 20 22 15 64
183 20 18 9 50
183 20 17 9 82
183 21 32 11 34
183 21 31 11 66
183 21 27 11 40
183 21 26 11 8
183 21 25 11 8
183 21 24 11 8
183 21 23 11 8
183 21 22 11 72
183 21 18 11 34
183 21 17 11 66
183 22 32 11 34
183 22 31 11 66
183 22 18 11 34
183 22 17 11 66
183 23 32 9 42
183 23 31 9 74
183 23 18 9 42
183 23 17 9 74
183 24 30 15 54
183 24 29 15 22
183 24 28 15 22
183 24 27 15 82
183 24 22 15 50
183 24 21 15 22
183 24 20 15 22
183 24 19 15 86
183 25 30 15 38
183 25 29 15 6
183 25 28 15 6
183 25 27 15 66
183 25 22 15 34
183 25 21 15 6
183 25 20 15 6
183 25 19 15 70
183 26 30 15 42
183 26 29 15 10
183 26 28 15 10
183 26 27 15 10
183 26 26 8 24
183 26 25 8 24
183 26 24 8 24
183 26 23 8 24
183 26 22 15 10
183 26 21 15 10
183 26 20 15 10
183 26 19 15 74
184 1 26 19 50
184 1 25 19 18
184 1 24 19 18
184 1 23 19 82
184 2 26 19 38
184 2 25 19 6
184 2 24 19 6
184 2 23 19 70
184 3 26 19 38
184 3 25 19 6
184 3 24 19 6
184 3 23 19 70
184 4 30 9 54
184 4 29 9 22
184 4 28 9 22
184 4 27 9 22
184 4 26 19 4
184 4 25 19 4
184 4 24 19 4
184 4 23 19 4
184 4 22 9 22
184 4 21 9 22
184 4 20 9 22
184 4 19 9 86
184 5 30 11 38
184 5 29 11 6
184 5 28 11 6
184 5 27 11 6
184 5 26 19 4
184 5 25 19 4
184 5 24 19 4
184 5 23 19 4
184 5 22 11 6
184 5 21 11 6
184 5 20 11 6
184 5 19 11 70
184 6 30 11 38
184 6 29 11 6
184 6 28 11 6
184 6 27 11 6
184 6 26 19 4
184 6 25 19 4
184 6 24 19 4
184 6 23 19 4
184 6 22 11 6
184 6 21 11 6
