Qubicle Exchange Format
Version 0.2
www.minddesk.com
65 89 39
20
0.078431 0.513725 0.776471
0.121569 0.125490 0.125490
0.188235 0.192157 0.196078
0.356863 0.501961 0.592157
0.368627 0.372549 0.376471
0.376471 0.309804 0.149020
0.454902 0.466667 0.474510
0.470588 0.368627 0.125490
0.486275 0.309804 0.054902
0.592157 0.596078 0.596078
0.623529 0.521569 0.152941
0.635294 0.647059 0.650980
0.705882 0.600000 0.207843
0.717647 0.627451 0.298039
0.725490 0.725490 0.725490
0.792157 0.701961 0.176471
0.796078 0.803922 0.807843
0.909804 0.913725 0.913725
1.000000 0.905882 0.003922
1.000000 1.000000 1.000000
1 21 12 7 60
1 21 11 7 28
1 21 10 7 28
1 21 9 7 28
1 21 8 7 28
1 21 7 7 28
1 21 6 7 28
1 21 5 7 28
1 21 4 7 28
1 21 3 7 28
1 21 2 7 28
1 21 1 7 28
1 21 0 7 92
2 20 12 5 52
2 20 11 5 20
2 20 10 5 20
2 20 9 5 20
2 20 8 5 20
2 20 7 5 20
2 20 6 5 20
2 20 5 5 20
2 20 4 5 20
2 20 3 5 20
2 20 2 5 20
2 20 1 5 20
2 20 0 5 84
2 21 12 7 32
2 21 11 7 0
2 21 10 7 0
2 21 9 7 0
2 21 8 7 0
2 21 7 7 0
2 21 6 7 0
2 21 5 7 0
2 21 4 7 0
2 21 3 7 0
2 21 2 7 0
2 21 1 7 0
2 21 0 7 64
2 22 25 13 52
2 22 24 13 20
2 22 23 13 20
2 22 22 13 20
2 22 21 13 20
2 22 20 13 20
2 22 19 13 20
2 22 18 13 20
2 22 17 13 20
2 22 16 13 20
2 22 15 13 20
2 22 14 13 20
2 22 13 13 20
2 22 12 13 4
2 22 11 13 4
2 22 10 13 4
2 22 9 13 4
2 22 8 13 4
2 22 7 13 4
2 22 6 13 4
2 22 5 13 4
2 22 4 13 4
2 22 3 13 4
2 22 2 13 4
2 22 1 13 4
2 22 0 13 68
2 23 25 13 44
2 23 24 13 12
2 23 23 13 12
2 23 22 13 12
2 23 21 13 12
2 23 20 13 12
2 23 19 13 12
2 23 18 13 12
2 23 17 13 12
2 23 16 13 12
2 23 15 13 12
2 23 14 13 12
2 23 13 13 12
2 23 12 13 12
2 23 11 13 12
2 23 10 13 12
2 23 9 13 12
2 23 8 13 12
2 23 7 13 12
2 23 6 13 12
2 23 5 13 12
2 23 4 13 12
2 23 3 13 12
2 23 2 13 12
2 23 1 13 12
2 23 0 13 76
3 2 36 4 52
3 2 35 4 28
3 2 34 4 28
3 2 33 4 28
3 2 32 4 84
3 3 36 4 100
3 3 32 4 100
3 4 36 4 100
3 4 32 4 100
3 5 36 4 100
3 5 32 4 100
3 6 36 4 100
3 6 32 4 100
3 7 36 4 100
3 7 32 4 100
3 8 36 4 100
3 8 32 4 100
3 9 36 4 100
3 9 32 4 100
3 10 36 4 100
3 10 32 4 100
3 11 36 4 100
3 11 32 4 100
3 12 36 4 100
3 12 32 4 100
3 13 36 4 100
3 13 32 4 100
3 14 36 4 100
3 14 32 4 100
3 15 36 4 100
3 15 32 4 100
3 16 36 4 100
3 16 32 4 100
3 17 36 4 100
3 17 32 4 100
3 18 36 4 100
3 18 32 4 100
3 19 36 4 100
3 19 32 4 100
3 20 36 4 100
3 20 32 4 100
3 20 12 5 48
3 20 11 5 16
3 20 10 5 16
3 20 9 5 16
3 20 8 5 16
3 20 7 5 16
3 20 6 5 16
3 20 5 5 16
3 20 4 5 16
3 20 3 5 16
3 20 2 5 16
3 20 1 5 16
3 20 0 5 80
3 21 36 4 100
3 21 32 4 100
3 21 12 7 32
3 21 11 7 0
3 21 10 7 0
3 21 9 7 0
3 21 8 7 0
3 21 7 7 0
3 21 6 7 0
3 21 5 7 0
3 21 4 7 0
3 21 3 7 0
3 21 2 7 0
3 21 1 7 0
3 21 0 7 64
3 22 36 4 100
3 22 32 4 100
3 22 25 13 48
3 22 24 13 16
3 22 23 13 16
3 22 22 13 16
3 22 21 13 16
3 22 20 13 16
3 22 19 13 16
3 22 18 13 16
3 22 17 13 16
3 22 16 13 16
3 22 15 13 16
3 22 14 13 16
3 22 13 13 16
3 22 12 13 0
3 22 11 13 0
3 22 10 13 0
3 22 9 13 0
3 22 8 13 0
3 22 7 13 0
3 22 6 13 0
3 22 5 13 0
3 22 4 13 0
3 22 3 13 0
3 22 2 13 0
3 22 1 13 0
3 22 0 13 64
3 23 36 4 100
3 23 32 4 100
3 23 25 13 40
3 23 24 13 8
3 23 23 13 8
3 23 22 13 8
3 23 21 13 8
3 23 20 13 8
3 23 19 13 8
3 23 18 13 8
3 23 17 13 8
3 23 16 13 8
3 23 15 13 8
3 23 14 13 8
3 23 13 13 8
3 23 12 13 8
3 23 11 13 8
3 23 10 13 8
3 23 9 13 8
3 23 8 13 8
3 23 7 13 8
3 23 6 13 8
3 23 5 13 8
3 23 4 13 8
3 23 3 13 8
3 23 2 13 8
3 23 1 13 8
3 23 0 13 72
3 24 36 4 100
3 24 32 4 100
3 25 36 4 100
3 25 32 4 100
3 26 36 4 100
3 26 32 4 100
3 27 36 4 100
3 27 32 4 100
3 28 36 4 100
3 28 32 4 100
3 29 36 4 100
3 29 32 4 100
3 30 36 4 100
3 30 32 4 100
3 31 36 4 100
3 31 32 4 100
3 32 36 4 100
3 32 32 4 100
3 33 36 4 100
3 33 32 4 100
3 34 36 4 100
3 34 32 4 100
3 35 36 4 100
3 35 32 4 100
3 36 36 4 100
3 36 32 4 100
3 37 36 4 100
3 37 32 4 100
3 38 36 4 100
3 38 32 4 100
3 39 36 4 100
3 39 32 4 100
3 40 36 4 100
3 40 32 4 100
3 41 36 4 100
3 41 32 4 100
3 42 36 4 100
3 42 32 4 100
3 43 36 4 100
3 43 32 4 100
3 44 36 4 100
3 44 32 4 100
3 45 36 4 100
3 45 32 4 100
3 46 36 4 100
3 46 32 4 100
3 47 36 4 100
3 47 32 4 100
3 48 36 4 100
3 48 32 4 100
3 49 36 4 100
3 49 32 4 100
3 50 36 4 100
3 50 32 4 100
3 51 36 4 100
3 51 32 4 100
3 52 36 4 100
3 52 32 4 100
3 53 36 4 100
3 53 32 4 100
3 54 36 4 100
3 54 32 4 100
3 55 36 4 100
3 55 32 4 100
3 56 36 4 100
3 56 32 4 100
3 57 36 4 100
3 57 32 4 100
3 58 36 4 100
3 58 32 4 100
3 59 36 4 100
3 59 32 4 100
3 60 36 4 44
3 60 35 4 28
3 60 34 4 28
3 60 33 4 28
3 60 32 4 76
4 1 37 1 52
4 1 36 1 20
4 1 35 1 20
4 1 34 1 20
4 1 33 1 20
4 1 32 1 20
4 1 31 1 84
4 2 37 1 36
4 2 36 1 0
4 2 35 1 0
4 2 34 1 0
4 2 33 1 0
4 2 32 1 0
4 2 31 1 68
4 3 37 1 36
4 3 36 1 0
4 3 35 1 4
4 3 34 1 4
4 3 33 1 4
4 3 32 1 0
4 3 31 1 68
4 4 37 1 36
4 4 36 1 0
4 4 35 1 4
4 4 34 1 4
4 4 33 1 4
4 4 32 1 0
4 4 31 1 68
4 5 37 1 36
4 5 36 1 0
4 5 35 1 4
4 5 34 1 4
4 5 33 1 4
4 5 32 1 0
4 5 31 1 68
4 6 37 1 36
4 6 36 1 0
4 6 35 1 4
4 6 34 1 4
4 6 33 1 4
4 6 32 1 0
4 6 31 1 68
4 7 37 1 36
4 7 36 1 0
4 7 35 1 4
4 7 34 1 4
4 7 33 1 4
4 7 32 1 0
4 7 31 1 68
4 8 37 2 36
4 8 36 2 0
4 8 35 2 4
4 8 34 2 4
4 8 33 2 4
4 8 32 2 0
4 8 31 2 68
4 9 37 2 36
4 9 36 2 0
4 9 35 2 4
4 9 34 2 4
4 9 33 2 4
4 9 32 2 0
4 9 31 2 68
4 10 37 2 36
4 10 36 2 0
4 10 35 2 4
4 10 34 2 4
4 10 33 2 4
4 10 32 2 0
4 10 31 2 68
4 11 37 2 36
4 11 36 2 0
4 11 35 2 4
4 11 34 2 4
4 11 33 2 4
4 11 32 2 0
4 11 31 2 68
4 12 37 2 36
4 12 36 2 0
4 12 35 2 4
4 12 34 2 4
4 12 33 2 4
4 12 32 2 0
4 12 31 2 68
4 13 37 2 36
4 13 36 2 0
4 13 35 2 4
4 13 34 2 4
4 13 33 2 4
4 13 32 2 0
4 13 31 2 68
4 14 37 2 36
4 14 36 2 0
4 14 35 2 4
4 14 34 2 4
4 14 33 2 4
4 14 32 2 0
4 14 31 2 68
4 15 37 2 36
4 15 36 2 0
4 15 35 2 4
4 15 34 2 4
4 15 33 2 4
4 15 32 2 0
4 15 31 2 68
4 16 37 2 36
4 16 36 2 0
4 16 35 2 4
4 16 34 2 4
4 16 33 2 4
4 16 32 2 0
4 16 31 2 68
4 17 37 2 36
4 17 36 2 0
4 17 35 2 4
4 17 34 2 4
4 17 33 2 4
4 17 32 2 0
4 17 31 2 68
4 18 37 2 36
4 18 36 2 0
4 18 35 2 4
4 18 34 2 4
4 18 33 2 4
4 18 32 2 0
4 18 31 2 68
4 19 37 2 36
4 19 36 2 0
4 19 35 2 4
4 19 34 2 4
4 19 33 2 4
4 19 32 2 0
4 19 31 2 68
4 20 37 2 36
4 20 36 2 0
4 20 35 2 4
4 20 34 2 4
4 20 33 2 4
4 20 32 2 0
4 20 31 2 68
4 20 12 5 48
4 20 11 5 16
4 20 10 5 16
4 20 9 5 16
4 20 8 5 16
4 20 7 5 16
4 20 6 5 16
4 20 5 5 16
4 20 4 5 16
4 20 3 5 16
4 20 2 5 16
4 20 1 5 16
4 20 0 5 80
4 21 37 2 36
4 21 36 2 0
4 21 35 2 4
4 21 34 2 4
4 21 33 2 4
4 21 32 2 0
4 21 31 2 68
4 21 12 7 32
4 21 11 7 0
4 21 10 7 0
4 21 9 7 0
4 21 8 7 0
4 21 7 7 0
4 21 6 7 0
4 21 5 7 0
4 21 4 7 0
4 21 3 7 0
4 21 2 7 0
4 21 1 7 0
4 21 0 7 64
4 22 37 2 36
4 22 36 2 0
4 22 35 2 4
4 22 34 2 4
4 22 33 2 4
4 22 32 2 0
4 22 31 2 68
4 22 25 13 48
4 22 24 13 16
4 22 23 13 16
4 22 22 13 16
4 22 21 13 16
4 22 20 13 16
4 22 19 13 16
4 22 18 13 16
4 22 17 13 16
4 22 16 13 16
4 22 15 13 16
4 22 14 13 16
4 22 13 13 16
4 22 12 13 0
4 22 11 13 0
4 22 10 13 0
4 22 9 13 0
4 22 8 13 0
4 22 7 13 0
4 22 6 13 0
4 22 5 13 0
4 22 4 13 0
4 22 3 13 0
4 22 2 13 0
4 22 1 13 0
4 22 0 13 64
4 23 37 2 36
4 23 36 2 0
4 23 35 2 4
4 23 34 2 4
4 23 33 2 4
4 23 32 2 0
4 23 31 2 68
4 23 25 13 40
4 23 24 13 0
4 23 23 13 0
4 23 22 13 0
4 23 21 13 0
4 23 20 13 0
4 23 19 13 0
4 23 18 13 0
4 23 17 13 0
4 23 16 13 0
4 23 15 13 0
4 23 14 13 0
4 23 13 13 0
4 23 12 13 0
4 23 11 13 0
4 23 10 13 0
4 23 9 13 0
4 23 8 13 0
4 23 7 13 0
4 23 6 13 0
4 23 5 13 0
4 23 4 13 0
4 23 3 13 8
4 23 2 13 8
4 23 1 13 8
4 23 0 13 72
4 24 37 2 36
4 24 36 2 0
4 24 35 2 4
4 24 34 2 4
4 24 33 2 4
4 24 32 2 0
4 24 31 2 68
4 24 24 13 44
4 24 23 13 12
4 24 22 13 12
4 24 21 13 12
4 24 20 13 12
4 24 19 13 12
4 24 18 13 12
4 24 17 13 12
4 24 16 13 12
4 24 15 13 12
4 24 14 13 12
4 24 13 13 12
4 24 12 13 12
4 24 11 13 12
4 24 10 13 12
4 24 9 13 12
4 24 8 13 12
4 24 7 13 12
4 24 6 13 12
4 24 5 13 12
4 24 4 13 76
4 25 37 2 36
4 25 36 2 0
4 25 35 2 4
4 25 34 2 4
4 25 33 2 4
4 25 32 2 0
4 25 31 2 68
4 26 37 2 36
4 26 36 2 0
4 26 35 2 4
4 26 34 2 4
4 26 33 2 4
4 26 32 2 0
4 26 31 2 68
4 27 37 2 36
4 27 36 2 0
4 27 35 2 4
4 27 34 2 4
4 27 33 2 4
4 27 32 2 0
4 27 31 2 68
4 28 37 2 36
4 28 36 2 0
4 28 35 2 4
4 28 34 2 4
4 28 33 2 4
4 28 32 2 0
4 28 31 2 68
4 29 37 2 36
4 29 36 2 0
4 29 35 2 4
4 29 34 2 4
4 29 33 2 4
4 29 32 2 0
4 29 31 2 68
4 30 37 2 36
4 30 36 2 0
4 30 35 2 4
4 30 34 2 4
4 30 33 2 4
4 30 32 2 0
4 30 31 2 68
4 31 37 2 36
4 31 36 2 0
4 31 35 2 4
4 31 34 2 4
4 31 33 2 4
4 31 32 2 0
4 31 31 2 68
4 32 37 2 36
4 32 36 2 0
4 32 35 2 4
4 32 34 2 4
4 32 33 2 4
4 32 32 2 0
4 32 31 2 68
4 33 37 2 36
4 33 36 2 0
4 33 35 2 4
4 33 34 2 4
4 33 33 2 4
4 33 32 2 0
4 33 31 2 68
4 34 37 2 36
4 34 36 2 0
4 34 35 2 4
4 34 34 2 4
4 34 33 2 4
4 34 32 2 0
4 34 31 2 68
4 35 37 2 36
4 35 36 2 0
4 35 35 2 4
4 35 34 2 4
4 35 33 2 4
4 35 32 2 0
4 35 31 2 68
4 36 37 2 36
4 36 36 2 0
4 36 35 2 4
4 36 34 2 4
4 36 33 2 4
4 36 32 2 0
4 36 31 2 68
4 37 37 2 36
4 37 36 2 0
4 37 35 2 4
4 37 34 2 4
4 37 33 2 4
4 37 32 2 0
4 37 31 2 68
4 38 37 2 36
4 38 36 2 0
4 38 35 2 4
4 38 34 2 4
4 38 33 2 4
4 38 32 2 0
4 38 31 2 68
4 39 37 2 36
4 39 36 2 0
4 39 35 2 4
4 39 34 2 4
4 39 33 2 4
4 39 32 2 0
4 39 31 2 68
4 40 37 2 36
4 40 36 2 0
4 40 35 2 4
4 40 34 2 4
4 40 33 2 4
4 40 32 2 0
4 40 31 2 68
4 41 37 2 36
4 41 36 2 0
4 41 35 2 4
4 41 34 2 4
4 41 33 2 4
4 41 32 2 0
4 41 31 2 68
4 42 37 2 36
4 42 36 2 0
4 42 35 2 4
4 42 34 2 4
4 42 33 2 4
4 42 32 2 0
4 42 31 2 68
4 43 37 2 36
4 43 36 2 0
4 43 35 2 4
4 43 34 2 4
4 43 33 2 4
4 43 32 2 0
4 43 31 2 68
4 44 37 2 36
4 44 36 2 0
4 44 35 2 4
4 44 34 2 4
4 44 33 2 4
4 44 32 2 0
4 44 31 2 68
4 45 37 2 36
4 45 36 2 0
4 45 35 2 4
4 45 34 2 4
4 45 33 2 4
4 45 32 2 0
4 45 31 2 68
4 46 37 2 36
4 46 36 2 0
4 46 35 2 4
4 46 34 2 4
4 46 33 2 4
4 46 32 2 0
4 46 31 2 68
4 47 37 2 36
4 47 36 2 0
4 47 35 2 4
4 47 34 2 4
4 47 33 2 4
4 47 32 2 0
4 47 31 2 68
4 48 37 2 36
4 48 36 2 0
4 48 35 2 4
4 48 34 2 4
4 48 33 2 4
4 48 32 2 0
4 48 31 2 68
4 49 37 2 36
4 49 36 2 0
4 49 35 2 4
4 49 34 2 4
4 49 33 2 4
4 49 32 2 0
4 49 31 2 68
4 50 37 2 36
4 50 36 2 0
4 50 35 2 4
4 50 34 2 4
4 50 33 2 4
4 50 32 2 0
4 50 31 2 68
4 51 37 2 36
4 51 36 2 0
4 51 35 2 4
4 51 34 2 4
4 51 33 2 4
4 51 32 2 0
4 51 31 2 68
4 52 37 2 36
4 52 36 2 0
4 52 35 2 4
4 52 34 2 4
4 52 33 2 4
4 52 32 2 0
4 52 31 2 68
4 53 37 2 36
4 53 36 2 0
4 53 35 2 4
4 53 34 2 4
4 53 33 2 4
4 53 32 2 0
4 53 31 2 68
4 54 37 2 36
4 54 36 2 0
4 54 35 2 4
4 54 34 2 4
4 54 33 2 4
4 54 32 2 0
4 54 31 2 68
4 55 37 2 36
4 55 36 2 0
4 55 35 2 4
4 55 34 2 4
4 55 33 2 4
4 55 32 2 0
4 55 31 2 68
4 56 37 2 36
4 56 36 2 0
4 56 35 2 4
4 56 34 2 4
4 56 33 2 4
4 56 32 2 0
4 56 31 2 68
4 57 37 2 36
4 57 36 2 0
4 57 35 2 4
4 57 34 2 4
4 57 33 2 4
4 57 32 2 0
4 57 31 2 68
4 58 37 2 36
4 58 36 2 0
4 58 35 2 4
4 58 34 2 4
4 58 33 2 4
4 58 32 2 0
4 58 31 2 68
4 59 37 2 36
4 59 36 2 0
4 59 35 2 4
4 59 34 2 4
4 59 33 2 4
4 59 32 2 0
4 59 31 2 68
4 60 37 2 36
4 60 36 2 0
4 60 35 2 0
4 60 34 2 0
4 60 33 2 0
4 60 32 2 0
4 60 31 2 68
4 61 37 2 44
4 61 36 2 12
4 61 35 2 12
4 61 34 2 12
4 61 33 2 12
4 61 32 2 12
4 61 31 2 76
5 1 37 1 48
5 1 36 1 16
5 1 35 1 16
5 1 34 1 16
5 1 33 1 16
5 1 32 1 16
5 1 31 1 80
5 2 37 1 32
5 2 36 1 0
5 2 35 1 0
5 2 34 1 0
5 2 33 1 0
5 2 32 1 0
5 2 31 1 64
5 3 37 1 32
5 3 36 1 0
5 3 35 1 0
5 3 34 1 0
5 3 33 1 0
5 3 32 1 0
5 3 31 1 64
5 4 37 1 32
5 4 36 1 0
5 4 35 1 0
5 4 34 1 0
5 4 33 1 0
5 4 32 1 0
5 4 31 1 64
5 5 37 1 32
5 5 36 1 0
5 5 35 1 0
5 5 34 1 0
5 5 33 1 0
5 5 32 1 0
5 5 31 1 64
5 6 37 1 32
5 6 36 1 0
5 6 35 1 0
5 6 34 1 0
5 6 33 1 0
5 6 32 1 0
5 6 31 1 64
5 7 37 1 32
5 7 36 1 0
5 7 35 1 0
5 7 34 1 0
5 7 33 1 0
5 7 32 1 0
5 7 31 1 64
5 8 37 2 32
5 8 36 2 0
5 8 35 2 0
5 8 34 2 0
5 8 33 2 0
5 8 32 2 0
5 8 31 2 64
5 9 37 2 32
5 9 36 2 0
5 9 35 2 0
5 9 34 2 0
5 9 33 2 0
5 9 32 2 0
5 9 31 2 64
5 10 37 2 32
5 10 36 2 0
5 10 35 2 0
5 10 34 2 0
5 10 33 2 0
5 10 32 2 0
5 10 31 2 64
5 11 37 2 32
5 11 36 2 0
5 11 35 2 0
5 11 34 2 0
5 11 33 2 0
5 11 32 2 0
5 11 31 2 64
5 12 37 2 32
5 12 36 2 0
5 12 35 2 0
5 12 34 2 0
5 12 33 2 0
5 12 32 2 0
5 12 31 2 64
5 13 37 2 32
5 13 36 2 0
5 13 35 2 0
5 13 34 2 0
5 13 33 2 0
5 13 32 2 0
5 13 31 2 64
5 14 37 2 32
5 14 36 2 0
5 14 35 2 0
5 14 34 2 0
5 14 33 2 0
5 14 32 2 0
5 14 31 2 64
5 15 37 2 32
5 15 36 2 0
5 15 35 2 0
5 15 34 2 0
5 15 33 2 0
5 15 32 2 0
5 15 31 2 64
5 16 37 2 32
5 16 36 2 0
5 16 35 2 0
5 16 34 2 0
5 16 33 2 0
5 16 32 2 0
5 16 31 2 64
5 17 37 2 32
5 17 36 2 0
5 17 35 2 0
5 17 34 2 0
5 17 33 2 0
5 17 32 2 0
5 17 31 2 64
5 18 37 2 32
5 18 36 2 0
5 18 35 2 0
5 18 34 2 0
5 18 33 2 0
5 18 32 2 0
5 18 31 2 64
5 19 37 2 32
5 19 36 2 0
5 19 35 2 0
5 19 34 2 0
5 19 33 2 0
5 19 32 2 0
5 19 31 2 64
5 20 37 2 32
5 20 36 2 0
5 20 35 2 0
5 20 34 2 0
5 20 33 2 0
5 20 32 2 0
5 20 31 2 64
5 20 12 5 48
5 20 11 5 16
5 20 10 5 16
5 20 9 5 16
5 20 8 5 16
5 20 7 5 16
5 20 6 5 16
5 20 5 5 16
5 20 4 5 16
5 20 3 5 16
5 20 2 5 16
5 20 1 5 16
5 20 0 5 80
5 21 37 2 32
5 21 36 2 0
5 21 35 2 0
5 21 34 2 0
5 21 33 2 0
5 21 32 2 0
5 21 31 2 64
5 21 12 7 32
5 21 11 7 0
5 21 10 7 0
5 21 9 7 0
5 21 8 7 0
5 21 7 7 0
5 21 6 7 0
5 21 5 7 0
5 21 4 7 0
5 21 3 7 0
5 21 2 7 0
5 21 1 7 0
5 21 0 7 64
5 22 37 2 32
5 22 36 2 0
5 22 35 2 0
5 22 34 2 0
5 22 33 2 0
5 22 32 2 0
5 22 31 2 64
5 22 25 13 48
5 22 24 13 16
5 22 23 13 16
5 22 22 13 16
5 22 21 13 16
5 22 20 13 16
5 22 19 13 16
5 22 18 13 16
5 22 17 13 16
5 22 16 13 16
5 22 15 13 16
5 22 14 13 16
5 22 13 13 16
5 22 12 13 0
5 22 11 13 0
5 22 10 13 0
5 22 9 13 0
5 22 8 13 0
5 22 7 13 0
5 22 6 13 0
5 22 5 13 0
5 22 4 13 0
5 22 3 13 0
5 22 2 13 0
5 22 1 13 0
5 22 0 13 64
5 23 37 2 32
5 23 36 2 0
5 23 35 2 0
5 23 34 2 0
5 23 33 2 0
5 23 32 2 0
5 23 31 2 64
5 23 25 13 40
5 23 24 13 0
5 23 23 13 0
5 23 22 13 0
5 23 21 13 0
5 23 20 13 0
5 23 19 13 0
5 23 18 13 0
5 23 17 13 0
5 23 16 13 0
5 23 15 13 0
5 23 14 13 0
5 23 13 13 0
5 23 12 13 0
5 23 11 13 0
5 23 10 13 0
5 23 9 13 0
5 23 8 13 0
5 23 7 13 0
5 23 6 13 0
5 23 5 13 0
5 23 4 13 0
5 23 3 13 8
5 23 2 13 8
5 23 1 13 8
5 23 0 13 72
5 24 37 2 32
5 24 36 2 0
5 24 35 2 0
5 24 34 2 0
5 24 33 2 0
5 24 32 2 0
5 24 31 2 64
5 24 24 13 40
5 24 23 13 8
5 24 22 13 8
5 24 21 13 8
5 24 20 13 8
5 24 19 13 8
5 24 18 13 8
5 24 17 13 8
5 24 16 13 8
5 24 15 13 8
5 24 14 13 8
5 24 13 13 8
5 24 12 13 8
5 24 11 13 8
5 24 10 13 8
5 24 9 13 8
5 24 8 13 8
5 24 7 13 8
5 24 6 13 8
5 24 5 13 8
5 24 4 13 72
5 25 37 2 32
5 25 36 2 0
5 25 35 2 0
5 25 34 2 0
5 25 33 2 0
5 25 32 2 0
5 25 31 2 64
5 26 37 2 32
5 26 36 2 0
5 26 35 2 0
5 26 34 2 0
5 26 33 2 0
5 26 32 2 0
5 26 31 2 64
5 27 37 2 32
5 27 36 2 0
5 27 35 2 0
5 27 34 2 0
5 27 33 2 0
5 27 32 2 0
5 27 31 2 64
5 28 37 2 32
5 28 36 2 0
5 28 35 2 0
5 28 34 2 0
5 28 33 2 0
5 28 32 2 0
5 28 31 2 64
5 29 37 2 32
5 29 36 2 0
5 29 35 2 0
5 29 34 2 0
5 29 33 2 0
5 29 32 2 0
5 29 31 2 64
5 30 37 2 32
5 30 36 2 0
5 30 35 2 0
5 30 34 2 0
5 30 33 2 0
5 30 32 2 0
5 30 31 2 64
5 31 37 2 32
5 31 36 2 0
5 31 35 2 0
5 31 34 2 0
5 31 33 2 0
5 31 32 2 0
5 31 31 2 64
5 32 37 2 32
5 32 36 2 0
5 32 35 2 0
5 32 34 2 0
5 32 33 2 0
5 32 32 2 0
5 32 31 2 64
5 33 37 2 32
5 33 36 2 0
5 33 35 2 0
5 33 34 2 0
5 33 33 2 0
5 33 32 2 0
5 33 31 2 64
5 34 37 2 32
5 34 36 2 0
5 34 35 2 0
5 34 34 2 0
5 34 33 2 0
5 34 32 2 0
5 34 31 2 64
5 35 37 2 32
5 35 36 2 0
5 35 35 2 0
5 35 34 2 0
5 35 33 2 0
5 35 32 2 0
5 35 31 2 64
5 36 37 2 32
5 36 36 2 0
5 36 35 2 0
5 36 34 2 0
5 36 33 2 0
5 36 32 2 0
5 36 31 2 64
5 37 37 2 32
5 37 36 2 0
5 37 35 2 0
5 37 34 2 0
5 37 33 2 0
5 37 32 2 0
5 37 31 2 64
5 38 37 2 32
5 38 36 2 0
5 38 35 2 0
5 38 34 2 0
5 38 33 2 0
5 38 32 2 0
5 38 31 2 64
5 39 37 2 32
5 39 36 2 0
5 39 35 2 0
5 39 34 2 0
5 39 33 2 0
5 39 32 2 0
5 39 31 2 64
5 40 37 2 32
5 40 36 2 0
5 40 35 2 0
5 40 34 2 0
5 40 33 2 0
5 40 32 2 0
5 40 31 2 64
5 41 37 2 32
5 41 36 2 0
5 41 35 2 0
5 41 34 2 0
5 41 33 2 0
5 41 32 2 0
5 41 31 2 64
5 42 37 2 32
5 42 36 2 0
5 42 35 2 0
5 42 34 2 0
5 42 33 2 0
5 42 32 2 0
5 42 31 2 64
5 43 37 2 32
5 43 36 2 0
5 43 35 2 0
5 43 34 2 0
5 43 33 2 0
5 43 32 2 0
5 43 31 2 66
5 44 37 2 32
5 44 36 2 0
5 44 35 2 0
5 44 34 2 0
5 44 33 2 0
5 44 32 2 0
5 44 31 2 64
5 45 37 2 32
5 45 36 2 0
5 45 35 2 0
5 45 34 2 0
5 45 33 2 0
5 45 32 2 0
5 45 31 2 66
5 46 37 2 32
5 46 36 2 0
5 46 35 2 0
5 46 34 2 0
5 46 33 2 0
5 46 32 2 0
5 46 31 2 66
5 47 37 2 32
5 47 36 2 0
5 47 35 2 0
5 47 34 2 0
5 47 33 2 0
5 47 32 2 0
5 47 31 2 66
5 48 37 2 32
5 48 36 2 0
5 48 35 2 0
5 48 34 2 0
5 48 33 2 0
5 48 32 2 0
5 48 31 2 66
5 49 37 2 32
5 49 36 2 0
5 49 35 2 0
5 49 34 2 0
5 49 33 2 0
5 49 32 2 0
5 49 31 2 66
5 50 37 2 32
5 50 36 2 0
5 50 35 2 0
5 50 34 2 0
5 50 33 2 0
5 50 32 2 0
5 50 31 2 64
5 51 37 2 32
5 51 36 2 0
5 51 35 2 0
5 51 34 2 0
5 51 33 2 0
5 51 32 2 0
5 51 31 2 64
5 52 37 2 32
5 52 36 2 0
5 52 35 2 0
5 52 34 2 0
5 52 33 2 0
5 52 32 2 0
5 52 31 2 66
5 53 37 2 32
5 53 36 2 0
5 53 35 2 0
5 53 34 2 0
5 53 33 2 0
5 53 32 2 0
5 53 31 2 66
5 54 37 2 32
5 54 36 2 0
5 54 35 2 0
5 54 34 2 0
5 54 33 2 0
5 54 32 2 0
5 54 31 2 66
5 55 37 2 32
5 55 36 2 0
5 55 35 2 0
5 55 34 2 0
5 55 33 2 0
5 55 32 2 0
5 55 31 2 66
5 56 37 2 32
5 56 36 2 0
5 56 35 2 0
5 56 34 2 0
5 56 33 2 0
5 56 32 2 0
5 56 31 2 66
5 57 37 2 32
5 57 36 2 0
5 57 35 2 0
5 57 34 2 0
5 57 33 2 0
5 57 32 2 0
5 57 31 2 66
5 58 37 2 32
5 58 36 2 0
5 58 35 2 0
5 58 34 2 0
5 58 33 2 0
5 58 32 2 0
5 58 31 2 64
5 59 37 2 32
5 59 36 2 0
5 59 35 2 0
5 59 34 2 0
5 59 33 2 0
5 59 32 2 0
5 59 31 2 64
5 60 37 2 32
5 60 36 2 0
5 60 35 2 0
5 60 34 2 0
5 60 33 2 0
5 60 32 2 0
5 60 31 2 64
5 61 37 2 40
5 61 36 2 8
5 61 35 2 8
5 61 34 2 8
5 61 33 2 8
5 61 32 2 8
5 61 31 2 72
5 71 35 9 52
5 71 34 9 20
5 71 33 9 84
5 72 36 11 60
5 72 35 11 4
5 72 34 11 4
5 72 33 11 4
5 72 32 11 92
5 73 35 9 44
5 73 34 9 12
5 73 33 9 76
6 1 37 1 48
6 1 36 1 16
6 1 35 1 16
6 1 34 1 16
6 1 33 1 16
6 1 32 1 16
6 1 31 1 80
6 2 37 1 32
6 2 36 1 0
6 2 35 1 0
6 2 34 1 0
6 2 33 1 0
6 2 32 1 0
6 2 31 1 64
6 3 37 1 32
6 3 36 1 0
6 3 35 1 0
6 3 34 1 0
6 3 33 1 0
6 3 32 1 0
6 3 31 1 64
6 4 37 1 32
6 4 36 1 0
6 4 35 1 0
6 4 34 1 0
6 4 33 1 0
6 4 32 1 0
6 4 31 1 64
6 5 37 1 32
6 5 36 1 0
6 5 35 1 0
6 5 34 1 0
6 5 33 1 0
6 5 32 1 0
6 5 31 1 64
6 6 37 1 32
6 6 36 1 0
6 6 35 1 0
6 6 34 1 0
6 6 33 1 0
6 6 32 1 0
6 6 31 1 64
6 7 37 1 32
6 7 36 1 0
6 7 35 1 0
6 7 34 1 0
6 7 33 1 0
6 7 32 1 0
6 7 31 1 64
6 8 37 2 32
6 8 36 2 0
6 8 35 2 0
6 8 34 2 0
6 8 33 2 0
6 8 32 2 0
6 8 31 2 64
6 9 37 2 32
6 9 36 2 0
6 9 35 2 0
6 9 34 2 0
6 9 33 2 0
6 9 32 2 0
6 9 31 2 64
6 10 37 2 32
6 10 36 2 0
6 10 35 2 0
6 10 34 2 0
6 10 33 2 0
6 10 32 2 0
6 10 31 2 64
6 11 37 2 32
6 11 36 2 0
6 11 35 2 0
6 11 34 2 0
6 11 33 2 0
6 11 32 2 0
6 11 31 2 64
6 12 37 2 32
6 12 36 2 0
6 12 35 2 0
6 12 34 2 0
6 12 33 2 0
6 12 32 2 0
6 12 31 2 64
6 13 37 2 32
6 13 36 2 0
6 13 35 2 0
6 13 34 2 0
6 13 33 2 0
6 13 32 2 0
6 13 31 2 64
6 14 37 2 32
6 14 36 2 0
6 14 35 2 0
6 14 34 2 0
6 14 33 2 0
6 14 32 2 0
6 14 31 2 64
6 15 37 2 32
6 15 36 2 0
6 15 35 2 0
6 15 34 2 0
6 15 33 2 0
6 15 32 2 0
6 15 31 2 64
6 16 37 2 32
6 16 36 2 0
6 16 35 2 0
6 16 34 2 0
6 16 33 2 0
6 16 32 2 0
6 16 31 2 64
6 17 37 2 32
6 17 36 2 0
6 17 35 2 0
6 17 34 2 0
6 17 33 2 0
6 17 32 2 0
6 17 31 2 64
6 18 37 2 32
6 18 36 2 0
6 18 35 2 0
6 18 34 2 0
6 18 33 2 0
6 18 32 2 0
6 18 31 2 64
6 19 37 2 32
6 19 36 2 0
6 19 35 2 0
6 19 34 2 0
6 19 33 2 0
6 19 32 2 0
6 19 31 2 64
6 20 37 2 32
6 20 36 2 0
6 20 35 2 0
6 20 34 2 0
6 20 33 2 0
6 20 32 2 0
6 20 31 2 64
6 20 12 5 48
6 20 11 5 16
6 20 10 5 16
6 20 9 5 16
6 20 8 5 16
6 20 7 5 16
6 20 6 5 16
6 20 5 5 16
6 20 4 5 16
6 20 3 5 16
6 20 2 5 16
6 20 1 5 16
6 20 0 5 80
6 21 37 2 32
6 21 36 2 0
6 21 35 2 0
6 21 34 2 0
6 21 33 2 0
6 21 32 2 0
6 21 31 2 64
6 21 12 7 32
6 21 11 7 0
6 21 10 7 0
6 21 9 7 0
6 21 8 7 0
6 21 7 7 0
6 21 6 7 0
6 21 5 7 0
6 21 4 7 0
6 21 3 7 0
6 21 2 7 0
6 21 1 7 0
6 21 0 7 64
6 22 37 2 32
6 22 36 2 0
6 22 35 2 0
6 22 34 2 0
6 22 33 2 0
6 22 32 2 0
6 22 31 2 64
6 22 25 13 48
6 22 24 13 16
6 22 23 13 16
6 22 22 13 16
6 22 21 13 16
6 22 20 13 16
6 22 19 13 16
6 22 18 13 16
6 22 17 13 16
6 22 16 13 16
6 22 15 13 16
6 22 14 13 16
6 22 13 13 16
6 22 12 13 0
6 22 11 13 0
6 22 10 13 0
6 22 9 13 0
6 22 8 13 0
6 22 7 13 0
6 22 6 13 0
6 22 5 13 0
6 22 4 13 0
6 22 3 13 0
6 22 2 13 0
6 22 1 13 0
6 22 0 13 64
6 23 37 2 32
6 23 36 2 0
6 23 35 2 0
6 23 34 2 0
6 23 33 2 0
6 23 32 2 0
6 23 31 2 64
6 23 25 13 40
6 23 24 13 0
6 23 23 13 0
6 23 22 13 0
6 23 21 13 0
6 23 20 13 0
6 23 19 13 0
6 23 18 13 0
6 23 17 13 0
6 23 16 13 0
6 23 15 13 0
6 23 14 13 0
6 23 13 13 0
6 23 12 13 0
6 23 11 13 0
6 23 10 13 0
6 23 9 13 0
6 23 8 13 0
6 23 7 13 0
6 23 6 13 0
6 23 5 13 0
6 23 4 13 0
6 23 3 13 8
6 23 2 13 8
6 23 1 13 8
6 23 0 13 72
6 24 37 2 32
6 24 36 2 0
6 24 35 2 0
6 24 34 2 0
6 24 33 2 0
6 24 32 2 0
6 24 31 2 64
6 24 24 13 40
6 24 23 13 8
6 24 22 13 8
6 24 21 13 8
6 24 20 13 8
6 24 19 13 8
6 24 18 13 8
6 24 17 13 8
6 24 16 13 8
6 24 15 13 8
6 24 14 13 8
6 24 13 13 8
6 24 12 13 8
6 24 11 13 8
6 24 10 13 8
6 24 9 13 8
6 24 8 13 8
6 24 7 13 8
6 24 6 13 8
6 24 5 13 8
6 24 4 13 72
6 25 37 2 32
6 25 36 2 0
6 25 35 2 0
6 25 34 2 0
6 25 33 2 0
6 25 32 2 0
6 25 31 2 64
6 26 37 2 32
6 26 36 2 0
6 26 35 2 0
6 26 34 2 0
6 26 33 2 0
6 26 32 2 0
6 26 31 2 64
6 27 37 2 32
6 27 36 2 0
6 27 35 2 0
6 27 34 2 0
6 27 33 2 0
6 27 32 2 0
6 27 31 2 64
6 28 37 2 32
6 28 36 2 0
6 28 35 2 0
6 28 34 2 0
6 28 33 2 0
6 28 32 2 0
6 28 31 2 64
6 29 37 2 32
6 29 36 2 0
6 29 35 2 0
6 29 34 2 0
6 29 33 2 0
6 29 32 2 0
6 29 31 2 64
6 30 37 2 32
6 30 36 2 0
6 30 35 2 0
6 30 34 2 0
6 30 33 2 0
6 30 32 2 0
6 30 31 2 64
6 31 37 2 32
6 31 36 2 0
6 31 35 2 0
6 31 34 2 0
6 31 33 2 0
6 31 32 2 0
6 31 31 2 64
6 32 37 2 32
6 32 36 2 0
6 32 35 2 0
6 32 34 2 0
6 32 33 2 0
6 32 32 2 0
6 32 31 2 64
6 33 37 2 32
6 33 36 2 0
6 33 35 2 0
6 33 34 2 0
6 33 33 2 0
6 33 32 2 0
6 33 31 2 64
6 34 37 2 32
6 34 36 2 0
6 34 35 2 0
6 34 34 2 0
6 34 33 2 0
6 34 32 2 0
6 34 31 2 64
6 35 37 2 32
6 35 36 2 0
6 35 35 2 0
6 35 34 2 0
6 35 33 2 0
6 35 32 2 0
6 35 31 2 64
6 36 37 2 32
6 36 36 2 0
6 36 35 2 0
6 36 34 2 0
6 36 33 2 0
6 36 32 2 0
6 36 31 2 64
6 37 37 2 32
6 37 36 2 0
6 37 35 2 0
6 37 34 2 0
6 37 33 2 0
6 37 32 2 0
6 37 31 2 64
6 38 37 2 32
6 38 36 2 0
6 38 35 2 0
6 38 34 2 0
6 38 33 2 0
6 38 32 2 0
6 38 31 2 64
6 39 37 2 32
6 39 36 2 0
6 39 35 2 0
6 39 34 2 0
6 39 33 2 0
6 39 32 2 0
6 39 31 2 64
6 40 37 2 32
6 40 36 2 0
6 40 35 2 0
6 40 34 2 0
6 40 33 2 0
6 40 32 2 0
6 40 31 2 64
6 41 37 2 32
6 41 36 2 0
6 41 35 2 0
6 41 34 2 0
6 41 33 2 0
6 41 32 2 0
6 41 31 2 64
6 42 37 2 32
6 42 36 2 0
6 42 35 2 0
6 42 34 2 0
6 42 33 2 0
6 42 32 2 0
6 42 31 2 72
6 43 37 2 32
6 43 36 2 0
6 43 35 2 0
6 43 34 2 0
6 43 33 2 0
6 43 32 4 64
6 44 37 2 32
6 44 36 2 0
6 44 35 2 0
6 44 34 2 0
6 44 33 2 0
6 44 32 2 0
6 44 31 2 88
6 45 37 2 32
6 45 36 2 0
6 45 35 2 0
6 45 34 2 0
6 45 33 2 0
6 45 32 4 64
6 46 37 2 32
6 46 36 2 0
6 46 35 2 0
6 46 34 2 0
6 46 33 2 0
6 46 32 4 66
6 47 37 2 32
6 47 36 2 0
6 47 35 2 0
6 47 34 2 0
6 47 33 2 0
6 47 32 4 66
6 48 37 2 32
6 48 36 2 0
6 48 35 2 0
6 48 34 2 0
6 48 33 2 0
6 48 32 4 66
6 49 37 2 32
6 49 36 2 0
6 49 35 2 0
6 49 34 2 0
6 49 33 2 0
6 49 32 4 64
6 50 37 2 32
6 50 36 2 0
6 50 35 2 0
6 50 34 2 0
6 50 33 2 0
6 50 32 2 0
6 50 31 2 82
6 51 37 2 32
6 51 36 2 0
6 51 35 2 0
6 51 34 2 0
6 51 33 2 0
6 51 32 2 0
6 51 31 2 74
6 52 37 2 32
6 52 36 2 0
6 52 35 2 0
6 52 34 2 0
6 52 33 2 0
6 52 32 4 64
6 53 37 2 32
6 53 36 2 0
6 53 35 2 0
6 53 34 2 0
6 53 33 2 0
6 53 32 4 66
6 54 37 2 32
6 54 36 2 0
6 54 35 2 0
6 54 34 2 0
6 54 33 2 0
6 54 32 4 66
6 55 37 2 32
6 55 36 2 0
6 55 35 2 0
6 55 34 2 0
6 55 33 2 0
6 55 32 4 66
6 56 37 2 32
6 56 36 2 0
6 56 35 2 0
6 56 34 2 0
6 56 33 2 0
6 56 32 4 66
6 57 37 2 32
6 57 36 2 0
6 57 35 2 0
6 57 34 2 0
6 57 33 2 0
6 57 32 4 64
6 58 37 2 32
6 58 36 2 0
6 58 35 2 0
6 58 34 2 0
6 58 33 2 0
6 58 32 2 0
6 58 31 2 82
6 59 37 2 32
6 59 36 2 0
6 59 35 2 0
6 59 34 2 0
6 59 33 2 0
6 59 32 2 0
6 59 31 2 64
6 60 37 2 32
6 60 36 2 0
6 60 35 2 0
6 60 34 2 0
6 60 33 2 0
6 60 32 2 0
6 60 31 2 64
6 61 37 2 40
6 61 36 2 8
6 61 35 2 8
6 61 34 2 8
6 61 33 2 8
6 61 32 2 8
6 61 31 2 72
6 71 36 6 52
6 71 35 6 16
6 71 34 6 16
6 71 33 6 16
6 71 32 6 84
6 72 36 11 32
6 72 35 11 0
6 72 34 11 0
6 72 33 11 0
6 72 32 11 64
6 73 36 11 36
6 73 35 11 0
6 73 34 11 0
6 73 33 11 0
6 73 32 11 68
6 74 36 11 44
6 74 35 11 12
6 74 34 11 12
6 74 33 11 12
6 74 32 11 76
6 77 36 14 60
6 77 35 14 28
6 77 34 14 28
6 77 33 14 28
6 77 32 14 92
7 1 37 1 48
7 1 36 1 16
7 1 35 1 16
7 1 34 1 16
7 1 33 1 16
7 1 32 1 16
7 1 31 1 80
7 2 37 1 32
7 2 36 1 0
7 2 35 1 0
7 2 34 1 0
7 2 33 1 0
7 2 32 1 0
7 2 31 1 64
7 3 37 1 32
7 3 36 1 0
7 3 35 1 0
7 3 34 1 0
7 3 33 1 0
7 3 32 1 0
7 3 31 1 64
7 4 37 1 32
7 4 36 1 0
7 4 35 1 0
7 4 34 1 0
7 4 33 1 0
7 4 32 1 0
7 4 31 1 64
7 5 37 1 32
7 5 36 1 0
7 5 35 1 0
7 5 34 1 0
7 5 33 1 0
7 5 32 1 0
7 5 31 1 64
7 6 37 1 32
7 6 36 1 0
7 6 35 1 0
7 6 34 1 0
7 6 33 1 0
7 6 32 1 0
7 6 31 1 64
7 7 37 1 32
7 7 36 1 0
7 7 35 1 0
7 7 34 1 0
7 7 33 1 0
7 7 32 1 0
7 7 31 1 64
7 8 37 2 32
7 8 36 2 0
7 8 35 2 0
7 8 34 2 0
7 8 33 2 0
7 8 32 2 0
7 8 31 2 64
7 9 37 2 32
7 9 36 2 0
7 9 35 2 0
7 9 34 2 0
7 9 33 2 0
7 9 32 2 0
7 9 31 2 64
7 10 37 2 32
7 10 36 2 0
7 10 35 2 0
7 10 34 2 0
7 10 33 2 0
7 10 32 2 0
7 10 31 2 64
7 11 37 2 32
7 11 36 2 0
7 11 35 2 0
7 11 34 2 0
7 11 33 2 0
7 11 32 2 0
7 11 31 2 64
7 12 37 2 32
7 12 36 2 0
7 12 35 2 0
7 12 34 2 0
7 12 33 2 0
7 12 32 2 0
7 12 31 2 64
7 13 37 2 32
7 13 36 2 0
7 13 35 2 0
7 13 34 2 0
7 13 33 2 0
7 13 32 2 0
7 13 31 2 64
7 14 37 2 32
7 14 36 2 0
7 14 35 2 0
7 14 34 2 0
7 14 33 2 0
7 14 32 2 0
7 14 31 2 64
7 15 37 2 32
7 15 36 2 0
7 15 35 2 0
7 15 34 2 0
7 15 33 2 0
7 15 32 2 0
7 15 31 2 64
7 16 37 2 32
7 16 36 2 0
7 16 35 2 0
7 16 34 2 0
7 16 33 2 0
7 16 32 2 0
7 16 31 2 64
7 17 37 2 32
7 17 36 2 0
7 17 35 2 0
7 17 34 2 0
7 17 33 2 0
7 17 32 2 0
7 17 31 2 64
7 18 37 2 32
7 18 36 2 0
7 18 35 2 0
7 18 34 2 0
7 18 33 2 0
7 18 32 2 0
7 18 31 2 64
7 19 37 2 32
7 19 36 2 0
7 19 35 2 0
7 19 34 2 0
7 19 33 2 0
7 19 32 2 0
7 19 31 2 64
7 20 37 2 32
7 20 36 2 0
7 20 35 2 0
7 20 34 2 0
7 20 33 2 0
7 20 32 2 0
7 20 31 2 64
7 20 12 5 48
7 20 11 5 16
7 20 10 5 16
7 20 9 5 16
7 20 8 5 16
7 20 7 5 16
7 20 6 5 16
7 20 5 5 16
7 20 4 5 16
7 20 3 5 16
7 20 2 5 16
7 20 1 5 16
7 20 0 5 80
7 21 37 2 32
7 21 36 2 0
7 21 35 2 0
7 21 34 2 0
7 21 33 2 0
7 21 32 2 0
7 21 31 2 64
7 21 12 7 32
7 21 11 7 0
7 21 10 7 0
7 21 9 7 0
7 21 8 7 0
7 21 7 7 0
7 21 6 7 0
7 21 5 7 0
7 21 4 7 0
7 21 3 7 0
7 21 2 7 0
7 21 1 7 0
7 21 0 7 64
7 22 37 2 32
7 22 36 2 0
7 22 35 2 0
7 22 34 2 0
7 22 33 2 0
7 22 32 2 0
7 22 31 2 64
7 22 25 13 48
7 22 24 13 16
7 22 23 13 16
7 22 22 13 16
7 22 21 13 16
7 22 20 13 16
7 22 19 13 16
7 22 18 13 16
7 22 17 13 16
7 22 16 13 16
7 22 15 13 16
7 22 14 13 16
7 22 13 13 16
7 22 12 13 0
7 22 11 13 0
7 22 10 13 0
7 22 9 13 0
7 22 8 13 0
7 22 7 13 0
7 22 6 13 0
7 22 5 13 0
7 22 4 13 0
7 22 3 13 0
7 22 2 13 0
7 22 1 13 0
7 22 0 13 64
7 23 37 2 32
7 23 36 2 0
7 23 35 2 0
7 23 34 2 0
7 23 33 2 0
7 23 32 2 0
7 23 31 2 0
7 23 30 13 20
7 23 29 13 20
7 23 28 13 20
7 23 27 13 20
7 23 26 13 20
7 23 25 13 0
7 23 24 13 0
7 23 23 13 0
7 23 22 13 0
7 23 21 13 0
7 23 20 13 0
7 23 19 13 0
7 23 18 13 0
7 23 17 13 0
7 23 16 13 0
7 23 15 13 0
7 23 14 13 0
7 23 13 13 0
7 23 12 13 0
7 23 11 13 0
7 23 10 13 0
7 23 9 13 0
7 23 8 13 0
7 23 7 13 0
7 23 6 13 0
7 23 5 13 0
7 23 4 13 0
7 23 3 13 8
7 23 2 13 8
7 23 1 13 8
7 23 0 13 72
7 24 37 2 32
7 24 36 2 0
7 24 35 2 0
7 24 34 2 0
7 24 33 2 0
7 24 32 2 0
7 24 31 2 0
7 24 30 13 4
7 24 29 13 4
7 24 28 13 4
7 24 27 13 4
7 24 26 13 4
7 24 25 13 4
7 24 24 13 0
7 24 23 13 0
7 24 22 13 0
7 24 21 13 8
7 24 20 13 8
7 24 19 13 8
7 24 18 13 8
7 24 17 13 10
7 24 16 13 10
7 24 15 13 10
7 24 14 13 10
7 24 13 13 10
7 24 12 13 10
7 24 11 13 10
7 24 10 13 10
7 24 9 13 10
7 24 8 13 10
7 24 7 13 10
7 24 6 13 10
7 24 5 13 10
7 24 4 13 74
7 25 37 2 32
7 25 36 2 0
7 25 35 2 0
7 25 34 2 0
7 25 33 2 0
7 25 32 2 0
7 25 31 2 0
7 25 30 8 4
7 25 29 8 4
7 25 28 8 4
7 25 27 8 4
7 25 26 8 4
7 25 25 8 4
7 25 24 8 4
7 25 23 8 4
7 25 22 8 68
7 26 37 2 32
7 26 36 2 0
7 26 35 2 0
7 26 34 2 0
7 26 33 2 0
7 26 32 2 0
7 26 31 2 0
7 26 30 8 4
7 26 29 8 4
7 26 28 8 4
7 26 27 8 4
7 26 26 8 4
7 26 25 8 4
7 26 24 8 4
7 26 23 8 12
7 26 22 8 76
7 27 37 2 32
7 27 36 2 0
7 27 35 2 0
7 27 34 2 0
7 27 33 2 0
7 27 32 2 0
7 27 31 2 0
7 27 30 8 4
7 27 29 8 4
7 27 28 8 4
7 27 27 8 4
7 27 26 8 4
7 27 25 8 4
7 27 24 8 68
7 28 37 2 32
7 28 36 2 0
7 28 35 2 0
7 28 34 2 0
7 28 33 2 0
7 28 32 2 0
7 28 31 2 0
7 28 30 8 12
7 28 29 8 12
7 28 28 8 12
7 28 27 8 12
7 28 26 8 12
7 28 25 8 12
7 28 24 8 76
7 29 37 2 32
7 29 36 2 0
7 29 35 2 0
7 29 34 2 0
7 29 33 2 0
7 29 32 2 0
7 29 31 2 64
7 30 37 2 32
7 30 36 2 0
7 30 35 2 0
7 30 34 2 0
7 30 33 2 0
7 30 32 2 0
7 30 31 2 64
7 31 37 2 32
7 31 36 2 0
7 31 35 2 0
7 31 34 2 0
7 31 33 2 0
7 31 32 2 0
7 31 31 2 64
7 32 37 2 32
7 32 36 2 0
7 32 35 2 0
7 32 34 2 0
7 32 33 2 0
7 32 32 2 0
7 32 31 2 64
7 33 37 2 32
7 33 36 2 0
7 33 35 2 0
7 33 34 2 0
7 33 33 2 0
7 33 32 2 0
7 33 31 2 64
7 34 37 2 32
7 34 36 2 0
7 34 35 2 0
7 34 34 2 0
7 34 33 2 0
7 34 32 2 0
7 34 31 2 64
7 35 37 2 32
7 35 36 2 0
7 35 35 2 0
7 35 34 2 0
7 35 33 2 0
7 35 32 2 0
7 35 31 2 64
7 36 37 2 32
7 36 36 2 0
7 36 35 2 0
7 36 34 2 0
7 36 33 2 0
7 36 32 2 0
7 36 31 2 64
7 37 37 2 32
7 37 36 2 0
7 37 35 2 0
7 37 34 2 0
7 37 33 2 0
7 37 32 2 0
7 37 31 2 64
7 38 37 2 32
7 38 36 2 0
7 38 35 2 0
7 38 34 2 0
7 38 33 2 0
7 38 32 2 0
7 38 31 2 64
7 39 37 2 32
7 39 36 2 0
7 39 35 2 0
7 39 34 2 0
7 39 33 2 0
7 39 32 2 0
7 39 31 2 64
7 40 37 2 32
7 40 36 2 0
7 40 35 2 0
7 40 34 2 0
7 40 33 2 0
7 40 32 2 0
7 40 31 2 64
7 41 37 2 32
7 41 36 2 0
7 41 35 2 0
7 41 34 2 0
7 41 33 2 0
7 41 32 2 0
7 41 31 2 64
7 42 37 2 32
7 42 36 2 0
7 42 35 2 0
7 42 34 2 0
7 42 33 2 0
7 42 32 2 0
7 42 31 2 72
7 43 37 2 32
7 43 36 2 0
7 43 35 2 0
7 43 34 2 0
7 43 33 2 0
7 43 32 4 64
7 44 37 2 32
7 44 36 2 0
7 44 35 2 0
7 44 34 2 0
7 44 33 2 0
7 44 32 2 0
7 44 31 2 88
7 45 37 2 32
7 45 36 2 0
7 45 35 2 0
7 45 34 2 0
7 45 33 2 0
7 45 32 4 72
7 46 37 2 32
7 46 36 2 0
7 46 35 2 0
7 46 34 2 0
7 46 33 2 64
7 47 37 2 32
7 47 36 2 0
7 47 35 2 0
7 47 34 2 0
7 47 33 2 64
7 48 37 2 32
7 48 36 2 0
7 48 35 2 0
7 48 34 2 0
7 48 33 2 64
7 49 37 2 32
7 49 36 2 0
7 49 35 2 0
7 49 34 2 0
7 49 33 2 0
7 49 32 4 80
7 50 37 2 32
7 50 36 2 0
7 50 35 2 0
7 50 34 2 0
7 50 33 2 0
7 50 32 4 66
7 51 37 2 32
7 51 36 2 0
7 51 35 2 0
7 51 34 2 0
7 51 33 2 0
7 51 32 4 64
7 52 37 2 32
7 52 36 2 0
7 52 35 2 0
7 52 34 2 0
7 52 33 2 0
7 52 32 4 72
7 53 37 2 32
7 53 36 2 0
7 53 35 2 0
7 53 34 2 0
7 53 33 2 64
7 54 37 2 32
7 54 36 2 0
7 54 35 2 0
7 54 34 2 0
7 54 33 2 64
7 55 37 2 32
7 55 36 2 0
7 55 35 2 0
7 55 34 2 0
7 55 33 2 64
7 56 37 2 32
7 56 36 2 0
7 56 35 2 0
7 56 34 2 0
7 56 33 2 64
7 57 37 2 32
7 57 36 2 0
7 57 35 2 0
7 57 34 2 0
7 57 33 2 0
7 57 32 4 82
7 58 37 2 32
7 58 36 2 0
7 58 35 2 0
7 58 34 2 0
7 58 33 2 0
7 58 32 4 64
7 59 37 2 32
7 59 36 2 0
7 59 35 2 0
7 59 34 2 0
7 59 33 2 0
7 59 32 2 0
7 59 31 2 82
7 60 37 2 32
7 60 36 2 0
7 60 35 2 0
7 60 34 2 0
7 60 33 2 0
7 60 32 2 0
7 60 31 2 64
7 61 37 2 40
7 61 36 2 8
7 61 35 2 0
7 61 34 2 0
7 61 33 2 0
7 61 32 2 8
7 61 31 2 72
7 62 35 9 36
7 62 34 9 4
7 62 33 9 68
7 63 35 11 44
7 63 34 11 12
7 63 33 11 76
7 70 35 6 52
7 70 34 6 20
7 70 33 6 84
7 71 36 9 48
7 71 35 11 0
7 71 34 11 0
7 71 33 11 0
7 71 32 9 80
7 72 36 11 32
7 72 35 11 0
7 72 34 11 0
7 72 33 11 0
7 72 32 11 64
7 73 36 11 32
7 73 35 11 0
7 73 34 11 0
7 73 33 11 0
7 73 32 11 64
7 74 36 11 40
7 74 35 11 0
7 74 34 11 0
7 74 33 11 0
7 74 32 11 72
7 75 35 9 44
7 75 34 9 12
7 75 33 9 76
7 77 36 14 56
7 77 35 11 16
7 77 34 11 16
7 77 33 11 16
7 77 32 14 88
7 78 35 19 36
7 78 34 19 4
7 78 33 19 68
7 79 35 19 44
7 79 34 19 12
7 79 33 19 76
8 1 37 1 48
8 1 36 1 16
8 1 35 1 16
8 1 34 1 16
8 1 33 1 16
8 1 32 1 16
8 1 31 1 80
8 2 37 1 32
8 2 36 1 0
8 2 35 1 0
8 2 34 1 0
8 2 33 1 0
8 2 32 1 0
8 2 31 1 64
8 3 37 1 32
8 3 36 1 0
8 3 35 1 0
8 3 34 1 0
8 3 33 1 0
8 3 32 1 0
8 3 31 1 64
8 4 37 1 32
8 4 36 1 0
8 4 35 1 0
8 4 34 1 0
8 4 33 1 0
8 4 32 1 0
8 4 31 1 64
8 5 37 1 32
8 5 36 1 0
8 5 35 1 0
8 5 34 1 0
8 5 33 1 0
8 5 32 1 0
8 5 31 1 64
8 6 37 1 32
8 6 36 1 0
8 6 35 1 0
8 6 34 1 0
8 6 33 1 0
8 6 32 1 0
8 6 31 1 64
8 7 37 1 32
8 7 36 1 0
8 7 35 1 0
8 7 34 1 0
8 7 33 1 0
8 7 32 1 0
8 7 31 1 64
8 8 37 2 32
8 8 36 2 0
8 8 35 2 0
8 8 34 2 0
8 8 33 2 0
8 8 32 2 0
8 8 31 2 64
8 9 37 2 32
8 9 36 2 0
8 9 35 2 0
8 9 34 2 0
8 9 33 2 0
8 9 32 2 0
8 9 31 2 64
8 10 37 2 32
8 10 36 2 0
8 10 35 2 0
8 10 34 2 0
8 10 33 2 0
8 10 32 2 0
8 10 31 2 64
8 11 37 2 32
8 11 36 2 0
8 11 35 2 0
8 11 34 2 0
8 11 33 2 0
8 11 32 2 0
8 11 31 2 64
8 12 37 2 32
8 12 36 2 0
8 12 35 2 0
8 12 34 2 0
8 12 33 2 0
8 12 32 2 0
8 12 31 2 64
8 13 37 2 32
8 13 36 2 0
8 13 35 2 0
8 13 34 2 0
8 13 33 2 0
8 13 32 2 0
8 13 31 2 64
8 14 37 2 32
8 14 36 2 0
8 14 35 2 0
8 14 34 2 0
8 14 33 2 0
8 14 32 2 0
8 14 31 2 64
8 15 37 2 32
8 15 36 2 0
8 15 35 2 0
8 15 34 2 0
8 15 33 2 0
8 15 32 2 0
8 15 31 2 64
8 16 37 2 32
8 16 36 2 0
8 16 35 2 0
8 16 34 2 0
8 16 33 2 0
8 16 32 2 0
8 16 31 2 64
8 17 37 2 32
8 17 36 2 0
8 17 35 2 0
8 17 34 2 0
8 17 33 2 0
8 17 32 2 0
8 17 31 2 64
8 18 37 2 32
8 18 36 2 0
8 18 35 2 0
8 18 34 2 0
8 18 33 2 0
8 18 32 2 0
8 18 31 2 64
8 19 37 2 32
8 19 36 2 0
8 19 35 2 0
8 19 34 2 0
8 19 33 2 0
8 19 32 2 0
8 19 31 2 64
8 20 37 2 32
8 20 36 2 0
8 20 35 2 0
8 20 34 2 0
8 20 33 2 0
8 20 32 2 0
8 20 31 2 64
8 20 12 5 48
8 20 11 5 16
8 20 10 5 16
8 20 9 5 16
8 20 8 5 16
8 20 7 5 16
8 20 6 5 16
8 20 5 5 16
8 20 4 5 16
8 20 3 5 16
8 20 2 5 16
8 20 1 5 16
8 20 0 5 80
8 21 37 2 32
8 21 36 2 0
8 21 35 2 0
8 21 34 2 0
8 21 33 2 0
8 21 32 2 0
8 21 31 2 64
8 21 12 7 32
8 21 11 7 0
8 21 10 7 0
8 21 9 7 0
8 21 8 7 0
8 21 7 7 0
8 21 6 7 0
8 21 5 7 0
8 21 4 7 0
8 21 3 7 0
8 21 2 7 0
8 21 1 7 0
8 21 0 7 64
8 22 37 2 32
8 22 36 2 0
8 22 35 2 0
8 22 34 2 0
8 22 33 2 0
8 22 32 2 0
8 22 31 2 64
8 22 25 13 48
8 22 24 13 16
8 22 23 13 16
8 22 22 13 16
8 22 21 13 16
8 22 20 13 16
8 22 19 13 16
8 22 18 13 16
8 22 17 13 16
8 22 16 13 16
8 22 15 13 16
8 22 14 13 16
8 22 13 13 16
8 22 12 13 0
8 22 11 13 0
8 22 10 13 0
8 22 9 13 0
8 22 8 13 0
8 22 7 13 0
8 22 6 13 0
8 22 5 13 0
8 22 4 13 0
8 22 3 13 0
8 22 2 13 0
8 22 1 13 0
8 22 0 13 66
8 23 37 2 32
8 23 36 2 0
8 23 35 2 0
8 23 34 2 0
8 23 33 2 0
8 23 32 2 0
8 23 31 2 0
8 23 30 13 16
8 23 29 13 16
8 23 28 13 16
8 23 27 13 16
8 23 26 13 16
8 23 25 13 0
8 23 24 13 0
8 23 23 13 0
8 23 22 13 0
8 23 21 13 0
8 23 20 13 0
8 23 19 13 0
8 23 18 13 0
8 23 17 13 8
8 23 16 13 8
8 23 15 13 8
8 23 14 13 8
8 23 13 13 8
8 23 12 13 10
8 23 11 13 8
8 23 10 13 10
8 23 9 13 8
8 23 8 13 10
8 23 7 13 8
8 23 6 13 10
8 23 5 13 10
8 23 4 13 8
8 23 3 13 10
8 23 2 13 8
8 23 1 13 10
8 23 0 13 74
8 24 37 2 32
8 24 36 2 0
8 24 35 2 0
8 24 34 2 0
8 24 33 2 0
8 24 32 2 0
8 24 31 2 0
8 24 30 13 0
8 24 29 13 0
8 24 28 13 0
8 24 27 13 0
8 24 26 13 0
8 24 25 13 0
8 24 24 13 0
8 24 23 13 0
8 24 22 13 0
8 24 21 13 8
8 24 20 13 8
8 24 19 13 8
8 24 18 13 72
8 25 37 2 32
8 25 36 2 0
8 25 35 2 0
8 25 34 2 0
8 25 33 2 0
8 25 32 2 0
8 25 31 2 0
8 25 30 8 0
8 25 29 8 0
8 25 28 8 0
8 25 27 8 0
8 25 26 8 0
8 25 25 8 0
8 25 24 8 0
8 25 23 8 0
8 25 22 8 64
8 26 37 2 32
8 26 36 2 0
8 26 35 2 0
8 26 34 2 0
8 26 33 2 0
8 26 32 2 0
8 26 31 2 0
8 26 30 8 0
8 26 29 8 0
8 26 28 8 0
8 26 27 8 0
8 26 26 8 0
8 26 25 8 0
8 26 24 8 0
8 26 23 8 0
8 26 22 8 0
8 26 21 8 84
8 27 37 2 32
8 27 36 2 0
8 27 35 2 0
8 27 34 2 0
8 27 33 2 0
8 27 32 2 0
8 27 31 2 0
8 27 30 8 0
8 27 29 8 0
8 27 28 8 0
8 27 27 8 0
8 27 26 8 0
8 27 25 8 0
8 27 24 8 0
8 27 23 8 4
8 27 22 8 4
8 27 21 8 4
8 27 20 8 20
8 27 19 8 20
8 27 18 8 92
8 28 37 2 32
8 28 36 2 0
8 28 35 2 0
8 28 34 2 0
8 28 33 2 0
8 28 32 2 0
8 28 31 2 0
8 28 30 8 0
8 28 29 8 0
8 28 28 8 0
8 28 27 8 0
8 28 26 8 0
8 28 25 8 0
8 28 24 8 2
8 28 23 11 12
8 28 22 11 12
8 28 21 11 12
8 28 20 11 12
8 28 19 11 76
8 29 37 2 32
8 29 36 2 0
8 29 35 2 0
8 29 34 2 0
8 29 33 2 0
8 29 32 2 0
8 29 31 2 0
8 29 30 8 4
8 29 29 8 4
8 29 28 8 4
8 29 27 8 4
8 29 26 8 4
8 29 25 8 4
8 29 24 8 70
8 30 37 2 32
8 30 36 2 0
8 30 35 2 0
8 30 34 2 0
8 30 33 2 0
8 30 32 2 0
8 30 31 2 0
8 30 30 8 4
8 30 29 8 4
8 30 28 8 4
8 30 27 8 4
8 30 26 8 4
8 30 25 8 4
8 30 24 8 70
8 31 37 2 32
8 31 36 2 0
8 31 35 2 0
8 31 34 2 0
8 31 33 2 0
8 31 32 2 0
8 31 31 2 0
8 31 30 8 4
8 31 29 8 4
8 31 28 8 4
8 31 27 8 4
8 31 26 8 4
8 31 25 8 4
8 31 24 8 70
8 32 37 2 32
8 32 36 2 0
8 32 35 2 0
8 32 34 2 0
8 32 33 2 0
8 32 32 2 0
8 32 31 2 0
8 32 30 8 4
8 32 29 8 4
8 32 28 8 4
8 32 27 8 4
8 32 26 8 4
8 32 25 8 4
8 32 24 8 70
8 33 37 2 32
8 33 36 2 0
8 33 35 2 0
8 33 34 2 0
8 33 33 2 0
8 33 32 2 0
8 33 31 2 0
8 33 30 8 12
8 33 29 8 12
8 33 28 8 12
8 33 27 8 12
8 33 26 8 12
8 33 25 8 12
8 33 24 8 76
8 34 37 2 32
8 34 36 2 0
8 34 35 2 0
8 34 34 2 0
8 34 33 2 0
8 34 32 2 0
8 34 31 2 64
8 35 37 2 32
8 35 36 2 0
8 35 35 2 0
8 35 34 2 0
8 35 33 2 0
8 35 32 2 0
8 35 31 2 64
8 36 37 2 32
8 36 36 2 0
8 36 35 2 0
8 36 34 2 0
8 36 33 2 0
8 36 32 2 0
8 36 31 2 64
8 37 37 2 32
8 37 36 2 0
8 37 35 2 0
8 37 34 2 0
8 37 33 2 0
8 37 32 2 0
8 37 31 2 64
8 38 37 2 32
8 38 36 2 0
8 38 35 2 0
8 38 34 2 0
8 38 33 2 0
8 38 32 2 0
8 38 31 2 64
8 39 37 2 32
8 39 36 2 0
8 39 35 2 0
8 39 34 2 0
8 39 33 2 0
8 39 32 2 0
8 39 31 2 64
8 40 37 2 32
8 40 36 2 0
8 40 35 2 0
8 40 34 2 0
8 40 33 2 0
8 40 32 2 0
8 40 31 2 64
8 41 37 2 32
8 41 36 2 0
8 41 35 2 0
8 41 34 2 0
8 41 33 2 0
8 41 32 2 0
8 41 31 2 64
8 42 37 2 32
8 42 36 2 0
8 42 35 2 0
8 42 34 2 0
8 42 33 2 0
8 42 32 2 0
8 42 31 2 72
8 43 37 2 32
8 43 36 2 0
8 43 35 2 0
8 43 34 2 0
8 43 33 2 0
8 43 32 4 64
8 44 37 2 32
8 44 36 2 0
8 44 35 2 0
8 44 34 2 0
8 44 33 2 0
8 44 32 2 0
8 44 31 2 88
8 45 37 2 32
8 45 36 2 0
8 45 35 2 0
8 45 34 2 0
8 45 33 2 0
8 45 32 4 72
8 46 37 2 32
8 46 36 2 0
8 46 35 2 0
8 46 34 2 0
8 46 33 2 64
8 47 37 2 32
8 47 36 2 0
8 47 35 2 0
8 47 34 2 0
8 47 33 2 0
8 47 32 2 94
8 48 37 2 32
8 48 36 2 0
8 48 35 2 0
8 48 34 2 0
8 48 33 2 64
8 49 37 2 32
8 49 36 2 0
8 49 35 2 0
8 49 34 2 0
8 49 33 2 0
8 49 32 4 88
8 50 37 2 32
8 50 36 2 0
8 50 35 2 0
8 50 34 2 0
8 50 33 2 64
8 51 37 2 32
8 51 36 2 0
8 51 35 2 0
8 51 34 2 0
8 51 33 2 0
8 51 32 4 80
8 52 37 2 32
8 52 36 2 0
8 52 35 2 0
8 52 34 2 0
8 52 33 2 0
8 52 32 4 72
8 53 37 2 32
8 53 36 2 0
8 53 35 2 0
8 53 34 2 0
8 53 33 2 64
8 54 37 2 32
8 54 36 2 0
8 54 35 2 0
8 54 34 2 0
8 54 33 2 0
8 54 32 2 22
8 54 31 2 86
8 55 37 2 32
8 55 36 2 0
8 55 35 2 0
8 55 34 2 0
8 55 33 2 0
8 55 32 2 14
8 55 31 2 78
8 56 37 2 32
8 56 36 2 0
8 56 35 2 0
8 56 34 2 0
8 56 33 2 64
8 57 37 2 32
8 57 36 2 0
8 57 35 2 0
8 57 34 2 0
8 57 33 2 64
8 58 37 2 32
8 58 36 2 0
8 58 35 2 0
8 58 34 2 0
8 58 33 2 0
8 58 32 4 80
8 59 37 2 32
8 59 36 2 0
8 59 35 2 0
8 59 34 2 0
8 59 33 2 0
8 59 32 4 64
8 60 37 2 32
8 60 36 2 0
8 60 35 2 0
8 60 34 2 0
8 60 33 2 0
8 60 32 2 0
8 60 31 2 80
8 61 37 2 40
8 61 36 2 8
8 61 35 2 0
8 61 34 2 0
8 61 33 2 0
8 61 32 2 8
8 61 31 2 72
8 62 35 9 32
8 62 34 11 0
8 62 33 9 64
8 63 35 11 40
8 63 34 11 0
8 63 33 11 72
8 64 34 11 102
8 65 34 11 102
8 66 34 11 102
8 67 34 9 102
8 68 34 9 102
8 69 35 6 54
8 69 34 6 6
8 69 33 6 86
8 70 36 6 54
8 70 35 11 0
8 70 34 11 0
8 70 33 11 0
8 70 32 6 86
8 71 36 11 32
8 71 35 11 0
8 71 34 11 0
8 71 33 11 0
8 71 32 9 64
8 72 36 11 32
8 72 35 11 0
8 72 34 11 0
8 72 33 11 0
8 72 32 11 64
8 73 36 11 32
8 73 35 11 0
8 73 34 11 0
8 73 33 11 0
8 73 32 11 64
8 74 36 11 40
8 74 35 11 0
8 74 34 11 0
8 74 33 11 0
8 74 32 11 72
8 75 35 9 40
8 75 34 11 0
8 75 33 9 72
8 76 34 11 102
8 77 36 14 56
8 77 35 11 16
8 77 34 19 0
8 77 33 11 16
8 77 32 14 88
8 78 35 19 32
8 78 34 19 0
8 78 33 19 64
8 79 35 19 40
8 79 34 19 8
8 79 33 19 72
8 81 34 18 118
8 82 34 18 110
9 1 37 1 48
9 1 36 1 16
9 1 35 1 16
9 1 34 1 16
9 1 33 1 16
9 1 32 1 16
9 1 31 1 16
9 1 30 1 20
9 1 29 1 20
9 1 28 1 20
9 1 27 1 20
9 1 26 1 20
9 1 25 1 20
9 1 24 1 20
9 1 23 1 20
9 1 22 1 20
9 1 21 1 20
9 1 20 1 84
9 2 37 1 32
9 2 36 1 0
9 2 35 1 0
9 2 34 1 0
9 2 33 1 0
9 2 32 1 0
9 2 31 1 0
9 2 30 1 4
9 2 29 1 4
9 2 28 1 4
9 2 27 1 4
9 2 26 1 4
9 2 25 1 4
9 2 24 1 4
9 2 23 1 4
9 2 22 1 4
9 2 21 1 4
9 2 20 1 68
9 3 37 1 32
9 3 36 1 0
9 3 35 1 0
9 3 34 1 0
9 3 33 1 0
9 3 32 1 0
9 3 31 1 0
9 3 30 1 4
9 3 29 1 4
9 3 28 1 4
9 3 27 1 4
9 3 26 1 4
9 3 25 1 4
9 3 24 1 4
9 3 23 1 4
9 3 22 1 4
9 3 21 1 4
9 3 20 1 68
9 4 37 1 32
9 4 36 1 0
9 4 35 1 0
9 4 34 1 0
9 4 33 1 0
9 4 32 1 0
9 4 31 1 0
9 4 30 1 4
9 4 29 1 4
9 4 28 1 4
9 4 27 1 4
9 4 26 1 4
9 4 25 1 4
9 4 24 1 4
9 4 23 1 4
9 4 22 1 4
9 4 21 1 4
9 4 20 1 68
9 5 37 1 32
9 5 36 1 0
9 5 35 1 0
9 5 34 1 0
9 5 33 1 0
9 5 32 1 0
9 5 31 1 0
9 5 30 1 4
9 5 29 1 4
9 5 28 1 4
9 5 27 1 4
9 5 26 1 4
9 5 25 1 4
9 5 24 1 4
9 5 23 1 4
9 5 22 1 4
9 5 21 1 4
9 5 20 1 68
9 6 37 1 32
9 6 36 1 0
9 6 35 1 0
9 6 34 1 0
9 6 33 1 0
9 6 32 1 0
9 6 31 1 0
9 6 30 1 4
9 6 29 1 4
9 6 28 1 4
9 6 27 1 4
9 6 26 1 4
9 6 25 1 4
9 6 24 1 4
9 6 23 1 4
9 6 22 1 4
9 6 21 1 4
9 6 20 1 68
9 7 37 1 32
9 7 36 1 0
9 7 35 1 0
9 7 34 1 0
9 7 33 1 0
9 7 32 1 0
9 7 31 1 0
9 7 30 1 4
9 7 29 1 4
9 7 28 1 4
9 7 27 1 4
9 7 26 1 4
9 7 25 1 4
9 7 24 1 4
9 7 23 1 4
9 7 22 1 4
9 7 21 1 4
9 7 20 1 68
9 8 37 2 32
9 8 36 2 0
9 8 35 2 0
9 8 34 2 0
9 8 33 2 0
9 8 32 2 0
9 8 31 2 0
9 8 30 1 4
9 8 29 1 4
9 8 28 1 4
9 8 27 1 4
9 8 26 1 4
9 8 25 1 4
9 8 24 1 4
9 8 23 1 4
9 8 22 1 4
9 8 21 1 4
9 8 20 1 68
9 9 37 2 32
9 9 36 2 0
9 9 35 2 0
9 9 34 2 0
9 9 33 2 0
9 9 32 2 0
9 9 31 2 0
9 9 30 1 4
9 9 29 1 4
9 9 28 1 4
9 9 27 1 4
9 9 26 1 4
9 9 25 1 4
9 9 24 1 4
9 9 23 1 4
9 9 22 1 4
9 9 21 1 4
9 9 20 1 68
9 10 37 2 32
9 10 36 2 0
9 10 35 2 0
9 10 34 2 0
9 10 33 2 0
9 10 32 2 0
9 10 31 2 0
9 10 30 1 4
9 10 29 1 4
9 10 28 1 4
9 10 27 1 4
9 10 26 1 4
9 10 25 1 4
9 10 24 1 4
9 10 23 1 4
9 10 22 1 4
9 10 21 1 4
9 10 20 1 68
9 11 37 2 32
9 11 36 2 0
9 11 35 2 0
9 11 34 2 0
9 11 33 2 0
9 11 32 2 0
9 11 31 2 0
9 11 30 1 4
9 11 29 1 4
9 11 28 1 4
9 11 27 1 4
9 11 26 1 4
9 11 25 1 4
9 11 24 1 4
9 11 23 1 4
9 11 22 1 4
9 11 21 1 4
9 11 20 1 68
9 12 37 2 32
9 12 36 2 0
9 12 35 2 0
9 12 34 2 0
9 12 33 2 0
9 12 32 2 0
9 12 31 2 0
9 12 30 1 4
9 12 29 1 4
9 12 28 1 4
9 12 27 1 4
9 12 26 1 4
9 12 25 1 4
9 12 24 1 4
9 12 23 1 4
9 12 22 1 4
9 12 21 1 4
9 12 20 1 68
9 13 37 2 32
9 13 36 2 0
9 13 35 2 0
9 13 34 2 0
9 13 33 2 0
9 13 32 2 0
9 13 31 2 0
9 13 30 1 4
9 13 29 1 4
9 13 28 1 4
9 13 27 1 4
9 13 26 1 4
9 13 25 1 4
9 13 24 1 4
9 13 23 1 4
9 13 22 1 4
9 13 21 1 4
9 13 20 1 68
9 14 37 2 32
9 14 36 2 0
9 14 35 2 0
9 14 34 2 0
9 14 33 2 0
9 14 32 2 0
9 14 31 2 0
9 14 30 2 4
9 14 29 2 4
9 14 28 2 4
9 14 27 2 4
9 14 26 2 4
9 14 25 2 4
9 14 24 2 4
9 14 23 2 4
9 14 22 2 4
9 14 21 2 4
9 14 20 2 68
9 15 37 2 32
9 15 36 2 0
9 15 35 2 0
9 15 34 2 0
9 15 33 2 0
9 15 32 2 0
9 15 31 2 0
9 15 30 2 4
9 15 29 2 4
9 15 28 2 4
9 15 27 2 4
9 15 26 2 4
9 15 25 2 4
9 15 24 2 4
9 15 23 2 4
9 15 22 2 4
9 15 21 2 4
9 15 20 2 68
9 16 37 2 32
9 16 36 2 0
9 16 35 2 0
9 16 34 2 0
9 16 33 2 0
9 16 32 2 0
9 16 31 2 0
9 16 30 2 4
9 16 29 2 4
9 16 28 2 4
9 16 27 2 4
9 16 26 2 4
9 16 25 2 4
9 16 24 2 4
9 16 23 2 4
9 16 22 2 4
9 16 21 2 4
9 16 20 2 68
9 17 37 2 32
9 17 36 2 0
9 17 35 2 0
9 17 34 2 0
9 17 33 2 0
9 17 32 2 0
9 17 31 2 0
9 17 30 2 4
9 17 29 2 4
9 17 28 2 4
9 17 27 2 4
9 17 26 2 4
9 17 25 2 4
9 17 24 2 4
9 17 23 2 4
9 17 22 2 4
9 17 21 2 4
9 17 20 2 68
9 18 37 2 32
9 18 36 2 0
9 18 35 2 0
9 18 34 2 0
9 18 33 2 0
9 18 32 2 0
9 18 31 2 0
9 18 30 2 4
9 18 29 2 4
9 18 28 2 4
9 18 27 2 4
9 18 26 2 4
9 18 25 2 4
9 18 24 2 4
9 18 23 2 4
9 18 22 2 4
9 18 21 2 4
9 18 20 2 68
9 19 37 2 32
9 19 36 2 0
9 19 35 2 0
9 19 34 2 0
9 19 33 2 0
9 19 32 2 0
9 19 31 2 0
9 19 30 2 4
9 19 29 2 4
9 19 28 2 4
9 19 27 2 4
9 19 26 2 4
9 19 25 2 4
9 19 24 2 4
9 19 23 2 4
9 19 22 2 4
9 19 21 2 4
9 19 20 2 68
9 20 37 2 32
9 20 36 2 0
9 20 35 2 0
9 20 34 2 0
9 20 33 2 0
9 20 32 2 0
9 20 31 2 0
9 20 30 2 4
9 20 29 2 4
9 20 28 2 4
9 20 27 2 4
9 20 26 2 4
9 20 25 2 4
9 20 24 2 4
9 20 23 2 4
9 20 22 2 4
9 20 21 2 4
9 20 20 2 68
9 20 12 5 48
9 20 11 5 16
9 20 10 5 16
9 20 9 5 16
9 20 8 5 16
9 20 7 5 16
9 20 6 5 16
9 20 5 5 16
9 20 4 5 16
9 20 3 5 16
9 20 2 5 16
9 20 1 5 16
9 20 0 5 80
9 21 37 2 32
9 21 36 2 0
9 21 35 2 0
9 21 34 2 0
9 21 33 2 0
9 21 32 2 0
9 21 31 2 0
9 21 30 2 4
9 21 29 2 4
9 21 28 2 4
9 21 27 2 4
9 21 26 2 4
9 21 25 2 4
9 21 24 2 4
9 21 23 2 4
9 21 22 2 4
9 21 21 2 4
9 21 20 2 68
9 21 12 7 32
9 21 11 7 0
9 21 10 7 0
9 21 9 7 0
9 21 8 7 0
9 21 7 7 0
9 21 6 7 0
9 21 5 7 0
9 21 4 7 0
9 21 3 7 0
9 21 2 7 0
9 21 1 7 0
9 21 0 7 72
9 22 37 2 32
9 22 36 2 0
9 22 35 2 0
9 22 34 2 0
9 22 33 2 0
9 22 32 2 0
9 22 31 2 0
9 22 30 2 4
9 22 29 2 4
9 22 28 2 4
9 22 27 2 4
9 22 26 2 4
9 22 25 13 0
9 22 24 13 0
9 22 23 13 0
9 22 22 13 0
9 22 21 13 0
9 22 20 13 0
9 22 19 13 16
9 22 18 13 16
9 22 17 13 16
9 22 16 13 16
9 22 15 13 16
9 22 14 13 16
9 22 13 13 16
9 22 12 17 8
9 22 11 17 0
9 22 10 17 8
9 22 9 17 0
9 22 8 17 8
9 22 7 17 0
9 22 6 17 8
9 22 5 17 8
9 22 4 17 0
9 22 3 17 8
9 22 2 17 0
9 22 1 17 72
9 23 37 2 32
9 23 36 2 0
9 23 35 2 0
9 23 34 2 0
9 23 33 2 0
9 23 32 2 0
9 23 31 2 0
9 23 30 13 0
9 23 29 13 0
9 23 28 13 0
9 23 27 13 0
9 23 26 13 0
9 23 25 13 0
9 23 24 13 0
9 23 23 13 0
9 23 22 13 0
9 23 21 13 0
9 23 20 13 0
9 23 19 13 0
9 23 18 13 0
9 23 17 13 8
9 23 16 13 8
9 23 15 13 8
9 23 14 13 8
9 23 13 13 72
9 23 11 2 104
9 23 9 2 104
9 23 7 2 104
9 23 4 2 104
9 23 2 2 104
9 24 37 2 32
9 24 36 2 0
9 24 35 2 0
9 24 34 2 0
9 24 33 2 0
9 24 32 2 0
9 24 31 2 0
9 24 30 13 0
9 24 29 13 0
9 24 28 13 0
9 24 27 13 0
9 24 26 13 0
9 24 25 13 0
9 24 24 13 0
9 24 23 13 0
9 24 22 13 0
9 24 21 13 8
9 24 20 13 8
9 24 19 13 8
9 24 18 13 72
9 25 37 2 32
9 25 36 2 0
9 25 35 2 0
9 25 34 2 0
9 25 33 2 0
9 25 32 2 0
9 25 31 2 0
9 25 30 8 0
9 25 29 8 0
9 25 28 8 0
9 25 27 8 0
9 25 26 8 0
9 25 25 8 0
9 25 24 8 0
9 25 23 8 0
9 25 22 8 64
9 26 37 2 32
9 26 36 2 0
9 26 35 2 0
9 26 34 2 0
9 26 33 2 0
9 26 32 2 0
9 26 31 2 0
9 26 30 8 0
9 26 29 8 0
9 26 28 8 0
9 26 27 8 0
9 26 26 8 0
9 26 25 8 0
9 26 24 8 0
9 26 23 8 0
9 26 22 8 0
9 26 21 8 16
9 26 20 8 84
9 27 37 2 32
9 27 36 2 0
9 27 35 2 0
9 27 34 2 0
9 27 33 2 0
9 27 32 2 0
9 27 31 2 0
9 27 30 8 0
9 27 29 8 0
9 27 28 8 0
9 27 27 8 0
9 27 26 8 0
9 27 25 8 0
9 27 24 8 8
9 27 23 8 0
9 27 22 8 0
9 27 21 8 0
9 27 20 8 0
9 27 19 8 16
9 27 18 8 24
9 27 17 8 92
9 28 37 2 32
9 28 36 2 0
9 28 35 2 0
9 28 34 2 0
9 28 33 2 0
9 28 32 2 0
9 28 31 2 0
9 28 30 8 0
9 28 29 8 0
9 28 28 8 0
9 28 27 8 0
9 28 26 8 0
9 28 25 15 64
9 28 23 11 40
9 28 22 9 8
9 28 21 9 8
9 28 20 9 8
9 28 19 11 72
9 29 37 2 32
9 29 36 2 0
9 29 35 2 0
9 29 34 2 0
9 29 33 2 0
9 29 32 2 0
9 29 31 2 0
9 29 30 8 0
9 29 29 8 0
9 29 28 8 0
9 29 27 8 0
9 29 26 8 0
9 29 25 15 64
9 30 37 2 32
9 30 36 2 0
9 30 35 2 0
9 30 34 2 0
9 30 33 2 0
9 30 32 2 0
9 30 31 2 0
9 30 30 8 0
9 30 29 8 0
9 30 28 8 0
9 30 27 8 0
9 30 26 8 0
9 30 25 15 64
9 30 22 11 52
9 30 21 11 20
9 30 20 11 84
9 31 37 2 32
9 31 36 2 0
9 31 35 2 0
9 31 34 2 0
9 31 33 2 0
9 31 32 2 0
9 31 31 2 0
9 31 30 8 0
9 31 29 8 0
9 31 28 8 0
9 31 27 8 0
9 31 26 8 0
9 31 25 15 64
9 31 22 19 36
9 31 21 19 4
9 31 20 19 68
9 32 37 2 32
9 32 36 2 0
9 32 35 2 0
9 32 34 2 0
9 32 33 2 0
9 32 32 2 0
9 32 31 2 0
9 32 30 8 0
9 32 29 8 0
9 32 28 8 0
9 32 27 8 0
9 32 26 8 0
9 32 25 15 64
9 32 22 19 44
9 32 21 19 12
9 32 20 19 76
9 33 37 2 32
9 33 36 2 0
9 33 35 2 0
9 33 34 2 0
9 33 33 2 0
9 33 32 2 0
9 33 31 2 0
9 33 30 8 0
9 33 29 8 0
9 33 28 8 0
9 33 27 8 8
9 33 26 8 8
9 33 25 8 8
9 33 24 8 88
9 34 37 2 32
9 34 36 2 0
9 34 35 2 0
9 34 34 2 0
9 34 33 2 0
9 34 32 2 0
9 34 31 2 0
9 34 30 10 4
9 34 29 10 4
9 34 28 12 68
9 35 37 2 32
9 35 36 2 0
9 35 35 2 0
9 35 34 2 0
9 35 33 2 0
9 35 32 2 0
9 35 31 2 0
9 35 30 10 4
9 35 29 10 4
9 35 28 12 68
9 36 37 2 32
9 36 36 2 0
9 36 35 2 0
9 36 34 2 0
9 36 33 2 0
9 36 32 2 0
9 36 31 2 0
9 36 30 10 4
9 36 29 10 4
9 36 28 12 68
9 37 37 2 32
9 37 36 2 0
9 37 35 2 0
9 37 34 2 0
9 37 33 2 0
9 37 32 2 0
9 37 31 2 0
9 37 30 10 4
9 37 29 10 4
9 37 28 12 68
9 38 37 2 32
9 38 36 2 0
9 38 35 2 0
9 38 34 2 0
9 38 33 2 0
9 38 32 2 0
9 38 31 2 0
9 38 30 10 4
9 38 29 10 4
9 38 28 12 68
9 39 37 2 32
9 39 36 2 0
9 39 35 2 0
9 39 34 2 0
9 39 33 2 0
9 39 32 2 0
9 39 31 2 0
9 39 30 10 4
9 39 29 10 4
9 39 28 12 68
9 40 37 2 32
9 40 36 2 0
9 40 35 2 0
9 40 34 2 0
9 40 33 2 0
9 40 32 2 0
9 40 31 2 0
9 40 30 10 4
9 40 29 10 6
9 40 28 12 68
9 41 37 2 32
9 41 36 2 0
9 41 35 2 0
9 41 34 2 0
9 41 33 2 0
9 41 32 2 0
9 41 31 2 0
9 41 30 10 12
9 41 29 10 14
9 41 28 12 76
9 42 37 2 32
9 42 36 2 0
9 42 35 2 0
9 42 34 2 0
9 42 33 2 0
9 42 32 2 0
9 42 31 2 72
9 43 37 2 32
9 43 36 2 0
9 43 35 2 0
9 43 34 2 0
9 43 33 2 0
9 43 32 4 64
9 44 37 2 32
9 44 36 2 0
9 44 35 2 0
9 44 34 2 0
9 44 33 2 0
9 44 32 2 0
9 44 31 2 88
9 45 37 2 32
9 45 36 2 0
9 45 35 2 0
9 45 34 2 0
9 45 33 2 0
9 45 32 4 72
9 46 37 2 32
9 46 36 2 0
9 46 35 2 0
9 46 34 2 0
9 46 33 2 64
9 47 37 2 32
9 47 36 2 0
9 47 35 2 0
9 47 34 2 0
9 47 33 2 64
9 48 37 2 32
9 48 36 2 0
9 48 35 2 0
9 48 34 2 0
9 48 33 2 64
9 49 37 2 32
9 49 36 2 0
9 49 35 2 0
9 49 34 2 0
9 49 33 2 0
9 49 32 4 80
9 50 37 2 32
9 50 36 2 0
9 50 35 2 0
9 50 34 2 0
9 50 33 2 0
9 50 32 4 68
9 51 37 2 32
9 51 36 2 0
9 51 35 2 0
9 51 34 2 0
9 51 33 2 0
9 51 32 4 64
9 52 37 2 32
9 52 36 2 0
9 52 35 2 0
9 52 34 2 0
9 52 33 2 0
9 52 32 4 72
9 53 37 2 32
9 53 36 2 0
9 53 35 2 0
9 53 34 2 0
9 53 33 2 64
9 54 37 2 32
9 54 36 2 0
9 54 35 2 0
9 54 34 2 0
9 54 33 2 64
9 55 37 2 32
9 55 36 2 0
9 55 35 2 0
9 55 34 2 0
9 55 33 2 64
9 56 37 2 32
9 56 36 2 0
9 56 35 2 0
9 56 34 2 0
9 56 33 2 64
9 57 37 2 32
9 57 36 2 0
9 57 35 2 0
9 57 34 2 0
9 57 33 2 0
9 57 32 4 84
9 58 37 2 32
9 58 36 2 0
9 58 35 2 0
9 58 34 2 0
9 58 33 2 0
9 58 32 4 64
9 59 37 2 32
9 59 36 2 0
9 59 35 2 0
9 59 34 2 0
9 59 33 2 0
9 59 32 2 0
9 59 31 2 84
9 60 37 2 32
9 60 36 2 0
9 60 35 2 0
9 60 34 2 0
9 60 33 2 0
9 60 32 2 0
9 60 31 2 64
9 61 37 2 40
9 61 36 2 8
9 61 35 2 0
9 61 34 2 0
9 61 33 2 0
9 61 32 2 8
9 61 31 2 72
9 62 35 9 34
9 62 34 9 2
9 62 33 9 66
9 63 35 11 42
9 63 34 11 10
9 63 33 11 74
9 70 35 6 50
9 70 34 6 18
9 70 33 6 82
9 71 36 9 48
9 71 35 11 0
9 71 34 11 0
9 71 33 11 0
9 71 32 9 80
9 72 36 11 32
9 72 35 11 0
9 72 34 11 0
9 72 33 11 0
9 72 32 11 64
9 73 36 11 32
9 73 35 11 0
9 73 34 11 0
9 73 33 11 0
9 73 32 11 64
9 74 36 11 40
9 74 35 11 0
9 74 34 11 0
9 74 33 11 0
9 74 32 11 72
9 75 35 9 42
9 75 34 9 10
9 75 33 9 74
9 77 36 14 56
9 77 35 11 16
9 77 34 11 16
9 77 33 11 16
9 77 32 14 88
9 78 35 19 34
9 78 34 19 2
9 78 33 19 66
9 79 35 19 42
9 79 34 19 10
9 79 33 19 74
10 1 37 1 48
10 1 36 1 16
10 1 35 1 16
10 1 34 1 16
10 1 33 1 16
10 1 32 1 16
10 1 31 1 16
10 1 30 1 16
10 1 29 1 16
10 1 28 1 16
10 1 27 1 16
10 1 26 1 16
10 1 25 1 16
10 1 24 1 16
10 1 23 1 16
10 1 22 1 16
10 1 21 1 16
10 1 20 1 80
10 2 37 1 32
10 2 36 1 0
10 2 35 1 0
10 2 34 1 0
10 2 33 1 0
10 2 32 1 0
10 2 31 1 0
10 2 30 1 0
10 2 29 1 0
10 2 28 1 0
10 2 27 1 0
10 2 26 1 0
10 2 25 1 0
10 2 24 1 0
10 2 23 1 0
10 2 22 1 0
10 2 21 1 0
10 2 20 1 64
10 3 37 1 32
10 3 36 1 0
10 3 35 1 0
10 3 34 1 0
10 3 33 1 0
10 3 32 1 0
10 3 31 1 0
10 3 30 1 0
10 3 29 1 0
10 3 28 1 0
10 3 27 1 0
10 3 26 1 0
10 3 25 1 0
10 3 24 1 0
10 3 23 1 0
10 3 22 1 0
10 3 21 1 0
10 3 20 1 64
10 4 37 1 32
10 4 36 1 0
10 4 35 1 0
10 4 34 1 0
10 4 33 1 0
10 4 32 1 0
10 4 31 1 0
10 4 30 1 0
10 4 29 1 0
10 4 28 1 0
10 4 27 1 0
10 4 26 1 0
10 4 25 1 0
10 4 24 1 0
10 4 23 1 0
10 4 22 1 0
10 4 21 1 0
10 4 20 1 64
10 5 37 1 32
10 5 36 1 0
10 5 35 1 0
10 5 34 1 0
10 5 33 1 0
10 5 32 1 0
10 5 31 1 0
10 5 30 1 0
10 5 29 1 0
10 5 28 1 0
10 5 27 1 0
10 5 26 1 0
10 5 25 1 0
10 5 24 1 0
10 5 23 1 0
10 5 22 1 0
10 5 21 1 0
10 5 20 1 64
10 6 37 1 32
10 6 36 1 0
10 6 35 1 0
10 6 34 1 0
10 6 33 1 0
10 6 32 1 0
10 6 31 1 0
10 6 30 1 0
10 6 29 1 0
10 6 28 1 0
10 6 27 1 0
10 6 26 1 0
10 6 25 1 0
10 6 24 1 0
10 6 23 1 0
10 6 22 1 0
10 6 21 1 0
10 6 20 1 64
10 7 37 1 32
10 7 36 1 0
10 7 35 1 0
10 7 34 1 0
10 7 33 1 0
10 7 32 1 0
10 7 31 1 0
10 7 30 1 0
10 7 29 1 0
10 7 28 1 0
10 7 27 1 0
10 7 26 1 0
10 7 25 1 0
10 7 24 1 0
10 7 23 1 0
10 7 22 1 0
10 7 21 1 0
10 7 20 1 64
10 8 37 2 32
10 8 36 2 0
10 8 35 2 0
10 8 34 2 0
10 8 33 2 0
10 8 32 2 0
10 8 31 2 0
10 8 30 1 0
10 8 29 1 0
10 8 28 1 0
10 8 27 1 0
10 8 26 1 0
10 8 25 1 0
10 8 24 1 0
10 8 23 1 0
10 8 22 1 0
10 8 21 1 0
10 8 20 1 64
10 9 37 2 32
10 9 36 2 0
10 9 35 2 0
10 9 34 2 0
10 9 33 2 0
10 9 32 2 0
10 9 31 2 0
10 9 30 1 0
10 9 29 1 0
10 9 28 1 0
10 9 27 1 0
10 9 26 1 0
10 9 25 1 0
10 9 24 1 0
10 9 23 1 0
10 9 22 1 0
10 9 21 1 0
10 9 20 1 64
10 10 37 2 32
10 10 36 2 0
10 10 35 2 0
10 10 34 2 0
10 10 33 2 0
10 10 32 2 0
10 10 31 2 0
10 10 30 1 0
10 10 29 1 0
10 10 28 1 0
10 10 27 1 0
10 10 26 1 0
10 10 25 1 0
10 10 24 1 0
10 10 23 1 0
10 10 22 1 0
10 10 21 1 0
10 10 20 1 64
10 11 37 2 32
10 11 36 2 0
10 11 35 2 0
10 11 34 2 0
10 11 33 2 0
10 11 32 2 0
10 11 31 2 0
10 11 30 1 0
10 11 29 1 0
10 11 28 1 0
10 11 27 1 0
10 11 26 1 0
10 11 25 1 0
10 11 24 1 0
10 11 23 1 0
10 11 22 1 0
10 11 21 1 0
10 11 20 1 64
10 12 37 2 32
10 12 36 2 0
10 12 35 2 0
10 12 34 2 0
10 12 33 2 0
10 12 32 2 0
10 12 31 2 0
10 12 30 1 0
10 12 29 1 0
10 12 28 1 0
10 12 27 1 0
10 12 26 1 0
10 12 25 1 0
10 12 24 1 0
10 12 23 1 0
10 12 22 1 0
10 12 21 1 0
10 12 20 1 64
10 13 37 2 32
10 13 36 2 0
10 13 35 2 0
10 13 34 2 0
10 13 33 2 0
10 13 32 2 0
10 13 31 2 0
10 13 30 1 0
10 13 29 1 0
10 13 28 1 0
10 13 27 1 0
10 13 26 1 0
10 13 25 1 0
10 13 24 1 0
10 13 23 1 0
10 13 22 1 0
10 13 21 1 0
10 13 20 1 64
10 14 37 2 32
10 14 36 2 0
10 14 35 2 0
10 14 34 2 0
10 14 33 2 0
10 14 32 2 0
10 14 31 2 0
10 14 30 2 0
10 14 29 2 0
10 14 28 2 0
10 14 27 2 0
10 14 26 2 0
10 14 25 2 0
10 14 24 2 0
10 14 23 2 0
10 14 22 2 0
10 14 21 2 0
10 14 20 2 64
10 15 37 2 32
10 15 36 2 0
10 15 35 2 0
10 15 34 2 0
10 15 33 2 0
10 15 32 2 0
10 15 31 2 0
10 15 30 2 0
10 15 29 2 0
10 15 28 2 0
10 15 27 2 0
10 15 26 2 0
10 15 25 2 0
10 15 24 2 0
10 15 23 2 0
10 15 22 2 0
10 15 21 2 0
10 15 20 2 64
10 16 37 2 32
10 16 36 2 0
10 16 35 2 0
10 16 34 2 0
10 16 33 2 0
10 16 32 2 0
10 16 31 2 0
10 16 30 2 0
10 16 29 2 0
10 16 28 2 0
10 16 27 2 0
10 16 26 2 0
10 16 25 2 0
10 16 24 2 0
10 16 23 2 0
10 16 22 2 0
10 16 21 2 0
10 16 20 2 64
10 17 37 2 32
10 17 36 2 0
10 17 35 2 0
10 17 34 2 0
10 17 33 2 0
10 17 32 2 0
10 17 31 2 0
10 17 30 2 0
10 17 29 2 0
10 17 28 2 0
10 17 27 2 0
10 17 26 2 0
10 17 25 2 0
10 17 24 2 0
10 17 23 2 0
10 17 22 2 0
10 17 21 2 0
10 17 20 2 64
10 18 37 2 32
10 18 36 2 0
10 18 35 2 0
10 18 34 2 0
10 18 33 2 0
10 18 32 2 0
10 18 31 2 0
10 18 30 2 0
10 18 29 2 0
10 18 28 2 0
10 18 27 2 0
10 18 26 2 0
10 18 25 2 0
10 18 24 2 0
10 18 23 2 0
10 18 22 2 0
10 18 21 2 0
10 18 20 2 64
10 19 37 2 32
10 19 36 2 0
10 19 35 2 0
10 19 34 2 0
10 19 33 2 0
10 19 32 2 0
10 19 31 2 0
10 19 30 2 0
10 19 29 2 0
10 19 28 2 0
10 19 27 2 0
10 19 26 2 0
10 19 25 2 0
10 19 24 2 0
10 19 23 2 0
10 19 22 2 0
10 19 21 2 0
10 19 20 2 64
10 19 12 7 116
10 19 10 7 116
10 19 8 7 116
10 20 37 2 32
10 20 36 2 0
10 20 35 2 0
10 20 34 2 0
10 20 33 2 0
10 20 32 2 0
10 20 31 2 0
10 20 30 2 0
10 20 29 2 0
10 20 28 2 0
10 20 27 2 0
10 20 26 2 0
10 20 25 2 0
10 20 24 2 0
10 20 23 2 0
10 20 22 2 0
10 20 21 2 0
10 20 20 2 64
10 20 12 5 32
10 20 11 5 16
10 20 10 5 0
10 20 9 5 16
10 20 8 5 0
10 20 7 5 16
10 20 6 5 16
10 20 5 5 16
10 20 4 5 16
10 20 3 5 16
10 20 2 5 16
10 20 1 5 16
10 20 0 5 80
10 21 37 2 32
10 21 36 2 0
10 21 35 2 0
10 21 34 2 0
10 21 33 2 0
10 21 32 2 0
10 21 31 2 0
10 21 30 2 0
10 21 29 2 0
10 21 28 2 0
10 21 27 2 0
10 21 26 2 0
10 21 25 2 0
10 21 24 2 0
10 21 23 2 0
10 21 22 2 0
10 21 21 2 0
10 21 20 2 64
10 21 12 7 32
10 21 11 7 0
10 21 10 7 0
10 21 9 7 0
10 21 8 7 0
10 21 7 7 0
10 21 6 7 0
10 21 5 7 0
10 21 4 7 0
10 21 3 7 0
10 21 2 7 0
10 21 1 7 0
10 21 0 7 72
10 22 37 2 32
10 22 36 2 0
10 22 35 2 0
10 22 34 2 0
10 22 33 2 0
10 22 32 2 0
10 22 31 2 0
10 22 30 2 0
10 22 29 2 0
10 22 28 2 0
10 22 27 2 0
10 22 26 2 0
10 22 25 13 0
10 22 24 13 0
10 22 23 13 0
10 22 22 13 0
10 22 21 13 0
10 22 20 13 0
10 22 19 13 16
10 22 18 13 16
10 22 17 13 16
10 22 16 13 16
10 22 15 13 16
10 22 14 13 16
10 22 13 13 16
10 22 12 17 8
10 22 11 17 0
10 22 10 17 8
10 22 9 17 0
10 22 8 17 8
10 22 7 17 0
10 22 6 17 8
10 22 5 17 8
10 22 4 17 0
10 22 3 17 8
10 22 2 17 0
10 22 1 17 72
10 23 37 2 32
10 23 36 2 0
10 23 35 2 0
10 23 34 2 0
10 23 33 2 0
10 23 32 2 0
10 23 31 2 0
10 23 30 13 0
10 23 29 13 0
10 23 28 13 0
10 23 27 13 0
10 23 26 13 0
10 23 25 13 0
10 23 24 13 0
10 23 23 13 0
10 23 22 13 0
10 23 21 13 0
10 23 20 13 0
10 23 19 13 0
10 23 18 13 0
10 23 17 13 8
10 23 16 13 8
10 23 15 13 8
10 23 14 13 8
10 23 13 13 72
10 23 11 2 104
10 23 9 2 104
10 23 7 2 104
10 23 4 2 104
10 23 2 2 104
10 24 37 2 32
10 24 36 2 0
10 24 35 2 0
10 24 34 2 0
10 24 33 2 0
10 24 32 2 0
10 24 31 2 0
10 24 30 13 0
10 24 29 13 0
10 24 28 13 0
10 24 27 13 0
10 24 26 13 0
10 24 25 13 0
10 24 24 13 0
10 24 23 13 0
10 24 22 13 0
10 24 21 13 8
10 24 20 13 8
10 24 19 13 8
10 24 18 13 72
10 25 37 2 32
10 25 36 2 0
10 25 35 2 0
10 25 34 2 0
10 25 33 2 0
10 25 32 2 0
10 25 31 2 0
10 25 30 8 0
10 25 29 8 0
10 25 28 8 0
10 25 27 8 0
10 25 26 8 0
10 25 25 8 0
10 25 24 8 0
10 25 23 8 0
10 25 22 8 64
10 26 37 2 32
10 26 36 2 0
10 26 35 2 0
10 26 34 2 0
10 26 33 2 0
10 26 32 2 0
10 26 31 2 0
10 26 30 8 0
10 26 29 8 0
10 26 28 8 0
10 26 27 8 0
10 26 26 8 0
10 26 25 8 0
10 26 24 8 0
10 26 23 8 0
10 26 22 8 0
10 26 21 8 16
10 26 20 8 80
10 27 37 2 32
10 27 36 2 0
10 27 35 2 0
10 27 34 2 0
10 27 33 2 0
10 27 32 2 0
10 27 31 2 0
10 27 30 8 0
10 27 29 8 0
10 27 28 8 0
10 27 27 8 0
10 27 26 8 0
10 27 25 8 0
10 27 24 8 8
10 27 23 8 0
10 27 22 8 0
10 27 21 8 0
10 27 20 8 0
10 27 19 8 16
10 27 18 8 24
10 27 17 8 88
10 28 37 2 32
10 28 36 2 0
10 28 35 2 0
10 28 34 2 0
10 28 33 2 0
10 28 32 2 0
10 28 31 2 0
10 28 30 8 0
10 28 29 8 0
10 28 28 8 0
10 28 27 8 0
10 28 26 8 0
10 28 25 15 64
10 28 23 11 40
10 28 22 9 8
10 28 21 11 0
10 28 20 9 8
10 28 19 11 72
10 29 37 2 32
10 29 36 2 0
10 29 35 2 0
10 29 34 2 0
10 29 33 2 0
10 29 32 2 0
10 29 31 2 0
10 29 30 8 0
10 29 29 8 0
10 29 28 8 0
10 29 27 8 0
10 29 26 8 0
10 29 25 15 64
10 29 21 11 102
10 30 37 2 32
10 30 36 2 0
10 30 35 2 0
10 30 34 2 0
10 30 33 2 0
10 30 32 2 0
10 30 31 2 0
10 30 30 8 0
10 30 29 8 0
10 30 28 8 0
10 30 27 8 0
10 30 26 8 0
10 30 25 15 64
10 30 22 11 48
10 30 21 19 0
10 30 20 11 80
10 31 37 2 32
10 31 36 2 0
10 31 35 2 0
10 31 34 2 0
10 31 33 2 0
10 31 32 2 0
10 31 31 2 0
10 31 30 8 0
10 31 29 8 0
10 31 28 8 0
10 31 27 8 0
10 31 26 8 0
10 31 25 15 64
10 31 22 19 32
10 31 21 19 0
10 31 20 19 64
10 32 37 2 32
10 32 36 2 0
10 32 35 2 0
10 32 34 2 0
10 32 33 2 0
10 32 32 2 0
10 32 31 2 0
10 32 30 8 0
10 32 29 8 0
10 32 28 8 0
10 32 27 8 0
10 32 26 8 0
10 32 25 15 64
10 32 22 19 40
10 32 21 19 8
10 32 20 19 72
10 33 37 2 32
10 33 36 2 0
10 33 35 2 0
10 33 34 2 0
10 33 33 2 0
10 33 32 2 0
10 33 31 2 0
10 33 30 8 0
10 33 29 8 0
10 33 28 8 0
10 33 27 8 8
10 33 26 8 8
10 33 25 8 8
10 33 24 8 88
10 34 37 2 32
10 34 36 2 0
10 34 35 2 0
10 34 34 2 0
10 34 33 2 0
10 34 32 2 0
10 34 31 2 0
10 34 30 10 0
10 34 29 10 0
10 34 28 10 64
10 34 21 18 118
10 35 37 2 32
10 35 36 2 0
10 35 35 2 0
10 35 34 2 0
10 35 33 2 0
10 35 32 2 0
10 35 31 2 0
10 35 30 10 0
10 35 29 10 0
10 35 28 10 64
10 35 21 18 110
10 36 37 2 32
10 36 36 2 0
10 36 35 2 0
10 36 34 2 0
10 36 33 2 0
10 36 32 2 0
10 36 31 2 0
10 36 30 10 0
10 36 29 10 0
10 36 28 10 64
10 37 37 2 32
10 37 36 2 0
10 37 35 2 0
10 37 34 2 0
10 37 33 2 0
10 37 32 2 0
10 37 31 2 0
10 37 30 10 0
10 37 29 10 0
10 37 28 10 64
10 38 37 2 32
10 38 36 2 0
10 38 35 2 0
10 38 34 2 0
10 38 33 2 0
10 38 32 2 0
10 38 31 2 0
10 38 30 10 0
10 38 29 10 0
10 38 28 10 64
10 39 37 2 32
10 39 36 2 0
10 39 35 2 0
10 39 34 2 0
10 39 33 2 0
10 39 32 2 0
10 39 31 2 0
10 39 30 10 0
10 39 29 10 8
10 39 28 10 64
10 40 37 2 32
10 40 36 2 0
10 40 35 2 0
10 40 34 2 0
10 40 33 2 0
10 40 32 2 0
10 40 31 2 0
10 40 30 10 64
10 40 28 10 96
10 41 37 2 32
10 41 36 2 0
10 41 35 2 0
10 41 34 2 0
10 41 33 2 0
10 41 32 2 0
10 41 31 2 0
10 41 30 10 72
10 41 28 10 104
10 42 37 2 32
10 42 36 2 0
10 42 35 2 0
10 42 34 2 0
10 42 33 2 0
10 42 32 2 0
10 42 31 2 72
10 43 37 2 32
10 43 36 2 0
10 43 35 2 0
10 43 34 2 0
10 43 33 2 0
10 43 32 4 64
10 44 37 2 32
10 44 36 2 0
10 44 35 2 0
10 44 34 2 0
10 44 33 2 0
10 44 32 2 0
10 44 31 2 88
10 45 37 2 32
10 45 36 2 0
10 45 35 2 0
10 45 34 2 0
10 45 33 2 0
10 45 32 4 64
10 46 37 2 32
10 46 36 2 0
10 46 35 2 0
10 46 34 2 0
10 46 33 2 0
10 46 32 4 68
10 47 37 2 32
10 47 36 2 0
10 47 35 2 0
10 47 34 2 0
10 47 33 2 0
10 47 32 4 68
10 48 37 2 32
10 48 36 2 0
10 48 35 2 0
10 48 34 2 0
10 48 33 2 0
10 48 32 4 68
10 49 37 2 32
10 49 36 2 0
10 49 35 2 0
10 49 34 2 0
10 49 33 2 0
10 49 32 4 64
10 50 37 2 32
10 50 36 2 0
10 50 35 2 0
10 50 34 2 0
10 50 33 2 0
10 50 32 2 0
10 50 31 2 84
10 51 37 2 32
10 51 36 2 0
10 51 35 2 0
10 51 34 2 0
10 51 33 2 0
10 51 32 2 0
10 51 31 2 76
10 52 37 2 32
10 52 36 2 0
10 52 35 2 0
10 52 34 2 0
10 52 33 2 0
10 52 32 4 64
10 53 37 2 32
10 53 36 2 0
10 53 35 2 0
10 53 34 2 0
10 53 33 2 0
10 53 32 4 68
10 54 37 2 32
10 54 36 2 0
10 54 35 2 0
10 54 34 2 0
10 54 33 2 0
10 54 32 4 68
10 55 37 2 32
10 55 36 2 0
10 55 35 2 0
10 55 34 2 0
10 55 33 2 0
10 55 32 4 68
10 56 37 2 32
10 56 36 2 0
10 56 35 2 0
10 56 34 2 0
10 56 33 2 0
10 56 32 4 68
10 57 37 2 32
10 57 36 2 0
10 57 35 2 0
10 57 34 2 0
10 57 33 2 0
10 57 32 4 64
10 58 37 2 32
10 58 36 2 0
10 58 35 2 0
10 58 34 2 0
10 58 33 2 0
10 58 32 2 0
10 58 31 2 84
10 59 37 2 32
10 59 36 2 0
10 59 35 2 0
10 59 34 2 0
10 59 33 2 0
10 59 32 2 0
10 59 31 2 64
10 60 37 2 32
10 60 36 2 0
10 60 35 2 0
10 60 34 2 0
10 60 33 2 0
10 60 32 2 0
10 60 31 2 64
10 61 37 2 40
10 61 36 2 8
10 61 35 2 8
10 61 34 2 8
10 61 33 2 8
10 61 32 2 8
10 61 31 2 72
10 71 36 6 50
10 71 35 6 16
10 71 34 6 16
10 71 33 6 16
10 71 32 6 82
10 72 36 11 32
10 72 35 11 0
10 72 34 11 0
10 72 33 11 0
10 72 32 11 64
10 73 36 11 34
10 73 35 11 0
10 73 34 11 0
10 73 33 11 0
10 73 32 11 66
10 74 36 11 42
10 74 35 11 10
10 74 34 11 10
10 74 33 11 10
10 74 32 11 74
10 77 36 14 58
10 77 35 14 26
10 77 34 14 26
10 77 33 14 26
10 77 32 14 90
11 1 37 1 48
11 1 36 1 16
11 1 35 1 16
11 1 34 1 16
11 1 33 1 16
11 1 32 1 16
11 1 31 1 16
11 1 30 1 16
11 1 29 1 16
11 1 28 1 16
11 1 27 1 16
11 1 26 1 16
11 1 25 1 16
11 1 24 1 16
11 1 23 1 16
11 1 22 1 16
11 1 21 1 16
11 1 20 1 80
11 2 37 1 32
11 2 36 1 0
11 2 35 1 0
11 2 34 1 0
11 2 33 1 0
11 2 32 1 0
11 2 31 1 0
11 2 30 1 0
11 2 29 1 0
11 2 28 1 0
11 2 27 1 0
11 2 26 1 0
11 2 25 1 0
11 2 24 1 0
11 2 23 1 0
11 2 22 1 0
11 2 21 1 0
11 2 20 1 64
11 3 37 1 32
11 3 36 1 0
11 3 35 1 0
11 3 34 1 0
11 3 33 1 0
11 3 32 1 0
11 3 31 1 0
11 3 30 1 0
11 3 29 1 0
11 3 28 1 0
11 3 27 1 0
11 3 26 1 0
11 3 25 1 0
11 3 24 1 0
11 3 23 1 0
11 3 22 1 0
11 3 21 1 0
11 3 20 1 64
11 4 37 1 32
11 4 36 1 0
11 4 35 1 0
11 4 34 1 0
11 4 33 1 0
11 4 32 1 0
11 4 31 1 0
11 4 30 1 0
11 4 29 1 0
11 4 28 1 0
11 4 27 1 0
11 4 26 1 0
11 4 25 1 0
11 4 24 1 0
11 4 23 1 0
11 4 22 1 0
11 4 21 1 0
11 4 20 1 64
11 5 37 1 32
11 5 36 1 0
11 5 35 1 0
11 5 34 1 0
11 5 33 1 0
11 5 32 1 0
11 5 31 1 0
11 5 30 1 0
11 5 29 1 0
11 5 28 1 0
11 5 27 1 0
11 5 26 1 0
11 5 25 1 0
11 5 24 1 0
11 5 23 1 0
11 5 22 1 0
11 5 21 1 0
11 5 20 1 64
11 6 37 1 32
11 6 36 1 0
11 6 35 1 0
11 6 34 1 0
11 6 33 1 0
11 6 32 1 0
11 6 31 1 0
11 6 30 1 0
11 6 29 1 0
11 6 28 1 0
11 6 27 1 0
11 6 26 1 0
11 6 25 1 0
11 6 24 1 0
11 6 23 1 0
11 6 22 1 0
11 6 21 1 0
11 6 20 1 64
11 7 37 1 32
11 7 36 1 0
11 7 35 1 0
11 7 34 1 0
11 7 33 1 0
11 7 32 1 0
11 7 31 1 0
11 7 30 1 0
11 7 29 1 0
11 7 28 1 0
11 7 27 1 0
11 7 26 1 0
11 7 25 1 0
11 7 24 1 0
11 7 23 1 0
11 7 22 1 0
11 7 21 1 0
11 7 20 1 64
11 8 37 2 32
11 8 36 2 0
11 8 35 2 0
11 8 34 2 0
11 8 33 2 0
11 8 32 2 0
11 8 31 2 0
11 8 30 1 0
11 8 29 1 0
11 8 28 1 0
11 8 27 1 0
11 8 26 1 0
11 8 25 1 0
11 8 24 1 0
11 8 23 1 0
11 8 22 1 0
11 8 21 1 0
11 8 20 1 64
11 9 37 2 32
11 9 36 2 0
11 9 35 2 0
11 9 34 2 0
11 9 33 2 0
11 9 32 2 0
11 9 31 2 0
11 9 30 1 0
11 9 29 1 0
11 9 28 1 0
11 9 27 1 0
11 9 26 1 0
11 9 25 1 0
11 9 24 1 0
11 9 23 1 0
11 9 22 1 0
11 9 21 1 0
11 9 20 1 64
11 10 37 2 32
11 10 36 2 0
11 10 35 2 0
11 10 34 2 0
11 10 33 2 0
11 10 32 2 0
11 10 31 2 0
11 10 30 1 0
11 10 29 1 0
11 10 28 1 0
11 10 27 1 0
11 10 26 1 0
11 10 25 1 0
11 10 24 1 0
11 10 23 1 0
11 10 22 1 0
11 10 21 1 0
11 10 20 1 64
11 11 37 2 32
11 11 36 2 0
11 11 35 2 0
11 11 34 2 0
11 11 33 2 0
11 11 32 2 0
11 11 31 2 0
11 11 30 1 0
11 11 29 1 0
11 11 28 1 0
11 11 27 1 0
11 11 26 1 0
11 11 25 1 0
11 11 24 1 0
11 11 23 1 0
11 11 22 1 0
11 11 21 1 0
11 11 20 1 64
11 12 37 2 32
11 12 36 2 0
11 12 35 2 0
11 12 34 2 0
11 12 33 2 0
11 12 32 2 0
11 12 31 2 0
11 12 30 1 0
11 12 29 1 0
11 12 28 1 0
11 12 27 1 0
11 12 26 1 0
11 12 25 1 0
11 12 24 1 0
11 12 23 1 0
11 12 22 1 0
11 12 21 1 0
11 12 20 1 64
11 13 37 2 32
11 13 36 2 0
11 13 35 2 0
11 13 34 2 0
11 13 33 2 0
11 13 32 2 0
11 13 31 2 0
11 13 30 1 0
11 13 29 1 0
11 13 28 1 0
11 13 27 1 0
11 13 26 1 0
11 13 25 1 0
11 13 24 1 0
11 13 23 1 0
11 13 22 1 0
11 13 21 1 0
11 13 20 1 64
11 14 37 2 32
11 14 36 2 0
11 14 35 2 0
11 14 34 2 0
11 14 33 2 0
11 14 32 2 0
11 14 31 2 0
11 14 30 2 0
11 14 29 2 0
11 14 28 2 0
11 14 27 2 0
11 14 26 2 0
11 14 25 2 0
11 14 24 2 0
11 14 23 2 0
11 14 22 2 0
11 14 21 2 0
11 14 20 2 64
11 15 37 2 32
11 15 36 2 0
11 15 35 2 0
11 15 34 2 0
11 15 33 2 0
11 15 32 2 0
11 15 31 2 0
11 15 30 2 0
11 15 29 2 0
11 15 28 2 0
11 15 27 2 0
11 15 26 2 0
11 15 25 2 0
11 15 24 2 0
11 15 23 2 0
11 15 22 2 0
11 15 21 2 0
11 15 20 2 64
11 16 37 2 32
11 16 36 2 0
11 16 35 2 0
11 16 34 2 0
11 16 33 2 0
11 16 32 2 0
11 16 31 2 0
11 16 30 2 0
11 16 29 2 0
11 16 28 2 0
11 16 27 2 0
11 16 26 2 0
11 16 25 2 0
11 16 24 2 0
11 16 23 2 0
11 16 22 2 0
11 16 21 2 0
11 16 20 2 64
11 17 37 2 32
11 17 36 2 0
11 17 35 2 0
11 17 34 2 0
11 17 33 2 0
11 17 32 2 0
11 17 31 2 0
11 17 30 2 0
11 17 29 2 0
11 17 28 2 0
11 17 27 2 0
11 17 26 2 0
11 17 25 2 0
11 17 24 2 0
11 17 23 2 0
11 17 22 2 0
11 17 21 2 0
11 17 20 2 64
11 18 37 2 32
11 18 36 2 0
11 18 35 2 0
11 18 34 2 0
11 18 33 2 0
11 18 32 2 0
11 18 31 2 0
11 18 30 2 0
11 18 29 2 0
11 18 28 2 0
11 18 27 2 0
11 18 26 2 0
11 18 25 2 0
11 18 24 2 0
11 18 23 2 0
11 18 22 2 0
11 18 21 2 0
11 18 20 2 64
11 19 37 2 32
11 19 36 2 0
11 19 35 2 0
11 19 34 2 0
11 19 33 2 0
11 19 32 2 0
11 19 31 2 0
11 19 30 2 0
11 19 29 2 0
11 19 28 2 0
11 19 27 2 0
11 19 26 2 0
11 19 25 2 0
11 19 24 2 0
11 19 23 2 0
11 19 22 2 0
11 19 21 2 0
11 19 20 2 64
11 19 12 7 112
11 19 10 7 112
11 19 8 7 112
11 20 37 2 32
11 20 36 2 0
11 20 35 2 0
11 20 34 2 0
11 20 33 2 0
11 20 32 2 0
11 20 31 2 0
11 20 30 2 0
11 20 29 2 0
11 20 28 2 0
11 20 27 2 0
11 20 26 2 0
11 20 25 2 0
11 20 24 2 0
11 20 23 2 0
11 20 22 2 0
11 20 21 2 0
11 20 20 2 64
11 20 12 5 32
11 20 11 5 16
11 20 10 5 0
11 20 9 5 16
11 20 8 5 0
11 20 7 5 16
11 20 6 5 16
11 20 5 5 16
11 20 4 5 16
11 20 3 5 16
11 20 2 5 16
11 20 1 5 16
11 20 0 5 80
11 21 37 2 32
11 21 36 2 0
11 21 35 2 0
11 21 34 2 0
11 21 33 2 0
11 21 32 2 0
11 21 31 2 0
11 21 30 2 0
11 21 29 2 0
11 21 28 2 0
11 21 27 2 0
11 21 26 2 0
11 21 25 2 0
11 21 24 2 0
11 21 23 2 0
11 21 22 2 0
11 21 21 2 0
11 21 20 2 64
11 21 12 7 32
11 21 11 7 0
11 21 10 7 0
11 21 9 7 0
11 21 8 7 0
11 21 7 7 0
11 21 6 7 0
11 21 5 7 0
11 21 4 7 0
11 21 3 7 0
11 21 2 7 0
11 21 1 7 0
11 21 0 7 72
11 22 37 2 32
11 22 36 2 0
11 22 35 2 0
11 22 34 2 0
11 22 33 2 0
11 22 32 2 0
11 22 31 2 0
11 22 30 2 0
11 22 29 2 0
11 22 28 2 0
11 22 27 2 0
11 22 26 2 0
11 22 25 13 0
11 22 24 13 0
11 22 23 13 0
11 22 22 13 0
11 22 21 13 0
11 22 20 13 0
11 22 19 13 16
11 22 18 13 16
11 22 17 13 16
11 22 16 13 16
11 22 15 13 16
11 22 14 13 16
11 22 13 13 16
11 22 12 17 8
11 22 11 17 0
11 22 10 17 8
11 22 9 17 0
11 22 8 17 8
11 22 7 17 0
11 22 6 17 8
11 22 5 17 8
11 22 4 17 0
11 22 3 17 8
11 22 2 17 0
11 22 1 17 72
11 23 37 2 32
11 23 36 2 0
11 23 35 2 0
11 23 34 2 0
11 23 33 2 0
11 23 32 2 0
11 23 31 2 0
11 23 30 13 0
11 23 29 13 0
11 23 28 13 0
11 23 27 13 0
11 23 26 13 0
11 23 25 13 0
11 23 24 13 0
11 23 23 13 0
11 23 22 13 0
11 23 21 13 0
11 23 20 13 0
11 23 19 13 0
11 23 18 13 0
11 23 17 13 8
11 23 16 13 8
11 23 15 13 8
11 23 14 13 8
11 23 13 13 72
11 23 11 2 106
11 23 9 2 106
11 23 7 2 106
11 23 4 2 106
11 23 2 2 106
11 24 37 2 32
11 24 36 2 0
11 24 35 2 0
11 24 34 2 0
11 24 33 2 0
11 24 32 2 0
11 24 31 2 0
11 24 30 13 0
11 24 29 13 0
11 24 28 13 0
11 24 27 13 0
11 24 26 13 0
11 24 25 13 0
11 24 24 13 0
11 24 23 13 0
11 24 22 13 0
11 24 21 13 8
11 24 20 13 8
11 24 19 13 8
11 24 18 13 72
11 25 37 2 32
11 25 36 2 0
11 25 35 2 0
11 25 34 2 0
11 25 33 2 0
11 25 32 2 0
11 25 31 2 0
11 25 30 8 0
11 25 29 8 0
11 25 28 8 0
11 25 27 8 0
11 25 26 8 0
11 25 25 8 0
11 25 24 8 0
11 25 23 8 0
11 25 22 8 64
11 26 37 2 32
11 26 36 2 0
11 26 35 2 0
11 26 34 2 0
11 26 33 2 0
11 26 32 2 0
11 26 31 2 0
11 26 30 8 0
11 26 29 8 0
11 26 28 8 0
11 26 27 8 0
11 26 26 8 0
11 26 25 8 0
11 26 24 8 0
11 26 23 8 0
11 26 22 8 0
11 26 21 8 16
11 26 20 8 82
11 27 37 2 32
11 27 36 2 0
11 27 35 2 0
11 27 34 2 0
11 27 33 2 0
11 27 32 2 0
11 27 31 2 0
11 27 30 8 0
11 27 29 8 0
11 27 28 8 0
11 27 27 8 0
11 27 26 8 0
11 27 25 8 0
11 27 24 8 0
11 27 23 8 0
11 27 22 8 0
11 27 21 8 0
11 27 20 8 0
11 27 19 8 16
11 27 18 8 24
11 27 17 8 90
11 28 37 2 32
11 28 36 2 0
11 28 35 2 0
11 28 34 2 0
11 28 33 2 0
11 28 32 2 0
11 28 31 2 0
11 28 30 8 0
11 28 29 8 0
11 28 28 8 0
11 28 27 8 0
11 28 26 8 0
11 28 25 8 0
11 28 24 8 4
11 28 23 11 8
11 28 22 9 8
11 28 21 9 8
11 28 20 9 8
11 28 19 11 72
11 29 37 2 32
11 29 36 2 0
11 29 35 2 0
11 29 34 2 0
11 29 33 2 0
11 29 32 2 0
11 29 31 2 0
11 29 30 8 0
11 29 29 8 0
11 29 28 8 0
11 29 27 8 0
11 29 26 8 0
11 29 25 8 0
11 29 24 8 68
11 30 37 2 32
11 30 36 2 0
11 30 35 2 0
11 30 34 2 0
11 30 33 2 0
11 30 32 2 0
11 30 31 2 0
11 30 30 8 0
11 30 29 8 0
11 30 28 8 0
11 30 27 8 0
11 30 26 8 0
11 30 25 8 0
11 30 24 8 68
11 30 22 11 50
11 30 21 11 18
11 30 20 11 82
11 31 37 2 32
11 31 36 2 0
11 31 35 2 0
11 31 34 2 0
11 31 33 2 0
11 31 32 2 0
11 31 31 2 0
11 31 30 8 0
11 31 29 8 0
11 31 28 8 0
11 31 27 8 0
11 31 26 8 0
11 31 25 8 0
11 31 24 8 76
11 31 22 19 34
11 31 21 19 2
11 31 20 19 66
11 32 37 2 32
11 32 36 2 0
11 32 35 2 0
11 32 34 2 0
11 32 33 2 0
11 32 32 2 0
11 32 31 2 0
11 32 30 8 0
11 32 29 8 0
11 32 28 8 0
11 32 27 8 0
11 32 26 8 0
11 32 25 15 64
11 32 22 19 42
11 32 21 19 10
11 32 20 19 74
11 33 37 2 32
11 33 36 2 0
11 33 35 2 0
11 33 34 2 0
11 33 33 2 0
11 33 32 2 0
11 33 31 2 0
11 33 30 8 0
11 33 29 8 0
11 33 28 8 0
11 33 27 8 8
11 33 26 8 8
11 33 25 8 8
11 33 24 8 88
11 34 37 2 32
11 34 36 2 0
11 34 35 2 0
11 34 34 2 0
11 34 33 2 0
11 34 32 2 0
11 34 31 2 0
11 34 30 10 0
11 34 29 10 0
11 34 28 10 64
11 35 37 2 32
11 35 36 2 0
11 35 35 2 0
11 35 34 2 0
11 35 33 2 0
11 35 32 2 0
11 35 31 2 0
11 35 30 10 0
11 35 29 10 0
11 35 28 10 64
11 36 37 2 32
11 36 36 2 0
11 36 35 2 0
11 36 34 2 0
11 36 33 2 0
11 36 32 2 0
11 36 31 2 0
11 36 30 10 0
11 36 29 10 0
11 36 28 10 64
11 37 37 2 32
11 37 36 2 0
11 37 35 2 0
11 37 34 2 0
11 37 33 2 0
11 37 32 2 0
11 37 31 2 0
11 37 30 10 0
11 37 29 10 0
11 37 28 10 64
11 38 37 2 32
11 38 36 2 0
11 38 35 2 0
11 38 34 2 0
11 38 33 2 0
11 38 32 2 0
11 38 31 2 0
11 38 30 10 0
11 38 29 10 0
11 38 28 10 64
11 39 37 2 32
11 39 36 2 0
11 39 35 2 0
11 39 34 2 0
11 39 33 2 0
11 39 32 2 0
11 39 31 2 0
11 39 30 10 0
11 39 29 10 0
11 39 28 10 64
11 40 37 2 32
11 40 36 2 0
11 40 35 2 0
11 40 34 2 0
11 40 33 2 0
11 40 32 2 0
11 40 31 2 0
11 40 30 10 0
11 40 29 10 4
11 40 28 10 64
11 41 37 2 32
11 41 36 2 0
11 41 35 2 0
11 41 34 2 0
11 41 33 2 0
11 41 32 2 0
11 41 31 2 0
11 41 30 10 8
11 41 29 10 12
11 41 28 10 72
11 42 37 2 32
11 42 36 2 0
11 42 35 2 0
11 42 34 2 0
11 42 33 2 0
11 42 32 2 0
11 42 31 2 64
11 43 37 2 32
11 43 36 2 0
11 43 35 2 0
11 43 34 2 0
11 43 33 2 0
11 43 32 2 0
11 43 31 2 68
11 44 37 2 32
11 44 36 2 0
11 44 35 2 0
11 44 34 2 0
11 44 33 2 0
11 44 32 2 0
11 44 31 2 64
11 45 37 2 32
11 45 36 2 0
11 45 35 2 0
11 45 34 2 0
11 45 33 2 0
11 45 32 2 0
11 45 31 2 68
11 46 37 2 32
11 46 36 2 0
11 46 35 2 0
11 46 34 2 0
11 46 33 2 0
11 46 32 2 0
11 46 31 2 68
11 47 37 2 32
11 47 36 2 0
11 47 35 2 0
11 47 34 2 0
11 47 33 2 0
11 47 32 2 0
11 47 31 2 68
11 48 37 2 32
11 48 36 2 0
11 48 35 2 0
11 48 34 2 0
11 48 33 2 0
11 48 32 2 0
11 48 31 2 68
11 49 37 2 32
11 49 36 2 0
11 49 35 2 0
11 49 34 2 0
11 49 33 2 0
11 49 32 2 0
11 49 31 2 68
11 50 37 2 32
11 50 36 2 0
11 50 35 2 0
11 50 34 2 0
11 50 33 2 0
11 50 32 2 0
11 50 31 2 64
11 51 37 2 32
11 51 36 2 0
11 51 35 2 0
11 51 34 2 0
11 51 33 2 0
11 51 32 2 0
11 51 31 2 64
11 52 37 2 32
11 52 36 2 0
11 52 35 2 0
11 52 34 2 0
11 52 33 2 0
11 52 32 2 0
11 52 31 2 68
11 53 37 2 32
11 53 36 2 0
11 53 35 2 0
11 53 34 2 0
11 53 33 2 0
11 53 32 2 0
11 53 31 2 68
11 54 37 2 32
11 54 36 2 0
11 54 35 2 0
11 54 34 2 0
11 54 33 2 0
11 54 32 2 0
11 54 31 2 68
11 55 37 2 32
11 55 36 2 0
11 55 35 2 0
11 55 34 2 0
11 55 33 2 0
11 55 32 2 0
11 55 31 2 68
11 56 37 2 32
11 56 36 2 0
11 56 35 2 0
11 56 34 2 0
11 56 33 2 0
11 56 32 2 0
11 56 31 2 68
11 57 37 2 32
11 57 36 2 0
11 57 35 2 0
11 57 34 2 0
11 57 33 2 0
11 57 32 2 0
11 57 31 2 68
11 58 37 2 32
11 58 36 2 0
11 58 35 2 0
11 58 34 2 0
11 58 33 2 0
11 58 32 2 0
11 58 31 2 64
11 59 37 2 32
11 59 36 2 0
11 59 35 2 0
11 59 34 2 0
11 59 33 2 0
11 59 32 2 0
11 59 31 2 64
11 60 37 2 32
11 60 36 2 0
11 60 35 2 0
11 60 34 2 0
11 60 33 2 0
11 60 32 2 0
11 60 31 2 64
11 61 37 2 40
11 61 36 2 8
11 61 35 2 8
11 61 34 2 8
11 61 33 2 8
11 61 32 2 8
11 61 31 2 72
11 71 35 9 50
11 71 34 9 18
11 71 33 9 82
11 72 36 11 58
11 72 35 11 2
11 72 34 11 2
11 72 33 11 2
11 72 32 11 90
11 73 35 9 42
11 73 34 9 10
11 73 33 9 74
12 1 37 1 48
12 1 36 1 16
12 1 35 1 16
12 1 34 1 16
12 1 33 1 16
12 1 32 1 16
12 1 31 1 16
12 1 30 1 16
12 1 29 1 16
12 1 28 1 16
12 1 27 1 16
12 1 26 1 16
12 1 25 1 16
12 1 24 1 16
12 1 23 1 16
12 1 22 1 16
12 1 21 1 16
12 1 20 1 80
12 2 37 1 32
12 2 36 1 0
12 2 35 1 0
12 2 34 1 0
12 2 33 1 0
12 2 32 1 0
12 2 31 1 0
12 2 30 1 0
12 2 29 1 0
12 2 28 1 0
12 2 27 1 0
12 2 26 1 0
12 2 25 1 0
12 2 24 1 0
12 2 23 1 0
12 2 22 1 0
12 2 21 1 0
12 2 20 1 64
12 3 37 1 32
12 3 36 1 0
12 3 35 1 0
12 3 34 1 0
12 3 33 1 0
12 3 32 1 0
12 3 31 1 0
12 3 30 1 0
12 3 29 1 0
12 3 28 1 0
12 3 27 1 0
12 3 26 1 0
12 3 25 1 0
12 3 24 1 0
12 3 23 1 0
12 3 22 1 0
12 3 21 1 0
12 3 20 1 64
12 4 37 1 32
12 4 36 1 0
12 4 35 1 0
12 4 34 1 0
12 4 33 1 0
12 4 32 1 0
12 4 31 1 0
12 4 30 1 0
12 4 29 1 0
12 4 28 1 0
12 4 27 1 0
12 4 26 1 0
12 4 25 1 0
12 4 24 1 0
12 4 23 1 0
12 4 22 1 0
12 4 21 1 0
12 4 20 1 64
12 5 37 1 32
12 5 36 1 0
12 5 35 1 0
12 5 34 1 0
12 5 33 1 0
12 5 32 1 0
12 5 31 1 0
12 5 30 1 0
12 5 29 1 0
12 5 28 1 0
12 5 27 1 0
12 5 26 1 0
12 5 25 1 0
12 5 24 1 0
12 5 23 1 0
12 5 22 1 0
12 5 21 1 0
12 5 20 1 64
12 6 37 1 32
12 6 36 1 0
12 6 35 1 0
12 6 34 1 0
12 6 33 1 0
12 6 32 1 0
12 6 31 1 0
12 6 30 1 0
12 6 29 1 0
12 6 28 1 0
12 6 27 1 0
12 6 26 1 0
12 6 25 1 0
12 6 24 1 0
12 6 23 1 0
12 6 22 1 0
12 6 21 1 0
12 6 20 1 64
12 7 37 1 32
12 7 36 1 0
12 7 35 1 0
12 7 34 1 0
12 7 33 1 0
12 7 32 1 0
12 7 31 1 0
12 7 30 1 0
12 7 29 1 0
12 7 28 1 0
12 7 27 1 0
12 7 26 1 0
12 7 25 1 0
12 7 24 1 0
12 7 23 1 0
12 7 22 1 0
12 7 21 1 0
12 7 20 1 64
12 8 37 2 32
12 8 36 2 0
12 8 35 2 0
12 8 34 2 0
12 8 33 2 0
12 8 32 2 0
12 8 31 2 0
12 8 30 1 0
12 8 29 1 0
12 8 28 1 0
12 8 27 1 0
12 8 26 1 0
12 8 25 1 0
12 8 24 1 0
12 8 23 1 0
12 8 22 1 0
12 8 21 1 0
12 8 20 1 64
12 9 37 2 32
12 9 36 2 0
12 9 35 2 0
12 9 34 2 0
12 9 33 2 0
12 9 32 2 0
12 9 31 2 0
12 9 30 1 0
12 9 29 1 0
12 9 28 1 0
12 9 27 1 0
12 9 26 1 0
12 9 25 1 0
12 9 24 1 0
12 9 23 1 0
12 9 22 1 0
12 9 21 1 0
12 9 20 1 64
12 10 37 2 32
12 10 36 2 0
12 10 35 2 0
12 10 34 2 0
12 10 33 2 0
12 10 32 2 0
12 10 31 2 0
12 10 30 1 0
12 10 29 1 0
12 10 28 1 0
12 10 27 1 0
12 10 26 1 0
12 10 25 1 0
12 10 24 1 0
12 10 23 1 0
12 10 22 1 0
12 10 21 1 0
12 10 20 1 64
12 11 37 2 32
12 11 36 2 0
12 11 35 2 0
12 11 34 2 0
12 11 33 2 0
12 11 32 2 0
12 11 31 2 0
12 11 30 1 0
12 11 29 1 0
12 11 28 1 0
12 11 27 1 0
12 11 26 1 0
12 11 25 1 0
12 11 24 1 0
12 11 23 1 0
12 11 22 1 0
12 11 21 1 0
12 11 20 1 64
12 12 37 2 32
12 12 36 2 0
12 12 35 2 0
12 12 34 2 0
12 12 33 2 0
12 12 32 2 0
12 12 31 2 0
12 12 30 1 0
12 12 29 1 0
12 12 28 1 0
12 12 27 1 0
12 12 26 1 0
12 12 25 1 0
12 12 24 1 0
12 12 23 1 0
12 12 22 1 0
12 12 21 1 0
12 12 20 1 64
12 13 37 2 32
12 13 36 2 0
12 13 35 2 0
12 13 34 2 0
12 13 33 2 0
12 13 32 2 0
12 13 31 2 0
12 13 30 1 0
12 13 29 1 0
12 13 28 1 0
12 13 27 1 0
12 13 26 1 0
12 13 25 1 0
12 13 24 1 0
12 13 23 1 0
12 13 22 1 0
12 13 21 1 0
12 13 20 1 64
12 14 37 2 32
12 14 36 2 0
12 14 35 2 0
12 14 34 2 0
12 14 33 2 0
12 14 32 2 0
12 14 31 2 0
12 14 30 2 0
12 14 29 2 0
12 14 28 2 0
12 14 27 2 0
12 14 26 2 0
12 14 25 2 0
12 14 24 2 0
12 14 23 2 0
12 14 22 2 0
12 14 21 2 0
12 14 20 2 64
12 15 37 2 32
12 15 36 2 0
12 15 35 2 0
12 15 34 2 0
12 15 33 2 0
12 15 32 2 0
12 15 31 2 0
12 15 30 2 0
12 15 29 2 0
12 15 28 2 0
12 15 27 2 0
12 15 26 2 0
12 15 25 2 0
12 15 24 2 0
12 15 23 2 0
12 15 22 2 0
12 15 21 2 0
12 15 20 2 64
12 16 37 2 32
12 16 36 2 0
12 16 35 2 0
12 16 34 2 0
12 16 33 2 0
12 16 32 2 0
12 16 31 2 0
12 16 30 2 0
12 16 29 2 0
12 16 28 2 0
12 16 27 2 0
12 16 26 2 0
12 16 25 2 0
12 16 24 2 0
12 16 23 2 0
12 16 22 2 0
12 16 21 2 0
12 16 20 2 64
12 17 37 2 32
12 17 36 2 0
12 17 35 2 0
12 17 34 2 0
12 17 33 2 0
12 17 32 2 0
12 17 31 2 0
12 17 30 2 0
12 17 29 2 0
12 17 28 2 0
12 17 27 2 0
12 17 26 2 0
12 17 25 2 0
12 17 24 2 0
12 17 23 2 0
12 17 22 2 0
12 17 21 2 0
12 17 20 2 64
12 18 37 2 32
12 18 36 2 0
12 18 35 2 0
12 18 34 2 0
12 18 33 2 0
12 18 32 2 0
12 18 31 2 0
12 18 30 2 0
12 18 29 2 0
12 18 28 2 0
12 18 27 2 0
12 18 26 2 0
12 18 25 2 0
12 18 24 2 0
12 18 23 2 0
12 18 22 2 0
12 18 21 2 0
12 18 20 2 64
12 18 12 7 116
12 18 10 7 116
12 18 8 7 116
12 19 37 2 32
12 19 36 2 0
12 19 35 2 0
12 19 34 2 0
12 19 33 2 0
12 19 32 2 0
12 19 31 2 0
12 19 30 2 0
12 19 29 2 0
12 19 28 2 0
12 19 27 2 0
12 19 26 2 0
12 19 25 2 0
12 19 24 2 0
12 19 23 2 0
12 19 22 2 0
12 19 21 2 0
12 19 20 2 64
12 19 12 7 96
12 19 10 7 96
12 19 8 7 96
12 20 37 2 32
12 20 36 2 0
12 20 35 2 0
12 20 34 2 0
12 20 33 2 0
12 20 32 2 0
12 20 31 2 0
12 20 30 2 0
12 20 29 2 0
12 20 28 2 0
12 20 27 2 0
12 20 26 2 0
12 20 25 2 0
12 20 24 2 0
12 20 23 2 0
12 20 22 2 0
12 20 21 2 0
12 20 20 2 64
12 20 12 5 32
12 20 11 5 16
12 20 10 5 0
12 20 9 5 16
12 20 8 5 0
12 20 7 5 18
12 20 6 5 18
12 20 5 5 18
12 20 4 5 18
12 20 3 5 18
12 20 2 5 18
12 20 1 5 18
12 20 0 5 82
12 21 37 2 32
12 21 36 2 0
12 21 35 2 0
12 21 34 2 0
12 21 33 2 0
12 21 32 2 0
12 21 31 2 0
12 21 30 2 0
12 21 29 2 0
12 21 28 2 0
12 21 27 2 0
12 21 26 2 0
12 21 25 2 0
12 21 24 2 0
12 21 23 2 0
12 21 22 2 0
12 21 21 2 0
12 21 20 2 64
12 21 12 7 32
12 21 11 7 0
12 21 10 7 0
12 21 9 7 0
12 21 8 7 0
12 21 7 7 0
12 21 6 7 0
12 21 5 7 0
12 21 4 7 0
12 21 3 7 0
12 21 2 7 0
12 21 1 7 0
12 21 0 7 72
12 22 37 2 32
12 22 36 2 0
12 22 35 2 0
12 22 34 2 0
12 22 33 2 0
12 22 32 2 0
12 22 31 2 0
12 22 30 2 0
12 22 29 2 0
12 22 28 2 0
12 22 27 2 0
12 22 26 2 0
12 22 25 13 0
12 22 24 13 0
12 22 23 13 0
12 22 22 13 0
12 22 21 13 0
12 22 20 13 0
12 22 19 13 16
12 22 18 13 16
12 22 17 13 16
12 22 16 13 16
12 22 15 13 16
12 22 14 13 16
12 22 13 13 16
12 22 12 17 8
12 22 11 17 8
12 22 10 17 8
12 22 9 17 8
12 22 8 17 8
12 22 7 17 8
12 22 6 17 8
12 22 5 17 8
12 22 4 17 8
12 22 3 17 8
12 22 2 17 8
12 22 1 17 72
12 23 37 2 32
12 23 36 2 0
12 23 35 2 0
12 23 34 2 0
12 23 33 2 0
12 23 32 2 0
12 23 31 2 0
12 23 30 13 0
12 23 29 13 0
12 23 28 13 0
12 23 27 13 0
12 23 26 13 0
12 23 25 13 0
12 23 24 13 0
12 23 23 13 0
12 23 22 13 0
12 23 21 13 0
12 23 20 13 0
12 23 19 13 0
12 23 18 13 0
12 23 17 13 8
12 23 16 13 8
12 23 15 13 8
12 23 14 13 8
12 23 13 13 72
12 24 37 2 32
12 24 36 2 0
12 24 35 2 0
12 24 34 2 0
12 24 33 2 0
12 24 32 2 0
12 24 31 2 0
12 24 30 13 0
12 24 29 13 0
12 24 28 13 0
12 24 27 13 0
12 24 26 13 0
12 24 25 13 0
12 24 24 13 0
12 24 23 13 0
12 24 22 13 0
12 24 21 13 8
12 24 20 13 8
12 24 19 13 8
12 24 18 13 72
12 25 37 2 32
12 25 36 2 0
12 25 35 2 0
12 25 34 2 0
12 25 33 2 0
12 25 32 2 0
12 25 31 2 0
12 25 30 8 0
12 25 29 8 0
12 25 28 8 0
12 25 27 8 0
12 25 26 8 0
12 25 25 8 0
12 25 24 8 0
12 25 23 8 0
12 25 22 8 64
12 26 37 2 32
12 26 36 2 0
12 26 35 2 0
12 26 34 2 0
12 26 33 2 0
12 26 32 2 0
12 26 31 2 0
12 26 30 8 0
12 26 29 8 0
12 26 28 8 0
12 26 27 8 0
12 26 26 8 0
12 26 25 8 0
12 26 24 8 0
12 26 23 8 0
12 26 22 8 0
12 26 21 8 82
12 27 37 2 32
12 27 36 2 0
12 27 35 2 0
12 27 34 2 0
12 27 33 2 0
12 27 32 2 0
12 27 31 2 0
12 27 30 8 0
12 27 29 8 0
12 27 28 8 0
12 27 27 8 0
12 27 26 8 0
12 27 25 8 0
12 27 24 8 0
12 27 23 8 2
12 27 22 8 2
12 27 21 8 2
12 27 20 8 18
12 27 19 8 18
12 27 18 8 90
12 28 37 2 32
12 28 36 2 0
12 28 35 2 0
12 28 34 2 0
12 28 33 2 0
12 28 32 2 0
12 28 31 2 0
12 28 30 8 0
12 28 29 8 0
12 28 28 8 0
12 28 27 8 0
12 28 26 8 0
12 28 25 8 0
12 28 24 8 0
12 28 23 11 10
12 28 22 11 10
12 28 21 11 10
12 28 20 11 10
12 28 19 11 74
12 29 37 2 32
12 29 36 2 0
12 29 35 2 0
12 29 34 2 0
12 29 33 2 0
12 29 32 2 0
12 29 31 2 0
12 29 30 8 0
12 29 29 8 0
12 29 28 8 0
12 29 27 8 0
12 29 26 8 0
12 29 25 8 0
12 29 24 8 64
12 30 37 2 32
12 30 36 2 0
12 30 35 2 0
12 30 34 2 0
12 30 33 2 0
12 30 32 2 0
12 30 31 2 0
12 30 30 8 0
12 30 29 8 0
12 30 28 8 0
12 30 27 8 0
12 30 26 8 0
12 30 25 8 0
12 30 24 8 64
12 31 37 2 32
12 31 36 2 0
12 31 35 2 0
12 31 34 2 0
12 31 33 2 0
12 31 32 2 0
12 31 31 2 0
12 31 30 8 0
12 31 29 8 0
12 31 28 8 0
12 31 27 8 0
12 31 26 8 0
12 31 25 8 0
12 31 24 8 72
12 32 37 2 32
12 32 36 2 0
12 32 35 2 0
12 32 34 2 0
12 32 33 2 0
12 32 32 2 0
12 32 31 2 0
12 32 30 8 0
12 32 29 8 0
12 32 28 8 0
12 32 27 8 0
12 32 26 8 0
12 32 25 15 64
12 33 37 2 32
12 33 36 2 0
12 33 35 2 0
12 33 34 2 0
12 33 33 2 0
12 33 32 2 0
12 33 31 2 0
12 33 30 8 0
12 33 29 8 0
12 33 28 8 0
12 33 27 8 8
12 33 26 8 8
12 33 25 8 8
12 33 24 8 88
12 34 37 2 32
12 34 36 2 0
12 34 35 2 0
12 34 34 2 0
12 34 33 2 0
12 34 32 2 0
12 34 31 2 0
12 34 30 10 0
12 34 29 10 0
12 34 28 12 64
12 35 37 2 32
12 35 36 2 0
12 35 35 2 0
12 35 34 2 0
12 35 33 2 0
12 35 32 2 0
12 35 31 2 0
12 35 30 10 0
12 35 29 10 0
12 35 28 12 64
12 36 37 2 32
12 36 36 2 0
12 36 35 2 0
12 36 34 2 0
12 36 33 2 0
12 36 32 2 0
12 36 31 2 0
12 36 30 10 0
12 36 29 10 0
12 36 28 12 64
12 37 37 2 32
12 37 36 2 0
12 37 35 2 0
12 37 34 2 0
12 37 33 2 0
12 37 32 2 0
12 37 31 2 0
12 37 30 10 0
12 37 29 10 0
12 37 28 12 64
12 38 37 2 32
12 38 36 2 0
12 38 35 2 0
12 38 34 2 0
12 38 33 2 0
12 38 32 2 0
12 38 31 2 0
12 38 30 10 0
12 38 29 10 0
12 38 28 12 64
12 39 37 2 32
12 39 36 2 0
12 39 35 2 0
12 39 34 2 0
12 39 33 2 0
12 39 32 2 0
12 39 31 2 0
12 39 30 10 0
12 39 29 10 0
12 39 28 12 64
12 40 37 2 32
12 40 36 2 0
12 40 35 2 0
12 40 34 2 0
12 40 33 2 0
12 40 32 2 0
12 40 31 2 0
12 40 30 10 0
12 40 29 10 0
12 40 28 12 64
12 41 37 2 32
12 41 36 2 0
12 41 35 2 0
12 41 34 2 0
12 41 33 2 0
12 41 32 2 0
12 41 31 2 0
12 41 30 10 0
12 41 29 10 0
12 41 28 12 64
12 42 37 2 32
12 42 36 2 0
12 42 35 2 0
12 42 34 2 0
12 42 33 2 0
12 42 32 2 0
12 42 31 2 0
12 42 30 10 4
12 42 29 10 4
12 42 28 12 68
12 43 37 2 32
12 43 36 2 0
12 43 35 2 0
12 43 34 2 0
12 43 33 2 0
12 43 32 2 0
12 43 31 2 0
12 43 30 10 4
12 43 29 10 4
12 43 28 12 68
12 44 37 2 32
12 44 36 2 0
12 44 35 2 0
12 44 34 2 0
12 44 33 2 0
12 44 32 2 0
12 44 31 2 0
12 44 30 10 4
12 44 29 10 4
12 44 28 12 68
12 45 37 2 32
12 45 36 2 0
12 45 35 2 0
12 45 34 2 0
12 45 33 2 0
12 45 32 2 0
12 45 31 2 0
12 45 30 10 4
12 45 29 10 4
12 45 28 12 68
12 46 37 2 32
12 46 36 2 0
12 46 35 2 0
12 46 34 2 0
12 46 33 2 0
12 46 32 2 0
12 46 31 2 0
12 46 30 10 4
12 46 29 10 4
12 46 28 12 68
12 47 37 2 32
12 47 36 2 0
12 47 35 2 0
12 47 34 2 0
12 47 33 2 0
12 47 32 2 0
12 47 31 2 0
12 47 30 10 4
12 47 29 10 6
12 47 28 12 68
12 48 37 2 32
12 48 36 2 0
12 48 35 2 0
12 48 34 2 0
12 48 33 2 0
12 48 32 2 0
12 48 31 2 0
12 48 30 10 12
12 48 29 10 14
12 48 28 12 76
12 49 37 2 32
12 49 36 2 0
12 49 35 2 0
12 49 34 2 0
12 49 33 2 0
12 49 32 2 0
12 49 31 2 64
12 50 37 2 32
12 50 36 2 0
12 50 35 2 0
12 50 34 2 0
12 50 33 2 0
12 50 32 2 0
12 50 31 2 64
12 51 37 2 32
12 51 36 2 0
12 51 35 2 0
12 51 34 2 0
12 51 33 2 0
12 51 32 2 0
12 51 31 2 64
12 52 37 2 32
12 52 36 2 0
12 52 35 2 0
12 52 34 2 0
12 52 33 2 0
12 52 32 2 0
12 52 31 2 64
12 53 37 2 32
12 53 36 2 0
12 53 35 2 0
12 53 34 2 0
12 53 33 2 0
12 53 32 2 0
12 53 31 2 64
12 54 37 2 32
12 54 36 2 0
12 54 35 2 0
12 54 34 2 0
12 54 33 2 0
12 54 32 2 0
12 54 31 2 64
12 55 37 2 32
12 55 36 2 0
12 55 35 2 0
12 55 34 2 0
12 55 33 2 0
12 55 32 2 0
12 55 31 2 64
12 56 37 2 32
12 56 36 2 0
12 56 35 2 0
12 56 34 2 0
12 56 33 2 0
12 56 32 2 0
12 56 31 2 64
12 57 37 2 32
12 57 36 2 0
12 57 35 2 0
12 57 34 2 0
12 57 33 2 0
12 57 32 2 0
12 57 31 2 64
12 58 37 2 32
12 58 36 2 0
12 58 35 2 0
12 58 34 2 0
12 58 33 2 0
12 58 32 2 0
12 58 31 2 64
12 59 37 2 32
12 59 36 2 0
12 59 35 2 0
12 59 34 2 0
12 59 33 2 0
12 59 32 2 0
12 59 31 2 64
12 60 37 2 34
12 60 36 2 2
12 60 35 2 2
12 60 34 2 2
12 60 33 2 2
12 60 32 2 2
12 60 31 2 66
12 61 37 2 42
12 61 36 2 10
12 61 35 2 10
12 61 34 2 10
12 61 33 2 10
12 61 32 2 10
12 61 31 2 74
13 1 37 1 48
13 1 36 1 16
13 1 35 1 16
13 1 34 1 16
13 1 33 1 16
13 1 32 1 16
13 1 31 1 16
13 1 30 1 16
13 1 29 1 16
13 1 28 1 16
13 1 27 1 16
13 1 26 1 16
13 1 25 7 16
13 1 24 7 16
13 1 23 7 16
13 1 22 7 16
13 1 21 7 16
13 1 20 7 16
13 1 19 7 20
13 1 18 7 28
13 1 17 7 28
13 1 16 7 28
13 1 15 7 28
13 1 14 7 28
13 1 13 7 28
13 1 12 7 28
13 1 11 7 28
13 1 10 7 28
13 1 9 7 28
13 1 8 7 84
13 2 37 1 32
13 2 36 1 0
13 2 35 1 0
13 2 34 1 0
13 2 33 1 0
13 2 32 1 0
13 2 31 1 0
13 2 30 1 0
13 2 29 1 0
13 2 28 1 0
13 2 27 1 0
13 2 26 1 0
13 2 25 7 0
13 2 24 7 0
13 2 23 7 0
13 2 22 7 0
13 2 21 7 0
13 2 20 7 0
13 2 19 7 68
13 2 8 7 100
13 3 37 1 32
13 3 36 1 0
13 3 35 1 0
13 3 34 1 0
13 3 33 1 0
13 3 32 1 0
13 3 31 1 0
13 3 30 1 0
13 3 29 1 0
13 3 28 1 0
13 3 27 1 0
13 3 26 1 0
13 3 25 7 0
13 3 24 7 0
13 3 23 7 0
13 3 22 7 0
13 3 21 7 0
13 3 20 7 0
13 3 19 7 68
13 3 17 7 52
13 3 16 7 20
13 3 15 7 20
13 3 14 7 20
13 3 13 7 20
13 3 12 7 20
13 3 11 7 20
13 3 10 7 84
13 3 8 7 100
13 4 37 1 32
13 4 36 1 0
13 4 35 1 0
13 4 34 1 0
13 4 33 1 0
13 4 32 1 0
13 4 31 1 0
13 4 30 1 0
13 4 29 1 0
13 4 28 1 0
13 4 27 1 0
13 4 26 1 0
13 4 25 7 0
13 4 24 7 0
13 4 23 7 0
13 4 22 7 0
13 4 21 7 0
13 4 20 7 0
13 4 19 7 68
13 4 17 7 36
13 4 16 7 4
13 4 15 7 4
13 4 14 7 4
13 4 13 7 4
13 4 12 7 4
13 4 11 7 4
13 4 10 7 68
13 4 8 7 100
13 5 37 1 32
13 5 36 1 0
13 5 35 1 0
13 5 34 1 0
13 5 33 1 0
13 5 32 1 0
13 5 31 1 0
13 5 30 1 0
13 5 29 1 0
13 5 28 1 0
13 5 27 1 0
13 5 26 1 0
13 5 25 7 0
13 5 24 7 0
13 5 23 7 0
13 5 22 7 0
13 5 21 7 0
13 5 20 7 0
13 5 19 7 68
13 5 17 7 36
13 5 16 7 4
13 5 15 7 4
13 5 14 7 4
13 5 13 7 4
13 5 12 7 4
13 5 11 7 4
13 5 10 7 68
13 5 8 7 100
13 6 37 1 32
13 6 36 1 0
13 6 35 1 0
13 6 34 1 0
13 6 33 1 0
13 6 32 1 0
13 6 31 1 0
13 6 30 1 0
13 6 29 1 0
13 6 28 1 0
13 6 27 1 0
13 6 26 1 0
13 6 25 7 0
13 6 24 7 0
13 6 23 7 0
13 6 22 7 0
13 6 21 7 0
13 6 20 7 0
13 6 19 7 68
13 6 17 7 36
13 6 16 7 4
13 6 15 7 4
13 6 14 7 4
13 6 13 7 4
13 6 12 7 4
13 6 11 7 4
13 6 10 7 68
13 6 8 7 100
13 7 37 1 32
13 7 36 1 0
13 7 35 1 0
13 7 34 1 0
13 7 33 1 0
13 7 32 1 0
13 7 31 1 0
13 7 30 1 0
13 7 29 1 0
13 7 28 1 0
13 7 27 1 0
13 7 26 1 0
13 7 25 7 0
13 7 24 7 0
13 7 23 7 0
13 7 22 7 0
13 7 21 7 0
13 7 20 7 0
13 7 19 7 68
13 7 17 7 36
13 7 16 7 4
13 7 15 7 4
13 7 14 7 4
13 7 13 7 4
13 7 12 7 4
13 7 11 7 4
13 7 10 7 68
13 7 8 7 100
13 8 37 2 32
13 8 36 2 0
13 8 35 2 0
13 8 34 2 0
13 8 33 2 0
13 8 32 2 0
13 8 31 2 0
13 8 30 1 0
13 8 29 1 0
13 8 28 1 0
13 8 27 1 0
13 8 26 1 0
13 8 25 7 0
13 8 24 7 0
13 8 23 7 0
13 8 22 7 0
13 8 21 7 0
13 8 20 7 0
13 8 19 7 68
13 8 17 7 36
13 8 16 7 4
13 8 15 7 4
13 8 14 7 4
13 8 13 7 4
13 8 12 7 4
13 8 11 7 4
13 8 10 7 68
13 8 8 7 100
13 9 37 2 32
13 9 36 2 0
13 9 35 2 0
13 9 34 2 0
13 9 33 2 0
13 9 32 2 0
13 9 31 2 0
13 9 30 1 0
13 9 29 1 0
13 9 28 1 0
13 9 27 1 0
13 9 26 1 0
13 9 25 7 0
13 9 24 7 0
13 9 23 7 0
13 9 22 7 0
13 9 21 7 0
13 9 20 7 0
13 9 19 7 68
13 9 17 7 36
13 9 16 7 4
13 9 15 7 4
13 9 14 7 4
13 9 13 7 4
13 9 12 7 4
13 9 11 7 4
13 9 10 7 68
13 9 8 7 100
13 10 37 2 32
13 10 36 2 0
13 10 35 2 0
13 10 34 2 0
13 10 33 2 0
13 10 32 2 0
13 10 31 2 0
13 10 30 1 0
13 10 29 1 0
13 10 28 1 0
13 10 27 1 0
13 10 26 1 0
13 10 25 7 0
13 10 24 7 0
13 10 23 7 0
13 10 22 7 0
13 10 21 7 0
13 10 20 7 0
13 10 19 7 68
13 10 17 7 44
13 10 16 7 4
13 10 15 7 4
13 10 14 7 4
13 10 13 7 4
13 10 12 7 4
13 10 11 7 4
13 10 10 7 76
13 10 8 7 100
13 11 37 2 32
13 11 36 2 0
13 11 35 2 0
13 11 34 2 0
13 11 33 2 0
13 11 32 2 0
13 11 31 2 0
13 11 30 1 0
13 11 29 1 0
13 11 28 1 0
13 11 27 1 0
13 11 26 1 0
13 11 25 7 0
13 11 24 7 0
13 11 23 7 0
13 11 22 7 0
13 11 21 7 0
13 11 20 7 0
13 11 19 7 68
13 11 16 7 44
13 11 15 7 12
13 11 14 7 12
13 11 13 7 12
13 11 12 7 12
13 11 11 7 76
13 11 8 7 100
13 12 37 2 32
13 12 36 2 0
13 12 35 2 0
13 12 34 2 0
13 12 33 2 0
13 12 32 2 0
13 12 31 2 0
13 12 30 1 0
13 12 29 1 0
13 12 28 1 0
13 12 27 1 0
13 12 26 1 0
13 12 25 7 0
13 12 24 7 0
13 12 23 7 0
13 12 22 7 0
13 12 21 7 0
13 12 20 7 0
13 12 19 7 4
13 12 18 7 84
13 12 9 7 52
13 12 8 7 68
13 13 37 2 32
13 13 36 2 0
13 13 35 2 0
13 13 34 2 0
13 13 33 2 0
13 13 32 2 0
13 13 31 2 0
13 13 30 1 0
13 13 29 1 0
13 13 28 1 0
13 13 27 1 0
13 13 26 1 0
13 13 25 7 0
13 13 24 7 0
13 13 23 7 0
13 13 22 7 0
13 13 21 7 0
13 13 20 7 0
13 13 19 7 4
13 13 18 7 4
13 13 17 7 20
13 13 16 7 20
13 13 15 7 20
13 13 14 7 20
13 13 13 7 20
13 13 12 7 20
13 13 11 7 20
13 13 10 7 20
13 13 9 7 4
13 13 8 7 68
13 14 37 2 32
13 14 36 2 0
13 14 35 2 0
13 14 34 2 0
13 14 33 2 0
13 14 32 2 0
13 14 31 2 0
13 14 30 2 0
13 14 29 2 0
13 14 28 2 0
13 14 27 2 0
13 14 26 2 0
13 14 25 7 0
13 14 24 7 0
13 14 23 7 0
13 14 22 7 0
13 14 21 7 0
13 14 20 7 0
13 14 19 7 12
13 14 18 7 12
13 14 17 7 12
13 14 16 7 12
13 14 15 7 12
13 14 14 7 12
13 14 13 7 12
13 14 12 7 12
13 14 11 7 12
13 14 10 7 12
13 14 9 7 12
13 14 8 7 68
13 15 37 2 32
13 15 36 2 0
13 15 35 2 0
13 15 34 2 0
13 15 33 2 0
13 15 32 2 0
13 15 31 2 0
13 15 30 2 0
13 15 29 2 0
13 15 28 2 0
13 15 27 2 0
13 15 26 2 0
13 15 25 7 0
13 15 24 7 0
13 15 23 7 0
13 15 22 7 0
13 15 21 7 0
13 15 20 7 64
13 15 8 7 102
13 16 37 2 32
13 16 36 2 0
13 16 35 2 0
13 16 34 2 0
13 16 33 2 0
13 16 32 2 0
13 16 31 2 0
13 16 30 2 0
13 16 29 2 0
13 16 28 2 0
13 16 27 2 0
13 16 26 2 0
13 16 25 7 0
13 16 24 7 0
13 16 23 7 0
13 16 22 7 0
13 16 21 7 0
13 16 20 7 64
13 16 8 7 102
13 17 37 2 32
13 17 36 2 0
13 17 35 2 0
13 17 34 2 0
13 17 33 2 0
13 17 32 2 0
13 17 31 2 0
13 17 30 2 0
13 17 29 2 0
13 17 28 2 0
13 17 27 2 0
13 17 26 2 0
13 17 25 7 0
13 17 24 7 0
13 17 23 7 0
13 17 22 7 0
13 17 21 7 0
13 17 20 7 64
13 17 8 7 102
13 18 37 2 32
13 18 36 2 0
13 18 35 2 0
13 18 34 2 0
13 18 33 2 0
13 18 32 2 0
13 18 31 2 0
13 18 30 2 0
13 18 29 2 0
13 18 28 2 0
13 18 27 2 0
13 18 26 2 0
13 18 25 7 0
13 18 24 7 0
13 18 23 7 0
13 18 22 7 0
13 18 21 7 0
13 18 20 7 0
13 18 19 7 20
13 18 18 7 20
13 18 17 7 20
13 18 16 7 20
13 18 15 7 20
13 18 14 7 20
13 18 13 7 20
13 18 12 7 16
13 18 11 7 20
13 18 10 7 16
13 18 9 7 20
13 18 8 7 64
13 19 37 2 32
13 19 36 2 0
13 19 35 2 0
13 19 34 2 0
13 19 33 2 0
13 19 32 2 0
13 19 31 2 0
13 19 30 2 0
13 19 29 2 0
13 19 28 2 0
13 19 27 2 0
13 19 26 2 0
13 19 25 7 0
13 19 24 7 0
13 19 23 7 0
13 19 22 7 0
13 19 21 7 0
13 19 20 7 0
13 19 19 7 4
13 19 18 7 4
13 19 17 7 4
13 19 16 7 4
13 19 15 7 4
13 19 14 7 4
13 19 13 7 4
13 19 12 7 2
13 19 11 7 6
13 19 10 7 2
13 19 9 7 6
13 19 8 7 66
13 20 37 2 32
13 20 36 2 0
13 20 35 2 0
13 20 34 2 0
13 20 33 2 0
13 20 32 2 0
13 20 31 2 0
13 20 30 2 0
13 20 29 2 0
13 20 28 2 0
13 20 27 2 0
13 20 26 2 0
13 20 25 7 0
13 20 24 7 0
13 20 23 7 0
13 20 22 7 0
13 20 21 7 0
13 20 20 7 0
13 20 19 7 4
13 20 18 7 4
13 20 17 7 4
13 20 16 7 4
13 20 15 7 4
13 20 14 7 4
13 20 13 7 4
13 20 12 7 2
13 20 11 7 2
13 20 10 7 2
13 20 9 7 2
13 20 8 7 66
13 21 37 2 32
13 21 36 2 0
13 21 35 2 0
13 21 34 2 0
13 21 33 2 0
13 21 32 2 0
13 21 31 2 0
13 21 30 2 0
13 21 29 2 0
13 21 28 2 0
13 21 27 2 0
13 21 26 2 0
13 21 25 7 0
13 21 24 7 0
13 21 23 7 0
13 21 22 7 0
13 21 21 7 0
13 21 20 7 0
13 21 19 7 4
13 21 18 7 4
13 21 17 7 4
13 21 16 7 4
13 21 15 7 4
13 21 14 7 4
13 21 13 7 6
13 21 12 7 2
13 21 11 7 2
13 21 10 7 2
13 21 9 7 2
13 21 8 7 2
13 21 7 7 18
13 21 6 7 18
13 21 5 7 18
13 21 4 7 18
13 21 3 7 18
13 21 2 7 18
13 21 1 7 18
13 21 0 7 90
13 22 37 2 32
13 22 36 2 0
13 22 35 2 0
13 22 34 2 0
13 22 33 2 0
13 22 32 2 0
13 22 31 2 0
13 22 30 2 0
13 22 29 2 0
13 22 28 2 0
13 22 27 2 0
13 22 26 2 0
13 22 25 13 0
13 22 24 13 0
13 22 23 13 0
13 22 22 13 0
13 22 21 13 0
13 22 20 13 0
13 22 19 13 0
13 22 18 13 0
13 22 17 13 0
13 22 16 13 0
13 22 15 13 0
13 22 14 13 0
13 22 13 13 0
13 22 12 17 10
13 22 11 17 10
13 22 10 17 10
13 22 9 17 10
13 22 8 17 10
13 22 7 17 10
13 22 6 17 10
13 22 5 17 10
13 22 4 17 10
13 22 3 17 10
13 22 2 17 10
13 22 1 17 74
13 23 37 2 32
13 23 36 2 0
13 23 35 2 0
13 23 34 2 0
13 23 33 2 0
13 23 32 2 0
13 23 31 2 0
13 23 30 13 0
13 23 29 13 0
13 23 28 13 0
13 23 27 13 0
13 23 26 13 0
13 23 25 13 0
13 23 24 13 0
13 23 23 13 0
13 23 22 13 0
13 23 21 13 0
13 23 20 13 0
13 23 19 13 0
13 23 18 13 0
13 23 17 13 10
13 23 16 13 10
13 23 15 13 10
13 23 14 13 10
13 23 13 13 74
13 24 37 2 32
13 24 36 2 0
13 24 35 2 0
13 24 34 2 0
13 24 33 2 0
13 24 32 2 0
13 24 31 2 0
13 24 30 13 0
13 24 29 13 0
13 24 28 13 0
13 24 27 13 0
13 24 26 13 0
13 24 25 13 0
13 24 24 13 0
13 24 23 13 0
13 24 22 13 0
13 24 21 13 8
13 24 20 13 8
13 24 19 13 8
13 24 18 13 72
13 25 37 2 32
13 25 36 2 0
13 25 35 2 0
13 25 34 2 0
13 25 33 2 0
13 25 32 2 0
13 25 31 2 0
13 25 30 8 0
13 25 29 8 0
13 25 28 8 0
13 25 27 8 0
13 25 26 8 0
13 25 25 8 0
13 25 24 8 0
13 25 23 8 0
13 25 22 8 64
13 26 37 2 32
13 26 36 2 0
13 26 35 2 0
13 26 34 2 0
13 26 33 2 0
13 26 32 2 0
13 26 31 2 0
13 26 30 8 0
13 26 29 8 0
13 26 28 8 0
13 26 27 8 0
13 26 26 8 0
13 26 25 8 0
13 26 24 8 0
13 26 23 8 8
13 26 22 8 72
13 27 37 2 32
13 27 36 2 0
13 27 35 2 0
13 27 34 2 0
13 27 33 2 0
13 27 32 2 0
13 27 31 2 0
13 27 30 8 0
13 27 29 8 0
13 27 28 8 0
13 27 27 8 0
13 27 26 8 0
13 27 25 8 0
13 27 24 8 64
13 28 37 2 32
13 28 36 2 0
13 28 35 2 0
13 28 34 2 0
13 28 33 2 0
13 28 32 2 0
13 28 31 2 0
13 28 30 8 0
13 28 29 8 0
13 28 28 8 0
13 28 27 8 0
13 28 26 8 0
13 28 25 8 0
13 28 24 8 64
13 29 37 2 32
13 29 36 2 0
13 29 35 2 0
13 29 34 2 0
13 29 33 2 0
13 29 32 2 0
13 29 31 2 0
13 29 30 8 0
13 29 29 8 0
13 29 28 8 0
13 29 27 8 0
13 29 26 8 0
13 29 25 8 0
13 29 24 8 64
13 30 37 2 32
13 30 36 2 0
13 30 35 2 0
13 30 34 2 0
13 30 33 2 0
13 30 32 2 0
13 30 31 2 0
13 30 30 8 0
13 30 29 8 0
13 30 28 8 0
13 30 27 8 0
13 30 26 8 0
13 30 25 8 0
13 30 24 8 64
13 31 37 2 32
13 31 36 2 0
13 31 35 2 0
13 31 34 2 0
13 31 33 2 0
13 31 32 2 0
13 31 31 2 0
13 31 30 8 0
13 31 29 8 0
13 31 28 8 0
13 31 27 8 0
13 31 26 8 0
13 31 25 8 0
13 31 24 8 72
13 32 37 2 32
13 32 36 2 0
13 32 35 2 0
13 32 34 2 0
13 32 33 2 0
13 32 32 2 0
13 32 31 2 0
13 32 30 8 0
13 32 29 8 0
13 32 28 8 0
13 32 27 8 0
13 32 26 8 0
13 32 25 15 64
13 33 37 2 32
13 33 36 2 0
13 33 35 2 0
13 33 34 2 0
13 33 33 2 0
13 33 32 2 0
13 33 31 2 0
13 33 30 8 0
13 33 29 8 0
13 33 28 8 0
13 33 27 8 8
13 33 26 8 8
13 33 25 8 8
13 33 24 8 88
13 34 37 2 32
13 34 36 2 0
13 34 35 2 0
13 34 34 2 0
13 34 33 2 0
13 34 32 2 0
13 34 31 2 0
13 34 30 10 0
13 34 29 10 0
13 34 28 10 64
13 35 37 2 32
13 35 36 2 0
13 35 35 2 0
13 35 34 2 0
13 35 33 2 0
13 35 32 2 0
13 35 31 2 0
13 35 30 10 0
13 35 29 10 0
13 35 28 10 64
13 36 37 2 32
13 36 36 2 0
13 36 35 2 0
13 36 34 2 0
13 36 33 2 0
13 36 32 2 0
13 36 31 2 0
13 36 30 10 0
13 36 29 10 0
13 36 28 10 64
13 37 37 2 32
13 37 36 2 0
13 37 35 2 0
13 37 34 2 0
13 37 33 2 0
13 37 32 2 0
13 37 31 2 0
13 37 30 10 0
13 37 29 10 0
13 37 28 10 64
13 38 37 2 32
13 38 36 2 0
13 38 35 2 0
13 38 34 2 0
13 38 33 2 0
13 38 32 2 0
13 38 31 2 0
13 38 30 10 0
13 38 29 10 0
13 38 28 10 64
13 39 37 2 32
13 39 36 2 0
13 39 35 2 0
13 39 34 2 0
13 39 33 2 0
13 39 32 2 0
13 39 31 2 0
13 39 30 10 0
13 39 29 10 0
13 39 28 10 64
13 40 37 2 32
13 40 36 2 0
13 40 35 2 0
13 40 34 2 0
13 40 33 2 0
13 40 32 2 0
13 40 31 2 0
13 40 30 10 0
13 40 29 10 0
13 40 28 10 64
13 41 37 2 32
13 41 36 2 0
13 41 35 2 0
13 41 34 2 0
13 41 33 2 0
13 41 32 2 0
13 41 31 2 0
13 41 30 10 0
13 41 29 10 0
13 41 28 10 64
13 42 37 2 32
13 42 36 2 0
13 42 35 2 0
13 42 34 2 0
13 42 33 2 0
13 42 32 2 0
13 42 31 2 0
13 42 30 10 0
13 42 29 10 0
13 42 28 10 64
13 43 37 2 32
13 43 36 2 0
13 43 35 2 0
13 43 34 2 0
13 43 33 2 0
13 43 32 2 0
13 43 31 2 0
13 43 30 10 0
13 43 29 10 0
13 43 28 10 64
13 44 37 2 32
13 44 36 2 0
13 44 35 2 0
13 44 34 2 0
13 44 33 2 0
13 44 32 2 0
13 44 31 2 0
13 44 30 10 0
13 44 29 10 0
13 44 28 10 64
13 45 37 2 32
13 45 36 2 0
13 45 35 2 0
13 45 34 2 0
13 45 33 2 0
13 45 32 2 0
13 45 31 2 0
13 45 30 10 0
13 45 29 10 0
13 45 28 10 64
13 46 37 2 32
13 46 36 2 0
13 46 35 2 0
13 46 34 2 0
13 46 33 2 0
13 46 32 2 0
13 46 31 2 0
13 46 30 10 0
13 46 29 10 8
13 46 28 10 64
13 47 37 2 32
13 47 36 2 0
13 47 35 2 0
13 47 34 2 0
13 47 33 2 0
13 47 32 2 0
13 47 31 2 0
13 47 30 10 64
13 47 28 10 96
13 48 37 2 32
13 48 36 2 0
13 48 35 2 0
13 48 34 2 0
13 48 33 2 0
13 48 32 2 0
13 48 31 2 0
13 48 30 10 72
13 48 28 10 104
13 49 37 2 32
13 49 36 2 0
13 49 35 2 0
13 49 34 2 0
13 49 33 2 0
13 49 32 2 0
13 49 31 2 64
13 50 37 2 32
13 50 36 2 0
13 50 35 2 0
13 50 34 2 0
13 50 33 2 0
13 50 32 2 0
13 50 31 2 64
13 51 37 2 32
13 51 36 2 0
13 51 35 2 0
13 51 34 2 0
13 51 33 2 0
13 51 32 2 0
13 51 31 2 64
13 52 37 2 32
13 52 36 2 0
13 52 35 2 0
13 52 34 2 0
13 52 33 2 0
13 52 32 2 0
13 52 31 2 64
13 53 37 2 32
13 53 36 2 0
13 53 35 2 0
13 53 34 2 0
13 53 33 2 0
13 53 32 2 0
13 53 31 2 64
13 54 37 2 32
13 54 36 2 0
13 54 35 2 0
13 54 34 2 0
13 54 33 2 0
13 54 32 2 0
13 54 31 2 64
13 55 37 2 32
13 55 36 2 0
13 55 35 2 0
13 55 34 2 0
13 55 33 2 0
13 55 32 2 0
13 55 31 2 64
13 56 37 2 32
13 56 36 2 0
13 56 35 2 0
13 56 34 2 0
13 56 33 2 0
13 56 32 2 0
13 56 31 2 64
13 57 37 2 32
13 57 36 2 0
13 57 35 2 0
13 57 34 2 0
13 57 33 2 0
13 57 32 2 0
13 57 31 2 64
13 58 37 2 32
13 58 36 2 0
13 58 35 2 0
13 58 34 2 0
13 58 33 2 0
13 58 32 2 0
13 58 31 2 64
13 59 37 2 40
13 59 36 2 8
13 59 35 2 8
13 59 34 2 8
13 59 33 2 8
13 59 32 2 8
13 59 31 2 72
14 1 37 1 48
14 1 36 1 16
14 1 35 1 16
14 1 34 1 16
14 1 33 1 16
14 1 32 1 16
14 1 31 1 16
14 1 30 1 16
14 1 29 1 16
14 1 28 1 16
14 1 27 1 16
14 1 26 1 16
14 1 25 7 16
14 1 24 5 16
14 1 23 5 16
14 1 22 5 16
14 1 21 5 16
14 1 20 7 16
14 1 19 7 16
14 1 18 7 16
14 1 17 7 16
14 1 16 7 16
14 1 15 7 16
14 1 14 7 16
14 1 13 7 16
14 1 12 7 16
14 1 11 7 16
14 1 10 7 16
14 1 9 7 16
14 1 8 7 80
14 2 37 1 32
14 2 36 1 0
14 2 35 1 0
14 2 34 1 0
14 2 33 1 0
14 2 32 1 0
14 2 31 1 0
14 2 30 1 0
14 2 29 1 0
14 2 28 1 0
14 2 27 1 0
14 2 26 1 0
14 2 25 7 0
14 2 24 5 0
14 2 23 5 0
14 2 22 5 0
14 2 21 5 0
14 2 20 7 0
14 2 19 7 0
14 2 18 7 4
14 2 17 7 4
14 2 16 7 4
14 2 15 7 4
14 2 14 7 4
14 2 13 7 4
14 2 12 7 4
14 2 11 7 4
14 2 10 7 4
14 2 9 7 4
14 2 8 7 64
14 3 37 1 32
14 3 36 1 0
14 3 35 1 0
14 3 34 1 0
14 3 33 1 0
14 3 32 1 0
14 3 31 1 0
14 3 30 1 0
14 3 29 1 0
14 3 28 1 0
14 3 27 1 0
14 3 26 1 0
14 3 25 7 0
14 3 24 5 0
14 3 23 5 0
14 3 22 5 0
14 3 21 5 0
14 3 20 7 0
14 3 19 7 0
14 3 18 7 4
14 3 17 7 0
14 3 16 7 0
14 3 15 7 0
14 3 14 7 0
14 3 13 7 0
14 3 12 7 0
14 3 11 7 0
14 3 10 7 0
14 3 9 7 4
14 3 8 7 64
14 4 37 1 32
14 4 36 1 0
14 4 35 1 0
14 4 34 1 0
14 4 33 1 0
14 4 32 1 0
14 4 31 1 0
14 4 30 1 0
14 4 29 1 0
14 4 28 1 0
14 4 27 1 0
14 4 26 1 0
14 4 25 7 0
14 4 24 5 0
14 4 23 5 0
14 4 22 5 0
14 4 21 5 0
14 4 20 7 0
14 4 19 7 0
14 4 18 7 4
14 4 17 7 0
14 4 16 7 0
14 4 15 7 0
14 4 14 7 0
14 4 13 7 0
14 4 12 7 0
14 4 11 7 0
14 4 10 7 0
14 4 9 7 4
14 4 8 7 64
14 5 37 1 32
14 5 36 1 0
14 5 35 1 0
14 5 34 1 0
14 5 33 1 0
14 5 32 1 0
14 5 31 1 0
14 5 30 1 0
14 5 29 1 0
14 5 28 1 0
14 5 27 1 0
14 5 26 1 0
14 5 25 7 0
14 5 24 5 0
14 5 23 5 0
14 5 22 5 0
14 5 21 5 0
14 5 20 7 0
14 5 19 7 0
14 5 18 7 4
14 5 17 7 0
14 5 16 7 0
14 5 15 7 0
14 5 14 7 0
14 5 13 7 0
14 5 12 7 0
14 5 11 7 0
14 5 10 7 0
14 5 9 7 4
14 5 8 7 64
14 6 37 1 32
14 6 36 1 0
14 6 35 1 0
14 6 34 1 0
14 6 33 1 0
14 6 32 1 0
14 6 31 1 0
14 6 30 1 0
14 6 29 1 0
14 6 28 1 0
14 6 27 1 0
14 6 26 1 0
14 6 25 7 0
14 6 24 5 0
14 6 23 5 0
14 6 22 5 0
14 6 21 5 0
14 6 20 7 0
14 6 19 7 0
14 6 18 7 4
14 6 17 7 0
14 6 16 7 0
14 6 15 7 0
14 6 14 7 0
14 6 13 7 0
14 6 12 7 0
14 6 11 7 0
14 6 10 7 0
14 6 9 7 4
14 6 8 7 64
14 7 37 1 32
14 7 36 1 0
14 7 35 1 0
14 7 34 1 0
14 7 33 1 0
14 7 32 1 0
14 7 31 1 0
14 7 30 1 0
14 7 29 1 0
14 7 28 1 0
14 7 27 1 0
14 7 26 1 0
14 7 25 7 0
14 7 24 5 0
14 7 23 5 0
14 7 22 5 0
14 7 21 5 0
