Qubicle Exchange Format
Version 0.2
www.minddesk.com
249 147 151
1
0.701961 0.309804 0.231373
1 119 149 0 52
1 119 148 0 20
1 119 147 0 84
1 119 2 0 52
1 119 1 0 20
1 119 0 0 84
1 120 149 0 36
1 120 148 0 4
1 120 147 0 68
1 120 2 0 36
1 120 1 0 4
1 120 0 0 68
1 121 149 0 36
1 121 148 0 4
1 121 147 0 68
1 121 2 0 36
1 121 1 0 4
1 121 0 0 68
1 122 149 0 36
1 122 148 0 4
1 122 147 0 68
1 122 2 0 36
1 122 1 0 4
1 122 0 0 68
1 123 149 0 44
1 123 148 0 12
1 123 147 0 76
1 123 2 0 44
1 123 1 0 12
1 123 0 0 76
2 118 149 0 52
2 118 148 0 20
2 118 147 0 84
2 118 2 0 52
2 118 1 0 20
2 118 0 0 84
2 119 149 0 32
2 119 148 0 0
2 119 147 0 64
2 119 2 0 32
2 119 1 0 0
2 119 0 0 64
2 120 149 0 32
2 120 148 0 0
2 120 147 0 64
2 120 2 0 32
2 120 1 0 0
2 120 0 0 64
2 121 149 0 32
2 121 148 0 0
2 121 147 0 64
2 121 2 0 32
2 121 1 0 0
2 121 0 0 64
2 122 149 0 34
2 122 148 0 2
2 122 147 0 66
2 122 2 0 34
2 122 1 0 2
2 122 0 0 66
2 123 149 0 32
2 123 148 0 0
2 123 147 0 64
2 123 2 0 32
2 123 1 0 0
2 123 0 0 64
2 124 149 0 44
2 124 148 0 12
2 124 147 0 76
2 124 2 0 44
2 124 1 0 12
2 124 0 0 76
3 117 149 0 52
3 117 148 0 20
3 117 147 0 84
3 117 2 0 52
3 117 1 0 20
3 117 0 0 84
3 118 149 0 32
3 118 148 0 0
3 118 147 0 64
3 118 2 0 32
3 118 1 0 0
3 118 0 0 64
3 119 149 0 32
3 119 148 0 0
3 119 147 0 64
3 119 2 0 32
3 119 1 0 0
3 119 0 0 64
3 120 149 0 32
3 120 148 0 0
3 120 147 0 64
3 120 2 0 32
3 120 1 0 0
3 120 0 0 64
3 121 149 0 42
3 121 148 0 10
3 121 147 0 74
3 121 2 0 42
3 121 1 0 10
3 121 0 0 74
3 123 149 0 50
3 123 148 0 18
3 123 147 0 82
3 123 2 0 50
3 123 1 0 18
3 123 0 0 82
3 124 149 0 40
3 124 148 0 8
3 124 147 0 72
3 124 2 0 40
3 124 1 0 8
3 124 0 0 72
4 117 149 0 48
4 117 148 0 16
4 117 147 0 80
4 117 2 0 48
4 117 1 0 16
4 117 0 0 80
4 118 149 0 32
4 118 148 0 0
4 118 147 0 64
4 118 2 0 32
4 118 1 0 0
4 118 0 0 64
4 119 149 0 32
4 119 148 0 0
4 119 147 0 64
4 119 2 0 32
4 119 1 0 0
4 119 0 0 64
4 120 149 0 42
4 120 148 0 10
4 120 147 0 74
4 120 2 0 42
4 120 1 0 10
4 120 0 0 74
4 124 149 0 58
4 124 148 0 26
4 124 147 0 90
4 124 2 0 58
4 124 1 0 26
4 124 0 0 90
5 117 149 0 48
5 117 148 0 16
5 117 147 0 80
5 117 2 0 48
5 117 1 0 16
5 117 0 0 80
5 118 149 0 32
5 118 148 0 0
5 118 147 0 64
5 118 2 0 32
5 118 1 0 0
5 118 0 0 64
5 119 149 0 40
5 119 148 0 8
5 119 147 0 72
5 119 2 0 40
5 119 1 0 8
5 119 0 0 72
6 117 149 0 48
6 117 148 0 16
6 117 147 0 80
6 117 2 0 48
6 117 1 0 16
6 117 0 0 80
6 118 149 0 32
6 118 148 0 0
6 118 147 0 64
6 118 2 0 32
6 118 1 0 0
6 118 0 0 64
6 119 149 0 40
6 119 148 0 8
6 119 147 0 72
6 119 2 0 40
6 119 1 0 8
6 119 0 0 72
7 117 149 0 48
7 117 148 0 16
7 117 147 0 80
7 117 2 0 48
7 117 1 0 16
7 117 0 0 80
7 118 149 0 32
7 118 148 0 0
7 118 147 0 64
7 118 2 0 32
7 118 1 0 0
7 118 0 0 64
7 119 149 0 40
7 119 148 0 8
7 119 147 0 72
7 119 2 0 40
7 119 1 0 8
7 119 0 0 72
8 117 149 0 48
8 117 148 0 16
8 117 147 0 80
8 117 2 0 48
8 117 1 0 16
8 117 0 0 80
8 118 149 0 32
8 118 148 0 0
8 118 147 0 64
8 118 2 0 32
8 118 1 0 0
8 118 0 0 64
8 119 149 0 40
8 119 148 0 8
8 119 147 0 72
8 119 2 0 40
8 119 1 0 8
8 119 0 0 72
9 117 149 0 48
9 117 148 0 16
9 117 147 0 80
9 117 2 0 48
9 117 1 0 16
9 117 0 0 80
9 118 149 0 32
9 118 148 0 0
9 118 147 0 64
9 118 2 0 32
9 118 1 0 0
9 118 0 0 64
9 119 149 0 40
9 119 148 0 8
9 119 147 0 72
9 119 2 0 40
9 119 1 0 8
9 119 0 0 72
10 117 149 0 48
10 117 148 0 16
10 117 147 0 80
10 117 2 0 48
10 117 1 0 16
10 117 0 0 80
10 118 149 0 32
10 118 148 0 0
10 118 147 0 64
10 118 2 0 32
10 118 1 0 0
10 118 0 0 64
10 119 149 0 40
10 119 148 0 8
10 119 147 0 72
10 119 2 0 40
10 119 1 0 8
10 119 0 0 72
11 117 149 0 48
11 117 148 0 16
11 117 147 0 80
11 117 2 0 48
11 117 1 0 16
11 117 0 0 80
11 118 149 0 32
11 118 148 0 0
11 118 147 0 64
11 118 2 0 32
11 118 1 0 0
11 118 0 0 64
11 119 149 0 40
11 119 148 0 8
11 119 147 0 72
11 119 2 0 40
11 119 1 0 8
11 119 0 0 72
12 114 149 0 60
12 114 148 0 28
12 114 147 0 92
12 114 2 0 60
12 114 1 0 28
12 114 0 0 92
12 117 149 0 48
12 117 148 0 16
12 117 147 0 80
12 117 2 0 48
12 117 1 0 16
12 117 0 0 80
12 118 149 0 32
12 118 148 0 0
12 118 147 0 64
12 118 2 0 32
12 118 1 0 0
12 118 0 0 64
12 119 149 0 40
12 119 148 0 8
12 119 147 0 72
12 119 2 0 40
12 119 1 0 8
12 119 0 0 72
13 113 149 0 52
13 113 148 0 20
13 113 147 0 84
13 113 2 0 52
13 113 1 0 20
13 113 0 0 84
13 114 149 0 34
13 114 148 0 2
13 114 147 0 66
13 114 2 0 34
13 114 1 0 2
13 114 0 0 66
13 115 149 0 44
13 115 148 0 12
13 115 147 0 76
13 115 2 0 44
13 115 1 0 12
13 115 0 0 76
13 117 149 0 48
13 117 148 0 16
13 117 147 0 80
13 117 2 0 48
13 117 1 0 16
13 117 0 0 80
13 118 149 0 32
13 118 148 0 0
13 118 147 0 64
13 118 2 0 32
13 118 1 0 0
13 118 0 0 64
13 119 149 0 40
13 119 148 0 8
13 119 147 0 72
13 119 2 0 40
13 119 1 0 8
13 119 0 0 72
14 113 149 0 58
14 113 148 0 26
14 113 147 0 90
14 113 2 0 58
14 113 1 0 26
14 113 0 0 90
14 115 149 0 48
14 115 148 0 16
14 115 147 0 80
14 115 2 0 48
14 115 1 0 16
14 115 0 0 80
14 116 149 0 36
14 116 148 0 4
14 116 147 0 68
14 116 2 0 36
14 116 1 0 4
14 116 0 0 68
14 117 149 0 32
14 117 148 0 0
14 117 147 0 64
14 117 2 0 32
14 117 1 0 0
14 117 0 0 64
14 118 149 0 32
14 118 148 0 0
14 118 147 0 64
14 118 2 0 32
14 118 1 0 0
14 118 0 0 64
14 119 149 0 40
14 119 148 0 8
14 119 147 0 72
14 119 2 0 40
14 119 1 0 8
14 119 0 0 72
15 115 149 0 48
15 115 148 0 16
15 115 147 0 80
15 115 2 0 48
15 115 1 0 16
15 115 0 0 80
15 116 149 0 32
15 116 148 0 0
15 116 147 0 64
15 116 2 0 32
15 116 1 0 0
15 116 0 0 64
15 117 149 0 32
15 117 148 0 0
15 117 147 0 64
15 117 2 0 32
15 117 1 0 0
15 117 0 0 64
15 118 149 0 32
15 118 148 0 0
15 118 147 0 64
15 118 2 0 32
15 118 1 0 0
15 118 0 0 64
15 119 149 0 40
15 119 148 0 8
15 119 147 0 72
15 119 2 0 40
15 119 1 0 8
15 119 0 0 72
16 115 149 0 48
16 115 148 0 16
16 115 147 0 80
16 115 2 0 48
16 115 1 0 16
16 115 0 0 80
16 116 149 0 32
16 116 148 0 0
16 116 147 0 64
16 116 2 0 32
16 116 1 0 0
16 116 0 0 64
16 117 149 0 32
16 117 148 0 0
16 117 147 0 64
16 117 2 0 32
16 117 1 0 0
16 117 0 0 64
16 118 149 0 32
16 118 148 0 0
16 118 147 0 64
16 118 2 0 32
16 118 1 0 0
16 118 0 0 64
16 119 149 0 40
16 119 148 0 8
16 119 147 0 72
16 119 2 0 40
16 119 1 0 8
16 119 0 0 72
17 115 149 0 48
17 115 148 0 16
17 115 147 0 80
17 115 2 0 48
17 115 1 0 16
17 115 0 0 80
17 116 149 0 32
17 116 148 0 0
17 116 147 0 64
17 116 2 0 32
17 116 1 0 0
17 116 0 0 64
17 117 149 0 32
17 117 148 0 0
17 117 147 0 64
17 117 2 0 32
17 117 1 0 0
17 117 0 0 64
17 118 149 0 32
17 118 148 0 0
17 118 147 0 64
17 118 2 0 32
17 118 1 0 0
17 118 0 0 64
17 119 149 0 40
17 119 148 0 8
17 119 147 0 72
17 119 2 0 40
17 119 1 0 8
17 119 0 0 72
18 110 149 0 52
18 110 148 0 20
18 110 147 0 84
18 110 2 0 52
18 110 1 0 20
18 110 0 0 84
18 111 149 0 44
18 111 148 0 12
18 111 147 0 76
18 111 2 0 44
18 111 1 0 12
18 111 0 0 76
18 114 149 0 52
18 114 148 0 20
18 114 147 0 84
18 114 2 0 52
18 114 1 0 20
18 114 0 0 84
18 115 149 0 32
18 115 148 0 0
18 115 147 0 64
18 115 2 0 32
18 115 1 0 0
18 115 0 0 64
18 116 149 0 34
18 116 148 0 2
18 116 147 0 66
18 116 2 0 34
18 116 1 0 2
18 116 0 0 66
18 117 149 0 32
18 117 148 0 0
18 117 147 0 64
18 117 2 0 32
18 117 1 0 0
18 117 0 0 64
18 118 149 0 32
18 118 148 0 0
18 118 147 0 64
18 118 2 0 32
18 118 1 0 0
18 118 0 0 64
18 119 149 0 40
18 119 148 0 8
18 119 147 0 72
18 119 2 0 40
18 119 1 0 8
18 119 0 0 72
19 110 149 0 50
19 110 148 0 18
19 110 147 0 82
19 110 2 0 50
19 110 1 0 18
19 110 0 0 82
19 111 149 0 32
19 111 148 0 0
19 111 147 0 64
19 111 2 0 32
19 111 1 0 0
19 111 0 0 64
19 112 149 0 36
19 112 148 0 4
19 112 147 0 68
19 112 2 0 36
19 112 1 0 4
19 112 0 0 68
19 113 149 0 36
19 113 148 0 4
19 113 147 0 68
19 113 2 0 36
19 113 1 0 4
19 113 0 0 68
19 114 149 0 32
19 114 148 0 0
19 114 147 0 64
19 114 2 0 32
19 114 1 0 0
19 114 0 0 64
19 115 149 0 42
19 115 148 0 10
19 115 147 0 74
19 115 2 0 42
19 115 1 0 10
19 115 0 0 74
19 117 149 0 48
19 117 148 0 16
19 117 147 0 80
19 117 2 0 48
19 117 1 0 16
19 117 0 0 80
19 118 149 0 32
19 118 148 0 0
19 118 147 0 64
19 118 2 0 32
19 118 1 0 0
19 118 0 0 64
19 119 149 0 40
19 119 148 0 8
19 119 147 0 72
19 119 2 0 40
19 119 1 0 8
19 119 0 0 72
20 111 149 0 48
20 111 148 0 16
20 111 147 0 80
20 111 2 0 48
20 111 1 0 16
20 111 0 0 80
20 112 149 0 32
20 112 148 0 0
20 112 147 0 64
20 112 2 0 32
20 112 1 0 0
20 112 0 0 64
20 113 149 0 34
20 113 148 0 2
20 113 147 0 66
20 113 2 0 34
20 113 1 0 2
20 113 0 0 66
20 114 149 0 42
20 114 148 0 10
20 114 147 0 74
20 114 2 0 42
20 114 1 0 10
20 114 0 0 74
20 117 149 0 48
20 117 148 0 16
20 117 147 0 80
20 117 2 0 48
20 117 1 0 16
20 117 0 0 80
20 118 149 0 32
20 118 148 0 0
20 118 147 0 64
20 118 2 0 32
20 118 1 0 0
20 118 0 0 64
20 119 149 0 40
20 119 148 0 8
20 119 147 0 72
20 119 2 0 40
20 119 1 0 8
20 119 0 0 72
21 105 149 0 52
21 105 148 0 20
21 105 147 0 84
21 105 2 0 52
21 105 1 0 20
21 105 0 0 84
21 106 149 0 46
21 106 148 0 14
21 106 147 0 78
21 106 2 0 46
21 106 1 0 14
21 106 0 0 78
21 111 149 0 48
21 111 148 0 16
21 111 147 0 80
21 111 2 0 48
21 111 1 0 16
21 111 0 0 80
21 112 149 0 40
21 112 148 0 8
21 112 147 0 72
21 112 2 0 40
21 112 1 0 8
21 112 0 0 72
21 117 149 0 48
21 117 148 0 16
21 117 147 0 80
21 117 2 0 48
21 117 1 0 16
21 117 0 0 80
21 118 149 0 32
21 118 148 0 0
21 118 147 0 64
21 118 2 0 32
21 118 1 0 0
21 118 0 0 64
21 119 149 0 40
21 119 148 0 8
21 119 147 0 72
21 119 2 0 40
21 119 1 0 8
21 119 0 0 72
22 104 149 0 54
22 104 148 0 22
22 104 147 0 86
22 104 2 0 54
22 104 1 0 22
22 104 0 0 86
22 105 149 0 40
22 105 148 0 8
22 105 147 0 72
22 105 2 0 40
22 105 1 0 8
22 105 0 0 72
22 110 149 0 52
22 110 148 0 20
22 110 147 0 84
22 110 2 0 52
22 110 1 0 20
22 110 0 0 84
22 111 149 0 32
22 111 148 0 0
22 111 147 0 64
22 111 2 0 32
22 111 1 0 0
22 111 0 0 64
22 112 149 0 42
22 112 148 0 10
22 112 147 0 74
22 112 2 0 42
22 112 1 0 10
22 112 0 0 74
22 117 149 0 48
22 117 148 0 16
22 117 147 0 80
22 117 2 0 48
22 117 1 0 16
22 117 0 0 80
22 118 149 0 32
22 118 148 0 0
22 118 147 0 64
22 118 2 0 32
22 118 1 0 0
22 118 0 0 64
22 119 149 0 40
22 119 148 0 8
22 119 147 0 72
22 119 2 0 40
22 119 1 0 8
22 119 0 0 72
23 105 149 0 50
23 105 148 0 18
23 105 147 0 82
23 105 2 0 50
23 105 1 0 18
23 105 0 0 82
23 106 149 0 36
23 106 148 0 4
23 106 147 0 68
23 106 2 0 36
23 106 1 0 4
23 106 0 0 68
23 107 149 0 36
23 107 148 0 4
23 107 147 0 68
23 107 2 0 36
23 107 1 0 4
23 107 0 0 68
23 108 149 0 36
23 108 148 0 4
23 108 147 0 68
23 108 2 0 36
23 108 1 0 4
23 108 0 0 68
23 109 149 0 36
23 109 148 0 4
23 109 147 0 68
23 109 2 0 36
23 109 1 0 4
23 109 0 0 68
23 110 149 0 32
23 110 148 0 0
23 110 147 0 64
23 110 2 0 32
23 110 1 0 0
23 110 0 0 64
23 111 149 0 42
23 111 148 0 10
23 111 147 0 74
23 111 2 0 42
23 111 1 0 10
23 111 0 0 74
23 117 149 0 48
23 117 148 0 16
23 117 147 0 80
23 117 2 0 48
23 117 1 0 16
23 117 0 0 80
23 118 149 0 32
23 118 148 0 0
23 118 147 0 64
23 118 2 0 32
23 118 1 0 0
23 118 0 0 64
23 119 149 0 40
23 119 148 0 8
23 119 147 0 72
23 119 2 0 40
23 119 1 0 8
23 119 0 0 72
24 106 149 0 48
24 106 148 0 16
24 106 147 0 80
24 106 2 0 48
24 106 1 0 16
24 106 0 0 80
24 107 149 0 32
24 107 148 0 0
24 107 147 0 64
24 107 2 0 32
24 107 1 0 0
24 107 0 0 64
24 108 149 0 32
24 108 148 0 0
24 108 147 0 64
24 108 2 0 32
24 108 1 0 0
24 108 0 0 64
24 109 149 0 32
24 109 148 0 0
24 109 147 0 64
24 109 2 0 32
24 109 1 0 0
24 109 0 0 64
24 110 149 0 40
24 110 148 0 8
24 110 147 0 72
24 110 2 0 40
24 110 1 0 8
24 110 0 0 72
24 117 149 0 48
24 117 148 0 16
24 117 147 0 80
24 117 2 0 48
24 117 1 0 16
24 117 0 0 80
24 118 149 0 32
24 118 148 0 0
24 118 147 0 64
24 118 2 0 32
24 118 1 0 0
24 118 0 0 64
24 119 149 0 40
24 119 148 0 8
24 119 147 0 72
24 119 2 0 40
24 119 1 0 8
24 119 0 0 72
25 1 149 0 52
25 1 148 0 20
25 1 147 0 84
25 1 2 0 52
25 1 1 0 20
25 1 0 0 84
25 2 149 0 36
25 2 148 0 4
25 2 147 0 68
25 2 2 0 36
25 2 1 0 4
25 2 0 0 68
25 3 149 0 36
25 3 148 0 4
25 3 147 0 68
25 3 2 0 36
25 3 1 0 4
25 3 0 0 68
25 4 149 0 36
25 4 148 0 4
25 4 147 0 68
25 4 2 0 36
25 4 1 0 4
25 4 0 0 68
25 5 149 0 36
25 5 148 0 4
25 5 147 0 68
25 5 2 0 36
25 5 1 0 4
25 5 0 0 68
25 6 149 0 36
25 6 148 0 4
25 6 147 0 68
25 6 2 0 36
25 6 1 0 4
25 6 0 0 68
25 7 149 0 36
25 7 148 0 4
25 7 147 0 68
25 7 2 0 36
25 7 1 0 4
25 7 0 0 68
25 8 149 0 36
25 8 148 0 4
25 8 147 0 68
25 8 2 0 36
25 8 1 0 4
25 8 0 0 68
25 9 149 0 36
25 9 148 0 4
25 9 147 0 68
25 9 2 0 36
25 9 1 0 4
25 9 0 0 68
25 10 149 0 36
25 10 148 0 4
25 10 147 0 68
25 10 2 0 36
25 10 1 0 4
25 10 0 0 68
25 11 149 0 36
25 11 148 0 4
25 11 147 0 68
25 11 2 0 36
25 11 1 0 4
25 11 0 0 68
25 12 149 0 36
25 12 148 0 4
25 12 147 0 68
25 12 2 0 36
25 12 1 0 4
25 12 0 0 68
25 13 149 0 36
25 13 148 0 4
25 13 147 0 68
25 13 2 0 36
25 13 1 0 4
25 13 0 0 68
25 14 149 0 36
25 14 148 0 4
25 14 147 0 68
25 14 2 0 36
25 14 1 0 4
25 14 0 0 68
25 15 149 0 36
25 15 148 0 4
25 15 147 0 68
25 15 2 0 36
25 15 1 0 4
25 15 0 0 68
25 16 149 0 36
25 16 148 0 4
25 16 147 0 68
25 16 2 0 36
25 16 1 0 4
25 16 0 0 68
25 17 149 0 36
25 17 148 0 4
25 17 147 0 68
25 17 2 0 36
25 17 1 0 4
25 17 0 0 68
25 18 149 0 36
25 18 148 0 4
25 18 147 0 68
25 18 2 0 36
25 18 1 0 4
25 18 0 0 68
25 19 149 0 36
25 19 148 0 4
25 19 147 0 68
25 19 2 0 36
25 19 1 0 4
25 19 0 0 68
25 20 149 0 36
25 20 148 0 4
25 20 147 0 68
25 20 2 0 36
25 20 1 0 4
25 20 0 0 68
25 21 149 0 36
25 21 148 0 4
25 21 147 0 68
25 21 2 0 36
25 21 1 0 4
25 21 0 0 68
25 22 149 0 36
25 22 148 0 4
25 22 147 0 68
25 22 2 0 36
25 22 1 0 4
25 22 0 0 68
25 23 149 0 36
25 23 148 0 4
25 23 147 0 68
25 23 2 0 36
25 23 1 0 4
25 23 0 0 68
25 24 149 0 36
25 24 148 0 4
25 24 147 0 68
25 24 2 0 36
25 24 1 0 4
25 24 0 0 68
25 25 149 0 36
25 25 148 0 4
25 25 147 0 68
25 25 2 0 36
25 25 1 0 4
25 25 0 0 68
25 26 149 0 36
25 26 148 0 4
25 26 147 0 68
25 26 2 0 36
25 26 1 0 4
25 26 0 0 68
25 27 149 0 36
25 27 148 0 4
25 27 147 0 68
25 27 2 0 36
25 27 1 0 4
25 27 0 0 68
25 28 149 0 36
25 28 148 0 4
25 28 147 0 68
25 28 2 0 36
25 28 1 0 4
25 28 0 0 68
25 29 149 0 36
25 29 148 0 4
25 29 147 0 68
25 29 2 0 36
25 29 1 0 4
25 29 0 0 68
25 30 149 0 36
25 30 148 0 4
25 30 147 0 68
25 30 2 0 36
25 30 1 0 4
25 30 0 0 68
25 31 149 0 36
25 31 148 0 4
25 31 147 0 68
25 31 2 0 36
25 31 1 0 4
25 31 0 0 68
25 32 149 0 36
25 32 148 0 4
25 32 147 0 68
25 32 2 0 36
25 32 1 0 4
25 32 0 0 68
25 33 149 0 36
25 33 148 0 4
25 33 147 0 68
25 33 2 0 36
25 33 1 0 4
25 33 0 0 68
25 34 149 0 36
25 34 148 0 4
25 34 147 0 68
25 34 2 0 36
25 34 1 0 4
25 34 0 0 68
25 35 149 0 36
25 35 148 0 4
25 35 147 0 68
25 35 2 0 36
25 35 1 0 4
25 35 0 0 68
25 36 149 0 36
25 36 148 0 4
25 36 147 0 68
25 36 2 0 36
25 36 1 0 4
25 36 0 0 68
25 37 149 0 36
25 37 148 0 4
25 37 147 0 68
25 37 2 0 36
25 37 1 0 4
25 37 0 0 68
25 38 149 0 36
25 38 148 0 4
25 38 147 0 68
25 38 2 0 36
25 38 1 0 4
25 38 0 0 68
25 39 149 0 36
25 39 148 0 4
25 39 147 0 68
25 39 2 0 36
25 39 1 0 4
25 39 0 0 68
25 40 149 0 36
25 40 148 0 4
25 40 147 0 68
25 40 2 0 36
25 40 1 0 4
25 40 0 0 68
25 41 149 0 36
25 41 148 0 4
25 41 147 0 68
25 41 2 0 36
25 41 1 0 4
25 41 0 0 68
25 42 149 0 36
25 42 148 0 4
25 42 147 0 68
25 42 2 0 36
25 42 1 0 4
25 42 0 0 68
25 43 149 0 36
25 43 148 0 4
25 43 147 0 68
25 43 2 0 36
25 43 1 0 4
25 43 0 0 68
25 44 149 0 36
25 44 148 0 4
25 44 147 0 68
25 44 2 0 36
25 44 1 0 4
25 44 0 0 68
25 45 149 0 36
25 45 148 0 4
25 45 147 0 68
25 45 2 0 36
25 45 1 0 4
25 45 0 0 68
25 46 149 0 36
25 46 148 0 4
25 46 147 0 68
25 46 2 0 36
25 46 1 0 4
25 46 0 0 68
25 47 149 0 36
25 47 148 0 4
25 47 147 0 68
25 47 2 0 36
25 47 1 0 4
25 47 0 0 68
25 48 149 0 36
25 48 148 0 4
25 48 147 0 68
25 48 2 0 36
25 48 1 0 4
25 48 0 0 68
25 49 149 0 36
25 49 148 0 4
25 49 147 0 68
25 49 2 0 36
25 49 1 0 4
25 49 0 0 68
25 50 149 0 36
25 50 148 0 4
25 50 147 0 68
25 50 2 0 36
25 50 1 0 4
25 50 0 0 68
25 51 149 0 36
25 51 148 0 4
25 51 147 0 68
25 51 2 0 36
25 51 1 0 4
25 51 0 0 68
25 52 149 0 36
25 52 148 0 4
25 52 147 0 68
25 52 2 0 36
25 52 1 0 4
25 52 0 0 68
25 53 149 0 36
25 53 148 0 4
25 53 147 0 68
25 53 2 0 36
25 53 1 0 4
25 53 0 0 68
25 54 149 0 36
25 54 148 0 4
25 54 147 0 68
25 54 2 0 36
25 54 1 0 4
25 54 0 0 68
25 55 149 0 36
25 55 148 0 4
25 55 147 0 68
25 55 2 0 36
25 55 1 0 4
25 55 0 0 68
25 56 149 0 36
25 56 148 0 4
25 56 147 0 68
25 56 2 0 36
25 56 1 0 4
25 56 0 0 68
25 57 149 0 36
25 57 148 0 4
25 57 147 0 68
25 57 2 0 36
25 57 1 0 4
25 57 0 0 68
25 58 149 0 36
25 58 148 0 4
25 58 147 0 68
25 58 2 0 36
25 58 1 0 4
25 58 0 0 68
25 59 149 0 36
25 59 148 0 4
25 59 147 0 68
25 59 2 0 36
25 59 1 0 4
25 59 0 0 68
25 60 149 0 36
25 60 148 0 4
25 60 147 0 68
25 60 2 0 36
25 60 1 0 4
25 60 0 0 68
25 61 149 0 36
25 61 148 0 4
25 61 147 0 68
25 61 2 0 36
25 61 1 0 4
25 61 0 0 68
25 62 149 0 36
25 62 148 0 4
25 62 147 0 68
25 62 2 0 36
25 62 1 0 4
25 62 0 0 68
25 63 149 0 36
25 63 148 0 4
25 63 147 0 68
25 63 2 0 36
25 63 1 0 4
25 63 0 0 68
25 64 149 0 36
25 64 148 0 4
25 64 147 0 68
25 64 2 0 36
25 64 1 0 4
25 64 0 0 68
25 65 149 0 36
25 65 148 0 4
25 65 147 0 68
25 65 2 0 36
25 65 1 0 4
25 65 0 0 68
25 66 149 0 36
25 66 148 0 4
25 66 147 0 68
25 66 2 0 36
25 66 1 0 4
25 66 0 0 68
25 67 149 0 36
25 67 148 0 4
25 67 147 0 68
25 67 2 0 36
25 67 1 0 4
25 67 0 0 68
25 68 149 0 36
25 68 148 0 4
25 68 147 0 68
25 68 2 0 36
25 68 1 0 4
25 68 0 0 68
25 69 149 0 36
25 69 148 0 4
25 69 147 0 68
25 69 2 0 36
25 69 1 0 4
25 69 0 0 68
25 70 149 0 36
25 70 148 0 4
25 70 147 0 68
25 70 2 0 36
25 70 1 0 4
25 70 0 0 68
25 71 149 0 36
25 71 148 0 4
25 71 147 0 68
25 71 2 0 36
25 71 1 0 4
25 71 0 0 68
25 72 149 0 36
25 72 148 0 4
25 72 147 0 68
25 72 2 0 36
25 72 1 0 4
25 72 0 0 68
25 73 149 0 36
25 73 148 0 4
25 73 147 0 68
25 73 2 0 36
25 73 1 0 4
25 73 0 0 68
25 74 149 0 36
25 74 148 0 4
25 74 147 0 68
25 74 2 0 36
25 74 1 0 4
25 74 0 0 68
25 75 149 0 36
25 75 148 0 4
25 75 147 0 68
25 75 2 0 36
25 75 1 0 4
25 75 0 0 68
25 76 149 0 36
25 76 148 0 4
25 76 147 0 68
25 76 2 0 36
25 76 1 0 4
25 76 0 0 68
25 77 149 0 36
25 77 148 0 4
25 77 147 0 68
25 77 2 0 36
25 77 1 0 4
25 77 0 0 68
25 78 149 0 36
25 78 148 0 4
25 78 147 0 68
25 78 2 0 36
25 78 1 0 4
25 78 0 0 68
25 79 149 0 36
25 79 148 0 4
25 79 147 0 68
25 79 2 0 36
25 79 1 0 4
25 79 0 0 68
25 80 149 0 36
25 80 148 0 4
25 80 147 0 68
25 80 2 0 36
25 80 1 0 4
25 80 0 0 68
25 81 149 0 36
25 81 148 0 4
25 81 147 0 68
25 81 2 0 36
25 81 1 0 4
25 81 0 0 68
25 82 149 0 36
25 82 148 0 4
25 82 147 0 68
25 82 2 0 36
25 82 1 0 4
25 82 0 0 68
25 83 149 0 36
25 83 148 0 4
25 83 147 0 68
25 83 2 0 36
25 83 1 0 4
25 83 0 0 68
25 84 149 0 36
25 84 148 0 4
25 84 147 0 68
25 84 2 0 36
25 84 1 0 4
25 84 0 0 68
25 85 149 0 36
25 85 148 0 4
25 85 147 0 68
25 85 2 0 36
25 85 1 0 4
25 85 0 0 68
25 86 149 0 36
25 86 148 0 4
25 86 147 0 68
25 86 2 0 36
25 86 1 0 4
25 86 0 0 68
25 87 149 0 36
25 87 148 0 4
25 87 147 0 68
25 87 2 0 36
25 87 1 0 4
25 87 0 0 68
25 88 149 0 36
25 88 148 0 4
25 88 147 0 68
25 88 2 0 36
25 88 1 0 4
25 88 0 0 68
25 89 149 0 36
25 89 148 0 4
25 89 147 0 68
25 89 2 0 36
25 89 1 0 4
25 89 0 0 68
25 90 149 0 36
25 90 148 0 4
25 90 147 0 68
25 90 2 0 36
25 90 1 0 4
25 90 0 0 68
25 91 149 0 36
25 91 148 0 4
25 91 147 0 68
25 91 2 0 36
25 91 1 0 4
25 91 0 0 68
25 92 149 0 36
25 92 148 0 4
25 92 147 0 68
25 92 2 0 36
25 92 1 0 4
25 92 0 0 68
25 93 149 0 36
25 93 148 0 4
25 93 147 0 68
25 93 2 0 36
25 93 1 0 4
25 93 0 0 68
25 94 149 0 36
25 94 148 0 4
25 94 147 0 68
25 94 2 0 36
25 94 1 0 4
25 94 0 0 68
25 95 149 0 36
25 95 148 0 4
25 95 147 0 68
25 95 2 0 36
25 95 1 0 4
25 95 0 0 68
25 96 149 0 36
25 96 148 0 4
25 96 147 0 68
25 96 2 0 36
25 96 1 0 4
25 96 0 0 68
25 97 149 0 36
25 97 148 0 4
25 97 147 0 68
25 97 2 0 36
25 97 1 0 4
25 97 0 0 68
25 98 149 0 36
25 98 148 0 4
25 98 147 0 68
25 98 2 0 36
25 98 1 0 4
25 98 0 0 68
25 99 149 0 36
25 99 148 0 4
25 99 147 0 68
25 99 2 0 36
25 99 1 0 4
25 99 0 0 68
25 100 149 0 36
25 100 148 0 4
25 100 147 0 68
25 100 2 0 36
25 100 1 0 4
25 100 0 0 68
25 101 149 0 36
25 101 148 0 4
25 101 147 0 68
25 101 2 0 36
25 101 1 0 4
25 101 0 0 68
25 102 149 0 36
25 102 148 0 4
25 102 147 0 68
25 102 2 0 36
25 102 1 0 4
25 102 0 0 68
25 103 149 0 36
25 103 148 0 4
25 103 147 0 68
25 103 2 0 36
25 103 1 0 4
25 103 0 0 68
25 104 149 0 36
25 104 148 0 4
25 104 147 0 68
25 104 2 0 36
25 104 1 0 4
25 104 0 0 68
25 105 149 0 36
25 105 148 0 4
25 105 147 0 68
25 105 2 0 36
25 105 1 0 4
25 105 0 0 68
25 106 149 0 32
25 106 148 0 0
25 106 147 0 64
25 106 2 0 32
25 106 1 0 0
25 106 0 0 64
25 107 149 0 32
25 107 148 0 0
25 107 147 0 64
25 107 2 0 32
25 107 1 0 0
25 107 0 0 64
25 108 149 0 32
25 108 148 0 0
25 108 147 0 64
25 108 2 0 32
25 108 1 0 0
25 108 0 0 64
25 109 149 0 32
25 109 148 0 0
25 109 147 0 64
25 109 2 0 32
25 109 1 0 0
25 109 0 0 64
25 110 149 0 32
25 110 148 0 0
25 110 147 0 64
25 110 2 0 32
25 110 1 0 0
25 110 0 0 64
25 111 149 0 36
25 111 148 0 4
25 111 147 0 68
25 111 2 0 36
25 111 1 0 4
25 111 0 0 68
25 112 149 0 36
25 112 148 0 4
25 112 147 0 68
25 112 2 0 36
25 112 1 0 4
25 112 0 0 68
25 113 149 0 36
25 113 148 0 4
25 113 147 0 68
25 113 2 0 36
25 113 1 0 4
25 113 0 0 68
25 114 149 0 36
25 114 148 0 4
25 114 147 0 68
25 114 2 0 36
25 114 1 0 4
25 114 0 0 68
25 115 149 0 36
25 115 148 0 4
25 115 147 0 68
25 115 2 0 36
25 115 1 0 4
25 115 0 0 68
25 116 149 0 36
25 116 148 0 4
25 116 147 0 68
25 116 2 0 36
25 116 1 0 4
25 116 0 0 68
25 117 149 0 32
25 117 148 0 0
25 117 147 0 64
25 117 2 0 32
25 117 1 0 0
25 117 0 0 64
25 118 149 0 32
25 118 148 0 0
25 118 147 0 64
25 118 2 0 32
25 118 1 0 0
25 118 0 0 64
25 119 149 0 32
25 119 148 0 0
25 119 147 0 64
25 119 2 0 32
25 119 1 0 0
25 119 0 0 64
25 120 149 0 36
25 120 148 0 4
25 120 147 0 68
25 120 2 0 36
25 120 1 0 4
25 120 0 0 68
25 121 149 0 36
25 121 148 0 4
25 121 147 0 68
25 121 2 0 36
25 121 1 0 4
25 121 0 0 68
25 122 149 0 36
25 122 148 0 4
25 122 147 0 68
25 122 2 0 36
25 122 1 0 4
25 122 0 0 68
25 123 149 0 36
25 123 148 0 4
25 123 147 0 68
25 123 2 0 36
25 123 1 0 4
25 123 0 0 68
25 124 149 0 36
25 124 148 0 4
25 124 147 0 68
25 124 2 0 36
25 124 1 0 4
25 124 0 0 68
25 125 149 0 36
25 125 148 0 4
25 125 147 0 68
25 125 2 0 36
25 125 1 0 4
25 125 0 0 68
25 126 149 0 36
25 126 148 0 4
25 126 147 0 68
25 126 2 0 36
25 126 1 0 4
25 126 0 0 68
25 127 149 0 36
25 127 148 0 4
25 127 147 0 68
25 127 2 0 36
25 127 1 0 4
25 127 0 0 68
25 128 149 0 36
25 128 148 0 4
25 128 147 0 68
25 128 2 0 36
25 128 1 0 4
25 128 0 0 68
25 129 149 0 36
25 129 148 0 4
25 129 147 0 68
25 129 2 0 36
25 129 1 0 4
25 129 0 0 68
25 130 149 0 36
25 130 148 0 4
25 130 147 0 68
25 130 2 0 36
25 130 1 0 4
25 130 0 0 68
25 131 149 0 36
25 131 148 0 4
25 131 147 0 68
25 131 2 0 36
25 131 1 0 4
25 131 0 0 68
25 132 149 0 36
25 132 148 0 4
25 132 147 0 68
25 132 2 0 36
25 132 1 0 4
25 132 0 0 68
25 133 149 0 36
25 133 148 0 4
25 133 147 0 68
25 133 2 0 36
25 133 1 0 4
25 133 0 0 68
25 134 149 0 36
25 134 148 0 4
25 134 147 0 68
25 134 2 0 36
25 134 1 0 4
25 134 0 0 68
25 135 149 0 36
25 135 148 0 4
25 135 147 0 68
25 135 2 0 36
25 135 1 0 4
25 135 0 0 68
25 136 149 0 36
25 136 148 0 4
25 136 147 0 68
25 136 2 0 36
25 136 1 0 4
25 136 0 0 68
25 137 149 0 36
25 137 148 0 4
25 137 147 0 68
25 137 2 0 36
25 137 1 0 4
25 137 0 0 68
25 138 149 0 36
25 138 148 0 4
25 138 147 0 68
25 138 2 0 36
25 138 1 0 4
25 138 0 0 68
25 139 149 0 36
25 139 148 0 4
25 139 147 0 68
25 139 2 0 36
25 139 1 0 4
25 139 0 0 68
25 140 149 0 36
25 140 148 0 4
25 140 147 0 68
25 140 2 0 36
25 140 1 0 4
25 140 0 0 68
25 141 149 0 36
25 141 148 0 4
25 141 147 0 68
25 141 2 0 36
25 141 1 0 4
25 141 0 0 68
25 142 149 0 36
25 142 148 0 4
25 142 147 0 68
25 142 2 0 36
25 142 1 0 4
25 142 0 0 68
25 143 149 0 36
25 143 148 0 4
25 143 147 0 68
25 143 2 0 36
25 143 1 0 4
25 143 0 0 68
25 144 149 0 36
25 144 148 0 4
25 144 147 0 68
25 144 2 0 36
25 144 1 0 4
25 144 0 0 68
25 145 149 0 36
25 145 148 0 4
25 145 147 0 68
25 145 2 0 36
25 145 1 0 4
25 145 0 0 68
25 146 149 0 44
25 146 148 0 12
25 146 147 0 76
25 146 2 0 44
25 146 1 0 12
25 146 0 0 76
26 1 149 0 48
26 1 148 0 16
26 1 147 0 80
26 1 2 0 48
26 1 1 0 16
26 1 0 0 80
26 2 149 0 32
26 2 148 0 0
26 2 147 0 64
26 2 2 0 32
26 2 1 0 0
26 2 0 0 64
26 3 149 0 32
26 3 148 0 0
26 3 147 0 64
26 3 2 0 32
26 3 1 0 0
26 3 0 0 64
26 4 149 0 32
26 4 148 0 0
26 4 147 0 64
26 4 2 0 32
26 4 1 0 0
26 4 0 0 64
26 5 149 0 32
26 5 148 0 0
26 5 147 0 64
26 5 2 0 32
26 5 1 0 0
26 5 0 0 64
26 6 149 0 32
26 6 148 0 0
26 6 147 0 64
26 6 2 0 32
26 6 1 0 0
26 6 0 0 64
26 7 149 0 32
26 7 148 0 0
26 7 147 0 64
26 7 2 0 32
26 7 1 0 0
26 7 0 0 64
26 8 149 0 32
26 8 148 0 0
26 8 147 0 64
26 8 2 0 32
26 8 1 0 0
26 8 0 0 64
26 9 149 0 32
26 9 148 0 0
26 9 147 0 64
26 9 2 0 32
26 9 1 0 0
26 9 0 0 64
26 10 149 0 32
26 10 148 0 0
26 10 147 0 64
26 10 2 0 32
26 10 1 0 0
26 10 0 0 64
26 11 149 0 32
26 11 148 0 0
26 11 147 0 64
26 11 2 0 32
26 11 1 0 0
26 11 0 0 64
26 12 149 0 32
26 12 148 0 0
26 12 147 0 64
26 12 2 0 32
26 12 1 0 0
26 12 0 0 64
26 13 149 0 32
26 13 148 0 0
26 13 147 0 64
26 13 2 0 32
26 13 1 0 0
26 13 0 0 64
26 14 149 0 32
26 14 148 0 0
26 14 147 0 64
26 14 2 0 32
26 14 1 0 0
26 14 0 0 64
26 15 149 0 32
26 15 148 0 0
26 15 147 0 64
26 15 2 0 32
26 15 1 0 0
26 15 0 0 64
26 16 149 0 32
26 16 148 0 0
26 16 147 0 64
26 16 2 0 32
26 16 1 0 0
26 16 0 0 64
26 17 149 0 32
26 17 148 0 0
26 17 147 0 64
26 17 2 0 32
26 17 1 0 0
26 17 0 0 64
26 18 149 0 32
26 18 148 0 0
26 18 147 0 64
26 18 2 0 32
26 18 1 0 0
26 18 0 0 64
26 19 149 0 32
26 19 148 0 0
26 19 147 0 64
26 19 2 0 32
26 19 1 0 0
26 19 0 0 64
26 20 149 0 32
26 20 148 0 0
26 20 147 0 64
26 20 2 0 32
26 20 1 0 0
26 20 0 0 64
26 21 149 0 32
26 21 148 0 0
26 21 147 0 64
26 21 2 0 32
26 21 1 0 0
26 21 0 0 64
26 22 149 0 32
26 22 148 0 0
26 22 147 0 64
26 22 2 0 32
26 22 1 0 0
26 22 0 0 64
26 23 149 0 32
26 23 148 0 0
26 23 147 0 64
26 23 2 0 32
26 23 1 0 0
26 23 0 0 64
26 24 149 0 32
26 24 148 0 0
26 24 147 0 64
26 24 2 0 32
26 24 1 0 0
26 24 0 0 64
26 25 149 0 32
26 25 148 0 0
26 25 147 0 64
26 25 2 0 32
26 25 1 0 0
26 25 0 0 64
26 26 149 0 32
26 26 148 0 0
26 26 147 0 64
26 26 2 0 32
26 26 1 0 0
26 26 0 0 64
26 27 149 0 32
26 27 148 0 0
26 27 147 0 64
26 27 2 0 32
26 27 1 0 0
26 27 0 0 64
26 28 149 0 32
26 28 148 0 0
26 28 147 0 64
26 28 2 0 32
26 28 1 0 0
26 28 0 0 64
26 29 149 0 32
26 29 148 0 0
26 29 147 0 64
26 29 2 0 32
26 29 1 0 0
26 29 0 0 64
26 30 149 0 32
26 30 148 0 0
26 30 147 0 64
26 30 2 0 32
26 30 1 0 0
26 30 0 0 64
26 31 149 0 32
26 31 148 0 0
26 31 147 0 64
26 31 2 0 32
26 31 1 0 0
26 31 0 0 64
26 32 149 0 32
26 32 148 0 0
26 32 147 0 64
26 32 2 0 32
26 32 1 0 0
26 32 0 0 64
26 33 149 0 32
26 33 148 0 0
26 33 147 0 64
26 33 2 0 32
26 33 1 0 0
26 33 0 0 64
26 34 149 0 32
26 34 148 0 0
26 34 147 0 64
26 34 2 0 32
26 34 1 0 0
26 34 0 0 64
26 35 149 0 32
26 35 148 0 0
26 35 147 0 64
26 35 2 0 32
26 35 1 0 0
26 35 0 0 64
26 36 149 0 32
26 36 148 0 0
26 36 147 0 64
26 36 2 0 32
26 36 1 0 0
26 36 0 0 64
26 37 149 0 32
26 37 148 0 0
26 37 147 0 64
26 37 2 0 32
26 37 1 0 0
26 37 0 0 64
26 38 149 0 32
26 38 148 0 0
26 38 147 0 64
26 38 2 0 32
26 38 1 0 0
26 38 0 0 64
26 39 149 0 32
26 39 148 0 0
26 39 147 0 64
26 39 2 0 32
26 39 1 0 0
26 39 0 0 64
26 40 149 0 32
26 40 148 0 0
26 40 147 0 64
26 40 2 0 32
26 40 1 0 0
26 40 0 0 64
26 41 149 0 32
26 41 148 0 0
26 41 147 0 64
26 41 2 0 32
26 41 1 0 0
26 41 0 0 64
26 42 149 0 32
26 42 148 0 0
26 42 147 0 64
26 42 2 0 32
26 42 1 0 0
26 42 0 0 64
26 43 149 0 32
26 43 148 0 0
26 43 147 0 64
26 43 2 0 32
26 43 1 0 0
26 43 0 0 64
26 44 149 0 32
26 44 148 0 0
26 44 147 0 64
26 44 2 0 32
26 44 1 0 0
26 44 0 0 64
26 45 149 0 32
26 45 148 0 0
26 45 147 0 64
26 45 2 0 32
26 45 1 0 0
26 45 0 0 64
26 46 149 0 32
26 46 148 0 0
26 46 147 0 64
26 46 2 0 32
26 46 1 0 0
26 46 0 0 64
26 47 149 0 32
26 47 148 0 0
26 47 147 0 64
26 47 2 0 32
26 47 1 0 0
26 47 0 0 64
26 48 149 0 32
26 48 148 0 0
26 48 147 0 64
26 48 2 0 32
26 48 1 0 0
26 48 0 0 64
26 49 149 0 32
26 49 148 0 0
26 49 147 0 64
26 49 2 0 32
26 49 1 0 0
26 49 0 0 64
26 50 149 0 32
26 50 148 0 0
26 50 147 0 64
26 50 2 0 32
26 50 1 0 0
26 50 0 0 64
26 51 149 0 32
26 51 148 0 0
26 51 147 0 64
26 51 2 0 32
26 51 1 0 0
26 51 0 0 64
26 52 149 0 32
26 52 148 0 0
26 52 147 0 64
26 52 2 0 32
26 52 1 0 0
26 52 0 0 64
26 53 149 0 32
26 53 148 0 0
26 53 147 0 64
26 53 2 0 32
26 53 1 0 0
26 53 0 0 64
26 54 149 0 32
26 54 148 0 0
26 54 147 0 64
26 54 2 0 32
26 54 1 0 0
26 54 0 0 64
26 55 149 0 32
26 55 148 0 0
26 55 147 0 64
26 55 2 0 32
26 55 1 0 0
26 55 0 0 64
26 56 149 0 32
26 56 148 0 0
26 56 147 0 64
26 56 2 0 32
26 56 1 0 0
26 56 0 0 64
26 57 149 0 32
26 57 148 0 0
26 57 147 0 64
26 57 2 0 32
26 57 1 0 0
26 57 0 0 64
26 58 149 0 32
26 58 148 0 0
26 58 147 0 64
26 58 2 0 32
26 58 1 0 0
26 58 0 0 64
26 59 149 0 32
26 59 148 0 0
26 59 147 0 64
26 59 2 0 32
26 59 1 0 0
26 59 0 0 64
26 60 149 0 32
26 60 148 0 0
26 60 147 0 64
26 60 2 0 32
26 60 1 0 0
26 60 0 0 64
26 61 149 0 32
26 61 148 0 0
26 61 147 0 64
26 61 2 0 32
26 61 1 0 0
26 61 0 0 64
26 62 149 0 32
26 62 148 0 0
26 62 147 0 64
26 62 2 0 32
26 62 1 0 0
26 62 0 0 64
26 63 149 0 32
26 63 148 0 0
26 63 147 0 64
26 63 2 0 32
26 63 1 0 0
26 63 0 0 64
26 64 149 0 32
26 64 148 0 0
26 64 147 0 64
26 64 2 0 32
26 64 1 0 0
26 64 0 0 64
26 65 149 0 32
26 65 148 0 0
26 65 147 0 64
26 65 2 0 32
26 65 1 0 0
26 65 0 0 64
26 66 149 0 32
26 66 148 0 0
26 66 147 0 64
26 66 2 0 32
26 66 1 0 0
26 66 0 0 64
26 67 149 0 32
26 67 148 0 0
26 67 147 0 64
26 67 2 0 32
26 67 1 0 0
26 67 0 0 64
26 68 149 0 32
26 68 148 0 0
26 68 147 0 64
26 68 2 0 32
26 68 1 0 0
26 68 0 0 64
26 69 149 0 32
26 69 148 0 0
26 69 147 0 64
26 69 2 0 32
26 69 1 0 0
26 69 0 0 64
26 70 149 0 32
26 70 148 0 0
26 70 147 0 64
26 70 2 0 32
26 70 1 0 0
26 70 0 0 64
26 71 149 0 32
26 71 148 0 0
26 71 147 0 64
26 71 2 0 32
26 71 1 0 0
26 71 0 0 64
26 72 149 0 32
26 72 148 0 0
26 72 147 0 64
26 72 2 0 32
26 72 1 0 0
26 72 0 0 64
26 73 149 0 32
26 73 148 0 0
26 73 147 0 64
26 73 2 0 32
26 73 1 0 0
26 73 0 0 64
26 74 149 0 32
26 74 148 0 0
26 74 147 0 64
26 74 2 0 32
26 74 1 0 0
26 74 0 0 64
26 75 149 0 32
26 75 148 0 0
26 75 147 0 64
26 75 2 0 32
26 75 1 0 0
26 75 0 0 64
26 76 149 0 32
26 76 148 0 0
26 76 147 0 64
26 76 2 0 32
26 76 1 0 0
26 76 0 0 64
26 77 149 0 32
26 77 148 0 0
26 77 147 0 64
26 77 2 0 32
26 77 1 0 0
26 77 0 0 64
26 78 149 0 32
26 78 148 0 0
26 78 147 0 64
26 78 2 0 32
26 78 1 0 0
26 78 0 0 64
26 79 149 0 32
26 79 148 0 0
26 79 147 0 64
26 79 2 0 32
26 79 1 0 0
26 79 0 0 64
26 80 149 0 32
26 80 148 0 0
26 80 147 0 64
26 80 2 0 32
26 80 1 0 0
26 80 0 0 64
26 81 149 0 32
26 81 148 0 0
26 81 147 0 64
26 81 2 0 32
26 81 1 0 0
26 81 0 0 64
26 82 149 0 32
26 82 148 0 0
26 82 147 0 64
26 82 2 0 32
26 82 1 0 0
26 82 0 0 64
26 83 149 0 32
26 83 148 0 0
26 83 147 0 64
26 83 2 0 32
26 83 1 0 0
26 83 0 0 64
26 84 149 0 32
26 84 148 0 0
26 84 147 0 64
26 84 2 0 32
26 84 1 0 0
26 84 0 0 64
26 85 149 0 32
26 85 148 0 0
26 85 147 0 64
26 85 2 0 32
26 85 1 0 0
26 85 0 0 64
26 86 149 0 32
26 86 148 0 0
26 86 147 0 64
26 86 2 0 32
26 86 1 0 0
26 86 0 0 64
26 87 149 0 32
26 87 148 0 0
26 87 147 0 64
26 87 2 0 32
26 87 1 0 0
26 87 0 0 64
26 88 149 0 32
26 88 148 0 0
26 88 147 0 64
26 88 2 0 32
26 88 1 0 0
26 88 0 0 64
26 89 149 0 32
26 89 148 0 0
26 89 147 0 64
26 89 2 0 32
26 89 1 0 0
26 89 0 0 64
26 90 149 0 32
26 90 148 0 0
26 90 147 0 64
26 90 2 0 32
26 90 1 0 0
26 90 0 0 64
26 91 149 0 32
26 91 148 0 0
26 91 147 0 64
26 91 2 0 32
26 91 1 0 0
26 91 0 0 64
26 92 149 0 32
26 92 148 0 0
26 92 147 0 64
26 92 2 0 32
26 92 1 0 0
26 92 0 0 64
26 93 149 0 32
26 93 148 0 0
26 93 147 0 64
26 93 2 0 32
26 93 1 0 0
26 93 0 0 64
26 94 149 0 32
26 94 148 0 0
26 94 147 0 64
26 94 2 0 32
26 94 1 0 0
26 94 0 0 64
26 95 149 0 32
26 95 148 0 0
26 95 147 0 64
26 95 2 0 32
26 95 1 0 0
26 95 0 0 64
26 96 149 0 32
26 96 148 0 0
26 96 147 0 64
26 96 2 0 32
26 96 1 0 0
26 96 0 0 64
26 97 149 0 32
26 97 148 0 0
26 97 147 0 64
26 97 2 0 32
26 97 1 0 0
26 97 0 0 64
26 98 149 0 32
26 98 148 0 0
26 98 147 0 64
26 98 2 0 32
26 98 1 0 0
26 98 0 0 64
26 99 149 0 32
26 99 148 0 0
26 99 147 0 64
26 99 2 0 32
26 99 1 0 0
26 99 0 0 64
26 100 149 0 32
26 100 148 0 0
26 100 147 0 64
26 100 2 0 32
26 100 1 0 0
26 100 0 0 64
26 101 149 0 32
26 101 148 0 0
26 101 147 0 64
26 101 2 0 32
26 101 1 0 0
26 101 0 0 64
26 102 149 0 32
26 102 148 0 0
26 102 147 0 64
26 102 2 0 32
26 102 1 0 0
26 102 0 0 64
26 103 149 0 32
26 103 148 0 0
26 103 147 0 64
26 103 2 0 32
26 103 1 0 0
26 103 0 0 64
26 104 149 0 32
26 104 148 0 0
26 104 147 0 64
26 104 2 0 32
26 104 1 0 0
26 104 0 0 64
26 105 149 0 32
26 105 148 0 0
26 105 147 0 64
26 105 2 0 32
26 105 1 0 0
26 105 0 0 64
26 106 149 0 32
26 106 148 0 0
26 106 147 0 64
26 106 2 0 32
26 106 1 0 0
26 106 0 0 64
26 107 149 0 32
26 107 148 0 0
26 107 147 0 64
26 107 2 0 32
26 107 1 0 0
26 107 0 0 64
26 108 149 0 32
26 108 148 0 0
26 108 147 0 64
26 108 2 0 32
26 108 1 0 0
26 108 0 0 64
26 109 149 0 32
26 109 148 0 0
26 109 147 0 64
26 109 2 0 32
26 109 1 0 0
26 109 0 0 64
26 110 149 0 32
26 110 148 0 0
26 110 147 0 64
26 110 2 0 32
26 110 1 0 0
26 110 0 0 64
26 111 149 0 32
26 111 148 0 0
26 111 147 0 64
26 111 2 0 32
26 111 1 0 0
26 111 0 0 64
26 112 149 0 32
26 112 148 0 0
26 112 147 0 64
26 112 2 0 32
26 112 1 0 0
26 112 0 0 64
26 113 149 0 32
26 113 148 0 0
26 113 147 0 64
26 113 2 0 32
26 113 1 0 0
26 113 0 0 64
26 114 149 0 32
26 114 148 0 0
26 114 147 0 64
26 114 2 0 32
26 114 1 0 0
26 114 0 0 64
26 115 149 0 32
26 115 148 0 0
26 115 147 0 64
26 115 2 0 32
26 115 1 0 0
26 115 0 0 64
26 116 149 0 32
26 116 148 0 0
26 116 147 0 64
26 116 2 0 32
26 116 1 0 0
26 116 0 0 64
26 117 149 0 32
26 117 148 0 0
26 117 147 0 64
26 117 2 0 32
26 117 1 0 0
26 117 0 0 64
26 118 149 0 32
26 118 148 0 0
26 118 147 0 64
26 118 2 0 32
26 118 1 0 0
26 118 0 0 64
26 119 149 0 32
26 119 148 0 0
26 119 147 0 64
26 119 2 0 32
26 119 1 0 0
26 119 0 0 64
26 120 149 0 32
26 120 148 0 0
26 120 147 0 64
26 120 2 0 32
26 120 1 0 0
26 120 0 0 64
26 121 149 0 32
26 121 148 0 0
26 121 147 0 64
26 121 2 0 32
26 121 1 0 0
26 121 0 0 64
26 122 149 0 32
26 122 148 0 0
26 122 147 0 64
26 122 2 0 32
26 122 1 0 0
26 122 0 0 64
26 123 149 0 32
26 123 148 0 0
26 123 147 0 64
26 123 2 0 32
26 123 1 0 0
26 123 0 0 64
26 124 149 0 32
26 124 148 0 0
26 124 147 0 64
26 124 2 0 32
26 124 1 0 0
26 124 0 0 64
26 125 149 0 32
26 125 148 0 0
26 125 147 0 64
26 125 2 0 32
26 125 1 0 0
26 125 0 0 64
26 126 149 0 32
26 126 148 0 0
26 126 147 0 64
26 126 2 0 32
26 126 1 0 0
26 126 0 0 64
26 127 149 0 32
26 127 148 0 0
26 127 147 0 64
26 127 2 0 32
26 127 1 0 0
26 127 0 0 64
26 128 149 0 32
26 128 148 0 0
26 128 147 0 64
26 128 2 0 32
26 128 1 0 0
26 128 0 0 64
26 129 149 0 32
26 129 148 0 0
26 129 147 0 64
26 129 2 0 32
26 129 1 0 0
26 129 0 0 64
26 130 149 0 32
26 130 148 0 0
26 130 147 0 64
26 130 2 0 32
26 130 1 0 0
26 130 0 0 64
26 131 149 0 32
26 131 148 0 0
26 131 147 0 64
26 131 2 0 32
26 131 1 0 0
26 131 0 0 64
26 132 149 0 32
26 132 148 0 0
26 132 147 0 64
26 132 2 0 32
26 132 1 0 0
26 132 0 0 64
26 133 149 0 32
26 133 148 0 0
26 133 147 0 64
26 133 2 0 32
26 133 1 0 0
26 133 0 0 64
26 134 149 0 32
26 134 148 0 0
26 134 147 0 64
26 134 2 0 32
26 134 1 0 0
26 134 0 0 64
26 135 149 0 32
26 135 148 0 0
26 135 147 0 64
26 135 2 0 32
26 135 1 0 0
26 135 0 0 64
26 136 149 0 32
26 136 148 0 0
26 136 147 0 64
26 136 2 0 32
26 136 1 0 0
26 136 0 0 64
26 137 149 0 32
26 137 148 0 0
26 137 147 0 64
26 137 2 0 32
26 137 1 0 0
26 137 0 0 64
26 138 149 0 32
26 138 148 0 0
26 138 147 0 64
26 138 2 0 32
26 138 1 0 0
26 138 0 0 64
26 139 149 0 32
26 139 148 0 0
26 139 147 0 64
26 139 2 0 32
26 139 1 0 0
26 139 0 0 64
26 140 149 0 32
26 140 148 0 0
26 140 147 0 64
26 140 2 0 32
26 140 1 0 0
26 140 0 0 64
26 141 149 0 32
26 141 148 0 0
26 141 147 0 64
26 141 2 0 32
26 141 1 0 0
26 141 0 0 64
26 142 149 0 32
26 142 148 0 0
26 142 147 0 64
26 142 2 0 32
26 142 1 0 0
26 142 0 0 64
26 143 149 0 32
26 143 148 0 0
26 143 147 0 64
26 143 2 0 32
26 143 1 0 0
26 143 0 0 64
26 144 149 0 32
26 144 148 0 0
26 144 147 0 64
26 144 2 0 32
26 144 1 0 0
26 144 0 0 64
26 145 149 0 32
26 145 148 0 0
26 145 147 0 64
26 145 2 0 32
26 145 1 0 0
26 145 0 0 64
26 146 149 0 40
26 146 148 0 8
26 146 147 0 72
26 146 2 0 40
26 146 1 0 8
26 146 0 0 72
27 1 149 0 50
27 1 148 0 18
27 1 147 0 82
27 1 2 0 50
27 1 1 0 18
27 1 0 0 82
27 2 149 0 34
27 2 148 0 2
27 2 147 0 66
27 2 2 0 34
27 2 1 0 2
27 2 0 0 66
27 3 149 0 34
27 3 148 0 2
27 3 147 0 66
27 3 2 0 34
27 3 1 0 2
27 3 0 0 66
27 4 149 0 34
27 4 148 0 2
27 4 147 0 66
27 4 2 0 34
27 4 1 0 2
27 4 0 0 66
27 5 149 0 34
27 5 148 0 2
27 5 147 0 66
27 5 2 0 34
27 5 1 0 2
27 5 0 0 66
27 6 149 0 34
27 6 148 0 2
27 6 147 0 66
27 6 2 0 34
27 6 1 0 2
27 6 0 0 66
27 7 149 0 34
27 7 148 0 2
27 7 147 0 66
27 7 2 0 34
27 7 1 0 2
27 7 0 0 66
27 8 149 0 34
27 8 148 0 2
27 8 147 0 66
27 8 2 0 34
27 8 1 0 2
27 8 0 0 66
27 9 149 0 34
27 9 148 0 2
27 9 147 0 66
27 9 2 0 34
27 9 1 0 2
27 9 0 0 66
27 10 149 0 34
27 10 148 0 2
27 10 147 0 66
27 10 2 0 34
27 10 1 0 2
27 10 0 0 66
27 11 149 0 34
27 11 148 0 2
27 11 147 0 66
27 11 2 0 34
27 11 1 0 2
27 11 0 0 66
27 12 149 0 34
27 12 148 0 2
27 12 147 0 66
27 12 2 0 34
27 12 1 0 2
27 12 0 0 66
27 13 149 0 34
27 13 148 0 2
27 13 147 0 66
27 13 2 0 34
27 13 1 0 2
27 13 0 0 66
27 14 149 0 34
27 14 148 0 2
27 14 147 0 66
27 14 2 0 34
27 14 1 0 2
27 14 0 0 66
27 15 149 0 34
27 15 148 0 2
27 15 147 0 66
27 15 2 0 34
27 15 1 0 2
27 15 0 0 66
27 16 149 0 34
27 16 148 0 2
27 16 147 0 66
27 16 2 0 34
27 16 1 0 2
27 16 0 0 66
27 17 149 0 34
27 17 148 0 2
27 17 147 0 66
27 17 2 0 34
27 17 1 0 2
27 17 0 0 66
27 18 149 0 34
27 18 148 0 2
27 18 147 0 66
27 18 2 0 34
27 18 1 0 2
27 18 0 0 66
27 19 149 0 34
27 19 148 0 2
27 19 147 0 66
27 19 2 0 34
27 19 1 0 2
27 19 0 0 66
27 20 149 0 34
27 20 148 0 2
27 20 147 0 66
27 20 2 0 34
27 20 1 0 2
27 20 0 0 66
27 21 149 0 34
27 21 148 0 2
27 21 147 0 66
27 21 2 0 34
27 21 1 0 2
27 21 0 0 66
27 22 149 0 34
27 22 148 0 2
27 22 147 0 66
27 22 2 0 34
27 22 1 0 2
27 22 0 0 66
27 23 149 0 34
27 23 148 0 2
27 23 147 0 66
27 23 2 0 34
27 23 1 0 2
27 23 0 0 66
27 24 149 0 34
27 24 148 0 2
27 24 147 0 66
27 24 2 0 34
27 24 1 0 2
27 24 0 0 66
27 25 149 0 34
27 25 148 0 2
27 25 147 0 66
27 25 2 0 34
27 25 1 0 2
27 25 0 0 66
27 26 149 0 34
27 26 148 0 2
27 26 147 0 66
27 26 2 0 34
27 26 1 0 2
27 26 0 0 66
27 27 149 0 34
27 27 148 0 2
27 27 147 0 66
27 27 2 0 34
27 27 1 0 2
27 27 0 0 66
27 28 149 0 34
27 28 148 0 2
27 28 147 0 66
27 28 2 0 34
27 28 1 0 2
27 28 0 0 66
27 29 149 0 34
27 29 148 0 2
27 29 147 0 66
27 29 2 0 34
27 29 1 0 2
27 29 0 0 66
27 30 149 0 34
27 30 148 0 2
27 30 147 0 66
27 30 2 0 34
27 30 1 0 2
27 30 0 0 66
27 31 149 0 34
27 31 148 0 2
27 31 147 0 66
27 31 2 0 34
27 31 1 0 2
27 31 0 0 66
27 32 149 0 34
27 32 148 0 2
27 32 147 0 66
27 32 2 0 34
27 32 1 0 2
27 32 0 0 66
27 33 149 0 34
27 33 148 0 2
27 33 147 0 66
27 33 2 0 34
27 33 1 0 2
27 33 0 0 66
27 34 149 0 34
27 34 148 0 2
27 34 147 0 66
27 34 2 0 34
27 34 1 0 2
27 34 0 0 66
27 35 149 0 34
27 35 148 0 2
27 35 147 0 66
27 35 2 0 34
27 35 1 0 2
27 35 0 0 66
27 36 149 0 34
27 36 148 0 2
27 36 147 0 66
27 36 2 0 34
27 36 1 0 2
27 36 0 0 66
27 37 149 0 34
27 37 148 0 2
27 37 147 0 66
27 37 2 0 34
27 37 1 0 2
27 37 0 0 66
27 38 149 0 34
27 38 148 0 2
27 38 147 0 66
27 38 2 0 34
27 38 1 0 2
27 38 0 0 66
27 39 149 0 34
27 39 148 0 2
27 39 147 0 66
27 39 2 0 34
27 39 1 0 2
27 39 0 0 66
27 40 149 0 34
27 40 148 0 2
27 40 147 0 66
27 40 2 0 34
27 40 1 0 2
27 40 0 0 66
27 41 149 0 34
27 41 148 0 2
27 41 147 0 66
27 41 2 0 34
27 41 1 0 2
27 41 0 0 66
27 42 149 0 34
27 42 148 0 2
27 42 147 0 66
27 42 2 0 34
27 42 1 0 2
27 42 0 0 66
27 43 149 0 34
27 43 148 0 2
27 43 147 0 66
27 43 2 0 34
27 43 1 0 2
27 43 0 0 66
27 44 149 0 34
27 44 148 0 2
27 44 147 0 66
27 44 2 0 34
27 44 1 0 2
27 44 0 0 66
27 45 149 0 34
27 45 148 0 2
27 45 147 0 66
27 45 2 0 34
27 45 1 0 2
27 45 0 0 66
27 46 149 0 34
27 46 148 0 2
27 46 147 0 66
27 46 2 0 34
27 46 1 0 2
27 46 0 0 66
27 47 149 0 34
27 47 148 0 2
27 47 147 0 66
27 47 2 0 34
27 47 1 0 2
27 47 0 0 66
27 48 149 0 34
27 48 148 0 2
27 48 147 0 66
27 48 2 0 34
27 48 1 0 2
27 48 0 0 66
27 49 149 0 34
27 49 148 0 2
27 49 147 0 66
27 49 2 0 34
27 49 1 0 2
27 49 0 0 66
27 50 149 0 34
27 50 148 0 2
27 50 147 0 66
27 50 2 0 34
27 50 1 0 2
27 50 0 0 66
27 51 149 0 34
27 51 148 0 2
27 51 147 0 66
27 51 2 0 34
27 51 1 0 2
27 51 0 0 66
27 52 149 0 34
27 52 148 0 2
27 52 147 0 66
27 52 2 0 34
27 52 1 0 2
27 52 0 0 66
27 53 149 0 34
27 53 148 0 2
27 53 147 0 66
27 53 2 0 34
27 53 1 0 2
27 53 0 0 66
27 54 149 0 34
27 54 148 0 2
27 54 147 0 66
27 54 2 0 34
27 54 1 0 2
27 54 0 0 66
27 55 149 0 34
27 55 148 0 2
27 55 147 0 66
27 55 2 0 34
27 55 1 0 2
27 55 0 0 66
27 56 149 0 34
27 56 148 0 2
27 56 147 0 66
27 56 2 0 34
27 56 1 0 2
27 56 0 0 66
27 57 149 0 34
27 57 148 0 2
27 57 147 0 66
27 57 2 0 34
27 57 1 0 2
27 57 0 0 66
27 58 149 0 34
27 58 148 0 2
27 58 147 0 66
27 58 2 0 34
27 58 1 0 2
27 58 0 0 66
27 59 149 0 34
27 59 148 0 2
27 59 147 0 66
27 59 2 0 34
27 59 1 0 2
27 59 0 0 66
27 60 149 0 34
27 60 148 0 2
27 60 147 0 66
27 60 2 0 34
27 60 1 0 2
27 60 0 0 66
27 61 149 0 34
27 61 148 0 2
27 61 147 0 66
27 61 2 0 34
27 61 1 0 2
27 61 0 0 66
27 62 149 0 34
27 62 148 0 2
27 62 147 0 66
27 62 2 0 34
27 62 1 0 2
27 62 0 0 66
27 63 149 0 34
27 63 148 0 2
27 63 147 0 66
27 63 2 0 34
27 63 1 0 2
27 63 0 0 66
27 64 149 0 34
27 64 148 0 2
27 64 147 0 66
27 64 2 0 34
27 64 1 0 2
27 64 0 0 66
27 65 149 0 34
27 65 148 0 2
27 65 147 0 66
27 65 2 0 34
27 65 1 0 2
27 65 0 0 66
27 66 149 0 34
27 66 148 0 2
27 66 147 0 66
27 66 2 0 34
27 66 1 0 2
27 66 0 0 66
27 67 149 0 34
27 67 148 0 2
27 67 147 0 66
27 67 2 0 34
27 67 1 0 2
27 67 0 0 66
27 68 149 0 34
27 68 148 0 2
27 68 147 0 66
27 68 2 0 34
27 68 1 0 2
27 68 0 0 66
27 69 149 0 34
27 69 148 0 2
27 69 147 0 66
27 69 2 0 34
27 69 1 0 2
27 69 0 0 66
27 70 149 0 34
27 70 148 0 2
27 70 147 0 66
27 70 2 0 34
27 70 1 0 2
27 70 0 0 66
27 71 149 0 34
27 71 148 0 2
27 71 147 0 66
27 71 2 0 34
27 71 1 0 2
27 71 0 0 66
27 72 149 0 34
27 72 148 0 2
27 72 147 0 66
27 72 2 0 34
27 72 1 0 2
27 72 0 0 66
27 73 149 0 34
27 73 148 0 2
27 73 147 0 66
27 73 2 0 34
27 73 1 0 2
27 73 0 0 66
27 74 149 0 34
27 74 148 0 2
27 74 147 0 66
27 74 2 0 34
27 74 1 0 2
27 74 0 0 66
27 75 149 0 34
27 75 148 0 2
27 75 147 0 66
27 75 2 0 34
27 75 1 0 2
27 75 0 0 66
27 76 149 0 34
27 76 148 0 2
27 76 147 0 66
27 76 2 0 34
27 76 1 0 2
27 76 0 0 66
27 77 149 0 34
27 77 148 0 2
27 77 147 0 66
27 77 2 0 34
27 77 1 0 2
27 77 0 0 66
27 78 149 0 34
27 78 148 0 2
27 78 147 0 66
27 78 2 0 34
27 78 1 0 2
27 78 0 0 66
27 79 149 0 34
27 79 148 0 2
27 79 147 0 66
27 79 2 0 34
27 79 1 0 2
27 79 0 0 66
27 80 149 0 34
27 80 148 0 2
27 80 147 0 66
27 80 2 0 34
27 80 1 0 2
27 80 0 0 66
27 81 149 0 34
27 81 148 0 2
27 81 147 0 66
27 81 2 0 34
27 81 1 0 2
27 81 0 0 66
27 82 149 0 34
27 82 148 0 2
27 82 147 0 66
27 82 2 0 34
27 82 1 0 2
27 82 0 0 66
27 83 149 0 34
27 83 148 0 2
27 83 147 0 66
27 83 2 0 34
27 83 1 0 2
27 83 0 0 66
27 84 149 0 34
27 84 148 0 2
27 84 147 0 66
27 84 2 0 34
27 84 1 0 2
27 84 0 0 66
27 85 149 0 34
27 85 148 0 2
27 85 147 0 66
27 85 2 0 34
27 85 1 0 2
27 85 0 0 66
27 86 149 0 34
27 86 148 0 2
27 86 147 0 66
27 86 2 0 34
27 86 1 0 2
27 86 0 0 66
27 87 149 0 34
27 87 148 0 2
27 87 147 0 66
27 87 2 0 34
27 87 1 0 2
27 87 0 0 66
27 88 149 0 34
27 88 148 0 2
27 88 147 0 66
27 88 2 0 34
27 88 1 0 2
27 88 0 0 66
27 89 149 0 34
27 89 148 0 2
27 89 147 0 66
27 89 2 0 34
27 89 1 0 2
27 89 0 0 66
27 90 149 0 34
27 90 148 0 2
27 90 147 0 66
27 90 2 0 34
27 90 1 0 2
27 90 0 0 66
27 91 149 0 34
27 91 148 0 2
27 91 147 0 66
27 91 2 0 34
27 91 1 0 2
27 91 0 0 66
27 92 149 0 34
27 92 148 0 2
27 92 147 0 66
27 92 2 0 34
27 92 1 0 2
27 92 0 0 66
27 93 149 0 34
27 93 148 0 2
27 93 147 0 66
27 93 2 0 34
27 93 1 0 2
27 93 0 0 66
27 94 149 0 34
27 94 148 0 2
27 94 147 0 66
27 94 2 0 34
27 94 1 0 2
27 94 0 0 66
27 95 149 0 34
27 95 148 0 2
27 95 147 0 66
27 95 2 0 34
27 95 1 0 2
27 95 0 0 66
27 96 149 0 34
27 96 148 0 2
27 96 147 0 66
27 96 2 0 34
27 96 1 0 2
27 96 0 0 66
27 97 149 0 34
27 97 148 0 2
27 97 147 0 66
27 97 2 0 34
27 97 1 0 2
27 97 0 0 66
27 98 149 0 34
27 98 148 0 2
27 98 147 0 66
27 98 2 0 34
27 98 1 0 2
27 98 0 0 66
27 99 149 0 34
27 99 148 0 2
27 99 147 0 66
27 99 2 0 34
27 99 1 0 2
27 99 0 0 66
27 100 149 0 34
27 100 148 0 2
27 100 147 0 66
27 100 2 0 34
27 100 1 0 2
27 100 0 0 66
27 101 149 0 34
27 101 148 0 2
27 101 147 0 66
27 101 2 0 34
27 101 1 0 2
27 101 0 0 66
27 102 149 0 34
27 102 148 0 2
27 102 147 0 66
27 102 2 0 34
27 102 1 0 2
27 102 0 0 66
27 103 149 0 34
27 103 148 0 2
27 103 147 0 66
27 103 2 0 34
27 103 1 0 2
27 103 0 0 66
27 104 149 0 34
27 104 148 0 2
27 104 147 0 66
27 104 2 0 34
27 104 1 0 2
27 104 0 0 66
27 105 149 0 34
27 105 148 0 2
27 105 147 0 66
27 105 2 0 34
27 105 1 0 2
27 105 0 0 66
27 106 149 0 32
27 106 148 0 0
27 106 147 0 64
27 106 2 0 32
27 106 1 0 0
27 106 0 0 64
27 107 149 0 32
27 107 148 0 0
27 107 147 0 64
27 107 2 0 32
27 107 1 0 0
27 107 0 0 64
27 108 149 0 32
27 108 148 0 0
27 108 147 0 64
27 108 2 0 32
27 108 1 0 0
27 108 0 0 64
27 109 149 0 32
27 109 148 0 0
27 109 147 0 64
27 109 2 0 32
27 109 1 0 0
27 109 0 0 64
27 110 149 0 32
27 110 148 0 0
27 110 147 0 64
27 110 2 0 32
27 110 1 0 0
27 110 0 0 64
27 111 149 0 34
27 111 148 0 2
27 111 147 0 66
27 111 2 0 34
27 111 1 0 2
27 111 0 0 66
27 112 149 0 34
27 112 148 0 2
27 112 147 0 66
27 112 2 0 34
27 112 1 0 2
27 112 0 0 66
27 113 149 0 34
27 113 148 0 2
27 113 147 0 66
27 113 2 0 34
27 113 1 0 2
27 113 0 0 66
27 114 149 0 34
27 114 148 0 2
27 114 147 0 66
27 114 2 0 34
27 114 1 0 2
27 114 0 0 66
27 115 149 0 34
27 115 148 0 2
27 115 147 0 66
27 115 2 0 34
27 115 1 0 2
27 115 0 0 66
27 116 149 0 34
27 116 148 0 2
27 116 147 0 66
27 116 2 0 34
27 116 1 0 2
27 116 0 0 66
27 117 149 0 32
27 117 148 0 0
27 117 147 0 64
27 117 2 0 32
27 117 1 0 0
27 117 0 0 64
27 118 149 0 32
27 118 148 0 0
27 118 147 0 64
27 118 2 0 32
27 118 1 0 0
27 118 0 0 64
27 119 149 0 32
27 119 148 0 0
27 119 147 0 64
27 119 2 0 32
27 119 1 0 0
27 119 0 0 64
27 120 149 0 34
27 120 148 0 2
27 120 147 0 66
27 120 2 0 34
27 120 1 0 2
27 120 0 0 66
27 121 149 0 34
27 121 148 0 2
27 121 147 0 66
27 121 2 0 34
27 121 1 0 2
27 121 0 0 66
27 122 149 0 34
27 122 148 0 2
27 122 147 0 66
27 122 2 0 34
27 122 1 0 2
27 122 0 0 66
27 123 149 0 34
27 123 148 0 2
27 123 147 0 66
27 123 2 0 34
27 123 1 0 2
27 123 0 0 66
27 124 149 0 34
27 124 148 0 2
27 124 147 0 66
27 124 2 0 34
27 124 1 0 2
27 124 0 0 66
27 125 149 0 34
27 125 148 0 2
27 125 147 0 66
27 125 2 0 34
27 125 1 0 2
27 125 0 0 66
27 126 149 0 34
27 126 148 0 2
27 126 147 0 66
27 126 2 0 34
27 126 1 0 2
27 126 0 0 66
27 127 149 0 34
27 127 148 0 2
27 127 147 0 66
27 127 2 0 34
27 127 1 0 2
27 127 0 0 66
27 128 149 0 34
27 128 148 0 2
27 128 147 0 66
27 128 2 0 34
27 128 1 0 2
27 128 0 0 66
27 129 149 0 34
27 129 148 0 2
27 129 147 0 66
27 129 2 0 34
27 129 1 0 2
27 129 0 0 66
27 130 149 0 34
27 130 148 0 2
27 130 147 0 66
27 130 2 0 34
27 130 1 0 2
27 130 0 0 66
27 131 149 0 34
27 131 148 0 2
27 131 147 0 66
27 131 2 0 34
27 131 1 0 2
27 131 0 0 66
27 132 149 0 34
27 132 148 0 2
27 132 147 0 66
27 132 2 0 34
27 132 1 0 2
27 132 0 0 66
27 133 149 0 34
27 133 148 0 2
27 133 147 0 66
27 133 2 0 34
27 133 1 0 2
27 133 0 0 66
27 134 149 0 34
27 134 148 0 2
27 134 147 0 66
27 134 2 0 34
27 134 1 0 2
27 134 0 0 66
27 135 149 0 34
27 135 148 0 2
27 135 147 0 66
27 135 2 0 34
27 135 1 0 2
27 135 0 0 66
27 136 149 0 34
27 136 148 0 2
27 136 147 0 66
27 136 2 0 34
27 136 1 0 2
27 136 0 0 66
27 137 149 0 34
27 137 148 0 2
27 137 147 0 66
27 137 2 0 34
27 137 1 0 2
27 137 0 0 66
27 138 149 0 34
27 138 148 0 2
27 138 147 0 66
27 138 2 0 34
27 138 1 0 2
27 138 0 0 66
27 139 149 0 34
27 139 148 0 2
27 139 147 0 66
27 139 2 0 34
27 139 1 0 2
27 139 0 0 66
27 140 149 0 34
27 140 148 0 2
27 140 147 0 66
27 140 2 0 34
27 140 1 0 2
27 140 0 0 66
27 141 149 0 34
27 141 148 0 2
27 141 147 0 66
27 141 2 0 34
27 141 1 0 2
27 141 0 0 66
27 142 149 0 34
27 142 148 0 2
27 142 147 0 66
27 142 2 0 34
27 142 1 0 2
27 142 0 0 66
27 143 149 0 34
27 143 148 0 2
27 143 147 0 66
27 143 2 0 34
27 143 1 0 2
27 143 0 0 66
27 144 149 0 34
27 144 148 0 2
27 144 147 0 66
27 144 2 0 34
27 144 1 0 2
27 144 0 0 66
27 145 149 0 34
27 145 148 0 2
27 145 147 0 66
27 145 2 0 34
27 145 1 0 2
27 145 0 0 66
27 146 149 0 42
27 146 148 0 10
27 146 147 0 74
27 146 2 0 42
27 146 1 0 10
27 146 0 0 74
28 106 149 0 48
28 106 148 0 16
28 106 147 0 80
28 106 2 0 48
28 106 1 0 16
28 106 0 0 80
28 107 149 0 32
28 107 148 0 0
28 107 147 0 64
28 107 2 0 32
28 107 1 0 0
28 107 0 0 64
28 108 149 0 32
28 108 148 0 0
28 108 147 0 64
28 108 2 0 32
28 108 1 0 0
28 108 0 0 64
28 109 149 0 32
28 109 148 0 0
28 109 147 0 64
28 109 2 0 32
28 109 1 0 0
28 109 0 0 64
28 110 149 0 40
28 110 148 0 8
28 110 147 0 72
28 110 2 0 40
28 110 1 0 8
28 110 0 0 72
28 117 149 0 48
28 117 148 0 16
28 117 147 0 80
28 117 2 0 48
28 117 1 0 16
28 117 0 0 80
28 118 149 0 32
28 118 148 0 0
28 118 147 0 64
28 118 2 0 32
28 118 1 0 0
28 118 0 0 64
28 119 149 0 40
28 119 148 0 8
28 119 147 0 72
28 119 2 0 40
28 119 1 0 8
28 119 0 0 72
29 105 149 0 52
29 105 148 0 20
29 105 147 0 84
29 105 2 0 52
29 105 1 0 20
29 105 0 0 84
29 106 149 0 34
29 106 148 0 2
29 106 147 0 66
29 106 2 0 34
29 106 1 0 2
29 106 0 0 66
29 107 149 0 34
29 107 148 0 2
29 107 147 0 66
29 107 2 0 34
29 107 1 0 2
29 107 0 0 66
29 108 149 0 34
29 108 148 0 2
29 108 147 0 66
29 108 2 0 34
29 108 1 0 2
29 108 0 0 66
29 109 149 0 34
29 109 148 0 2
29 109 147 0 66
29 109 2 0 34
29 109 1 0 2
29 109 0 0 66
29 110 149 0 32
29 110 148 0 0
29 110 147 0 64
29 110 2 0 32
29 110 1 0 0
29 110 0 0 64
29 111 149 0 44
29 111 148 0 12
29 111 147 0 76
29 111 2 0 44
29 111 1 0 12
29 111 0 0 76
29 117 149 0 48
29 117 148 0 16
29 117 147 0 80
29 117 2 0 48
29 117 1 0 16
29 117 0 0 80
29 118 149 0 32
29 118 148 0 0
29 118 147 0 64
29 118 2 0 32
29 118 1 0 0
29 118 0 0 64
29 119 149 0 40
29 119 148 0 8
29 119 147 0 72
29 119 2 0 40
29 119 1 0 8
29 119 0 0 72
30 104 149 0 54
30 104 148 0 22
30 104 147 0 86
30 104 2 0 54
30 104 1 0 22
30 104 0 0 86
30 105 149 0 40
30 105 148 0 8
30 105 147 0 72
30 105 2 0 40
30 105 1 0 8
30 105 0 0 72
30 110 149 0 50
30 110 148 0 18
30 110 147 0 82
30 110 2 0 50
30 110 1 0 18
30 110 0 0 82
30 111 149 0 32
30 111 148 0 0
30 111 147 0 64
30 111 2 0 32
30 111 1 0 0
30 111 0 0 64
30 112 149 0 44
30 112 148 0 12
30 112 147 0 76
30 112 2 0 44
30 112 1 0 12
30 112 0 0 76
30 117 149 0 48
30 117 148 0 16
30 117 147 0 80
30 117 2 0 48
30 117 1 0 16
30 117 0 0 80
30 118 149 0 32
30 118 148 0 0
30 118 147 0 64
30 118 2 0 32
30 118 1 0 0
30 118 0 0 64
30 119 149 0 40
30 119 148 0 8
30 119 147 0 72
30 119 2 0 40
30 119 1 0 8
30 119 0 0 72
31 105 149 0 50
31 105 148 0 18
31 105 147 0 82
31 105 2 0 50
31 105 1 0 18
31 105 0 0 82
31 106 149 0 46
31 106 148 0 14
31 106 147 0 78
31 106 2 0 46
31 106 1 0 14
31 106 0 0 78
31 111 149 0 48
31 111 148 0 16
31 111 147 0 80
31 111 2 0 48
31 111 1 0 16
31 111 0 0 80
31 112 149 0 40
31 112 148 0 8
31 112 147 0 72
31 112 2 0 40
31 112 1 0 8
31 112 0 0 72
31 117 149 0 48
31 117 148 0 16
31 117 147 0 80
31 117 2 0 48
31 117 1 0 16
31 117 0 0 80
31 118 149 0 32
31 118 148 0 0
31 118 147 0 64
31 118 2 0 32
31 118 1 0 0
31 118 0 0 64
31 119 149 0 40
31 119 148 0 8
31 119 147 0 72
31 119 2 0 40
31 119 1 0 8
31 119 0 0 72
32 111 149 0 48
32 111 148 0 16
32 111 147 0 80
32 111 2 0 48
32 111 1 0 16
32 111 0 0 80
32 112 149 0 32
32 112 148 0 0
32 112 147 0 64
32 112 2 0 32
32 112 1 0 0
32 112 0 0 64
32 113 149 0 36
32 113 148 0 4
32 113 147 0 68
32 113 2 0 36
32 113 1 0 4
32 113 0 0 68
32 114 149 0 44
32 114 148 0 12
32 114 147 0 76
32 114 2 0 44
32 114 1 0 12
32 114 0 0 76
32 117 149 0 48
32 117 148 0 16
32 117 147 0 80
32 117 2 0 48
32 117 1 0 16
32 117 0 0 80
32 118 149 0 32
32 118 148 0 0
32 118 147 0 64
32 118 2 0 32
32 118 1 0 0
32 118 0 0 64
32 119 149 0 40
32 119 148 0 8
32 119 147 0 72
32 119 2 0 40
32 119 1 0 8
32 119 0 0 72
33 110 149 0 52
33 110 148 0 20
33 110 147 0 84
33 110 2 0 52
33 110 1 0 20
33 110 0 0 84
33 111 149 0 32
33 111 148 0 0
33 111 147 0 64
33 111 2 0 32
33 111 1 0 0
33 111 0 0 64
33 112 149 0 34
33 112 148 0 2
33 112 147 0 66
33 112 2 0 34
33 112 1 0 2
33 112 0 0 66
33 113 149 0 34
33 113 148 0 2
33 113 147 0 66
33 113 2 0 34
33 113 1 0 2
33 113 0 0 66
33 114 149 0 32
33 114 148 0 0
33 114 147 0 64
33 114 2 0 32
33 114 1 0 0
33 114 0 0 64
33 115 149 0 44
33 115 148 0 12
33 115 147 0 76
33 115 2 0 44
33 115 1 0 12
33 115 0 0 76
33 117 149 0 48
33 117 148 0 16
33 117 147 0 80
33 117 2 0 48
33 117 1 0 16
33 117 0 0 80
33 118 149 0 32
33 118 148 0 0
33 118 147 0 64
33 118 2 0 32
33 118 1 0 0
33 118 0 0 64
33 119 149 0 40
33 119 148 0 8
33 119 147 0 72
33 119 2 0 40
33 119 1 0 8
33 119 0 0 72
34 110 149 0 50
34 110 148 0 18
34 110 147 0 82
34 110 2 0 50
34 110 1 0 18
34 110 0 0 82
34 111 149 0 42
34 111 148 0 10
34 111 147 0 74
34 111 2 0 42
34 111 1 0 10
34 111 0 0 74
34 114 149 0 50
34 114 148 0 18
34 114 147 0 82
34 114 2 0 50
34 114 1 0 18
34 114 0 0 82
34 115 149 0 32
34 115 148 0 0
34 115 147 0 64
34 115 2 0 32
34 115 1 0 0
34 115 0 0 64
34 116 149 0 36
34 116 148 0 4
34 116 147 0 68
34 116 2 0 36
34 116 1 0 4
34 116 0 0 68
34 117 149 0 32
34 117 148 0 0
34 117 147 0 64
34 117 2 0 32
34 117 1 0 0
34 117 0 0 64
34 118 149 0 32
34 118 148 0 0
34 118 147 0 64
34 118 2 0 32
34 118 1 0 0
34 118 0 0 64
34 119 149 0 40
34 119 148 0 8
34 119 147 0 72
34 119 2 0 40
34 119 1 0 8
34 119 0 0 72
35 115 149 0 48
35 115 148 0 16
35 115 147 0 80
35 115 2 0 48
35 115 1 0 16
35 115 0 0 80
35 116 149 0 32
35 116 148 0 0
35 116 147 0 64
35 116 2 0 32
35 116 1 0 0
35 116 0 0 64
35 117 149 0 32
35 117 148 0 0
35 117 147 0 64
35 117 2 0 32
35 117 1 0 0
35 117 0 0 64
35 118 149 0 32
35 118 148 0 0
35 118 147 0 64
35 118 2 0 32
35 118 1 0 0
35 118 0 0 64
35 119 149 0 40
35 119 148 0 8
35 119 147 0 72
35 119 2 0 40
35 119 1 0 8
35 119 0 0 72
36 115 149 0 48
36 115 148 0 16
36 115 147 0 80
36 115 2 0 48
36 115 1 0 16
36 115 0 0 80
36 116 149 0 32
36 116 148 0 0
36 116 147 0 64
36 116 2 0 32
36 116 1 0 0
36 116 0 0 64
36 117 149 0 32
36 117 148 0 0
36 117 147 0 64
36 117 2 0 32
36 117 1 0 0
36 117 0 0 64
36 118 149 0 32
36 118 148 0 0
36 118 147 0 64
36 118 2 0 32
36 118 1 0 0
36 118 0 0 64
36 119 149 0 40
36 119 148 0 8
36 119 147 0 72
36 119 2 0 40
36 119 1 0 8
36 119 0 0 72
37 115 149 0 48
37 115 148 0 16
37 115 147 0 80
37 115 2 0 48
37 115 1 0 16
37 115 0 0 80
37 116 149 0 32
37 116 148 0 0
37 116 147 0 64
37 116 2 0 32
37 116 1 0 0
37 116 0 0 64
37 117 149 0 32
37 117 148 0 0
37 117 147 0 64
37 117 2 0 32
37 117 1 0 0
37 117 0 0 64
37 118 149 0 32
37 118 148 0 0
37 118 147 0 64
37 118 2 0 32
37 118 1 0 0
37 118 0 0 64
37 119 149 0 40
37 119 148 0 8
37 119 147 0 72
37 119 2 0 40
37 119 1 0 8
37 119 0 0 72
38 113 149 0 60
38 113 148 0 28
38 113 147 0 92
38 113 2 0 60
38 113 1 0 28
38 113 0 0 92
38 115 149 0 48
38 115 148 0 16
38 115 147 0 80
38 115 2 0 48
38 115 1 0 16
38 115 0 0 80
38 116 149 0 34
38 116 148 0 2
38 116 147 0 66
38 116 2 0 34
38 116 1 0 2
38 116 0 0 66
38 117 149 0 32
38 117 148 0 0
38 117 147 0 64
38 117 2 0 32
38 117 1 0 0
38 117 0 0 64
38 118 149 0 32
38 118 148 0 0
38 118 147 0 64
38 118 2 0 32
38 118 1 0 0
38 118 0 0 64
38 119 149 0 40
38 119 148 0 8
38 119 147 0 72
38 119 2 0 40
38 119 1 0 8
38 119 0 0 72
39 113 149 0 50
39 113 148 0 18
39 113 147 0 82
39 113 2 0 50
39 113 1 0 18
39 113 0 0 82
39 114 149 0 36
39 114 148 0 4
39 114 147 0 68
39 114 2 0 36
39 114 1 0 4
39 114 0 0 68
39 115 149 0 42
39 115 148 0 10
39 115 147 0 74
39 115 2 0 42
39 115 1 0 10
39 115 0 0 74
39 117 149 0 48
39 117 148 0 16
39 117 147 0 80
39 117 2 0 48
39 117 1 0 16
39 117 0 0 80
39 118 149 0 32
39 118 148 0 0
39 118 147 0 64
39 118 2 0 32
39 118 1 0 0
39 118 0 0 64
39 119 149 0 40
39 119 148 0 8
39 119 147 0 72
39 119 2 0 40
39 119 1 0 8
39 119 0 0 72
40 114 149 0 58
40 114 148 0 26
40 114 147 0 90
40 114 2 0 58
40 114 1 0 26
40 114 0 0 90
40 117 149 0 48
40 117 148 0 16
40 117 147 0 80
40 117 2 0 48
40 117 1 0 16
40 117 0 0 80
40 118 149 0 32
40 118 148 0 0
40 118 147 0 64
40 118 2 0 32
40 118 1 0 0
40 118 0 0 64
40 119 149 0 40
40 119 148 0 8
40 119 147 0 72
40 119 2 0 40
40 119 1 0 8
40 119 0 0 72
41 117 149 0 48
41 117 148 0 16
41 117 147 0 80
41 117 2 0 48
41 117 1 0 16
41 117 0 0 80
41 118 149 0 32
41 118 148 0 0
41 118 147 0 64
41 118 2 0 32
41 118 1 0 0
41 118 0 0 64
41 119 149 0 40
41 119 148 0 8
41 119 147 0 72
41 119 2 0 40
41 119 1 0 8
41 119 0 0 72
42 117 149 0 48
42 117 148 0 16
42 117 147 0 80
42 117 2 0 48
42 117 1 0 16
42 117 0 0 80
42 118 149 0 32
42 118 148 0 0
42 118 147 0 64
42 118 2 0 32
42 118 1 0 0
42 118 0 0 64
42 119 149 0 40
42 119 148 0 8
42 119 147 0 72
42 119 2 0 40
42 119 1 0 8
42 119 0 0 72
43 117 149 0 48
43 117 148 0 16
43 117 147 0 80
43 117 2 0 48
43 117 1 0 16
43 117 0 0 80
43 118 149 0 32
43 118 148 0 0
43 118 147 0 64
43 118 2 0 32
43 118 1 0 0
43 118 0 0 64
43 119 149 0 40
43 119 148 0 8
43 119 147 0 72
43 119 2 0 40
43 119 1 0 8
43 119 0 0 72
44 117 149 0 48
44 117 148 0 16
44 117 147 0 80
44 117 2 0 48
44 117 1 0 16
44 117 0 0 80
44 118 149 0 32
44 118 148 0 0
44 118 147 0 64
44 118 2 0 32
44 118 1 0 0
44 118 0 0 64
44 119 149 0 40
44 119 148 0 8
44 119 147 0 72
44 119 2 0 40
44 119 1 0 8
44 119 0 0 72
45 117 149 0 48
45 117 148 0 16
45 117 147 0 80
45 117 2 0 48
45 117 1 0 16
45 117 0 0 80
45 118 149 0 32
45 118 148 0 0
45 118 147 0 64
45 118 2 0 32
45 118 1 0 0
45 118 0 0 64
45 119 149 0 40
45 119 148 0 8
45 119 147 0 72
45 119 2 0 40
45 119 1 0 8
45 119 0 0 72
46 117 149 0 48
46 117 148 0 16
46 117 147 0 80
46 117 2 0 48
46 117 1 0 16
46 117 0 0 80
46 118 149 0 32
46 118 148 0 0
46 118 147 0 64
46 118 2 0 32
46 118 1 0 0
46 118 0 0 64
46 119 149 0 40
46 119 148 0 8
46 119 147 0 72
46 119 2 0 40
46 119 1 0 8
46 119 0 0 72
47 117 149 0 48
47 117 148 0 16
47 117 147 0 80
47 117 2 0 48
47 117 1 0 16
47 117 0 0 80
47 118 149 0 32
47 118 148 0 0
47 118 147 0 64
47 118 2 0 32
47 118 1 0 0
47 118 0 0 64
47 119 149 0 40
47 119 148 0 8
47 119 147 0 72
47 119 2 0 40
47 119 1 0 8
47 119 0 0 72
48 117 149 0 48
48 117 148 0 16
48 117 147 0 80
48 117 2 0 48
48 117 1 0 16
48 117 0 0 80
48 118 149 0 32
48 118 148 0 0
48 118 147 0 64
48 118 2 0 32
48 118 1 0 0
48 118 0 0 64
48 119 149 0 32
48 119 148 0 0
48 119 147 0 64
48 119 2 0 32
48 119 1 0 0
48 119 0 0 64
48 120 149 0 44
48 120 148 0 12
48 120 147 0 76
48 120 2 0 44
48 120 1 0 12
48 120 0 0 76
48 124 149 0 60
48 124 148 0 28
48 124 147 0 92
48 124 2 0 60
48 124 1 0 28
48 124 0 0 92
49 117 149 0 50
49 117 148 0 18
49 117 147 0 82
49 117 2 0 50
49 117 1 0 18
49 117 0 0 82
49 118 149 0 32
49 118 148 0 0
49 118 147 0 64
49 118 2 0 32
49 118 1 0 0
49 118 0 0 64
49 119 149 0 32
49 119 148 0 0
49 119 147 0 64
49 119 2 0 32
49 119 1 0 0
49 119 0 0 64
49 120 149 0 32
49 120 148 0 0
49 120 147 0 64
49 120 2 0 32
49 120 1 0 0
49 120 0 0 64
49 121 149 0 44
49 121 148 0 12
49 121 147 0 76
49 121 2 0 44
49 121 1 0 12
49 121 0 0 76
49 123 149 0 52
49 123 148 0 20
49 123 147 0 84
49 123 2 0 52
49 123 1 0 20
49 123 0 0 84
49 124 149 0 40
49 124 148 0 8
49 124 147 0 72
49 124 2 0 40
49 124 1 0 8
49 124 0 0 72
50 118 149 0 50
50 118 148 0 18
50 118 147 0 82
50 118 2 0 50
50 118 1 0 18
50 118 0 0 82
50 119 149 0 32
50 119 148 0 0
50 119 147 0 64
50 119 2 0 32
50 119 1 0 0
50 119 0 0 64
50 120 149 0 32
50 120 148 0 0
50 120 147 0 64
50 120 2 0 32
50 120 1 0 0
50 120 0 0 64
50 121 149 0 32
50 121 148 0 0
50 121 147 0 64
50 121 2 0 32
50 121 1 0 0
50 121 0 0 64
50 122 149 0 36
50 122 148 0 4
50 122 147 0 68
50 122 2 0 36
50 122 1 0 4
50 122 0 0 68
50 123 149 0 32
50 123 148 0 0
50 123 147 0 64
50 123 2 0 32
50 123 1 0 0
50 123 0 0 64
50 124 149 0 42
50 124 148 0 10
50 124 147 0 74
50 124 2 0 42
50 124 1 0 10
50 124 0 0 74
51 119 149 0 50
51 119 148 0 18
51 119 147 0 82
51 119 2 0 50
51 119 1 0 18
51 119 0 0 82
51 120 149 0 34
51 120 148 0 2
51 120 147 0 66
51 120 2 0 34
51 120 1 0 2
51 120 0 0 66
51 121 149 0 34
51 121 148 0 2
51 121 147 0 66
51 121 2 0 34
51 121 1 0 2
51 121 0 0 66
51 122 149 0 34
51 122 148 0 2
51 122 147 0 66
51 122 2 0 34
51 122 1 0 2
51 122 0 0 66
51 123 149 0 42
51 123 148 0 10
51 123 147 0 74
51 123 2 0 42
51 123 1 0 10
51 123 0 0 74
198 119 149 0 52
198 119 148 0 20
198 119 147 0 84
198 119 2 0 52
198 119 1 0 20
198 119 0 0 84
198 120 149 0 36
198 120 148 0 4
198 120 147 0 68
198 120 2 0 36
198 120 1 0 4
198 120 0 0 68
198 121 149 0 36
198 121 148 0 4
198 121 147 0 68
198 121 2 0 36
198 121 1 0 4
198 121 0 0 68
198 122 149 0 36
198 122 148 0 4
198 122 147 0 68
198 122 2 0 36
198 122 1 0 4
198 122 0 0 68
198 123 149 0 44
198 123 148 0 12
198 123 147 0 76
198 123 2 0 44
198 123 1 0 12
198 123 0 0 76
199 118 149 0 52
199 118 148 0 20
199 118 147 0 84
199 118 2 0 52
199 118 1 0 20
199 118 0 0 84
199 119 149 0 32
199 119 148 0 0
199 119 147 0 64
199 119 2 0 32
199 119 1 0 0
199 119 0 0 64
199 120 149 0 32
199 120 148 0 0
199 120 147 0 64
199 120 2 0 32
199 120 1 0 0
199 120 0 0 64
199 121 149 0 32
199 121 148 0 0
199 121 147 0 64
199 121 2 0 32
199 121 1 0 0
199 121 0 0 64
199 122 149 0 34
199 122 148 0 2
199 122 147 0 66
199 122 2 0 34
199 122 1 0 2
199 122 0 0 66
199 123 149 0 32
199 123 148 0 0
199 123 147 0 64
199 123 2 0 32
199 123 1 0 0
199 123 0 0 64
199 124 149 0 44
199 124 148 0 12
199 124 147 0 76
199 124 2 0 44
199 124 1 0 12
199 124 0 0 76
200 117 149 0 52
200 117 148 0 20
200 117 147 0 84
200 117 2 0 52
200 117 1 0 20
200 117 0 0 84
200 118 149 0 32
200 118 148 0 0
200 118 147 0 64
200 118 2 0 32
200 118 1 0 0
200 118 0 0 64
200 119 149 0 32
200 119 148 0 0
200 119 147 0 64
200 119 2 0 32
200 119 1 0 0
200 119 0 0 64
200 120 149 0 32
200 120 148 0 0
200 120 147 0 64
200 120 2 0 32
200 120 1 0 0
200 120 0 0 64
200 121 149 0 42
200 121 148 0 10
200 121 147 0 74
200 121 2 0 42
200 121 1 0 10
200 121 0 0 74
200 123 149 0 50
200 123 148 0 18
200 123 147 0 82
200 123 2 0 50
200 123 1 0 18
200 123 0 0 82
200 124 149 0 40
200 124 148 0 8
200 124 147 0 72
200 124 2 0 40
200 124 1 0 8
200 124 0 0 72
201 117 149 0 48
201 117 148 0 16
201 117 147 0 80
201 117 2 0 48
201 117 1 0 16
201 117 0 0 80
201 118 149 0 32
201 118 148 0 0
201 118 147 0 64
201 118 2 0 32
201 118 1 0 0
201 118 0 0 64
201 119 149 0 32
201 119 148 0 0
201 119 147 0 64
201 119 2 0 32
201 119 1 0 0
201 119 0 0 64
201 120 149 0 42
201 120 148 0 10
201 120 147 0 74
201 120 2 0 42
201 120 1 0 10
201 120 0 0 74
201 124 149 0 58
201 124 148 0 26
201 124 147 0 90
201 124 2 0 58
201 124 1 0 26
201 124 0 0 90
202 117 149 0 48
202 117 148 0 16
202 117 147 0 80
202 117 2 0 48
202 117 1 0 16
202 117 0 0 80
202 118 149 0 32
202 118 148 0 0
202 118 147 0 64
202 118 2 0 32
202 118 1 0 0
202 118 0 0 64
202 119 149 0 40
202 119 148 0 8
202 119 147 0 72
202 119 2 0 40
202 119 1 0 8
202 119 0 0 72
203 117 149 0 48
203 117 148 0 16
203 117 147 0 80
203 117 2 0 48
203 117 1 0 16
203 117 0 0 80
203 118 149 0 32
203 118 148 0 0
203 118 147 0 64
203 118 2 0 32
203 118 1 0 0
203 118 0 0 64
203 119 149 0 40
203 119 148 0 8
203 119 147 0 72
203 119 2 0 40
203 119 1 0 8
203 119 0 0 72
204 117 149 0 48
204 117 148 0 16
204 117 147 0 80
204 117 2 0 48
204 117 1 0 16
204 117 0 0 80
204 118 149 0 32
204 118 148 0 0
204 118 147 0 64
204 118 2 0 32
204 118 1 0 0
204 118 0 0 64
204 119 149 0 40
204 119 148 0 8
204 119 147 0 72
204 119 2 0 40
204 119 1 0 8
204 119 0 0 72
205 117 149 0 48
205 117 148 0 16
205 117 147 0 80
205 117 2 0 48
205 117 1 0 16
205 117 0 0 80
205 118 149 0 32
205 118 148 0 0
205 118 147 0 64
205 118 2 0 32
205 118 1 0 0
205 118 0 0 64
205 119 149 0 40
205 119 148 0 8
205 119 147 0 72
205 119 2 0 40
205 119 1 0 8
205 119 0 0 72
206 117 149 0 48
206 117 148 0 16
206 117 147 0 80
206 117 2 0 48
206 117 1 0 16
206 117 0 0 80
206 118 149 0 32
206 118 148 0 0
206 118 147 0 64
206 118 2 0 32
206 118 1 0 0
206 118 0 0 64
206 119 149 0 40
206 119 148 0 8
206 119 147 0 72
206 119 2 0 40
206 119 1 0 8
206 119 0 0 72
207 117 149 0 48
207 117 148 0 16
207 117 147 0 80
207 117 2 0 48
207 117 1 0 16
207 117 0 0 80
207 118 149 0 32
207 118 148 0 0
207 118 147 0 64
207 118 2 0 32
207 118 1 0 0
207 118 0 0 64
207 119 149 0 40
207 119 148 0 8
207 119 147 0 72
207 119 2 0 40
207 119 1 0 8
207 119 0 0 72
208 117 149 0 48
208 117 148 0 16
208 117 147 0 80
208 117 2 0 48
208 117 1 0 16
208 117 0 0 80
208 118 149 0 32
208 118 148 0 0
208 118 147 0 64
208 118 2 0 32
208 118 1 0 0
208 118 0 0 64
208 119 149 0 40
208 119 148 0 8
208 119 147 0 72
208 119 2 0 40
208 119 1 0 8
208 119 0 0 72
209 114 149 0 60
209 114 148 0 28
209 114 147 0 92
209 114 2 0 60
209 114 1 0 28
209 114 0 0 92
209 117 149 0 48
209 117 148 0 16
209 117 147 0 80
209 117 2 0 48
209 117 1 0 16
209 117 0 0 80
209 118 149 0 32
209 118 148 0 0
209 118 147 0 64
209 118 2 0 32
209 118 1 0 0
209 118 0 0 64
209 119 149 0 40
209 119 148 0 8
209 119 147 0 72
209 119 2 0 40
209 119 1 0 8
209 119 0 0 72
210 113 149 0 52
210 113 148 0 20
210 113 147 0 84
210 113 2 0 52
210 113 1 0 20
210 113 0 0 84
210 114 149 0 34
210 114 148 0 2
210 114 147 0 66
210 114 2 0 34
210 114 1 0 2
210 114 0 0 66
210 115 149 0 44
210 115 148 0 12
210 115 147 0 76
210 115 2 0 44
210 115 1 0 12
210 115 0 0 76
210 117 149 0 48
210 117 148 0 16
210 117 147 0 80
210 117 2 0 48
210 117 1 0 16
210 117 0 0 80
210 118 149 0 32
210 118 148 0 0
210 118 147 0 64
210 118 2 0 32
210 118 1 0 0
210 118 0 0 64
210 119 149 0 40
210 119 148 0 8
210 119 147 0 72
210 119 2 0 40
210 119 1 0 8
210 119 0 0 72
211 113 149 0 58
211 113 148 0 26
211 113 147 0 90
211 113 2 0 58
211 113 1 0 26
211 113 0 0 90
211 115 149 0 48
211 115 148 0 16
211 115 147 0 80
211 115 2 0 48
211 115 1 0 16
211 115 0 0 80
211 116 149 0 36
211 116 148 0 4
211 116 147 0 68
211 116 2 0 36
211 116 1 0 4
211 116 0 0 68
211 117 149 0 32
211 117 148 0 0
211 117 147 0 64
211 117 2 0 32
211 117 1 0 0
211 117 0 0 64
211 118 149 0 32
211 118 148 0 0
211 118 147 0 64
211 118 2 0 32
211 118 1 0 0
211 118 0 0 64
211 119 149 0 40
211 119 148 0 8
211 119 147 0 72
211 119 2 0 40
211 119 1 0 8
211 119 0 0 72
212 115 149 0 48
212 115 148 0 16
212 115 147 0 80
212 115 2 0 48
212 115 1 0 16
212 115 0 0 80
212 116 149 0 32
212 116 148 0 0
212 116 147 0 64
212 116 2 0 32
212 116 1 0 0
212 116 0 0 64
212 117 149 0 32
212 117 148 0 0
212 117 147 0 64
212 117 2 0 32
212 117 1 0 0
212 117 0 0 64
212 118 149 0 32
212 118 148 0 0
212 118 147 0 64
212 118 2 0 32
212 118 1 0 0
212 118 0 0 64
212 119 149 0 40
212 119 148 0 8
212 119 147 0 72
212 119 2 0 40
212 119 1 0 8
212 119 0 0 72
213 115 149 0 48
213 115 148 0 16
213 115 147 0 80
213 115 2 0 48
213 115 1 0 16
213 115 0 0 80
213 116 149 0 32
213 116 148 0 0
213 116 147 0 64
213 116 2 0 32
213 116 1 0 0
213 116 0 0 64
213 117 149 0 32
213 117 148 0 0
213 117 147 0 64
213 117 2 0 32
213 117 1 0 0
213 117 0 0 64
213 118 149 0 32
213 118 148 0 0
213 118 147 0 64
213 118 2 0 32
213 118 1 0 0
213 118 0 0 64
213 119 149 0 40
213 119 148 0 8
213 119 147 0 72
213 119 2 0 40
213 119 1 0 8
213 119 0 0 72
214 115 149 0 48
214 115 148 0 16
214 115 147 0 80
214 115 2 0 48
214 115 1 0 16
214 115 0 0 80
214 116 149 0 32
214 116 148 0 0
214 116 147 0 64
214 116 2 0 32
214 116 1 0 0
214 116 0 0 64
214 117 149 0 32
214 117 148 0 0
214 117 147 0 64
214 117 2 0 32
214 117 1 0 0
214 117 0 0 64
214 118 149 0 32
214 118 148 0 0
214 118 147 0 64
214 118 2 0 32
214 118 1 0 0
214 118 0 0 64
214 119 149 0 40
214 119 148 0 8
214 119 147 0 72
214 119 2 0 40
214 119 1 0 8
214 119 0 0 72
215 110 149 0 52
215 110 148 0 20
215 110 147 0 84
215 110 2 0 52
215 110 1 0 20
215 110 0 0 84
215 111 149 0 44
215 111 148 0 12
215 111 147 0 76
215 111 2 0 44
215 111 1 0 12
215 111 0 0 76
215 114 149 0 52
215 114 148 0 20
215 114 147 0 84
215 114 2 0 52
215 114 1 0 20
215 114 0 0 84
215 115 149 0 32
215 115 148 0 0
215 115 147 0 64
215 115 2 0 32
215 115 1 0 0
215 115 0 0 64
215 116 149 0 34
215 116 148 0 2
215 116 147 0 66
215 116 2 0 34
215 116 1 0 2
215 116 0 0 66
215 117 149 0 32
215 117 148 0 0
215 117 147 0 64
215 117 2 0 32
215 117 1 0 0
215 117 0 0 64
215 118 149 0 32
215 118 148 0 0
215 118 147 0 64
215 118 2 0 32
215 118 1 0 0
215 118 0 0 64
215 119 149 0 40
215 119 148 0 8
215 119 147 0 72
215 119 2 0 40
215 119 1 0 8
215 119 0 0 72
216 110 149 0 50
216 110 148 0 18
216 110 147 0 82
216 110 2 0 50
216 110 1 0 18
216 110 0 0 82
216 111 149 0 32
216 111 148 0 0
216 111 147 0 64
216 111 2 0 32
216 111 1 0 0
216 111 0 0 64
216 112 149 0 36
216 112 148 0 4
216 112 147 0 68
216 112 2 0 36
216 112 1 0 4
216 112 0 0 68
216 113 149 0 36
216 113 148 0 4
216 113 147 0 68
216 113 2 0 36
216 113 1 0 4
216 113 0 0 68
216 114 149 0 32
216 114 148 0 0
216 114 147 0 64
216 114 2 0 32
216 114 1 0 0
216 114 0 0 64
216 115 149 0 42
216 115 148 0 10
216 115 147 0 74
216 115 2 0 42
216 115 1 0 10
216 115 0 0 74
216 117 149 0 48
216 117 148 0 16
216 117 147 0 80
216 117 2 0 48
216 117 1 0 16
216 117 0 0 80
216 118 149 0 32
216 118 148 0 0
216 118 147 0 64
216 118 2 0 32
216 118 1 0 0
216 118 0 0 64
216 119 149 0 40
216 119 148 0 8
216 119 147 0 72
216 119 2 0 40
216 119 1 0 8
216 119 0 0 72
217 111 149 0 48
217 111 148 0 16
217 111 147 0 80
217 111 2 0 48
217 111 1 0 16
217 111 0 0 80
217 112 149 0 32
217 112 148 0 0
217 112 147 0 64
217 112 2 0 32
217 112 1 0 0
217 112 0 0 64
217 113 149 0 34
217 113 148 0 2
217 113 147 0 66
217 113 2 0 34
217 113 1 0 2
217 113 0 0 66
217 114 149 0 42
217 114 148 0 10
217 114 147 0 74
217 114 2 0 42
217 114 1 0 10
217 114 0 0 74
217 117 149 0 48
217 117 148 0 16
217 117 147 0 80
217 117 2 0 48
217 117 1 0 16
217 117 0 0 80
217 118 149 0 32
217 118 148 0 0
217 118 147 0 64
217 118 2 0 32
217 118 1 0 0
217 118 0 0 64
217 119 149 0 40
217 119 148 0 8
217 119 147 0 72
217 119 2 0 40
217 119 1 0 8
217 119 0 0 72
218 105 149 0 52
218 105 148 0 20
218 105 147 0 84
218 105 2 0 52
218 105 1 0 20
218 105 0 0 84
218 106 149 0 46
218 106 148 0 14
218 106 147 0 78
218 106 2 0 46
218 106 1 0 14
218 106 0 0 78
218 111 149 0 48
218 111 148 0 16
218 111 147 0 80
218 111 2 0 48
218 111 1 0 16
218 111 0 0 80
218 112 149 0 40
218 112 148 0 8
218 112 147 0 72
218 112 2 0 40
218 112 1 0 8
218 112 0 0 72
218 117 149 0 48
218 117 148 0 16
218 117 147 0 80
218 117 2 0 48
218 117 1 0 16
218 117 0 0 80
218 118 149 0 32
218 118 148 0 0
218 118 147 0 64
218 118 2 0 32
218 118 1 0 0
218 118 0 0 64
218 119 149 0 40
218 119 148 0 8
218 119 147 0 72
218 119 2 0 40
218 119 1 0 8
218 119 0 0 72
219 104 149 0 54
219 104 148 0 22
219 104 147 0 86
219 104 2 0 54
219 104 1 0 22
219 104 0 0 86
219 105 149 0 40
219 105 148 0 8
219 105 147 0 72
219 105 2 0 40
219 105 1 0 8
219 105 0 0 72
219 110 149 0 52
219 110 148 0 20
219 110 147 0 84
219 110 2 0 52
219 110 1 0 20
219 110 0 0 84
219 111 149 0 32
219 111 148 0 0
219 111 147 0 64
219 111 2 0 32
219 111 1 0 0
219 111 0 0 64
219 112 149 0 42
219 112 148 0 10
219 112 147 0 74
219 112 2 0 42
219 112 1 0 10
219 112 0 0 74
219 117 149 0 48
219 117 148 0 16
219 117 147 0 80
219 117 2 0 48
219 117 1 0 16
219 117 0 0 80
219 118 149 0 32
219 118 148 0 0
219 118 147 0 64
219 118 2 0 32
219 118 1 0 0
219 118 0 0 64
219 119 149 0 40
219 119 148 0 8
219 119 147 0 72
219 119 2 0 40
219 119 1 0 8
219 119 0 0 72
220 105 149 0 50
220 105 148 0 18
220 105 147 0 82
220 105 2 0 50
220 105 1 0 18
220 105 0 0 82
220 106 149 0 36
220 106 148 0 4
220 106 147 0 68
220 106 2 0 36
220 106 1 0 4
220 106 0 0 68
220 107 149 0 36
220 107 148 0 4
220 107 147 0 68
220 107 2 0 36
220 107 1 0 4
220 107 0 0 68
220 108 149 0 36
220 108 148 0 4
220 108 147 0 68
220 108 2 0 36
220 108 1 0 4
220 108 0 0 68
220 109 149 0 36
220 109 148 0 4
220 109 147 0 68
220 109 2 0 36
220 109 1 0 4
220 109 0 0 68
220 110 149 0 32
220 110 148 0 0
220 110 147 0 64
220 110 2 0 32
220 110 1 0 0
220 110 0 0 64
220 111 149 0 42
220 111 148 0 10
220 111 147 0 74
220 111 2 0 42
220 111 1 0 10
220 111 0 0 74
220 117 149 0 48
220 117 148 0 16
220 117 147 0 80
220 117 2 0 48
220 117 1 0 16
220 117 0 0 80
220 118 149 0 32
220 118 148 0 0
220 118 147 0 64
220 118 2 0 32
220 118 1 0 0
220 118 0 0 64
220 119 149 0 40
220 119 148 0 8
220 119 147 0 72
220 119 2 0 40
220 119 1 0 8
220 119 0 0 72
221 106 149 0 48
221 106 148 0 16
221 106 147 0 80
221 106 2 0 48
221 106 1 0 16
221 106 0 0 80
221 107 149 0 32
221 107 148 0 0
221 107 147 0 64
221 107 2 0 32
221 107 1 0 0
221 107 0 0 64
221 108 149 0 32
221 108 148 0 0
221 108 147 0 64
221 108 2 0 32
221 108 1 0 0
221 108 0 0 64
221 109 149 0 32
221 109 148 0 0
221 109 147 0 64
221 109 2 0 32
221 109 1 0 0
221 109 0 0 64
221 110 149 0 40
221 110 148 0 8
221 110 147 0 72
221 110 2 0 40
221 110 1 0 8
221 110 0 0 72
221 117 149 0 48
221 117 148 0 16
221 117 147 0 80
221 117 2 0 48
221 117 1 0 16
221 117 0 0 80
221 118 149 0 32
221 118 148 0 0
221 118 147 0 64
221 118 2 0 32
221 118 1 0 0
221 118 0 0 64
221 119 149 0 40
221 119 148 0 8
221 119 147 0 72
221 119 2 0 40
221 119 1 0 8
221 119 0 0 72
222 1 149 0 52
222 1 148 0 20
222 1 147 0 84
222 1 2 0 52
222 1 1 0 20
222 1 0 0 84
222 2 149 0 36
222 2 148 0 4
222 2 147 0 68
222 2 2 0 36
222 2 1 0 4
222 2 0 0 68
222 3 149 0 36
222 3 148 0 4
222 3 147 0 68
222 3 2 0 36
222 3 1 0 4
222 3 0 0 68
222 4 149 0 36
222 4 148 0 4
222 4 147 0 68
222 4 2 0 36
222 4 1 0 4
222 4 0 0 68
222 5 149 0 36
222 5 148 0 4
222 5 147 0 68
222 5 2 0 36
222 5 1 0 4
222 5 0 0 68
222 6 149 0 36
222 6 148 0 4
222 6 147 0 68
222 6 2 0 36
222 6 1 0 4
222 6 0 0 68
222 7 149 0 36
222 7 148 0 4
222 7 147 0 68
222 7 2 0 36
222 7 1 0 4
222 7 0 0 68
222 8 149 0 36
222 8 148 0 4
222 8 147 0 68
222 8 2 0 36
222 8 1 0 4
222 8 0 0 68
222 9 149 0 36
222 9 148 0 4
222 9 147 0 68
222 9 2 0 36
222 9 1 0 4
222 9 0 0 68
222 10 149 0 36
222 10 148 0 4
222 10 147 0 68
222 10 2 0 36
222 10 1 0 4
222 10 0 0 68
222 11 149 0 36
222 11 148 0 4
222 11 147 0 68
222 11 2 0 36
222 11 1 0 4
222 11 0 0 68
222 12 149 0 36
222 12 148 0 4
222 12 147 0 68
222 12 2 0 36
222 12 1 0 4
222 12 0 0 68
222 13 149 0 36
222 13 148 0 4
222 13 147 0 68
222 13 2 0 36
222 13 1 0 4
222 13 0 0 68
222 14 149 0 36
222 14 148 0 4
222 14 147 0 68
222 14 2 0 36
222 14 1 0 4
222 14 0 0 68
222 15 149 0 36
222 15 148 0 4
222 15 147 0 68
222 15 2 0 36
222 15 1 0 4
222 15 0 0 68
222 16 149 0 36
222 16 148 0 4
222 16 147 0 68
222 16 2 0 36
222 16 1 0 4
222 16 0 0 68
222 17 149 0 36
222 17 148 0 4
222 17 147 0 68
222 17 2 0 36
222 17 1 0 4
222 17 0 0 68
222 18 149 0 36
222 18 148 0 4
222 18 147 0 68
222 18 2 0 36
222 18 1 0 4
222 18 0 0 68
222 19 149 0 36
222 19 148 0 4
222 19 147 0 68
222 19 2 0 36
222 19 1 0 4
222 19 0 0 68
222 20 149 0 36
222 20 148 0 4
222 20 147 0 68
222 20 2 0 36
222 20 1 0 4
222 20 0 0 68
222 21 149 0 36
222 21 148 0 4
222 21 147 0 68
222 21 2 0 36
222 21 1 0 4
222 21 0 0 68
222 22 149 0 36
222 22 148 0 4
222 22 147 0 68
222 22 2 0 36
222 22 1 0 4
222 22 0 0 68
222 23 149 0 36
222 23 148 0 4
222 23 147 0 68
222 23 2 0 36
222 23 1 0 4
222 23 0 0 68
222 24 149 0 36
222 24 148 0 4
222 24 147 0 68
222 24 2 0 36
222 24 1 0 4
222 24 0 0 68
222 25 149 0 36
222 25 148 0 4
222 25 147 0 68
222 25 2 0 36
222 25 1 0 4
222 25 0 0 68
222 26 149 0 36
222 26 148 0 4
222 26 147 0 68
222 26 2 0 36
222 26 1 0 4
222 26 0 0 68
222 27 149 0 36
222 27 148 0 4
222 27 147 0 68
222 27 2 0 36
222 27 1 0 4
222 27 0 0 68
222 28 149 0 36
222 28 148 0 4
222 28 147 0 68
222 28 2 0 36
222 28 1 0 4
222 28 0 0 68
222 29 149 0 36
222 29 148 0 4
222 29 147 0 68
222 29 2 0 36
222 29 1 0 4
222 29 0 0 68
222 30 149 0 36
222 30 148 0 4
222 30 147 0 68
222 30 2 0 36
222 30 1 0 4
222 30 0 0 68
222 31 149 0 36
222 31 148 0 4
222 31 147 0 68
222 31 2 0 36
222 31 1 0 4
222 31 0 0 68
222 32 149 0 36
222 32 148 0 4
222 32 147 0 68
222 32 2 0 36
222 32 1 0 4
222 32 0 0 68
222 33 149 0 36
222 33 148 0 4
222 33 147 0 68
222 33 2 0 36
222 33 1 0 4
222 33 0 0 68
222 34 149 0 36
222 34 148 0 4
222 34 147 0 68
222 34 2 0 36
222 34 1 0 4
222 34 0 0 68
222 35 149 0 36
222 35 148 0 4
222 35 147 0 68
222 35 2 0 36
222 35 1 0 4
222 35 0 0 68
222 36 149 0 36
222 36 148 0 4
222 36 147 0 68
222 36 2 0 36
222 36 1 0 4
222 36 0 0 68
222 37 149 0 36
222 37 148 0 4
222 37 147 0 68
222 37 2 0 36
222 37 1 0 4
222 37 0 0 68
222 38 149 0 36
222 38 148 0 4
222 38 147 0 68
222 38 2 0 36
222 38 1 0 4
222 38 0 0 68
222 39 149 0 36
222 39 148 0 4
222 39 147 0 68
222 39 2 0 36
222 39 1 0 4
222 39 0 0 68
222 40 149 0 36
222 40 148 0 4
222 40 147 0 68
222 40 2 0 36
222 40 1 0 4
222 40 0 0 68
222 41 149 0 36
222 41 148 0 4
222 41 147 0 68
222 41 2 0 36
222 41 1 0 4
222 41 0 0 68
222 42 149 0 36
222 42 148 0 4
222 42 147 0 68
222 42 2 0 36
222 42 1 0 4
222 42 0 0 68
222 43 149 0 36
222 43 148 0 4
222 43 147 0 68
222 43 2 0 36
222 43 1 0 4
222 43 0 0 68
222 44 149 0 36
222 44 148 0 4
222 44 147 0 68
222 44 2 0 36
222 44 1 0 4
222 44 0 0 68
222 45 149 0 36
222 45 148 0 4
222 45 147 0 68
222 45 2 0 36
222 45 1 0 4
222 45 0 0 68
222 46 149 0 36
222 46 148 0 4
222 46 147 0 68
222 46 2 0 36
222 46 1 0 4
222 46 0 0 68
222 47 149 0 36
222 47 148 0 4
222 47 147 0 68
222 47 2 0 36
222 47 1 0 4
222 47 0 0 68
222 48 149 0 36
222 48 148 0 4
222 48 147 0 68
222 48 2 0 36
222 48 1 0 4
222 48 0 0 68
222 49 149 0 36
222 49 148 0 4
222 49 147 0 68
222 49 2 0 36
222 49 1 0 4
222 49 0 0 68
222 50 149 0 36
222 50 148 0 4
222 50 147 0 68
222 50 2 0 36
222 50 1 0 4
222 50 0 0 68
222 51 149 0 36
222 51 148 0 4
222 51 147 0 68
222 51 2 0 36
222 51 1 0 4
222 51 0 0 68
222 52 149 0 36
222 52 148 0 4
222 52 147 0 68
222 52 2 0 36
222 52 1 0 4
222 52 0 0 68
222 53 149 0 36
222 53 148 0 4
222 53 147 0 68
222 53 2 0 36
222 53 1 0 4
222 53 0 0 68
222 54 149 0 36
222 54 148 0 4
222 54 147 0 68
222 54 2 0 36
222 54 1 0 4
222 54 0 0 68
222 55 149 0 36
222 55 148 0 4
222 55 147 0 68
222 55 2 0 36
222 55 1 0 4
222 55 0 0 68
222 56 149 0 36
222 56 148 0 4
222 56 147 0 68
222 56 2 0 36
222 56 1 0 4
222 56 0 0 68
222 57 149 0 36
222 57 148 0 4
222 57 147 0 68
222 57 2 0 36
222 57 1 0 4
222 57 0 0 68
222 58 149 0 36
222 58 148 0 4
222 58 147 0 68
222 58 2 0 36
222 58 1 0 4
222 58 0 0 68
222 59 149 0 36
222 59 148 0 4
222 59 147 0 68
222 59 2 0 36
222 59 1 0 4
222 59 0 0 68
222 60 149 0 36
222 60 148 0 4
222 60 147 0 68
222 60 2 0 36
222 60 1 0 4
222 60 0 0 68
222 61 149 0 36
222 61 148 0 4
222 61 147 0 68
222 61 2 0 36
222 61 1 0 4
222 61 0 0 68
222 62 149 0 36
222 62 148 0 4
222 62 147 0 68
222 62 2 0 36
222 62 1 0 4
222 62 0 0 68
222 63 149 0 36
222 63 148 0 4
222 63 147 0 68
222 63 2 0 36
222 63 1 0 4
222 63 0 0 68
222 64 149 0 36
222 64 148 0 4
222 64 147 0 68
222 64 2 0 36
222 64 1 0 4
222 64 0 0 68
222 65 149 0 36
222 65 148 0 4
222 65 147 0 68
222 65 2 0 36
222 65 1 0 4
222 65 0 0 68
222 66 149 0 36
222 66 148 0 4
222 66 147 0 68
222 66 2 0 36
222 66 1 0 4
222 66 0 0 68
222 67 149 0 36
222 67 148 0 4
222 67 147 0 68
222 67 2 0 36
222 67 1 0 4
222 67 0 0 68
222 68 149 0 36
222 68 148 0 4
222 68 147 0 68
222 68 2 0 36
222 68 1 0 4
222 68 0 0 68
222 69 149 0 36
222 69 148 0 4
222 69 147 0 68
222 69 2 0 36
222 69 1 0 4
222 69 0 0 68
222 70 149 0 36
222 70 148 0 4
222 70 147 0 68
222 70 2 0 36
222 70 1 0 4
222 70 0 0 68
222 71 149 0 36
222 71 148 0 4
222 71 147 0 68
222 71 2 0 36
222 71 1 0 4
222 71 0 0 68
222 72 149 0 36
222 72 148 0 4
222 72 147 0 68
222 72 2 0 36
222 72 1 0 4
222 72 0 0 68
222 73 149 0 36
222 73 148 0 4
222 73 147 0 68
222 73 2 0 36
222 73 1 0 4
222 73 0 0 68
222 74 149 0 36
222 74 148 0 4
222 74 147 0 68
222 74 2 0 36
222 74 1 0 4
222 74 0 0 68
222 75 149 0 36
222 75 148 0 4
222 75 147 0 68
222 75 2 0 36
222 75 1 0 4
222 75 0 0 68
222 76 149 0 36
222 76 148 0 4
222 76 147 0 68
222 76 2 0 36
222 76 1 0 4
222 76 0 0 68
222 77 149 0 36
222 77 148 0 4
222 77 147 0 68
222 77 2 0 36
222 77 1 0 4
222 77 0 0 68
222 78 149 0 36
222 78 148 0 4
222 78 147 0 68
222 78 2 0 36
222 78 1 0 4
222 78 0 0 68
222 79 149 0 36
222 79 148 0 4
222 79 147 0 68
222 79 2 0 36
222 79 1 0 4
222 79 0 0 68
222 80 149 0 36
222 80 148 0 4
222 80 147 0 68
222 80 2 0 36
222 80 1 0 4
222 80 0 0 68
222 81 149 0 36
222 81 148 0 4
222 81 147 0 68
222 81 2 0 36
222 81 1 0 4
222 81 0 0 68
222 82 149 0 36
222 82 148 0 4
222 82 147 0 68
222 82 2 0 36
222 82 1 0 4
222 82 0 0 68
222 83 149 0 36
222 83 148 0 4
222 83 147 0 68
222 83 2 0 36
222 83 1 0 4
222 83 0 0 68
222 84 149 0 36
222 84 148 0 4
222 84 147 0 68
222 84 2 0 36
222 84 1 0 4
222 84 0 0 68
222 85 149 0 36
222 85 148 0 4
222 85 147 0 68
222 85 2 0 36
222 85 1 0 4
222 85 0 0 68
222 86 149 0 36
222 86 148 0 4
222 86 147 0 68
222 86 2 0 36
222 86 1 0 4
222 86 0 0 68
222 87 149 0 36
222 87 148 0 4
222 87 147 0 68
222 87 2 0 36
222 87 1 0 4
222 87 0 0 68
222 88 149 0 36
222 88 148 0 4
222 88 147 0 68
222 88 2 0 36
222 88 1 0 4
222 88 0 0 68
222 89 149 0 36
222 89 148 0 4
222 89 147 0 68
222 89 2 0 36
222 89 1 0 4
222 89 0 0 68
222 90 149 0 36
222 90 148 0 4
222 90 147 0 68
222 90 2 0 36
222 90 1 0 4
222 90 0 0 68
222 91 149 0 36
222 91 148 0 4
222 91 147 0 68
222 91 2 0 36
222 91 1 0 4
222 91 0 0 68
222 92 149 0 36
222 92 148 0 4
222 92 147 0 68
222 92 2 0 36
222 92 1 0 4
222 92 0 0 68
222 93 149 0 36
222 93 148 0 4
222 93 147 0 68
222 93 2 0 36
222 93 1 0 4
222 93 0 0 68
222 94 149 0 36
222 94 148 0 4
222 94 147 0 68
222 94 2 0 36
222 94 1 0 4
222 94 0 0 68
222 95 149 0 36
222 95 148 0 4
222 95 147 0 68
222 95 2 0 36
222 95 1 0 4
222 95 0 0 68
222 96 149 0 36
222 96 148 0 4
222 96 147 0 68
222 96 2 0 36
222 96 1 0 4
222 96 0 0 68
222 97 149 0 36
222 97 148 0 4
222 97 147 0 68
222 97 2 0 36
222 97 1 0 4
222 97 0 0 68
222 98 149 0 36
222 98 148 0 4
222 98 147 0 68
222 98 2 0 36
222 98 1 0 4
222 98 0 0 68
222 99 149 0 36
222 99 148 0 4
222 99 147 0 68
222 99 2 0 36
222 99 1 0 4
222 99 0 0 68
222 100 149 0 36
222 100 148 0 4
222 100 147 0 68
222 100 2 0 36
222 100 1 0 4
222 100 0 0 68
222 101 149 0 36
222 101 148 0 4
222 101 147 0 68
222 101 2 0 36
222 101 1 0 4
222 101 0 0 68
222 102 149 0 36
222 102 148 0 4
222 102 147 0 68
222 102 2 0 36
222 102 1 0 4
222 102 0 0 68
222 103 149 0 36
222 103 148 0 4
222 103 147 0 68
222 103 2 0 36
222 103 1 0 4
222 103 0 0 68
222 104 149 0 36
222 104 148 0 4
222 104 147 0 68
222 104 2 0 36
222 104 1 0 4
222 104 0 0 68
222 105 149 0 36
222 105 148 0 4
222 105 147 0 68
222 105 2 0 36
222 105 1 0 4
222 105 0 0 68
222 106 149 0 32
222 106 148 0 0
222 106 147 0 64
222 106 2 0 32
222 106 1 0 0
222 106 0 0 64
222 107 149 0 32
222 107 148 0 0
222 107 147 0 64
222 107 2 0 32
222 107 1 0 0
222 107 0 0 64
222 108 149 0 32
222 108 148 0 0
222 108 147 0 64
222 108 2 0 32
222 108 1 0 0
222 108 0 0 64
222 109 149 0 32
222 109 148 0 0
222 109 147 0 64
222 109 2 0 32
222 109 1 0 0
222 109 0 0 64
222 110 149 0 32
222 110 148 0 0
222 110 147 0 64
222 110 2 0 32
222 110 1 0 0
222 110 0 0 64
222 111 149 0 36
222 111 148 0 4
222 111 147 0 68
222 111 2 0 36
222 111 1 0 4
222 111 0 0 68
222 112 149 0 36
222 112 148 0 4
222 112 147 0 68
222 112 2 0 36
222 112 1 0 4
222 112 0 0 68
222 113 149 0 36
222 113 148 0 4
222 113 147 0 68
222 113 2 0 36
222 113 1 0 4
222 113 0 0 68
222 114 149 0 36
222 114 148 0 4
222 114 147 0 68
222 114 2 0 36
222 114 1 0 4
222 114 0 0 68
222 115 149 0 36
222 115 148 0 4
222 115 147 0 68
222 115 2 0 36
222 115 1 0 4
222 115 0 0 68
222 116 149 0 36
222 116 148 0 4
222 116 147 0 68
222 116 2 0 36
222 116 1 0 4
222 116 0 0 68
222 117 149 0 32
222 117 148 0 0
222 117 147 0 64
222 117 2 0 32
222 117 1 0 0
222 117 0 0 64
222 118 149 0 32
222 118 148 0 0
222 118 147 0 64
222 118 2 0 32
222 118 1 0 0
222 118 0 0 64
222 119 149 0 32
222 119 148 0 0
222 119 147 0 64
222 119 2 0 32
222 119 1 0 0
222 119 0 0 64
222 120 149 0 36
222 120 148 0 4
222 120 147 0 68
222 120 2 0 36
222 120 1 0 4
222 120 0 0 68
222 121 149 0 36
222 121 148 0 4
222 121 147 0 68
222 121 2 0 36
222 121 1 0 4
222 121 0 0 68
222 122 149 0 36
222 122 148 0 4
222 122 147 0 68
222 122 2 0 36
222 122 1 0 4
222 122 0 0 68
222 123 149 0 36
222 123 148 0 4
222 123 147 0 68
222 123 2 0 36
222 123 1 0 4
222 123 0 0 68
222 124 149 0 36
222 124 148 0 4
222 124 147 0 68
222 124 2 0 36
222 124 1 0 4
222 124 0 0 68
222 125 149 0 36
222 125 148 0 4
222 125 147 0 68
222 125 2 0 36
222 125 1 0 4
222 125 0 0 68
222 126 149 0 36
222 126 148 0 4
222 126 147 0 68
222 126 2 0 36
222 126 1 0 4
222 126 0 0 68
222 127 149 0 36
222 127 148 0 4
222 127 147 0 68
222 127 2 0 36
222 127 1 0 4
222 127 0 0 68
222 128 149 0 36
222 128 148 0 4
222 128 147 0 68
222 128 2 0 36
222 128 1 0 4
222 128 0 0 68
222 129 149 0 36
222 129 148 0 4
222 129 147 0 68
222 129 2 0 36
222 129 1 0 4
222 129 0 0 68
222 130 149 0 36
222 130 148 0 4
222 130 147 0 68
222 130 2 0 36
222 130 1 0 4
222 130 0 0 68
222 131 149 0 36
222 131 148 0 4
222 131 147 0 68
222 131 2 0 36
222 131 1 0 4
222 131 0 0 68
222 132 149 0 36
222 132 148 0 4
222 132 147 0 68
222 132 2 0 36
222 132 1 0 4
222 132 0 0 68
222 133 149 0 36
222 133 148 0 4
222 133 147 0 68
222 133 2 0 36
222 133 1 0 4
222 133 0 0 68
222 134 149 0 36
222 134 148 0 4
222 134 147 0 68
222 134 2 0 36
222 134 1 0 4
222 134 0 0 68
222 135 149 0 36
222 135 148 0 4
222 135 147 0 68
222 135 2 0 36
222 135 1 0 4
222 135 0 0 68
222 136 149 0 36
222 136 148 0 4
222 136 147 0 68
222 136 2 0 36
222 136 1 0 4
222 136 0 0 68
222 137 149 0 36
222 137 148 0 4
222 137 147 0 68
222 137 2 0 36
222 137 1 0 4
222 137 0 0 68
222 138 149 0 36
222 138 148 0 4
222 138 147 0 68
222 138 2 0 36
222 138 1 0 4
222 138 0 0 68
222 139 149 0 36
222 139 148 0 4
222 139 147 0 68
222 139 2 0 36
222 139 1 0 4
222 139 0 0 68
222 140 149 0 36
222 140 148 0 4
222 140 147 0 68
222 140 2 0 36
222 140 1 0 4
222 140 0 0 68
222 141 149 0 36
222 141 148 0 4
222 141 147 0 68
222 141 2 0 36
222 141 1 0 4
222 141 0 0 68
222 142 149 0 36
222 142 148 0 4
222 142 147 0 68
222 142 2 0 36
222 142 1 0 4
222 142 0 0 68
222 143 149 0 36
222 143 148 0 4
222 143 147 0 68
222 143 2 0 36
222 143 1 0 4
222 143 0 0 68
222 144 149 0 36
222 144 148 0 4
222 144 147 0 68
222 144 2 0 36
222 144 1 0 4
222 144 0 0 68
222 145 149 0 36
222 145 148 0 4
222 145 147 0 68
222 145 2 0 36
222 145 1 0 4
222 145 0 0 68
222 146 149 0 44
222 146 148 0 12
222 146 147 0 76
222 146 2 0 44
222 146 1 0 12
222 146 0 0 76
223 1 149 0 48
223 1 148 0 16
223 1 147 0 80
223 1 2 0 48
223 1 1 0 16
223 1 0 0 80
223 2 149 0 32
223 2 148 0 0
223 2 147 0 64
223 2 2 0 32
223 2 1 0 0
223 2 0 0 64
223 3 149 0 32
223 3 148 0 0
223 3 147 0 64
223 3 2 0 32
223 3 1 0 0
223 3 0 0 64
223 4 149 0 32
223 4 148 0 0
223 4 147 0 64
223 4 2 0 32
223 4 1 0 0
223 4 0 0 64
223 5 149 0 32
223 5 148 0 0
223 5 147 0 64
223 5 2 0 32
223 5 1 0 0
223 5 0 0 64
223 6 149 0 32
223 6 148 0 0
223 6 147 0 64
223 6 2 0 32
223 6 1 0 0
223 6 0 0 64
223 7 149 0 32
223 7 148 0 0
223 7 147 0 64
223 7 2 0 32
223 7 1 0 0
223 7 0 0 64
223 8 149 0 32
223 8 148 0 0
223 8 147 0 64
223 8 2 0 32
223 8 1 0 0
223 8 0 0 64
223 9 149 0 32
223 9 148 0 0
223 9 147 0 64
223 9 2 0 32
223 9 1 0 0
223 9 0 0 64
223 10 149 0 32
223 10 148 0 0
223 10 147 0 64
223 10 2 0 32
223 10 1 0 0
223 10 0 0 64
223 11 149 0 32
223 11 148 0 0
223 11 147 0 64
223 11 2 0 32
223 11 1 0 0
223 11 0 0 64
223 12 149 0 32
223 12 148 0 0
223 12 147 0 64
223 12 2 0 32
223 12 1 0 0
223 12 0 0 64
223 13 149 0 32
223 13 148 0 0
223 13 147 0 64
223 13 2 0 32
223 13 1 0 0
223 13 0 0 64
223 14 149 0 32
223 14 148 0 0
223 14 147 0 64
223 14 2 0 32
223 14 1 0 0
223 14 0 0 64
223 15 149 0 32
223 15 148 0 0
223 15 147 0 64
223 15 2 0 32
223 15 1 0 0
223 15 0 0 64
223 16 149 0 32
223 16 148 0 0
223 16 147 0 64
223 16 2 0 32
223 16 1 0 0
223 16 0 0 64
223 17 149 0 32
223 17 148 0 0
223 17 147 0 64
223 17 2 0 32
223 17 1 0 0
223 17 0 0 64
223 18 149 0 32
223 18 148 0 0
223 18 147 0 64
223 18 2 0 32
223 18 1 0 0
223 18 0 0 64
223 19 149 0 32
223 19 148 0 0
223 19 147 0 64
223 19 2 0 32
223 19 1 0 0
223 19 0 0 64
223 20 149 0 32
223 20 148 0 0
223 20 147 0 64
223 20 2 0 32
223 20 1 0 0
223 20 0 0 64
223 21 149 0 32
223 21 148 0 0
223 21 147 0 64
223 21 2 0 32
223 21 1 0 0
223 21 0 0 64
223 22 149 0 32
223 22 148 0 0
223 22 147 0 64
223 22 2 0 32
223 22 1 0 0
223 22 0 0 64
223 23 149 0 32
223 23 148 0 0
223 23 147 0 64
223 23 2 0 32
223 23 1 0 0
223 23 0 0 64
223 24 149 0 32
223 24 148 0 0
223 24 147 0 64
223 24 2 0 32
223 24 1 0 0
223 24 0 0 64
223 25 149 0 32
223 25 148 0 0
223 25 147 0 64
223 25 2 0 32
223 25 1 0 0
223 25 0 0 64
223 26 149 0 32
223 26 148 0 0
223 26 147 0 64
223 26 2 0 32
223 26 1 0 0
223 26 0 0 64
223 27 149 0 32
223 27 148 0 0
223 27 147 0 64
223 27 2 0 32
223 27 1 0 0
223 27 0 0 64
223 28 149 0 32
223 28 148 0 0
223 28 147 0 64
223 28 2 0 32
223 28 1 0 0
223 28 0 0 64
223 29 149 0 32
223 29 148 0 0
223 29 147 0 64
223 29 2 0 32
223 29 1 0 0
223 29 0 0 64
223 30 149 0 32
223 30 148 0 0
223 30 147 0 64
223 30 2 0 32
223 30 1 0 0
223 30 0 0 64
223 31 149 0 32
223 31 148 0 0
223 31 147 0 64
223 31 2 0 32
223 31 1 0 0
223 31 0 0 64
223 32 149 0 32
223 32 148 0 0
223 32 147 0 64
223 32 2 0 32
223 32 1 0 0
223 32 0 0 64
223 33 149 0 32
223 33 148 0 0
223 33 147 0 64
223 33 2 0 32
223 33 1 0 0
223 33 0 0 64
223 34 149 0 32
223 34 148 0 0
223 34 147 0 64
223 34 2 0 32
223 34 1 0 0
223 34 0 0 64
223 35 149 0 32
223 35 148 0 0
223 35 147 0 64
223 35 2 0 32
223 35 1 0 0
223 35 0 0 64
223 36 149 0 32
223 36 148 0 0
223 36 147 0 64
223 36 2 0 32
223 36 1 0 0
223 36 0 0 64
223 37 149 0 32
223 37 148 0 0
223 37 147 0 64
223 37 2 0 32
223 37 1 0 0
223 37 0 0 64
223 38 149 0 32
223 38 148 0 0
223 38 147 0 64
223 38 2 0 32
223 38 1 0 0
223 38 0 0 64
223 39 149 0 32
223 39 148 0 0
223 39 147 0 64
223 39 2 0 32
223 39 1 0 0
223 39 0 0 64
223 40 149 0 32
223 40 148 0 0
223 40 147 0 64
223 40 2 0 32
223 40 1 0 0
223 40 0 0 64
223 41 149 0 32
223 41 148 0 0
223 41 147 0 64
223 41 2 0 32
223 41 1 0 0
223 41 0 0 64
223 42 149 0 32
223 42 148 0 0
223 42 147 0 64
223 42 2 0 32
223 42 1 0 0
223 42 0 0 64
223 43 149 0 32
223 43 148 0 0
223 43 147 0 64
223 43 2 0 32
223 43 1 0 0
223 43 0 0 64
223 44 149 0 32
223 44 148 0 0
223 44 147 0 64
223 44 2 0 32
223 44 1 0 0
223 44 0 0 64
223 45 149 0 32
223 45 148 0 0
223 45 147 0 64
223 45 2 0 32
223 45 1 0 0
223 45 0 0 64
223 46 149 0 32
223 46 148 0 0
223 46 147 0 64
223 46 2 0 32
223 46 1 0 0
223 46 0 0 64
223 47 149 0 32
223 47 148 0 0
223 47 147 0 64
223 47 2 0 32
223 47 1 0 0
223 47 0 0 64
223 48 149 0 32
223 48 148 0 0
223 48 147 0 64
223 48 2 0 32
223 48 1 0 0
223 48 0 0 64
223 49 149 0 32
223 49 148 0 0
223 49 147 0 64
223 49 2 0 32
223 49 1 0 0
223 49 0 0 64
223 50 149 0 32
223 50 148 0 0
223 50 147 0 64
223 50 2 0 32
223 50 1 0 0
223 50 0 0 64
223 51 149 0 32
223 51 148 0 0
223 51 147 0 64
223 51 2 0 32
223 51 1 0 0
223 51 0 0 64
223 52 149 0 32
223 52 148 0 0
223 52 147 0 64
223 52 2 0 32
223 52 1 0 0
223 52 0 0 64
223 53 149 0 32
223 53 148 0 0
223 53 147 0 64
223 53 2 0 32
223 53 1 0 0
223 53 0 0 64
223 54 149 0 32
223 54 148 0 0
223 54 147 0 64
223 54 2 0 32
223 54 1 0 0
223 54 0 0 64
223 55 149 0 32
223 55 148 0 0
223 55 147 0 64
223 55 2 0 32
223 55 1 0 0
223 55 0 0 64
223 56 149 0 32
223 56 148 0 0
223 56 147 0 64
223 56 2 0 32
223 56 1 0 0
223 56 0 0 64
223 57 149 0 32
223 57 148 0 0
223 57 147 0 64
223 57 2 0 32
223 57 1 0 0
223 57 0 0 64
223 58 149 0 32
223 58 148 0 0
223 58 147 0 64
223 58 2 0 32
223 58 1 0 0
223 58 0 0 64
223 59 149 0 32
223 59 148 0 0
223 59 147 0 64
223 59 2 0 32
223 59 1 0 0
223 59 0 0 64
223 60 149 0 32
223 60 148 0 0
223 60 147 0 64
223 60 2 0 32
223 60 1 0 0
223 60 0 0 64
223 61 149 0 32
223 61 148 0 0
223 61 147 0 64
223 61 2 0 32
223 61 1 0 0
223 61 0 0 64
223 62 149 0 32
223 62 148 0 0
223 62 147 0 64
223 62 2 0 32
223 62 1 0 0
223 62 0 0 64
223 63 149 0 32
223 63 148 0 0
223 63 147 0 64
223 63 2 0 32
223 63 1 0 0
223 63 0 0 64
223 64 149 0 32
223 64 148 0 0
223 64 147 0 64
223 64 2 0 32
223 64 1 0 0
223 64 0 0 64
223 65 149 0 32
223 65 148 0 0
223 65 147 0 64
223 65 2 0 32
223 65 1 0 0
223 65 0 0 64
223 66 149 0 32
223 66 148 0 0
223 66 147 0 64
223 66 2 0 32
223 66 1 0 0
223 66 0 0 64
223 67 149 0 32
223 67 148 0 0
223 67 147 0 64
223 67 2 0 32
223 67 1 0 0
223 67 0 0 64
223 68 149 0 32
223 68 148 0 0
223 68 147 0 64
223 68 2 0 32
223 68 1 0 0
223 68 0 0 64
223 69 149 0 32
223 69 148 0 0
223 69 147 0 64
223 69 2 0 32
223 69 1 0 0
223 69 0 0 64
223 70 149 0 32
223 70 148 0 0
223 70 147 0 64
223 70 2 0 32
223 70 1 0 0
223 70 0 0 64
223 71 149 0 32
223 71 148 0 0
223 71 147 0 64
223 71 2 0 32
223 71 1 0 0
223 71 0 0 64
223 72 149 0 32
223 72 148 0 0
223 72 147 0 64
223 72 2 0 32
223 72 1 0 0
223 72 0 0 64
223 73 149 0 32
223 73 148 0 0
223 73 147 0 64
223 73 2 0 32
223 73 1 0 0
223 73 0 0 64
223 74 149 0 32
223 74 148 0 0
223 74 147 0 64
223 74 2 0 32
223 74 1 0 0
223 74 0 0 64
223 75 149 0 32
223 75 148 0 0
223 75 147 0 64
223 75 2 0 32
223 75 1 0 0
223 75 0 0 64
223 76 149 0 32
223 76 148 0 0
223 76 147 0 64
223 76 2 0 32
223 76 1 0 0
223 76 0 0 64
223 77 149 0 32
223 77 148 0 0
223 77 147 0 64
223 77 2 0 32
223 77 1 0 0
223 77 0 0 64
223 78 149 0 32
223 78 148 0 0
223 78 147 0 64
223 78 2 0 32
223 78 1 0 0
223 78 0 0 64
223 79 149 0 32
223 79 148 0 0
223 79 147 0 64
223 79 2 0 32
223 79 1 0 0
223 79 0 0 64
223 80 149 0 32
223 80 148 0 0
223 80 147 0 64
223 80 2 0 32
223 80 1 0 0
223 80 0 0 64
223 81 149 0 32
223 81 148 0 0
223 81 147 0 64
223 81 2 0 32
223 81 1 0 0
223 81 0 0 64
223 82 149 0 32
223 82 148 0 0
223 82 147 0 64
223 82 2 0 32
223 82 1 0 0
223 82 0 0 64
223 83 149 0 32
223 83 148 0 0
223 83 147 0 64
223 83 2 0 32
223 83 1 0 0
223 83 0 0 64
223 84 149 0 32
223 84 148 0 0
223 84 147 0 64
223 84 2 0 32
223 84 1 0 0
223 84 0 0 64
223 85 149 0 32
223 85 148 0 0
223 85 147 0 64
223 85 2 0 32
223 85 1 0 0
223 85 0 0 64
223 86 149 0 32
223 86 148 0 0
223 86 147 0 64
223 86 2 0 32
223 86 1 0 0
223 86 0 0 64
223 87 149 0 32
223 87 148 0 0
223 87 147 0 64
223 87 2 0 32
223 87 1 0 0
223 87 0 0 64
223 88 149 0 32
223 88 148 0 0
223 88 147 0 64
223 88 2 0 32
223 88 1 0 0
223 88 0 0 64
223 89 149 0 32
223 89 148 0 0
223 89 147 0 64
223 89 2 0 32
223 89 1 0 0
223 89 0 0 64
223 90 149 0 32
223 90 148 0 0
223 90 147 0 64
223 90 2 0 32
223 90 1 0 0
223 90 0 0 64
223 91 149 0 32
223 91 148 0 0
223 91 147 0 64
223 91 2 0 32
223 91 1 0 0
223 91 0 0 64
223 92 149 0 32
223 92 148 0 0
223 92 147 0 64
223 92 2 0 32
223 92 1 0 0
223 92 0 0 64
223 93 149 0 32
223 93 148 0 0
223 93 147 0 64
223 93 2 0 32
223 93 1 0 0
223 93 0 0 64
223 94 149 0 32
223 94 148 0 0
223 94 147 0 64
223 94 2 0 32
223 94 1 0 0
223 94 0 0 64
223 95 149 0 32
223 95 148 0 0
223 95 147 0 64
223 95 2 0 32
223 95 1 0 0
223 95 0 0 64
223 96 149 0 32
223 96 148 0 0
223 96 147 0 64
223 96 2 0 32
223 96 1 0 0
223 96 0 0 64
223 97 149 0 32
223 97 148 0 0
223 97 147 0 64
223 97 2 0 32
223 97 1 0 0
223 97 0 0 64
223 98 149 0 32
223 98 148 0 0
223 98 147 0 64
223 98 2 0 32
223 98 1 0 0
223 98 0 0 64
223 99 149 0 32
223 99 148 0 0
223 99 147 0 64
223 99 2 0 32
223 99 1 0 0
223 99 0 0 64
223 100 149 0 32
223 100 148 0 0
223 100 147 0 64
223 100 2 0 32
223 100 1 0 0
223 100 0 0 64
223 101 149 0 32
223 101 148 0 0
223 101 147 0 64
223 101 2 0 32
223 101 1 0 0
223 101 0 0 64
223 102 149 0 32
223 102 148 0 0
223 102 147 0 64
223 102 2 0 32
223 102 1 0 0
223 102 0 0 64
223 103 149 0 32
223 103 148 0 0
223 103 147 0 64
223 103 2 0 32
223 103 1 0 0
223 103 0 0 64
223 104 149 0 32
223 104 148 0 0
223 104 147 0 64
223 104 2 0 32
223 104 1 0 0
223 104 0 0 64
223 105 149 0 32
223 105 148 0 0
223 105 147 0 64
223 105 2 0 32
223 105 1 0 0
223 105 0 0 64
223 106 149 0 32
223 106 148 0 0
223 106 147 0 64
223 106 2 0 32
223 106 1 0 0
223 106 0 0 64
223 107 149 0 32
223 107 148 0 0
223 107 147 0 64
223 107 2 0 32
223 107 1 0 0
223 107 0 0 64
223 108 149 0 32
223 108 148 0 0
223 108 147 0 64
223 108 2 0 32
223 108 1 0 0
223 108 0 0 64
223 109 149 0 32
223 109 148 0 0
223 109 147 0 64
223 109 2 0 32
223 109 1 0 0
223 109 0 0 64
223 110 149 0 32
223 110 148 0 0
223 110 147 0 64
223 110 2 0 32
223 110 1 0 0
223 110 0 0 64
223 111 149 0 32
223 111 148 0 0
223 111 147 0 64
223 111 2 0 32
223 111 1 0 0
223 111 0 0 64
223 112 149 0 32
223 112 148 0 0
223 112 147 0 64
223 112 2 0 32
223 112 1 0 0
223 112 0 0 64
223 113 149 0 32
223 113 148 0 0
223 113 147 0 64
223 113 2 0 32
223 113 1 0 0
223 113 0 0 64
223 114 149 0 32
223 114 148 0 0
223 114 147 0 64
223 114 2 0 32
223 114 1 0 0
223 114 0 0 64
223 115 149 0 32
223 115 148 0 0
223 115 147 0 64
223 115 2 0 32
223 115 1 0 0
223 115 0 0 64
223 116 149 0 32
223 116 148 0 0
223 116 147 0 64
223 116 2 0 32
223 116 1 0 0
223 116 0 0 64
223 117 149 0 32
223 117 148 0 0
223 117 147 0 64
223 117 2 0 32
223 117 1 0 0
223 117 0 0 64
223 118 149 0 32
223 118 148 0 0
223 118 147 0 64
223 118 2 0 32
223 118 1 0 0
223 118 0 0 64
223 119 149 0 32
223 119 148 0 0
223 119 147 0 64
223 119 2 0 32
223 119 1 0 0
223 119 0 0 64
223 120 149 0 32
223 120 148 0 0
223 120 147 0 64
223 120 2 0 32
223 120 1 0 0
223 120 0 0 64
223 121 149 0 32
223 121 148 0 0
223 121 147 0 64
223 121 2 0 32
223 121 1 0 0
223 121 0 0 64
223 122 149 0 32
223 122 148 0 0
223 122 147 0 64
223 122 2 0 32
223 122 1 0 0
223 122 0 0 64
223 123 149 0 32
223 123 148 0 0
223 123 147 0 64
223 123 2 0 32
223 123 1 0 0
223 123 0 0 64
223 124 149 0 32
223 124 148 0 0
223 124 147 0 64
223 124 2 0 32
223 124 1 0 0
223 124 0 0 64
223 125 149 0 32
223 125 148 0 0
223 125 147 0 64
223 125 2 0 32
223 125 1 0 0
223 125 0 0 64
223 126 149 0 32
223 126 148 0 0
223 126 147 0 64
223 126 2 0 32
223 126 1 0 0
223 126 0 0 64
223 127 149 0 32
223 127 148 0 0
223 127 147 0 64
223 127 2 0 32
223 127 1 0 0
223 127 0 0 64
223 128 149 0 32
223 128 148 0 0
223 128 147 0 64
223 128 2 0 32
223 128 1 0 0
223 128 0 0 64
223 129 149 0 32
223 129 148 0 0
223 129 147 0 64
223 129 2 0 32
223 129 1 0 0
223 129 0 0 64
223 130 149 0 32
223 130 148 0 0
223 130 147 0 64
223 130 2 0 32
223 130 1 0 0
223 130 0 0 64
223 131 149 0 32
223 131 148 0 0
223 131 147 0 64
223 131 2 0 32
223 131 1 0 0
223 131 0 0 64
223 132 149 0 32
223 132 148 0 0
223 132 147 0 64
223 132 2 0 32
223 132 1 0 0
223 132 0 0 64
223 133 149 0 32
223 133 148 0 0
223 133 147 0 64
223 133 2 0 32
223 133 1 0 0
223 133 0 0 64
223 134 149 0 32
223 134 148 0 0
223 134 147 0 64
223 134 2 0 32
223 134 1 0 0
223 134 0 0 64
223 135 149 0 32
223 135 148 0 0
223 135 147 0 64
223 135 2 0 32
223 135 1 0 0
223 135 0 0 64
223 136 149 0 32
223 136 148 0 0
223 136 147 0 64
223 136 2 0 32
223 136 1 0 0
223 136 0 0 64
223 137 149 0 32
223 137 148 0 0
223 137 147 0 64
223 137 2 0 32
223 137 1 0 0
223 137 0 0 64
223 138 149 0 32
223 138 148 0 0
223 138 147 0 64
223 138 2 0 32
223 138 1 0 0
223 138 0 0 64
223 139 149 0 32
223 139 148 0 0
223 139 147 0 64
223 139 2 0 32
223 139 1 0 0
223 139 0 0 64
223 140 149 0 32
223 140 148 0 0
223 140 147 0 64
223 140 2 0 32
223 140 1 0 0
223 140 0 0 64
223 141 149 0 32
223 141 148 0 0
223 141 147 0 64
223 141 2 0 32
223 141 1 0 0
223 141 0 0 64
223 142 149 0 32
223 142 148 0 0
223 142 147 0 64
223 142 2 0 32
223 142 1 0 0
223 142 0 0 64
223 143 149 0 32
223 143 148 0 0
223 143 147 0 64
223 143 2 0 32
223 143 1 0 0
223 143 0 0 64
223 144 149 0 32
223 144 148 0 0
223 144 147 0 64
223 144 2 0 32
223 144 1 0 0
223 144 0 0 64
223 145 149 0 32
223 145 148 0 0
223 145 147 0 64
223 145 2 0 32
223 145 1 0 0
223 145 0 0 64
223 146 149 0 40
223 146 148 0 8
223 146 147 0 72
223 146 2 0 40
223 146 1 0 8
223 146 0 0 72
224 1 149 0 50
224 1 148 0 18
224 1 147 0 82
224 1 2 0 50
224 1 1 0 18
224 1 0 0 82
224 2 149 0 34
224 2 148 0 2
224 2 147 0 66
224 2 2 0 34
224 2 1 0 2
224 2 0 0 66
224 3 149 0 34
224 3 148 0 2
224 3 147 0 66
224 3 2 0 34
224 3 1 0 2
224 3 0 0 66
224 4 149 0 34
224 4 148 0 2
224 4 147 0 66
224 4 2 0 34
224 4 1 0 2
224 4 0 0 66
224 5 149 0 34
224 5 148 0 2
224 5 147 0 66
224 5 2 0 34
224 5 1 0 2
224 5 0 0 66
224 6 149 0 34
224 6 148 0 2
224 6 147 0 66
224 6 2 0 34
224 6 1 0 2
224 6 0 0 66
224 7 149 0 34
224 7 148 0 2
224 7 147 0 66
224 7 2 0 34
224 7 1 0 2
224 7 0 0 66
224 8 149 0 34
224 8 148 0 2
224 8 147 0 66
224 8 2 0 34
224 8 1 0 2
224 8 0 0 66
224 9 149 0 34
224 9 148 0 2
224 9 147 0 66
224 9 2 0 34
224 9 1 0 2
224 9 0 0 66
224 10 149 0 34
224 10 148 0 2
224 10 147 0 66
224 10 2 0 34
224 10 1 0 2
224 10 0 0 66
224 11 149 0 34
224 11 148 0 2
224 11 147 0 66
224 11 2 0 34
224 11 1 0 2
224 11 0 0 66
224 12 149 0 34
224 12 148 0 2
224 12 147 0 66
224 12 2 0 34
224 12 1 0 2
224 12 0 0 66
224 13 149 0 34
224 13 148 0 2
224 13 147 0 66
224 13 2 0 34
224 13 1 0 2
224 13 0 0 66
224 14 149 0 34
224 14 148 0 2
224 14 147 0 66
224 14 2 0 34
224 14 1 0 2
